Workbook
Name N_b2_breaking_note: 'Τεχνικοί Υπολογισμοί'!$G$64
Name N_b2_breaking_price: 'Τεχνικοί Υπολογισμοί'!$E$64
Name N_b2_breaking_qty: 'Τεχνικοί Υπολογισμοί'!$D$64
Name N_b2_breaking_total: 'Τεχνικοί Υπολογισμοί'!$F$64
Name N_b2_conc_note: 'Τεχνικοί Υπολογισμοί'!$G$58
Name N_b2_conc_price: 'Τεχνικοί Υπολογισμοί'!$E$58
Name N_b2_conc_qty: 'Τεχνικοί Υπολογισμοί'!$D$58
Name N_b2_conc_total: 'Τεχνικοί Υπολογισμοί'!$F$58
Name N_b2_drill_600_note: 'Τεχνικοί Υπολογισμοί'!$G$57
Name N_b2_drill_600_price: 'Τεχνικοί Υπολογισμοί'!$E$57
Name N_b2_drill_600_qty: 'Τεχνικοί Υπολογισμοί'!$D$57
Name N_b2_drill_600_total: 'Τεχνικοί Υπολογισμοί'!$F$57
Name N_b2_drill_800_note: 'Τεχνικοί Υπολογισμοί'!$G$56
Name N_b2_drill_800_price: 'Τεχνικοί Υπολογισμοί'!$E$56
Name N_b2_drill_800_qty: 'Τεχνικοί Υπολογισμοί'!$D$56
Name N_b2_drill_800_total: 'Τεχνικοί Υπολογισμοί'!$F$56
Name N_b2_grand_total: 'Τεχνικοί Υπολογισμοί'!$F$66
Name N_b2_grand_total_note: 'Τεχνικοί Υπολογισμοί'!$G$66
Name N_b2_mob_note: 'Τεχνικοί Υπολογισμοί'!$G$55
Name N_b2_mob_price: 'Τεχνικοί Υπολογισμοί'!$E$55
Name N_b2_mob_qty: 'Τεχνικοί Υπολογισμοί'!$D$55
Name N_b2_mob_total: 'Τεχνικοί Υπολογισμοί'!$F$55
Name N_b2_sleeve_note: 'Τεχνικοί Υπολογισμοί'!$G$63
Name N_b2_sleeve_price: 'Τεχνικοί Υπολογισμοί'!$E$63
Name N_b2_sleeve_qty: 'Τεχνικοί Υπολογισμοί'!$D$63
Name N_b2_sleeve_total: 'Τεχνικοί Υπολογισμοί'!$F$63
Name N_b2_soil_note: 'Τεχνικοί Υπολογισμοί'!$G$65
Name N_b2_soil_price: 'Τεχνικοί Υπολογισμοί'!$E$65
Name N_b2_soil_qty: 'Τεχνικοί Υπολογισμοί'!$D$65
Name N_b2_soil_total: 'Τεχνικοί Υπολογισμοί'!$F$65
Name N_b2_steel_head_note: 'Τεχνικοί Υπολογισμοί'!$G$61
Name N_b2_steel_head_price: 'Τεχνικοί Υπολογισμοί'!$E$61
Name N_b2_steel_head_qty: 'Τεχνικοί Υπολογισμοί'!$D$61
Name N_b2_steel_head_total: 'Τεχνικοί Υπολογισμοί'!$F$61
Name N_b2_steel_note: 'Τεχνικοί Υπολογισμοί'!$G$62
Name N_b2_steel_price: 'Τεχνικοί Υπολογισμοί'!$E$62
Name N_b2_steel_qty: 'Τεχνικοί Υπολογισμοί'!$D$62
Name N_b2_steel_spiral_note: 'Τεχνικοί Υπολογισμοί'!$G$60
Name N_b2_steel_spiral_price: 'Τεχνικοί Υπολογισμοί'!$E$60
Name N_b2_steel_spiral_qty: 'Τεχνικοί Υπολογισμοί'!$D$60
Name N_b2_steel_spiral_total: 'Τεχνικοί Υπολογισμοί'!$F$60
Name N_b2_steel_total: 'Τεχνικοί Υπολογισμοί'!$F$62
Name N_b2_steel_vert_note: 'Τεχνικοί Υπολογισμοί'!$G$59
Name N_b2_steel_vert_price: 'Τεχνικοί Υπολογισμοί'!$E$59
Name N_b2_steel_vert_qty: 'Τεχνικοί Υπολογισμοί'!$D$59
Name N_b2_steel_vert_total: 'Τεχνικοί Υπολογισμοί'!$F$59
Name N_b2g_grand_total: 'Τεχνικοί Υπολογισμοί'!$F$97
Name N_b2g_grand_total_note: 'Τεχνικοί Υπολογισμοί'!$G$97
Name N_b2g0_breaking_note: 'Τεχνικοί Υπολογισμοί'!$G$79
Name N_b2g0_breaking_price: 'Τεχνικοί Υπολογισμοί'!$E$79
Name N_b2g0_breaking_qty: 'Τεχνικοί Υπολογισμοί'!$D$79
Name N_b2g0_breaking_total: 'Τεχνικοί Υπολογισμοί'!$F$79
Name N_b2g0_conc_note: 'Τεχνικοί Υπολογισμοί'!$G$73
Name N_b2g0_conc_price: 'Τεχνικοί Υπολογισμοί'!$E$73
Name N_b2g0_conc_qty: 'Τεχνικοί Υπολογισμοί'!$D$73
Name N_b2g0_conc_total: 'Τεχνικοί Υπολογισμοί'!$F$73
Name N_b2g0_drill_note: 'Τεχνικοί Υπολογισμοί'!$G$72
Name N_b2g0_drill_price: 'Τεχνικοί Υπολογισμοί'!$E$72
Name N_b2g0_drill_qty: 'Τεχνικοί Υπολογισμοί'!$D$72
Name N_b2g0_drill_total: 'Τεχνικοί Υπολογισμοί'!$F$72

Sheet Οικονομική Προσφορά
A1: ΘΕΜΕΛΙΟΤΕΧΝΙΚΗ ΛΤΔ — ΟΙΚΟΝΟΜΙΚΗ ΠΡΟΣΦΟΡΑ ΠΑΣΣΑΛΩΝ
A2: Έργο: Atlantic Forest — Plot 1 (Παρεκκλησιά, Λεμεσός) | Πελάτης: ATLANTIC FOREST PROPERTIES LTD | Τοποθεσία: | Τιμές & Κουμπιά ΝΑΙ/ΟΧΙ στο Φύλλο 3: «Τιμές & Έλεγχος»
A4: 🛑 ΠΡΟΣΟΧΗ — RED ALERT: Δεν έχουν δοθεί η στάθμη πλατφόρμας (WPL, κοινή για όλους) ή/και οι στάθμες αποκοπής (Cut-Off) ανά πάσσαλο. Όπου λείπουν, η προσφορά υπολογίζει Δh = 0.00 m (χωρίς κενή διάτρηση, sleeves και κεφαλοκοπή). Απαιτείται συμπλήρωση πριν την οριστικοποίηση.
A7: Α/Α | B7: Περιγραφή Εργασίας / Υλικού | C7: Ποσότητα | D7: Μονάδα | E7: Τιμή Μονάδας (€) [Από «Τιμές & Έλεγχος»] | F7: Σύνολο (€) | G7: Μέσο Κόστος ανά Πάσσαλο (€)
A8: 1 | B8: Μετακινήσεις γεωτρύπανου & Συνοδεία Αστυνομίας (επιμερισμός ανά πάσσαλο) | C8: ='Τεχνικοί Υπολογισμοί'!$D$14 -> 35 | D8: πάσσαλο | E8: ='Τεχνικοί Υπολογισμοί'!$D$15 -> 34.971429 | F8: =$C$8*$E$8 -> 1224 | G8: =$F$8/'Τεχνικοί Υπολογισμοί'!$D$14 -> 34.971429
A9: 2a | B9: Τρύπημα / διάτρηση πασσάλων Ø800mm (15 τεμ.) | C9: ='Τεχνικοί Υπολογισμοί'!$D$45 -> 150 | D9: m | E9: ='Τιμές & Έλεγχος'!$D$9 -> 115 | F9: =$C$9*$E$9 -> 17250 | G9: =$F$9/'Τεχνικοί Υπολογισμοί'!$D$14 -> 492.85714
A10: 2b | B10: Τρύπημα / διάτρηση πασσάλων Ø600mm (20 τεμ.) | C10: ='Τεχνικοί Υπολογισμοί'!$D$46 -> 100 | D10: m | E10: ='Τιμές & Έλεγχος'!$D$10 -> 90 | F10: =$C$10*$E$10 -> 9000 | G10: =$F$10/'Τεχνικοί Υπολογισμοί'!$D$14 -> 257.14286
A11: 3 | B11: ="Σκυροδέτηση πασσάλων "&'Τεχνικοί Υπολογισμοί'!$D$18&" (με απώλεια +"&ROUND('Τεχνικοί Υπολογισμοί'!$D$101*100,0)&"%)" -> Σκυροδέτηση πασσάλων C25/30 (με απώλεια +10%) | C11: ='Τεχνικοί Υπολογισμοί'!$D$47 -> 114.03981 | D11: m³ | E11: ='Τιμές & Έλεγχος'!$D$22 -> 120 | F11: =$C$11*$E$11 -> 13684.778 | G11: =$F$11/'Τεχνικοί Υπολογισμοί'!$D$14 -> 390.99365
A12: 4 | B12: ="Χάλυβας οπλισμού B500C (κάθετα σίδερα "&'Τεχνικοί Υπολογισμοί'!$D$28&"Φ"&'Τεχνικοί Υπολογισμοί'!$D$29&", σούστα Φ"&'Τεχνικοί Υπολογισμοί'!$D$34&"/"&ROUND('Τεχνικοί Υπολογισμοί'!$D$37/10,0)&" & στεφάνια αναμονής)" -> Χάλυβας οπλισμού B500C (κάθετα σίδερα 16Φ20, σούστα Φ10/15 & στεφάνια αναμονής) | C12: ='Τεχνικοί Υπολογισμοί'!$D$48 -> 11595.754 | D12: kg | E12: ='Τιμές & Έλεγχος'!$D$11 -> 1.1 | F12: =$C$12*$E$12 -> 12755.329 | G12: =$F$12/'Τεχνικοί Υπολογισμοί'!$D$14 -> 364.43797
A13: 5 | B13: ="Sleeves προστασίας αναμονών starter (Sleeve Φ32 για κάθετα σίδερα Φ"&'Τεχνικοί Υπολογισμοί'!$D$29&")" -> Sleeves προστασίας αναμονών starter (Sleeve Φ32 για κάθετα σίδερα Φ20) | C13: ='Τεχνικοί Υπολογισμοί'!$D$49 -> 0 | D13: τεμ. | E13: ='Τιμές & Έλεγχος'!$D$27 -> 3 | F13: =$C$13*$E$13 -> 0 | G13: =$F$13/'Τεχνικοί Υπολογισμοί'!$D$14 -> 0
A14: =IF('Τιμές & Έλεγχος'!$D$36="ΝΑΙ","6","") -> 6 | B14: =IF('Τιμές & Έλεγχος'!$D$36="ΝΑΙ","Κεφαλοκοπή πασσάλων / Pile Breaking","") -> Κεφαλοκοπή πασσάλων / Pile Breaking | C14: =IF('Τιμές & Έλεγχος'!$D$36="ΝΑΙ",'Τεχνικοί Υπολογισμοί'!$D$50,0) -> 0 | D14: =IF('Τιμές & Έλεγχος'!$D$36="ΝΑΙ","τεμ.","") -> τεμ. | E14: =IF('Τιμές & Έλεγχος'!$D$36="ΝΑΙ",'Τιμές & Έλεγχος'!$D$12,0) -> 150 | F14: =$C$14*$E$14 -> 0 | G14: =$F$14/'Τεχνικοί Υπολογισμοί'!$D$14 -> 0
A15: =IF('Τιμές & Έλεγχος'!$D$37="ΝΑΙ",IF('Τιμές & Έλεγχος'!$D$36="ΝΑΙ","7","6"),"") -> 7 | B15: =IF('Τιμές & Έλεγχος'!$D$37="ΝΑΙ","Απομάκρυνση εκσκαπτόμενου χώματος & Λατομικά τέλη","") -> Απομάκρυνση εκσκαπτόμενου χώματος & Λατομικά τέλη | C15: =IF('Τιμές & Έλεγχος'!$D$37="ΝΑΙ",'Τεχνικοί Υπολογισμοί'!$D$51,0) -> 103.67256 | D15: =IF('Τιμές & Έλεγχος'!$D$37="ΝΑΙ","m³","") -> m³ | E15: =IF('Τιμές & Έλεγχος'!$D$37="ΝΑΙ",'Τιμές & Έλεγχος'!$D$38,0) -> 15 | F15: =$C$15*$E$15 -> 1555.0884 | G15: =$F$15/'Τεχνικοί Υπολογισμοί'!$D$14 -> 44.431096
A16: ΓΕΝΙΚΟ ΣΥΝΟΛΟ ΠΡΟΣΦΟΡΑΣ (ΧΩΡΙΣ Φ.Π.Α.) | F16: =$F$8+$F$9+$F$10+$F$11+$F$12+$F$13+$F$14+$F$15 -> 55469.195 | G16: =$F$16/'Τεχνικοί Υπολογισμοί'!$D$14 -> 1584.8341
A18: ΟΡΟΙ, ΠΑΡΑΔΟΧΕΣ & ΠΑΡΑΤΗΡΗΣΕΙΣ (100% ΔΥΝΑΜΙΚΕΣ ΣΗΜΕΙΩΣΕΙΣ — ΕΝΗΜΕΡΩΝΟΝΤΑΙ ΑΥΤΟΜΑΤΑ ΑΠΟ ΤΟ ΦΥΛΛΟ «Τιμές & Έλεγχος»):
A19: ="1. Στις τιμές ΔΕΝ περιλαμβάνεται ο Φ.Π.Α. — Γενικό Σύνολο Προσφοράς: "&ROUND($F$16,2)&" € (Μέσο κόστος ανά πάσσαλο: "&ROUND($F$16/'Τεχνικοί Υπολογισμοί'!$D$14,2)&" € για "&'Τεχνικοί Υπολογισμοί'!$D$14&" πασσάλους)." -> 1. Στις τιμές ΔΕΝ περιλαμβάνεται ο Φ.Π.Α. — Γενικό Σύνολο Προσφοράς: 55469.19 € (Μέσο κόστος ανά πάσσαλο: 1584.83 € για 35 πασσάλους).
A20: ="2. Μετακινήσεις γεωτρύπανου: Βασική Λεμεσού ("&ROUND('Τιμές & Έλεγχος'!$D$7,2)&" €) + Εκτός Λεμεσού ανά "&ROUND('Τεχνικοί Υπολογισμοί'!$D$8,0)&"km ("&'Τεχνικοί Υπολογισμοί'!$D$9&" × "&ROUND('Τιμές & Έλεγχος'!$D$8,2)&" € = "&ROUND('Τεχνικοί Υπολογισμοί'!$D$9*'Τιμές & Έλεγχος'!$D$8,2)&" €) + Συνοδεία Αστυνομίας από Σπύρου Κυπριανού 32, Αγ. Συλά ("&ROUND('Τιμές & Έλεγχος'!$D$30,1)&" km × "&ROUND('Τιμές & Έλεγχος'!$D$31,2)&" €/km = "&ROUND('Τιμές & Έλεγχος'!$D$32,2)&" €) = "&ROUND('Τεχνικοί Υπολογισμοί'!$D$13,2)&" € ("&ROUND($E$8,2)&" €/πάσσαλο)." -> 2. Μετακινήσεις γεωτρύπανου: Βασική Λεμεσού (1000 €) + Εκτός Λεμεσού ανά 10km (0 × 200 € = 0 €) + Συνοδεία Αστυνομίας από Σπύρου Κυπριανού 32, Αγ. Συλά (28 km × 8 €/km = 224 €) = 1224 € (34.97 €/πάσσαλο).
A21: ="3. Εκσκαφή / Διάτρηση (από στάθμη πλατφόρμας WPL "&ROUND('Τεχνικοί Υπολογισμοί'!$D$17,2)&"m): Ύψος σκυροδετημένου πασσάλου = "&ROUND('Τεχνικοί Υπολογισμοί'!$D$25,3)&"m, Συνολικά μέτρα διάτρησης = "&ROUND('Τεχνικοί Υπολογισμοί'!$D$45,2)&"m × Τιμή μέτρου ("&ROUND($E$9,2)&" €) = "&ROUND($F$9,2)&" €." -> 3. Εκσκαφή / Διάτρηση (από στάθμη πλατφόρμας WPL 0m): Ύψος σκυροδετημένου πασσάλου = 10m, Συνολικά μέτρα διάτρησης = 150m × Τιμή μέτρου (115 €) = 17250 €.
A22: ="4. Σκυρόδεμα "&'Τεχνικοί Υπολογισμοί'!$D$18&": ROUND(Αγορά "&ROUND('Τιμές & Έλεγχος'!$D$16,2)&" €/m³ + Τοποθέτηση "&ROUND('Τιμές & Έλεγχος'!$D$17,2)&" €/m³ + Αντλία "&ROUND('Τιμές & Έλεγχος'!$D$21,2)&" €/m³, 0) = "&ROUND($E$11,0)&" €/m³ × "&ROUND('Τεχνικοί Υπολογισμοί'!$D$47,2)&" m³ = "&ROUND($F$11,2)&" €." -> 4. Σκυρόδεμα C25/30: ROUND(Αγορά 105 €/m³ + Τοποθέτηση 15 €/m³ + Αντλία 0 €/m³, 0) = 120 €/m³ × 114.04 m³ = 13684.78 €.
A23: ="5. Οπλισμός κλωβού ("&'Τεχνικοί Υπολογισμοί'!$D$28&"Φ"&'Τεχνικοί Υπολογισμοί'!$D$29&" + σούστα Φ"&'Τεχνικοί Υπολογισμοί'!$D$34&"/"&ROUND('Τεχνικοί Υπολογισμοί'!$D$37/10,0)&"): Αναμονή starter = "&ROUND('Τεχνικοί Υπολογισμοί'!$D$30,2)&"m, Γωνία πάνω = "&ROUND('Τεχνικοί Υπολογισμοί'!$D$31,2)&"m, Γωνία κάτω = "&ROUND('Τεχνικοί Υπολογισμοί'!$D$32,2)&"m, Ύψος μάτισης = "&ROUND('Τεχνικοί Υπολογισμοί'!$D$33,2)&"m ("&'Τεχνικοί Υπολογισμοί'!$D$121&" μάτιση), Σπείρες σούστας = "&'Τεχνικοί Υπολογισμοί'!$D$125&" (με +1) + "&'Τεχνικοί Υπολογισμοί'!$D$128&" στεφάνια αναμονής (χωρίς +1) → "&ROUND('Τεχνικοί Υπολογισμοί'!$D$131,2)&" kg/πασσ., Σύνολο = "&ROUND('Τεχνικοί Υπολογισμοί'!$D$48,1)&" kg × Τιμή κιλού ("&ROUND($E$12,2)&" €) = "&ROUND($F$12,2)&" €." -> 5. Οπλισμός κλωβού (16Φ20 + σούστα Φ10/15): Αναμονή starter = 0.45m, Γωνία πάνω = 0.5m, Γωνία κάτω = 0m, Ύψος μάτισης = 1m (0 μάτιση), Σπείρες σούστας = 68 (με +1) + 3 στεφάνια αναμονής (χωρίς +1) → 528.33 kg/πασσ., Σύνολο = 11595.8 kg × Τιμή κιλού (1.1 €) = 12755.33 €.
A24: ="6. Sleeves αναμονών (Sleeve Φ32 για Φ"&'Τεχνικοί Υπολογισμοί'!$D$29&"): ((Κόστος αγοράς + Κόστος τοποθέτησης) × Profit, Waste, Overhead) = "&ROUND('Τιμές & Έλεγχος'!$D$26,2)&" € → Στρογγυλεμένο τελικό αποτέλεσμα = "&ROUND($E$13,2)&" €/τεμ. × "&'Τεχνικοί Υπολογισμοί'!$D$49&" τεμ. = "&ROUND($F$13,2)&" €." -> 6. Sleeves αναμονών (Sleeve Φ32 για Φ20): ((Κόστος αγοράς + Κόστος τοποθέτησης) × Profit, Waste, Overhead) = 2.87 € → Στρογγυλεμένο τελικό αποτέλεσμα = 3 €/τεμ. × 0 τεμ. = 0 €.
A25: ="7. Κεφαλοκοπή πασσάλων (Κουμπί Τ.Ε.1 = "&'Τιμές & Έλεγχος'!$D$36&"): "&IF('Τιμές & Έλεγχος'!$D$36="ΝΑΙ","ΠΕΡΙΛΑΜΒΑΝΕΤΑΙ στην προσφορά ("&$C$14&" τεμ. × "&ROUND($E$14,2)&" € = "&ROUND($F$14,2)&" €).","ΔΕΝ ΠΕΡΙΛΑΜΒΑΝΕΤΑΙ στην προσφορά (Ευθύνη Πελάτη / Εργολάβου — 0,00 €).")&" | Απομάκρυνση εκσκαπτόμενου χώματος & Λατομικά τέλη (Κουμπί Τ.Ε.2 = "&'Τιμές & Έλεγχος'!$D$37&"): "&IF('Τιμές & Έλεγχος'!$D$37="ΝΑΙ","ΠΕΡΙΛΑΜΒΑΝΕΤΑΙ στην προσφορά ("&ROUND($C$15,2)&" m³ × "&ROUND($E$15,2)&" €/m³ = "&ROUND($F$15,2)&" €).","ΔΕΝ ΠΕΡΙΛΑΜΒΑΝΕΤΑΙ στην προσφορά (Ευθύνη Πελάτη / Εργολάβου — 0,00 €).") -> 7. Κεφαλοκοπή πασσάλων (Κουμπί Τ.Ε.1 = ΝΑΙ): ΠΕΡΙΛΑΜΒΑΝΕΤΑΙ στην προσφορά (0 τεμ. × 150 € = 0 €). | Απομάκρυνση εκσκαπτόμενου χώματος & Λατομικά τέλη (Κουμπί Τ.Ε.2 = ΝΑΙ): ΠΕΡΙΛΑΜΒΑΝΕΤΑΙ στην προσφορά (103.67 m³ × 15 €/m³ = 1555.09 €).
A26: 8. Πληρωμή βάσει επιμετρήσεων πραγματικά εκτελεσθέντων μέτρων διάτρησης, κυβικών σκυροδέματος και κιλών οπλισμού. Όλες οι τιμές μονάδας και τα κουμπιά επιλογής (ΝΑΙ/ΟΧΙ) ορίζονται στο Φύλλο 3 («Τιμές & Έλεγχος»).

Sheet Τεχνικοί Υπολογισμοί
A1: ΘΕΜΕΛΙΟΤΕΧΝΙΚΗ ΛΤΔ — ΤΕΧΝΙΚΟΙ ΥΠΟΛΟΓΙΣΜΟΙ ΔΙΑΤΡΗΤΩΝ ΠΑΣΣΑΛΩΝ
A2: Έργο: Atlantic Forest — Plot 1 (Παρεκκλησιά, Λεμεσός) | Πελάτης: ATLANTIC FOREST PROPERTIES LTD | Μελέτη: Πανίκος Μ. Χαριλάου (Architect Engineer Consultant) | Μηχανή v7.0 (Τιμές & Κουμπιά ΝΑΙ/ΟΧΙ στο Φύλλο 3: «Τιμές & Έλεγχος»)
A4: 1. ΔΕΔΟΜΕΝΑ ΣΧΕΔΙΟΥ & ΥΨΟΜΕΤΡΑ
A5: Κωδ. | B5: Παράμετρος | C5: Μονάδα | D5: Τιμή | G5: Παρατηρήσεις / Προέλευση
A6: Τομέας 1 — Μετακινήσεις & Συνοδεία Αστυνομίας (Τιμές από το Φύλλο 3: «Τιμές & Έλεγχος»)
A7: 1.1.1 | B7: Χιλιόμετρα εκτός Λεμεσού (0 km αν το έργο είναι μέσα στη Λεμεσό) | C7: km | D7: ='Τιμές & Έλεγχος'!$D$6 -> 0 | G7: Από Φύλλο 3 («Τιμές & Έλεγχος» Τ.1)
A8: 1.1.2 | B8: Βήμα χιλιομετρικής χρέωσης εκτός Λεμεσού (ανά 10 km) | C8: km | D8: 10 | G8: Τιμοκατάλογος (γρ. 28)
A9: 1.1.3 | B9: Δεκάδες χιλιομέτρων εκτός Λεμεσού (ανά 10 km) | C9: ζώνες | D9: =IF('Τιμές & Έλεγχος'!$D$6>0,ROUNDUP(ROUND('Τιμές & Έλεγχος'!$D$6/$D$8,9),0),0) -> 0 | G9: ROUNDUP(km εκτός Λεμεσού / 10, 0)
A10: 1.1.4 | B10: Μετακίνηση — βασική τιμή εντός Λεμεσού | C10: € | D10: ='Τιμές & Έλεγχος'!$D$7 -> 1000 | G10: Από Φύλλο 3 («Τιμές & Έλεγχος» Τ.2 = 1.000,00 €)
A11: 1.1.5 | B11: Μετακίνηση — επιβάρυνση ανά 10 km εκτός Λεμεσού | C11: € | D11: ='Τιμές & Έλεγχος'!$D$8 -> 200 | G11: Από Φύλλο 3 («Τιμές & Έλεγχος» Τ.3 = 200,00 €/10km)
A12: 1.1.6 | B12: Κόστος Συνοδείας Αστυνομίας (Χιλιόμετρα × 8,00 €/km) | C12: € | D12: ='Τιμές & Έλεγχος'!$D$32 -> 224 | G12: Από Φύλλο 3 («Τιμές & Έλεγχος» Τ.Δ.3 = police_km × 8,00 €/km)
A13: 1.1.7 | B13: Συνολικό εφάπαξ ποσό μετακίνησης & συνοδείας Αστυνομίας | C13: € | D13: ='Τιμές & Έλεγχος'!$D$7+$D$9*'Τιμές & Έλεγχος'!$D$8+'Τιμές & Έλεγχος'!$D$32 -> 1224 | G13: Βασική Λεμεσού (1.000€) + Δεκάδες km × 200€ + Συνοδεία Αστυνομίας
A14: 1.1.8 | B14: Συνολικό πλήθος πασσάλων έργου | C14: τεμ. | D14: =$D$23+$E$23 -> 35 | G14: Άθροισμα ομάδων
A15: 1.1.9 | B15: Επιμερισμένη μετακίνηση ανά πάσσαλο | C15: € | D15: =$D$13/$D$14 -> 34.971429 | G15: Συνολική μετακίνηση ÷ Πάσσαλοι
A16: Τομέας 2 — Υψόμετρα & Σκυρόδεμα (WPL κοινό για όλους, Cut-Off ανά πάσσαλο στον Τομέα 3)
A17: 1.2.1 | B17: Στάθμη πλατφόρμας γεωτρύπανου (WPL) — κοινή για όλους τους πασσάλους | C17: m | D17: 0 | G17: ΚΟΚΚΙΝΟΣ ΣΥΝΑΓΕΡΜΟΣ: δεν δόθηκε — προσωρινά 0.00
A18: 1.2.2 | B18: Κατηγορία σκυροδέματος | C18: - | D18: C25/30 | G18: Από Σημείωση 1 σχεδίου 00Σ: «1. Σκυρόδεμα C25/30»
A19: 1.2.3 | B19: Επικάλυψη οπλισμού (Cover) | C19: mm | D19: 50 | G19: Από Σημείωση 4 σχεδίου 00Σ: «4. Επικάλυψη οπλισμού πεδίλων και γενικά στοιχείων μέσα στο έδαφος, 5 εκ.» (50 mm)
A20: Τομέας 3 — Ομάδες πασσάλων & κλωβός οπλισμού (μία στήλη ανά ομάδα)
A21: Κωδ. | B21: Παράμετρος | C21: Μονάδα | D21: Ομάδα 1 | E21: Ομάδα 2 | G21: Παρατηρήσεις
A22: 1.3.0 | B22: Πάσσαλοι | D22: Πάσσαλοι ΠΣ Ø800mm (Κοιτόστρωση Υπογείου) ΠΣ #1 έως ΠΣ #15 (12 σε κοιτόστρωση 55εκ. + 3 σε κοιτόστρωση 40εκ.) | E22: Πάσσαλοι ΠΣ1 Ø600mm (Περίφραξη / Περιμετρικά Τοιχεία) ΠΣ1 #1 έως ΠΣ1 #20 (ανά ~5m στην περίφραξη ΤΠ1/ΤΠ2/ΤΑ4)
A23: 1.3.1 | B23: Πλήθος πασσάλων ομάδας | C23: τεμ. | D23: 15 | E23: 20 | F23: =$D$23+$E$23 -> 35 | G23: Καταμέτρηση από κάτοψη 00Σ με OpenCV & ανάλυση διανυσμάτων PDF (15 ΠΣ + 20 ΠΣ1 = 35 πάσσαλοι)
A24: 1.3.2 | B24: Διάμετρος τρύπας πασσάλου | C24: mm | D24: 800 | E24: 600 | G24: Σχέδιο 00Σ & 001Σ: ΠΣ = Ø800mm, ΠΣ1 = Ø600mm
A25: 1.3.3 | B25: Ύψος σκυροδετημένου πασσάλου (κάτω από το Cut-Off) | C25: m | D25: 10 | E25: 5 | G25: Σχέδιο 00Σ & 001Σ: ΠΣ = Βάθος 10.00m, ΠΣ1 = Βάθος 5.00m
A26: 1.3.4 | B26: Στάθμη αποκοπής κεφαλής πασσάλου (Cut-Off) | C26: m | D26: ΛΕΙΠΕΙ | E26: ΛΕΙΠΕΙ | G26: ΚΟΚΚΙΝΟΣ ΣΥΝΑΓΕΡΜΟΣ: Δεν καθορίζεται η υψομετρική διαφορά WPL − Cut-Off (προσωρινά Δh = 0.00m)
A27: 1.3.5 | B27: Βάθος / Πάχος πεδιλόπλακας | C27: m | D27: 0.55 | E27: 0.55 | G27: Σχέδιο 00Σ & Τομή 001Σ: Κοιτόστρωση / Πεδιλοδοκός πάχους 55 εκ. (0.55m — 3 ΠΣ βρίσκονται σε τμήμα 40 εκ.)
A28: 1.3.6 | B28: Κάθετα σίδερα κλωβού — Πλήθος | C28: τεμ. | D28: 16 | E28: 10 | G28: Σχέδιο 00Σ: ΠΣ = 16Υ20 (16 ράβδοι), ΠΣ1 = 10Υ20 (10 ράβδοι)
A29: 1.3.7 | B29: Κάθετα σίδερα κλωβού — Διάμετρος Φ | C29: mm | D29: 20 | E29: 20 | G29: Σχέδιο 00Σ: Κάθετος οπλισμός Υ20 (Φ20mm) B500C και στους δύο τύπους
A30: 1.3.8 | B30: Ύψος αναμονής / Starter (κενό σχεδίου → πεδιλόπλακα − 0.10m) | C30: m | D30: =$D$27-$D$107 -> 0.45 | E30: =$E$27-$D$107 -> 0.45 | G30: Κανόνας εταιρείας (RULES_v7 §11.1): Βάθος πεδιλόπλακας (0.55m) − 0.10m = 0.45m
A31: 1.3.9 | B31: Γωνία πάνω (κενό σχεδίου → 0.50m) | C31: m | D31: =$D$108 -> 0.5 | E31: =$D$108 -> 0.5 | G31: Τομή 001Σ («να γυρίζει γωνία μέσα στη κοιτόστρωση») + Κανόνας εταιρείας (RULES_v7 §11.2): 0.50m
A32: 1.3.10 | B32: Γωνία κάτω (στον πυθμένα) | C32: m | D32: 0 | E32: 0 | G32: Τομή 001Σ: Ευθύγραμμες ράβδοι στον πυθμένα (0.00m)
A33: 1.3.11 | B33: Ύψος μάτισης (κενό σχεδίου → 50×Φ) | C33: m | D33: =$D$104*$D$29/1000 -> 1 | E33: =$D$104*$E$29/1000 -> 1 | G33: Κανόνας εταιρείας (RULES_v7 §11.5): 50 × Φ = 1.00m (δεν απαιτείται μάτιση αφού L_base < 12.00m)
A34: 1.3.12 | B34: Σούστα & στεφάνια — Διάμετρος Φ | C34: mm | D34: 10 | E34: 10 | G34: Σχέδιο 00Σ & 001Σ: Συνδετήρες σπειροειδείς Υ10/15 (Φ10mm)
A35: 1.3.13 | B35: Βήμα σούστας στα άκρα (πρώτα & τελευταία μέτρα) | C35: mm | D35: 150 | E35: 150 | G35: Σχέδιο 00Σ & 001Σ: Ενιαίο βήμα σπείρας 15 εκ. (150mm)
A36: 1.3.14 | B36: Μήκος ζώνης πύκνωσης άκρου (πάνω & κάτω) | C36: m | D36: 0 | E36: 0 | G36: Δεν προβλέπεται ξεχωριστή ζώνη πύκνωσης (0.00m)
A37: 1.3.15 | B37: Βήμα σούστας (απόσταση μεταξύ σπειρών) | C37: mm | D37: 150 | E37: 150 | G37: Σχέδιο 00Σ & 001Σ: Σπειροειδείς συνδετήρες Υ10/15 (βήμα 150mm)
A38: 1.3.16 | B38: Στεφάνια αναμονής starter — ρητά από σχέδιο (κενό → υπολογισμός) | C38: τεμ. | D38: — | E38: —
A39: 1.3.17 | B39: Πρόσθετος οπλισμός (U-bars κ.λπ.) — Πλήθος | C39: τεμ. | D39: 0 | E39: 0
A40: 1.3.18 | B40: Πρόσθετος οπλισμός — Διάμετρος Φ | C40: mm | D40: 0 | E40: 0
A41: 1.3.19 | B41: Πρόσθετος οπλισμός — Μήκος ανά βέργα | C41: m | D41: 0 | E41: 0
...

Sheet Τιμές & Έλεγχος
A1: ΘΕΜΕΛΙΟΤΕΧΝΙΚΗ ΛΤΔ — ΚΕΝΤΡΙΚΟΣ ΠΙΝΑΚΑΣ ΤΙΜΩΝ, ΚΟΥΜΠΙΩΝ (ΝΑΙ/ΟΧΙ) & ΕΛΕΓΧΟΥ ΕΡΓΟΥ | Z1: ΝΑΙ
A2: Όλες οι τιμές μονάδας, τα κουτάκια σκυροδέματος/sleeve (άτομα, λεπτά, εργατοώρα, τέλλα) και τα κουμπιά ΝΑΙ/ΟΧΙ ορίζονται ΕΔΩ και ενημερώνουν αυτόματα όλα τα φύλλα και όλες τις σημειώσεις! | Z2: ΟΧΙ
A4: Α. ΚΥΡΙΕΣ ΤΙΜΕΣ ΜΟΝΑΔΑΣ & ΜΕΤΑΚΙΝΗΣΕΙΣ (ΚΙΤΡΙΝΟ = ΑΛΛΑΖΕΙΣ ΕΔΩ)
A5: Κωδ. | B5: Περιγραφή Τιμής / Παραμέτρου | C5: Μονάδα | D5: Τιμή [ΑΛΛΑΖΕΙΣ ΕΔΩ] | E5: Προέλευση | F5: Πού Εφαρμόζεται (100% Δυναμική Σημείωση)
A6: Τ.1 | B6: Χιλιόμετρα εκτός Λεμεσού για επιβάρυνση ζωνών +200€/10km (0 km αν το έργο είναι μέσα στη Λεμεσό) | C6: km | D6: 0 | E6: Έργο στην Παρεκκλησιά (Εντός επαρχίας Λεμεσού — 0 km εκτός Λεμεσού για τις ζώνες +200€/10km) | F6: ="Υπολογίζει αυτόματα τις ζώνες των "&ROUND('Τεχνικοί Υπολογισμοί'!$D$8,0)&" km εκτός Λεμεσού ("&'Τεχνικοί Υπολογισμοί'!$D$9&" × "&ROUND($D$8,2)&" € = "&ROUND('Τεχνικοί Υπολογισμοί'!$D$9*$D$8,2)&" €)" -> Υπολογίζει αυτόματα τις ζώνες των 10 km εκτός Λεμεσού (0 × 200 € = 0 €)
A7: Τ.2 | B7: Μετακίνηση γεωτρύπανου — Βασική τιμή (Μέσα στη Λεμεσό) | C7: € | D7: 1000 | E7: Τιμοκατάλογος (γρ. 5) | F7: ="Βασική χρέωση "&ROUND($D$7,2)&" € εντός Λεμεσού → Φύλλο 1 (Γρ. 1) & Φύλλο 2 (1.1.4, 2Β.1 & 2Γ)" -> Βασική χρέωση 1000 € εντός Λεμεσού → Φύλλο 1 (Γρ. 1) & Φύλλο 2 (1.1.4, 2Β.1 & 2Γ)
A8: Τ.3 | B8: ="Μετακίνηση γεωτρύπανου — Επιβάρυνση ανά "&ROUND('Τεχνικοί Υπολογισμοί'!$D$8,0)&" km εκτός Λεμεσού (+"&ROUND($D$8,0)&" €/"&ROUND('Τεχνικοί Υπολογισμοί'!$D$8,0)&"km)" -> Μετακίνηση γεωτρύπανου — Επιβάρυνση ανά 10 km εκτός Λεμεσού (+200 €/10km) | C8: € | D8: 200 | E8: Τιμοκατάλογος (γρ. 6) | F8: ="+"&ROUND($D$8,2)&" € ανά "&ROUND('Τεχνικοί Υπολογισμοί'!$D$8,0)&" km εκτός Λεμεσού → Φύλλο 1 (Γρ. 1) & Φύλλο 2 (1.1.5, 2Β.1 & 2Γ)" -> +200 € ανά 10 km εκτός Λεμεσού → Φύλλο 1 (Γρ. 1) & Φύλλο 2 (1.1.5, 2Β.1 & 2Γ)
A9: Τ.4.1 | B9: Τρύπημα / Διάτρηση Πασσάλων Ø800mm | C9: € | D9: 115 | E9: Τιμοκατάλογος (γρ. 11) | F9: ="Τιμή διάτρησης Ø800mm = "&ROUND($D$9,2)&" €/m → Φύλλο 1 (Γρ. 2) & Φύλλο 2 (2Β.2 & 2Γ)" -> Τιμή διάτρησης Ø800mm = 115 €/m → Φύλλο 1 (Γρ. 2) & Φύλλο 2 (2Β.2 & 2Γ)
A10: Τ.4.2 | B10: Τρύπημα / Διάτρηση Πασσάλων Ø600mm | C10: € | D10: 90 | E10: Τιμοκατάλογος (γρ. 9) | F10: ="Τιμή διάτρησης Ø600mm = "&ROUND($D$10,2)&" €/m → Φύλλο 1 (Γρ. 2) & Φύλλο 2 (2Β.2 & 2Γ)" -> Τιμή διάτρησης Ø600mm = 90 €/m → Φύλλο 1 (Γρ. 2) & Φύλλο 2 (2Β.2 & 2Γ)
A11: Τ.5 | B11: Χάλυβας οπλισμού B500C (Κάθετα σίδερα & Σούστα) — Τιμή κιλού | C11: € | D11: 1.1 | E11: Τιμοκατάλογος (γρ. 19) | F11: ="Τιμή σιδήρου = "&ROUND($D$11,2)&" €/kg → Φύλλο 1 (Γρ. 4) & Φύλλο 2 (2Β.4 & 2Γ)" -> Τιμή σιδήρου = 1.1 €/kg → Φύλλο 1 (Γρ. 4) & Φύλλο 2 (2Β.4 & 2Γ)
A12: Τ.6 | B12: Κεφαλοκοπή πασσάλων (Pile Breaking) — Τιμή τεμαχίου | C12: € | D12: 150 | E12: Τιμοκατάλογος (γρ. 23) | F12: ="Τιμή κεφαλοκοπής = "&ROUND($D$12,2)&" €/πάσσαλο (Κουμπί Τ.Ε.1 = "&$D$36&") → Φύλλο 1 (Γρ. 6) & Φύλλο 2 (2Β.6 & 2Γ)" -> Τιμή κεφαλοκοπής = 150 €/πάσσαλο (Κουμπί Τ.Ε.1 = ΝΑΙ) → Φύλλο 1 (Γρ. 6) & Φύλλο 2 (2Β.6 & 2Γ)
A14: Β. ΥΠΟΛΟΓΙΣΜΟΣ ΤΙΜΗΣ ΚΑΝΟΝΙΚΟΥ ΣΚΥΡΟΔΕΜΑΤΟΣ (C25/30) — ΚΟΥΤΑΚΙΑ ΜΗΧΑΝΙΚΟΥ
A15: Κωδ. | B15: Παράμετρος Κόστους Σκυροδέτησης | C15: Μονάδα | D15: Τιμή / Κουτάκι | E15: Προέλευση / Τύπος | F15: Δυναμική Επεξήγηση
A16: Τ.Β.1 | B16: Τιμή αγοράς σκυροδέματος (C25/30) από προμηθευτή [ΚΟΥΤΑΚΙ ΜΗΧΑΝΙΚΟΥ] | C16: € | D16: 105 | E16: Τιμοκατάλογος (γρ. 16) | F16: ="Τιμή αγοράς κουγκριού από προμηθευτή = "&ROUND($D$16,2)&" €/m³" -> Τιμή αγοράς κουγκριού από προμηθευτή = 105 €/m³
A17: Τ.Β.2 | B17: Κόστος τοποθέτησης σκυροδέματος (σταθερό ανά κυβικό) | C17: € | D17: 15 | E17: Τιμοκατάλογος (γρ. 18) | F17: ="Σταθερή χρέωση τοποθέτησης = +"&ROUND($D$17,2)&" €/m³ από τον Τιμοκατάλογο Εταιρείας" -> Σταθερή χρέωση τοποθέτησης = +15 €/m³ από τον Τιμοκατάλογο Εταιρείας
A18: Τ.Β.3 | B18: Κόστος στησίματος αντλίας (πρέσας) ανά στήσιμο [ΚΟΥΤΑΚΙ ΜΗΧΑΝΙΚΟΥ] | C18: € | D18: 0 | E18: Κουτάκι Μηχανικού (Κόστος στησίματος αντλίας) | F18: ="Κόστος στησίματος αντλίας = "&ROUND($D$18,2)&" €/στήσιμο" -> Κόστος στησίματος αντλίας = 0 €/στήσιμο
A19: Τ.Β.4 | B19: Πόσες τρύπες (πασσάλους) θα κάνει η αντλία ανά στήσιμο [ΚΟΥΤΑΚΙ ΜΗΧΑΝΙΚΟΥ] | C19: τρύπες | D19: 6 | E19: Κουτάκι Μηχανικού (Τρύπες/πασσάλους ανά στήσιμο αντλίας) | F19: ="Η αντλία σκυροδετεί "&ROUND($D$19,0)&" πασσάλους ανά στήσιμο" -> Η αντλία σκυροδετεί 6 πασσάλους ανά στήσιμο
A20: Τ.Β.5 | B20: Κυβικά κουγκριού που αντλεί η αντλία ανά στήσιμο (Τρύπες × m³/τρύπα) | C20: m³ | D20: =$D$19*('Τεχνικοί Υπολογισμοί'!$D$47/'Τεχνικοί Υπολογισμοί'!$D$14) -> 19.549682 | E20: ="Αυτόματος τύπος: "&ROUND($D$19,0)&" τρύπες × "&ROUND('Τεχνικοί Υπολογισμοί'!$D$47/'Τεχνικοί Υπολογισμοί'!$D$14,3)&" m³/τρύπα" -> Αυτόματος τύπος: 6 τρύπες × 3.258 m³/τρύπα | F20: ="Κυβικά ανά στήσιμο αντλίας = "&ROUND($D$20,2)&" m³" -> Κυβικά ανά στήσιμο αντλίας = 19.55 m³
A21: Τ.Β.6 | B21: Επιβάρυνση στησίματος αντλίας ανά κυβικό (Στήσιμο ÷ m³ ανά στήσιμο) | C21: € | D21: =IF(AND($D$18>0,$D$20>0),$D$18/$D$20,0) -> 0 | E21: ="Αυτόματος τύπος: "&ROUND($D$18,2)&" € ÷ "&ROUND($D$20,2)&" m³" -> Αυτόματος τύπος: 0 € ÷ 19.55 m³ | F21: ="Επιβάρυνση αντλίας = "&ROUND($D$21,2)&" €/m³" -> Επιβάρυνση αντλίας = 0 €/m³
A22: Τ.Β.7 | B22: ΤΕΛΙΚΗ ΤΙΜΗ ΣΚΥΡΟΔΕΤΗΣΗΣ (C25/30) ΑΝΑ ΚΥΒΙΚΟ [ΣΤΡΟΓΓΥΛΟΠΟΙΗΜΕΝΗ ΣΕ ΑΚΕΡΑΙΟ €] | C22: € | D22: =ROUND($D$16+$D$17+$D$21,0) -> 120 | E22: ="ROUND("&ROUND($D$16,2)&" € + "&ROUND($D$17,2)&" € + "&ROUND($D$21,2)&" €, 0) = "&ROUND($D$22,0)&" €/m³" -> ROUND(105 € + 15 € + 0 €, 0) = 120 €/m³ | F22: ="Στρογγυλοποιημένη τελική τιμή ("&ROUND($D$22,0)&" €/m³) — Τροφοδοτεί Φύλλο 1 (Γρ. 3) & Φύλλο 2 (2Β.3 & 2Γ)" -> Στρογγυλοποιημένη τελική τιμή (120 €/m³) — Τροφοδοτεί Φύλλο 1 (Γρ. 3) & Φύλλο 2 (2Β.3 & 2Γ)
A24: Γ. ΚΟΣΤΟΛΟΓΗΣΗ SLEEVE ΕΡΓΟΥ — ΜΟΝΟ ΓΙΑ SLEEVE Φ32 (ΓΙΑ ΚΆΘΕΤΟ ΣΊΔΕΡΟ Φ20 ≤ Φ20)
A25: Κωδ. | B25: Στοιχείο Κόστους Sleeve Έργου | C25: Μονάδα | D25: Τιμή | E25: Προέλευση / Τύπος | F25: Δυναμική Επεξήγηση
A26: Τ.Γ.1 | B26: Τελικό Αποτέλεσμα Sleeve (Sleeve Φ32): ((Κόστος αγοράς + Κόστος τοποθέτησης) × Profit, Waste, Overhead) | C26: € | D26: =((IF('Τεχνικοί Υπολογισμοί'!$D$30+'Τεχνικοί Υπολογισμοί'!$D$31<=0,0,IF('Τεχνικοί Υπολογισμοί'!$D$30+'Τεχνικοί Υπολογισμοί'!$D$31<=3,3/INT(ROUND(3/('Τεχνικοί Υπολογισμοί'!$D$30+'Τεχνικοί Υπολογισμοί'!$D$31),6)),CEILING('Τεχνικοί Υπολογισμοί'!$D$30+'Τεχνικοί Υπολογισμοί'!$D$31,3)))*1.34)+0.8676)*1.3 -> 2.86988 | E26: Από Τιμοκατάλογο Εταιρείας: ((Κόστος αγοράς + Κόστος τοποθέτησης) × Profit, Waste, Overhead) | F26: ="((Κόστος αγοράς + Κόστος τοποθέτησης) × Profit, Waste, Overhead) = "&ROUND($D$26,2)&" €/τεμ." -> ((Κόστος αγοράς + Κόστος τοποθέτησης) × Profit, Waste, Overhead) = 2.87 €/τεμ.
A27: Τ.Γ.2 | B27: ΣΤΡΟΓΓΥΛΕΜΕΝΟ ΤΕΛΙΚΟ ΑΠΟΤΕΛΕΣΜΑ SLEEVE (Sleeve Φ32) [ΣΤΟ ΠΛΗΣΙΕΣΤΕΡΟ 0,50 €] | C27: € | D27: =ROUND($D$26*2,0)/2 -> 3 | E27: ="ROUND("&ROUND($D$26,2)&" × 2, 0) / 2 = "&ROUND($D$27,2)&" €/τεμ." -> ROUND(2.87 × 2, 0) / 2 = 3 €/τεμ. | F27: ="Στρογγυλεμένο τελικό αποτέλεσμα ("&ROUND($D$27,2)&" €/τεμ.) — Τροφοδοτεί Φύλλο 1 (Γρ. 5) & Φύλλο 2 (2Β.5 & 2Γ)" -> Στρογγυλεμένο τελικό αποτέλεσμα (3 €/τεμ.) — Τροφοδοτεί Φύλλο 1 (Γρ. 5) & Φύλλο 2 (2Β.5 & 2Γ)
A29: ="Δ. ΣΥΝΟΔΕΙΑ ΑΣΤΥΝΟΜΙΑΣ ΓΕΩΤΡΥΠΑΝΟΥ ("&ROUND($D$31,2)&" €/km — ΑΠΟ ΣΠΥΡΟΥ ΚΥΠΡΙΑΝΟΥ 32, ΑΓΙΟ ΣΥΛΑ ΕΩΣ ΤΟ ΕΡΓΟ)" -> Δ. ΣΥΝΟΔΕΙΑ ΑΣΤΥΝΟΜΙΑΣ ΓΕΩΤΡΥΠΑΝΟΥ (8 €/km — ΑΠΟ ΣΠΥΡΟΥ ΚΥΠΡΙΑΝΟΥ 32, ΑΓΙΟ ΣΥΛΑ ΕΩΣ ΤΟ ΕΡΓΟ)
A30: Τ.Δ.1 | B30: Χιλιόμετρα Συνοδείας Αστυνομίας (Από Κεντρικά: Σπύρου Κυπριανού 32, Άγιος Συλάς μέχρι το χωριό/έργο — ΚΑΙ εντός ΚΑΙ εκτός Λεμεσού) | C30: km | D30: 28 | E30: Οδική απόσταση 28,0 km από τα Κεντρικά (Σπύρου Κυπριανού 32, Άγιος Συλάς) έως την Παρεκκλησιά (× 8,00 €/km = 224,00 €) | F30: ="Απόσταση από Σπύρου Κυπριανού 32 (Άγιος Συλάς) έως το έργο ("&ROUND($D$30,1)&" km) × "&ROUND($D$31,2)&" €/km = "&ROUND($D$32,2)&" €" -> Απόσταση από Σπύρου Κυπριανού 32 (Άγιος Συλάς) έως το έργο (28 km) × 8 €/km = 224 €
A31: Τ.Δ.2 | B31: ="Κόστος Συνοδείας Αστυνομίας ανά χιλιόμετρο ("&ROUND($D$31,2)&" €/km)" -> Κόστος Συνοδείας Αστυνομίας ανά χιλιόμετρο (8 €/km) | C31: €/km | D31: 8 | E31: Τιμοκατάλογος (γρ. 48) | F31: ="Από Τιμοκατάλογο Εταιρείας (Φύλλο 6): "&ROUND($D$31,2)&" €/km" -> Από Τιμοκατάλογο Εταιρείας (Φύλλο 6): 8 €/km
A32: Τ.Δ.3 | B32: ="Συνολικό Κόστος Συνοδείας Αστυνομίας ("&ROUND($D$30,1)&" km × "&ROUND($D$31,2)&" €/km)" -> Συνολικό Κόστος Συνοδείας Αστυνομίας (28 km × 8 €/km) | C32: € | D32: =$D$30*$D$31 -> 224 | E32: ="Αυτόματος υπολογισμός: "&ROUND($D$30,1)&" km × "&ROUND($D$31,2)&" €/km = "&ROUND($D$32,2)&" €" -> Αυτόματος υπολογισμός: 28 km × 8 €/km = 224 € | F32: Προστίθεται αυτόματα στις Μετακινήσεις (Φύλλο 1 Γρ. 1 & Φύλλο 2 2Β.1 & 2Γ)
A34: Ε. ΚΟΥΜΠΙΑ ΕΠΙΛΟΓΗΣ ΕΡΓΑΣΙΩΝ (ΠΑΤΗΣΕ «ΝΑΙ» Ή «ΟΧΙ») — ΚΕΦΑΛΟΚΟΠΗ & ΑΠΟΜΑΚΡΥΝΣΗ ΧΩΜΑΤΟΣ
A35: Κωδ. | B35: Εργασία / Ερώτηση Ευθύνης (Πάνω μας ή Πάνω τους;) | C35: Μονάδα | D35: ΚΟΥΜΠΙ / ΤΙΜΗ [ΠΑΤΗΣΕ ΕΔΩ] | E35: Προέλευση / Επιλογή | F35: Τι κάνει όταν πατήσεις ΝΑΙ ή ΟΧΙ (100% Δυναμική Σημείωση)
A36: Τ.Ε.1 | B36: ΚΟΥΜΠΙ 1 — Η Κεφαλοκοπή Πασσάλων (Pile Breaking) είναι πάνω μας; [Πάτησε το βελάκι: ΝΑΙ / ΟΧΙ] | C36: ΝΑΙ / ΟΧΙ | D36: ΝΑΙ | E36: Κουμπί Επιλογής Μηχανικού (Dropdown: ΝΑΙ ή ΟΧΙ) | F36: ="Τώρα είναι «"&$D$36&"»: Αν ΝΑΙ → χρεώνεται ("&ROUND($D$12,2)&" €/τεμ.). Αν ΟΧΙ → κρύβεται αυτόματα (0,00 €) σε όλα τα φύλλα!" -> Τώρα είναι «ΝΑΙ»: Αν ΝΑΙ → χρεώνεται (150 €/τεμ.). Αν ΟΧΙ → κρύβεται αυτόματα (0,00 €) σε όλα τα φύλλα!
A37: Τ.Ε.2 | B37: ΚΟΥΜΠΙ 2 — Η Απομάκρυνση Εκσκαπτόμενου Χώματος & Λατομικά Τέλη είναι πάνω μας; [Πάτησε το βελάκι: ΝΑΙ / ΟΧΙ] | C37: ΝΑΙ / ΟΧΙ | D37: ΝΑΙ | E37: Κουμπί Επιλογής Μηχανικού (Dropdown: ΝΑΙ ή ΟΧΙ) | F37: ="Τώρα είναι «"&$D$37&"»: Αν ΝΑΙ → χρεώνεται ("&ROUND($D$39,2)&" m³ × "&ROUND($D$38,2)&" €/m³ = "&ROUND($D$40,2)&" €). Αν ΟΧΙ → κρύβεται αυτόματα (0,00 €)!" -> Τώρα είναι «ΝΑΙ»: Αν ΝΑΙ → χρεώνεται (103.67 m³ × 15 €/m³ = 1555.09 €). Αν ΟΧΙ → κρύβεται αυτόματα (0,00 €)!
A38: Τ.Ε.3 | B38: Τιμή Απομάκρυνσης Εκσκαπτόμενου Χώματος & Λατομικών Τελών (ανά m³ εκσκαφής) | C38: € | D38: 15 | E38: Τιμοκατάλογος (γρ. 49) | F38: ="Πολλαπλασιάζεται με τα κυβικά που σκάβουμε ("&ROUND($D$39,2)&" m³ × "&ROUND($D$38,2)&" €/m³) όταν το Κουμπί 2 (Τ.Ε.2) είναι «ΝΑΙ»" -> Πολλαπλασιάζεται με τα κυβικά που σκάβουμε (103.67 m³ × 15 €/m³) όταν το Κουμπί 2 (Τ.Ε.2) είναι «ΝΑΙ»
A39: Τ.Ε.4 | B39: Συνολικά Κυβικά Εκσκαπτόμενου Χώματος Έργου (V_exc από Τεχνικούς Υπολογισμούς) | C39: m³ | D39: ='Τεχνικοί Υπολογισμοί'!$F$115 -> 103.67256 | E39: Αυτόματος υπολογισμός: Άθροισμα (π × Διάμετρος² / 4 × Βάθος Τρυπήματος) όλων των πασσάλων | F39: ="Συνολικά κυβικά χώματος που βγαίνουν από τις τρύπες = "&ROUND($D$39,2)&" m³" -> Συνολικά κυβικά χώματος που βγαίνουν από τις τρύπες = 103.67 m³
A40: Τ.Ε.5 | B40: Συνολικό Κόστος Απομάκρυνσης Χώματος & Λατομικών Τελών (όταν Κουμπί 2 = ΝΑΙ) | C40: € | D40: =IF($D$37="ΝΑΙ",'Τεχνικοί Υπολογισμοί'!$F$115*$D$38,0) -> 1555.0884 | E40: ="IF(Κουμπί_2 = ΝΑΙ, "&ROUND($D$39,2)&" m³ × "&ROUND($D$38,2)&" €/m³, 0) = "&ROUND($D$40,2)&" €" -> IF(Κουμπί_2 = ΝΑΙ, 103.67 m³ × 15 €/m³, 0) = 1555.09 € | F40: Τροφοδοτεί Φύλλο 1 (Γρ. 7) & Φύλλο 2 (2Β.7 & 2Γ)
A42: ΓΕΝΙΚΟ ΣΥΝΟΛΟ ΠΡΟΣΦΟΡΑΣ (ΧΩΡΙΣ Φ.Π.Α.): | D42: ='Οικονομική Προσφορά'!$F$16 -> 55469.195 | E42: ="Μέσο Κόστος ανά Πάσσαλο: "&ROUND('Οικονομική Προσφορά'!$F$16/'Τεχνικοί Υπολογισμοί'!$D$14,2)&" € ("&'Τεχνικοί Υπολογισμοί'!$D$14&" πάσσαλοι)" -> Μέσο Κόστος ανά Πάσσαλο: 1584.83 € (35 πάσσαλοι)
