Workbook

Sheet 1_Στοιχεία_Μελέτης_&_Ποσότητες
A1: ΕΡΓΟ: BERLIN WALL & ΑΓΚΥΡΩΣΕΙΣ — ΣΤΟΙΧΕΙΑ ΜΕΛΕΤΗΣ & ΦΥΣΙΚΕΣ ΠΟΣΟΤΗΤΕΣ (ΧΩΡΙΣ ΕΥΡΩ)
A2: ΧΩΡΙΣΜΕΝΟ ΣΕ 2 ΜΕΓΑΛΑ ΚΕΦΑΛΑΙΑ: [ΚΕΦΑΛΑΙΟ Α] = ΜΟΝΟ ΣΤΟΙΧΕΙΑ ΜΕΛΕΤΗΣ | [ΚΕΦΑΛΑΙΟ Β] = ΟΛΟΙ ΟΙ ΥΠΟΛΟΓΙΣΜΟΙ
A4: 🏛️ ΚΕΦΑΛΑΙΟ Α: ΜΟΝΟ ΣΤΟΙΧΕΙΑ ΠΟΥ ΔΙΑΒΑΣΤΗΚΑΝ ΑΠΟ ΤΗ ΜΕΛΕΤΗ (RAW INPUTS)
A5: Α.1 Τοποθεσία Εργοταξίου, Έδρα & Σειρές Αγκυρώσεων ανά Ζώνη
A6: Έδρα Εταιρείας (Αφετηρία) | B6: Άγιος Συλάς, Σπύρου Κυπριανού 32, Λεμεσός | C6: - | D6: Σταθερή βάση εκκίνησης συνεργείων & μηχανημάτων
A7: Τοποθεσία Εργοταξίου | B7: Λεμεσός | C7: - | D7: Τοποθεσία έργου από μελέτη
A8: Χιλιομετρική Απόσταση από Έδρα | B8: 12 | C8: km | D8: Απόσταση σε km από Άγιο Συλά
A9: Πλήθος Οριζόντιων Σειρών Αγκυρώσεων Μελέτης | B9: 2 | C9: σειρές | D9: Αριθμός οριζόντιων επιπέδων/σειρών αγκυρώσεων
A11: Α.2 Γεωμετρία Μετώπου Εκσκαφής (Berlin Wall)
A12: Μήκος Τμήματος 1 Μετώπου (L1) | B12: 15 | C12: m | D12: Μήκος τοίχου τμήματος 1
A13: Μήκος Τμήματος 2 Μετώπου (L2) | B13: 15 | C13: m | D13: Μήκος τοίχου τμήματος 2
A14: Ελεύθερο Ύψος Εκσκαφής Μετώπου (H_exc) | B14: 8 | C14: m | D14: Καθαρό ύψος εκσκαφής που συγκρατείται από το Berlin Wall
A16: Α.3 Σχάρες & Εκτοξευόμενο Σκυρόδεμα (Shotcrete)
A17: Τύπος Χάλυβα Σχάρας | B17: B500A Δομικό Πλέγμα | C17: - | D17: Πλέγμα οπλισμού εκτοξευόμενου
A18: Διάμετρος Ράβδων Σχάρας (mm) | B18: 10 | C18: mm | D18: Διάμετρος ράβδων πλέγματος (π.χ. Y10)
A19: Οριζόντιο Βήμα Ράβδων Σχάρας (s_horiz) | B19: 150 | C19: mm | D19: Βήμα οριζόντιων ράβδων σε mm
A20: Κάθετο Βήμα Ράβδων Σχάρας (s_vert) | B20: 150 | C20: mm | D20: Βήμα κάθετων ράβδων σε mm
A21: Κατηγορία Σκυροδέματος Shotcrete | B21: C30/37 | C21: - | D21: Κατηγορία σκυροδέματος μελέτης
A22: Ονομαστικό Πάχος Shotcrete Μελέτης | B22: 0.12 | C22: m | D22: 120 mm ονομαστικό πάχος εκτοξευόμενου
A23: Πάγια Απώλεια / Αναπήδηση Εταιρείας | B23: 0.05 | C23: m | D23: +5 cm πάγια προσαύξηση εταιρείας (χρεώνεται στα €/m³)
A25: Α.4 H-Beams (Νέφκες / Soldier Piles: Οπές, Χάλυβας, Λάμες, Κουγκρί, Γωνιές)
A26: Πλήθος Οπών / Νεφκών (N_holes) | B26: 20 | C26: οπές | D26: Αριθμός πασσάλων/νεφκών μετώπου
A27: Διάμετρος Οπής Διάτρησης Μεγάλου Τρυπανιού (D) | B27: 0.8 | C27: m | D27: 800 mm προεπιλογή αν δεν δίνεται στο σχέδιο
A28: Βάθος Πάκτωσης Νέφκας κάτω από Εκσκαφή (H_embed) | B28: 4 | C28: m | D28: Βάθος έμπηξης/πάκτωσης στο έδαφος
A29: Τύπος Χαλύβδινης Διατομής Νέφκας | B29: HEB 200 | C29: - | D29: Από σχέδιο (βλ. Φύλλο 3: 61.3 kg/m)
A30: Πλήθος Προφίλ ανά Οπή | B30: 1 | C30: προφίλ/οπή | D30: 1 για HEB/HEA, 2 για διπλό UPN
A31: Θεωρητικό Βάρος Προφίλ Νέφκας ανά Μέτρο | B31: 61.3 | C31: kg / m | D31: Βάρος διατομής από βιβλιοθήκη (Φύλλο 3)
A32: Κατακόρυφο Βήμα Λαμών ανά Νέφκα (s_plate) | B32: 2 | C32: m | D32: Απόσταση λαμών ενίσχυσης κατά ύψος
A33: Πλάτος Λάμας Σύνδεσης (W_plate) | B33: 200 | C33: mm | D33: Πλάτος λάμας σε mm
A34: Μήκος Λάμας Σύνδεσης (L_plate) | B34: 200 | C34: mm | D34: Μήκος λάμας σε mm
A35: Πάχος Λάμας Σύνδεσης (t_plate) | B35: 12 | C35: mm | D35: Πάχος λάμας σε mm
A36: Ύπαρξη Γωνιών Στήριξης στο Σχέδιο (L-Angles) | B36: ΝΑΙ | C36: - | D36: ΝΑΙ ή ΟΧΙ (μόνο αν ζητείται στο σχέδιο)
A37: Διατομή Γωνιών Στήριξης | B37: L 70x70x6 | C37: - | D37: Διατομή γωνίας (2 γωνιές ανά οπή στο ελεύθερο ύψος)
A38: Θεωρητικό Βάρος Γωνίας ανά Μέτρο | B38: 6.38 | C38: kg / m | D38: Βάρος L70x70x6 σε kg/m
A40: Α.5 Αγκυρώσεις (Prestressed Tieback Anchors: Γραμμές, Βάθη, Grout, Τένοντες & Κεφαλές)
A41: Πλήθος Αγκυρώσεων Σειράς 1 | B41: 15 | C41: τεμ. | D41: Αριθμός αγκυρώσεων στην 1η οριζόντια γραμμή
A42: Μήκος / Βάθος Διάτρησης Σειράς 1 | B42: 15 | C42: m | D42: Βάθος αγκυρώσεων 1ης σειράς στο σχέδιο
A43: Πλήθος Αγκυρώσεων Σειράς 2 | B43: 15 | C43: τεμ. | D43: Αριθμός αγκυρώσεων στη 2η οριζόντια γραμμή
A44: Μήκος / Βάθος Διάτρησης Σειράς 2 | B44: 12 | C44: m | D44: Βάθος αγκυρώσεων 2ης σειράς στο σχέδιο
A45: Πλήθος Τενόντων (Strands) ανά Οπή Αγκύρωσης | B45: 4 | C45: τεμ. / οπή | D45: Αριθμός συρματόσχοινων 0.6" ανά αγκύρωση
...

Sheet 2_Υπολογισμοί_&_Κοστολόγηση
A1: ΕΡΓΟ: BERLIN WALL & ΑΓΚΥΡΩΣΕΙΣ — ΥΠΟΛΟΓΙΣΜΟΙ ΕΥΡΩ (€) & ΟΙΚΟΝΟΜΙΚΗ ΠΡΟΣΦΟΡΑ
A2: Οι τιμές μονάδας περιλαμβάνουν ήδη γενικά έξοδα, απρόβλεπτα & εργολαβικό όφελος | [ΚΙΤΡΙΝΟ #FFF2CC] = Τιμές Μονάδας
A4: Περιγραφή Εργασίας / Υλικού | B4: Ποσότητα | C4: Μονάδα | D4: Τιμή Μονάδας (€) | E4: Συνολικό Κόστος (€) | F4: Πηγή Ποσότητας / Τεχνικός Κανόνας
A5: ΠΥΛΩΝΑΣ 1: ΜΕΤΑΚΙΝΗΣΕΙΣ & ΣΤΡΑΤΕΣ (3 ΕΙΔΗ)
A6: Μετακίνηση Μεγάλου Τρυπανιού (Piling Rig) | B6: ='1_Στοιχεία_Μελέτης_&_Ποσότητες'!B54 | C6: στράτες | D6: 1500 | E6: =B6*D6 | F6: Βάση Λεμεσός (0-40km: 1500€, 40-80km: +500€, >80km: +1500€)
A7: Μετακινήσεις Εξοπλισμού Αγκυρώσεων | B7: ='1_Στοιχεία_Μελέτης_&_Ποσότητες'!B55 | C7: στράτες | D7: 300 | E7: =B7*D7 | F7: Από Φύλλο 1 (1 στράτα ανά οριζόντια σειρά αγκυρώσεων = 2 στράτες)
A8: Μετακινήσεις Συνεργείου & Αντλίας Shotcrete | B8: ='1_Στοιχεία_Μελέτης_&_Ποσότητες'!B56 | C8: στράτες | D8: 200 | E8: =B8*D8 | F8: Από Φύλλο 1 (Σειρές αγκυρώσεων + 1 = 3 στράτες)
A9: ΣΥΝΟΛΟ ΠΥΛΩΝΑ 1 (ΜΕΤΑΚΙΝΗΣΕΙΣ) | E9: =SUM(E6:E8)
A11: ΠΥΛΩΝΑΣ 2: ΣΧΑΡΕΣ & ΕΚΤΟΞΕΥΟΜΕΝΟ ΣΚΥΡΟΔΕΜΑ (SHOTCRETE)
A12: ="Αγορά Χάλυβα Σχάρας (Y" & '1_Στοιχεία_Μελέτης_&_Ποσότητες'!B18 & " " & '1_Στοιχεία_Μελέτης_&_Ποσότητες'!B17 & ")" | B12: ='1_Στοιχεία_Μελέτης_&_Ποσότητες'!B63 | C12: kg | D12: 2.5 | E12: =B12*D12 | F12: ="Από Φύλλο 1 (" & TEXT(B12, "#,##0.00") & " kg) × 2.50 €/kg"
A13: Τοποθέτηση Σχάρας / Εργατικά Μετώπου | B13: ='1_Στοιχεία_Μελέτης_&_Ποσότητες'!B59 | C13: m² | D13: 15 | E13: =B13*D13 | F13: ="Από Φύλλο 1 (" & TEXT(B13, "#,##0.00") & " m²) × 15.00 €/m²"
A14: ="Αγορά Σκυροδέματος Shotcrete (" & '1_Στοιχεία_Μελέτης_&_Ποσότητες'!B21 & ")" | B14: ='1_Στοιχεία_Μελέτης_&_Ποσότητες'!B66 | C14: m³ | D14: 90 | E14: =B14*D14 | F14: Σταθερή τιμή αγοράς C30/37 (90 €/m³)
A15: Τοποθέτηση / Εκτόξευση / Αντλία (με προσαύξηση απώλειας) | B15: ='1_Στοιχεία_Μελέτης_&_Ποσότητες'!B66 | C15: m³ | D15: =ROUND((IF(B14>7, 200, 250)*(1+'1_Στοιχεία_Μελέτης_&_Ποσότητες'!B65))-90, 2) | E15: =B15*D15 | F15: ="Βάση " & IF(B14>7,200,250) & "€ × (1+" & TEXT('1_Στοιχεία_Μελέτης_&_Ποσότητες'!B65, "0.0%") & " απώλεια) - 90€ αγορά"
A16: ΣΥΝΟΛΟ ΠΥΛΩΝΑ 2 (ΣΧΑΡΕΣ & SHOTCRETE) | E16: =SUM(E12:E15)
A18: ΠΥΛΩΝΑΣ 3: H-BEAMS (ΝΕΦΚΕΣ / SOLDIER PILES — 5 ΕΡΓΑΣΙΕΣ/ΥΛΙΚΑ)
A19: ="3.1 Διάτρηση Μεγάλου Τρυπανιού (Ø" & TEXT('1_Στοιχεία_Μελέτης_&_Ποσότητες'!B27*1000, "0") & " mm)" | B19: ='1_Στοιχεία_Μελέτης_&_Ποσότητες'!B69 | C19: m | D19: 75 | E19: =B19*D19 | F19: Εύρος 65 - 90 €/m (προεπιλογή 75.00 €/m)
A20: ="3.2 Νέφκες Χάλυβα (" & '1_Στοιχεία_Μελέτης_&_Ποσότητες'!B29 & " - Αγορά + Επεξεργασία)" | B20: ='1_Στοιχεία_Μελέτης_&_Ποσότητες'!B72 | C20: kg | D20: 1.4 | E20: =B20*D20 | F20: 1.00 €/kg αγορά + 0.40 €/kg επεξεργασία = 1.40 €/kg
A21: ="3.3 Λάμες Σύνδεσης/Ενίσχυσης (" & '1_Στοιχεία_Μελέτης_&_Ποσότητες'!B33 & "×" & '1_Στοιχεία_Μελέτης_&_Ποσότητες'!B34 & "×" & '1_Στοιχεία_Μελέτης_&_Ποσότητες'!B35 & " mm)" | B21: ='1_Στοιχεία_Μελέτης_&_Ποσότητες'!B76 | C21: kg | D21: 1.6 | E21: =B21*D21 | F21: 1.00 €/kg αγορά + 0.60 €/kg τοποθέτηση = 1.60 €/kg
A22: 3.4 Κουγκρί Πάκτωσης Οπών Νέφκας | B22: ='1_Στοιχεία_Μελέτης_&_Ποσότητες'!B77 | C22: m³ | D22: 120 | E22: =B22*D22 | F22: 120.00 €/m³ (Διακριτό χρώμα για επιβεβαίωση/αλλαγή)
A23: ="3.5 Γωνιές Στήριξης (" & '1_Στοιχεία_Μελέτης_&_Ποσότητες'!B37 & " - αν ζητούνται)" | B23: ='1_Στοιχεία_Μελέτης_&_Ποσότητες'!B79 | C23: kg | D23: 1.6 | E23: =B23*D23 | F23: 1.00 €/kg αγορά + 0.60 €/kg επεξεργασία = 1.60 €/kg
A24: ΣΥΝΟΛΟ ΠΥΛΩΝΑ 3 (H-BEAMS / ΝΕΦΚΕΣ) | E24: =SUM(E19:E23)
A26: ΠΥΛΩΝΑΣ 4: ΑΓΚΥΡΩΣΕΙΣ (PRESTRESSED TIEBACK ANCHORS — 5 ΕΡΓΑΣΙΕΣ/ΥΛΙΚΑ)
A27: 4.1 Διάτρηση / Τρύπημα Αγκυρώσεων | B27: ='1_Στοιχεία_Μελέτης_&_Ποσότητες'!B84 | C27: m | D27: 30 | E27: =B27*D27 | F27: Εύρος 25 - 35 €/m (προεπιλογή 30.00 €/m)
A28: 4.2 Grout Τσιμεντένεμα Αγκυρώσεων (με απώλεια 1.20) | B28: ='1_Στοιχεία_Μελέτης_&_Ποσότητες'!B86 | C28: m³ | D28: 500 | E28: =B28*D28 | F28: 500.00 €/m³ grout πλήρωσης οπής
A29: 4.3 Τένοντες Προέντασης (Strands 0.6" - 1.10 kg/m) | B29: ='1_Στοιχεία_Μελέτης_&_Ποσότητες'!B87 | C29: m | D29: 2.28 | E29: =B29*D29 | F29: 2.28 €/m τρέχον τένοντα (συμπεριλαμβάνει +1.0m)
A30: 4.4 Προένταση Αγκυρώσεων (Stressing & Lock-off) | B30: ='1_Στοιχεία_Μελέτης_&_Ποσότητες'!B81 | C30: τεμ. | D30: 18 | E30: =B30*D30 | F30: 18.00 € ανά οπή / αγκύρωση
A31: 4.5 Κεφαλή Αγκύρωσης (Anchor Head, Wedges, Plate) | B31: ='1_Στοιχεία_Μελέτης_&_Ποσότητες'!B81 | C31: τεμ. | D31: 55 | E31: =B31*D31 | F31: 55.00 € ανά οπή / αγκύρωση πλήρες σετ
A32: ΣΥΝΟΛΟ ΠΥΛΩΝΑ 4 (ΑΓΚΥΡΩΣΕΙΣ) | E32: =SUM(E27:E31)
A34: ΤΕΛΙΚΑ ΣΥΝΟΛΑ ΠΡΟΣΦΟΡΑΣ (ΓΕΝΙΚΑ ΕΞΟΔΑ & ΚΕΡΔΟΣ ΕΝΣΩΜΑΤΩΜΕΝΑ ΣΤΙΣ ΤΙΜΕΣ)
A35: ΚΑΘΑΡΟ ΣΥΝΟΛΟ ΠΡΟΣΦΟΡΑΣ (ΠΡΟ Φ.Π.Α.) | E35: =E9+E16+E24+E32 | F35: Άθροισμα 4 Πυλώνων (Περιλαμβάνει Γενικά Έξοδα & Όφελος)
A36: Φ.Π.Α. (19%) | E36: =ROUND(E35*0.19, 2) | F36: Νόμιμος Φ.Π.Α. Κύπρου (19%)
A37: ΤΕΛΙΚΟ ΠΛΗΡΩΤΕΟ ΠΟΣΟ (ΜΕ Φ.Π.Α.) | E37: =E35+E36 | F37: Τελικό πληρωτέο ποσό έργου
A39: ΒΑΣΙΚΟΙ ΔΕΙΚΤΕΣ ΚΟΣΤΟΥΣ & VALUE ENGINEERING (KPIs)
A40: KPI 1: Συνολικό Κόστος ανά m² Μετώπου Εκσκαφής | E40: =ROUND(E35/'1_Στοιχεία_Μελέτης_&_Ποσότητες'!B59, 2) | F40: ="Καθαρό σύνολο / " & '1_Στοιχεία_Μελέτης_&_Ποσότητες'!B59 & " m²"
A41: KPI 2: Συνολικό Κόστος ανά Αγκύρωση (Πλήρες Σύστημα Αγκύρωσης) | E41: =ROUND(E32/'1_Στοιχεία_Μελέτης_&_Ποσότητες'!B81, 2) | F41: ="Σύνολο Πυλώνα 4 / " & '1_Στοιχεία_Μελέτης_&_Ποσότητες'!B81 & " αγκυρώσεις"
A42: KPI 3: Συνολικό Κόστος Σχαρών & Shotcrete ανά m² Μετώπου | E42: =ROUND(E16/'1_Στοιχεία_Μελέτης_&_Ποσότητες'!B59, 2) | F42: ="Σύνολο Πυλώνα 2 / " & '1_Στοιχεία_Μελέτης_&_Ποσότητες'!B59 & " m²"
A43: KPI 4: Συνολικό Κόστος H-Beams ανά Πάσσαλο / Οπή | E43: =ROUND(E24/'1_Στοιχεία_Μελέτης_&_Ποσότητες'!B26, 2) | F43: ="Σύνολο Πυλώνα 3 / " & '1_Στοιχεία_Μελέτης_&_Ποσότητες'!B26 & " οπές"

Sheet 3_Πίνακες_Διατομών_Χάλυβα
A1: ΒΙΒΛΙΟΘΗΚΗ ΔΙΑΤΟΜΩΝ ΧΑΛΥΒΑ (EUROPEAN STRUCTURAL STEEL PROFILES)
A2: Τεχνικά χαρακτηριστικά & βάρη ανά μέτρο για διατομές HEA, HEB, UPN & Γωνιών (L)
A4: 1. ΔΙΑΤΟΜΕΣ HEA (Ευρωπαϊκά Πλατύπελμα Ελαφρού Τύπου)
A5: Ονομασία Διατομής | B5: Ύψος h (mm) | C5: Πλάτος b (mm) | D5: Πάχος tw (mm) | E5: Πάχος tf (mm) | F5: Διατομή A (cm²) | G5: Βάρος (kg / m)
A6: HEA 140 | B6: 133 | C6: 140 | D6: 5.5 | E6: 8.5 | F6: 31.4 | G6: 24.7
A7: HEA 160 | B7: 152 | C7: 160 | D7: 6 | E7: 9 | F7: 38.8 | G7: 30.4
A8: HEA 180 | B8: 171 | C8: 180 | D8: 6 | E8: 9.5 | F8: 45.3 | G8: 35.5
A9: HEA 200 | B9: 190 | C9: 200 | D9: 6.5 | E9: 10 | F9: 53.8 | G9: 42.3
A10: HEA 220 | B10: 210 | C10: 220 | D10: 7 | E10: 11 | F10: 64.3 | G10: 50.5
A11: HEA 240 | B11: 230 | C11: 240 | D11: 7.5 | E11: 12 | F11: 76.8 | G11: 60.3
A12: HEA 260 | B12: 250 | C12: 260 | D12: 7.5 | E12: 12.5 | F12: 86.8 | G12: 68.2
A13: HEA 280 | B13: 270 | C13: 280 | D13: 8 | E13: 13 | F13: 97.3 | G13: 76.4
A14: HEA 300 | B14: 290 | C14: 300 | D14: 8.5 | E14: 14 | F14: 112.5 | G14: 88.3
A16: 2. ΔΙΑΤΟΜΕΣ HEB (Ευρωπαϊκά Πλατύπελμα Κανονικού Τύπου)
A17: Ονομασία Διατομής | B17: Ύψος h (mm) | C17: Πλάτος b (mm) | D17: Πάχος tw (mm) | E17: Πάχος tf (mm) | F17: Διατομή A (cm²) | G17: Βάρος (kg / m)
A18: HEB 140 | B18: 140 | C18: 140 | D18: 7 | E18: 12 | F18: 43 | G18: 33.7
A19: HEB 160 | B19: 160 | C19: 160 | D19: 8 | E19: 13 | F19: 54.3 | G19: 42.6
A20: HEB 180 | B20: 180 | C20: 180 | D20: 8.5 | E20: 14 | F20: 65.3 | G20: 51.2
A21: HEB 200 | B21: 200 | C21: 200 | D21: 9 | E21: 15 | F21: 78.1 | G21: 61.3
A22: HEB 220 | B22: 220 | C22: 220 | D22: 9.5 | E22: 16 | F22: 91 | G22: 71.5
A23: HEB 240 | B23: 240 | C23: 240 | D23: 10 | E23: 17 | F23: 106 | G23: 83.2
A24: HEB 260 | B24: 260 | C24: 260 | D24: 10 | E24: 17.5 | F24: 118.4 | G24: 93
A25: HEB 280 | B25: 280 | C25: 280 | D25: 10.5 | E25: 18 | F25: 131.4 | G25: 103
A26: HEB 300 | B26: 300 | C26: 300 | D26: 11 | E26: 19 | F26: 149.1 | G26: 117
A28: 3. ΔΙΑΤΟΜΕΣ UPN (Ευρωπαϊκά Κοίλα Προφίλ U)
A29: Ονομασία Διατομής | B29: Ύψος h (mm) | C29: Πλάτος b (mm) | D29: Πάχος tw (mm) | E29: Πάχος tf (mm) | F29: Διατομή A (cm²) | G29: Βάρος (kg / m)
A30: UPN 140 | B30: 140 | C30: 60 | D30: 7 | E30: 10 | F30: 20.4 | G30: 16
A31: UPN 160 | B31: 160 | C31: 65 | D31: 7.5 | E31: 10.5 | F31: 24 | G31: 18.8
A32: UPN 180 | B32: 180 | C32: 70 | D32: 8 | E32: 11 | F32: 28 | G32: 22
A33: UPN 200 | B33: 200 | C33: 75 | D33: 8.5 | E33: 11.5 | F33: 32.2 | G33: 25.3
A34: UPN 220 | B34: 220 | C34: 80 | D34: 9 | E34: 12.5 | F34: 37.4 | G34: 29.4
A35: UPN 240 | B35: 240 | C35: 85 | D35: 9.5 | E35: 13 | F35: 42.3 | G35: 33.2
A36: UPN 260 | B36: 260 | C36: 90 | D36: 10 | E36: 14 | F36: 48.3 | G36: 37.9
A37: UPN 280 | B37: 280 | C37: 95 | D37: 10 | E37: 15 | F37: 53.3 | G37: 41.8
A38: UPN 300 | B38: 300 | C38: 100 | D38: 10 | E38: 16 | F38: 58.8 | G38: 46.2
A40: 4. ΙΣΟΣΚΕΛΕΙΣ ΓΩΝΙΕΣ (Equal Angles L)
A41: Ονομασία Διατομής | B41: Ύψος h (mm) | C41: Πλάτος b (mm) | D41: Πάχος tw (mm) | E41: Πάχος tf (mm) | F41: Διατομή A (cm²) | G41: Βάρος (kg / m)
A42: L 50x50x5 | B42: 50 | C42: 50 | D42: 5 | E42: 5 | F42: 4.8 | G42: 3.77
A43: L 60x60x6 | B43: 60 | C43: 60 | D43: 6 | E43: 6 | F43: 6.91 | G43: 5.42
A44: L 70x70x6 | B44: 70 | C44: 70 | D44: 6 | E44: 6 | F44: 8.13 | G44: 6.38
...
