Workbook

Sheet 1_Τιμές_Εταιρείας
A1: ΚΕΝΤΡΙΚΟΣ ΤΙΜΟΚΑΤΑΛΟΓΟΣ ΕΤΑΙΡΕΙΑΣ — BERLIN WALL & ΑΓΚΥΡΩΣΕΙΣ
A2: ΕΔΡΑ: ΑΓΙΟΣ ΣΥΛΑΣ, ΣΠΥΡΟΥ ΚΥΠΡΙΑΝΟΥ 32, ΛΕΜΕΣΟΣ | ΚΙΤΡΙΝΟ = Τιμές μονάδας αγοράς | ΛΕΥΚΟ = Φυσικές σταθερές & τύποι
A4: Α/Α | B4: Πυλώνας Κόστους | C4: Είδος Υλικού / Εργασίας | D4: Τιμή Μονάδας (€) [ΚΙΤΡΙΝΟ = ΑΛΛΑΖΕΙ] | E4: Μονάδα | F4: Κανόνας, Επεξήγηση & Χρήση στην Κοστολόγηση
A5: 1 | B5: 1. Μετακινήσεις | C5: Στράτα Μεγάλου Τρυπανιού (Piling Rig) — Βασική (Λεμεσός / 0–40 km) | D5: 1500 | E5: € / στράτα | F5: Βάση: Άγιος Συλάς. Συνήθως 1 στράτα ανά έργο.
A6: 2 | B6: 1. Μετακινήσεις | C6: Επιβάρυνση Μεγάλου Τρυπανιού για 40–80 km | D6: 500 | E6: € / στράτα | F6: Προστίθεται στη βασική για αποστάσεις 40–80 km (Σύνολο 2,000 €).
A7: 3 | B7: 1. Μετακινήσεις | C7: Επιβάρυνση Μεγάλου Τρυπανιού για >80 km (π.χ. Λευκωσία) | D7: 1500 | E7: € / στράτα | F7: Προστίθεται στη βασική για αποστάσεις άνω των 80 km (Σύνολο 3,000 €).
A8: 4 | B8: 1. Μετακινήσεις | C8: Στράτα Εξοπλισμού Αγκυρώσεων — Βασική (Λεμεσός / 0–40 km) | D8: 300 | E8: € / στράτα | F8: Στράτες = Άθροισμα οριζόντιων σειρών αγκυρώσεων ανά ζώνη.
A9: 5 | B9: 1. Μετακινήσεις | C9: Στράτα Shotcrete — Βασική (Λεμεσός / 0–40 km) | D9: 200 | E9: € / στράτα | F9: Στράτες = Σειρές αγκυρώσεων + 1 στράτα.
A10: 6 | B10: 1. Μετακινήσεις | C10: Επιβάρυνση Αγκυρώσεων & Shotcrete ανά επιπλέον 40 km | D10: 50 | E10: € / στράτα | F10: +50 € ανά στράτα για κάθε 40 km έξω από τη βασική ακτίνα 40 km.
A11: 7 | B11: 2. Σχάρες & Shotcrete | C11: Σίδηρος Σχάρας Μετώπου — Αγορά Χάλυβα B500C | D11: 2.5 | E11: € / kg | F11: Υπολογίζεται με βάση τα kg/m² της σχάρας (π.χ. Q188 = 3.02 kg/m²).
A12: 8 | B12: 2. Σχάρες & Shotcrete | C12: Σχάρα Μετώπου — Τοποθέτηση / Εργατικά | D12: 15 | E12: € / m² | F12: Ενιαία τιμή τοποθέτησης ανά m² όψης εκσκαφής.
A13: 9 | B13: 2. Σχάρες & Shotcrete | C13: Σκυρόδεμα Shotcrete C30/37 — Αγορά Κουγκριού | D13: 90 | E13: € / m³ | F13: Ονομαστικός όγκος μελέτης = Εμβαδόν × Ονομαστικό πάχος (m).
A14: 10 | B14: 2. Σχάρες & Shotcrete | C14: Εκτοξευόμενο — Εφαρμογή/Εκτόξευση (Βάση > 7 m³) | D14: 200 | E14: € / m³ | F14: Βάση υπολογισμού: [(200 × (1 + %απώλειας)) - 90] €/m³.
A15: 11 | B15: 2. Σχάρες & Shotcrete | C15: Εκτοξευόμενο — Εφαρμογή/Εκτόξευση (Βάση ≤ 7 m³) | D15: 250 | E15: € / m³ | F15: Εφαρμόζεται σε μικρές ποσότητες κάτω των 7 m³.
A16: 12 | B16: 3. H-Beams (Νέφκες) | C16: Διάτρηση Μεγάλου Τρυπανιού (Ø800 mm προεπιλογή) | D16: 75 | E16: € / m | F16: Εύρος τιμών: 65–90 €/m. Μέτρα = Πλήθος οπών × (H_exc + H_embed).
... A27: 23 | B27: 4. Αγκυρώσεις | C27: Κεφαλή Αγκύρωσης (Anchor Head, Wedges, Bearing Plate) | D27: 55 | E27: € / τεμ | F27: Πλήρες σετ κεφαλής αγκύρωσης, σφηνών και πλάκας ανά οπή.
A29: Β. ΦΥΣΙΚΕΣ ΣΤΑΘΕΡΕΣ & ΠΑΓΙΟΙ ΚΑΝΟΝΕΣ (ΛΕΥΚΟ — ΔΕΝ ΑΛΛΑΖΟΥΝ ΠΟΤΕ)
A30: — | B30: Σταθερά | C30: Πυκνότητα Χάλυβα (ρ) | D30: 7850 | E30: kg / m³ | F30: Φυσική σταθερά για υπολογισμό βάρους προφίλ, πλακών, λαμών.
A31: — | B31: Σταθερά | C31: Πάγια Απώλεια Πάχους Shotcrete | D31: 0.05 | E31: m | F31: +5 cm πάγια προσαύξηση εταιρείας για αναπήδηση / υπερκατανάλωση.
A32: — | B32: Σταθερά | C32: Βασική Ακτίνα Έδρας (Λεμεσός) | D32: 40 | E32: km | F32: Ακτίνα 0–40 km από Άγιο Συλά, Σπύρου Κυπριανού 32, Λεμεσό.
A33: — | B33: Σταθερά | C33: Διάμετρος Οπής Grout Αγκυρώσεων | D33: 0.12 | E33: m | F33: Τυπική οπή διάτρησης αγκυρώσεων 120 mm.
A34: — | B34: Σταθερά | C34: Συντελεστής Υπερκατανάλωσης Grout | D34: 1.2 | E34: συντελεστής | F34: +20% υπερκατανάλωση τσιμεντενέματος στο έδαφος.
A35: — | B35: Σταθερά | C35: Προεπιλεγμένη Διάμετρος Οπής H-Beams | D35: 0.8 | E35: m | F35: Προεπιλογή Ø800 mm εάν δεν ορίζεται διαφορετικά στη μελέτη.
A36: — | B36: Σταθερά | C36: Επιπλέον Μήκος Τενόντων για Τάνυση | D36: 1 | E36: m | F36: +1.0 m ανά τένοντα έξω από το μέτωπο για την κεφαλή και το γρύλο.

Sheet 2_Βάρη_Διατομών_Χάλυβα
A1: ΠΙΝΑΚΕΣ ΔΙΑΤΟΜΩΝ & ΘΕΩΡΗΤΙΚΩΝ ΒΑΡΩΝ ΧΑΛΥΒΑ (EUROCODES)
A2: Περιλαμβάνει Ευρωπαϊκά Πλατύπελμα HEA, HEB, UPN, Ισοσκελείς Γωνίες L και Ράβδους Οπλισμού Y
A4: 1. ΡΑΒΔΟΙ ΟΠΛΙΣΜΟΥ B500C (ΣΧΑΡΕΣ & ΟΠΛΙΣΜΟΙ)
A5: Ονομασία | B5: Διάμετρος (mm) | C5: Θεωρητικό Βάρος (kg/m) | D5: Τιμή Αγοράς (€/kg) | E5: Κόστος ανά Μέτρο (€/m) | F5: Συνήθης Χρήση
A6: Y8 | B6: 8 | C6: =ROUND(PI()*(B6/1000)^2/4*'1_Τιμές_Εταιρείας'!$D$30, 3) -> 0.395 | D6: ='1_Τιμές_Εταιρείας'!$D$11 -> 2.5 | E6: =ROUND(C6*D6, 2) -> 0.99 | F6: Ελαφριές σχάρες μετώπου
A7: Y10 | B7: 10 | C7: =ROUND(PI()*(B7/1000)^2/4*'1_Τιμές_Εταιρείας'!$D$30, 3) -> 0.617 | D7: ='1_Τιμές_Εταιρείας'!$D$11 -> 2.5 | E7: =ROUND(C7*D7, 2) -> 1.54 | F7: Τυπική σχάρα shotcrete (π.χ. Y10/150)
A8: Y12 | B8: 12 | C8: =ROUND(PI()*(B8/1000)^2/4*'1_Τιμές_Εταιρείας'!$D$30, 3) -> 0.888 | D8: ='1_Τιμές_Εταιρείας'!$D$11 -> 2.5 | E8: =ROUND(C8*D8, 2) -> 2.22 | F8: Ενισχυμένη σχάρα shotcrete
A9: Y14 | B9: 14 | C9: =ROUND(PI()*(B9/1000)^2/4*'1_Τιμές_Εταιρείας'!$D$30, 3) -> 1.208 | D9: ='1_Τιμές_Εταιρείας'!$D$11 -> 2.5 | E9: =ROUND(C9*D9, 2) -> 3.02 | F9: Σχάρες βαρέως τύπου
A10: Y16 | B10: 16 | C10: =ROUND(PI()*(B10/1000)^2/4*'1_Τιμές_Εταιρείας'!$D$30, 3) -> 1.578 | D10: ='1_Τιμές_Εταιρείας'!$D$11 -> 2.5 | E10: =ROUND(C10*D10, 2) -> 3.95 | F10: Ενισχύσεις / συνδετήρες
A11: Y20 | B11: 20 | C11: =ROUND(PI()*(B11/1000)^2/4*'1_Τιμές_Εταιρείας'!$D$30, 3) -> 2.466 | D11: ='1_Τιμές_Εταιρείας'!$D$11 -> 2.5 | E11: =ROUND(C11*D11, 2) -> 6.17 | F11: Δευτερεύοντες οπλισμοί
A12: Y25 | B12: 25 | C12: =ROUND(PI()*(B12/1000)^2/4*'1_Τιμές_Εταιρείας'!$D$30, 3) -> 3.853 | D12: ='1_Τιμές_Εταιρείας'!$D$11 -> 2.5 | E12: =ROUND(C12*D12, 2) -> 9.63 | F12: Εδαφοηλώσεις μικρού βάθους
A13: Y32 | B13: 32 | C13: =ROUND(PI()*(B13/1000)^2/4*'1_Τιμές_Εταιρείας'!$D$30, 3) -> 6.313 | D13: ='1_Τιμές_Εταιρείας'!$D$11 -> 2.5 | E13: =ROUND(C13*D13, 2) -> 15.78 | F13: Βαριές εδαφοηλώσεις
A15: 2. ΔΙΑΤΟΜΕΣ HEA (Ευρωπαϊκά Πλατύπελμα Ελαφρού Τύπου)
A16: Ονομασία Διατομής | B16: Ύψος h (mm) | C16: Πλάτος b (mm) | D16: Πάχος tw (mm) | E16: Πάχος tf (mm) | F16: Βάρος (kg/m) | G16: Κόστος Υλικού (€/m) [1.40 €/kg]
A17: HEA 140 | B17: 133 | C17: 140 | D17: 5.5 | E17: 8.5 | F17: 24.7 | G17: =ROUND(F17*('1_Τιμές_Εταιρείας'!$D$17+'1_Τιμές_Εταιρείας'!$D$18), 2) -> 34.58
A18: HEA 160 | B18: 152 | C18: 160 | D18: 6 | E18: 9 | F18: 30.4 | G18: =ROUND(F18*('1_Τιμές_Εταιρείας'!$D$17+'1_Τιμές_Εταιρείας'!$D$18), 2) -> 42.56
A19: HEA 180 | B19: 171 | C19: 180 | D19: 6 | E19: 9.5 | F19: 35.5 | G19: =ROUND(F19*('1_Τιμές_Εταιρείας'!$D$17+'1_Τιμές_Εταιρείας'!$D$18), 2) -> 49.7
A20: HEA 200 | B20: 190 | C20: 200 | D20: 6.5 | E20: 10 | F20: 42.3 | G20: =ROUND(F20*('1_Τιμές_Εταιρείας'!$D$17+'1_Τιμές_Εταιρείας'!$D$18), 2) -> 59.22
A21: HEA 220 | B21: 210 | C21: 220 | D21: 7 | E21: 11 | F21: 50.5 | G21: =ROUND(F21*('1_Τιμές_Εταιρείας'!$D$17+'1_Τιμές_Εταιρείας'!$D$18), 2) -> 70.7
A22: HEA 240 | B22: 230 | C22: 240 | D22: 7.5 | E22: 12 | F22: 60.3 | G22: =ROUND(F22*('1_Τιμές_Εταιρείας'!$D$17+'1_Τιμές_Εταιρείας'!$D$18), 2) -> 84.42
A23: HEA 260 | B23: 250 | C23: 260 | D23: 7.5 | E23: 12.5 | F23: 68.2 | G23: =ROUND(F23*('1_Τιμές_Εταιρείας'!$D$17+'1_Τιμές_Εταιρείας'!$D$18), 2) -> 95.48
A24: HEA 280 | B24: 270 | C24: 280 | D24: 8 | E24: 13 | F24: 76.4 | G24: =ROUND(F24*('1_Τιμές_Εταιρείας'!$D$17+'1_Τιμές_Εταιρείας'!$D$18), 2) -> 106.96
A25: HEA 300 | B25: 290 | C25: 300 | D25: 8.5 | E25: 14 | F25: 88.3 | G25: =ROUND(F25*('1_Τιμές_Εταιρείας'!$D$17+'1_Τιμές_Εταιρείας'!$D$18), 2) -> 123.62
A26: HEA 320 | B26: 310 | C26: 300 | D26: 9 | E26: 15.5 | F26: 97.6 | G26: =ROUND(F26*('1_Τιμές_Εταιρείας'!$D$17+'1_Τιμές_Εταιρείας'!$D$18), 2) -> 136.64
A27: HEA 340 | B27: 330 | C27: 300 | D27: 9.5 | E27: 16.5 | F27: 105 | G27: =ROUND(F27*('1_Τιμές_Εταιρείας'!$D$17+'1_Τιμές_Εταιρείας'!$D$18), 2) -> 147
A28: HEA 360 | B28: 350 | C28: 300 | D28: 10 | E28: 17.5 | F28: 112 | G28: =ROUND(F28*('1_Τιμές_Εταιρείας'!$D$17+'1_Τιμές_Εταιρείας'!$D$18), 2) -> 156.8
... A31: HEA 500 | B31: 490 | C31: 300 | D31: 12 | E31: 23 | F31: 155 | G31: =ROUND(F31*('1_Τιμές_Εταιρείας'!$D$17+'1_Τιμές_Εταιρείας'!$D$18), 2) -> 217
A33: 3. ΔΙΑΤΟΜΕΣ HEB (Ευρωπαϊκά Πλατύπελμα Κανονικού Τύπου — ΤΥΠΙΚΕΣ ΝΕΦΚΕΣ)
A34: Ονομασία Διατομής | B34: Ύψος h (mm) | C34: Πλάτος b (mm) | D34: Πάχος tw (mm) | E34: Πάχος tf (mm) | F34: Βάρος (kg/m) | G34: Κόστος Υλικού (€/m) [1.40 €/kg]
A35: HEB 140 | B35: 140 | C35: 140 | D35: 7 | E35: 12 | F35: 33.7 | G35: =ROUND(F35*('1_Τιμές_Εταιρείας'!$D$17+'1_Τιμές_Εταιρείας'!$D$18), 2) -> 47.18
A36: HEB 160 | B36: 160 | C36: 160 | D36: 8 | E36: 13 | F36: 42.6 | G36: =ROUND(F36*('1_Τιμές_Εταιρείας'!$D$17+'1_Τιμές_Εταιρείας'!$D$18), 2) -> 59.64
A37: HEB 180 | B37: 180 | C37: 180 | D37: 8.5 | E37: 14 | F37: 51.2 | G37: =ROUND(F37*('1_Τιμές_Εταιρείας'!$D$17+'1_Τιμές_Εταιρείας'!$D$18), 2) -> 71.68
A38: HEB 200 | B38: 200 | C38: 200 | D38: 9 | E38: 15 | F38: 61.3 | G38: =ROUND(F38*('1_Τιμές_Εταιρείας'!$D$17+'1_Τιμές_Εταιρείας'!$D$18), 2) -> 85.82
A39: HEB 220 | B39: 220 | C39: 220 | D39: 9.5 | E39: 16 | F39: 71.5 | G39: =ROUND(F39*('1_Τιμές_Εταιρείας'!$D$17+'1_Τιμές_Εταιρείας'!$D$18), 2) -> 100.1
A40: HEB 240 | B40: 240 | C40: 240 | D40: 10 | E40: 17 | F40: 83.2 | G40: =ROUND(F40*('1_Τιμές_Εταιρείας'!$D$17+'1_Τιμές_Εταιρείας'!$D$18), 2) -> 116.48
A41: HEB 260 | B41: 260 | C41: 260 | D41: 10 | E41: 17.5 | F41: 93 | G41: =ROUND(F41*('1_Τιμές_Εταιρείας'!$D$17+'1_Τιμές_Εταιρείας'!$D$18), 2) -> 130.2
A42: HEB 280 | B42: 280 | C42: 280 | D42: 10.5 | E42: 18 | F42: 103 | G42: =ROUND(F42*('1_Τιμές_Εταιρείας'!$D$17+'1_Τιμές_Εταιρείας'!$D$18), 2) -> 144.2
A43: HEB 300 | B43: 300 | C43: 300 | D43: 11 | E43: 19 | F43: 117 | G43: =ROUND(F43*('1_Τιμές_Εταιρείας'!$D$17+'1_Τιμές_Εταιρείας'!$D$18), 2) -> 163.8
A44: HEB 320 | B44: 320 | C44: 300 | D44: 11.5 | E44: 20.5 | F44: 127 | G44: =ROUND(F44*('1_Τιμές_Εταιρείας'!$D$17+'1_Τιμές_Εταιρείας'!$D$18), 2) -> 177.8
A45: HEB 340 | B45: 340 | C45: 300 | D45: 12 | E45: 21.5 | F45: 134 | G45: =ROUND(F45*('1_Τιμές_Εταιρείας'!$D$17+'1_Τιμές_Εταιρείας'!$D$18), 2) -> 187.6
...

Sheet 3_Υπολογιστές_Έργων_&_Math
A1: ΔΙΑΔΡΑΣΤΙΚΟΙ ΥΠΟΛΟΓΙΣΤΕΣ ΕΡΓΩΝ BERLIN WALL & ΑΓΚΥΡΩΣΕΩΝ
A2: ΓΑΛΑΖΙΑ ΚΕΛΙΑ = Εισαγωγή στοιχείων μελέτης | Οι τιμές μονάδας αντλούνται αυτόματα από τον Τιμοκατάλογο (Φύλλο 1)
A4: 1. ΥΠΟΛΟΓΙΣΤΗΣ ΣΤΡΑΤΩΝ ΜΕΤΑΚΙΝΗΣΗΣ ΑΝΑ ΑΠΟΣΤΑΣΗ
A5: Παράμετρος Έργου | B5: Τιμή / Εισαγωγή | C5: Μονάδα | D5: Τύπος Υπολογισμού | E5: Τελική Τιμή Στράτας (€) | F5: Παρατηρήσεις
A6: Οδική Απόσταση Έργου από Άγιο Συλά | B6: 40 | C6: km | D6: Εισαγωγή από μελέτη / Google Maps | E6: — | F6: Βασική ζώνη 0–40 km (Λεμεσός)
A7: Επιπλέον Ζώνες των 40 km (για Αγκυρώσεις/Shotcrete) | B7: =MAX(0, ROUNDUP((B6-'1_Τιμές_Εταιρείας'!$D$31)/'1_Τιμές_Εταιρείας'!$D$31, 0)) -> 799 | C7: ζώνες | D7: MAX(0, ROUNDUP((km-40)/40, 0)) | E7: =B7 -> 799 | F7: 0 = έως 40km, 1 = 41-80km, 2 = 81-120km
A8: Τιμή Στράτας Μεγάλου Τρυπανιού | B8: ='1_Τιμές_Εταιρείας'!$D$5 + IF(B6>80, '1_Τιμές_Εταιρείας'!$D$7, IF(B6>40, '1_Τιμές_Εταιρείας'!$D$6, 0)) -> 1500 | C8: € / στράτα | D8: 1500 + (+500 αν >40km, +1500 αν >80km) | E8: =B8 -> 1500 | F8: Λεμεσός: 1500 €, 40-80km: 2000 €, Λευκωσία: 3000 €
A9: Τιμή Στράτας Εξοπλισμού Αγκυρώσεων | B9: ='1_Τιμές_Εταιρείας'!$D$8 + B7*'1_Τιμές_Εταιρείας'!$D$10 -> 40250 | C9: € / στράτα | D9: 300 € + Επιπλέον Ζώνες × 50 € | E9: =B9 -> 40250 | F9: 300 € (0-40km), 350 € (40-80km), 400 € (80-120km)
A10: Τιμή Στράτας Shotcrete | B10: ='1_Τιμές_Εταιρείας'!$D$9 + B7*'1_Τιμές_Εταιρείας'!$D$10 -> 40150 | C10: € / στράτα | D10: 200 € + Επιπλέον Ζώνες × 50 € | E10: =B10 -> 40150 | F10: 200 € (0-40km), 250 € (40-80km), 300 € (80-120km)
A12: 2. ΥΠΟΛΟΓΙΣΤΗΣ ΒΑΡΟΥΣ & ΚΟΣΤΟΥΣ ΣΧΑΡΑΣ ΜΕΤΩΠΟΥ (CUSTOM GRID CALCULATOR)
A13: Διεύθυνση Οπλισμού | B13: Διάμετρος Y (mm) | C13: Βήμα s (mm) | D13: Μέτρα Ράβδων ανά m² | E13: Βάρος Ράβδων (kg/m²) | F13: Τρόπος Υπολογισμού
A14: Οριζόντιες Ράβδοι Μετώπου | B14: 10 | C14: 150 | D14: =ROUND(1000/C14, 2) -> 6.67 | E14: =ROUND(D14*VLOOKUP(B14, '2_Βάρη_Διατομών_Χάλυβα'!$B$6:$C$13, 2, FALSE), 3) -> 4.115 | F14: 1000 / s × kg/m του Y
A15: Κάθετες Ράβδοι Μετώπου | B15: 10 | C15: 150 | D15: =ROUND(1000/C15, 2) -> 6.67 | E15: =ROUND(D15*VLOOKUP(B15, '2_Βάρη_Διατομών_Χάλυβα'!$B$6:$C$13, 2, FALSE), 3) -> 4.115 | F15: 1000 / s × kg/m του Y
A16: ΣΥΝΟΛΙΚΟ ΒΑΡΟΣ ΧΑΛΥΒΑ ΣΧΑΡΑΣ | B16: — | C16: — | D16: =D14+D15 -> 13.34 | E16: =E14+E15 -> 8.23 | F16: kg χάλυβα ανά m² επιφάνειας μετώπου
A17: Κόστος Αγοράς Σιδήρου Σχάρας ανά m² | B17: =ROUND(E16*'1_Τιμές_Εταιρείας'!$D$11, 2) -> 20.58 | C17: € / m² | D17: kg/m² × 2.50 €/kg (από Τιμοκατάλογο) | E17: =B17 -> 20.58 | F17: —
A18: Κόστος Τοποθέτησης Σχάρας ανά m² | B18: ='1_Τιμές_Εταιρείας'!$D$12 -> 15 | C18: € / m² | D18: 15.00 €/m² ενιαία τοποθέτηση | E18: =B18 -> 15 | F18: —
A19: ΤΕΛΙΚΟ ΚΟΣΤΟΣ ΣΧΑΡΑΣ ΑΝΑ m² (ΑΓΟΡΑ + ΤΟΠΟΘΕΤΗΣΗ) | B19: =B17+B18 -> 35.58 | C19: € / m² | D19: Αγορά + Τοποθέτηση | E19: =B19 -> 35.58 | F19: —
A21: 3. ΥΠΟΛΟΓΙΣΤΗΣ ΜΟΝΑΔΑΣ H-BEAM / ΠΑΣΣΑΛΟΥ (SOLDIER PILE CALCULATOR)
A22: Στοιχείο Πασσάλου / Νέφκας | B22: Τιμή / Εισαγωγή | C22: Μονάδα | D22: Τύπος Υπολογισμού | E22: Κόστος ανά Πάσσαλο (€) | F22: Παρατηρήσεις
A23: Ύψος Εκσκαφής Μετώπου (H_exc) | B23: 8 | C23: m | D23: Εισαγωγή από μελέτη | E23: — | F23: Ελεύθερο ύψος
A24: Βάθος Πάκτωσης Πασσάλου (H_embed) | B24: 4 | C24: m | D24: Εισαγωγή από μελέτη | E24: — | F24: Βάθος πάκτωσης κάτω από πυθμένα
A25: Συνολικό Μήκος Οπής & Νέφκας (L_beam) | B25: =B23+B24 -> 12 | C25: m | D25: H_exc + H_embed | E25: — | F25: Συνολικό μήκος τρυπήματος
A26: Διάμετρος Οπής Μεγάλου Τρυπανιού (D) | B26: 0.8 | C26: m | D26: Εισαγωγή από μελέτη (προεπιλογή 0.80 m) | E26: — | F26: 800 mm τυπική διάμετρος
A27: Κόστος Διάτρησης ανά Πάσσαλο | B27: =ROUND(B25*'1_Τιμές_Εταιρείας'!$D$16, 2) -> 900 | C27: € / πάσσαλο | D27: L_beam × 75.00 €/m (από Τιμοκατάλογο) | E27: =B27 -> 900 | F27: Διάτρηση μεγάλου τρυπανιού
A28: Βάρος Προφίλ Νέφκας ανά Μέτρο (π.χ. HEB 240) | B28: 83.2 | C28: kg / m | D28: Από Πίνακα Διατομών (Φύλλο 2) | E28: — | F28: 83.2 kg/m για HEB 240
A29: Κόστος Προφίλ Νέφκας ανά Πάσσαλο | B29: =ROUND(B25*B28*('1_Τιμές_Εταιρείας'!$D$17+'1_Τιμές_Εταιρείας'!$D$18), 2) -> 1397.76 | C29: € / πάσσαλο | D29: L_beam × kg/m × 1.40 €/kg | E29: =B29 -> 1397.76 | F29: Χάλυβας νέφκας
A30: Κόστος Λαμών Σύνδεσης ανά Πάσσαλο | B30: 47.1 | C30: € / πάσσαλο | D30: Λάμες ανά 1.0 m × 1.60 €/kg | E30: =B30 -> 47.1 | F30: Ενισχύσεις / συνδέσεις
A31: Κουγκρί Πάκτωσης ανά Πάσσαλο (Κυβικά & Κόστος) | B31: =ROUND(PI()*((B26/2)^2)*B24*'1_Τιμές_Εταιρείας'!$D$21, 2) -> 241.27 | C31: € / πάσσαλο | D31: π × (D/2)² × H_embed × 120.00 €/m³ | E31: =B31 -> 241.27 | F31: Σκυρόδεμα πάκτωσης
A32: ΣΥΝΟΛΙΚΟ ΚΟΣΤΟΣ ΑΝΑ ΠΑΣΣΑΛΟ / ΟΠΗ BERLIN WALL | B32: =E27+E29+E30+E31 -> 2586.13 | C32: € / πάσσαλο | D32: Διάτρηση + Νέφκα + Λάμες + Κουγκρί | E32: =B32 -> 2586.13 | F32: Πλήρες κόστος ανά οπή
A34: 4. ΥΠΟΛΟΓΙΣΤΗΣ ΜΟΝΑΔΑΣ ΑΓΚΥΡΩΣΗΣ (TIEBACK ANCHOR CALCULATOR)
A35: Στοιχείο Αγκύρωσης | B35: Τιμή / Εισαγωγή | C35: Μονάδα | D35: Τύπος Υπολογισμού | E35: Κόστος ανά Αγκύρωση (€) | F35: Παρατηρήσεις
A36: Μήκος / Βάθος Διάτρησης Αγκύρωσης (L_drill) | B36: 14 | C36: m | D36: Εισαγωγή από μελέτη | E36: — | F36: Μήκος οπής
A37: Αριθμός Τενόντων ανά Οπή (N_strands) | B37: 4 | C37: τεμ / οπή | D37: Εισαγωγή από μελέτη | E37: — | F37: Τυπικά 3 έως 5 τένοντες
A38: Κόστος Διάτρησης ανά Αγκύρωση | B38: =ROUND(B36*'1_Τιμές_Εταιρείας'!$D$23, 2) -> 420 | C38: € / αγκύρωση | D38: L_drill × 30.00 €/m | E38: =B38 -> 420 | F38: Διάτρηση οπής
A39: Κόστος Grout Τσιμεντενέματος ανά Αγκύρωση | B39: =ROUND(B36*PI()*(( '1_Τιμές_Εταιρείας'!$D$32 /2)^2)* '1_Τιμές_Εταιρείας'!$D$33 * '1_Τιμές_Εταιρείας'!$D$24, 2) -> 1055575.1 | C39: € / αγκύρωση | D39: L_drill × 0.013572 m³/m × 500 €/m³ | E39: =B39 -> 1055575.1 | F39: Grout πλήρωσης
A40: Κόστος Τενόντων Προέντασης ανά Αγκύρωση | B40: =ROUND((B36+ '1_Τιμές_Εταιρείας'!$D$35)*B37* '1_Τιμές_Εταιρείας'!$D$25, 2) -> 134.98 | C40: € / αγκύρωση | D40: (L_drill + 1.0 m) × N_strands × 2.28 €/m | E40: =B40 -> 134.98 | F40: Χάλυβας προέντασης
A41: Κόστος Προέντασης & Lock-off ανά Αγκύρωση | B41: ='1_Τιμές_Εταιρείας'!$D$26 -> 18 | C41: € / αγκύρωση | D41: 18.00 € / τεμάχιο (από Τιμοκατάλογο) | E41: =B41 -> 18 | F41: Εργασία τάνυσης
A42: Κόστος Κεφαλής Αγκύρωσης & Πλάκας ανά Αγκύρωση | B42: ='1_Τιμές_Εταιρείας'!$D$27 -> 55 | C42: € / αγκύρωση | D42: 55.00 € / τεμάχιο (από Τιμοκατάλογο) | E42: =B42 -> 55 | F42: Υλικά κεφαλής
A43: ΣΥΝΟΛΙΚΟ ΚΟΣΤΟΣ ΑΝΑ ΠΛΗΡΗ ΑΓΚΥΡΩΣΗ (TIEBACK ANCHOR) | B43: =E38+E39+E40+E41+E42 -> 1056203.1 | C43: € / αγκύρωση | D43: Διάτρηση + Grout + Τένοντες + Τάνυση + Κεφαλή | E43: =B43 -> 1056203.1 | F43: Πλήρες κόστος αγκύρωσης

Sheet 4_Κανόνες_&_Πολιτική
A1: ΚΑΝΟΝΕΣ ΤΙΜΟΚΑΤΑΛΟΓΟΥ & ΠΟΛΙΤΙΚΗ ΑΠΟΥΣΙΑΣ ΥΛΙΚΟΥ (BERLIN WALL)
A2: Αυστηρές οδηγίες κοστολόγησης και συμπεριφοράς για το AI και τους μηχανικούς
A4: Θέμα / Πεδίο | B4: Κανόνας Λειτουργίας & Οδηγία για το AI
A5: Κανόνας Χρωματισμού | B5: • ΚΙΤΡΙΝΟ (#FFF2CC): Τιμές μονάδας που αλλάζουν με τους καιρούς / συνθήκες αγοράς. • ΛΕΥΚΟ (Χωρίς γέμισμα): Φυσικές σταθερές (7850 kg/m³, π), γεωμετρία και δυναμικοί τύποι. • ΓΑΛΑΖΙΟ (#DDEBF7): Εισαγωγή στοιχείων ανά έργο στους διαδραστικούς υπολογιστές. • ΑΠΑΛΟ ΠΟΡΤΟΚΑΛΙ (#FFE699): Κουγκρί πάκτωσης πασσάλων για άμεση εποπτεία.
A6: Κανόνας Μετακινήσεων (3 Είδη) | B6: • Μεγάλο τρυπάνι: 1 στράτα συνήθως. 1,500 € Λεμεσό, +500 € (40–80 km), +1,500 € (>80 km, π.χ. Λευκωσία = 3,000 €). • Εξοπλισμός αγκυρώσεων: 300 € Λεμεσό (+50 € / 40 km). Στράτες = Σειρές αγκυρώσεων ανά ζώνη. • Shotcrete: 200 € Λεμεσό (+50 € / 40 km). Στράτες = Σειρές αγκυρώσεων + 1 στράτα.
A7: Κανόνας Σχαρών & Shotcrete | B7: Μετριούνται ακριβώς όπως στις εδαφοηλώσεις: • Σχάρα: 2.50 €/kg αγορά + 15.00 €/m² τοποθέτηση. • Shotcrete C30/37: 90.00 €/m³ αγορά + εφαρμογή [(Βάση 200 ή 250 × (1 + %απώλειας)) - 90] €/m³. • Πάγια απώλεια: +0.05 m (+5cm) πάνω στο ονομαστικό πάχος μελέτης.
A8: Κανόνας H-Beams (Νέφκες & Πάσσαλοι) | B8: Περιλαμβάνει 5 στοιχεία: 1. Διάτρηση μεγάλου τρυπανιού: 75.00 €/m (εύρος 65–90 €/m). Προεπιλογή Ø800 mm. 2. Χάλυβας νέφκας: 1.40 €/kg (1.00 € αγορά + 0.40 € επεξεργασία/τοποθέτηση). 3. Λάμες σύνδεσης: 1.60 €/kg (1.00 € αγορά + 0.60 € επεξεργασία/συγκόλληση). 4. Κουγκρί πάκτωσης: 120.00 €/m³ (σε ύψος H_embed). 5. Γωνιές στήριξης L: 1.60 €/kg (μόνο εφόσον ζητούνται στο σχέδιο).
A9: Κανόνας Αγκυρώσεων (Tieback Anchors) | B9: Περιλαμβάνει 5 στοιχεία: 1. Διάτρηση: 30.00 €/m (εύρος 25–35 €/m). 2. Grout: 500.00 €/m³ με όγκο π × (0.12/2)² × 1.20 = 0.013572 m³/m. 3. Τένοντες προέντασης: 2.28 €/m τένοντα (0.6" - 1.10 kg/m), μήκος = (Βάθος + 1.0 m) × strands. 4. Προένταση (Stressing & Lock-off): 18.00 € / τεμάχιο (ανά οπή). 5. Κεφαλή αγκύρωσης: 55.00 € / τεμάχιο (ανά οπή).
A10: ΚΑΝΟΝΑΣ ΑΠΟΥΣΙΑΣ ΥΛΙΚΟΥ (ΥΠΟΧΡΕΩΤΙΚΟ ΜΗΝΥΜΑ AI) | B10: Εάν ο μελετητής ζητήσει υλικό που ΔΕΝ υπάρχει στον παρόντα τιμοκατάλογο (π.χ. διάτρηση Ø1000 mm, διατομή HEB 700, ίνες, κ.λπ.): -> Το σύστημα AI ΑΠΑΓΟΡΕΥΕΤΑΙ ΑΥΣΤΗΡΑ να μαντέψει ή να εφεύρει τιμή! -> Το σύστημα ΣΤΑΜΑΤΑΕΙ και εμφανίζει στον χρήστη ρητά το μήνυμα: «Δεν υπάρχει αυτό το είδος ([Όνομα Είδους]) στον τιμοκατάλογο. Καθοδήγησέ με με τιμή να ξέρω.» -> Μόνο αφού ο χρήστης δώσει την τιμή, η κοστολόγηση προχωρά.
