Workbook

Sheet 1_Τιμές_Εταιρείας
A1: ΚΕΝΤΡΙΚΟΣ ΤΙΜΟΚΑΤΑΛΟΓΟΣ ΕΤΑΙΡΕΙΑΣ — ΕΔΡΑ: ΑΓΙΟΣ ΣΥΛΑΣ, ΛΕΜΕΣΟΣ
A2: ΚΙΤΡΙΝΟ = Τιμές μονάδας που αλλάζουν με τους καιρούς | ΓΚΡΙ ΠΛΑΙΣΙΑ = Γενικές φόρμουλες υπολογισμού ανά πυλώνα
A4: Α/Α | B4: Πυλώνας Κόστους | C4: Είδος Υλικού / Εργασίας | D4: Τιμή Μονάδας (€) [ΚΙΤΡΙΝΟ = ΑΛΛΑΖΕΙ] | E4: Μονάδα | F4: Παρατηρήσεις / Προδιαγραφή
A5: ΠΥΛΩΝΑΣ 1: ΜΕΤΑΚΙΝΗΣΕΙΣ (ΣΤΡΑΤΕΣ)
A6: 1 | B6: 1. Μετακινήσεις | C6: Στράτα Shotcrete — Βασική τιμή (Ζώνη 1: 0–50 km) | D6: 200 | E6: €/στράτα | F6: Βάση: Άγιος Συλάς. Φορτηγό εκτόξευσης & πλεγμάτων
A7: 2 | B7: 1. Μετακινήσεις | C7: Στράτα Εδαφοηλώσεων — Βασική τιμή (Ζώνη 1: 0–50 km) | D7: 300 | E7: €/στράτα | F7: Βάση: Άγιος Συλάς. Φορτηγό ράβδων, πλακών, nuts
A8: 3 | B8: 1. Μετακινήσεις | C8: Επιβάρυνση ανά επιπλέον 50 km (έξω από τα 50 km) | D8: 50 | E8: €/στράτα | F8: Προστίθεται αυτόματα ανά ζώνη 50km πάνω από τη βασική
A9: 📐 ΓΕΝΙΚΗ ΦΟΡΜΟΥΛΑ & ΚΑΝΟΝΕΣ ΥΠΟΛΟΓΙΣΜΟΥ ΜΕΤΑΚΙΝΗΣΕΩΝ:
A10: • ΓΕΝΙΚΗ ΦΟΡΜΟΥΛΑ: Κόστος Μετακινήσεων = (Στράτες Shotcrete × Τιμή Στράτας) + (Στράτες Ήλων × Τιμή Στράτας)
A11: • ΠΟΣΕΣ ΣΤΡΑΤΕΣ SHOTCRETE: Στράτες Shotcrete = (Πλήθος Οριζόντιων Σειρών Ήλων) + 1 στράτα (λόγω κλεισίματος ποδιού/τελικής εκσκαφής).
A12: • ΠΟΣΕΣ ΣΤΡΑΤΕΣ ΗΛΩΝ: Στράτες Ήλων = (Πλήθος Οριζόντιων Σειρών Ήλων). Κάθε οριζόντια σειρά αποτελεί ξεχωριστή φάση παράδοσης υλικών.
A13: • ΠΩΣ ΥΠΟΛΟΓΙΖΕΤΑΙ Η ΤΙΜΗ ΣΤΡΑΤΑΣ: Αν απόσταση έργου <= 50 km από Άγιο Συλά -> Βασική Τιμή. Αν > 50 km -> Βασική Τιμή + [ROUNDUP((km - 50)/50) × 50.00 €].
A14: • ΓΕΩΤΡΥΠΑΝΟ (DRILLING RIG): Μένει στο εργοτάξιο καθ' όλη τη διάρκεια του έργου (δεν χρεώνονται καθημερινές μετακινήσεις).
A16: ΠΥΛΩΝΑΣ 2: ΣΧΑΡΕΣ (WIRE MESH GRIDS)
A17: 4 | B17: 2. Σχάρες | C17: Σίδηρος σχάρας — Αγορά χάλυβα | D17: 2.5 | E17: €/kg | F17: Ενιαία τιμή αγοράς για όλες τις διατομές σιδήρου πλέγματος
A18: 5 | B18: 2. Σχάρες | C18: Σχάρα — Τοποθέτηση / Εργατικά | D18: 15 | E18: €/m² | F18: Ενιαία τιμή εργατικών τοποθέτησης ανά m² μετώπου εκσκαφής
A19: 📐 ΓΕΝΙΚΗ ΦΟΡΜΟΥΛΑ & ΚΑΝΟΝΕΣ ΥΠΟΛΟΓΙΣΜΟΥ ΣΧΑΡΩΝ:
A20: • ΓΕΝΙΚΗ ΦΟΡΜΟΥΛΑ: Κόστος Σχαρών = (Εμβαδόν Μετώπου m² × kg/m² × 2,50 €/kg) + (Εμβαδόν Μετώπου m² × 15,00 €/m²)
A21: • ΕΜΒΑΔΟΝ ΜΕΤΩΠΟΥ (m²): Μήκος Εκσκαφής L (m) × Ύψος Εκσκαφής H (m).
A22: • ΠΩΣ ΥΠΟΛΟΓΙΖΟΝΤΑΙ ΤΑ ΚΙΛΑ ΑΝΑ ΤΕΤΡΑΓΩΝΙΚΟ (kg/m²):
A23: 1. Σε 1 m² (1000×1000 mm), τα τρέχοντα μέτρα ράβδων είναι: (1000 / s_horiz) οριζόντια + (1000 / s_vert) κάθετα.
A24: 2. Κάθε μέτρο ράβδου ζυγίζει: w = (π × d² / 4) × 7.850 kg/m³, όπου d η διάμετρος σε μέτρα (π.χ. Y10 -> 0,617 kg/m, Y8 -> 0,395 kg/m).
A25: 3. ΠΑΡΑΔΕΙΓΜΑ Y10/150: (1000/150 + 1000/150) = 13,333 m/m² × 0,6165 kg/m = 8,220 kg/m².
A26: 4. ΠΑΡΑΔΕΙΓΜΑ ΣΥΝΘΕΤΗΣ ΣΧΑΡΑΣ (π.χ. Y8/100 οριζόντια + Y10/200 κάθετα): (1000/100 × 0,395) + (1000/200 × 0,617) = 3,95 + 3,085 = 7,035 kg/m².
A28: ΠΥΛΩΝΑΣ 3: ΕΚΤΟΞΕΥΟΜΕΝΟ ΣΚΥΡΟΔΕΜΑ (SHOTCRETE)
A29: 6 | B29: 3. Shotcrete | C29: Σκυρόδεμα C30/37 — Αγορά κουγκριού | D29: 90 | E29: €/m³ | F29: Τιμή αγοράς έτοιμου σκυροδέματος C30/37
A30: 7 | B30: 3. Shotcrete | C30: Εκτοξευόμενο — Τοποθέτηση / Εκτόξευση | D30: 160 | E30: €/m³ | F30: Τιμή αντλίας, χειριστή, εργατικών & εκτόξευσης ανά m³
A31: 📐 ΓΕΝΙΚΗ ΦΟΡΜΟΥΛΑ & ΚΑΝΟΝΕΣ ΥΠΟΛΟΓΙΣΜΟΥ SHOTCRETE:
A32: • ΓΕΝΙΚΗ ΦΟΡΜΟΥΛΑ: Κόστος Shotcrete = Συνολικός Όγκος m³ × (90,00 €/m³ αγορά + 160,00 €/m³ τοποθέτηση) = Όγκος m³ × 250,00 €/m³
A33: • ΠΩΣ ΥΠΟΛΟΓΙΖΕΤΑΙ Ο ΟΓΚΟΣ SHOTCRETE (m³):
A34: Όγκος = Μήκος Μετώπου L (m) × Ύψος Μετώπου H (m) × Υπολογιστικό Πάχος (m)
A35: • ΚΑΝΟΝΑΣ ΠΑΧΟΥΣ (+5cm ΑΠΩΛΕΙΑ): Υπολογιστικό Πάχος = (Ονομαστικό Πάχος Μελέτης) + 0,05 m πάγια απώλεια.
A36: Π.χ. για σχέδιο με πάχος 12cm (0,12m) -> Υπολογιστικό Πάχος = 0,12 + 0,05 = 0,17 m.
A37: • ΚΟΣΤΟΣ ΑΝΑ ΤΕΤΡΑΓΩΝΙΚΟ ΜΕΤΩΠΟΥ: 0,17 m × 250,00 €/m³ = 42,50 €/m² μετώπου.
A39: ΠΥΛΩΝΑΣ 4: ΕΔΑΦΟΗΛΩΣΕΙΣ (SOIL NAILS)
A40: 8 | B40: 4. Εδαφοηλώσεις | C40: Τρύπημα (Διάτρηση) — Ήλοι μήκους ≥ 6.0 m | D40: 25 | E40: €/m | F40: Τιμή ανά τρέχον μέτρο διάτρησης για ήλους μήκους 6m και άνω
A41: 9 | B41: 4. Εδαφοηλώσεις | C41: Τρύπημα (Διάτρηση) — Ήλοι μήκους < 6.0 m | D41: 30 | E41: €/m | F41: Τιμή ανά τρέχον μέτρο διάτρησης για ήλους μήκους κάτω των 6m
A42: 10 | B42: 4. Εδαφοηλώσεις | C42: Τρύπημα (Διάτρηση) — Μικρές δουλειές (≤ 5 ήλοι) | D42: 35 | E42: €/m | F42: Εφαρμόζεται σε μικρά έργα με συνολικό πλήθος έως 5 εδαφοηλώσεις
A43: 11 | B43: 4. Εδαφοηλώσεις | C43: Grout (Τσιμεντένεμα) πλήρωσης οπών | D43: 500 | E43: €/m³ | F43: Ενιαία τιμή έτοιμου τσιμεντενέματος πλήρωσης οπών ανά m³
A44: 12 | B44: 4. Εδαφοηλώσεις | C44: Σίδηρος ήλωσης B500C (Αγορά+Τοποθέτηση+Επεξεργασία) | D44: 1.5 | E44: €/kg | F44: Ενιαία τιμή ράβδων B500C ανά κιλό (συμπεριλαμβάνει αγορά, τοποθέτηση & επεξεργασία)
...

Sheet 2_Βάρη_Διατομών_Χάλυβα
A1: ΜΗΤΡΩΟ ΔΙΑΤΟΜΩΝ ΧΑΛΥΒΑ (Y6 ΕΩΣ Y40) — ΘΕΩΡΗΤΙΚΟ ΒΑΡΟΣ kg/m
A2: Φυσικός τύπος: kg/m = π × (d/1000)² / 4 × 7.850 kg/m³ | Ίδια τιμή €/kg για όλες τις διατομές
A4: Διατομή (Y) | B4: Διάμετρος d (mm) | C4: Θεωρητικό Βάρος (kg/m) | D4: Τιμή Σιδήρου Ήλωσης (€/kg) | E4: Κόστος ράβδου ανά τρέχον μέτρο (€/m) | F4: Συνήθης Χρήση
A5: Y6 | B5: 6 | C5: =ROUND(PI()*(B5/1000)^2/4*'1_Τιμές_Εταιρείας'!$D$63, 3) -> 0.222 | D5: ='1_Τιμές_Εταιρείας'!$D$44 -> 1.5 | E5: =ROUND(C5*D5, 2) -> 0.33 | F5: Σχάρες μετώπου ελαφρού τύπου
A6: Y8 | B6: 8 | C6: =ROUND(PI()*(B6/1000)^2/4*'1_Τιμές_Εταιρείας'!$D$63, 3) -> 0.395 | D6: ='1_Τιμές_Εταιρείας'!$D$44 -> 1.5 | E6: =ROUND(C6*D6, 2) -> 0.59 | F6: Σχάρες μετώπου τυπικού τύπου
A7: Y10 | B7: 10 | C7: =ROUND(PI()*(B7/1000)^2/4*'1_Τιμές_Εταιρείας'!$D$63, 3) -> 0.617 | D7: ='1_Τιμές_Εταιρείας'!$D$44 -> 1.5 | E7: =ROUND(C7*D7, 2) -> 0.93 | F7: Σχάρες μετώπου (π.χ. ALDO SQ1 Y10/150)
A8: Y12 | B8: 12 | C8: =ROUND(PI()*(B8/1000)^2/4*'1_Τιμές_Εταιρείας'!$D$63, 3) -> 0.888 | D8: ='1_Τιμές_Εταιρείας'!$D$44 -> 1.5 | E8: =ROUND(C8*D8, 2) -> 1.33 | F8: Βαριές σχάρες μετώπου / μικροί ήλοι
A9: Y14 | B9: 14 | C9: =ROUND(PI()*(B9/1000)^2/4*'1_Τιμές_Εταιρείας'!$D$63, 3) -> 1.208 | D9: ='1_Τιμές_Εταιρείας'!$D$44 -> 1.5 | E9: =ROUND(C9*D9, 2) -> 1.81 | F9: Ειδικοί οπλισμοί
A10: Y16 | B10: 16 | C10: =ROUND(PI()*(B10/1000)^2/4*'1_Τιμές_Εταιρείας'!$D$63, 3) -> 1.578 | D10: ='1_Τιμές_Εταιρείας'!$D$44 -> 1.5 | E10: =ROUND(C10*D10, 2) -> 2.37 | F10: Ήλοι μικρού μήκους
A11: Y20 | B11: 20 | C11: =ROUND(PI()*(B11/1000)^2/4*'1_Τιμές_Εταιρείας'!$D$63, 3) -> 2.466 | D11: ='1_Τιμές_Εταιρείας'!$D$44 -> 1.5 | E11: =ROUND(C11*D11, 2) -> 3.7 | F11: Εδαφοηλώσεις μέσου φορτίου / βαριά grids
A12: Y25 | B12: 25 | C12: =ROUND(PI()*(B12/1000)^2/4*'1_Τιμές_Εταιρείας'!$D$63, 3) -> 3.853 | D12: ='1_Τιμές_Εταιρείας'!$D$44 -> 1.5 | E12: =ROUND(C12*D12, 2) -> 5.78 | F12: Κύριος οπλισμός ήλων (π.χ. ALDO SQ1 Y25)
A13: Y28 | B13: 28 | C13: =ROUND(PI()*(B13/1000)^2/4*'1_Τιμές_Εταιρείας'!$D$63, 3) -> 4.834 | D13: ='1_Τιμές_Εταιρείας'!$D$44 -> 1.5 | E13: =ROUND(C13*D13, 2) -> 7.25 | F13: Εδαφοηλώσεις υψηλού φορτίου
A14: Y32 | B14: 32 | C14: =ROUND(PI()*(B14/1000)^2/4*'1_Τιμές_Εταιρείας'!$D$63, 3) -> 6.313 | D14: ='1_Τιμές_Εταιρείας'!$D$44 -> 1.5 | E14: =ROUND(C14*D14, 2) -> 9.47 | F14: Βαριές εδαφοηλώσεις / μόνιμα αγκύρια
A15: Y40 | B15: 40 | C15: =ROUND(PI()*(B15/1000)^2/4*'1_Τιμές_Εταιρείας'!$D$63, 3) -> 9.865 | D15: ='1_Τιμές_Εταιρείας'!$D$44 -> 1.5 | E15: =ROUND(C15*D15, 2) -> 14.8 | F15: Πολύ βαριά αγκύρια / μικροπάσσαλοι

Sheet 3_Υπολογιστές_Έργων_&_Math
A1: ΕΡΓΑΛΕΙΑ ΥΠΟΛΟΓΙΣΜΟΥ ΕΡΓΩΝ & ΕΠΕΞΗΓΗΣΗ ΜΑΘΗΜΑΤΙΚΩΝ (SANDBOX)
A2: ΓΑΛΑΖΙΑ ΚΕΛΙΑ = Εισαγωγή στοιχείων από τη μελέτη μηχανικού | Οι τιμές μονάδας αντλούνται αυτόματα από τον Τιμοκατάλογο (Φύλλο 1)
A4: 1. ΥΠΟΛΟΓΙΣΤΗΣ ΤΙΜΗΣ ΣΤΡΑΤΑΣ ΑΝΑ ΑΠΟΣΤΑΣΗ ΕΡΓΟΤΑΞΙΟΥ
A5: Εισάγετε τη χιλιομετρική απόσταση του έργου από την έδρα (Άγιος Συλάς, Σπύρου Κυπριανού 32):
A6: Παράμετρος Έργου | B6: Τιμή / Εισαγωγή | C6: Μονάδα | D6: Τύπος Υπολογισμού | E6: Αποτέλεσμα | F6: Παρατηρήσεις
A7: Οδική Απόσταση Έργου από Άγιο Συλά | B7: 50 | C7: km | D7: Εισαγωγή από μελέτη / Google Maps | E7: — | F7: Βασική ζώνη έως 50 km
A8: Επιπλέον Ζώνες των 50 km | B8: =MAX(0, ROUNDUP((B7-'1_Τιμές_Εταιρείας'!$D$67)/'1_Τιμές_Εταιρείας'!$D$67, 0)) -> 0 | C8: ζώνες | D8: MAX(0, ROUNDUP((km − 50)/50, 0)) | E8: =B8 -> 0 | F8: 0 = έως 50km, 1 = 51-100km, 2 = 101-150km
A9: Τελική Τιμή Στράτας Shotcrete για το Έργο | B9: ='1_Τιμές_Εταιρείας'!$D$6 + B8*'1_Τιμές_Εταιρείας'!$D$8 -> 200 | C9: € / στράτα | D9: Βασική (200 €) + Ζώνες × 50 € | E9: =B9 -> 200 | F9: Χρησιμοποιείται στην κοστολόγηση shotcrete
A10: Τελική Τιμή Στράτας Εδαφοηλώσεων για το Έργο | B10: ='1_Τιμές_Εταιρείας'!$D$7 + B8*'1_Τιμές_Εταιρείας'!$D$8 -> 300 | C10: € / στράτα | D10: Βασική (300 €) + Ζώνες × 50 € | E10: =B10 -> 300 | F10: Χρησιμοποιείται στην κοστολόγηση ήλων
A12: 2. ΥΠΟΛΟΓΙΣΤΗΣ ΒΑΡΟΥΣ & ΚΟΣΤΟΥΣ ΣΧΑΡΑΣ ΜΕΛΕΤΗΣ (CUSTOM GRID CALCULATOR)
A13: Εισάγετε τη διάμετρο Y και το βήμα (απόσταση σε mm) για τις οριζόντιες και κάθετες ράβδους:
A14: Διεύθυνση Οπλισμού | B14: Διάμετρος Y (mm) | C14: Βήμα s (mm) | D14: Μέτρα Ράβδων ανά m² | E14: Βάρος Ράβδων (kg/m²) | F14: Τρόπος Υπολογισμού
A15: Οριζόντιες Ράβδοι Μετώπου | B15: 10 | C15: 150 | D15: =ROUND(1000/C15, 2) -> 6.67 | E15: =ROUND(D15*VLOOKUP(B15, '2_Βάρη_Διατομών_Χάλυβα'!$B$5:$C$15, 2, FALSE), 3) -> 4.115 | F15: 1000/s × kg/m του Y
A16: Κάθετες Ράβδοι Μετώπου | B16: 10 | C16: 150 | D16: =ROUND(1000/C16, 2) -> 6.67 | E16: =ROUND(D16*VLOOKUP(B16, '2_Βάρη_Διατομών_Χάλυβα'!$B$5:$C$15, 2, FALSE), 3) -> 4.115 | F16: 1000/s × kg/m του Y
A17: ΣΥΝΟΛΙΚΟ ΒΑΡΟΣ ΧΑΛΥΒΑ ΣΧΑΡΑΣ | B17: — | C17: — | D17: =D15+D16 -> 13.34 | E17: =E15+E16 -> 8.23 | F17: kg χάλυβα ανά m² επιφάνειας μετώπου
A18: Κόστος Αγοράς Σιδήρου Σχάρας ανά m² | B18: =ROUND(E17*'1_Τιμές_Εταιρείας'!$D$17, 2) -> 20.58 | C18: € / m² | D18: kg/m² × 2,50 €/kg (από Τιμοκατάλογο) | E18: =B18 -> 20.58 | F18: Κόστος υλικού
A19: Κόστος Τοποθέτησης Σχάρας ανά m² | B19: ='1_Τιμές_Εταιρείας'!$D$18 -> 15 | C19: € / m² | D19: 15,00 €/m² (από Τιμοκατάλογο) | E19: =B19 -> 15 | F19: Εργατικά τοποθέτησης
A20: ΤΕΛΙΚΟ ΚΟΣΤΟΣ ΣΧΑΡΑΣ ΑΝΑ m² (ΑΓΟΡΑ + ΤΟΠΟΘΕΤΗΣΗ) | B20: =B18+B19 -> 35.58 | C20: € / m² | D20: Αγορά + Τοποθέτηση | E20: =B20 -> 35.58 | F20: Συνολικό κόστος ανά m² για την κοστολόγηση
A22: 3. ΥΠΟΛΟΓΙΣΤΗΣ GROUT ΗΛΩΝ (ΤΡΥΠΑ D=12cm, R=0.06m & ΑΠΩΛΕΙΑ * 1.20)
A23: Κανόνας Μάστρου: Τρύπα ΠΑΝΤΑ 12cm (R=0.06m) και συντελεστής απώλειας * 1.20 (20%):
A24: Τύπος Ήλου | B24: Μήκος L (m) | C24: Διάμετρος Οπής D (m) | D24: Ακτίνα R (m) | E24: Όγκος Grout ανά Ήλο (m³) [π × R² × L × 1,20] | F24: Κόστος Grout ανά Ήλο (€) [m³ × 500 €/m³]
A25: Ήλος 7m (Σειρές 1, 2, 3) | B25: 7 | C25: ='1_Τιμές_Εταιρείας'!$D$64 -> 0.12 | D25: =ROUND(C25/2, 3) -> 0.06 | E25: =ROUND(PI()*(D25^2)*B25*'1_Τιμές_Εταιρείας'!$D$65, 4) -> 0.095 | F25: =ROUND(E25*'1_Τιμές_Εταιρείας'!$D$43, 2) -> 47.5
A26: Ήλος 6m (Σειρές 4, 5, 6) | B26: 6 | C26: ='1_Τιμές_Εταιρείας'!$D$64 -> 0.12 | D26: =ROUND(C26/2, 3) -> 0.06 | E26: =ROUND(PI()*(D26^2)*B26*'1_Τιμές_Εταιρείας'!$D$65, 4) -> 0.0814 | F26: =ROUND(E26*'1_Τιμές_Εταιρείας'!$D$43, 2) -> 40.7
A28: 4. ΥΠΟΛΟΓΙΣΤΗΣ ΒΑΡΟΥΣ & ΚΟΣΤΟΥΣ ΠΛΑΚΑΣ ΕΔΡΑΣΗΣ
A29: Εισάγετε τις διαστάσεις της χαλύβδινης πλάκας έδρασης κεφαλής από το σχέδιο (σε mm):
A30: Ύψος H (mm) | B30: Πλάτος W (mm) | C30: Πάχος T (mm) | D30: Όγκος Πλάκας (m³) | E30: Βάρος Πλάκας (kg/τεμ) | F30: Κόστος Πλάκας (€/τεμ)
A31: 200 | B31: 200 | C31: 12 | D31: =ROUND((A31/1000)*(B31/1000)*(C31/1000), 6) -> 0.00048 | E31: =ROUND(D31*'1_Τιμές_Εταιρείας'!$D$63, 3) -> 3.768 | F31: =ROUND(E31*'1_Τιμές_Εταιρείας'!$D$46, 2) -> 7.54

Sheet 4_Κανόνες_&_Πολιτική
A1: ΚΑΝΟΝΕΣ ΤΙΜΟΚΑΤΑΛΟΓΟΥ & ΠΟΛΙΤΙΚΗ ΑΠΟΥΣΙΑΣ ΥΛΙΚΟΥ (MISSING MATERIAL POLICY)
A3: Θέμα / Πεδίο | B3: Κανόνας Λειτουργίας & Οδηγία για το AI
A4: Κανόνας Χρωματισμού | B4: • ΚΙΤΡΙΝΟ (#FFF2CC): Τιμές μονάδας που αλλάζουν με τους καιρούς / συνθήκες αγοράς. • ΛΕΥΚΟ (Χωρίς γέμισμα): Φυσικές σταθερές (7850 kg/m³, π), γεωμετρία και δυναμικοί τύποι. • ΓΑΛΑΖΙΟ (#DDEBF7): Εισαγωγή στοιχείων ανά έργο στους διαδραστικούς υπολογιστές.
A5: Κανόνας Σιδήρου (Σχάρες & Ήλοι) | B5: Ο σίδηρος τιμολογείται ΑΠΟΚΛΕΙΣΤΙΚΑ με βάση το βάρος σε ευρώ ανά κιλό (€/kg): • Σχάρες: 2,50 €/kg αγορά + 15,00 €/m² τοποθέτηση. • Ήλοι: 1,50 €/kg (αγορά + τοποθέτηση + επεξεργασία όλα μαζί). ΔΕΝ υπάρχουν διαφορετικές τιμές ανά Y ούτε λίστα προκατασκευασμένων πλεγμάτων. Τα κιλά υπολογίζονται από τον ενιαίο πίνακα βαρών (Φύλλο 2).
A6: Κανόνας Εκτοξευόμενου Σκυροδέματος | B6: Προς το παρόν υπάρχει μία κατηγορία: C30/37 με 90,00 €/m³ αγορά και 160,00 €/m³ τοποθέτηση. Το πάχος υπολογισμού είναι πάντα: Ονομαστικό πάχος μελέτης + 0,05 m (+5cm πάγια απώλεια).
A7: Κανόνας Grout (Τρύπα 12cm & Απώλεια * 1.20) | B7: • Η διάμετρος τρύπησης είναι ΠΑΝΤΑ 12 cm (R = 0,06 m) ανεξαρτήτως αν η μελέτη αναφέρει 10 cm ή 13 cm. • Στον όγκο του grout προστίθεται ΠΑΝΤΑ απώλεια * 1,20 (+20%). • Ενιαία τιμή grout: 500,00 €/m³.
A8: ΚΑΝΟΝΑΣ ΑΠΟΥΣΙΑΣ ΥΛΙΚΟΥ (ΥΠΟΧΡΕΩΤΙΚΟ ΜΗΝΥΜΑ AI) | B8: Εάν ο μελετητής ζητήσει υλικό που ΔΕΝ υπάρχει στον παρόντα τιμοκατάλογο (π.χ. άλλη κατηγορία σκυροδέματος C35/45, διατομή εκτός πίνακα Y6–Y40, κοίλες ράβδους, ειδικές ίνες): -> Το σύστημα AI ΑΠΑΓΟΡΕΥΕΤΑΙ ΑΥΣΤΗΡΑ να μαντέψει ή να εφεύρει τιμή! -> Το σύστημα ΣΤΑΜΑΤΑΕΙ και εμφανίζει στον χρήστη ρητά το μήνυμα: «Δεν υπάρχει αυτό το είδος ([Όνομα Είδους]) στον τιμοκατάλογο. Καθοδήγησέ με με τιμή να ξέρω.» -> Μόνο αφού ο χρήστης δώσει την τιμή, η κοστολόγηση προχωρά.
A9: Κανόνας Απόστασης (Έδρα Άγιος Συλάς) | B9: Αφετηρία: Άγιος Συλάς, Σπύρου Κυπριανού 32, Λεμεσός. • Ζώνη 1 (0 – 50 km): Βασική τιμή στράτας (200 € shotcrete, 300 € ήλοι). • Κάθε επιπλέον 50 km (ή μέρος αυτών): +50,00 € ανά στράτα αυτόματα.
