Workbook

Sheet 1_Στοιχεία_Μελέτης_&_Ποσότητες
A1: ΕΡΓΟ: THE HUB (Μ.Π. 421) — ΠΡΟΣΩΡΙΝΟΣ ΤΟΙΧΟΣ ΑΝΤΙΣΤΗΡΙΞΗΣ ΤΥΠΟΥ 'ΒΕΡΟΛΙΝΟ' (ΣΤΟΙΧΕΙΑ ΜΕΛΕΤΗΣ & ΠΟΣΟΤΗΤΕΣ ΧΩΡΙΣ €)
A2: ΑΡΧΙΤΕΚΤΟΝΙΚΗ v8 (BOX LAYOUT): [ΚΕΦΑΛΑΙΟ Α] = RAW INPUTS, CITATIONS & AUDITING | [ΚΕΦΑΛΑΙΟ Β] = 100% ΔΥΝΑΜΙΚΟΙ ΥΠΟΛΟΓΙΣΜΟΙ ΦΥΣΙΚΩΝ ΜΕΓΕΘΩΝ
A4: 🏛️ ΚΕΦΑΛΑΙΟ Α: ΣΤΟΙΧΕΙΑ ΠΟΥ ΔΙΑΒΑΣΤΗΚΑΝ ΑΠΟ ΤΗ ΜΕΛΕΤΗ (RAW INPUTS, CITATIONS & ΕΛΕΓΧΟΣ ΚΑΝΟΝΩΝ)
A5: Κουτί / Κωδ. | B5: Περιγραφή Στοιχείου Μελέτης | C5: Τιμή Μελέτης | D5: Μονάδα | E5: Πηγή Μελέτης (Σχέδιο / Σελίδα) | F5: Τεχνική Σημείωση / Έλεγχος Κανόνα (Auditing)
A6: 📦 ΚΟΥΤΙ [ΚΟΙΝΑ]: ΓΕΝΙΚΑ ΣΤΟΙΧΕΙΑ ΕΡΓΟΥ, ΣΧΑΡΕΣ, SHOTCRETE, ΛΑΜΕΣ ΣΥΝΔΕΣΗΣ & ΓΩΝΙΕΣ ΣΤΗΡΙΞΗΣ
A7: ΚΟΙΝΑ | B7: Έδρα Εταιρείας (Αφετηρία Μετακινήσεων) | C7: Άγιος Συλάς, Σπύρου Κυπριανού 32, Λεμεσός | D7: - | E7: Τιμοκατάλογος Εταιρείας §1 | F7: Σταθερή βάση εκκίνησης συνεργείων και μηχανημάτων (ΘΕΜΕΛΙΟΤΕΧΝΙΚΗ ΛΤΔ).
A8: ΚΟΙΝΑ | B8: Τοποθεσία Εργοταξίου (Έργο: The Hub - Μ.Π. 421) | C8: Λεμεσός (Οδός Μισιαούλη & Καβάζογλου) | D8: - | E8: Σχέδιο CB01 (Σελ. 1), Κάτοψη 1:250 | F8: Οδός Μισιαούλη & Καβάζογλου / Οδός Εμίρ, Τεμ. 609–615, Λεμεσός (Cybarco Development Ltd).
A9: ΚΟΙΝΑ | B9: Χιλιομετρική Απόσταση Εργοταξίου από Έδρα | C9: 8 | D9: km | E9: Σχέδιο CB01 (Σελ. 1) / Google Maps | F9: Εντός βασικής ακτίνας 0–40 km Λεμεσού (μηδενική χιλιομετρική επιβάρυνση στρατών).
A10: ΚΟΙΝΑ | B10: Οριζόντιο Βήμα Τοποθέτησης Νεφκών (s_c/c) | C10: 2 | D10: m | E10: Σχέδιο CD01 (Σελ. 2), Λεπτ. 1 (1:10) | F10: Αναγράφεται ρητά '2000 ΤΥΠ' (2000 mm = 2.00 m κέντρο με κέντρο) στην Τυπική Κάτοψη Τοίχου 1.
A11: ΚΟΙΝΑ | B11: Διάμετρος Οπής Διάτρησης Μεγάλου Τρυπανιού (D_pile) | C11: 0.8 | D11: m | E11: Σχέδιο CD01 (Σελ. 2), Λεπτ. 1 & 3 | F11: [DEFAULT / OVERRIDE ΚΑΝΟΝΑ ΕΤΑΙΡΕΙΑΣ]: Δεν αναγράφεται αριθμητικά διάμετρος οπής στη μελέτη (σχεδιαστικά ~500mm). Εφαρμόζεται υποχρεωτικά Ø800 mm (0.80 m) βάσει κανόνα ελάχιστης διαμέτρου εταιρείας.
A12: ΚΟΙΝΑ | B12: Τύπος Δομικού Πλέγματος Σχάρας Μετώπου | C12: A252 (B500B) | D12: - | E12: Σχέδιο CD01 (Σελ. 2), Λεπτ. 1 & Υλικά §2 | F12: Αναγράφεται ρητά 'ΣΧΑΡΑ ΟΠΛΙΣΜΟΥ Α252' (Λεπτ. 1) & 'ΟΠΛΙΣΜΟΣ Α252 Β500Β' (Υλικά §2: Y8 @ 200×200 mm).
A13: ΚΟΙΝΑ | B13: Διάμετρος Ράβδων Σχάρας Μετώπου (d_mesh) | C13: 8 | D13: mm | E13: Σχέδιο CD01 (Σελ. 2), Λεπτ. 1 & Υλικά §2 | F13: Τυποποιημένο δομικό πλέγμα A252 (ράβδοι Y8 = 8 mm, 3.95 kg/m²).
A14: ΚΟΙΝΑ | B14: Οριζόντιο Βήμα Ράβδων Σχάρας (s_horiz) | C14: 200 | D14: mm | E14: Σχέδιο CD01 (Σελ. 2), Λεπτ. 1 & Υλικά §2 | F14: Τυποποιημένο βήμα πλέγματος A252 (200 mm οριζόντια).
A15: ΚΟΙΝΑ | B15: Κάθετο Βήμα Ράβδων Σχάρας (s_vert) | C15: 200 | D15: mm | E15: Σχέδιο CD01 (Σελ. 2), Λεπτ. 1 & Υλικά §2 | F15: Τυποποιημένο βήμα πλέγματος A252 (200 mm κάθετα).
A16: ΚΟΙΝΑ | B16: Κατηγορία Εκτοξευόμενου Σκυροδέματος (Shotcrete) | C16: C20/25 | D16: - | E16: Σχέδιο CD01 (Σελ. 2), Λεπτ. 1 & Υλικά §2 | F16: [OVERRIDE / DEFAULT ΤΙΜΟΚΑΤΑΛΟΓΟΥ]: Η μελέτη ζητά C20/25 (fck=20MPa). Τιμολογείται με τη στάνταρ τιμή Shotcrete του τιμοκαταλόγου εταιρείας (90 €/m³ αγορά, 200 €/m³ βάση).
A17: ΚΟΙΝΑ | B17: Ονομαστικό Πάχος Shotcrete Μελέτης (t_shot) | C17: 0.12 | D17: m | E17: Σχέδιο CD01 (Σελ. 2), Λεπτ. 1 (1:10) | F17: Αναγράφεται ρητά 'ΕΚΤΟΞΕΥΟΜΕΝΟ ΣΚΥΡΟΔΕΜΑ C20/25 ΜΕΣΟ ΠΑΧΟΣ 120mm' (0.12 m).
A18: ΚΟΙΝΑ | B18: Πάγια Απώλεια / Αναπήδηση Shotcrete Εταιρείας (t_loss) | C18: 0.05 | D18: m | E18: Κανόνας Εταιρείας / Τιμοκατάλογος §Β | F18: [DEFAULT ΕΤΑΙΡΕΙΑΣ]: +0.05 m (+5 cm) πάγια προσαύξηση πάχους για αναπήδηση/υπερκατανάλωση (ενσωματώνεται στην τιμή εφαρμογής €/m³).
A19: ΚΟΙΝΑ | B19: Κατακόρυφο Βήμα Λαμών Σύνδεσης Νεφκών (s_plate) | C19: 2 | D19: m | E19: Σχέδιο CD01 (Σελ. 2), Λεπτ. 1 & Λεπτ. 2 | F19: Αναγράφεται 'ΑΝΑ 2000mm ΚΑΘ' ΥΨΟΣ' (Λεπτ. 1) και 'ΠΕΡΙΠΟΥ ΑΝΑ 2m ΚΑΘ' ΥΨΟΣ' (Λεπτ. 2).
A20: ΚΟΙΝΑ | B20: Πλάτος Λάμας Σύνδεσης Νεφκών (b_plate) | C20: 350 | D20: mm | E20: Σχέδιο CD01 (Σελ. 2), Λεπτ. 1 & Λεπτ. 2 | F20: Αναγράφεται 350 mm (350x100x10 στη Λεπτ. 1 και 350x100x6 στη Λεπτ. 2).
A21: ΚΟΙΝΑ | B21: Μήκος / Ύψος Λάμας Σύνδεσης Νεφκών (h_plate) | C21: 100 | D21: mm | E21: Σχέδιο CD01 (Σελ. 2), Λεπτ. 1 & Λεπτ. 2 | F21: Αναγράφεται 100 mm (350x100x10 στη Λεπτ. 1 και 350x100x6 στη Λεπτ. 2).
A22: ΚΟΙΝΑ | B22: Πάχος Λάμας Σύνδεσης Νεφκών (t_plate) | C22: 10 | D22: mm | E22: Σχέδιο CD01 (Σελ. 2), Λεπτ. 1 vs Λεπτ. 2 | F22: [!!! ΣΥΓΚΡΟΥΣΗ ΜΕΛΕΤΗΣ !!!]: Στη Λεπτ. 1 (Τυπική Κάτοψη 1:10) αναγράφεται '350x100x10' (10mm), ενώ στη Λεπτ. 2 (Τυπική Όψη 1:50) αναγράφεται '350x100x6' (6mm). Βάσει Κανόνα 3.3 επιλέγεται υποχρεωτικά το στατικά ασφαλέστερο πάχος 10 mm!
A23: ΚΟΙΝΑ | B23: ="Βάρος 1 Λάμας Σύνδεσης (" & C20 & "×" & C21 & "×" & C22 & " mm)" | C23: =ROUND((C20/1000)*(C21/1000)*(C22/1000)*7850, 4) | D23: kg / τεμ. | E23: Μαθηματικός Τύπος (Κανόνας 3.2.1) | F23: ="= (" & C20 & "/1000) × (" & C21 & "/1000) × (" & C22 & "/1000) × 7850 = " & TEXT(C23,"0.0000") & " kg/τεμ. (100% δυναμικός υπολογισμός)"
A24: ΚΟΙΝΑ | B24: Ύπαρξη Γωνιών Στήριξης Σχάρας στο Σχέδιο (L-Angles) | C24: ΝΑΙ | D24: - | E24: Σχέδιο CD01 (Σελ. 2), Λεπτ. 1 (1:10) | F24: Αναγράφεται ρητά 'L70x6 ΚΑΘ' ΥΨΟΣ' στις δύο παρειές του ζεύγους UPN 240 στην Τυπική Κάτοψη 1.
A25: ΚΟΙΝΑ | B25: Διατομή Γωνιών Στήριξης Σχάρας | C25: L 70x70x6 | D25: - | E25: Σχέδιο CD01 (Σελ. 2), Λεπτ. 1 & Φύλλο 3 | F25: Ισοσκελής γωνία L 70x70x6 (βλ. Φύλλο 3, Γραμμή 44).
A26: ΚΟΙΝΑ | B26: ="Θεωρητικό Βάρος Γωνίας Στήριξης (" & C25 & ")" | C26: ='3_Πίνακες_Διατομών_Χάλυβα'!G44 | D26: kg / m | E26: Φύλλο 3 (Πίνακας Γωνιών L, Γρ. 44) | F26: ="= " & TEXT(C26,"0.00") & " kg/m από Βιβλιοθήκη Διατομών (2 γωνιές ανά οπή καθ' όλο το ελεύθερο ύψος H_exc)."
A28: ="📦 ΚΟΥΤΙ [TYPE A]: ΠΕΡΙΜΕΤΡΙΚΟΣ ΤΟΙΧΟΣ ΑΝΤΙΣΤΗΡΙΞΗΣ ΤΥΠΟΥ 'ΒΕΡΟΛΙΝΟ' (" & C32 & " × " & C31 & " | L = " & TEXT(C30,"#,##0.00") & " m | H_exc = " & TEXT(C35,"0.00") & " m)"
A29: TYPE A | B29: Πλήθος Οπών / Νεφκών Μετώπου Type A (N_piles) | C29: 120 | D29: οπές | E29: Σχέδιο CB01 (1:250) & Σχέδιο CD01 (1:500) | F29: ="Καταμέτρηση OpenCV επί της περιμέτρου υπογείου (240.00 m / " & TEXT(C10,"0.00") & " m c/c = " & C29 & " οπές/νέφκες)."
A30: TYPE A | B30: ="Αναπτυγμένο Μήκος Μετώπου Type A (" & C29 & " × " & TEXT(C10,"0.00") & " m)" | C30: =ROUND(C29*C10, 2) | D30: m | E30: Σχέδιο CB01 (1:250) & Σχέδιο CD01 (Λεπτ. 1) | F30: ="= " & C29 & " διαστήματα × " & TEXT(C10,"0.00") & " m c/c = " & TEXT(C30,"#,##0.00") & " m συνολική περίμετρος αντιστήριξης."
A31: TYPE A | B31: Τύπος Χαλύβδινης Διατομής Νέφκας (S275) | C31: UPN 240 | D31: - | E31: Σχέδιο CD01 (Σελ. 2), Λεπτ. 1 & Υλικά §3 | F31: Αναγράφεται ρητά 'UPN 240' στην Τυπική Κάτοψη 1 & 'ΚΑΤΗΓΟΡΙΑ ΧΑΛΥΒΑ S275' στα Υλικά §3.
A32: TYPE A | B32: Πλήθος Προφίλ ανά Οπή Νέφκας (Ζεύγος UPN) | C32: 2 | D32: προφίλ/οπή | E32: Σχέδιο CD01 (Σελ. 2), Λεπτ. 1, 2, 5 & 7 | F32: Ζεύγος (2 τεμάχια) UPN 240 ανά διάτρημα σε διάταξη πλάτη-με-πλάτη ώστε να διέρχονται τα αγκύρια.
A33: TYPE A | B33: ="Θεωρητικό Βάρος 1 Προφίλ (" & C31 & ")" | C33: ='3_Πίνακες_Διατομών_Χάλυβα'!G35 | D33: kg / m | E33: Φύλλο 3 (Πίνακας UPN, Γρ. 35) | F33: ="= " & TEXT(C33,"0.00") & " kg/m ανά προφίλ " & C31 & " από Βιβλιοθήκη Διατομών Χάλυβα."
A34: TYPE A | B34: ="Συνολικό Βάρος Νέφκας ανά Μέτρο Οπής (" & C32 & " × " & C31 & ")" | C34: =ROUND(C32*C33, 2) | D34: kg / m | E34: Μαθηματικός Τύπος (C32 × C33) | F34: ="= " & C32 & " προφίλ × " & TEXT(C33,"0.00") & " kg/m = " & TEXT(C34,"0.00") & " kg/m ανά μέτρο νέφκας."
A35: TYPE A | B35: Ελεύθερο Ύψος Εκσκαφής Μετώπου (H_exc) | C35: 8.5 | D35: m | E35: Σχέδιο CD01 (Σελ. 2), Λεπτ. 2 (1:50) & Λεπτ. 3 | F35: Ανεξάρτητο Raw Input (Κανόνας 3.5): Αναγράφεται ρητά 8500 mm (= 1000 + 2000 + 2500 + 3000 mm = 8.50 m).
A36: TYPE A | B36: Ύψος Πάκτωσης Σκυροδέματος C30/37 στη Βάση (H_embed) | C36: 3.5 | D36: m | E36: Σχέδιο CD01 (Σελ. 2), Λεπτ. 2 & Λεπτ. 3 | F36: Ανεξάρτητο Raw Input (Κανόνας 3.5): Υπόγειο τμήμα 12000 - 8500 = 3500 mm (3.50 m) πληρωμένο με σκυρόδεμα C30/37.
A37: TYPE A | B37: Συνολικό Μήκος Χαλύβδινης Νέφκας Μελέτης (L_beam) | C37: 12 | D37: m | E37: Σχέδιο CD01 (Σελ. 2), Λεπτ. 2 (1:50) & Λεπτ. 3 | F37: Ανεξάρτητο Raw Input (Κανόνας 3.5): Αναγράφεται ρητά 12000 mm (12.00 m) τόσο στην Τυπική Όψη 2 όσο και στην Τυπική Τομή 3.
A38: TYPE A | B38: Ύψος Εκσκαφής / Διάτρησης Νέφκας βάσει WPL / Cut-Off Level (L_drill_WPL) | D38: m | E38: Έλεγχος WPL / Cut-Off Level (Κανόνας 3.8) | F38: =IF(ISBLANK(C38), "[!!! ΕΛΛΕΙΨΗ WPL / CUT-OFF LEVEL — ΚΟΚΚΙΝΟ ΚΕΛΙ !!!]: Δεν δόθηκε WPL / Cut-Off Level στη μελέτη. Θεωρείται ότι το ύψος εκσκαφής/διάτρησης ισούται με το μήκος της νέφκας (" & TEXT(C37,"0.00") & " m). Συμπληρώστε εδώ το ύψος εκσκαφής βάσει WPL αν διαφέρει!", "[ΕΦΑΡΜΟΓΗ WPL / CUT-OFF LEVEL]: Το ύψος εκσκαφής/διάτρησης νεφκών ορίστηκε βάσει WPL σε " & TEXT(C38,"0.00") & " m (αντί " & TEXT(C37,"0.00") & " m της νέφκας χάλυβα).")
A39: TYPE A | B39: Ενεργό Ύψος Διάτρησης Μεγάλου Τρυπανιού (L_drill_active) | C39: =IF(ISBLANK(C38), C37, C38) | D39: m / οπή | E39: Κανόνας 3.8: =IF(ISBLANK(WPL), L_beam, WPL) | F39: ="= " & TEXT(C39,"0.00") & " m/οπή (καθορίζει αποκλειστικά τα μέτρα διάτρησης A.1 και τα κυβικά εκσκαφής A.1α)."
A40: TYPE A | B40: Πλήθος Οριζόντιων Σειρών Αγκυρώσεων Type A | C40: 3 | D40: σειρές | E40: Σχέδιο CD01 (Σελ. 2), Λεπτ. 2 & Λεπτ. 3 | F40: 3 οριζόντιες σειρές προεντεταμένων αγκυρίων σε βάθη -1.00 m, -3.00 m και -5.50 m από τη στέψη (κλίση 27° ΤΥΠ).
A41: TYPE A | B41: Πλήθος Αγκυρώσεων 1ης Σειράς (Βάθος -1.00m, Stress 150kN) | C41: =C29 | D41: τεμ. | E41: Σχέδιο CD01 (Σελ. 2), Λεπτ. 1, 2 & 3 | F41: ="= " & C41 & " αγκυρώσεις (1 αγκύριο ανά νέφκα στη Σειρά 1, δυναμικά συνδεδεμένο με C29)."
A42: TYPE A | B42: Ελεύθερο Μήκος Αγκυρίου 1ης Σειράς (L_free_1) | C42: 4 | D42: m | E42: Σχέδιο CD01 (Σελ. 2), Λεπτ. 4 (ΧΚ) | F42: Αναγράφεται ρητά '4000' (4.00 m) στο πρώτο τμήμα του αγκυρίου από την παρειά του τοίχου έως τον βολβό πάκτωσης.
...

Sheet 2_Υπολογισμοί_&_Κοστολόγηση
A1: ΕΡΓΟ: THE HUB (Μ.Π. 421) — ΟΙΚΟΝΟΜΙΚΗ ΠΡΟΣΦΟΡΑ & ΚΟΣΤΟΛΟΓΗΣΗ BERLIN WALL (ΣΕ ΚΟΥΤΙΑ ΑΝΑ ΤΥΠΟ — ΧΩΡΙΣ Φ.Π.Α.)
A2: ΚΙΤΡΙΝΟ (#FFF2CC) = Τιμές Μονάδας Εταιρείας | ΠΟΡΤΟΚΑΛΙ (#FFE699) = Κουγκρί Πάκτωσης (120 €/m³) | Γενικά Έξοδα & Όφελος ενσωματωμένα στις τιμές | ΧΩΡΙΣ Φ.Π.Α.
A4: Κωδ. | B4: Περιγραφή Εργασίας / Υλικού (Δυναμική Σύνδεση) | C4: Ποσότητα | D4: Μονάδα | E4: Τιμή Μονάδας (€) | F4: Συνολικό Κόστος (€) | G4: ΤΕΛ. ΣΥΝΟΛΑ ΚΟΥΤΙΟΥ (€) | H4: Πηγή Ποσότητας & Τεχνικός Κανόνας Κοστολόγησης
A5: ="📦 ΚΟΥΤΙ [TYPE A]: ΠΕΡΙΜΕΤΡΙΚΟΣ ΤΟΙΧΟΣ ΑΝΤΙΣΤΗΡΙΞΗΣ ΤΥΠΟΥ 'ΒΕΡΟΛΙΝΟ' — " & TEXT('1_Στοιχεία_Μελέτης_&_Ποσότητες'!C30,"#,##0.00") & " τρ.μ. | " & TEXT(ROUND(G6/'1_Στοιχεία_Μελέτης_&_Ποσότητες'!C30,2),"#,##0.00") & " €/τρ.μ. | ΣΥΝΟΛΟ: " & TEXT(G6,"#,##0.00") & " €"
A6: A.1 | B6: ="[ΠΥΛ. 3] Διάτρηση Μεγάλου Τρυπανιού (Ø" & TEXT('1_Στοιχεία_Μελέτης_&_Ποσότητες'!C11*1000,"0") & " mm)" | C6: ='1_Στοιχεία_Μελέτης_&_Ποσότητες'!C74 | D6: m | E6: 75 | F6: =ROUND(C6*E6, 2) | G6: =SUM(F6:F19) | H6: ="Από Φύλλο 1 (A.1): " & '1_Στοιχεία_Μελέτης_&_Ποσότητες'!C29 & " οπές × " & TEXT('1_Στοιχεία_Μελέτης_&_Ποσότητες'!C39,"0.00") & " m = " & TEXT(C6,"#,##0.00") & " m × " & TEXT(E6,"0.00") & " €/m"
A7: A.2 | B7: ="[ΠΥΛ. 3] Χάλυβας Νεφκών (" & '1_Στοιχεία_Μελέτης_&_Ποσότητες'!C32 & " × " & '1_Στοιχεία_Μελέτης_&_Ποσότητες'!C31 & " S275 — Αγορά + Επεξεργασία)" | C7: ='1_Στοιχεία_Μελέτης_&_Ποσότητες'!C76 | D7: kg | E7: 1.4 | F7: =ROUND(C7*E7, 2) | H7: ="Από Φύλλο 1 (A.2): " & TEXT(C7,"#,##0.00") & " kg × " & TEXT(E7,"0.00") & " €/kg (1.00 € αγορά + 0.40 € επεξεργασία/τοποθέτηση)"
A8: A.3 | B8: ="[ΠΥΛ. 3] Λάμες Σύνδεσης Νεφκών (" & '1_Στοιχεία_Μελέτης_&_Ποσότητες'!C20 & "×" & '1_Στοιχεία_Μελέτης_&_Ποσότητες'!C21 & "×" & '1_Στοιχεία_Μελέτης_&_Ποσότητες'!C22 & " mm)" | C8: ='1_Στοιχεία_Μελέτης_&_Ποσότητες'!C79 | D8: kg | E8: 1.6 | F8: =ROUND(C8*E8, 2) | H8: ="Από Φύλλο 1 (A.3): " & '1_Στοιχεία_Μελέτης_&_Ποσότητες'!C78 & " τεμ. (" & TEXT(C8,"#,##0.00") & " kg) × " & TEXT(E8,"0.00") & " €/kg (1.00 € αγορά + 0.60 € συγκόλληση)"
A9: A.4 | B9: ="[ΠΥΛ. 3] Κουγκρί Πάκτωσης Βάσης Νεφκών C30/37 (H_embed = " & TEXT('1_Στοιχεία_Μελέτης_&_Ποσότητες'!C36,"0.00") & " m)" | C9: ='1_Στοιχεία_Μελέτης_&_Ποσότητες'!C80 | D9: m³ | E9: 120 | F9: =ROUND(C9*E9, 2) | H9: ="Από Φύλλο 1 (A.4): " & TEXT(C9,"#,##0.00") & " m³ × " & TEXT(E9,"0.00") & " €/m³ [ΠΟΡΤΟΚΑΛΙ ΚΕΛΙ ΓΙΑ ΕΠΙΒΕΒΑΙΩΣΗ]"
A10: A.5 | B10: ="[ΠΥΛ. 3] Γωνιές Στήριξης Σχάρας (2 × " & '1_Στοιχεία_Μελέτης_&_Ποσότητες'!C25 & " καθ' ύψος)" | C10: ='1_Στοιχεία_Μελέτης_&_Ποσότητες'!C82 | D10: kg | E10: 1.6 | F10: =ROUND(C10*E10, 2) | H10: ="Από Φύλλο 1 (A.5): " & TEXT('1_Στοιχεία_Μελέτης_&_Ποσότητες'!C81,"#,##0.00") & " m (" & TEXT(C10,"#,##0.00") & " kg) × " & TEXT(E10,"0.00") & " €/kg"
A11: A.6 | B11: ="[ΠΥΛ. 2] Αγορά Χάλυβα Σχάρας Μετώπου (" & '1_Στοιχεία_Μελέτης_&_Ποσότητες'!C12 & " — Y" & '1_Στοιχεία_Μελέτης_&_Ποσότητες'!C13 & " @ " & '1_Στοιχεία_Μελέτης_&_Ποσότητες'!C14 & "×" & '1_Στοιχεία_Μελέτης_&_Ποσότητες'!C15 & " mm)" | C11: ='1_Στοιχεία_Μελέτης_&_Ποσότητες'!C83 | D11: kg | E11: 2.5 | F11: =ROUND(C11*E11, 2) | H11: ="Από Φύλλο 1 (A.6): " & TEXT(C11,"#,##0.00") & " kg × " & TEXT(E11,"0.00") & " €/kg"
A12: A.7 | B12: ="[ΠΥΛ. 2] Τοποθέτηση Σχάρας Μετώπου / Εργατικά (" & '1_Στοιχεία_Μελέτης_&_Ποσότητες'!C12 & ")" | C12: ='1_Στοιχεία_Μελέτης_&_Ποσότητες'!C84 | D12: m² | E12: 15 | F12: =ROUND(C12*E12, 2) | H12: ="Από Φύλλο 1 (A.7): " & TEXT(C12,"#,##0.00") & " m² × " & TEXT(E12,"0.00") & " €/m² ενιαία τιμή τοποθέτησης"
A13: A.8 | B13: ="[ΠΥΛ. 2] Αγορά Σκυροδέματος Shotcrete (" & '1_Στοιχεία_Μελέτης_&_Ποσότητες'!C16 & ", πάχος " & TEXT('1_Στοιχεία_Μελέτης_&_Ποσότητες'!C17*100,"0") & " cm)" | C13: ='1_Στοιχεία_Μελέτης_&_Ποσότητες'!C85 | D13: m³ | E13: 90 | F13: =ROUND(C13*E13, 2) | H13: ="Από Φύλλο 1 (A.8): " & TEXT(C13,"#,##0.00") & " m³ ονομαστικός όγκος × " & TEXT(E13,"0.00") & " €/m³ αγορά κουγκριού"
A14: A.9 | B14: ="[ΠΥΛ. 2] Εφαρμογή / Εκτόξευση Shotcrete (με +" & TEXT('1_Στοιχεία_Μελέτης_&_Ποσότητες'!C18*100,"0") & " cm απώλεια)" | C14: ='1_Στοιχεία_Μελέτης_&_Ποσότητες'!C85 | D14: m³ | E14: =ROUND((IF(C13>7, 200, 250)*(1+'1_Στοιχεία_Μελέτης_&_Ποσότητες'!C64))-E13, 2) | F14: =ROUND(C14*E14, 2) | H14: ="Βάση " & IF(C13>7,200,250) & "€ × (1 + " & TEXT('1_Στοιχεία_Μελέτης_&_Ποσότητες'!C64,"0.0%") & " απώλεια) - " & TEXT(E13,"0.00") & "€ αγορά = " & TEXT(E14,"0.00") & " €/m³"
A15: A.10 | B15: ="[ΠΥΛ. 4] Διάτρηση Προεντεταμένων Αγκυρώσεων (" & '1_Στοιχεία_Μελέτης_&_Ποσότητες'!C40 & " Σειρές × " & '1_Στοιχεία_Μελέτης_&_Ποσότητες'!C29 & " οπές × " & TEXT('1_Στοιχεία_Μελέτης_&_Ποσότητες'!C44,"0.00") & " m)" | C15: ='1_Στοιχεία_Μελέτης_&_Ποσότητες'!C87 | D15: m | E15: 30 | F15: =ROUND(C15*E15, 2) | H15: ="Από Φύλλο 1 (A.10): " & TEXT(C15,"#,##0.00") & " m × " & TEXT(E15,"0.00") & " €/m (κλίση 27°, 4m ελεύθερο + 12m πακτωμένο)"
A16: A.11 | B16: ="[ΠΥΛ. 4] Grout Τσιμεντένεμα Αγκυρώσεων (Ø" & TEXT('1_Στοιχεία_Μελέτης_&_Ποσότητες'!C67*1000,"0") & " mm × " & TEXT('1_Στοιχεία_Μελέτης_&_Ποσότητες'!C68,"0.00") & ")" | C16: ='1_Στοιχεία_Μελέτης_&_Ποσότητες'!C88 | D16: m³ | E16: 500 | F16: =ROUND(C16*E16, 2) | H16: ="Από Φύλλο 1 (A.11): " & TEXT(C16,"#,##0.00") & " m³ × " & TEXT(E16,"0.00") & " €/m³ (fck=35MPa)"
A17: A.12 | B17: ="[ΠΥΛ. 4] Τένοντες Προέντασης 0.6'' (" & '1_Στοιχεία_Μελέτης_&_Ποσότητες'!C45 & " Strands/οπή, S 1570/1770)" | C17: ='1_Στοιχεία_Μελέτης_&_Ποσότητες'!C89 | D17: m | E17: 2.28 | F17: =ROUND(C17*E17, 2) | H17: ="Από Φύλλο 1 (A.12): " & TEXT(C17,"#,##0.00") & " m τενόντων (συμπερ. +" & TEXT('1_Στοιχεία_Μελέτης_&_Ποσότητες'!C66,"0.0") & "m) × " & TEXT(E17,"0.00") & " €/m"
A18: A.13 | B18: [ΠΥΛ. 4] Προένταση Αγκυρώσεων (Stressing & Lock-off: 150kN / 270kN / 300kN) | C18: ='1_Στοιχεία_Μελέτης_&_Ποσότητες'!C86 | D18: τεμ. | E18: 18 | F18: =ROUND(C18*E18, 2) | H18: ="Από Φύλλο 1 (A.9): " & TEXT(C18,"#,##0") & " αγκυρώσεις × " & TEXT(E18,"0.00") & " €/τεμ. (τάνυση, δοκιμή & κλείδωμα)"
A19: A.14 | B19: [ΠΥΛ. 4] Κεφαλές Αγκύρωσης (Anchor Head, Wedges, Bearing Plate Λεπτ. 4–7) | C19: ='1_Στοιχεία_Μελέτης_&_Ποσότητες'!C86 | D19: τεμ. | E19: 55 | F19: =ROUND(C19*E19, 2) | H19: ="Από Φύλλο 1 (A.9): " & TEXT(C19,"#,##0") & " πλήρη σετ κεφαλών, σφηνών & πλακών × " & TEXT(E19,"0.00") & " €/τεμ."
A21: ="📦 ΚΟΥΤΙ [ΠΥΛ. 1]: ΜΕΤΑΚΙΝΗΣΕΙΣ ΕΞΟΠΛΙΣΜΟΥ & ΣΥΝΕΡΓΕΙΩΝ (Απόσταση: " & '1_Στοιχεία_Μελέτης_&_Ποσότητες'!C9 & " km — Λεμεσός) | ΣΥΝΟΛΟ: " & TEXT(G22,"#,##0.00") & " €"
A22: M.1 | B22: ="Μετακίνηση Μεγάλου Τρυπανιού (Piling Rig — Απόσταση " & '1_Στοιχεία_Μελέτης_&_Ποσότητες'!C9 & " km)" | C22: ='1_Στοιχεία_Μελέτης_&_Ποσότητες'!C93 | D22: στράτες | E22: =1500+IF('1_Στοιχεία_Μελέτης_&_Ποσότητες'!C9>80,1500,IF('1_Στοιχεία_Μελέτης_&_Ποσότητες'!C9>40,500,0)) | F22: =ROUND(C22*E22, 2) | G22: =SUM(F22:F24) | H22: ="Βασική ζώνη Λεμεσού (0–40 km): 1,500.00 € / στράτα (+500€ για 40–80km, +1500€ για >80km)"
A23: M.2 | B23: ="Μετακινήσεις Εξοπλισμού Αγκυρώσεων (" & '1_Στοιχεία_Μελέτης_&_Ποσότητες'!C40 & " οριζόντιες σειρές)" | C23: ='1_Στοιχεία_Μελέτης_&_Ποσότητες'!C94 | D23: στράτες | E23: =300+MAX(0,ROUNDUP(('1_Στοιχεία_Μελέτης_&_Ποσότητες'!C9-40)/40,0))*50 | F23: =ROUND(C23*E23, 2) | H23: ="1 στράτα ανά οριζόντια σειρά αγκυρώσεων = " & C23 & " στράτες × " & TEXT(E23,"0.00") & " €"
A24: M.3 | B24: ="Μετακινήσεις Συνεργείου & Αντλίας Shotcrete (" & '1_Στοιχεία_Μελέτης_&_Ποσότητες'!C40 & " + 1 στράτες)" | C24: ='1_Στοιχεία_Μελέτης_&_Ποσότητες'!C95 | D24: στράτες | E24: =200+MAX(0,ROUNDUP(('1_Στοιχεία_Μελέτης_&_Ποσότητες'!C9-40)/40,0))*50 | F24: =ROUND(C24*E24, 2) | H24: ="Σειρές αγκυρώσεων + 1 = " & C24 & " στράτες × " & TEXT(E24,"0.00") & " €"
A26: 📊 ΣΥΓΚΕΝΤΡΩΤΙΚΟΣ ΠΙΝΑΚΑΣ ΑΝΑ ΤΥΠΟ ΤΟΙΧΟΥ, CROSS-CHECK 4 ΠΥΛΩΝΩΝ & ΤΕΛΙΚΟ ΣΥΝΟΛΟ ΠΡΟΣΦΟΡΑΣ (ΧΩΡΙΣ Φ.Π.Α.)
A27: ΣΥΝ.Α | B27: ="Σύνολο Κουτιού [TYPE A] — Περιμετρικός Τοίχος Βερολίνου (" & TEXT('1_Στοιχεία_Μελέτης_&_Ποσότητες'!C30,"#,##0.00") & " τρ.μ. / " & TEXT('1_Στοιχεία_Μελέτης_&_Ποσότητες'!C73,"#,##0.00") & " m²)" | F27: =G6 | G27: =G6/F33 | H27: ="Πλήρες κόστος H-Beams, Σχάρας/Shotcrete & Αγκυρώσεων Type A (" & TEXT(ROUND(G6/'1_Στοιχεία_Μελέτης_&_Ποσότητες'!C30,2),"#,##0.00") & " €/τρ.μ.)"
A28: ΠΥΛ.1 | B28: Πυλώνας 1: Μετακινήσεις Εξοπλισμού & Συνεργείων (Piling Rig, Αγκυρώσεις, Shotcrete) | F28: =G22 | G28: =G22/F33 | H28: ="Σύνολο Κουτιού Μετακινήσεων (" & (C22+C23+C24) & " στράτες συνολικά στη Λεμεσό)"
A29: ΠΥΛ.2 | B29: ="[Cross-Check] Πυλώνας 2: Σχάρες (" & '1_Στοιχεία_Μελέτης_&_Ποσότητες'!C12 & ") & Shotcrete (" & '1_Στοιχεία_Μελέτης_&_Ποσότητες'!C16 & ", " & TEXT('1_Στοιχεία_Μελέτης_&_Ποσότητες'!C17*100,"0") & " cm)" | F29: =SUM(F11:F14) | G29: =F29/F33 | H29: ="= Αγορά Σχάρας (" & TEXT(F11,"#,##0.00") & "€) + Τοποθέτηση (" & TEXT(F12,"#,##0.00") & "€) + Shotcrete (" & TEXT(F13+F14,"#,##0.00") & "€)"
A30: ΠΥΛ.3 | B30: ="[Cross-Check] Πυλώνας 3: Νέφκες (" & '1_Στοιχεία_Μελέτης_&_Ποσότητες'!C32 & "×" & '1_Στοιχεία_Μελέτης_&_Ποσότητες'!C31 & "), Διάτρηση Ø" & TEXT('1_Στοιχεία_Μελέτης_&_Ποσότητες'!C11*1000,"0") & ", Λάμες, Κουγκρί & Γωνιές" | F30: =SUM(F6:F10) | G30: =F30/F33 | H30: ="= Διάτρηση (" & TEXT(F6,"#,##0.00") & "€) + UPN (" & TEXT(F7,"#,##0.00") & "€) + Λάμες (" & TEXT(F8,"#,##0.00") & "€) + Κουγκρί (" & TEXT(F9,"#,##0.00") & "€) + Γωνιές (" & TEXT(F10,"#,##0.00") & "€)"
A31: ΠΥΛ.4 | B31: ="[Cross-Check] Πυλώνας 4: Προεντεταμένες Αγκυρώσεις (" & '1_Στοιχεία_Μελέτης_&_Ποσότητες'!C86 & " οπές × " & TEXT('1_Στοιχεία_Μελέτης_&_Ποσότητες'!C44,"0.00") & " m, " & '1_Στοιχεία_Μελέτης_&_Ποσότητες'!C45 & " Strands)" | F31: =SUM(F15:F19) | G31: =F31/F33 | H31: ="= Διάτρηση (" & TEXT(F15,"#,##0.00") & "€) + Grout (" & TEXT(F16,"#,##0.00") & "€) + Τένοντες (" & TEXT(F17,"#,##0.00") & "€) + Τάνυση & Κεφαλές (" & TEXT(F18+F19,"#,##0.00") & "€)"
A32: ΕΛΕΓΧΟΣ | B32: Επαλήθευση Ισότητας (Κουτιά Type A + Μετακινήσεις == Άθροισμα 4 Πυλώνων) | F32: =ROUND((F27+F28)-(F28+F29+F30+F31), 2) | G32: 0 | H32: =IF(F32=0, "[OK — 100% ΤΑΥΤΙΣΗ ΚΟΥΤΙΩΝ & 4 ΠΥΛΩΝΩΝ]", "[ΣΦΑΛΜΑ ΑΘΡΟΙΣΗΣ]")
A33: ΣΥΝΟΛΟ | B33: ΤΕΛΙΚΟ ΣΥΝΟΛΟ ΠΡΟΣΦΟΡΑΣ BERLIN WALL (ΧΩΡΙΣ Φ.Π.Α.) | F33: =F27+F28 | G33: 1 | H33: Καθαρό Σύνολο Έργου (Περιλαμβάνει Γενικά Έξοδα & Εργολαβικό Όφελος — Χωρίς Φ.Π.Α. βάσει Κανόνα 3.7.2)
A35: 📈 ΒΑΣΙΚΟΙ ΔΕΙΚΤΕΣ ΚΟΣΤΟΥΣ & VALUE ENGINEERING (KPIs)
A36: KPI 1 | B36: Συνολικό Κόστος ανά m² Μετώπου Εκσκαφής (€ / m²) | F36: =ROUND(F33/'1_Στοιχεία_Μελέτης_&_Ποσότητες'!C97, 2) | G36: € / m² | H36: ="= Τελικό Σύνολο (" & TEXT(F33,"#,##0.00") & " €) / " & TEXT('1_Στοιχεία_Μελέτης_&_Ποσότητες'!C97,"#,##0.00") & " m² μετώπου"
A37: KPI 2 | B37: Συνολικό Κόστος ανά Τρέχον Μέτρο Περιμέτρου (€ / τρ.μ.) | F37: =ROUND(F33/'1_Στοιχεία_Μελέτης_&_Ποσότητες'!C96, 2) | G37: € / τρ.μ. | H37: ="= Τελικό Σύνολο (" & TEXT(F33,"#,##0.00") & " €) / " & TEXT('1_Στοιχεία_Μελέτης_&_Ποσότητες'!C96,"#,##0.00") & " m περιμέτρου"
A38: KPI 3 | B38: Κόστος Πυλώνα 3 (H-Beams / Νέφκες) ανά Πάσσαλο / Οπή (€ / πάσσαλο) | F38: =ROUND(F30/'1_Στοιχεία_Μελέτης_&_Ποσότητες'!C98, 2) | G38: € / πάσσαλο | H38: ="= Σύνολο Πυλώνα 3 (" & TEXT(F30,"#,##0.00") & " €) / " & '1_Στοιχεία_Μελέτης_&_Ποσότητες'!C98 & " οπές (Συνολικό έργο/πάσσαλο = " & TEXT(ROUND(F33/'1_Στοιχεία_Μελέτης_&_Ποσότητες'!C98,2),"#,##0.00") & " €)"
A39: KPI 4 | B39: Κόστος Πυλώνα 4 (Αγκυρώσεις) ανά Πλήρη Αγκύρωση (€ / αγκύρωση) | F39: =ROUND(F31/'1_Στοιχεία_Μελέτης_&_Ποσότητες'!C107, 2) | G39: € / αγκύρωση | H39: ="= Σύνολο Πυλώνα 4 (" & TEXT(F31,"#,##0.00") & " €) / " & '1_Στοιχεία_Μελέτης_&_Ποσότητες'!C107 & " αγκυρώσεις (16.00 m, 3 Strands)"
A40: KPI 5 | B40: Κόστος Πυλώνα 2 (Σχάρα A252 & Shotcrete 12cm) ανά m² Μετώπου (€ / m²) | F40: =ROUND(F29/'1_Στοιχεία_Μελέτης_&_Ποσότητες'!C97, 2) | G40: € / m² | H40: ="= Σύνολο Πυλώνα 2 (" & TEXT(F29,"#,##0.00") & " €) / " & TEXT('1_Στοιχεία_Μελέτης_&_Ποσότητες'!C97,"#,##0.00") & " m² μετώπου"

Sheet 3_Πίνακες_Διατομών_Χάλυβα
A1: ΒΙΒΛΙΟΘΗΚΗ ΔΙΑΤΟΜΩΝ ΧΑΛΥΒΑ (EUROPEAN STRUCTURAL STEEL PROFILES)
A2: Τεχνικά χαρακτηριστικά & βάρη ανά μέτρο για διατομές HEA, HEB, UPN & Γωνιών (L)
A4: 1. ΔΙΑΤΟΜΕΣ HEA (Ευρωπαϊκά Πλατύπελμα Ελαφρού Τύπου)
A5: Ονομασία Διατομής | B5: Ύψος h (mm) | C5: Πλάτος b (mm) | D5: Πάχος tw (mm) | E5: Πάχος tf (mm) | F5: Διατομή A (cm²) | G5: Βάρος (kg / m)
A6: HEA 140 | B6: 133 | C6: 140 | D6: 5.5 | E6: 8.5 | F6: 31.4 | G6: 24.7
A7: HEA 160 | B7: 152 | C7: 160 | D7: 6 | E7: 9 | F7: 38.8 | G7: 30.4
A8: HEA 180 | B8: 171 | C8: 180 | D8: 6 | E8: 9.5 | F8: 45.3 | G8: 35.5
A9: HEA 200 | B9: 190 | C9: 200 | D9: 6.5 | E9: 10 | F9: 53.8 | G9: 42.3
A10: HEA 220 | B10: 210 | C10: 220 | D10: 7 | E10: 11 | F10: 64.3 | G10: 50.5
A11: HEA 240 | B11: 230 | C11: 240 | D11: 7.5 | E11: 12 | F11: 76.8 | G11: 60.3
A12: HEA 260 | B12: 250 | C12: 260 | D12: 7.5 | E12: 12.5 | F12: 86.8 | G12: 68.2
A13: HEA 280 | B13: 270 | C13: 280 | D13: 8 | E13: 13 | F13: 97.3 | G13: 76.4
A14: HEA 300 | B14: 290 | C14: 300 | D14: 8.5 | E14: 14 | F14: 112.5 | G14: 88.3
A16: 2. ΔΙΑΤΟΜΕΣ HEB (Ευρωπαϊκά Πλατύπελμα Κανονικού Τύπου)
A17: Ονομασία Διατομής | B17: Ύψος h (mm) | C17: Πλάτος b (mm) | D17: Πάχος tw (mm) | E17: Πάχος tf (mm) | F17: Διατομή A (cm²) | G17: Βάρος (kg / m)
A18: HEB 140 | B18: 140 | C18: 140 | D18: 7 | E18: 12 | F18: 43 | G18: 33.7
A19: HEB 160 | B19: 160 | C19: 160 | D19: 8 | E19: 13 | F19: 54.3 | G19: 42.6
A20: HEB 180 | B20: 180 | C20: 180 | D20: 8.5 | E20: 14 | F20: 65.3 | G20: 51.2
A21: HEB 200 | B21: 200 | C21: 200 | D21: 9 | E21: 15 | F21: 78.1 | G21: 61.3
A22: HEB 220 | B22: 220 | C22: 220 | D22: 9.5 | E22: 16 | F22: 91 | G22: 71.5
A23: HEB 240 | B23: 240 | C23: 240 | D23: 10 | E23: 17 | F23: 106 | G23: 83.2
A24: HEB 260 | B24: 260 | C24: 260 | D24: 10 | E24: 17.5 | F24: 118.4 | G24: 93
A25: HEB 280 | B25: 280 | C25: 280 | D25: 10.5 | E25: 18 | F25: 131.4 | G25: 103
A26: HEB 300 | B26: 300 | C26: 300 | D26: 11 | E26: 19 | F26: 149.1 | G26: 117
A28: 3. ΔΙΑΤΟΜΕΣ UPN (Ευρωπαϊκά Κοίλα Προφίλ U)
A29: Ονομασία Διατομής | B29: Ύψος h (mm) | C29: Πλάτος b (mm) | D29: Πάχος tw (mm) | E29: Πάχος tf (mm) | F29: Διατομή A (cm²) | G29: Βάρος (kg / m)
A30: UPN 140 | B30: 140 | C30: 60 | D30: 7 | E30: 10 | F30: 20.4 | G30: 16
A31: UPN 160 | B31: 160 | C31: 65 | D31: 7.5 | E31: 10.5 | F31: 24 | G31: 18.8
A32: UPN 180 | B32: 180 | C32: 70 | D32: 8 | E32: 11 | F32: 28 | G32: 22
A33: UPN 200 | B33: 200 | C33: 75 | D33: 8.5 | E33: 11.5 | F33: 32.2 | G33: 25.3
A34: UPN 220 | B34: 220 | C34: 80 | D34: 9 | E34: 12.5 | F34: 37.4 | G34: 29.4
A35: UPN 240 | B35: 240 | C35: 85 | D35: 9.5 | E35: 13 | F35: 42.3 | G35: 33.2
A36: UPN 260 | B36: 260 | C36: 90 | D36: 10 | E36: 14 | F36: 48.3 | G36: 37.9
A37: UPN 280 | B37: 280 | C37: 95 | D37: 10 | E37: 15 | F37: 53.3 | G37: 41.8
A38: UPN 300 | B38: 300 | C38: 100 | D38: 10 | E38: 16 | F38: 58.8 | G38: 46.2
A40: 4. ΙΣΟΣΚΕΛΕΙΣ ΓΩΝΙΕΣ (Equal Angles L)
A41: Ονομασία Διατομής | B41: Ύψος h (mm) | C41: Πλάτος b (mm) | D41: Πάχος tw (mm) | E41: Πάχος tf (mm) | F41: Διατομή A (cm²) | G41: Βάρος (kg / m)
A42: L 50x50x5 | B42: 50 | C42: 50 | D42: 5 | E42: 5 | F42: 4.8 | G42: 3.77
A43: L 60x60x6 | B43: 60 | C43: 60 | D43: 6 | E43: 6 | F43: 6.91 | G43: 5.42
A44: L 70x70x6 | B44: 70 | C44: 70 | D44: 6 | E44: 6 | F44: 8.13 | G44: 6.38
...
