Workbook

Sheet 1_Στοιχεία_Μελέτης_&_Ποσότητες
A1: ΕΡΓΟ: ΠΟΛΥΚΑΤΟΙΚΙΑ EMERALDA 5 (S1480) — ΣΤΟΙΧΕΙΑ ΜΕΛΕΤΗΣ & ΦΥΣΙΚΕΣ ΠΟΣΟΤΗΤΕΣ BERLIN WALL (ΧΩΡΙΣ €)
A2: Αρχιτεκτονική v8.0 (Single Source of Truth & Box Layout): [ΚΕΦΑΛΑΙΟ Α] = Πρωτογενή Δεδομένα & Citations | [ΚΕΦΑΛΑΙΟ Β] = 100% Δυναμικοί Υπολογισμοί
A4: 🏛️ ΚΕΦΑΛΑΙΟ Α: ΠΡΩΤΟΓΕΝΗ ΣΤΟΙΧΕΙΑ ΜΕΛΕΤΗΣ, CITATIONS & ΕΛΕΓΧΟΣ ΚΑΝΟΝΩΝ (RAW INPUTS — ΣΕ ΚΟΥΤΙΑ)
A5: Κουτί | B5: Παράμετρος Μελέτης / Προδιαγραφή | C5: Τιμή Μελέτης / Εφαρμογής | D5: Μονάδα | E5: Πηγή Μελέτης (Σχέδιο / Σελίδα) | F5: Τεχνική Σημείωση / Έλεγχος Κανόνα (Rule Auditing)
A6: 📦 ΚΟΥΤΙ ΚΟΙΝΩΝ ΠΑΡΑΜΕΤΡΩΝ ΕΡΓΟΥ (ΚΟΙΝΑ — ΤΟΠΟΘΕΣΙΑ, SHOTCRETE, ΛΑΜΕΣ ΣΥΝΔΕΣΗΣ & ΤΕΝΟΝΤΕΣ)
A7: ΚΟΙΝΑ | B7: Έδρα Εταιρείας (Αφετηρία Μετακινήσεων) | C7: Άγιος Συλάς, Σπύρου Κυπριανού 32, Λεμεσός | D7: - | E7: Κεντρικός Τιμοκατάλογος Εταιρείας (Φύλλο 1) | F7: Σταθερή αφετηρία συνεργείων και διατρητικών μηχανημάτων εταιρείας.
B8: Τοποθεσία Εργοταξίου (Πολυκατοικία EMERALDA 5) | C8: Λεμεσός | D8: - | E8: Σχέδιο S01 & S02, Πινακίδα Μελέτης (S1480) | F8: Έργο εντός βασικής ζώνης Λεμεσού (ακτίνα 0–40 km από Άγιο Συλά).
B9: Χιλιομετρική Απόσταση Έργου από Έδρα | C9: 15 | D9: km | E9: Σχέδιο S01, Πινακίδα Μελέτης / Βασική Ζώνη Λεμεσού | F9: [DEFAULT ΕΤΑΙΡΕΙΑΣ]: Εντός βασικής ακτίνας ≤ 40 km (1,500 € μεγάλο τρυπάνι, 300 € αγκυρώσεις, 200 € shotcrete).
B10: Τύπος Χάλυβα Οπλισμού Σχάρας Μετώπου | C10: B500C | D10: - | E10: Σχέδιο S01 & S02, Γενικές Παρατηρήσεις #3 | F10: Ο οπλισμός είναι παντού υψηλής αντοχής B500C (fyk = 500 N/mm²).
B11: Διάμετρος Ράβδων Σχάρας Εκτοξευόμενου (d_mesh) | C11: 10 | D11: mm | E11: Σχέδιο S02, Τομή 02 / Λεπτομέρεια Λ01 & Τομή TX1 (Y10/15) | F11: Ρητή αναγραφή Y10/15 εντός της ζώνης 0.15 m του εκτοξευόμενου σκυροδέματος στην Τομή 02 / Λ01 (τα Y12/15 & Y16/15 αφορούν το μόνιμο τοίχωμα 0.25 m της Τομής TX1).
B12: Οριζόντιο Βήμα Ράβδων Σχάρας (s_horiz) | C12: 150 | D12: mm | E12: Σχέδιο S02, Τομή 02 / Λεπτομέρεια Λ01 (Y10/15) | F12: Αναγραφή Y10/15 (βήμα 15 cm = 150 mm).
B13: Κάθετο Βήμα Ράβδων Σχάρας (s_vert) | C13: 150 | D13: mm | E13: Σχέδιο S02, Τομή 02 / Λεπτομέρεια Λ01 (Y10/15) | F13: Αναγραφή Y10/15 (βήμα 15 cm = 150 mm).
B14: Κατηγορία Εκτοξευόμενου Σκυροδέματος (Shotcrete) | C14: C30/37 | D14: - | E14: Σχέδιο S01 & S02, Γενικές Παρατηρήσεις #1 & Τομή 01 / 02 | F14: Ποιότητα συνηθισμένου και εκτοξευόμενου σκυροδέματος C30/37 (fck = 30 N/mm²).
B15: Ονομαστικό Πάχος Shotcrete Μελέτης (t_shot) | C15: 0.15 | D15: m | E15: Σχέδιο S02, Τομή 01 (1:20) & Τομή 02 / Λεπτομέρεια Λ01 (1:10) | F15: Αναγράφεται ρητά 0.15 m (150 mm) στην Τομή 01 και στην Τομή 02 / Λεπτομέρεια Λ01.
B16: Πάγια Απώλεια / Αναπήδηση Shotcrete Εταιρείας | C16: 0.05 | D16: m | E16: Κανόνας Εταιρείας (Τιμοκατάλογος Φύλλο 1, Γραμμή 31) | F16: [DEFAULT ΕΤΑΙΡΕΙΑΣ]: +0.05 m (+5 cm) πάγια προσαύξηση αναπήδησης, ενσωματωμένη στην τιμή εκτόξευσης (€/m³).
B17: Κατακόρυφο Βήμα Λαμών Σύνδεσης Νεφκών (s_plate) | C17: 1.5 | D17: m | E17: Σχέδιο S02, Τυπική Τομή ΤΤ & Τυπική Λεπτομέρεια (1:20) | F17: Ρητή αναγραφή: «Οριζόντιο ενισχυτικό έλασμα πάχους 10mm. Τοποθετείται καθ' ύψος ενδιάμεσα των αγκυρώσεων ανά 1500mm» (1.50 m).
B18: Πλάτος Λάμας Σύνδεσης (b_plate) | C18: 200 | D18: mm | E18: Σχέδιο S02, Τυπική Τομή ΤΤ (Default Πλάτους Εταιρείας) | F18: [DEFAULT ΕΤΑΙΡΕΙΑΣ]: Δεν αναγράφεται αριθμητικά πλάτος για το έλασμα 10mm στην Τυπική Τομή ΤΤ. Εφαρμόζεται by default 200 mm (η πλάκα έδρασης 360x250x20mm αφορά την κεφαλή αγκυρίου).
B19: Μήκος / Ύψος Λάμας Σύνδεσης (h_plate) | C19: 200 | D19: mm | E19: Σχέδιο S02, Τυπική Τομή ΤΤ (Default Μήκους Εταιρείας) | F19: [DEFAULT ΕΤΑΙΡΕΙΑΣ]: Δεν αναγράφεται αριθμητικά μήκος/ύψος για το ενδιάμεσο έλασμα 10mm. Εφαρμόζεται by default 200 mm.
B20: Πάχος Λάμας Σύνδεσης (t_plate) | C20: 10 | D20: mm | E20: Σχέδιο S02, Τυπική Τομή ΤΤ & Τυπική Λεπτομέρεια (ΠΑΧΟΥΣ 10mm) | F20: Ρητή αναγραφή στη μελέτη: «Οριζόντιο ενισχυτικό έλασμα πάχους 10mm».
B21: ="Βάρος 1 Λάμας Σύνδεσης (" & C18 & "×" & C19 & "×" & C20 & " mm)" -> Βάρος 1 Λάμας Σύνδεσης (200×200×10 mm) | C21: =(C18/1000)*(C19/1000)*(C20/1000)*7850 -> 3.14 | D21: kg / τεμ. | E21: Μαθηματικός Τύπος Εταιρείας (Κανόνας §3.2.1) | F21: ="Δυναμικός υπολογισμός: (" & C18 & "/1000)×(" & C19 & "/1000)×(" & C20 & "/1000)×7850 = " & TEXT(C21,"0.00") & " kg/τεμ." -> Δυναμικός υπολογισμός: (200/1000)×(200/1000)×(10/1000)×7850 = 3.14 kg/τεμ.
B22: Διάμετρος Οπής Διάτρησης Αγκυρώσεων (D_anc) | C22: 0.12 | D22: m | E22: Κανόνας Εταιρείας (Τιμοκατάλογος Φύλλο 1, Γραμμή 33) | F22: [DEFAULT ΕΤΑΙΡΕΙΑΣ]: Δεν αναγράφεται στα σχέδια. Εφαρμόζεται τυπική διάμετρος οπής αγκύρωσης Ø120 mm (0.12 m).
B23: Συντελεστής Υπερκατανάλωσης Grout Αγκυρώσεων | C23: 1.2 | D23: συντ. | E23: Κανόνας Εταιρείας (Τιμοκατάλογος Φύλλο 1, Γραμμή 34) | F23: [DEFAULT ΕΤΑΙΡΕΙΑΣ]: +20% (×1.20) πάγιος συντελεστής υπερκατανάλωσης τσιμεντενέματος στο έδαφος.
B24: Επιπλέον Μήκος Τένοντα (Strand 0.6'' / 15.2mm) για Προένταση | C24: 1 | D24: m | E24: Κανόνας Εταιρείας & Σχέδιο S01/S02 (Σημείωση #3: 15.2mm Grade 1860) | F24: [DEFAULT ΕΤΑΙΡΕΙΑΣ]: +1.00 m επιπλέον μήκος ανά τένοντα έξω από την οπή για την κεφαλή και τον γρύλο τάνυσης (1.10 kg/m).
A26: ="📦 ΚΟΥΤΙ TYPE A — ΤΟΙΧΟΣ ΑΝΤΙΣΤΗΡΙΞΗΣ Π1 (2×" & C36 & " | " & C27 & " ΠΑΣΣΑΛΟΙ × " & TEXT(C28,"0.00") & "m = " & TEXT(C29,"0.00") & " τρ.μ. | H_exc = " & TEXT(C31,"0.00") & "m)" -> 📦 ΚΟΥΤΙ TYPE A — ΤΟΙΧΟΣ ΑΝΤΙΣΤΗΡΙΞΗΣ Π1 (2×UPN 300 | 35 ΠΑΣΣΑΛΟΙ × 2.00m = 70.00 τρ.μ. | H_exc = 7.95m)
A27: TYPE A | B27: Πλήθος Πασσάλων / Νεφκών (Π1) Type A (N_piles) | C27: 35 | D27: οπές | E27: Σχέδιο S01, Κάτοψη Τοίχου Αντιστήριξης (1:100) — Καταμέτρηση Π1 (A1..A35) | F27: Ακριβής καταμέτρηση 35 θέσεων Π1 στην Κάτοψη S01 (2 στο δυτικό σκέλος Κ46–Κ48, 23 στο βόρειο διαγώνιο Κ48–Κ62, 10 στο ανατολικό Κ62–Κ65) μέσω OpenCV & CAD.
B28: Αξονική Απόσταση Πασσάλων (Π1) Type A (s_c/c) | C28: 2 | D28: m | E28: Σχέδιο S01 (Κάτοψη) & Σχέδιο S02 (Τομή 01 & Τομή 02 / Λεπτομέρεια Λ01) | F28: Ρητή αναγραφή «2 UPN300 S275 ΣΕ ΑΠΟΣΤΑΣΗ 2.00m» και διαδοχικές ενδείξεις 2.00 στην Κάτοψη S01.
B29: ="Αναπτυγμένο Μήκος Μετώπου Type A (" & C27 & " × " & TEXT(C28,"0.00") & " m)" -> Αναπτυγμένο Μήκος Μετώπου Type A (35 × 2.00 m) | C29: =C27*C28 -> 70 | D29: m | E29: Σχέδιο S01, Κάτοψη (Κανόνας §3.4: L = N × s_c/c) | F29: ="Δυναμικός υπολογισμός περιμέτρου αντιστήριξης: " & C27 & " διαστήματα × " & TEXT(C28,"0.00") & " m = " & TEXT(C29,"0.00") & " m." -> Δυναμικός υπολογισμός περιμέτρου αντιστήριξης: 35 διαστήματα × 2.00 m = 70.00 m.
B30: Διάμετρος Διάτρησης Οπών Πασσάλων Type A (D_pile) | C30: 0.8 | D30: m | E30: Σχέδιο S02, Τομή 01 & Τομή 02 / Λ01 (Αναγραφή: Ελάχιστη Ø600mm) | F30: [OVERRIDE ΚΑΝΟΝΑ]: Η μελέτη ζητούσε ελάχιστη διάμετρο Ø600 mm (0.60 m). Εφαρμόζεται υποχρεωτικά Ø800 mm (0.80 m) βάσει κανόνα ελάχιστης διαμέτρου εταιρείας (§3.1).
B31: Ελεύθερο Ύψος Εκσκαφής Μετώπου Type A (H_exc) | C31: 7.95 | D31: m | E31: Σχέδιο S02, Τομή 01 & Τομή TX1 (+95.00 έως +87.05 ΕΚΣΚΑΦΗ) | F31: [!!! ΣΥΓΚΡΟΥΣΗ ΜΕΛΕΤΗΣ !!!]: Στην Τομή 01 η εξωτερική αλυσίδα εκσκαφής (2.00+3.50+2.35+0.10 = 7.95 m), οι στάθμες (+95.00 έως +87.05 = 7.95 m) και η συνολική διάσταση στην Τομή TX1 (7.95 m) δίνουν 7.95 m, ενώ η εσωτερική αλυσίδα της Τομής 01 (1.50+3.50+2.80+0.10) αθροίζει σε 7.90 m (λόγω αναγραφής 2.80 αντί 2.85). Επιλέγεται υποχρεωτικά ο στατικά ασφαλέστερος αριθμός 7.95 m (§3.3).
B32: Ύψος Πάκτωσης Σκυροδέματος στη Βάση Type A (H_embed) | C32: 4 | D32: m | E32: Σχέδιο S02, Τομή 01 (Αναγραφόμενη διάσταση 4.00 m κάτω από +87.05) | F32: Ανεξάρτητο Raw Input (§3.5.2): Αναγράφεται ρητά 4.00 m κάτω από τον πυθμένα εκσκαφής (+87.05) στην Τομή 01.
B33: Συνολικό Μήκος Χαλύβδινης Νέφκας Μελέτης Type A (L_beam) | C33: 11.95 | D33: m | E33: Σχέδιο S02, Τομή 01 & Τομή TX1 (7.95 m εκσκαφή + 4.00 m πάκτωση) | F33: [!!! ΣΥΓΚΡΟΥΣΗ ΜΕΛΕΤΗΣ !!!]: Βάσει της εξωτερικής αλυσίδας εκσκαφής (7.95 m) + πάκτωσης (4.00 m) της Τομής 01 & TX1 προκύπτει L_beam = 11.95 m, ενώ με την εσωτερική αλυσίδα (7.90 + 4.00) προκύπτει 11.90 m. Επιλέγεται ο στατικά ασφαλέστερος αριθμός 11.95 m (§3.3 & §3.5.2).
B34: Ύψος Εκσκαφής / Διάτρησης Νέφκας βάσει WPL / Cut-Off Level (L_drill_WPL) | D34: m | E34: Δεν δίνεται στα Σχέδια S01 & S02 (Κενό -> Κόκκινη Επισήμανση §3.8) | F34: =IF(ISBLANK(C34), "[!!! ΕΛΛΕΙΨΗ WPL / CUT-OFF LEVEL — ΚΟΚΚΙΝΟ ΚΕΛΙ !!!]: Δεν δόθηκε WPL / Cut-Off Level στη μελέτη. Θεωρείται ότι το ύψος εκσκαφής/διάτρησης ισούται με το μήκος της νέφκας (" & TEXT(C33,"0.00") & " m). Συμπληρώστε εδώ το ύψος εκσκαφής βάσει WPL αν διαφέρει!", "[ΕΦΑΡΜΟΓΗ WPL / CUT-OFF LEVEL]: Το ύψος εκσκαφής/διάτρησης νεφκών ορίστηκε βάσει WPL σε " & TEXT(C34,"0.00") & " m (αντί " & TEXT(C33,"0.00") & " m της νέφκας χάλυβα).") -> [!!! ΕΛΛΕΙΨΗ WPL / CUT-OFF LEVEL — ΚΟΚΚΙΝΟ ΚΕΛΙ !!!]: Δεν δόθηκε WPL / Cut-Off Level στη μελέτη. Θεωρείται ότι το ύψος εκσκαφής/διάτρησης ισούται με το μήκος της νέφκας (11.95 m). Συμπληρώστε εδώ το ύψος εκσκαφής βάσει WPL αν διαφέρει!
B35: Ενεργό Ύψος Διάτρησης Μεγάλου Τρυπανιού Type A (L_drill_active) | C35: =IF(ISBLANK(C34), C33, C34) -> 11.95 | D35: m | E35: Αυτόματος Κανόνας WPL / Cut-Off Level (§3.8.3 & §3.8.4) | F35: ="Χρησιμοποιείται αποκλειστικά για τα μέτρα διάτρησης (" & TEXT(C35,"0.00") & " m/οπή) και τα κυβικά εκσκαφής νεφκών (m³), χωρίς να αλλοιώνει το μήκος χάλυβα L_beam (" & TEXT(C33,"0.00") & " m)." -> Χρησιμοποιείται αποκλειστικά για τα μέτρα διάτρησης (11.95 m/οπή) και τα κυβικά εκσκαφής νεφκών (m³), χωρίς να αλλοιώνει το μήκος χάλυβα L_beam (11.95 m).
B36: Τύπος Χαλύβδινης Διατομής Νέφκας Type A | C36: UPN 300 | D36: - | E36: Σχέδιο S02, Τομή 01, Τομή 02 / Λ01, Τυπική Τομή ΤΤ (2 UPN300 S275) | F36: Δομικός χάλυβας S275 (Σημείωση #2), διπλή διατομή 2 × UPN 300 ανά πάσσαλο Π1.
B37: Πλήθος Προφίλ Χάλυβα ανά Οπή Πασσάλου (Π1) | C37: 2 | D37: προφίλ/οπή | E37: Σχέδιο S02, Τομή 01 & Τομή 02 / Λεπτομέρεια Λ01 (2 UPN300) | F37: 2 τεμάχια UPN 300 ανά οπή πασσάλου Π1 (σε απόσταση min 0.10 m μεταξύ των κορμών τους).
B38: ="Θεωρητικό Βάρος 1 Προφίλ (" & C36 & ") ανά Μέτρο" -> Θεωρητικό Βάρος 1 Προφίλ (UPN 300) ανά Μέτρο | C38: ='3_Πίνακες_Διατομών_Χάλυβα'!G38 -> 46.2 | D38: kg / m | E38: Φύλλο 3 (Βιβλιοθήκη Ευρωπαϊκών Διατομών Χάλυβα — Γραμμή 38) | F38: ="Αυτόματη άντληση από Φύλλο 3: 1 × " & C36 & " = " & TEXT(C38,"0.00") & " kg/m (Σύνολο " & C37 & "×" & TEXT(C38,"0.00") & " = " & TEXT(C37*C38,"0.00") & " kg/m ανά πάσσαλο Π1)." -> Αυτόματη άντληση από Φύλλο 3: 1 × UPN 300 = 46.20 kg/m (Σύνολο 2×46.20 = 92.40 kg/m ανά πάσσαλο Π1).
B39: Ύπαρξη Γωνιών Στήριξης (Equal Angles L) στο Type A | C39: ΟΧΙ | D39: - | E39: Σχέδιο S02, Τομή 01 & Τομή 02 / Λεπτομέρεια Λ01 | F39: Δεν ζητούνται γωνιές στήριξης L στη μελέτη (ο οπλισμός Y10/15 αγκυρώνεται απευθείας εντός των 2 UPN 300).
B40: Πλήθος Οριζόντιων Σειρών Αγκυρώσεων Type A | C40: 2 | D40: σειρές | E40: Σχέδιο S02, Τομή 01 & Πίνακας - Εκσκαφή Τενόντων (+93.50 & +90.00) | F40: 2 οριζόντιες σειρές προεντεταμένων αγκυρίων: Σειρά 1 (+93.50, 280 kN) και Σειρά 2 (+90.00, 400 kN) υπό κλίση 20°.
B41: Πλήθος Αγκυρώσεων ανά Οριζόντια Σειρά Type A | C41: =C27 -> 35 | D41: τεμ./σειρά | E41: Σχέδιο S01 (Κάτοψη) & Σχέδιο S02 (Τομή 02 / Λεπτομέρεια Λ01) | F41: ="1 αγκύρωση ανά πάσσαλο Π1 (διέρχεται ανάμεσα στα 2 UPN 300) = " & C41 & " αγκυρώσεις ανά σειρά." -> 1 αγκύρωση ανά πάσσαλο Π1 (διέρχεται ανάμεσα στα 2 UPN 300) = 35 αγκυρώσεις ανά σειρά.
B42: Ελεύθερο Μήκος Αγκυρίου Σειράς 1 (+93.50) (L_free_1) | C42: 9 | D42: m | E42: Σχέδιο S02, Πίνακας - Εκσκαφή Τενόντων (Υψόμετρο +93.50) | F42: Αναγράφεται ρητά στον Πίνακα Εκσκαφής Τενόντων: Υψόμετρο +93.50 -> Ελεύθερο Μήκος L = 9.00 m.
...

Sheet 2_Υπολογισμοί_&_Κοστολόγηση
A1: ΕΡΓΟ: ΠΟΛΥΚΑΤΟΙΚΙΑ EMERALDA 5 (S1480) — ΟΙΚΟΝΟΜΙΚΗ ΠΡΟΣΦΟΡΑ BERLIN WALL & ΑΓΚΥΡΩΣΕΩΝ (ΧΩΡΙΣ Φ.Π.Α.)
A2: Αρχιτεκτονική Κουτιών ανά Τύπο Τοίχου (Box Layout v8.0) | [ΚΙΤΡΙΝΟ #FFF2CC] = Τιμές Μονάδας (€) | [ΠΟΡΤΟΚΑΛΙ #FFE699] = Κουγκρί Πάκτωσης | Χωρίς Φ.Π.Α.
A4: Κωδ. | B4: Περιγραφή Εργασίας / Υλικού (100% Δυναμικός Τίτλος) | C4: Ποσότητα | D4: Μονάδα | E4: Τιμή Μονάδας (€) | F4: Συνολικό Κόστος (€) | G4: Τελ. Σύνολα Κουτιού (€) | H4: Πηγή Ποσότητας & Τεχνική Επεξήγηση (Dynamic String)
A5: ="📦 ΚΟΥΤΙ TYPE A — ΤΟΙΧΟΣ ΑΝΤΙΣΤΗΡΙΞΗΣ Π1 (2×" & '1_Στοιχεία_Μελέτης_&_Ποσότητες'!C36 & ") | ΜΗΚΟΣ: " & TEXT('1_Στοιχεία_Μελέτης_&_Ποσότητες'!C29,"0.00") & " τρ.μ. | ΚΟΣΤΟΣ/τρ.μ.: " & TEXT(F21/'1_Στοιχεία_Μελέτης_&_Ποσότητες'!C29,"#,##0.00") & " €/τρ.μ. | ΣΥΝΟΛΟ TYPE A: " & TEXT(F21,"#,##0.00") & " €" -> 📦 ΚΟΥΤΙ TYPE A — ΤΟΙΧΟΣ ΑΝΤΙΣΤΗΡΙΞΗΣ Π1 (2×UPN 300) | ΜΗΚΟΣ: 70.00 τρ.μ. | ΚΟΣΤΟΣ/τρ.μ.: 2,733.13 €/τρ.μ. | ΣΥΝΟΛΟ TYPE A: 191,319.28 €
A6: A.1 | B6: ="Διάτρηση Μεγάλου Τρυπανιού Type A (Ø" & TEXT('1_Στοιχεία_Μελέτης_&_Ποσότητες'!C30*1000,"0") & " mm, " & '1_Στοιχεία_Μελέτης_&_Ποσότητες'!C27 & " οπές × " & TEXT('1_Στοιχεία_Μελέτης_&_Ποσότητες'!C35,"0.00") & " m)" -> Διάτρηση Μεγάλου Τρυπανιού Type A (Ø800 mm, 35 οπές × 11.95 m) | C6: ='1_Στοιχεία_Μελέτης_&_Ποσότητες'!C64 -> 418.25 | D6: m | E6: 75 | F6: =ROUND(C6*E6, 2) -> 31368.75 | G6: =F21 -> 191319.28 | H6: ="=" & '1_Στοιχεία_Μελέτης_&_Ποσότητες'!C27 & " οπές × " & TEXT('1_Στοιχεία_Μελέτης_&_Ποσότητες'!C35,"0.00") & " m = " & TEXT(C6,"#,##0.00") & " m (Όγκος εκσκαφής = " & TEXT('1_Στοιχεία_Μελέτης_&_Ποσότητες'!C65,"#,##0.00") & " m³) × " & TEXT(E6,"0.00") & " €/m" -> =35 οπές × 11.95 m = 418.25 m (Όγκος εκσκαφής = 210.24 m³) × 75.00 €/m
A7: A.2 | B7: ="Χάλυβας Νεφκών Type A (" & '1_Στοιχεία_Μελέτης_&_Ποσότητες'!C37 & " × " & '1_Στοιχεία_Μελέτης_&_Ποσότητες'!C36 & " S275 = " & TEXT('1_Στοιχεία_Μελέτης_&_Ποσότητες'!C37*'1_Στοιχεία_Μελέτης_&_Ποσότητες'!C38,"0.00") & " kg/m — Αγορά + Επεξεργασία)" -> Χάλυβας Νεφκών Type A (2 × UPN 300 S275 = 92.40 kg/m — Αγορά + Επεξεργασία) | C7: ='1_Στοιχεία_Μελέτης_&_Ποσότητες'!C66 -> 38646.3 | D7: kg | E7: 1.4 | F7: =ROUND(C7*E7, 2) -> 54104.82 | H7: ="=" & '1_Στοιχεία_Μελέτης_&_Ποσότητες'!C27 & " οπές × " & '1_Στοιχεία_Μελέτης_&_Ποσότητες'!C37 & "×" & '1_Στοιχεία_Μελέτης_&_Ποσότητες'!C36 & " × " & TEXT('1_Στοιχεία_Μελέτης_&_Ποσότητες'!C33,"0.00") & " m = " & TEXT(C7,"#,##0.00") & " kg × (1.00€ αγορά + 0.40€ τοποθέτηση)" -> =35 οπές × 2×UPN 300 × 11.95 m = 38,646.30 kg × (1.00€ αγορά + 0.40€ τοποθέτηση)
A8: A.3 | B8: ="Λάμες Σύνδεσης / Ενίσχυσης Type A (" & '1_Στοιχεία_Μελέτης_&_Ποσότητες'!C18 & "×" & '1_Στοιχεία_Μελέτης_&_Ποσότητες'!C19 & "×" & '1_Στοιχεία_Μελέτης_&_Ποσότητες'!C20 & " mm ανά " & TEXT('1_Στοιχεία_Μελέτης_&_Ποσότητες'!C17,"0.00") & " m)" -> Λάμες Σύνδεσης / Ενίσχυσης Type A (200×200×10 mm ανά 1.50 m) | C8: ='1_Στοιχεία_Μελέτης_&_Ποσότητες'!C68 -> 879.2 | D8: kg | E8: 1.6 | F8: =ROUND(C8*E8, 2) -> 1406.72 | H8: ="=" & ('1_Στοιχεία_Μελέτης_&_Ποσότητες'!C27*'1_Στοιχεία_Μελέτης_&_Ποσότητες'!C67) & " λάμες × " & TEXT('1_Στοιχεία_Μελέτης_&_Ποσότητες'!C21,"0.00") & " kg/τεμ. = " & TEXT(C8,"#,##0.00") & " kg × (1.00€ αγορά + 0.60€ συγκόλληση)" -> =280 λάμες × 3.14 kg/τεμ. = 879.20 kg × (1.00€ αγορά + 0.60€ συγκόλληση)
A9: A.4 | B9: ="Κουγκρί Πάκτωσης Οπών Νεφκών Type A (C30/37, Ø" & TEXT('1_Στοιχεία_Μελέτης_&_Ποσότητες'!C30*1000,"0") & " mm, H_embed = " & TEXT('1_Στοιχεία_Μελέτης_&_Ποσότητες'!C32,"0.00") & " m)" -> Κουγκρί Πάκτωσης Οπών Νεφκών Type A (C30/37, Ø800 mm, H_embed = 4.00 m) | C9: ='1_Στοιχεία_Μελέτης_&_Ποσότητες'!C69 -> 70.37 | D9: m³ | E9: 120 | F9: =ROUND(C9*E9, 2) -> 8444.4 | H9: ="=" & '1_Στοιχεία_Μελέτης_&_Ποσότητες'!C27 & " οπές × " & TEXT('1_Στοιχεία_Μελέτης_&_Ποσότητες'!C32,"0.00") & " m πάκτωση = " & TEXT(C9,"#,##0.00") & " m³ × " & TEXT(E9,"0.00") & " €/m³ [Πορτοκαλί Κελί Ελέγχου]" -> =35 οπές × 4.00 m πάκτωση = 70.37 m³ × 120.00 €/m³ [Πορτοκαλί Κελί Ελέγχου]
A10: A.5 | B10: ="Γωνιές Στήριξης (Equal Angles L) Type A (" & '1_Στοιχεία_Μελέτης_&_Ποσότητες'!C39 & ")" -> Γωνιές Στήριξης (Equal Angles L) Type A (ΟΧΙ) | C10: ='1_Στοιχεία_Μελέτης_&_Ποσότητες'!C70 -> 0 | D10: kg | E10: 1.6 | F10: =ROUND(C10*E10, 2) -> 0 | H10: ="Δεν ζητούνται γωνιές στήριξης L στη μελέτη (" & '1_Στοιχεία_Μελέτης_&_Ποσότητες'!C39 & " = " & TEXT(C10,"0.00") & " kg)." -> Δεν ζητούνται γωνιές στήριξης L στη μελέτη (ΟΧΙ = 0.00 kg).
A11: A.6 | B11: ="Αγορά Χάλυβα Σχάρας Μετώπου Type A (Y" & '1_Στοιχεία_Μελέτης_&_Ποσότητες'!C11 & "/" & '1_Στοιχεία_Μελέτης_&_Ποσότητες'!C12 & "×" & '1_Στοιχεία_Μελέτης_&_Ποσότητες'!C13 & " " & '1_Στοιχεία_Μελέτης_&_Ποσότητες'!C10 & ")" -> Αγορά Χάλυβα Σχάρας Μετώπου Type A (Y10/150×150 B500C) | C11: ='1_Στοιχεία_Μελέτης_&_Ποσότητες'!C72 -> 4574.43 | D11: kg | E11: 2.5 | F11: =ROUND(C11*E11, 2) -> 11436.08 | H11: ="=" & TEXT('1_Στοιχεία_Μελέτης_&_Ποσότητες'!C71,"#,##0.00") & " m² × " & TEXT('1_Στοιχεία_Μελέτης_&_Ποσότητες'!C55,"0.000") & " kg/m² = " & TEXT(C11,"#,##0.00") & " kg × " & TEXT(E11,"0.00") & " €/kg" -> =556.50 m² × 8.220 kg/m² = 4,574.43 kg × 2.50 €/kg
A12: A.7 | B12: ="Τοποθέτηση Σχάρας / Εργατικά Μετώπου Type A (H_exc = " & TEXT('1_Στοιχεία_Μελέτης_&_Ποσότητες'!C31,"0.00") & " m)" -> Τοποθέτηση Σχάρας / Εργατικά Μετώπου Type A (H_exc = 7.95 m) | C12: ='1_Στοιχεία_Μελέτης_&_Ποσότητες'!C73 -> 556.5 | D12: m² | E12: 15 | F12: =ROUND(C12*E12, 2) -> 8347.5 | H12: ="=" & TEXT('1_Στοιχεία_Μελέτης_&_Ποσότητες'!C29,"0.00") & " m × " & TEXT('1_Στοιχεία_Μελέτης_&_Ποσότητες'!C31,"0.00") & " m = " & TEXT(C12,"#,##0.00") & " m² × " & TEXT(E12,"0.00") & " €/m²" -> =70.00 m × 7.95 m = 556.50 m² × 15.00 €/m²
A13: A.8 | B13: ="Αγορά Σκυροδέματος Shotcrete (" & '1_Στοιχεία_Μελέτης_&_Ποσότητες'!C14 & ") Type A (Ονομαστικό πάχος " & TEXT('1_Στοιχεία_Μελέτης_&_Ποσότητες'!C15,"0.00") & " m)" -> Αγορά Σκυροδέματος Shotcrete (C30/37) Type A (Ονομαστικό πάχος 0.15 m) | C13: ='1_Στοιχεία_Μελέτης_&_Ποσότητες'!C74 -> 83.48 | D13: m³ | E13: 90 | F13: =ROUND(C13*E13, 2) -> 7513.2 | H13: ="=" & TEXT('1_Στοιχεία_Μελέτης_&_Ποσότητες'!C71,"#,##0.00") & " m² × " & TEXT('1_Στοιχεία_Μελέτης_&_Ποσότητες'!C15,"0.00") & " m = " & TEXT(C13,"#,##0.00") & " m³ × " & TEXT(E13,"0.00") & " €/m³" -> =556.50 m² × 0.15 m = 83.48 m³ × 90.00 €/m³
A14: A.9 | B14: ="Εφαρμογή / Εκτόξευση Shotcrete Type A (με προσαύξηση απώλειας +" & TEXT('1_Στοιχεία_Μελέτης_&_Ποσότητες'!C56,"0.0%") & ")" -> Εφαρμογή / Εκτόξευση Shotcrete Type A (με προσαύξηση απώλειας +33.3%) | C14: ='1_Στοιχεία_Μελέτης_&_Ποσότητες'!C74 -> 83.48 | D14: m³ | E14: =ROUND((IF(C13>7, 200, 250)*(1+'1_Στοιχεία_Μελέτης_&_Ποσότητες'!C56))-E13, 2) -> 176.67 | F14: =ROUND(C14*E14, 2) -> 14748.41 | H14: ="Βάση " & IF(C13>7,200,250) & "€ × (1 + " & TEXT('1_Στοιχεία_Μελέτης_&_Ποσότητες'!C56,"0.0%") & " απώλεια) - " & TEXT(E13,"0.00") & "€ αγορά = " & TEXT(E14,"0.00") & " €/m³" -> Βάση 200€ × (1 + 33.3% απώλεια) - 90.00€ αγορά = 176.67 €/m³
A15: A.10 | B15: ="Διάτρηση Αγκυρώσεων Σειράς 1 (+93.50, 280 kN) Type A (" & '1_Στοιχεία_Μελέτης_&_Ποσότητες'!C41 & " οπές × " & TEXT('1_Στοιχεία_Μελέτης_&_Ποσότητες'!C44,"0.00") & " m)" -> Διάτρηση Αγκυρώσεων Σειράς 1 (+93.50, 280 kN) Type A (35 οπές × 15.50 m) | C15: ='1_Στοιχεία_Μελέτης_&_Ποσότητες'!C75 -> 542.5 | D15: m | E15: 30 | F15: =ROUND(C15*E15, 2) -> 16275 | H15: ="=" & '1_Στοιχεία_Μελέτης_&_Ποσότητες'!C41 & " οπές × (" & TEXT('1_Στοιχεία_Μελέτης_&_Ποσότητες'!C42,"0.00") & "m ελεύθ. + " & TEXT('1_Στοιχεία_Μελέτης_&_Ποσότητες'!C43,"0.00") & "m πακτ.) = " & TEXT(C15,"#,##0.00") & " m × " & TEXT(E15,"0.00") & " €/m" -> =35 οπές × (9.00m ελεύθ. + 6.50m πακτ.) = 542.50 m × 30.00 €/m
A16: A.11 | B16: ="Διάτρηση Αγκυρώσεων Σειράς 2 (+90.00, 400 kN) Type A (" & '1_Στοιχεία_Μελέτης_&_Ποσότητες'!C41 & " οπές × " & TEXT('1_Στοιχεία_Μελέτης_&_Ποσότητες'!C47,"0.00") & " m)" -> Διάτρηση Αγκυρώσεων Σειράς 2 (+90.00, 400 kN) Type A (35 οπές × 14.50 m) | C16: ='1_Στοιχεία_Μελέτης_&_Ποσότητες'!C76 -> 507.5 | D16: m | E16: 30 | F16: =ROUND(C16*E16, 2) -> 15225 | H16: ="=" & '1_Στοιχεία_Μελέτης_&_Ποσότητες'!C41 & " οπές × (" & TEXT('1_Στοιχεία_Μελέτης_&_Ποσότητες'!C45,"0.00") & "m ελεύθ. + " & TEXT('1_Στοιχεία_Μελέτης_&_Ποσότητες'!C46,"0.00") & "m πακτ.) = " & TEXT(C16,"#,##0.00") & " m × " & TEXT(E16,"0.00") & " €/m" -> =35 οπές × (4.50m ελεύθ. + 10.00m πακτ.) = 507.50 m × 30.00 €/m
A17: A.12 | B17: ="Grout Τσιμεντενέματος Αγκυρώσεων Type A (Ø" & TEXT('1_Στοιχεία_Μελέτης_&_Ποσότητες'!C22*1000,"0") & " mm, συντ. ×" & TEXT('1_Στοιχεία_Μελέτης_&_Ποσότητες'!C23,"0.00") & ")" -> Grout Τσιμεντενέματος Αγκυρώσεων Type A (Ø120 mm, συντ. ×1.20) | C17: ='1_Στοιχεία_Μελέτης_&_Ποσότητες'!C78 -> 14.25 | D17: m³ | E17: 500 | F17: =ROUND(C17*E17, 2) -> 7125 | H17: ="=" & TEXT('1_Στοιχεία_Μελέτης_&_Ποσότητες'!C77,"#,##0.00") & " m διάτρησης × " & TEXT('1_Στοιχεία_Μελέτης_&_Ποσότητες'!C58,"0.0000") & " m³/m = " & TEXT(C17,"#,##0.00") & " m³ × " & TEXT(E17,"0.00") & " €/m³" -> =1,050.00 m διάτρησης × 0.0136 m³/m = 14.25 m³ × 500.00 €/m³
A18: A.13 | B18: ="Τένοντες Προέντασης Type A (" & '1_Στοιχεία_Μελέτης_&_Ποσότητες'!C48 & "-Strands 0.6'' / 15.2mm Grade 1860, +" & TEXT('1_Στοιχεία_Μελέτης_&_Ποσότητες'!C24,"0.00") & "m αναμονή)" -> Τένοντες Προέντασης Type A (4-Strands 0.6'' / 15.2mm Grade 1860, +1.00m αναμονή) | C18: ='1_Στοιχεία_Μελέτης_&_Ποσότητες'!C79 -> 4480 | D18: m | E18: 2.28 | F18: =ROUND(C18*E18, 2) -> 10214.4 | H18: ="=" & TEXT(C18,"#,##0.00") & " m τενόντων (" & TEXT(C18*1.1,"#,##0.00") & " kg) × " & TEXT(E18,"0.00") & " €/m" -> =4,480.00 m τενόντων (4,928.00 kg) × 2.28 €/m
A19: A.14 | B19: ="Προένταση Αγκυρώσεων (Stressing & Lock-off) Type A (" & '1_Στοιχεία_Μελέτης_&_Ποσότητες'!C40 & " σειρές × " & '1_Στοιχεία_Μελέτης_&_Ποσότητες'!C41 & " οπές)" -> Προένταση Αγκυρώσεων (Stressing & Lock-off) Type A (2 σειρές × 35 οπές) | C19: ='1_Στοιχεία_Μελέτης_&_Ποσότητες'!C80 -> 70 | D19: τεμ. | E19: 18 | F19: =ROUND(C19*E19, 2) -> 1260 | H19: ="=" & C19 & " προεντεταμένες αγκυρώσεις × " & TEXT(E19,"0.00") & " €/τεμ." -> =70 προεντεταμένες αγκυρώσεις × 18.00 €/τεμ.
A20: A.15 | B20: ="Κεφαλές Αγκύρωσης (Anchor Head, Wedges & Πλάκα Έδρασης 360×250×20mm) Type A" -> Κεφαλές Αγκύρωσης (Anchor Head, Wedges & Πλάκα Έδρασης 360×250×20mm) Type A | C20: ='1_Στοιχεία_Μελέτης_&_Ποσότητες'!C80 -> 70 | D20: τεμ. | E20: 55 | F20: =ROUND(C20*E20, 2) -> 3850 | H20: ="=" & C20 & " πλήρη σετ κεφαλής, σφηνών και πλάκας έδρασης × " & TEXT(E20,"0.00") & " €/τεμ." -> =70 πλήρη σετ κεφαλής, σφηνών και πλάκας έδρασης × 55.00 €/τεμ.
A21: ΣΥΝ. Α | B21: ="ΣΥΝΟΛΟ ΚΟΥΤΙΟΥ TYPE A (" & TEXT('1_Στοιχεία_Μελέτης_&_Ποσότητες'!C29,"0.00") & " τρ.μ. | " & TEXT(F21/'1_Στοιχεία_Μελέτης_&_Ποσότητες'!C29,"#,##0.00") & " €/τρ.μ.)" -> ΣΥΝΟΛΟ ΚΟΥΤΙΟΥ TYPE A (70.00 τρ.μ. | 2,733.13 €/τρ.μ.) | F21: =SUM(F6:F20) -> 191319.28 | H21: ="Συνολικό κόστος Type A (" & '1_Στοιχεία_Μελέτης_&_Ποσότητες'!C27 & " πάσσαλοι 2×" & '1_Στοιχεία_Μελέτης_&_Ποσότητες'!C36 & " & " & '1_Στοιχεία_Μελέτης_&_Ποσότητες'!C80 & " αγκυρώσεις 4-Strands)" -> Συνολικό κόστος Type A (35 πάσσαλοι 2×UPN 300 & 70 αγκυρώσεις 4-Strands)
A23: ="🚛 ΚΟΥΤΙ ΠΥΛΩΝΑ 1 — ΜΕΤΑΚΙΝΗΣΕΙΣ ΕΞΟΠΛΙΣΜΟΥ & ΣΥΝΕΡΓΕΙΩΝ (ΑΠΟΣΤΑΣΗ: " & '1_Στοιχεία_Μελέτης_&_Ποσότητες'!C9 & " km | ΣΥΝΟΛΟ: " & TEXT(F27,"#,##0.00") & " €)" -> 🚛 ΚΟΥΤΙ ΠΥΛΩΝΑ 1 — ΜΕΤΑΚΙΝΗΣΕΙΣ ΕΞΟΠΛΙΣΜΟΥ & ΣΥΝΕΡΓΕΙΩΝ (ΑΠΟΣΤΑΣΗ: 15 km | ΣΥΝΟΛΟ: 2,700.00 €)
A24: ΠΥΛ.1α | B24: ="Μετακίνηση Μεγάλου Τρυπανιού (Piling Rig — Βασική Ζώνη Λεμεσού " & '1_Στοιχεία_Μελέτης_&_Ποσότητες'!C9 & " km)" -> Μετακίνηση Μεγάλου Τρυπανιού (Piling Rig — Βασική Ζώνη Λεμεσού 15 km) | C24: ='1_Στοιχεία_Μελέτης_&_Ποσότητες'!C59 -> 1 | D24: στράτες | E24: =1500+IF('1_Στοιχεία_Μελέτης_&_Ποσότητες'!C9>80,1500,IF('1_Στοιχεία_Μελέτης_&_Ποσότητες'!C9>40,500,0)) -> 1500 | F24: =ROUND(C24*E24, 2) -> 1500 | G24: =F27 -> 2700 | H24: ="Βάση Άγιος Συλάς (" & '1_Στοιχεία_Μελέτης_&_Ποσότητες'!C9 & " km ≤ 40 km -> 1,500.00 €/στράτα)" -> Βάση Άγιος Συλάς (15 km ≤ 40 km -> 1,500.00 €/στράτα)
A25: ΠΥΛ.1β | B25: ="Μετακινήσεις Εξοπλισμού Αγκυρώσεων (" & '1_Στοιχεία_Μελέτης_&_Ποσότητες'!C40 & " οριζόντιες σειρές αγκυρώσεων)" -> Μετακινήσεις Εξοπλισμού Αγκυρώσεων (2 οριζόντιες σειρές αγκυρώσεων) | C25: ='1_Στοιχεία_Μελέτης_&_Ποσότητες'!C60 -> 2 | D25: στράτες | E25: =300+MAX(0,ROUNDUP(('1_Στοιχεία_Μελέτης_&_Ποσότητες'!C9-40)/40,0))*50 -> 300 | F25: =ROUND(C25*E25, 2) -> 600 | H25: ="1 στράτα ανά οριζόντια σειρά αγκυρώσεων (" & C25 & " × " & TEXT(E25,"0.00") & " €)" -> 1 στράτα ανά οριζόντια σειρά αγκυρώσεων (2 × 300.00 €)
A26: ΠΥΛ.1γ | B26: ="Μετακινήσεις Συνεργείου & Αντλίας Shotcrete (" & '1_Στοιχεία_Μελέτης_&_Ποσότητες'!C40 & " σειρές + 1)" -> Μετακινήσεις Συνεργείου & Αντλίας Shotcrete (2 σειρές + 1) | C26: ='1_Στοιχεία_Μελέτης_&_Ποσότητες'!C61 -> 3 | D26: στράτες | E26: =200+MAX(0,ROUNDUP(('1_Στοιχεία_Μελέτης_&_Ποσότητες'!C9-40)/40,0))*50 -> 200 | F26: =ROUND(C26*E26, 2) -> 600 | H26: ="Σειρές αγκυρώσεων + 1 στράτα (" & C26 & " × " & TEXT(E26,"0.00") & " €)" -> Σειρές αγκυρώσεων + 1 στράτα (3 × 200.00 €)
A27: ΣΥΝ. Π1 | B27: ΣΥΝΟΛΟ ΚΟΥΤΙΟΥ ΠΥΛΩΝΑ 1 (ΜΕΤΑΚΙΝΗΣΕΙΣ ΕΞΟΠΛΙΣΜΟΥ & ΣΥΝΕΡΓΕΙΩΝ) | F27: =SUM(F24:F26) -> 2700 | H27: ="Σύνολο μετακινήσεων μεγάλου τρυπανιού, αγκυρώσεων και shotcrete." -> Σύνολο μετακινήσεων μεγάλου τρυπανιού, αγκυρώσεων και shotcrete.
A29: 🏛️ ΣΥΓΚΕΝΤΡΩΤΙΚΟΣ ΠΙΝΑΚΑΣ ΠΡΟΣΦΟΡΑΣ BERLIN WALL & CROSS-CHECK 4 ΠΥΛΩΝΩΝ (ΧΩΡΙΣ Φ.Π.Α. — ΚΑΝΟΝΑΣ §3.7.2)
A30: ΠΥΛ. 1 | B30: Cross-Check Πυλώνας 1: Μετακινήσεις Εξοπλισμού & Συνεργείων | F30: =F27 -> 2700 | G30: =F30/$F$36 -> 0.013916143 | H30: ="3 είδη στρατών (Μεγάλο τρυπάνι, Αγκυρώσεις, Shotcrete)" -> 3 είδη στρατών (Μεγάλο τρυπάνι, Αγκυρώσεις, Shotcrete)
A31: ΠΥΛ. 2 | B31: ="Cross-Check Πυλώνας 2: Σχάρες (Y" & '1_Στοιχεία_Μελέτης_&_Ποσότητες'!C11 & "/" & '1_Στοιχεία_Μελέτης_&_Ποσότητες'!C12 & "×" & '1_Στοιχεία_Μελέτης_&_Ποσότητες'!C13 & ") & Εκτοξευόμενο Σκυρόδεμα (" & '1_Στοιχεία_Μελέτης_&_Ποσότητες'!C14 & ")" -> Cross-Check Πυλώνας 2: Σχάρες (Y10/150×150) & Εκτοξευόμενο Σκυρόδεμα (C30/37) | F31: =SUM(F11:F14) -> 42045.19 | G31: =F31/$F$36 -> 0.21670625 | H31: ="Επιφάνεια μετώπου " & TEXT('1_Στοιχεία_Μελέτης_&_Ποσότητες'!C85,"#,##0.00") & " m², όγκος shotcrete " & TEXT('1_Στοιχεία_Μελέτης_&_Ποσότητες'!C92,"#,##0.00") & " m³" -> Επιφάνεια μετώπου 556.50 m², όγκος shotcrete 83.48 m³
A32: ΠΥΛ. 3 | B32: ="Cross-Check Πυλώνας 3: Χαλύβδινες Νέφκες (" & '1_Στοιχεία_Μελέτης_&_Ποσότητες'!C37 & "×" & '1_Στοιχεία_Μελέτης_&_Ποσότητες'!C36 & "), Διάτρηση Ø" & TEXT('1_Στοιχεία_Μελέτης_&_Ποσότητες'!C30*1000,"0") & "mm, Λάμες & Κουγκρί" -> Cross-Check Πυλώνας 3: Χαλύβδινες Νέφκες (2×UPN 300), Διάτρηση Ø800mm, Λάμες & Κουγκρί | F32: =SUM(F6:F10) -> 95324.69 | G32: =F32/$F$36 -> 0.49131555 | H32: ="=" & '1_Στοιχεία_Μελέτης_&_Ποσότητες'!C83 & " πάσσαλοι Π1 × " & TEXT('1_Στοιχεία_Μελέτης_&_Ποσότητες'!C33,"0.00") & " m (" & TEXT('1_Στοιχεία_Μελέτης_&_Ποσότητες'!C88,"#,##0.00") & " kg χάλυβα)" -> =35 πάσσαλοι Π1 × 11.95 m (38,646.30 kg χάλυβα)
A33: ΠΥΛ. 4 | B33: ="Cross-Check Πυλώνας 4: Προεντεταμένες Αγκυρώσεις (" & '1_Στοιχεία_Μελέτης_&_Ποσότητες'!C96 & " τεμ., " & '1_Στοιχεία_Μελέτης_&_Ποσότητες'!C48 & "-Strands 0.6'')" -> Cross-Check Πυλώνας 4: Προεντεταμένες Αγκυρώσεις (70 τεμ., 4-Strands 0.6'') | F33: =SUM(F15:F20) -> 53949.4 | G33: =F33/$F$36 -> 0.27806206 | H33: ="=" & TEXT('1_Στοιχεία_Μελέτης_&_Ποσότητες'!C93,"#,##0.00") & " m διάτρησης, " & TEXT('1_Στοιχεία_Μελέτης_&_Ποσότητες'!C95,"#,##0.00") & " m τενόντων" -> =1,050.00 m διάτρησης, 4,480.00 m τενόντων
A34: CHECK | B34: Άθροισμα 4 Πυλώνων (Πυλώνας 1 + Πυλώνας 2 + Πυλώνας 3 + Πυλώνας 4) | F34: =SUM(F30:F33) -> 194019.28 | G34: =F34/$F$36 -> 1 | H34: ="Διασταύρωση με Άθροισμα Κουτιών (Διαφορά = " & TEXT(F34-F36,"0.00") & " €)" -> Διασταύρωση με Άθροισμα Κουτιών (Διαφορά = 0.00 €)
A36: ΣΥΝΟΛΟ | B36: ΤΕΛΙΚΟ ΣΥΝΟΛΟ ΠΡΟΣΦΟΡΑΣ BERLIN WALL & ΑΓΚΥΡΩΣΕΩΝ (ΧΩΡΙΣ Φ.Π.Α.) | F36: =G6+G24 -> 194019.28 | G36: =1 -> 1 | H36: ="Τελικό Ποσό Προσφοράς (Κουτί TYPE A + Κουτί ΠΥΛ. 1 — Χωρίς Φ.Π.Α. βάσει Κανόνα §3.7.2)" -> Τελικό Ποσό Προσφοράς (Κουτί TYPE A + Κουτί ΠΥΛ. 1 — Χωρίς Φ.Π.Α. βάσει Κανόνα §3.7.2)
A38: 📈 ΒΑΣΙΚΟΙ ΔΕΙΚΤΕΣ ΚΟΣΤΟΥΣ & VALUE ENGINEERING (KPIs ΕΡΓΟΥ)
A39: KPI 1 | B39: Συνολικό Κόστος ανά m² Μετώπου Εκσκαφής (€ / m²) | E39: € / m² | F39: =ROUND(F36/'1_Στοιχεία_Μελέτης_&_Ποσότητες'!C85, 2) -> 348.64 | G39: ="Τελικό Σύνολο " & TEXT(F36,"#,##0.00") & " € / " & TEXT('1_Στοιχεία_Μελέτης_&_Ποσότητες'!C85,"#,##0.00") & " m²" -> Τελικό Σύνολο 194,019.28 € / 556.50 m²
A40: KPI 2 | B40: Συνολικό Κόστος ανά Τρέχον Μέτρο Περιμέτρου (€ / τρ.μ.) | E40: € / τρ.μ. | F40: =ROUND(F36/'1_Στοιχεία_Μελέτης_&_Ποσότητες'!C84, 2) -> 2771.7 | G40: ="Τελικό Σύνολο " & TEXT(F36,"#,##0.00") & " € / " & TEXT('1_Στοιχεία_Μελέτης_&_Ποσότητες'!C84,"#,##0.00") & " τρ.μ." -> Τελικό Σύνολο 194,019.28 € / 70.00 τρ.μ.
A41: KPI 3 | B41: Κόστος Πυλώνα 3 (Νέφκες 2×UPN300, Διάτρηση, Λάμες, Κουγκρί) ανά Πάσσαλο Π1 | E41: € / πάσσαλο | F41: =ROUND(F32/'1_Στοιχεία_Μελέτης_&_Ποσότητες'!C83, 2) -> 2723.56 | G41: ="Σύνολο Πυλώνα 3 (" & TEXT(F32,"#,##0.00") & " €) / " & '1_Στοιχεία_Μελέτης_&_Ποσότητες'!C83 & " πασσάλους Π1 (Πλήρες έργο/πάσσαλο = " & TEXT(F36/'1_Στοιχεία_Μελέτης_&_Ποσότητες'!C83,"#,##0.00") & " €)" -> Σύνολο Πυλώνα 3 (95,324.69 €) / 35 πασσάλους Π1 (Πλήρες έργο/πάσσαλο = 5,543.41 €)
A42: KPI 4 | B42: Κόστος Πυλώνα 4 (Πλήρες Σύστημα Προεντεταμένης Αγκύρωσης) ανά Αγκύρωση | E42: € / αγκύρωση | F42: =ROUND(F33/'1_Στοιχεία_Μελέτης_&_Ποσότητες'!C96, 2) -> 770.71 | G42: ="Σύνολο Πυλώνα 4 (" & TEXT(F33,"#,##0.00") & " €) / " & '1_Στοιχεία_Μελέτης_&_Ποσότητες'!C96 & " αγκυρώσεις" -> Σύνολο Πυλώνα 4 (53,949.40 €) / 70 αγκυρώσεις
A43: KPI 5 | B43: Κόστος Πυλώνα 2 (Σχάρα Y10/150×150 & Shotcrete C30/37) ανά m² Μετώπου | E43: € / m² | F43: =ROUND(F31/'1_Στοιχεία_Μελέτης_&_Ποσότητες'!C85, 2) -> 75.55 | G43: ="Σύνολο Πυλώνα 2 (" & TEXT(F31,"#,##0.00") & " €) / " & TEXT('1_Στοιχεία_Μελέτης_&_Ποσότητες'!C85,"#,##0.00") & " m²" -> Σύνολο Πυλώνα 2 (42,045.19 €) / 556.50 m²

Sheet 3_Πίνακες_Διατομών_Χάλυβα
A1: ΒΙΒΛΙΟΘΗΚΗ ΔΙΑΤΟΜΩΝ ΧΑΛΥΒΑ (EUROPEAN STRUCTURAL STEEL PROFILES)
A2: Τεχνικά χαρακτηριστικά & θεωρητικά βάρη ανά μέτρο για διατομές HEA, HEB, UPN, Ισοσκελείς Γωνίες (L) & Ράβδους B500C
A4: 1. ΔΙΑΤΟΜΕΣ HEA (Ευρωπαϊκά Πλατύπελμα Ελαφρού Τύπου)
A5: Ονομασία Διατομής | B5: Ύψος h (mm) | C5: Πλάτος b (mm) | D5: Πάχος tw (mm) | E5: Πάχος tf (mm) | F5: Διατομή A (cm²) | G5: Βάρος (kg / m)
A6: HEA 140 | B6: 133 | C6: 140 | D6: 5.5 | E6: 8.5 | F6: 31.4 | G6: 24.7
A7: HEA 160 | B7: 152 | C7: 160 | D7: 6 | E7: 9 | F7: 38.8 | G7: 30.4
A8: HEA 180 | B8: 171 | C8: 180 | D8: 6 | E8: 9.5 | F8: 45.3 | G8: 35.5
A9: HEA 200 | B9: 190 | C9: 200 | D9: 6.5 | E9: 10 | F9: 53.8 | G9: 42.3
A10: HEA 220 | B10: 210 | C10: 220 | D10: 7 | E10: 11 | F10: 64.3 | G10: 50.5
A11: HEA 240 | B11: 230 | C11: 240 | D11: 7.5 | E11: 12 | F11: 76.8 | G11: 60.3
A12: HEA 260 | B12: 250 | C12: 260 | D12: 7.5 | E12: 12.5 | F12: 86.8 | G12: 68.2
A13: HEA 280 | B13: 270 | C13: 280 | D13: 8 | E13: 13 | F13: 97.3 | G13: 76.4
A14: HEA 300 | B14: 290 | C14: 300 | D14: 8.5 | E14: 14 | F14: 112.5 | G14: 88.3
A16: 2. ΔΙΑΤΟΜΕΣ HEB (Ευρωπαϊκά Πλατύπελμα Κανονικού Τύπου)
A17: Ονομασία Διατομής | B17: Ύψος h (mm) | C17: Πλάτος b (mm) | D17: Πάχος tw (mm) | E17: Πάχος tf (mm) | F17: Διατομή A (cm²) | G17: Βάρος (kg / m)
A18: HEB 140 | B18: 140 | C18: 140 | D18: 7 | E18: 12 | F18: 43 | G18: 33.7
A19: HEB 160 | B19: 160 | C19: 160 | D19: 8 | E19: 13 | F19: 54.3 | G19: 42.6
A20: HEB 180 | B20: 180 | C20: 180 | D20: 8.5 | E20: 14 | F20: 65.3 | G20: 51.2
A21: HEB 200 | B21: 200 | C21: 200 | D21: 9 | E21: 15 | F21: 78.1 | G21: 61.3
A22: HEB 220 | B22: 220 | C22: 220 | D22: 9.5 | E22: 16 | F22: 91 | G22: 71.5
A23: HEB 240 | B23: 240 | C23: 240 | D23: 10 | E23: 17 | F23: 106 | G23: 83.2
A24: HEB 260 | B24: 260 | C24: 260 | D24: 10 | E24: 17.5 | F24: 118.4 | G24: 93
A25: HEB 280 | B25: 280 | C25: 280 | D25: 10.5 | E25: 18 | F25: 131.4 | G25: 103
A26: HEB 300 | B26: 300 | C26: 300 | D26: 11 | E26: 19 | F26: 149.1 | G26: 117
A28: 3. ΔΙΑΤΟΜΕΣ UPN (Ευρωπαϊκά Κοίλα Προφίλ U — Ενεργή Διατομή Έργου: UPN 300 = 46.20 kg/m)
A29: Ονομασία Διατομής | B29: Ύψος h (mm) | C29: Πλάτος b (mm) | D29: Πάχος tw (mm) | E29: Πάχος tf (mm) | F29: Διατομή A (cm²) | G29: Βάρος (kg / m)
A30: UPN 140 | B30: 140 | C30: 60 | D30: 7 | E30: 10 | F30: 20.4 | G30: 16
A31: UPN 160 | B31: 160 | C31: 65 | D31: 7.5 | E31: 10.5 | F31: 24 | G31: 18.8
A32: UPN 180 | B32: 180 | C32: 70 | D32: 8 | E32: 11 | F32: 28 | G32: 22
A33: UPN 200 | B33: 200 | C33: 75 | D33: 8.5 | E33: 11.5 | F33: 32.2 | G33: 25.3
A34: UPN 220 | B34: 220 | C34: 80 | D34: 9 | E34: 12.5 | F34: 37.4 | G34: 29.4
A35: UPN 240 | B35: 240 | C35: 85 | D35: 9.5 | E35: 13 | F35: 42.3 | G35: 33.2
A36: UPN 260 | B36: 260 | C36: 90 | D36: 10 | E36: 14 | F36: 48.3 | G36: 37.9
A37: UPN 280 | B37: 280 | C37: 95 | D37: 10 | E37: 15 | F37: 53.3 | G37: 41.8
A38: UPN 300 | B38: 300 | C38: 100 | D38: 10 | E38: 16 | F38: 58.8 | G38: 46.2
A40: 4. ΙΣΟΣΚΕΛΕΙΣ ΓΩΝΙΕΣ (Equal Angles L)
A41: Ονομασία Διατομής | B41: Ύψος h (mm) | C41: Πλάτος b (mm) | D41: Πάχος tw (mm) | E41: Πάχος tf (mm) | F41: Διατομή A (cm²) | G41: Βάρος (kg / m)
A42: L 50x50x5 | B42: 50 | C42: 50 | D42: 5 | E42: 5 | F42: 4.8 | G42: 3.77
A43: L 60x60x6 | B43: 60 | C43: 60 | D43: 6 | E43: 6 | F43: 6.91 | G43: 5.42
A44: L 70x70x6 | B44: 70 | C44: 70 | D44: 6 | E44: 6 | F44: 8.13 | G44: 6.38
...
