Workbook

Sheet 1_Στοιχεία_Μελέτης_&_Ποσότητες
A1: ΕΡΓΟ: BOLTON TOWER (BERLIN WALL & ΑΓΚΥΡΩΣΕΙΣ) — ΣΤΟΙΧΕΙΑ ΜΕΛΕΤΗΣ & ΦΥΣΙΚΕΣ ΠΟΣΟΤΗΤΕΣ (ΧΩΡΙΣ ΕΥΡΩ)
A2: ΧΩΡΙΣΜΕΝΟ ΣΕ 2 ΜΕΓΑΛΑ ΚΕΦΑΛΑΙΑ: [ΚΕΦΑΛΑΙΟ Α] = ΜΟΝΟ ΣΤΟΙΧΕΙΑ ΜΕΛΕΤΗΣ (RAW INPUTS) | [ΚΕΦΑΛΑΙΟ Β] = ΟΛΟΙ ΟΙ ΥΠΟΛΟΓΙΣΜΟΙ
A4: 🏛️ ΚΕΦΑΛΑΙΟ Α: ΜΟΝΟ ΣΤΟΙΧΕΙΑ ΠΟΥ ΔΙΑΒΑΣΤΗΚΑΝ ΑΠΟ ΤΗ ΜΕΛΕΤΗ (RAW INPUTS)
A5: Περιγραφή Στοιχείου Μελέτης | B5: Τιμή / Εισαγωγή | C5: Μονάδα | D5: Πηγή Μελέτης (Σχέδιο / Σελίδα) | E5: Τεχνική Σημείωση / Έλεγχος Κανόνα
A6: Α.1 Τοποθεσία Εργοταξίου, Έδρα & Σειρές Αγκυρώσεων
A7: Έδρα Εταιρείας (Αφετηρία) | B7: Άγιος Συλάς, Σπύρου Κυπριανού 32, Λεμεσός | C7: - | D7: Βάση Εταιρείας | E7: Σταθερή βάση εκκίνησης συνεργείων & μηχανημάτων
A8: Τοποθεσία Εργοταξίου | B8: Λεμεσός (Bolton Tower) | C8: - | D8: Σχέδιο ΘΕΜ/1 & ΘΕΜ/6 | E8: Ανάπτυξη Bolton Tower, Λακέμια Κτηματική Λτδ
A9: Χιλιομετρική Απόσταση από Έδρα | B9: 12 | C9: km | D9: Google Maps / Οδικό Δίκτυο | E9: Βασική ζώνη 0-40 km (εντός Λεμεσού, βασικές τιμές μετακινήσεων)
A10: Μέγιστο Πλήθος Οριζόντιων Σειρών Αγκυρώσεων Μελέτης | B10: 4 | C10: σειρές | D10: Σχέδιο ΘΕΜ/6, Τομές A, B, Γ | E10: Τοίχοι Α & Β: 4 σειρές, Τοίχος Γ: 3 σειρές
A11: Α.2 Γεωμετρία Μετώπου Εκσκαφής ανά Τύπο Τοίχου (Wall Breakout)
A12: Αξονική Απόσταση Πασσάλων (s_c/c) | B12: 1.5 | C12: m | D12: Σχέδιο ΘΕΜ/1 & ΘΕΜ/6 | E12: [!!! ΣΥΓΚΡΟΥΣΗ ΜΕΛΕΤΗΣ !!!]: Αναγράφονται 2 διαφορετικοί αριθμοί για την αξονική απόσταση: @ 2000mm στο κείμενο λεπτομέρειας τοίχου vs (1500) στη διάσταση CL και 1.50m στις τομές. Επιλέχθηκε ο πιο ασφαλής στατικά αριθμός s = 1.50 m.
A13: Πλήθος Πασσάλων Τοίχου Α (N_piles_A) | B13: 24 | C13: πάσσαλοι | D13: Σχέδιο ΘΕΜ/1 (Κάτοψη) & OpenCV | E13: 24 πάσσαλοι (Ανατολικό & Νότιο τμήμα Τοίχου Α)
A14: Μήκος Τοίχου Α (L_A) | B14: =B13*B12 | C14: m | D14: Σχέδιο ΘΕΜ/1 (Intervals) | E14: ="=" & B13 & " πάσσαλοι × " & TEXT(B12, "0.00") & " m = " & TEXT(B13*B12, "0.00") & " m"
A15: Ελεύθερο Ύψος Εκσκαφής Τοίχου Α (H_exc_A) | B15: 17 | C15: m | D15: Σχέδιο ΘΕΜ/6, Τομή Τοίχου Α | E15: Αναγραφόμενο ύψος 17000 mm (17.0 m)
A16: Βάθος Πάκτωσης Νέφκας Τοίχου Α (H_embed_A) | B16: 2 | C16: m | D16: Σχέδιο ΘΕΜ/6, Τομή Τοίχου Α | E16: Αναγραφόμενο βάθος πάκτωσης 2000 mm (2.0 m)
A17: Πλήθος Πασσάλων Τοίχου Β (N_piles_B) | B17: 63 | C17: πάσσαλοι | D17: Σχέδιο ΘΕΜ/1 (Κάτοψη) & OpenCV | E17: 63 πάσσαλοι (Βόρειο, Βορειοανατολικό & Νότιο τμήμα Τοίχου Β)
A18: Μήκος Τοίχου Β (L_B) | B18: =B17*B12 | C18: m | D18: Σχέδιο ΘΕΜ/1 (Intervals) | E18: ="=" & B17 & " πάσσαλοι × " & TEXT(B12, "0.00") & " m = " & TEXT(B17*B12, "0.00") & " m"
A19: Ελεύθερο Ύψος Εκσκαφής Τοίχου Β (H_exc_B) | B19: 15.6 | C19: m | D19: Σχέδιο ΘΕΜ/6, Τομή Τοίχου Β | E19: Αναγραφόμενο ύψος 15600 mm (15.6 m)
A20: Βάθος Πάκτωσης Νέφκας Τοίχου Β (H_embed_B) | B20: 2 | C20: m | D20: Σχέδιο ΘΕΜ/6, Τομή Τοίχου Β | E20: Αναγραφόμενο βάθος πάκτωσης 2000 mm (2.0 m)
A21: Πλήθος Πασσάλων Τοίχου Γ (N_piles_C) | B21: 11 | C21: πάσσαλοι | D21: Σχέδιο ΘΕΜ/1 (Κάτοψη) & OpenCV | E21: 11 πάσσαλοι (Βορειοδυτικό τμήμα Τοίχου Γ)
A22: Μήκος Τοίχου Γ (L_C) | B22: =B21*B12 | C22: m | D22: Σχέδιο ΘΕΜ/1 (Intervals) | E22: ="=" & B21 & " πάσσαλοι × " & TEXT(B12, "0.00") & " m = " & TEXT(B21*B12, "0.00") & " m"
A23: Ελεύθερο Ύψος Εκσκαφής Τοίχου Γ (H_exc_C) | B23: 11.1 | C23: m | D23: Σχέδιο ΘΕΜ/6, Τομή Τοίχου Γ | E23: Αναγραφόμενο ύψος 11100 mm (11.1 m)
A24: Βάθος Πάκτωσης Νέφκας Τοίχου Γ (H_embed_C) | B24: 2 | C24: m | D24: Σχέδιο ΘΕΜ/6, Τομή Τοίχου Γ | E24: Αναγραφόμενο βάθος πάκτωσης 2000 mm (2.0 m)
A26: Α.3 Σχάρες & Εκτοξευόμενο Σκυρόδεμα (Shotcrete)
A27: Τύπος Χάλυβα Σχάρας | B27: B500C Δομικός Χάλυβας | C27: - | D27: Σχέδιο ΘΕΜ/6, Λεπτομέρεια | E27: Συγκόλληση ράβδων σχάρας στις γωνιές 70x70x6mm
A28: Διάμετρος Οριζόντιων Ράβδων Σχάρας (Y_horiz) | B28: 8 | C28: mm | D28: Σχέδιο ΘΕΜ/6, Λεπτομέρεια | E28: Αναγράφεται ρητά #Y8/150 (αυστηρή τήρηση Y8 βάσει κανόνα 2.3)
A29: Οριζόντιο Βήμα Ράβδων Σχάρας (s_horiz) | B29: 150 | C29: mm | D29: Σχέδιο ΘΕΜ/6, Λεπτομέρεια | E29: Βήμα οριζόντιων ράβδων ανά 0.15m (6.67 m/m²)
A30: Διάμετρος Κατακόρυφων Ράβδων Σχάρας (Y_vert) | B30: 8 | C30: mm | D30: Σχέδιο ΘΕΜ/6, Λεπτομέρεια | E30: Αναγράφεται ρητά #Y8/150 (αυστηρή τήρηση Y8 βάσει κανόνα 2.3)
A31: Κατακόρυφο Βήμα Ράβδων Σχάρας (s_vert) | B31: 150 | C31: mm | D31: Σχέδιο ΘΕΜ/6, Λεπτομέρεια | E31: Βήμα κατακόρυφων ράβδων ανά 0.15m (6.67 m/m²)
A32: Κατηγορία Σκυροδέματος Shotcrete | B32: C30/37 | C32: - | D32: Κανόνας Εταιρείας | E32: [DEFAULT ΕΤΑΙΡΕΙΑΣ]: Δεν αναγράφεται στη μελέτη. Εφαρμόζεται by default C30/37 βάσει κανόνα εταιρείας.
A33: Ονομαστικό Πάχος Shotcrete Μελέτης | B33: 0.15 | C33: m | D33: Σχέδιο ΘΕΜ/6, Λεπτομέρεια | E33: 150 mm (15 cm) εκτοξευόμενο σκυρόδεμα (gunite)
A34: Πάγια Απώλεια / Αναπήδηση Εταιρείας | B34: 0.05 | C34: m | D34: Κανόνας Εταιρείας | E34: +5 cm πάγια προσαύξηση εταιρείας για αναπήδηση (χρεώνεται στα €/m³)
A36: Α.4 H-Beams (Νέφκες: Οπές, Χάλυβας HEB 220 & HEB 200, Λάμες, Κουγκρί, Γωνιές)
A37: Διάμετρος Οπής Διάτρησης Μεγάλου Τρυπανιού (D) | B37: 0.8 | C37: m | D37: Κανόνας Εταιρείας | E37: [DEFAULT ΕΤΑΙΡΕΙΑΣ]: Δεν αναγράφεται διάμετρος νέφκας στη μελέτη (το D=800 στο ΘΕΜ/1 αφορά υποστυλώματα κτιρίου). Εφαρμόζεται by default Ø800 mm βάσει κανόνα εταιρείας.
A38: Διατομή Χάλυβα Τοίχου Α | B38: 2 No. HEB 220 | C38: - | D38: Σχέδιο ΘΕΜ/6, Τομή Τοίχου Α | E38: 2 HEB 220 / 1.5m (αναγράφεται ρητά στην τομή Α)
A39: Θεωρητικό Βάρος Προφίλ HEB 220 ανά Μέτρο | B39: 71.5 | C39: kg / m | D39: Βιβλιοθήκη Διατομών (Φύλλο 3) | E39: 71.5 kg/m ανά HEB 220 (143.0 kg/m ανά πάσσαλο)
A40: Διατομή Χάλυβα Τοίχων Β & Γ | B40: 2 No. HEB 200 | C40: - | D40: Σχέδιο ΘΕΜ/6, Τομές Β & Γ | E40: 2 HEB 200 / 1.5m (αναγράφεται ρητά στις τομές Β & Γ)
A41: Θεωρητικό Βάρος Προφίλ HEB 200 ανά Μέτρο | B41: 61.3 | C41: kg / m | D41: Βιβλιοθήκη Διατομών (Φύλλο 3) | E41: 61.3 kg/m ανά HEB 200 (122.6 kg/m ανά πάσσαλο)
A42: Πλήθος Προφίλ ανά Πάσσαλο | B42: 2 | C42: προφίλ/οπή | D42: Σχέδιο ΘΕΜ/6, Λεπτομέρεια | E42: Δίδυμο προφίλ 2 No. HEB ανά οπή
A43: Κατακόρυφο Βήμα Λαμών ανά Νέφκα (s_plate) | B43: 1 | C43: m | D43: Σχέδιο ΘΕΜ/6, Λεπτομέρεια | E43: Λάμες 200x10mm ανά 1000mm (1.0m) καθ' ύψος
...

Sheet 2_Υπολογισμοί_&_Κοστολόγηση
A1: ΕΡΓΟ: BOLTON TOWER (BERLIN WALL & ΑΓΚΥΡΩΣΕΙΣ) — ΟΙΚΟΝΟΜΙΚΗ ΠΡΟΣΦΟΡΑ & ΚΟΣΤΟΛΟΓΗΣΗ
A2: Οι τιμές μονάδας περιλαμβάνουν ήδη γενικά έξοδα, απρόβλεπτα & εργολαβικό όφελος | [ΚΙΤΡΙΝΟ #FFF2CC] = Τιμές Μονάδας | [ΠΟΡΤΟΚΑΛΙ #FFE699] = Κουγκρί Πάκτωσης
A4: Περιγραφή Εργασίας / Υλικού | B4: Ποσότητα | C4: Μονάδα | D4: Τιμή Μονάδας (€) | E4: Συνολικό Κόστος (€) | F4: Πηγή Ποσότητας / Τεχνικός Κανόνας
A5: ΠΥΛΩΝΑΣ 1: ΜΕΤΑΚΙΝΗΣΕΙΣ & ΣΤΡΑΤΕΣ (3 ΕΙΔΗ)
A6: Μετακίνηση Μεγάλου Τρυπανιού (Piling Rig) | B6: ='1_Στοιχεία_Μελέτης_&_Ποσότητες'!B86 | C6: στράτες | D6: 1500 | E6: =B6*D6 | F6: Βάση Λεμεσός (0-40 km από έδρα Αγίου Συλά: 1,500€ βασική)
A7: Μετακινήσεις Εξοπλισμού Αγκυρώσεων | B7: ='1_Στοιχεία_Μελέτης_&_Ποσότητες'!B87 | C7: στράτες | D7: 300 | E7: =B7*D7 | F7: ='1_Στοιχεία_Μελέτης_&_Ποσότητες'!B87 & " στράτες (όσες οι σειρές αγκυρώσεων = 4 στα 300€)"
A8: Μετακινήσεις Συνεργείου & Αντλίας Shotcrete | B8: ='1_Στοιχεία_Μελέτης_&_Ποσότητες'!B88 | C8: στράτες | D8: 200 | E8: =B8*D8 | F8: ='1_Στοιχεία_Μελέτης_&_Ποσότητες'!B88 & " στράτες (σειρές αγκυρώσεων + 1 = 5 στα 200€)"
A9: ΣΥΝΟΛΟ ΠΥΛΩΝΑ 1 (ΜΕΤΑΚΙΝΗΣΕΙΣ) | E9: =SUM(E6:E8)
A11: ΠΥΛΩΝΑΣ 2: ΣΧΑΡΕΣ & ΕΚΤΟΞΕΥΟΜΕΝΟ ΣΚΥΡΟΔΕΜΑ (SHOTCRETE)
A12: ="Αγορά Χάλυβα Σχάρας (#Y" & '1_Στοιχεία_Μελέτης_&_Ποσότητες'!B28 & "/" & '1_Στοιχεία_Μελέτης_&_Ποσότητες'!B29 & ")" | B12: ='1_Στοιχεία_Μελέτης_&_Ποσότητες'!B103 | C12: kg | D12: 2.5 | E12: =B12*D12 | F12: ="Από Φύλλο 1 (" & TEXT(B12, "#,##0.00") & " kg) × 2.50 €/kg"
A13: Τοποθέτηση Σχάρας / Εργατικά Μετώπου | B13: ='1_Στοιχεία_Μελέτης_&_Ποσότητες'!B95 | C13: m² | D13: 15 | E13: =B13*D13 | F13: ="Από Φύλλο 1 (" & TEXT(B13, "#,##0.00") & " m²) × 15.00 €/m²"
A14: ="Αγορά Σκυροδέματος Shotcrete (" & '1_Στοιχεία_Μελέτης_&_Ποσότητες'!B32 & ")" | B14: ='1_Στοιχεία_Μελέτης_&_Ποσότητες'!B106 | C14: m³ | D14: 90 | E14: =B14*D14 | F14: ="Σταθερή τιμή αγοράς C30/37 (90.00 €/m³) για " & TEXT(B14, "#,##0.00") & " m³"
A15: Τοποθέτηση / Εκτόξευση / Αντλία (με προσαύξηση απώλειας) | B15: ='1_Στοιχεία_Μελέτης_&_Ποσότητες'!B106 | C15: m³ | D15: =ROUND((IF(B14>7, 200, 250)*(1+'1_Στοιχεία_Μελέτης_&_Ποσότητες'!B105))-90, 2) | E15: =B15*D15 | F15: ="Βάση " & IF(B14>7,200,250) & "€ × (1+" & TEXT('1_Στοιχεία_Μελέτης_&_Ποσότητες'!B105, "0.0%") & " απώλεια) - 90€ αγορά"
A16: ΣΥΝΟΛΟ ΠΥΛΩΝΑ 2 (ΣΧΑΡΕΣ & SHOTCRETE) | E16: =SUM(E12:E15)
A18: ΠΥΛΩΝΑΣ 3: H-BEAMS (ΝΕΦΚΕΣ / SOLDIER PILES — PROFILE BREAKOUT)
A19: ="3.1 Διάτρηση Μεγάλου Τρυπανιού (Ø" & TEXT('1_Στοιχεία_Μελέτης_&_Ποσότητες'!B37*1000, "0") & " mm)" | B19: ='1_Στοιχεία_Μελέτης_&_Ποσότητες'!B115 | C19: m | D19: 75 | E19: =B19*D19 | F19: ="Ελάχιστη διάμετρος Ø800 mm για " & '1_Στοιχεία_Μελέτης_&_Ποσότητες'!B91 & " πασσάλους στα 75.00 €/m"
A20: ="3.2α Νέφκες Χάλυβα (" & '1_Στοιχεία_Μελέτης_&_Ποσότητες'!B38 & " - Τοίχος Α)" | B20: ='1_Στοιχεία_Μελέτης_&_Ποσότητες'!B118 | C20: kg | D20: 1.4 | E20: =B20*D20 | F20: ="1.00 €/kg αγορά + 0.40 €/kg επεξεργασία = 1.40 €/kg (2 No. HEB 220, " & '1_Στοιχεία_Μελέτης_&_Ποσότητες'!B13 & " πάσσαλοι)"
A21: ="3.2β Νέφκες Χάλυβα (" & '1_Στοιχεία_Μελέτης_&_Ποσότητες'!B40 & " - Τοίχοι Β & Γ)" | B21: ='1_Στοιχεία_Μελέτης_&_Ποσότητες'!B119 | C21: kg | D21: 1.4 | E21: =B21*D21 | F21: ="1.00 €/kg αγορά + 0.40 €/kg επεξεργασία = 1.40 €/kg (2 No. HEB 200, " & ('1_Στοιχεία_Μελέτης_&_Ποσότητες'!B17+'1_Στοιχεία_Μελέτης_&_Ποσότητες'!B21) & " πάσσαλοι)"
A22: ="3.3 Λάμες Σύνδεσης/Ενίσχυσης (" & '1_Στοιχεία_Μελέτης_&_Ποσότητες'!B44 & "×" & '1_Στοιχεία_Μελέτης_&_Ποσότητες'!B45 & "×" & '1_Στοιχεία_Μελέτης_&_Ποσότητες'!B46 & " mm)" | B22: ='1_Στοιχεία_Μελέτης_&_Ποσότητες'!B126 | C22: kg | D22: 1.6 | E22: =B22*D22 | F22: 1.00 €/kg αγορά + 0.60 €/kg τοποθέτηση = 1.60 €/kg
A23: ="3.4 Κουγκρί Πάκτωσης Οπών Νέφκας (" & '1_Στοιχεία_Μελέτης_&_Ποσότητες'!B47 & ")" | B23: ='1_Στοιχεία_Μελέτης_&_Ποσότητες'!B127 | C23: m³ | D23: 120 | E23: =B23*D23 | F23: 120.00 €/m³ (Διακριτό πορτοκαλί χρώμα #FFE699 για άμεση εποπτεία)
A24: ="3.5 Γωνιές Στήριξης (" & '1_Στοιχεία_Μελέτης_&_Ποσότητες'!B49 & " - αν ζητούνται)" | B24: ='1_Στοιχεία_Μελέτης_&_Ποσότητες'!B129 | C24: kg | D24: 1.6 | E24: =B24*D24 | F24: 1.00 €/kg αγορά + 0.60 €/kg επεξεργασία = 1.60 €/kg
A25: ΣΥΝΟΛΟ ΠΥΛΩΝΑ 3 (H-BEAMS / ΝΕΦΚΕΣ) | E25: =SUM(E19:E24)
A27: ΠΥΛΩΝΑΣ 4: ΑΓΚΥΡΩΣΕΙΣ (PRESTRESSED TIEBACK ANCHORS — STRAND BREAKOUT)
A28: ="4.1 Διάτρηση / Τρύπημα Αγκυρώσεων (Ø" & TEXT('1_Στοιχεία_Μελέτης_&_Ποσότητες'!B53*1000, "0") & " mm)" | B28: ='1_Στοιχεία_Μελέτης_&_Ποσότητες'!B141 | C28: m | D28: 30 | E28: =B28*D28 | F28: ="Διάτρηση Ø120 mm για " & '1_Στοιχεία_Μελέτης_&_Ποσότητες'!B135 & " αγκυρώσεις στα 30.00 €/m"
A29: 4.2 Grout Τσιμεντένεμα Αγκυρώσεων (με απώλεια 1.20) | B29: ='1_Στοιχεία_Μελέτης_&_Ποσότητες'!B143 | C29: m³ | D29: 500 | E29: =B29*D29 | F29: ="500.00 €/m³ grout πλήρωσης οπής για " & TEXT(B29, "#,##0.00") & " m³"
A30: 4.3 Τένοντες Προέντασης (Strands 0.6" - 1.10 kg/m) | B30: ='1_Στοιχεία_Μελέτης_&_Ποσότητες'!B147 | C30: m | D30: 2.28 | E30: =B30*D30 | F30: ="2.28 €/m τρέχον τένοντα (" & '1_Στοιχεία_Μελέτης_&_Ποσότητες'!B136 & " αγκ. 2-strands & " & '1_Στοιχεία_Μελέτης_&_Ποσότητες'!B137 & " αγκ. 3-strands, συμπεριλαμβάνει +1.0m)"
A31: 4.4 Προένταση Αγκυρώσεων (Stressing & Lock-off) | B31: ='1_Στοιχεία_Μελέτης_&_Ποσότητες'!B135 | C31: τεμ. | D31: 18 | E31: =B31*D31 | F31: ="18.00 € ανά οπή / αγκύρωση για " & '1_Στοιχεία_Μελέτης_&_Ποσότητες'!B135 & " αγκυρώσεις"
A32: 4.5 Κεφαλή Αγκύρωσης (Anchor Head, Wedges, Plate) | B32: ='1_Στοιχεία_Μελέτης_&_Ποσότητες'!B135 | C32: τεμ. | D32: 55 | E32: =B32*D32 | F32: ="55.00 € ανά οπή / αγκύρωση πλήρες σετ για " & '1_Στοιχεία_Μελέτης_&_Ποσότητες'!B135 & " αγκυρώσεις"
A33: ΣΥΝΟΛΟ ΠΥΛΩΝΑ 4 (ΑΓΚΥΡΩΣΕΙΣ) | E33: =SUM(E28:E32)
A35: ΤΕΛΙΚΑ ΣΥΝΟΛΑ ΠΡΟΣΦΟΡΑΣ (ΓΕΝΙΚΑ ΕΞΟΔΑ & ΚΕΡΔΟΣ ΕΝΣΩΜΑΤΩΜΕΝΑ ΣΤΙΣ ΤΙΜΕΣ)
A36: ΚΑΘΑΡΟ ΣΥΝΟΛΟ ΠΡΟΣΦΟΡΑΣ (ΠΡΟ Φ.Π.Α.) | E36: =E9+E16+E25+E33 | F36: Άθροισμα 4 Πυλώνων (Περιλαμβάνει Γενικά Έξοδα & Όφελος)
A37: Φ.Π.Α. (19%) | E37: =ROUND(E36*0.19, 2) | F37: Νόμιμος Φ.Π.Α. Κύπρου (19%)
A38: ΤΕΛΙΚΟ ΠΛΗΡΩΤΕΟ ΠΟΣΟ (ΜΕ Φ.Π.Α.) | E38: =E36+E37 | F38: Τελικό πληρωτέο ποσό έργου
A40: ΒΑΣΙΚΟΙ ΔΕΙΚΤΕΣ ΚΟΣΤΟΥΣ & VALUE ENGINEERING (KPIs)
A41: KPI 1: Συνολικό Κόστος ανά m² Μετώπου Εκσκαφής | C41: € / m² | E41: =ROUND(E36/'1_Στοιχεία_Μελέτης_&_Ποσότητες'!B95, 2) | F41: ="Καθαρό σύνολο / " & TEXT('1_Στοιχεία_Μελέτης_&_Ποσότητες'!B95, "#,##0.00") & " m²"
A42: KPI 2: Συνολικό Κόστος ανά Τρέχον Μέτρο Περιμέτρου | C42: € / τρέχον m | E42: =ROUND(E36/'1_Στοιχεία_Μελέτης_&_Ποσότητες'!B90, 2) | F42: ="Καθαρό σύνολο / " & TEXT('1_Στοιχεία_Μελέτης_&_Ποσότητες'!B90, "#,##0.00") & " m"
A43: KPI 3: Συνολικό Κόστος ανά Πάσσαλο / Οπή Berlin Wall | C43: € / πάσσαλο | E43: =ROUND(E36/'1_Στοιχεία_Μελέτης_&_Ποσότητες'!B91, 2) | F43: ="Καθαρό σύνολο / " & '1_Στοιχεία_Μελέτης_&_Ποσότητες'!B91 & " πάσσαλοι"
A44: KPI 4: Συνολικό Κόστος ανά Αγκύρωση (Πλήρες Σύστημα) | C44: € / αγκύρωση | E44: =ROUND(E33/'1_Στοιχεία_Μελέτης_&_Ποσότητες'!B135, 2) | F44: ="Σύνολο Πυλώνα 4 / " & '1_Στοιχεία_Μελέτης_&_Ποσότητες'!B135 & " αγκυρώσεις"

Sheet 3_Πίνακες_Διατομών_Χάλυβα
A1: ΒΙΒΛΙΟΘΗΚΗ ΔΙΑΤΟΜΩΝ ΧΑΛΥΒΑ (EUROPEAN STRUCTURAL STEEL PROFILES)
A2: Τεχνικά χαρακτηριστικά & βάρη ανά μέτρο για διατομές HEA, HEB, UPN & Γωνιών (L)
A4: 1. ΔΙΑΤΟΜΕΣ HEA (Ευρωπαϊκά Πλατύπελμα Ελαφρού Τύπου)
A5: Ονομασία Διατομής | B5: Ύψος h (mm) | C5: Πλάτος b (mm) | D5: Πάχος tw (mm) | E5: Πάχος tf (mm) | F5: Διατομή A (cm²) | G5: Βάρος (kg / m)
A6: HEA 140 | B6: 133 | C6: 140 | D6: 5.5 | E6: 8.5 | F6: 31.4 | G6: 24.7
A7: HEA 160 | B7: 152 | C7: 160 | D7: 6 | E7: 9 | F7: 38.8 | G7: 30.4
A8: HEA 180 | B8: 171 | C8: 180 | D8: 6 | E8: 9.5 | F8: 45.3 | G8: 35.5
A9: HEA 200 | B9: 190 | C9: 200 | D9: 6.5 | E9: 10 | F9: 53.8 | G9: 42.3
A10: HEA 220 | B10: 210 | C10: 220 | D10: 7 | E10: 11 | F10: 64.3 | G10: 50.5
A11: HEA 240 | B11: 230 | C11: 240 | D11: 7.5 | E11: 12 | F11: 76.8 | G11: 60.3
A12: HEA 260 | B12: 250 | C12: 260 | D12: 7.5 | E12: 12.5 | F12: 86.8 | G12: 68.2
A13: HEA 280 | B13: 270 | C13: 280 | D13: 8 | E13: 13 | F13: 97.3 | G13: 76.4
A14: HEA 300 | B14: 290 | C14: 300 | D14: 8.5 | E14: 14 | F14: 112.5 | G14: 88.3
A16: 2. ΔΙΑΤΟΜΕΣ HEB (Ευρωπαϊκά Πλατύπελμα Κανονικού Τύπου)
A17: Ονομασία Διατομής | B17: Ύψος h (mm) | C17: Πλάτος b (mm) | D17: Πάχος tw (mm) | E17: Πάχος tf (mm) | F17: Διατομή A (cm²) | G17: Βάρος (kg / m)
A18: HEB 140 | B18: 140 | C18: 140 | D18: 7 | E18: 12 | F18: 43 | G18: 33.7
A19: HEB 160 | B19: 160 | C19: 160 | D19: 8 | E19: 13 | F19: 54.3 | G19: 42.6
A20: HEB 180 | B20: 180 | C20: 180 | D20: 8.5 | E20: 14 | F20: 65.3 | G20: 51.2
A21: HEB 200 | B21: 200 | C21: 200 | D21: 9 | E21: 15 | F21: 78.1 | G21: 61.3
A22: HEB 220 | B22: 220 | C22: 220 | D22: 9.5 | E22: 16 | F22: 91 | G22: 71.5
A23: HEB 240 | B23: 240 | C23: 240 | D23: 10 | E23: 17 | F23: 106 | G23: 83.2
A24: HEB 260 | B24: 260 | C24: 260 | D24: 10 | E24: 17.5 | F24: 118.4 | G24: 93
A25: HEB 280 | B25: 280 | C25: 280 | D25: 10.5 | E25: 18 | F25: 131.4 | G25: 103
A26: HEB 300 | B26: 300 | C26: 300 | D26: 11 | E26: 19 | F26: 149.1 | G26: 117
A28: 3. ΔΙΑΤΟΜΕΣ UPN (Ευρωπαϊκά Κοίλα Προφίλ U)
A29: Ονομασία Διατομής | B29: Ύψος h (mm) | C29: Πλάτος b (mm) | D29: Πάχος tw (mm) | E29: Πάχος tf (mm) | F29: Διατομή A (cm²) | G29: Βάρος (kg / m)
A30: UPN 140 | B30: 140 | C30: 60 | D30: 7 | E30: 10 | F30: 20.4 | G30: 16
A31: UPN 160 | B31: 160 | C31: 65 | D31: 7.5 | E31: 10.5 | F31: 24 | G31: 18.8
A32: UPN 180 | B32: 180 | C32: 70 | D32: 8 | E32: 11 | F32: 28 | G32: 22
A33: UPN 200 | B33: 200 | C33: 75 | D33: 8.5 | E33: 11.5 | F33: 32.2 | G33: 25.3
A34: UPN 220 | B34: 220 | C34: 80 | D34: 9 | E34: 12.5 | F34: 37.4 | G34: 29.4
A35: UPN 240 | B35: 240 | C35: 85 | D35: 9.5 | E35: 13 | F35: 42.3 | G35: 33.2
A36: UPN 260 | B36: 260 | C36: 90 | D36: 10 | E36: 14 | F36: 48.3 | G36: 37.9
A37: UPN 280 | B37: 280 | C37: 95 | D37: 10 | E37: 15 | F37: 53.3 | G37: 41.8
A38: UPN 300 | B38: 300 | C38: 100 | D38: 10 | E38: 16 | F38: 58.8 | G38: 46.2
A40: 4. ΙΣΟΣΚΕΛΕΙΣ ΓΩΝΙΕΣ (Equal Angles L)
A41: Ονομασία Διατομής | B41: Ύψος h (mm) | C41: Πλάτος b (mm) | D41: Πάχος tw (mm) | E41: Πάχος tf (mm) | F41: Διατομή A (cm²) | G41: Βάρος (kg / m)
A42: L 50x50x5 | B42: 50 | C42: 50 | D42: 5 | E42: 5 | F42: 4.8 | G42: 3.77
A43: L 60x60x6 | B43: 60 | C43: 60 | D43: 6 | E43: 6 | F43: 6.91 | G43: 5.42
A44: L 70x70x6 | B44: 70 | C44: 70 | D44: 6 | E44: 6 | F44: 8.13 | G44: 6.38
...
