Workbook

Sheet 1_Στοιχεία_Μελέτης_&_Ποσότητες
A1: ΕΡΓΟ: BOLTON TOWER (BERLIN WALL & ΑΓΚΥΡΩΣΕΙΣ) — ΣΤΟΙΧΕΙΑ ΜΕΛΕΤΗΣ & ΦΥΣΙΚΕΣ ΠΟΣΟΤΗΤΕΣ ΑΝΑ ΤΥΠΟ ΤΟΙΧΟΥ (ΧΩΡΙΣ ΕΥΡΩ)
A2: ΕΚΔΟΣΗ ΚΑΝΟΝΩΝ v8 | 100% ΔΥΝΑΜΙΚΟΙ ΤΙΤΛΟΙ & ΣΗΜΕΙΩΣΕΙΣ ΣΕ ΚΟΥΤΙΑ (BOXES) ΑΝΑ ΤΥΠΟ ΤΟΙΧΟΥ | [ΚΟΚΚΙΝΟ #FFC7CE] = WPL / Cut-Off Level Εκσκαφής Νεφκών
A4: ΚΕΦΑΛΑΙΟ Α: ΣΤΟΙΧΕΙΑ ΜΕΛΕΤΗΣ (RAW INPUTS) — ΧΩΡΙΣΜΕΝΑ ΣΕ ΚΟΥΤΙΑ ΑΝΑ ΤΥΠΟ ΤΟΙΧΟΥ (100% ΔΥΝΑΜΙΚΗ ΣΥΝΔΕΣΗ)
A5: α/α | B5: ΠΕΡΙΓΡΑΦΗ ΣΤΟΙΧΕΙΟΥ / ΕΡΓΑΣΙΑΣ | C5: ΤΙΜΗ ΜΕΛΕΤΗΣ | D5: ΜΟΝ. | E5: ΠΗΓΗ ΜΕΛΕΤΗΣ (ΣΧΕΔΙΟ) | F5: ΤΕΧΝΙΚΗ ΣΗΜΕΙΩΣΗ / ΕΛΕΓΧΟΣ ΚΑΝΟΝΑ
A6: ΚΟΙΝΑ | B6: ΚΟΥΤΙ Α.0 — ΓΕΝΙΚΑ ΣΤΟΙΧΕΙΑ ΕΡΓΟΥ & ΚΟΙΝΕΣ ΠΡΟΔΙΑΓΡΑΦΕΣ (Εργοτάξιο, Διάτρηση, Λάμες, Γωνιές, Σχάρα, Shotcrete, Αγκυρώσεις)
A7: Κ.1 | B7: Έδρα Εταιρείας (Αφετηρία) | C7: Άγιος Συλάς, Σπύρου Κυπριανού 32, Λεμεσός | D7: - | E7: Βάση Εταιρείας | F7: Σταθερή βάση εκκίνησης συνεργείων & μηχανημάτων
A8: Κ.2 | B8: Τοποθεσία Εργοταξίου & Χιλιομετρική Απόσταση | C8: 12 | D8: km | E8: Σχέδιο ΘΕΜ/1 & ΘΕΜ/6 | F8: ="Λεμεσός (Bolton Tower, " & C8 & " km) — Ζώνη 0-40 km (βασικές τιμές μετακινήσεων)" -> Λεμεσός (Bolton Tower, 12 km) — Ζώνη 0-40 km (βασικές τιμές μετακινήσεων)
A9: Κ.3 | B9: Μέγιστο Πλήθος Οριζόντιων Σειρών Αγκυρώσεων Έργου | C9: 4 | D9: σειρές | E9: Σχέδιο ΘΕΜ/6, Τομές Α, Β, Γ | F9: ="Type A & B: " & C9 & " σειρές αγκυρώσεων | Type C: 3 σειρές αγκυρώσεων" -> Type A & B: 4 σειρές αγκυρώσεων | Type C: 3 σειρές αγκυρώσεων
A10: Κ.4 | B10: Αξονική Απόσταση Πασσάλων (s_c/c) | C10: 1.5 | D10: m | E10: Σχέδιο ΘΕΜ/1 & ΘΕΜ/6 | F10: ="[!!! ΣΥΓΚΡΟΥΣΗ ΜΕΛΕΤΗΣ !!!]: Αναγράφονται 2 διαφορετικοί αριθμοί: @ 2000mm στο κείμενο λεπτομέρειας vs (1500) στη διάσταση CL και 1.50m στις τομές. Επιλέχθηκε ο πιο ασφαλής στατικά αριθμός s = " & TEXT(C10,"0.00") & " m." -> [!!! ΣΥΓΚΡΟΥΣΗ ΜΕΛΕΤΗΣ !!!]: Αναγράφονται 2 διαφορετικοί αριθμοί: @ 2000mm στο κείμενο λεπτομέρειας vs (1500) στη διάσταση CL και 1.50m στις τομές. Επιλέχθηκε ο πιο ασφαλής στατικά αριθμός s = 1.50 m.
A11: Κ.5 | B11: ="Διάμετρος Οπής Διάτρησης Μεγάλου Τρυπανιού (Ø" & (C11*1000) & "mm)" -> Διάμετρος Οπής Διάτρησης Μεγάλου Τρυπανιού (Ø800mm) | C11: 0.8 | D11: m | E11: Κανόνας Εταιρείας | F11: ="[DEFAULT ΕΤΑΙΡΕΙΑΣ]: Δεν αναγράφεται διάμετρος νέφκας στη μελέτη (το D=800 στο ΘΕΜ/1 αφορά υποστυλώματα κτιρίου). Εφαρμόζεται by default Ø" & (C11*1000) & " mm (" & TEXT(C11,"0.00") & " m)." -> [DEFAULT ΕΤΑΙΡΕΙΑΣ]: Δεν αναγράφεται διάμετρος νέφκας στη μελέτη (το D=800 στο ΘΕΜ/1 αφορά υποστυλώματα κτιρίου). Εφαρμόζεται by default Ø800 mm (0.80 m).
A12: Κ.6 | B12: Πλήθος Προφίλ Χάλυβα ανά Πάσσαλο / Οπή | C12: 2 | D12: No/οπή | E12: Σχέδιο ΘΕΜ/6, Λεπτομέρεια | F12: ="Δίδυμο προφίλ (Ζεύγος " & C12 & " No. HEB ανά πάσσαλο)" -> Δίδυμο προφίλ (Ζεύγος 2 No. HEB ανά πάσσαλο)
A13: Κ.7 | B13: Θεωρητικό Βάρος Διατομής HEB 220 (για Type A) | C13: 71.5 | D13: kg/m | E13: Βιβλιοθήκη Διατομών (Φύλλο 3) | F13: ="=" & TEXT(C13,"0.0") & " kg/m ανά HEB 220 (" & TEXT(C13*C12,"0.0") & " kg/m ανά ζεύγος)" -> =71.5 kg/m ανά HEB 220 (143.0 kg/m ανά ζεύγος)
A14: Κ.8 | B14: Θεωρητικό Βάρος Διατομής HEB 200 (για Type B & Type C) | C14: 61.3 | D14: kg/m | E14: Βιβλιοθήκη Διατομών (Φύλλο 3) | F14: ="=" & TEXT(C14,"0.0") & " kg/m ανά HEB 200 (" & TEXT(C14*C12,"0.0") & " kg/m ανά ζεύγος)" -> =61.3 kg/m ανά HEB 200 (122.6 kg/m ανά ζεύγος)
A15: Κ.9 | B15: Κατακόρυφο Βήμα Λαμών Σύνδεσης (s_plate) | C15: 1 | D15: m | E15: Σχέδιο ΘΕΜ/6, Λεπτομέρεια | F15: ="Λάμες " & C16 & "x" & C17 & "x" & C18 & "mm ανά " & (C15*1000) & "mm (" & TEXT(C15,"0.00") & "m) καθ' ύψος (Κανόνας L_beam / s_plate)" -> Λάμες 200x200x10mm ανά 1000mm (1.00m) καθ' ύψος (Κανόνας L_beam / s_plate)
A16: Κ.10α | B16: Πλάτος Λάμας Σύνδεσης (b_plate) | C16: 200 | D16: mm | E16: Σχέδιο ΘΕΜ/6, Λεπτομέρεια | F16: ="Πλάτος λάμας σύνδεσης = " & C16 & " mm (" & TEXT(C16/1000,"0.00") & " m)" -> Πλάτος λάμας σύνδεσης = 200 mm (0.20 m)
A17: Κ.10β | B17: Μήκος / Ύψος Λάμας Σύνδεσης (h_plate) | C17: 200 | D17: mm | E17: Σχέδιο ΘΕΜ/6, Λεπτομέρεια | F17: ="Μήκος λάμας σύνδεσης = " & C17 & " mm (" & TEXT(C17/1000,"0.00") & " m)" -> Μήκος λάμας σύνδεσης = 200 mm (0.20 m)
A18: Κ.10γ | B18: Πάχος Λάμας Σύνδεσης (t_plate) | C18: 10 | D18: mm | E18: Σχέδιο ΘΕΜ/6, Λεπτομέρεια | F18: ="Πάχος λάμας σύνδεσης = " & C18 & " mm (" & TEXT(C18/1000,"0.000") & " m)" -> Πάχος λάμας σύνδεσης = 10 mm (0.010 m)
A19: Κ.10 | B19: ="Βάρος 1 Λάμας Σύνδεσης (" & C16 & "x" & C17 & "x" & C18 & " mm)" -> Βάρος 1 Λάμας Σύνδεσης (200x200x10 mm) | C19: =(C16/1000)*(C17/1000)*(C18/1000)*7850 -> 3.14 | D19: kg/τεμ | E19: ="Τύπος: (" & C16 & "/1000)×(" & C17 & "/1000)×(" & C18 & "/1000)×7850" -> Τύπος: (200/1000)×(200/1000)×(10/1000)×7850 | F19: ="=" & TEXT(C16/1000,"0.00") & "m × " & TEXT(C17/1000,"0.00") & "m × " & TEXT(C18/1000,"0.000") & "m × 7,850 kg/m³ = " & TEXT(C19,"0.000") & " kg/τεμ (Αλλάζοντας τα C16:C18 ενημερώνονται αυτόματα τίτλοι & σημειώσεις)" -> =0.20m × 0.20m × 0.010m × 7,850 kg/m³ = 3.140 kg/τεμ (Αλλάζοντας τα C16:C18 ενημερώνονται αυτόματα τίτλοι & σημειώσεις)
A20: Κ.11 | B20: Γωνιές Στήριξης Σχάρας L 70x70x6mm (2 τεμ. ανά πάσσαλο) | C20: 6.38 | D20: kg/m | E20: Σχέδιο ΘΕΜ/6 & Φύλλο 3 | F20: ="Γωνιές 70x70x6mm (" & TEXT(C20,"0.00") & " kg/m × 2 γωνιές καθ' ύψος εκσκαφής H_exc)" -> Γωνιές 70x70x6mm (6.38 kg/m × 2 γωνιές καθ' ύψος εκσκαφής H_exc)
A21: Κ.12 | B21: ="Διάμετρος Ράβδων Σχάρας Οριζόντιων & Κατακόρυφων (#Y" & C21 & "/" & C22 & ")" -> Διάμετρος Ράβδων Σχάρας Οριζόντιων & Κατακόρυφων (#Y8/150) | C21: 8 | D21: mm | E21: Σχέδιο ΘΕΜ/6, Λεπτομέρεια | F21: ="Αναγράφεται ρητά #Y" & C21 & "/" & C22 & " (αυστηρή τήρηση Y" & C21 & " βάσει κανόνα 2.3)" -> Αναγράφεται ρητά #Y8/150 (αυστηρή τήρηση Y8 βάσει κανόνα 2.3)
A22: Κ.13 | B22: ="Βήμα Ράβδων Σχάρας Οριζόντιων & Κατακόρυφων (#Y" & C21 & "/" & C22 & ")" -> Βήμα Ράβδων Σχάρας Οριζόντιων & Κατακόρυφων (#Y8/150) | C22: 150 | D22: mm | E22: Σχέδιο ΘΕΜ/6, Λεπτομέρεια | F22: ="Βήμα " & C22 & "mm × " & C22 & "mm (2 × " & TEXT(1000/C22,"0.00") & " m/m² = " & TEXT(C81,"0.000") & " kg/m²)" -> Βήμα 150mm × 150mm (2 × 6.67 m/m² = 5.261 kg/m²)
A23: Κ.14 | B23: Κατηγορία Σκυροδέματος Shotcrete & Πάκτωσης | C23: C30/37 | D23: - | E23: Κανόνας Εταιρείας | F23: ="[DEFAULT ΕΤΑΙΡΕΙΑΣ]: Δεν αναγράφεται στη μελέτη. Εφαρμόζεται by default " & C23 & " βάσει κανόνα εταιρείας." -> [DEFAULT ΕΤΑΙΡΕΙΑΣ]: Δεν αναγράφεται στη μελέτη. Εφαρμόζεται by default C30/37 βάσει κανόνα εταιρείας.
A24: Κ.15 | B24: ="Ονομαστικό Πάχος Shotcrete Μελέτης (" & (C24*100) & " cm)" -> Ονομαστικό Πάχος Shotcrete Μελέτης (15 cm) | C24: 0.15 | D24: m | E24: Σχέδιο ΘΕΜ/6, Λεπτομέρεια | F24: ="=" & (C24*1000) & " mm (" & (C24*100) & " cm) εκτοξευόμενο σκυρόδεμα (gunite)" -> =150 mm (15 cm) εκτοξευόμενο σκυρόδεμα (gunite)
A25: Κ.16 | B25: ="Πάγια Απώλεια / Αναπήδηση Shotcrete Εταιρείας (+" & (C25*100) & " cm)" -> Πάγια Απώλεια / Αναπήδηση Shotcrete Εταιρείας (+5 cm) | C25: 0.05 | D25: m | E25: Κανόνας Εταιρείας | F25: ="+" & (C25*100) & " cm πάγια προσαύξηση εταιρείας (+" & TEXT(C25/C24,"0.0%") & " επί του ονομαστικού πάχους)" -> +5 cm πάγια προσαύξηση εταιρείας (+33.3% επί του ονομαστικού πάχους)
A26: Κ.17 | B26: ="Διάμετρος Οπής Διάτρησης Αγκυρώσεων (Ø" & (C26*1000) & "mm)" -> Διάμετρος Οπής Διάτρησης Αγκυρώσεων (Ø120mm) | C26: 0.12 | D26: m | E26: Κανόνας Εταιρείας | F26: ="Ø" & (C26*1000) & " mm τυπική διάμετρος διάτρησης αγκυρίων" -> Ø120 mm τυπική διάμετρος διάτρησης αγκυρίων
A27: Κ.18 | B27: Συντελεστής Απώλειας Grout Αγκυρώσεων | C27: 1.2 | D27: - | E27: Κανόνας Εταιρείας | F27: ="+" & TEXT((C27-1),"0%") & " προσαύξηση όγκου τσιμεντενέματος (" & TEXT(C82,"0.000000") & " m³/m)" -> +20% προσαύξηση όγκου τσιμεντενέματος (0.013572 m³/m)
A28: Κ.19 | B28: Πρόσθετο Μήκος Τένοντα εκτός Μετώπου (για τάνυση/κεφαλή) | C28: 1 | D28: m | E28: Κανόνας Εταιρείας | F28: ="+" & TEXT(C28,"0.00") & " m έξω από το μέτωπο σε κάθε τένοντα" -> +1.00 m έξω από το μέτωπο σε κάθε τένοντα
A29: Κ.20 | B29: Τυπικό Βάρος Τένοντα Προέντασης 0.6'' (15.2mm) | C29: 1.1 | D29: kg/m | E29: Κανόνας Εταιρείας | F29: ="7-wire strand 0.6'' (1670/1860 MPa) = " & TEXT(C29,"0.00") & " kg/m" -> 7-wire strand 0.6'' (1670/1860 MPa) = 1.10 kg/m
A31: TYPE A | B31: ="ΚΟΥΤΙ ΣΤΟΙΧΕΙΩΝ ΜΕΛΕΤΗΣ TYPE A — ΤΟΙΧΟΣ ΑΝΤΙΣΤΗΡΙΞΗΣ Α (Εκσκαφή " & TEXT(C34,"0.00") & "m, " & C32 & "No Ζεύγη HEB 220, L_beam=" & TEXT(C36,"0.00") & "m, Εκσκαφή Νέφκας=" & TEXT(IF(ISBLANK(C37),C36,C37),"0.00") & "m, Πάκτωση " & TEXT(C35,"0.00") & "m)" -> ΚΟΥΤΙ ΣΤΟΙΧΕΙΩΝ ΜΕΛΕΤΗΣ TYPE A — ΤΟΙΧΟΣ ΑΝΤΙΣΤΗΡΙΞΗΣ Α (Εκσκαφή 17.00m, 27No Ζεύγη HEB 220, L_beam=19.00m, Εκσκαφή Νέφκας=19.00m, Πάκτωση 1.50m)
A32: A.in.1 | B32: Πλήθος Πασσάλων / Ζευγών HEB 220 (Type A) | C32: 27 | D32: No | E32: Σχέδιο ΘΕΜ/1 (Κάτοψη — Βέλη Αγκυρώσεων) | F32: ="=" & C32 & " πάσσαλοι / θέσεις αγκυρώσεων (22 στο Ανατολικό + 5 στο Νότιο τμήμα Τοίχου Α)" -> =27 πάσσαλοι / θέσεις αγκυρώσεων (22 στο Ανατολικό + 5 στο Νότιο τμήμα Τοίχου Α)
A33: A.in.2 | B33: ="Αναπτυγμένο Μήκος Μετώπου Type A (" & C32 & " × " & TEXT(C10,"0.00") & "m)" -> Αναπτυγμένο Μήκος Μετώπου Type A (27 × 1.50m) | C33: =C32*C10 -> 40.5 | D33: τρ.μ. | E33: Σχέδιο ΘΕΜ/1 (Intervals) | F33: ="=" & C32 & " πάσσαλοι × " & TEXT(C10,"0.00") & "m = " & TEXT(C33,"0.00") & " τρ.μ." -> =27 πάσσαλοι × 1.50m = 40.50 τρ.μ.
A34: A.in.3 | B34: Ελεύθερο Ύψος Εκσκαφής Type A (H_exc_A) | C34: 17 | D34: m | E34: Σχέδιο ΘΕΜ/6, Τομή Τοίχου Α | F34: ="Αναγραφόμενο ελεύθερο ύψος εκσκαφής " & (C34*1000) & " mm (" & TEXT(C34,"0.00") & " m)" -> Αναγραφόμενο ελεύθερο ύψος εκσκαφής 17000 mm (17.00 m)
A35: A.in.4 | B35: Ύψος Πάκτωσης Σκυροδέματος Νέφκας Type A (H_embed_A) | C35: 1.5 | D35: m | E35: Σχέδιο ΘΕΜ/6, Τομή Τοίχου Α | F35: ="Αναγραφόμενο ύψος πάκτωσης σκυροδέματος " & (C35*1000) & " mm (" & TEXT(C35,"0.00") & " m) στη βάση της νέφκας" -> Αναγραφόμενο ύψος πάκτωσης σκυροδέματος 1500 mm (1.50 m) στη βάση της νέφκας
A36: A.in.5 | B36: Συνολικό Μήκος Νέφκας Χάλυβα Μελέτης Type A (L_beam_A) | C36: 19 | D36: m | E36: Σχέδιο ΘΕΜ/6, Τομή Τοίχου Α | F36: ="Αναγραφόμενο συνολικό μήκος νέφκας " & (C36*1000) & " mm (" & TEXT(C36,"0.00") & " m) — ελεύθερο " & TEXT(C34,"0.00") & "m, υπόγειο " & TEXT(C36-C34,"0.00") & "m, πάκτωση μπετόν " & TEXT(C35,"0.00") & "m" -> Αναγραφόμενο συνολικό μήκος νέφκας 19000 mm (19.00 m) — ελεύθερο 17.00m, υπόγειο 2.00m, πάκτωση μπετόν 1.50m
A37: A.in.6 | B37: Ύψος Εκσκαφής / Διάτρησης Νέφκας βάσει WPL / Cut-Off Level (Type A) | D37: m | E37: =IF(ISBLANK(C37),"Δεν δόθηκε WPL / Cut-Off Level","Δόθηκε WPL / Cut-Off Level") -> Δεν δόθηκε WPL / Cut-Off Level | F37: =IF(ISBLANK(C37),"[!!! ΕΛΛΕΙΨΗ WPL / CUT-OFF LEVEL — ΚΟΚΚΙΝΟ ΚΕΛΙ !!!]: Δεν δόθηκε WPL / Cut-Off Level. Θεωρείται ότι το ύψος εκσκαφής νεφκών ισούται με το μήκος νέφκας (" & TEXT(C36,"0.00") & " m). Αν δοθεί WPL/Cut-Off Level, συμπληρώστε το εδώ!","[ΕΦΑΡΜΟΓΗ WPL / CUT-OFF LEVEL]: Το ύψος εκσκαφής/διάτρησης νεφκών ορίστηκε βάσει WPL σε " & TEXT(C37,"0.00") & " m (αντί " & TEXT(C36,"0.00") & " m της νέφκας).") -> [!!! ΕΛΛΕΙΨΗ WPL / CUT-OFF LEVEL — ΚΟΚΚΙΝΟ ΚΕΛΙ !!!]: Δεν δόθηκε WPL / Cut-Off Level. Θεωρείται ότι το ύψος εκσκαφής νεφκών ισούται με το μήκος νέφκας (19.00 m). Αν δοθεί WPL/Cut-Off Level, συμπληρώστε το εδώ!
A38: A.in.7 | B38: Αγκύρωση Σειρά 1 (στο -2.00m): Μήκος Διάτρησης L1 | C38: 20 | D38: m | E38: Σχέδιο ΘΕΜ/6, Τομή Τοίχου Α | F38: ="10.0m ελεύθερο + 10.0m πάκτωση grout = " & TEXT(C38,"0.00") & "m (30°, 144 kN)" -> 10.0m ελεύθερο + 10.0m πάκτωση grout = 20.00m (30°, 144 kN)
A39: A.in.8 | B39: Αγκύρωση Σειρά 1 (στο -2.00m): Καλώδια (Strands) | C39: 2 | D39: καλώδια | E39: Σχέδιο ΘΕΜ/6, Τομή Τοίχου Α | F39: ="Αναγράφεται: " & C39 & " ΚΑΛΩΔΙΑ 15.2mm (Type 1670/1860)" -> Αναγράφεται: 2 ΚΑΛΩΔΙΑ 15.2mm (Type 1670/1860)
A40: A.in.9 | B40: Αγκύρωση Σειρά 2 (στο -6.00m): Μήκος Διάτρησης L2 | C40: 19.5 | D40: m | E40: Σχέδιο ΘΕΜ/6, Τομή Τοίχου Α | F40: ="8.5m ελεύθερο + 11.0m πάκτωση grout = " & TEXT(C40,"0.00") & "m (30°, 338 kN)" -> 8.5m ελεύθερο + 11.0m πάκτωση grout = 19.50m (30°, 338 kN)
A41: A.in.10 | B41: Αγκύρωση Σειρά 2 (στο -6.00m): Καλώδια (Strands) | C41: 2 | D41: καλώδια | E41: Σχέδιο ΘΕΜ/6, Τομή Τοίχου Α | F41: ="Αναγράφεται: " & C41 & " ΚΑΛΩΔΙΑ 15.2mm (Type 1670/1860)" -> Αναγράφεται: 2 ΚΑΛΩΔΙΑ 15.2mm (Type 1670/1860)
A42: A.in.11 | B42: Αγκύρωση Σειρά 3 (στο -9.50m): Μήκος Διάτρησης L3 | C42: 20 | D42: m | E42: Σχέδιο ΘΕΜ/6, Τομή Τοίχου Α | F42: ="8.0m ελεύθερο + 12.0m πάκτωση grout = " & TEXT(C42,"0.00") & "m (30°, 439 kN)" -> 8.0m ελεύθερο + 12.0m πάκτωση grout = 20.00m (30°, 439 kN)
...

Sheet 2_Υπολογισμοί_&_Κοστολόγηση
A1: ΕΡΓΟ: BOLTON TOWER (BERLIN WALL & ΑΓΚΥΡΩΣΕΙΣ) — ΟΙΚΟΝΟΜΙΚΗ ΠΡΟΣΦΟΡΑ ΑΝΑ ΤΥΠΟ ΤΟΙΧΟΥ (TYPE A, TYPE B, TYPE C)
A2: ΕΚΔΟΣΗ ΚΑΝΟΝΩΝ v8 (BOX LAYOUT) | [ΚΙΤΡΙΝΟ #FFF2CC] = Τιμές Μονάδας Εταιρείας | [ΠΟΡΤΟΚΑΛΙ #FFE699] = Κουγκρί Πάκτωσης 120€ | Χωρίς Φ.Π.Α.
A4: α/α | B4: ΠΕΡΙΓΡΑΦΗ ΕΡΓΑΣΙΩΝ | C4: ΠΟΣΟΤΗΤΑ | D4: ΜΟΝ. | E4: ΤΙΜΗ (€) | F4: ΣΥΝΟΛΟ (€) | G4: ΤΕΛΙΚΟ ΠΟΣΟ (€) | H4: ΠΗΓΗ ΠΟΣΟΤΗΤΑΣ / ΤΕΧΝΙΚΟΣ ΚΑΝΟΝΑΣ & ΣΗΜΕΙΩΣΕΙΣ
A5: TYPE A | B5: ="BERLIN WALL TYPE A: " & '1_Στοιχεία_Μελέτης_&_Ποσότητες'!C32 & "No Ζεύγη HEB220, L=" & TEXT('1_Στοιχεία_Μελέτης_&_Ποσότητες'!C36,"0.00") & "m (Διάτρηση=" & TEXT(IF(ISBLANK('1_Στοιχεία_Μελέτης_&_Ποσότητες'!C37),'1_Στοιχεία_Μελέτης_&_Ποσότητες'!C36,'1_Στοιχεία_Μελέτης_&_Ποσότητες'!C37),"0.00") & "m), Εκσκαφή " & TEXT('1_Στοιχεία_Μελέτης_&_Ποσότητες'!C34,"0.00") & "m, " & TEXT('1_Στοιχεία_Μελέτης_&_Ποσότητες'!C33,"0.00") & " τρ.μ." -> BERLIN WALL TYPE A: 27No Ζεύγη HEB220, L=19.00m (Διάτρηση=19.00m), Εκσκαφή 17.00m, 40.50 τρ.μ. | C5: ='1_Στοιχεία_Μελέτης_&_Ποσότητες'!C33 -> 40.5 | D5: τρ.μ. | E5: =ROUND(F5/C5, 2) -> 7418.19 | F5: =SUM(F6:F20) -> 300436.75 | G5: ΤΕΛ. ΣΥΝΟΛΑ | H5: ="Σύνολο Τοίχου Α (Πυλώνες 2, 3 & 4 — HEB 220, " & '1_Στοιχεία_Μελέτης_&_Ποσότητες'!C32 & " πάσσαλοι, " & '1_Στοιχεία_Μελέτης_&_Ποσότητες'!C99 & " αγκυρώσεις)" -> Σύνολο Τοίχου Α (Πυλώνες 2, 3 & 4 — HEB 220, 27 πάσσαλοι, 108 αγκυρώσεις)
A6: A.1 | B6: ='1_Στοιχεία_Μελέτης_&_Ποσότητες'!B86 -> ΤΡΥΠΗΜΑ / ΕΚΣΚΑΦΗ ΝΕΦΚΩΝ Ø800mm = 27No X 19.00m (Όγκος: 257.86 m³) | C6: ='1_Στοιχεία_Μελέτης_&_Ποσότητες'!C86 -> 513 | D6: ='1_Στοιχεία_Μελέτης_&_Ποσότητες'!D86 -> m | E6: 75 | F6: =ROUND(C6*E6, 2) -> 38475 | G6: =F5 -> 300436.75 | H6: =IF(ISBLANK('1_Στοιχεία_Μελέτης_&_Ποσότητες'!C37),"Φύλλο 1 (A.1): " & '1_Στοιχεία_Μελέτης_&_Ποσότητες'!C32 & " πάσσαλοι × " & TEXT('1_Στοιχεία_Μελέτης_&_Ποσότητες'!C36,"0.00") & "m (χωρίς WPL, Όγκος " & TEXT(ROUND('1_Στοιχεία_Μελέτης_&_Ποσότητες'!C86*'1_Στοιχεία_Μελέτης_&_Ποσότητες'!C80,2),"#,##0.00") & " m³) @ 75.00 €/m","Φύλλο 1 (A.1 — ΜΕ WPL): " & '1_Στοιχεία_Μελέτης_&_Ποσότητες'!C32 & " πάσσαλοι × " & TEXT('1_Στοιχεία_Μελέτης_&_Ποσότητες'!C37,"0.00") & "m (Όγκος " & TEXT(ROUND('1_Στοιχεία_Μελέτης_&_Ποσότητες'!C86*'1_Στοιχεία_Μελέτης_&_Ποσότητες'!C80,2),"#,##0.00") & " m³) @ 75.00 €/m") -> Φύλλο 1 (A.1): 27 πάσσαλοι × 19.00m (χωρίς WPL, Όγκος 257.86 m³) @ 75.00 €/m
A7: A.2 | B7: ='1_Στοιχεία_Μελέτης_&_Ποσότητες'!B87 -> ΜΠΕΤΟΝ ΠΑΚΤΩΣΗΣ C30/37 = 27No X 1.50m X 0.503m³/m | C7: ='1_Στοιχεία_Μελέτης_&_Ποσότητες'!C87 -> 20.36 | D7: ='1_Στοιχεία_Μελέτης_&_Ποσότητες'!D87 -> m³ | E7: 120 | F7: =ROUND(C7*E7, 2) -> 2443.2 | H7: ="Φύλλο 1 (A.2): Πάκτωση H=" & TEXT('1_Στοιχεία_Μελέτης_&_Ποσότητες'!C35,"0.00") & "m σε Ø" & ('1_Στοιχεία_Μελέτης_&_Ποσότητες'!C11*1000) & "mm @ 120.00 €/m³ [Πορτοκαλί #FFE699]" -> Φύλλο 1 (A.2): Πάκτωση H=1.50m σε Ø800mm @ 120.00 €/m³ [Πορτοκαλί #FFE699]
A8: A.3 | B8: ='1_Στοιχεία_Μελέτης_&_Ποσότητες'!B88 -> HEB220 - ΠΡΟΜΗΘΕΙΑ, ΕΠΕΞΕΡΓΑΣΙΑ & ΤΟΠΟΘΕΤΗΣΗ (27No x 2No x 19.00m x 71.5kg/m) | C8: ='1_Στοιχεία_Μελέτης_&_Ποσότητες'!C88 -> 73359 | D8: ='1_Στοιχεία_Μελέτης_&_Ποσότητες'!D88 -> kg | E8: 1.4 | F8: =ROUND(C8*E8, 2) -> 102702.6 | H8: ="Φύλλο 1 (A.3): " & '1_Στοιχεία_Μελέτης_&_Ποσότητες'!C12 & " No. HEB 220 (" & TEXT('1_Στοιχεία_Μελέτης_&_Ποσότητες'!C13*'1_Στοιχεία_Μελέτης_&_Ποσότητες'!C12,"0.0") & " kg/m, L=" & TEXT('1_Στοιχεία_Μελέτης_&_Ποσότητες'!C36,"0.0") & "m) @ 1.40 €/kg" -> Φύλλο 1 (A.3): 2 No. HEB 220 (143.0 kg/m, L=19.0m) @ 1.40 €/kg
A9: A.4 | B9: ='1_Στοιχεία_Μελέτης_&_Ποσότητες'!B89 -> ΛΑΜΕΣ ΣΥΝΔΕΣΗΣ 200x200x10mm = 27No x (19No x 3.140kg) | C9: ='1_Στοιχεία_Μελέτης_&_Ποσότητες'!C89 -> 1610.82 | D9: ='1_Στοιχεία_Μελέτης_&_Ποσότητες'!D89 -> kg | E9: 1.6 | F9: =ROUND(C9*E9, 2) -> 2577.31 | H9: ="Φύλλο 1 (A.4): Λάμες " & '1_Στοιχεία_Μελέτης_&_Ποσότητες'!C16 & "x" & '1_Στοιχεία_Μελέτης_&_Ποσότητες'!C17 & "x" & '1_Στοιχεία_Μελέτης_&_Ποσότητες'!C18 & "mm (" & ('1_Στοιχεία_Μελέτης_&_Ποσότητες'!C36/'1_Στοιχεία_Μελέτης_&_Ποσότητες'!C15) & " λάμες/οπή = " & ('1_Στοιχεία_Μελέτης_&_Ποσότητες'!C32*('1_Στοιχεία_Μελέτης_&_Ποσότητες'!C36/'1_Στοιχεία_Μελέτης_&_Ποσότητες'!C15)) & " τεμ.) @ 1.60 €/kg" -> Φύλλο 1 (A.4): Λάμες 200x200x10mm (19 λάμες/οπή = 513 τεμ.) @ 1.60 €/kg
A10: A.5 | B10: ='1_Στοιχεία_Μελέτης_&_Ποσότητες'!B90 -> ΓΩΝΙΕΣ ΣΤΗΡΙΞΗΣ L70x70x6mm = 27No x 17.00m x 6.38kg/m x 2No | C10: ='1_Στοιχεία_Μελέτης_&_Ποσότητες'!C90 -> 5856.84 | D10: ='1_Στοιχεία_Μελέτης_&_Ποσότητες'!D90 -> kg | E10: 1.6 | F10: =ROUND(C10*E10, 2) -> 9370.94 | H10: ="Φύλλο 1 (A.5): 2 γωνιές L70x70x6 × " & TEXT('1_Στοιχεία_Μελέτης_&_Ποσότητες'!C34,"0.00") & "m (" & TEXT('1_Στοιχεία_Μελέτης_&_Ποσότητες'!C32*2*'1_Στοιχεία_Μελέτης_&_Ποσότητες'!C34,"0.0") & "m) @ 1.60 €/kg" -> Φύλλο 1 (A.5): 2 γωνιές L70x70x6 × 17.00m (918.0m) @ 1.60 €/kg
A11: A.6 | B11: ='1_Στοιχεία_Μελέτης_&_Ποσότητες'!B91 -> ΑΓΟΡΑ ΧΑΛΥΒΑ ΣΧΑΡΑΣ #Y8/150 = 688.50m² x 5.261kg/m² | C11: ='1_Στοιχεία_Μελέτης_&_Ποσότητες'!C91 -> 3622.2 | D11: ='1_Στοιχεία_Μελέτης_&_Ποσότητες'!D91 -> kg | E11: 2.5 | F11: =ROUND(C11*E11, 2) -> 9055.5 | H11: ="Φύλλο 1 (A.6): Σχάρα #Y" & '1_Στοιχεία_Μελέτης_&_Ποσότητες'!C21 & "/" & '1_Στοιχεία_Μελέτης_&_Ποσότητες'!C22 & " (" & TEXT('1_Στοιχεία_Μελέτης_&_Ποσότητες'!C81,"0.000") & " kg/m²) @ 2.50 €/kg αγορά" -> Φύλλο 1 (A.6): Σχάρα #Y8/150 (5.261 kg/m²) @ 2.50 €/kg αγορά
A12: A.7 | B12: ='1_Στοιχεία_Μελέτης_&_Ποσότητες'!B92 -> ΤΟΠΟΘΕΤΗΣΗ ΣΧΑΡΑΣ ΜΕΤΩΠΟΥ = 40.50m X 17.00m | C12: ='1_Στοιχεία_Μελέτης_&_Ποσότητες'!C92 -> 688.5 | D12: ='1_Στοιχεία_Μελέτης_&_Ποσότητες'!D92 -> m² | E12: 15 | F12: =ROUND(C12*E12, 2) -> 10327.5 | H12: ="Φύλλο 1 (A.7): Εργατικά τοποθέτησης σχάρας μετώπου (" & TEXT('1_Στοιχεία_Μελέτης_&_Ποσότητες'!C33,"0.0") & "m × " & TEXT('1_Στοιχεία_Μελέτης_&_Ποσότητες'!C34,"0.0") & "m) @ 15.00 €/m²" -> Φύλλο 1 (A.7): Εργατικά τοποθέτησης σχάρας μετώπου (40.5m × 17.0m) @ 15.00 €/m²
A13: A.8 | B13: ='1_Στοιχεία_Μελέτης_&_Ποσότητες'!B93 -> ΑΓΟΡΑ ΣΚΥΡΟΔΕΜΑΤΟΣ SHOTCRETE C30/37 = 688.50m² x 0.15m | C13: ='1_Στοιχεία_Μελέτης_&_Ποσότητες'!C93 -> 103.28 | D13: ='1_Στοιχεία_Μελέτης_&_Ποσότητες'!D93 -> m³ | E13: 90 | F13: =ROUND(C13*E13, 2) -> 9295.2 | H13: ="Φύλλο 1 (A.8): Αγορά " & '1_Στοιχεία_Μελέτης_&_Ποσότητες'!C23 & " ονομαστικού πάχους " & ('1_Στοιχεία_Μελέτης_&_Ποσότητες'!C24*100) & "cm @ 90.00 €/m³" -> Φύλλο 1 (A.8): Αγορά C30/37 ονομαστικού πάχους 15cm @ 90.00 €/m³
A14: A.9 | B14: ='1_Στοιχεία_Μελέτης_&_Ποσότητες'!B94 -> ΤΟΠΟΘΕΤΗΣΗ / ΕΚΤΟΞΕΥΣΗ SHOTCRETE = 688.50m² x 0.15m (με απώλεια +33.3%) | C14: ='1_Στοιχεία_Μελέτης_&_Ποσότητες'!C94 -> 103.28 | D14: ='1_Στοιχεία_Μελέτης_&_Ποσότητες'!D94 -> m³ | E14: =ROUND((200*(1+'1_Στοιχεία_Μελέτης_&_Ποσότητες'!C83))-90, 2) -> 176.67 | F14: =ROUND(C14*E14, 2) -> 18246.48 | H14: ="Φύλλο 1 (A.9): Εκτόξευση/Αντλία = Βάση 200€ × (1+" & TEXT('1_Στοιχεία_Μελέτης_&_Ποσότητες'!C83,"0.0%") & " απώλεια) - 90€" -> Φύλλο 1 (A.9): Εκτόξευση/Αντλία = Βάση 200€ × (1+33.3% απώλεια) - 90€
A15: A.10 | B15: ='1_Στοιχεία_Μελέτης_&_Ποσότητες'!B95 -> ΔΙΑΤΡΗΣΗ ΑΓΚΥΡΩΣΕΩΝ Ø120mm (4 Σειρές: L1=20m, L2=19.5m, L3=20m, L4=18.5m) | C15: ='1_Στοιχεία_Μελέτης_&_Ποσότητες'!C95 -> 2106 | D15: ='1_Στοιχεία_Μελέτης_&_Ποσότητες'!D95 -> m | E15: 30 | F15: =ROUND(C15*E15, 2) -> 63180 | H15: ="Φύλλο 1 (A.10): Διάτρηση " & '1_Στοιχεία_Μελέτης_&_Ποσότητες'!C99 & " αγκυρώσεων Ø" & ('1_Στοιχεία_Μελέτης_&_Ποσότητες'!C26*1000) & "mm (Σειρές 1-4: " & '1_Στοιχεία_Μελέτης_&_Ποσότητες'!C38 & "m, " & '1_Στοιχεία_Μελέτης_&_Ποσότητες'!C40 & "m, " & '1_Στοιχεία_Μελέτης_&_Ποσότητες'!C42 & "m, " & '1_Στοιχεία_Μελέτης_&_Ποσότητες'!C44 & "m) @ 30.00 €/m" -> Φύλλο 1 (A.10): Διάτρηση 108 αγκυρώσεων Ø120mm (Σειρές 1-4: 20m, 19.5m, 20m, 18.5m) @ 30.00 €/m
A16: A.11 | B16: ='1_Στοιχεία_Μελέτης_&_Ποσότητες'!B96 -> GROUT ΤΣΙΜΕΝΤΕΝΕΜΑ ΑΓΚΥΡΩΣΕΩΝ (με απώλεια 1.20) = 2,106.00m x 0.0136m³/m | C16: ='1_Στοιχεία_Μελέτης_&_Ποσότητες'!C96 -> 28.58 | D16: ='1_Στοιχεία_Μελέτης_&_Ποσότητες'!D96 -> m³ | E16: 500 | F16: =ROUND(C16*E16, 2) -> 14290 | H16: ="Φύλλο 1 (A.11): Grout Ø" & ('1_Στοιχεία_Μελέτης_&_Ποσότητες'!C26*1000) & "mm με απώλεια " & TEXT('1_Στοιχεία_Μελέτης_&_Ποσότητες'!C27,"0.00") & " (" & TEXT('1_Στοιχεία_Μελέτης_&_Ποσότητες'!C82,"0.000000") & " m³/m) @ 500.00 €/m³" -> Φύλλο 1 (A.11): Grout Ø120mm με απώλεια 1.20 (0.013572 m³/m) @ 500.00 €/m³
A17: A.12 | B17: ='1_Στοιχεία_Μελέτης_&_Ποσότητες'!B97 -> ΤΕΝΟΝΤΕΣ 0.6'' (2 ΚΑΛΩΔΙΑ) — Σειρά 1 (L=20m) & Σειρά 2 (L=19.5m) (+1.0m) | C17: ='1_Στοιχεία_Μελέτης_&_Ποσότητες'!C97 -> 2241 | D17: ='1_Στοιχεία_Μελέτης_&_Ποσότητες'!D97 -> m | E17: 2.28 | F17: =ROUND(C17*E17, 2) -> 5109.48 | H17: ="Φύλλο 1 (A.12): " & ('1_Στοιχεία_Μελέτης_&_Ποσότητες'!C32*2) & " αγκυρώσεις " & '1_Στοιχεία_Μελέτης_&_Ποσότητες'!C39 & "-strands (Σειρά 1 L=" & '1_Στοιχεία_Μελέτης_&_Ποσότητες'!C38 & "m & Σειρά 2 L=" & '1_Στοιχεία_Μελέτης_&_Ποσότητες'!C40 & "m, +" & TEXT('1_Στοιχεία_Μελέτης_&_Ποσότητες'!C28,"0.0") & "m) @ 2.28 €/m" -> Φύλλο 1 (A.12): 54 αγκυρώσεις 2-strands (Σειρά 1 L=20m & Σειρά 2 L=19.5m, +1.0m) @ 2.28 €/m
A18: A.13 | B18: ='1_Στοιχεία_Μελέτης_&_Ποσότητες'!B98 -> ΤΕΝΟΝΤΕΣ 0.6'' (3 ΚΑΛΩΔΙΑ) — Σειρά 3 (L=20m) & Σειρά 4 (L=18.5m) (+1.0m) | C18: ='1_Στοιχεία_Μελέτης_&_Ποσότητες'!C98 -> 3280.5 | D18: ='1_Στοιχεία_Μελέτης_&_Ποσότητες'!D98 -> m | E18: 2.28 | F18: =ROUND(C18*E18, 2) -> 7479.54 | H18: ="Φύλλο 1 (A.13): " & ('1_Στοιχεία_Μελέτης_&_Ποσότητες'!C32*2) & " αγκυρώσεις " & '1_Στοιχεία_Μελέτης_&_Ποσότητες'!C43 & "-strands (Σειρά 3 L=" & '1_Στοιχεία_Μελέτης_&_Ποσότητες'!C42 & "m & Σειρά 4 L=" & '1_Στοιχεία_Μελέτης_&_Ποσότητες'!C44 & "m, +" & TEXT('1_Στοιχεία_Μελέτης_&_Ποσότητες'!C28,"0.0") & "m) @ 2.28 €/m" -> Φύλλο 1 (A.13): 54 αγκυρώσεις 3-strands (Σειρά 3 L=20m & Σειρά 4 L=18.5m, +1.0m) @ 2.28 €/m
A19: A.14 | B19: ='1_Στοιχεία_Μελέτης_&_Ποσότητες'!B99 -> ΠΡΟΕΝΤΑΣΗ ΑΓΚΥΡΩΣΕΩΝ (STRESSING & LOCK-OFF) = 4 Σειρές X 27No | C19: ='1_Στοιχεία_Μελέτης_&_Ποσότητες'!C99 -> 108 | D19: ='1_Στοιχεία_Μελέτης_&_Ποσότητες'!D99 -> No | E19: 18 | F19: =ROUND(C19*E19, 2) -> 1944 | H19: ="Φύλλο 1 (A.14): Προένταση (Stressing & Lock-off) " & '1_Στοιχεία_Μελέτης_&_Ποσότητες'!C99 & " αγκυρώσεων Type A @ 18.00 €/No" -> Φύλλο 1 (A.14): Προένταση (Stressing & Lock-off) 108 αγκυρώσεων Type A @ 18.00 €/No
A20: A.15 | B20: ='1_Στοιχεία_Μελέτης_&_Ποσότητες'!B100 -> ΚΕΦΑΛΕΣ ΑΓΚΥΡΩΣΗΣ (ANCHOR HEAD, WEDGES, PLATE) = 4 Σειρές X 27No | C20: ='1_Στοιχεία_Μελέτης_&_Ποσότητες'!C100 -> 108 | D20: ='1_Στοιχεία_Μελέτης_&_Ποσότητες'!D100 -> No | E20: 55 | F20: =ROUND(C20*E20, 2) -> 5940 | H20: ="Φύλλο 1 (A.15): Πλήρες σετ κεφαλής (Head, Wedges, Plate) " & '1_Στοιχεία_Μελέτης_&_Ποσότητες'!C100 & " αγκυρώσεων Type A @ 55.00 €/No" -> Φύλλο 1 (A.15): Πλήρες σετ κεφαλής (Head, Wedges, Plate) 108 αγκυρώσεων Type A @ 55.00 €/No
A22: TYPE B | B22: ="BERLIN WALL TYPE B: " & '1_Στοιχεία_Μελέτης_&_Ποσότητες'!C48 & "No Ζεύγη HEB200, L=" & TEXT('1_Στοιχεία_Μελέτης_&_Ποσότητες'!C52,"0.00") & "m (Διάτρηση=" & TEXT(IF(ISBLANK('1_Στοιχεία_Μελέτης_&_Ποσότητες'!C53),'1_Στοιχεία_Μελέτης_&_Ποσότητες'!C52,'1_Στοιχεία_Μελέτης_&_Ποσότητες'!C53),"0.00") & "m), Εκσκαφή " & TEXT('1_Στοιχεία_Μελέτης_&_Ποσότητες'!C50,"0.00") & "m, " & TEXT('1_Στοιχεία_Μελέτης_&_Ποσότητες'!C49,"0.00") & " τρ.μ." -> BERLIN WALL TYPE B: 74No Ζεύγη HEB200, L=17.00m (Διάτρηση=17.00m), Εκσκαφή 15.60m, 111.00 τρ.μ. | C22: ='1_Στοιχεία_Μελέτης_&_Ποσότητες'!C49 -> 111 | D22: τρ.μ. | E22: =ROUND(F22/C22, 2) -> 6519.12 | F22: =SUM(F23:F37) -> 723622.84 | G22: ΤΕΛ. ΣΥΝΟΛΑ | H22: ="Σύνολο Τοίχου Β (Πυλώνες 2, 3 & 4 — HEB 200, " & '1_Στοιχεία_Μελέτης_&_Ποσότητες'!C48 & " πάσσαλοι, " & '1_Στοιχεία_Μελέτης_&_Ποσότητες'!C116 & " αγκυρώσεις)" -> Σύνολο Τοίχου Β (Πυλώνες 2, 3 & 4 — HEB 200, 74 πάσσαλοι, 296 αγκυρώσεις)
A23: B.1 | B23: ='1_Στοιχεία_Μελέτης_&_Ποσότητες'!B103 -> ΤΡΥΠΗΜΑ / ΕΚΣΚΑΦΗ ΝΕΦΚΩΝ Ø800mm = 74No X 17.00m (Όγκος: 632.34 m³) | C23: ='1_Στοιχεία_Μελέτης_&_Ποσότητες'!C103 -> 1258 | D23: ='1_Στοιχεία_Μελέτης_&_Ποσότητες'!D103 -> m | E23: 75 | F23: =ROUND(C23*E23, 2) -> 94350 | G23: =F22 -> 723622.84 | H23: =IF(ISBLANK('1_Στοιχεία_Μελέτης_&_Ποσότητες'!C53),"Φύλλο 1 (B.1): " & '1_Στοιχεία_Μελέτης_&_Ποσότητες'!C48 & " πάσσαλοι × " & TEXT('1_Στοιχεία_Μελέτης_&_Ποσότητες'!C52,"0.00") & "m (χωρίς WPL, Όγκος " & TEXT(ROUND('1_Στοιχεία_Μελέτης_&_Ποσότητες'!C103*'1_Στοιχεία_Μελέτης_&_Ποσότητες'!C80,2),"#,##0.00") & " m³) @ 75.00 €/m","Φύλλο 1 (B.1 — ΜΕ WPL): " & '1_Στοιχεία_Μελέτης_&_Ποσότητες'!C48 & " πάσσαλοι × " & TEXT('1_Στοιχεία_Μελέτης_&_Ποσότητες'!C53,"0.00") & "m (Όγκος " & TEXT(ROUND('1_Στοιχεία_Μελέτης_&_Ποσότητες'!C103*'1_Στοιχεία_Μελέτης_&_Ποσότητες'!C80,2),"#,##0.00") & " m³) @ 75.00 €/m") -> Φύλλο 1 (B.1): 74 πάσσαλοι × 17.00m (χωρίς WPL, Όγκος 632.34 m³) @ 75.00 €/m
A24: B.2 | B24: ='1_Στοιχεία_Μελέτης_&_Ποσότητες'!B104 -> ΜΠΕΤΟΝ ΠΑΚΤΩΣΗΣ C30/37 = 74No X 1.50m X 0.503m³/m | C24: ='1_Στοιχεία_Μελέτης_&_Ποσότητες'!C104 -> 55.79 | D24: ='1_Στοιχεία_Μελέτης_&_Ποσότητες'!D104 -> m³ | E24: 120 | F24: =ROUND(C24*E24, 2) -> 6694.8 | H24: ="Φύλλο 1 (B.2): Πάκτωση H=" & TEXT('1_Στοιχεία_Μελέτης_&_Ποσότητες'!C51,"0.00") & "m σε Ø" & ('1_Στοιχεία_Μελέτης_&_Ποσότητες'!C11*1000) & "mm @ 120.00 €/m³ [Πορτοκαλί #FFE699]" -> Φύλλο 1 (B.2): Πάκτωση H=1.50m σε Ø800mm @ 120.00 €/m³ [Πορτοκαλί #FFE699]
A25: B.3 | B25: ='1_Στοιχεία_Μελέτης_&_Ποσότητες'!B105 -> HEB200 - ΠΡΟΜΗΘΕΙΑ, ΕΠΕΞΕΡΓΑΣΙΑ & ΤΟΠΟΘΕΤΗΣΗ (74No x 2No x 17.00m x 61.3kg/m) | C25: ='1_Στοιχεία_Μελέτης_&_Ποσότητες'!C105 -> 154230.8 | D25: ='1_Στοιχεία_Μελέτης_&_Ποσότητες'!D105 -> kg | E25: 1.4 | F25: =ROUND(C25*E25, 2) -> 215923.12 | H25: ="Φύλλο 1 (B.3): " & '1_Στοιχεία_Μελέτης_&_Ποσότητες'!C12 & " No. HEB 200 (" & TEXT('1_Στοιχεία_Μελέτης_&_Ποσότητες'!C14*'1_Στοιχεία_Μελέτης_&_Ποσότητες'!C12,"0.0") & " kg/m, L=" & TEXT('1_Στοιχεία_Μελέτης_&_Ποσότητες'!C52,"0.0") & "m) @ 1.40 €/kg" -> Φύλλο 1 (B.3): 2 No. HEB 200 (122.6 kg/m, L=17.0m) @ 1.40 €/kg
A26: B.4 | B26: ='1_Στοιχεία_Μελέτης_&_Ποσότητες'!B106 -> ΛΑΜΕΣ ΣΥΝΔΕΣΗΣ 200x200x10mm = 74No x (17No x 3.140kg) | C26: ='1_Στοιχεία_Μελέτης_&_Ποσότητες'!C106 -> 3950.12 | D26: ='1_Στοιχεία_Μελέτης_&_Ποσότητες'!D106 -> kg | E26: 1.6 | F26: =ROUND(C26*E26, 2) -> 6320.19 | H26: ="Φύλλο 1 (B.4): Λάμες " & '1_Στοιχεία_Μελέτης_&_Ποσότητες'!C16 & "x" & '1_Στοιχεία_Μελέτης_&_Ποσότητες'!C17 & "x" & '1_Στοιχεία_Μελέτης_&_Ποσότητες'!C18 & "mm (" & ('1_Στοιχεία_Μελέτης_&_Ποσότητες'!C52/'1_Στοιχεία_Μελέτης_&_Ποσότητες'!C15) & " λάμες/οπή = " & ('1_Στοιχεία_Μελέτης_&_Ποσότητες'!C48*('1_Στοιχεία_Μελέτης_&_Ποσότητες'!C52/'1_Στοιχεία_Μελέτης_&_Ποσότητες'!C15)) & " τεμ.) @ 1.60 €/kg" -> Φύλλο 1 (B.4): Λάμες 200x200x10mm (17 λάμες/οπή = 1258 τεμ.) @ 1.60 €/kg
A27: B.5 | B27: ='1_Στοιχεία_Μελέτης_&_Ποσότητες'!B107 -> ΓΩΝΙΕΣ ΣΤΗΡΙΞΗΣ L70x70x6mm = 74No x 15.60m x 6.38kg/m x 2No | C27: ='1_Στοιχεία_Μελέτης_&_Ποσότητες'!C107 -> 14730.14 | D27: ='1_Στοιχεία_Μελέτης_&_Ποσότητες'!D107 -> kg | E27: 1.6 | F27: =ROUND(C27*E27, 2) -> 23568.22 | H27: ="Φύλλο 1 (B.5): 2 γωνιές L70x70x6 × " & TEXT('1_Στοιχεία_Μελέτης_&_Ποσότητες'!C50,"0.00") & "m (" & TEXT('1_Στοιχεία_Μελέτης_&_Ποσότητες'!C48*2*'1_Στοιχεία_Μελέτης_&_Ποσότητες'!C50,"0.0") & "m) @ 1.60 €/kg" -> Φύλλο 1 (B.5): 2 γωνιές L70x70x6 × 15.60m (2308.8m) @ 1.60 €/kg
A28: B.6 | B28: ='1_Στοιχεία_Μελέτης_&_Ποσότητες'!B108 -> ΑΓΟΡΑ ΧΑΛΥΒΑ ΣΧΑΡΑΣ #Y8/150 = 1,731.60m² x 5.261kg/m² | C28: ='1_Στοιχεία_Μελέτης_&_Ποσότητες'!C108 -> 9109.95 | D28: ='1_Στοιχεία_Μελέτης_&_Ποσότητες'!D108 -> kg | E28: 2.5 | F28: =ROUND(C28*E28, 2) -> 22774.88 | H28: ="Φύλλο 1 (B.6): Σχάρα #Y" & '1_Στοιχεία_Μελέτης_&_Ποσότητες'!C21 & "/" & '1_Στοιχεία_Μελέτης_&_Ποσότητες'!C22 & " (" & TEXT('1_Στοιχεία_Μελέτης_&_Ποσότητες'!C81,"0.000") & " kg/m²) @ 2.50 €/kg αγορά" -> Φύλλο 1 (B.6): Σχάρα #Y8/150 (5.261 kg/m²) @ 2.50 €/kg αγορά
A29: B.7 | B29: ='1_Στοιχεία_Μελέτης_&_Ποσότητες'!B109 -> ΤΟΠΟΘΕΤΗΣΗ ΣΧΑΡΑΣ ΜΕΤΩΠΟΥ = 111.00m X 15.60m | C29: ='1_Στοιχεία_Μελέτης_&_Ποσότητες'!C109 -> 1731.6 | D29: ='1_Στοιχεία_Μελέτης_&_Ποσότητες'!D109 -> m² | E29: 15 | F29: =ROUND(C29*E29, 2) -> 25974 | H29: ="Φύλλο 1 (B.7): Εργατικά τοποθέτησης σχάρας μετώπου (" & TEXT('1_Στοιχεία_Μελέτης_&_Ποσότητες'!C49,"0.0") & "m × " & TEXT('1_Στοιχεία_Μελέτης_&_Ποσότητες'!C50,"0.0") & "m) @ 15.00 €/m²" -> Φύλλο 1 (B.7): Εργατικά τοποθέτησης σχάρας μετώπου (111.0m × 15.6m) @ 15.00 €/m²
A30: B.8 | B30: ='1_Στοιχεία_Μελέτης_&_Ποσότητες'!B110 -> ΑΓΟΡΑ ΣΚΥΡΟΔΕΜΑΤΟΣ SHOTCRETE C30/37 = 1,731.60m² x 0.15m | C30: ='1_Στοιχεία_Μελέτης_&_Ποσότητες'!C110 -> 259.74 | D30: ='1_Στοιχεία_Μελέτης_&_Ποσότητες'!D110 -> m³ | E30: 90 | F30: =ROUND(C30*E30, 2) -> 23376.6 | H30: ="Φύλλο 1 (B.8): Αγορά " & '1_Στοιχεία_Μελέτης_&_Ποσότητες'!C23 & " ονομαστικού πάχους " & ('1_Στοιχεία_Μελέτης_&_Ποσότητες'!C24*100) & "cm @ 90.00 €/m³" -> Φύλλο 1 (B.8): Αγορά C30/37 ονομαστικού πάχους 15cm @ 90.00 €/m³
A31: B.9 | B31: ='1_Στοιχεία_Μελέτης_&_Ποσότητες'!B111 -> ΤΟΠΟΘΕΤΗΣΗ / ΕΚΤΟΞΕΥΣΗ SHOTCRETE = 1,731.60m² x 0.15m (με απώλεια +33.3%) | C31: ='1_Στοιχεία_Μελέτης_&_Ποσότητες'!C111 -> 259.74 | D31: ='1_Στοιχεία_Μελέτης_&_Ποσότητες'!D111 -> m³ | E31: =ROUND((200*(1+'1_Στοιχεία_Μελέτης_&_Ποσότητες'!C83))-90, 2) -> 176.67 | F31: =ROUND(C31*E31, 2) -> 45888.27 | H31: ="Φύλλο 1 (B.9): Εκτόξευση/Αντλία = Βάση 200€ × (1+" & TEXT('1_Στοιχεία_Μελέτης_&_Ποσότητες'!C83,"0.0%") & " απώλεια) - 90€" -> Φύλλο 1 (B.9): Εκτόξευση/Αντλία = Βάση 200€ × (1+33.3% απώλεια) - 90€
A32: B.10 | B32: ='1_Στοιχεία_Μελέτης_&_Ποσότητες'!B112 -> ΔΙΑΤΡΗΣΗ ΑΓΚΥΡΩΣΕΩΝ Ø120mm (4 Σειρές: L1=20m, L2=19.5m, L3=19.5m, L4=16m) | C32: ='1_Στοιχεία_Μελέτης_&_Ποσότητες'!C112 -> 5550 | D32: ='1_Στοιχεία_Μελέτης_&_Ποσότητες'!D112 -> m | E32: 30 | F32: =ROUND(C32*E32, 2) -> 166500 | H32: ="Φύλλο 1 (B.10): Διάτρηση " & '1_Στοιχεία_Μελέτης_&_Ποσότητες'!C116 & " αγκυρώσεων Ø" & ('1_Στοιχεία_Μελέτης_&_Ποσότητες'!C26*1000) & "mm (Σειρές 1-4: " & '1_Στοιχεία_Μελέτης_&_Ποσότητες'!C54 & "m, " & '1_Στοιχεία_Μελέτης_&_Ποσότητες'!C56 & "m, " & '1_Στοιχεία_Μελέτης_&_Ποσότητες'!C58 & "m, " & '1_Στοιχεία_Μελέτης_&_Ποσότητες'!C60 & "m) @ 30.00 €/m" -> Φύλλο 1 (B.10): Διάτρηση 296 αγκυρώσεων Ø120mm (Σειρές 1-4: 20m, 19.5m, 19.5m, 16m) @ 30.00 €/m
A33: B.11 | B33: ='1_Στοιχεία_Μελέτης_&_Ποσότητες'!B113 -> GROUT ΤΣΙΜΕΝΤΕΝΕΜΑ ΑΓΚΥΡΩΣΕΩΝ (με απώλεια 1.20) = 5,550.00m x 0.0136m³/m | C33: ='1_Στοιχεία_Μελέτης_&_Ποσότητες'!C113 -> 75.32 | D33: ='1_Στοιχεία_Μελέτης_&_Ποσότητες'!D113 -> m³ | E33: 500 | F33: =ROUND(C33*E33, 2) -> 37660 | H33: ="Φύλλο 1 (B.11): Grout Ø" & ('1_Στοιχεία_Μελέτης_&_Ποσότητες'!C26*1000) & "mm με απώλεια " & TEXT('1_Στοιχεία_Μελέτης_&_Ποσότητες'!C27,"0.00") & " (" & TEXT('1_Στοιχεία_Μελέτης_&_Ποσότητες'!C82,"0.000000") & " m³/m) @ 500.00 €/m³" -> Φύλλο 1 (B.11): Grout Ø120mm με απώλεια 1.20 (0.013572 m³/m) @ 500.00 €/m³
A34: B.12 | B34: ='1_Στοιχεία_Μελέτης_&_Ποσότητες'!B114 -> ΤΕΝΟΝΤΕΣ 0.6'' (2 ΚΑΛΩΔΙΑ) — Σειρά 1 (L=20m) & Σειρά 2 (L=19.5m) (+1.0m) | C34: ='1_Στοιχεία_Μελέτης_&_Ποσότητες'!C114 -> 6142 | D34: ='1_Στοιχεία_Μελέτης_&_Ποσότητες'!D114 -> m | E34: 2.28 | F34: =ROUND(C34*E34, 2) -> 14003.76 | H34: ="Φύλλο 1 (B.12): " & ('1_Στοιχεία_Μελέτης_&_Ποσότητες'!C48*2) & " αγκυρώσεις " & '1_Στοιχεία_Μελέτης_&_Ποσότητες'!C55 & "-strands (Σειρά 1 L=" & '1_Στοιχεία_Μελέτης_&_Ποσότητες'!C54 & "m & Σειρά 2 L=" & '1_Στοιχεία_Μελέτης_&_Ποσότητες'!C56 & "m, +" & TEXT('1_Στοιχεία_Μελέτης_&_Ποσότητες'!C28,"0.0") & "m) @ 2.28 €/m" -> Φύλλο 1 (B.12): 148 αγκυρώσεις 2-strands (Σειρά 1 L=20m & Σειρά 2 L=19.5m, +1.0m) @ 2.28 €/m
A35: B.13 | B35: ='1_Στοιχεία_Μελέτης_&_Ποσότητες'!B115 -> ΤΕΝΟΝΤΕΣ 0.6'' (3 ΚΑΛΩΔΙΑ) — Σειρά 3 (L=19.5m) & Σειρά 4 (L=16m) (+1.0m) | C35: ='1_Στοιχεία_Μελέτης_&_Ποσότητες'!C115 -> 8325 | D35: ='1_Στοιχεία_Μελέτης_&_Ποσότητες'!D115 -> m | E35: 2.28 | F35: =ROUND(C35*E35, 2) -> 18981 | H35: ="Φύλλο 1 (B.13): " & ('1_Στοιχεία_Μελέτης_&_Ποσότητες'!C48*2) & " αγκυρώσεις " & '1_Στοιχεία_Μελέτης_&_Ποσότητες'!C59 & "-strands (Σειρά 3 L=" & '1_Στοιχεία_Μελέτης_&_Ποσότητες'!C58 & "m & Σειρά 4 L=" & '1_Στοιχεία_Μελέτης_&_Ποσότητες'!C60 & "m, +" & TEXT('1_Στοιχεία_Μελέτης_&_Ποσότητες'!C28,"0.0") & "m) @ 2.28 €/m" -> Φύλλο 1 (B.13): 148 αγκυρώσεις 3-strands (Σειρά 3 L=19.5m & Σειρά 4 L=16m, +1.0m) @ 2.28 €/m
A36: B.14 | B36: ='1_Στοιχεία_Μελέτης_&_Ποσότητες'!B116 -> ΠΡΟΕΝΤΑΣΗ ΑΓΚΥΡΩΣΕΩΝ (STRESSING & LOCK-OFF) = 4 Σειρές X 74No | C36: ='1_Στοιχεία_Μελέτης_&_Ποσότητες'!C116 -> 296 | D36: ='1_Στοιχεία_Μελέτης_&_Ποσότητες'!D116 -> No | E36: 18 | F36: =ROUND(C36*E36, 2) -> 5328 | H36: ="Φύλλο 1 (B.14): Προένταση (Stressing & Lock-off) " & '1_Στοιχεία_Μελέτης_&_Ποσότητες'!C116 & " αγκυρώσεων Type B @ 18.00 €/No" -> Φύλλο 1 (B.14): Προένταση (Stressing & Lock-off) 296 αγκυρώσεων Type B @ 18.00 €/No
A37: B.15 | B37: ='1_Στοιχεία_Μελέτης_&_Ποσότητες'!B117 -> ΚΕΦΑΛΕΣ ΑΓΚΥΡΩΣΗΣ (ANCHOR HEAD, WEDGES, PLATE) = 4 Σειρές X 74No | C37: ='1_Στοιχεία_Μελέτης_&_Ποσότητες'!C117 -> 296 | D37: ='1_Στοιχεία_Μελέτης_&_Ποσότητες'!D117 -> No | E37: 55 | F37: =ROUND(C37*E37, 2) -> 16280 | H37: ="Φύλλο 1 (B.15): Πλήρες σετ κεφαλής (Head, Wedges, Plate) " & '1_Στοιχεία_Μελέτης_&_Ποσότητες'!C117 & " αγκυρώσεων Type B @ 55.00 €/No" -> Φύλλο 1 (B.15): Πλήρες σετ κεφαλής (Head, Wedges, Plate) 296 αγκυρώσεων Type B @ 55.00 €/No
A39: TYPE C | B39: ="BERLIN WALL TYPE C: " & '1_Στοιχεία_Μελέτης_&_Ποσότητες'!C64 & "No Ζεύγη HEB200, L=" & TEXT('1_Στοιχεία_Μελέτης_&_Ποσότητες'!C68,"0.00") & "m (Διάτρηση=" & TEXT(IF(ISBLANK('1_Στοιχεία_Μελέτης_&_Ποσότητες'!C69),'1_Στοιχεία_Μελέτης_&_Ποσότητες'!C68,'1_Στοιχεία_Μελέτης_&_Ποσότητες'!C69),"0.00") & "m), Εκσκαφή " & TEXT('1_Στοιχεία_Μελέτης_&_Ποσότητες'!C66,"0.00") & "m, " & TEXT('1_Στοιχεία_Μελέτης_&_Ποσότητες'!C65,"0.00") & " τρ.μ." -> BERLIN WALL TYPE C: 15No Ζεύγη HEB200, L=13.00m (Διάτρηση=13.00m), Εκσκαφή 11.10m, 22.50 τρ.μ. | C39: ='1_Στοιχεία_Μελέτης_&_Ποσότητες'!C65 -> 22.5 | D39: τρ.μ. | E39: =ROUND(F39/C39, 2) -> 4821.09 | F39: =SUM(F40:F53) -> 108474.48 | G39: ΤΕΛ. ΣΥΝΟΛΑ | H39: ="Σύνολο Τοίχου Γ (Πυλώνες 2, 3 & 4 — HEB 200, " & '1_Στοιχεία_Μελέτης_&_Ποσότητες'!C64 & " πάσσαλοι, " & '1_Στοιχεία_Μελέτης_&_Ποσότητες'!C132 & " αγκυρώσεις)" -> Σύνολο Τοίχου Γ (Πυλώνες 2, 3 & 4 — HEB 200, 15 πάσσαλοι, 45 αγκυρώσεις)
A40: C.1 | B40: ='1_Στοιχεία_Μελέτης_&_Ποσότητες'!B120 -> ΤΡΥΠΗΜΑ / ΕΚΣΚΑΦΗ ΝΕΦΚΩΝ Ø800mm = 15No X 13.00m (Όγκος: 98.02 m³) | C40: ='1_Στοιχεία_Μελέτης_&_Ποσότητες'!C120 -> 195 | D40: ='1_Στοιχεία_Μελέτης_&_Ποσότητες'!D120 -> m | E40: 75 | F40: =ROUND(C40*E40, 2) -> 14625 | G40: =F39 -> 108474.48 | H40: =IF(ISBLANK('1_Στοιχεία_Μελέτης_&_Ποσότητες'!C69),"Φύλλο 1 (C.1): " & '1_Στοιχεία_Μελέτης_&_Ποσότητες'!C64 & " πάσσαλοι × " & TEXT('1_Στοιχεία_Μελέτης_&_Ποσότητες'!C68,"0.00") & "m (χωρίς WPL, Όγκος " & TEXT(ROUND('1_Στοιχεία_Μελέτης_&_Ποσότητες'!C120*'1_Στοιχεία_Μελέτης_&_Ποσότητες'!C80,2),"#,##0.00") & " m³) @ 75.00 €/m","Φύλλο 1 (C.1 — ΜΕ WPL): " & '1_Στοιχεία_Μελέτης_&_Ποσότητες'!C64 & " πάσσαλοι × " & TEXT('1_Στοιχεία_Μελέτης_&_Ποσότητες'!C69,"0.00") & "m (Όγκος " & TEXT(ROUND('1_Στοιχεία_Μελέτης_&_Ποσότητες'!C120*'1_Στοιχεία_Μελέτης_&_Ποσότητες'!C80,2),"#,##0.00") & " m³) @ 75.00 €/m") -> Φύλλο 1 (C.1): 15 πάσσαλοι × 13.00m (χωρίς WPL, Όγκος 98.02 m³) @ 75.00 €/m
A41: C.2 | B41: ='1_Στοιχεία_Μελέτης_&_Ποσότητες'!B121 -> ΜΠΕΤΟΝ ΠΑΚΤΩΣΗΣ C30/37 = 15No X 1.50m X 0.503m³/m | C41: ='1_Στοιχεία_Μελέτης_&_Ποσότητες'!C121 -> 11.31 | D41: ='1_Στοιχεία_Μελέτης_&_Ποσότητες'!D121 -> m³ | E41: 120 | F41: =ROUND(C41*E41, 2) -> 1357.2 | H41: ="Φύλλο 1 (C.2): Πάκτωση H=" & TEXT('1_Στοιχεία_Μελέτης_&_Ποσότητες'!C67,"0.00") & "m σε Ø" & ('1_Στοιχεία_Μελέτης_&_Ποσότητες'!C11*1000) & "mm @ 120.00 €/m³ [Πορτοκαλί #FFE699]" -> Φύλλο 1 (C.2): Πάκτωση H=1.50m σε Ø800mm @ 120.00 €/m³ [Πορτοκαλί #FFE699]
A42: C.3 | B42: ='1_Στοιχεία_Μελέτης_&_Ποσότητες'!B122 -> HEB200 - ΠΡΟΜΗΘΕΙΑ, ΕΠΕΞΕΡΓΑΣΙΑ & ΤΟΠΟΘΕΤΗΣΗ (15No x 2No x 13.00m x 61.3kg/m) | C42: ='1_Στοιχεία_Μελέτης_&_Ποσότητες'!C122 -> 23907 | D42: ='1_Στοιχεία_Μελέτης_&_Ποσότητες'!D122 -> kg | E42: 1.4 | F42: =ROUND(C42*E42, 2) -> 33469.8 | H42: ="Φύλλο 1 (C.3): " & '1_Στοιχεία_Μελέτης_&_Ποσότητες'!C12 & " No. HEB 200 (" & TEXT('1_Στοιχεία_Μελέτης_&_Ποσότητες'!C14*'1_Στοιχεία_Μελέτης_&_Ποσότητες'!C12,"0.0") & " kg/m, L=" & TEXT('1_Στοιχεία_Μελέτης_&_Ποσότητες'!C68,"0.0") & "m) @ 1.40 €/kg" -> Φύλλο 1 (C.3): 2 No. HEB 200 (122.6 kg/m, L=13.0m) @ 1.40 €/kg
A43: C.4 | B43: ='1_Στοιχεία_Μελέτης_&_Ποσότητες'!B123 -> ΛΑΜΕΣ ΣΥΝΔΕΣΗΣ 200x200x10mm = 15No x (13No x 3.140kg) | C43: ='1_Στοιχεία_Μελέτης_&_Ποσότητες'!C123 -> 612.3 | D43: ='1_Στοιχεία_Μελέτης_&_Ποσότητες'!D123 -> kg | E43: 1.6 | F43: =ROUND(C43*E43, 2) -> 979.68 | H43: ="Φύλλο 1 (C.4): Λάμες " & '1_Στοιχεία_Μελέτης_&_Ποσότητες'!C16 & "x" & '1_Στοιχεία_Μελέτης_&_Ποσότητες'!C17 & "x" & '1_Στοιχεία_Μελέτης_&_Ποσότητες'!C18 & "mm (" & ('1_Στοιχεία_Μελέτης_&_Ποσότητες'!C68/'1_Στοιχεία_Μελέτης_&_Ποσότητες'!C15) & " λάμες/οπή = " & ('1_Στοιχεία_Μελέτης_&_Ποσότητες'!C64*('1_Στοιχεία_Μελέτης_&_Ποσότητες'!C68/'1_Στοιχεία_Μελέτης_&_Ποσότητες'!C15)) & " τεμ.) @ 1.60 €/kg" -> Φύλλο 1 (C.4): Λάμες 200x200x10mm (13 λάμες/οπή = 195 τεμ.) @ 1.60 €/kg
...

Sheet 3_Πίνακες_Διατομών_Χάλυβα
A1: ΒΙΒΛΙΟΘΗΚΗ ΔΙΑΤΟΜΩΝ ΧΑΛΥΒΑ (EUROPEAN STRUCTURAL STEEL PROFILES)
A2: Τεχνικά χαρακτηριστικά & βάρη ανά μέτρο για διατομές HEA, HEB, UPN & Γωνιών (L)
A4: 1. ΔΙΑΤΟΜΕΣ HEA (Ευρωπαϊκά Πλατύπελμα Ελαφρού Τύπου)
A5: Ονομασία Διατομής | B5: Ύψος h (mm) | C5: Πλάτος b (mm) | D5: Πάχος tw (mm) | E5: Πάχος tf (mm) | F5: Διατομή A (cm²) | G5: Βάρος (kg / m)
A6: HEA 140 | B6: 133 | C6: 140 | D6: 5.5 | E6: 8.5 | F6: 31.4 | G6: 24.7
A7: HEA 160 | B7: 152 | C7: 160 | D7: 6 | E7: 9 | F7: 38.8 | G7: 30.4
A8: HEA 180 | B8: 171 | C8: 180 | D8: 6 | E8: 9.5 | F8: 45.3 | G8: 35.5
A9: HEA 200 | B9: 190 | C9: 200 | D9: 6.5 | E9: 10 | F9: 53.8 | G9: 42.3
A10: HEA 220 | B10: 210 | C10: 220 | D10: 7 | E10: 11 | F10: 64.3 | G10: 50.5
A11: HEA 240 | B11: 230 | C11: 240 | D11: 7.5 | E11: 12 | F11: 76.8 | G11: 60.3
A12: HEA 260 | B12: 250 | C12: 260 | D12: 7.5 | E12: 12.5 | F12: 86.8 | G12: 68.2
A13: HEA 280 | B13: 270 | C13: 280 | D13: 8 | E13: 13 | F13: 97.3 | G13: 76.4
A14: HEA 300 | B14: 290 | C14: 300 | D14: 8.5 | E14: 14 | F14: 112.5 | G14: 88.3
A16: 2. ΔΙΑΤΟΜΕΣ HEB (Ευρωπαϊκά Πλατύπελμα Κανονικού Τύπου)
A17: Ονομασία Διατομής | B17: Ύψος h (mm) | C17: Πλάτος b (mm) | D17: Πάχος tw (mm) | E17: Πάχος tf (mm) | F17: Διατομή A (cm²) | G17: Βάρος (kg / m)
A18: HEB 140 | B18: 140 | C18: 140 | D18: 7 | E18: 12 | F18: 43 | G18: 33.7
A19: HEB 160 | B19: 160 | C19: 160 | D19: 8 | E19: 13 | F19: 54.3 | G19: 42.6
A20: HEB 180 | B20: 180 | C20: 180 | D20: 8.5 | E20: 14 | F20: 65.3 | G20: 51.2
A21: HEB 200 | B21: 200 | C21: 200 | D21: 9 | E21: 15 | F21: 78.1 | G21: 61.3
A22: HEB 220 | B22: 220 | C22: 220 | D22: 9.5 | E22: 16 | F22: 91 | G22: 71.5
A23: HEB 240 | B23: 240 | C23: 240 | D23: 10 | E23: 17 | F23: 106 | G23: 83.2
A24: HEB 260 | B24: 260 | C24: 260 | D24: 10 | E24: 17.5 | F24: 118.4 | G24: 93
A25: HEB 280 | B25: 280 | C25: 280 | D25: 10.5 | E25: 18 | F25: 131.4 | G25: 103
A26: HEB 300 | B26: 300 | C26: 300 | D26: 11 | E26: 19 | F26: 149.1 | G26: 117
A28: 3. ΔΙΑΤΟΜΕΣ UPN (Ευρωπαϊκά Κοίλα Προφίλ U)
A29: Ονομασία Διατομής | B29: Ύψος h (mm) | C29: Πλάτος b (mm) | D29: Πάχος tw (mm) | E29: Πάχος tf (mm) | F29: Διατομή A (cm²) | G29: Βάρος (kg / m)
A30: UPN 140 | B30: 140 | C30: 60 | D30: 7 | E30: 10 | F30: 20.4 | G30: 16
A31: UPN 160 | B31: 160 | C31: 65 | D31: 7.5 | E31: 10.5 | F31: 24 | G31: 18.8
A32: UPN 180 | B32: 180 | C32: 70 | D32: 8 | E32: 11 | F32: 28 | G32: 22
A33: UPN 200 | B33: 200 | C33: 75 | D33: 8.5 | E33: 11.5 | F33: 32.2 | G33: 25.3
A34: UPN 220 | B34: 220 | C34: 80 | D34: 9 | E34: 12.5 | F34: 37.4 | G34: 29.4
A35: UPN 240 | B35: 240 | C35: 85 | D35: 9.5 | E35: 13 | F35: 42.3 | G35: 33.2
A36: UPN 260 | B36: 260 | C36: 90 | D36: 10 | E36: 14 | F36: 48.3 | G36: 37.9
A37: UPN 280 | B37: 280 | C37: 95 | D37: 10 | E37: 15 | F37: 53.3 | G37: 41.8
A38: UPN 300 | B38: 300 | C38: 100 | D38: 10 | E38: 16 | F38: 58.8 | G38: 46.2
A40: 4. ΙΣΟΣΚΕΛΕΙΣ ΓΩΝΙΕΣ (Equal Angles L)
A41: Ονομασία Διατομής | B41: Ύψος h (mm) | C41: Πλάτος b (mm) | D41: Πάχος tw (mm) | E41: Πάχος tf (mm) | F41: Διατομή A (cm²) | G41: Βάρος (kg / m)
A42: L 50x50x5 | B42: 50 | C42: 50 | D42: 5 | E42: 5 | F42: 4.8 | G42: 3.77
A43: L 60x60x6 | B43: 60 | C43: 60 | D43: 6 | E43: 6 | F43: 6.91 | G43: 5.42
A44: L 70x70x6 | B44: 70 | C44: 70 | D44: 6 | E44: 6 | F44: 8.13 | G44: 6.38
...
