Workbook

Sheet 1_Στοιχεία_Μελέτης_&_Ποσότητες
A1: ΕΡΓΟ: BOLTON TOWER (BERLIN WALL & ΑΓΚΥΡΩΣΕΙΣ) — ΣΤΟΙΧΕΙΑ ΜΕΛΕΤΗΣ & ΦΥΣΙΚΕΣ ΠΟΣΟΤΗΤΕΣ ΑΝΑ ΤΥΠΟ ΤΟΙΧΟΥ (ΧΩΡΙΣ ΕΥΡΩ)
A2: 100% ΔΥΝΑΜΙΚΟΙ ΤΙΤΛΟΙ, ΤΥΠΟΙ & ΣΗΜΕΙΩΣΕΙΣ ΣΕ ΚΟΥΤΙΑ (BOXES) ΑΝΑ ΤΥΠΟ ΤΟΙΧΟΥ (TYPE A, TYPE B, TYPE C) | [ΚΕΦΑΛΑΙΟ Α] = INPUTS | [ΚΕΦΑΛΑΙΟ Β] = ΥΠΟΛΟΓΙΣΜΟΙ
A4: ΚΕΦΑΛΑΙΟ Α: ΣΤΟΙΧΕΙΑ ΜΕΛΕΤΗΣ (RAW INPUTS) — ΧΩΡΙΣΜΕΝΑ ΣΕ ΚΟΥΤΙΑ ΑΝΑ ΤΥΠΟ ΤΟΙΧΟΥ (100% ΔΥΝΑΜΙΚΗ ΣΥΝΔΕΣΗ)
A5: α/α | B5: ΠΕΡΙΓΡΑΦΗ ΣΤΟΙΧΕΙΟΥ / ΕΡΓΑΣΙΑΣ | C5: ΤΙΜΗ ΜΕΛΕΤΗΣ | D5: ΜΟΝ. | E5: ΠΗΓΗ ΜΕΛΕΤΗΣ (ΣΧΕΔΙΟ) | F5: ΤΕΧΝΙΚΗ ΣΗΜΕΙΩΣΗ / ΕΛΕΓΧΟΣ ΚΑΝΟΝΑ
A6: ΚΟΙΝΑ | B6: ΚΟΥΤΙ Α.0 — ΓΕΝΙΚΑ ΣΤΟΙΧΕΙΑ ΕΡΓΟΥ & ΚΟΙΝΕΣ ΠΡΟΔΙΑΓΡΑΦΕΣ (Εργοτάξιο, Διάτρηση, Λάμες, Γωνιές, Σχάρα, Shotcrete, Αγκυρώσεις)
A7: Κ.1 | B7: Έδρα Εταιρείας (Αφετηρία) | C7: Άγιος Συλάς, Σπύρου Κυπριανού 32, Λεμεσός | D7: - | E7: Βάση Εταιρείας | F7: Σταθερή βάση εκκίνησης συνεργείων & μηχανημάτων
A8: Κ.2 | B8: Τοποθεσία Εργοταξίου & Χιλιομετρική Απόσταση | C8: 12 | D8: km | E8: Σχέδιο ΘΕΜ/1 & ΘΕΜ/6 | F8: ="Λεμεσός (Bolton Tower, " & C8 & " km) — Ζώνη 0-40 km (βασικές τιμές μετακινήσεων)"
A9: Κ.3 | B9: Μέγιστο Πλήθος Οριζόντιων Σειρών Αγκυρώσεων Έργου | C9: 4 | D9: σειρές | E9: Σχέδιο ΘΕΜ/6, Τομές Α, Β, Γ | F9: ="Type A & B: " & C9 & " σειρές αγκυρώσεων | Type C: 3 σειρές αγκυρώσεων"
A10: Κ.4 | B10: Αξονική Απόσταση Πασσάλων (s_c/c) | C10: 1.5 | D10: m | E10: Σχέδιο ΘΕΜ/1 & ΘΕΜ/6 | F10: ="[!!! ΣΥΓΚΡΟΥΣΗ ΜΕΛΕΤΗΣ !!!]: Αναγράφονται 2 διαφορετικοί αριθμοί: @ 2000mm στο κείμενο λεπτομέρειας vs (1500) στη διάσταση CL και 1.50m στις τομές. Επιλέχθηκε ο πιο ασφαλής στατικά αριθμός s = " & TEXT(C10,"0.00") & " m."
A11: Κ.5 | B11: ="Διάμετρος Οπής Διάτρησης Μεγάλου Τρυπανιού (Ø" & (C11*1000) & "mm)" | C11: 0.8 | D11: m | E11: Κανόνας Εταιρείας | F11: ="[DEFAULT ΕΤΑΙΡΕΙΑΣ]: Δεν αναγράφεται διάμετρος νέφκας στη μελέτη (το D=800 στο ΘΕΜ/1 αφορά υποστυλώματα κτιρίου). Εφαρμόζεται by default Ø" & (C11*1000) & " mm (" & TEXT(C11,"0.00") & " m)."
A12: Κ.6 | B12: Πλήθος Προφίλ Χάλυβα ανά Πάσσαλο / Οπή | C12: 2 | D12: No/οπή | E12: Σχέδιο ΘΕΜ/6, Λεπτομέρεια | F12: ="Δίδυμο προφίλ (Ζεύγος " & C12 & " No. HEB ανά πάσσαλο)"
A13: Κ.7 | B13: Θεωρητικό Βάρος Διατομής HEB 220 (για Type A) | C13: 71.5 | D13: kg/m | E13: Βιβλιοθήκη Διατομών (Φύλλο 3) | F13: ="=" & TEXT(C13,"0.0") & " kg/m ανά HEB 220 (" & TEXT(C13*C12,"0.0") & " kg/m ανά ζεύγος)"
A14: Κ.8 | B14: Θεωρητικό Βάρος Διατομής HEB 200 (για Type B & Type C) | C14: 61.3 | D14: kg/m | E14: Βιβλιοθήκη Διατομών (Φύλλο 3) | F14: ="=" & TEXT(C14,"0.0") & " kg/m ανά HEB 200 (" & TEXT(C14*C12,"0.0") & " kg/m ανά ζεύγος)"
A15: Κ.9 | B15: Κατακόρυφο Βήμα Λαμών Σύνδεσης (s_plate) | C15: 1 | D15: m | E15: Σχέδιο ΘΕΜ/6, Λεπτομέρεια | F15: ="Λάμες " & C16 & "x" & C17 & "x" & C18 & "mm ανά " & (C15*1000) & "mm (" & TEXT(C15,"0.00") & "m) καθ' ύψος (Κανόνας L_beam / s_plate)"
A16: Κ.10α | B16: Πλάτος Λάμας Σύνδεσης (b_plate) | C16: 200 | D16: mm | E16: Σχέδιο ΘΕΜ/6, Λεπτομέρεια | F16: ="Πλάτος λάμας σύνδεσης = " & C16 & " mm (" & TEXT(C16/1000,"0.00") & " m)"
A17: Κ.10β | B17: Μήκος / Ύψος Λάμας Σύνδεσης (h_plate) | C17: 200 | D17: mm | E17: Σχέδιο ΘΕΜ/6, Λεπτομέρεια | F17: ="Μήκος λάμας σύνδεσης = " & C17 & " mm (" & TEXT(C17/1000,"0.00") & " m)"
A18: Κ.10γ | B18: Πάχος Λάμας Σύνδεσης (t_plate) | C18: 10 | D18: mm | E18: Σχέδιο ΘΕΜ/6, Λεπτομέρεια | F18: ="Πάχος λάμας σύνδεσης = " & C18 & " mm (" & TEXT(C18/1000,"0.000") & " m)"
A19: Κ.10 | B19: ="Βάρος 1 Λάμας Σύνδεσης (" & C16 & "x" & C17 & "x" & C18 & " mm)" | C19: =(C16/1000)*(C17/1000)*(C18/1000)*7850 | D19: kg/τεμ | E19: ="Τύπος: (" & C16 & "/1000)×(" & C17 & "/1000)×(" & C18 & "/1000)×7850" | F19: ="=" & TEXT(C16/1000,"0.00") & "m × " & TEXT(C17/1000,"0.00") & "m × " & TEXT(C18/1000,"0.000") & "m × 7,850 kg/m³ = " & TEXT(C19,"0.000") & " kg/τεμ (Αλλάζοντας τα C16:C18 ενημερώνονται αυτόματα τίτλοι & σημειώσεις)"
A20: Κ.11 | B20: Γωνιές Στήριξης Σχάρας L 70x70x6mm (2 τεμ. ανά πάσσαλο) | C20: 6.38 | D20: kg/m | E20: Σχέδιο ΘΕΜ/6 & Φύλλο 3 | F20: ="Γωνιές 70x70x6mm (" & TEXT(C20,"0.00") & " kg/m × 2 γωνιές καθ' ύψος εκσκαφής H_exc)"
A21: Κ.12 | B21: ="Διάμετρος Ράβδων Σχάρας Οριζόντιων & Κατακόρυφων (#Y" & C21 & "/" & C22 & ")" | C21: 8 | D21: mm | E21: Σχέδιο ΘΕΜ/6, Λεπτομέρεια | F21: ="Αναγράφεται ρητά #Y" & C21 & "/" & C22 & " (αυστηρή τήρηση Y" & C21 & " βάσει κανόνα 2.3)"
A22: Κ.13 | B22: ="Βήμα Ράβδων Σχάρας Οριζόντιων & Κατακόρυφων (#Y" & C21 & "/" & C22 & ")" | C22: 150 | D22: mm | E22: Σχέδιο ΘΕΜ/6, Λεπτομέρεια | F22: ="Βήμα " & C22 & "mm × " & C22 & "mm (2 × " & TEXT(1000/C22,"0.00") & " m/m² = " & TEXT(C78,"0.000") & " kg/m²)"
A23: Κ.14 | B23: Κατηγορία Σκυροδέματος Shotcrete & Πάκτωσης | C23: C30/37 | D23: - | E23: Κανόνας Εταιρείας | F23: ="[DEFAULT ΕΤΑΙΡΕΙΑΣ]: Δεν αναγράφεται στη μελέτη. Εφαρμόζεται by default " & C23 & " βάσει κανόνα εταιρείας."
A24: Κ.15 | B24: ="Ονομαστικό Πάχος Shotcrete Μελέτης (" & (C24*100) & " cm)" | C24: 0.15 | D24: m | E24: Σχέδιο ΘΕΜ/6, Λεπτομέρεια | F24: ="=" & (C24*1000) & " mm (" & (C24*100) & " cm) εκτοξευόμενο σκυρόδεμα (gunite)"
A25: Κ.16 | B25: ="Πάγια Απώλεια / Αναπήδηση Shotcrete Εταιρείας (+" & (C25*100) & " cm)" | C25: 0.05 | D25: m | E25: Κανόνας Εταιρείας | F25: ="+" & (C25*100) & " cm πάγια προσαύξηση εταιρείας (+" & TEXT(C25/C24,"0.0%") & " επί του ονομαστικού πάχους)"
A26: Κ.17 | B26: ="Διάμετρος Οπής Διάτρησης Αγκυρώσεων (Ø" & (C26*1000) & "mm)" | C26: 0.12 | D26: m | E26: Κανόνας Εταιρείας | F26: ="Ø" & (C26*1000) & " mm τυπική διάμετρος διάτρησης αγκυρίων"
A27: Κ.18 | B27: Συντελεστής Απώλειας Grout Αγκυρώσεων | C27: 1.2 | D27: - | E27: Κανόνας Εταιρείας | F27: ="+" & TEXT((C27-1),"0%") & " προσαύξηση όγκου τσιμεντενέματος (" & TEXT(C79,"0.000000") & " m³/m)"
A28: Κ.19 | B28: Πρόσθετο Μήκος Τένοντα εκτός Μετώπου (για τάνυση/κεφαλή) | C28: 1 | D28: m | E28: Κανόνας Εταιρείας | F28: ="+" & TEXT(C28,"0.00") & " m έξω από το μέτωπο σε κάθε τένοντα"
A29: Κ.20 | B29: Τυπικό Βάρος Τένοντα Προέντασης 0.6'' (15.2mm) | C29: 1.1 | D29: kg/m | E29: Κανόνας Εταιρείας | F29: ="7-wire strand 0.6'' (1670/1860 MPa) = " & TEXT(C29,"0.00") & " kg/m"
A31: TYPE A | B31: ="ΚΟΥΤΙ ΣΤΟΙΧΕΙΩΝ ΜΕΛΕΤΗΣ TYPE A — ΤΟΙΧΟΣ ΑΝΤΙΣΤΗΡΙΞΗΣ Α (Εκσκαφή " & TEXT(C34,"0.00") & "m, " & C32 & "No Ζεύγη HEB 220, L=" & TEXT(C36,"0.00") & "m, Πάκτωση " & TEXT(C35,"0.00") & "m, 4 Σειρές Αγκυρώσεων)"
A32: A.in.1 | B32: Πλήθος Πασσάλων / Ζευγών HEB 220 (Type A) | C32: 27 | D32: No | E32: Σχέδιο ΘΕΜ/1 (Κάτοψη — Βέλη Αγκυρώσεων) | F32: ="=" & C32 & " πάσσαλοι / θέσεις αγκυρώσεων (22 στο Ανατολικό + 5 στο Νότιο τμήμα Τοίχου Α)"
A33: A.in.2 | B33: ="Αναπτυγμένο Μήκος Μετώπου Type A (" & C32 & " × " & TEXT(C10,"0.00") & "m)" | C33: =C32*C10 | D33: τρ.μ. | E33: Σχέδιο ΘΕΜ/1 (Intervals) | F33: ="=" & C32 & " πάσσαλοι × " & TEXT(C10,"0.00") & "m = " & TEXT(C33,"0.00") & " τρ.μ."
A34: A.in.3 | B34: Ελεύθερο Ύψος Εκσκαφής Type A (H_exc_A) | C34: 17 | D34: m | E34: Σχέδιο ΘΕΜ/6, Τομή Τοίχου Α | F34: ="Αναγραφόμενο ελεύθερο ύψος εκσκαφής " & (C34*1000) & " mm (" & TEXT(C34,"0.00") & " m)"
A35: A.in.4 | B35: Ύψος Πάκτωσης Σκυροδέματος Νέφκας Type A (H_embed_A) | C35: 1.5 | D35: m | E35: Σχέδιο ΘΕΜ/6, Τομή Τοίχου Α | F35: ="Αναγραφόμενο ύψος πάκτωσης σκυροδέματος " & (C35*1000) & " mm (" & TEXT(C35,"0.00") & " m) στη βάση της νέφκας"
A36: A.in.5 | B36: Συνολικό Μήκος Νέφκας / Διάτρησης Type A (L_beam_A) | C36: 19 | D36: m | E36: Σχέδιο ΘΕΜ/6, Τομή Τοίχου Α | F36: ="Αναγραφόμενο συνολικό μήκος νέφκας " & (C36*1000) & " mm (" & TEXT(C36,"0.00") & " m) — ελεύθερο " & TEXT(C34,"0.00") & "m, υπόγειο " & TEXT(C36-C34,"0.00") & "m, πάκτωση μπετόν " & TEXT(C35,"0.00") & "m"
A37: A.in.6 | B37: Αγκύρωση Σειρά 1 (στο -2.00m): Μήκος Διάτρησης L1 | C37: 20 | D37: m | E37: Σχέδιο ΘΕΜ/6, Τομή Τοίχου Α | F37: ="10.0m ελεύθερο + 10.0m πάκτωση grout = " & TEXT(C37,"0.00") & "m (30°, 144 kN)"
A38: A.in.7 | B38: Αγκύρωση Σειρά 1 (στο -2.00m): Καλώδια (Strands) | C38: 2 | D38: καλώδια | E38: Σχέδιο ΘΕΜ/6, Τομή Τοίχου Α | F38: ="Αναγράφεται: " & C38 & " ΚΑΛΩΔΙΑ 15.2mm (Type 1670/1860)"
A39: A.in.8 | B39: Αγκύρωση Σειρά 2 (στο -6.00m): Μήκος Διάτρησης L2 | C39: 19.5 | D39: m | E39: Σχέδιο ΘΕΜ/6, Τομή Τοίχου Α | F39: ="8.5m ελεύθερο + 11.0m πάκτωση grout = " & TEXT(C39,"0.00") & "m (30°, 338 kN)"
A40: A.in.9 | B40: Αγκύρωση Σειρά 2 (στο -6.00m): Καλώδια (Strands) | C40: 2 | D40: καλώδια | E40: Σχέδιο ΘΕΜ/6, Τομή Τοίχου Α | F40: ="Αναγράφεται: " & C40 & " ΚΑΛΩΔΙΑ 15.2mm (Type 1670/1860)"
A41: A.in.10 | B41: Αγκύρωση Σειρά 3 (στο -9.50m): Μήκος Διάτρησης L3 | C41: 20 | D41: m | E41: Σχέδιο ΘΕΜ/6, Τομή Τοίχου Α | F41: ="8.0m ελεύθερο + 12.0m πάκτωση grout = " & TEXT(C41,"0.00") & "m (30°, 439 kN)"
A42: A.in.11 | B42: Αγκύρωση Σειρά 3 (στο -9.50m): Καλώδια (Strands) | C42: 3 | D42: καλώδια | E42: Σχέδιο ΘΕΜ/6, Τομή Τοίχου Α | F42: ="Αναγράφεται: " & C42 & " ΚΑΛΩΔΙΑ 15.2mm (Type 1670/1860)"
...

Sheet 2_Υπολογισμοί_&_Κοστολόγηση
A1: ΕΡΓΟ: BOLTON TOWER (BERLIN WALL & ΑΓΚΥΡΩΣΕΙΣ) — ΟΙΚΟΝΟΜΙΚΗ ΠΡΟΣΦΟΡΑ ΑΝΑ ΤΥΠΟ ΤΟΙΧΟΥ (TYPE A, TYPE B, TYPE C)
A2: ΔΟΜΗ ΠΙΝΑΚΩΝ ΑΝΑ ΤΥΠΟ BERLIN WALL (BOX LAYOUT) | [ΚΙΤΡΙΝΟ #FFF2CC] = Τιμές Μονάδας Εταιρείας | [ΠΟΡΤΟΚΑΛΙ #FFE699] = Κουγκρί Πάκτωσης 120€
A4: α/α | B4: ΠΕΡΙΓΡΑΦΗ ΕΡΓΑΣΙΩΝ | C4: ΠΟΣΟΤΗΤΑ | D4: ΜΟΝ. | E4: ΤΙΜΗ (€) | F4: ΣΥΝΟΛΟ (€) | G4: ΤΕΛΙΚΟ ΠΟΣΟ (€) | H4: ΠΗΓΗ ΠΟΣΟΤΗΤΑΣ / ΤΕΧΝΙΚΟΣ ΚΑΝΟΝΑΣ & ΣΗΜΕΙΩΣΕΙΣ
A5: TYPE A | B5: ="BERLIN WALL TYPE A: " & '1_Στοιχεία_Μελέτης_&_Ποσότητες'!C32 & "No Ζεύγη HEB220, L=" & TEXT('1_Στοιχεία_Μελέτης_&_Ποσότητες'!C36,"0.00") & "m για βάθος εκσκαφής " & TEXT('1_Στοιχεία_Μελέτης_&_Ποσότητες'!C34,"0.00") & "m και " & TEXT('1_Στοιχεία_Μελέτης_&_Ποσότητες'!C33,"0.00") & " τρ.μ." | C5: ='1_Στοιχεία_Μελέτης_&_Ποσότητες'!C33 | D5: τρ.μ. | E5: =ROUND(F5/C5, 2) | F5: =SUM(F6:F20) | G5: ΤΕΛ. ΣΥΝΟΛΑ | H5: ="Σύνολο Τοίχου Α (Πυλώνες 2, 3 & 4 — HEB 220, " & '1_Στοιχεία_Μελέτης_&_Ποσότητες'!C32 & " πάσσαλοι, " & '1_Στοιχεία_Μελέτης_&_Ποσότητες'!C96 & " αγκυρώσεις)"
A6: A.1 | B6: ='1_Στοιχεία_Μελέτης_&_Ποσότητες'!B83 | C6: ='1_Στοιχεία_Μελέτης_&_Ποσότητες'!C83 | D6: ='1_Στοιχεία_Μελέτης_&_Ποσότητες'!D83 | E6: 75 | F6: =ROUND(C6*E6, 2) | G6: =F5 | H6: ="Φύλλο 1 (A.1): " & '1_Στοιχεία_Μελέτης_&_Ποσότητες'!C32 & " πάσσαλοι × " & TEXT('1_Στοιχεία_Μελέτης_&_Ποσότητες'!C36,"0.00") & "m @ 75.00 €/m (Ø" & ('1_Στοιχεία_Μελέτης_&_Ποσότητες'!C11*1000) & "mm)"
A7: A.2 | B7: ='1_Στοιχεία_Μελέτης_&_Ποσότητες'!B84 | C7: ='1_Στοιχεία_Μελέτης_&_Ποσότητες'!C84 | D7: ='1_Στοιχεία_Μελέτης_&_Ποσότητες'!D84 | E7: 120 | F7: =ROUND(C7*E7, 2) | H7: ="Φύλλο 1 (A.2): Πάκτωση H=" & TEXT('1_Στοιχεία_Μελέτης_&_Ποσότητες'!C35,"0.00") & "m σε Ø" & ('1_Στοιχεία_Μελέτης_&_Ποσότητες'!C11*1000) & "mm @ 120.00 €/m³ [Πορτοκαλί #FFE699]"
A8: A.3 | B8: ='1_Στοιχεία_Μελέτης_&_Ποσότητες'!B85 | C8: ='1_Στοιχεία_Μελέτης_&_Ποσότητες'!C85 | D8: ='1_Στοιχεία_Μελέτης_&_Ποσότητες'!D85 | E8: 1.4 | F8: =ROUND(C8*E8, 2) | H8: ="Φύλλο 1 (A.3): " & '1_Στοιχεία_Μελέτης_&_Ποσότητες'!C12 & " No. HEB 220 (" & TEXT('1_Στοιχεία_Μελέτης_&_Ποσότητες'!C13*'1_Στοιχεία_Μελέτης_&_Ποσότητες'!C12,"0.0") & " kg/m) @ 1.40 €/kg (1.00€ αγορά + 0.40€ επεξεργασία)"
A9: A.4 | B9: ='1_Στοιχεία_Μελέτης_&_Ποσότητες'!B86 | C9: ='1_Στοιχεία_Μελέτης_&_Ποσότητες'!C86 | D9: ='1_Στοιχεία_Μελέτης_&_Ποσότητες'!D86 | E9: 1.6 | F9: =ROUND(C9*E9, 2) | H9: ="Φύλλο 1 (A.4): Λάμες " & '1_Στοιχεία_Μελέτης_&_Ποσότητες'!C16 & "x" & '1_Στοιχεία_Μελέτης_&_Ποσότητες'!C17 & "x" & '1_Στοιχεία_Μελέτης_&_Ποσότητες'!C18 & "mm (" & ('1_Στοιχεία_Μελέτης_&_Ποσότητες'!C36/'1_Στοιχεία_Μελέτης_&_Ποσότητες'!C15) & " λάμες/οπή = " & ('1_Στοιχεία_Μελέτης_&_Ποσότητες'!C32*('1_Στοιχεία_Μελέτης_&_Ποσότητες'!C36/'1_Στοιχεία_Μελέτης_&_Ποσότητες'!C15)) & " τεμ.) @ 1.60 €/kg"
A10: A.5 | B10: ='1_Στοιχεία_Μελέτης_&_Ποσότητες'!B87 | C10: ='1_Στοιχεία_Μελέτης_&_Ποσότητες'!C87 | D10: ='1_Στοιχεία_Μελέτης_&_Ποσότητες'!D87 | E10: 1.6 | F10: =ROUND(C10*E10, 2) | H10: ="Φύλλο 1 (A.5): 2 γωνιές L70x70x6 × " & TEXT('1_Στοιχεία_Μελέτης_&_Ποσότητες'!C34,"0.00") & "m (" & TEXT('1_Στοιχεία_Μελέτης_&_Ποσότητες'!C32*2*'1_Στοιχεία_Μελέτης_&_Ποσότητες'!C34,"0.0") & "m) @ 1.60 €/kg"
A11: A.6 | B11: ='1_Στοιχεία_Μελέτης_&_Ποσότητες'!B88 | C11: ='1_Στοιχεία_Μελέτης_&_Ποσότητες'!C88 | D11: ='1_Στοιχεία_Μελέτης_&_Ποσότητες'!D88 | E11: 2.5 | F11: =ROUND(C11*E11, 2) | H11: ="Φύλλο 1 (A.6): Σχάρα #Y" & '1_Στοιχεία_Μελέτης_&_Ποσότητες'!C21 & "/" & '1_Στοιχεία_Μελέτης_&_Ποσότητες'!C22 & " (" & TEXT('1_Στοιχεία_Μελέτης_&_Ποσότητες'!C78,"0.000") & " kg/m²) @ 2.50 €/kg αγορά"
A12: A.7 | B12: ='1_Στοιχεία_Μελέτης_&_Ποσότητες'!B89 | C12: ='1_Στοιχεία_Μελέτης_&_Ποσότητες'!C89 | D12: ='1_Στοιχεία_Μελέτης_&_Ποσότητες'!D89 | E12: 15 | F12: =ROUND(C12*E12, 2) | H12: ="Φύλλο 1 (A.7): Εργατικά τοποθέτησης σχάρας μετώπου (" & TEXT('1_Στοιχεία_Μελέτης_&_Ποσότητες'!C33,"0.0") & "m × " & TEXT('1_Στοιχεία_Μελέτης_&_Ποσότητες'!C34,"0.0") & "m) @ 15.00 €/m²"
A13: A.8 | B13: ='1_Στοιχεία_Μελέτης_&_Ποσότητες'!B90 | C13: ='1_Στοιχεία_Μελέτης_&_Ποσότητες'!C90 | D13: ='1_Στοιχεία_Μελέτης_&_Ποσότητες'!D90 | E13: 90 | F13: =ROUND(C13*E13, 2) | H13: ="Φύλλο 1 (A.8): Αγορά " & '1_Στοιχεία_Μελέτης_&_Ποσότητες'!C23 & " ονομαστικού πάχους " & ('1_Στοιχεία_Μελέτης_&_Ποσότητες'!C24*100) & "cm @ 90.00 €/m³"
A14: A.9 | B14: ='1_Στοιχεία_Μελέτης_&_Ποσότητες'!B91 | C14: ='1_Στοιχεία_Μελέτης_&_Ποσότητες'!C91 | D14: ='1_Στοιχεία_Μελέτης_&_Ποσότητες'!D91 | E14: =ROUND((200*(1+'1_Στοιχεία_Μελέτης_&_Ποσότητες'!C80))-90, 2) | F14: =ROUND(C14*E14, 2) | H14: ="Φύλλο 1 (A.9): Εκτόξευση/Αντλία = Βάση 200€ × (1+" & TEXT('1_Στοιχεία_Μελέτης_&_Ποσότητες'!C80,"0.0%") & " απώλεια) - 90€"
A15: A.10 | B15: ='1_Στοιχεία_Μελέτης_&_Ποσότητες'!B92 | C15: ='1_Στοιχεία_Μελέτης_&_Ποσότητες'!C92 | D15: ='1_Στοιχεία_Μελέτης_&_Ποσότητες'!D92 | E15: 30 | F15: =ROUND(C15*E15, 2) | H15: ="Φύλλο 1 (A.10): Διάτρηση " & '1_Στοιχεία_Μελέτης_&_Ποσότητες'!C96 & " αγκυρώσεων Ø" & ('1_Στοιχεία_Μελέτης_&_Ποσότητες'!C26*1000) & "mm (Σειρές 1-4: " & '1_Στοιχεία_Μελέτης_&_Ποσότητες'!C37 & "m, " & '1_Στοιχεία_Μελέτης_&_Ποσότητες'!C39 & "m, " & '1_Στοιχεία_Μελέτης_&_Ποσότητες'!C41 & "m, " & '1_Στοιχεία_Μελέτης_&_Ποσότητες'!C43 & "m) @ 30.00 €/m"
A16: A.11 | B16: ='1_Στοιχεία_Μελέτης_&_Ποσότητες'!B93 | C16: ='1_Στοιχεία_Μελέτης_&_Ποσότητες'!C93 | D16: ='1_Στοιχεία_Μελέτης_&_Ποσότητες'!D93 | E16: 500 | F16: =ROUND(C16*E16, 2) | H16: ="Φύλλο 1 (A.11): Grout Ø" & ('1_Στοιχεία_Μελέτης_&_Ποσότητες'!C26*1000) & "mm με απώλεια " & TEXT('1_Στοιχεία_Μελέτης_&_Ποσότητες'!C27,"0.00") & " (" & TEXT('1_Στοιχεία_Μελέτης_&_Ποσότητες'!C79,"0.000000") & " m³/m) @ 500.00 €/m³"
A17: A.12 | B17: ='1_Στοιχεία_Μελέτης_&_Ποσότητες'!B94 | C17: ='1_Στοιχεία_Μελέτης_&_Ποσότητες'!C94 | D17: ='1_Στοιχεία_Μελέτης_&_Ποσότητες'!D94 | E17: 2.28 | F17: =ROUND(C17*E17, 2) | H17: ="Φύλλο 1 (A.12): " & ('1_Στοιχεία_Μελέτης_&_Ποσότητες'!C32*2) & " αγκυρώσεις " & '1_Στοιχεία_Μελέτης_&_Ποσότητες'!C38 & "-strands (Σειρά 1 L=" & '1_Στοιχεία_Μελέτης_&_Ποσότητες'!C37 & "m & Σειρά 2 L=" & '1_Στοιχεία_Μελέτης_&_Ποσότητες'!C39 & "m, +" & TEXT('1_Στοιχεία_Μελέτης_&_Ποσότητες'!C28,"0.0") & "m) @ 2.28 €/m"
A18: A.13 | B18: ='1_Στοιχεία_Μελέτης_&_Ποσότητες'!B95 | C18: ='1_Στοιχεία_Μελέτης_&_Ποσότητες'!C95 | D18: ='1_Στοιχεία_Μελέτης_&_Ποσότητες'!D95 | E18: 2.28 | F18: =ROUND(C18*E18, 2) | H18: ="Φύλλο 1 (A.13): " & ('1_Στοιχεία_Μελέτης_&_Ποσότητες'!C32*2) & " αγκυρώσεις " & '1_Στοιχεία_Μελέτης_&_Ποσότητες'!C42 & "-strands (Σειρά 3 L=" & '1_Στοιχεία_Μελέτης_&_Ποσότητες'!C41 & "m & Σειρά 4 L=" & '1_Στοιχεία_Μελέτης_&_Ποσότητες'!C43 & "m, +" & TEXT('1_Στοιχεία_Μελέτης_&_Ποσότητες'!C28,"0.0") & "m) @ 2.28 €/m"
A19: A.14 | B19: ='1_Στοιχεία_Μελέτης_&_Ποσότητες'!B96 | C19: ='1_Στοιχεία_Μελέτης_&_Ποσότητες'!C96 | D19: ='1_Στοιχεία_Μελέτης_&_Ποσότητες'!D96 | E19: 18 | F19: =ROUND(C19*E19, 2) | H19: ="Φύλλο 1 (A.14): Προένταση (Stressing & Lock-off) " & '1_Στοιχεία_Μελέτης_&_Ποσότητες'!C96 & " αγκυρώσεων Type A @ 18.00 €/No"
A20: A.15 | B20: ='1_Στοιχεία_Μελέτης_&_Ποσότητες'!B97 | C20: ='1_Στοιχεία_Μελέτης_&_Ποσότητες'!C97 | D20: ='1_Στοιχεία_Μελέτης_&_Ποσότητες'!D97 | E20: 55 | F20: =ROUND(C20*E20, 2) | H20: ="Φύλλο 1 (A.15): Πλήρες σετ κεφαλής (Head, Wedges, Plate) " & '1_Στοιχεία_Μελέτης_&_Ποσότητες'!C97 & " αγκυρώσεων Type A @ 55.00 €/No"
A22: TYPE B | B22: ="BERLIN WALL TYPE B: " & '1_Στοιχεία_Μελέτης_&_Ποσότητες'!C47 & "No Ζεύγη HEB200, L=" & TEXT('1_Στοιχεία_Μελέτης_&_Ποσότητες'!C51,"0.00") & "m για βάθος εκσκαφής " & TEXT('1_Στοιχεία_Μελέτης_&_Ποσότητες'!C49,"0.00") & "m και " & TEXT('1_Στοιχεία_Μελέτης_&_Ποσότητες'!C48,"0.00") & " τρ.μ." | C22: ='1_Στοιχεία_Μελέτης_&_Ποσότητες'!C48 | D22: τρ.μ. | E22: =ROUND(F22/C22, 2) | F22: =SUM(F23:F37) | G22: ΤΕΛ. ΣΥΝΟΛΑ | H22: ="Σύνολο Τοίχου Β (Πυλώνες 2, 3 & 4 — HEB 200, " & '1_Στοιχεία_Μελέτης_&_Ποσότητες'!C47 & " πάσσαλοι, " & '1_Στοιχεία_Μελέτης_&_Ποσότητες'!C113 & " αγκυρώσεις)"
A23: B.1 | B23: ='1_Στοιχεία_Μελέτης_&_Ποσότητες'!B100 | C23: ='1_Στοιχεία_Μελέτης_&_Ποσότητες'!C100 | D23: ='1_Στοιχεία_Μελέτης_&_Ποσότητες'!D100 | E23: 75 | F23: =ROUND(C23*E23, 2) | G23: =F22 | H23: ="Φύλλο 1 (B.1): " & '1_Στοιχεία_Μελέτης_&_Ποσότητες'!C47 & " πάσσαλοι × " & TEXT('1_Στοιχεία_Μελέτης_&_Ποσότητες'!C51,"0.00") & "m @ 75.00 €/m (Ø" & ('1_Στοιχεία_Μελέτης_&_Ποσότητες'!C11*1000) & "mm)"
A24: B.2 | B24: ='1_Στοιχεία_Μελέτης_&_Ποσότητες'!B101 | C24: ='1_Στοιχεία_Μελέτης_&_Ποσότητες'!C101 | D24: ='1_Στοιχεία_Μελέτης_&_Ποσότητες'!D101 | E24: 120 | F24: =ROUND(C24*E24, 2) | H24: ="Φύλλο 1 (B.2): Πάκτωση H=" & TEXT('1_Στοιχεία_Μελέτης_&_Ποσότητες'!C50,"0.00") & "m σε Ø" & ('1_Στοιχεία_Μελέτης_&_Ποσότητες'!C11*1000) & "mm @ 120.00 €/m³ [Πορτοκαλί #FFE699]"
A25: B.3 | B25: ='1_Στοιχεία_Μελέτης_&_Ποσότητες'!B102 | C25: ='1_Στοιχεία_Μελέτης_&_Ποσότητες'!C102 | D25: ='1_Στοιχεία_Μελέτης_&_Ποσότητες'!D102 | E25: 1.4 | F25: =ROUND(C25*E25, 2) | H25: ="Φύλλο 1 (B.3): " & '1_Στοιχεία_Μελέτης_&_Ποσότητες'!C12 & " No. HEB 200 (" & TEXT('1_Στοιχεία_Μελέτης_&_Ποσότητες'!C14*'1_Στοιχεία_Μελέτης_&_Ποσότητες'!C12,"0.0") & " kg/m) @ 1.40 €/kg (1.00€ αγορά + 0.40€ επεξεργασία)"
A26: B.4 | B26: ='1_Στοιχεία_Μελέτης_&_Ποσότητες'!B103 | C26: ='1_Στοιχεία_Μελέτης_&_Ποσότητες'!C103 | D26: ='1_Στοιχεία_Μελέτης_&_Ποσότητες'!D103 | E26: 1.6 | F26: =ROUND(C26*E26, 2) | H26: ="Φύλλο 1 (B.4): Λάμες " & '1_Στοιχεία_Μελέτης_&_Ποσότητες'!C16 & "x" & '1_Στοιχεία_Μελέτης_&_Ποσότητες'!C17 & "x" & '1_Στοιχεία_Μελέτης_&_Ποσότητες'!C18 & "mm (" & ('1_Στοιχεία_Μελέτης_&_Ποσότητες'!C51/'1_Στοιχεία_Μελέτης_&_Ποσότητες'!C15) & " λάμες/οπή = " & ('1_Στοιχεία_Μελέτης_&_Ποσότητες'!C47*('1_Στοιχεία_Μελέτης_&_Ποσότητες'!C51/'1_Στοιχεία_Μελέτης_&_Ποσότητες'!C15)) & " τεμ.) @ 1.60 €/kg"
A27: B.5 | B27: ='1_Στοιχεία_Μελέτης_&_Ποσότητες'!B104 | C27: ='1_Στοιχεία_Μελέτης_&_Ποσότητες'!C104 | D27: ='1_Στοιχεία_Μελέτης_&_Ποσότητες'!D104 | E27: 1.6 | F27: =ROUND(C27*E27, 2) | H27: ="Φύλλο 1 (B.5): 2 γωνιές L70x70x6 × " & TEXT('1_Στοιχεία_Μελέτης_&_Ποσότητες'!C49,"0.00") & "m (" & TEXT('1_Στοιχεία_Μελέτης_&_Ποσότητες'!C47*2*'1_Στοιχεία_Μελέτης_&_Ποσότητες'!C49,"0.0") & "m) @ 1.60 €/kg"
A28: B.6 | B28: ='1_Στοιχεία_Μελέτης_&_Ποσότητες'!B105 | C28: ='1_Στοιχεία_Μελέτης_&_Ποσότητες'!C105 | D28: ='1_Στοιχεία_Μελέτης_&_Ποσότητες'!D105 | E28: 2.5 | F28: =ROUND(C28*E28, 2) | H28: ="Φύλλο 1 (B.6): Σχάρα #Y" & '1_Στοιχεία_Μελέτης_&_Ποσότητες'!C21 & "/" & '1_Στοιχεία_Μελέτης_&_Ποσότητες'!C22 & " (" & TEXT('1_Στοιχεία_Μελέτης_&_Ποσότητες'!C78,"0.000") & " kg/m²) @ 2.50 €/kg αγορά"
A29: B.7 | B29: ='1_Στοιχεία_Μελέτης_&_Ποσότητες'!B106 | C29: ='1_Στοιχεία_Μελέτης_&_Ποσότητες'!C106 | D29: ='1_Στοιχεία_Μελέτης_&_Ποσότητες'!D106 | E29: 15 | F29: =ROUND(C29*E29, 2) | H29: ="Φύλλο 1 (B.7): Εργατικά τοποθέτησης σχάρας μετώπου (" & TEXT('1_Στοιχεία_Μελέτης_&_Ποσότητες'!C48,"0.0") & "m × " & TEXT('1_Στοιχεία_Μελέτης_&_Ποσότητες'!C49,"0.0") & "m) @ 15.00 €/m²"
A30: B.8 | B30: ='1_Στοιχεία_Μελέτης_&_Ποσότητες'!B107 | C30: ='1_Στοιχεία_Μελέτης_&_Ποσότητες'!C107 | D30: ='1_Στοιχεία_Μελέτης_&_Ποσότητες'!D107 | E30: 90 | F30: =ROUND(C30*E30, 2) | H30: ="Φύλλο 1 (B.8): Αγορά " & '1_Στοιχεία_Μελέτης_&_Ποσότητες'!C23 & " ονομαστικού πάχους " & ('1_Στοιχεία_Μελέτης_&_Ποσότητες'!C24*100) & "cm @ 90.00 €/m³"
A31: B.9 | B31: ='1_Στοιχεία_Μελέτης_&_Ποσότητες'!B108 | C31: ='1_Στοιχεία_Μελέτης_&_Ποσότητες'!C108 | D31: ='1_Στοιχεία_Μελέτης_&_Ποσότητες'!D108 | E31: =ROUND((200*(1+'1_Στοιχεία_Μελέτης_&_Ποσότητες'!C80))-90, 2) | F31: =ROUND(C31*E31, 2) | H31: ="Φύλλο 1 (B.9): Εκτόξευση/Αντλία = Βάση 200€ × (1+" & TEXT('1_Στοιχεία_Μελέτης_&_Ποσότητες'!C80,"0.0%") & " απώλεια) - 90€"
A32: B.10 | B32: ='1_Στοιχεία_Μελέτης_&_Ποσότητες'!B109 | C32: ='1_Στοιχεία_Μελέτης_&_Ποσότητες'!C109 | D32: ='1_Στοιχεία_Μελέτης_&_Ποσότητες'!D109 | E32: 30 | F32: =ROUND(C32*E32, 2) | H32: ="Φύλλο 1 (B.10): Διάτρηση " & '1_Στοιχεία_Μελέτης_&_Ποσότητες'!C113 & " αγκυρώσεων Ø" & ('1_Στοιχεία_Μελέτης_&_Ποσότητες'!C26*1000) & "mm (Σειρές 1-4: " & '1_Στοιχεία_Μελέτης_&_Ποσότητες'!C52 & "m, " & '1_Στοιχεία_Μελέτης_&_Ποσότητες'!C54 & "m, " & '1_Στοιχεία_Μελέτης_&_Ποσότητες'!C56 & "m, " & '1_Στοιχεία_Μελέτης_&_Ποσότητες'!C58 & "m) @ 30.00 €/m"
A33: B.11 | B33: ='1_Στοιχεία_Μελέτης_&_Ποσότητες'!B110 | C33: ='1_Στοιχεία_Μελέτης_&_Ποσότητες'!C110 | D33: ='1_Στοιχεία_Μελέτης_&_Ποσότητες'!D110 | E33: 500 | F33: =ROUND(C33*E33, 2) | H33: ="Φύλλο 1 (B.11): Grout Ø" & ('1_Στοιχεία_Μελέτης_&_Ποσότητες'!C26*1000) & "mm με απώλεια " & TEXT('1_Στοιχεία_Μελέτης_&_Ποσότητες'!C27,"0.00") & " (" & TEXT('1_Στοιχεία_Μελέτης_&_Ποσότητες'!C79,"0.000000") & " m³/m) @ 500.00 €/m³"
A34: B.12 | B34: ='1_Στοιχεία_Μελέτης_&_Ποσότητες'!B111 | C34: ='1_Στοιχεία_Μελέτης_&_Ποσότητες'!C111 | D34: ='1_Στοιχεία_Μελέτης_&_Ποσότητες'!D111 | E34: 2.28 | F34: =ROUND(C34*E34, 2) | H34: ="Φύλλο 1 (B.12): " & ('1_Στοιχεία_Μελέτης_&_Ποσότητες'!C47*2) & " αγκυρώσεις " & '1_Στοιχεία_Μελέτης_&_Ποσότητες'!C53 & "-strands (Σειρά 1 L=" & '1_Στοιχεία_Μελέτης_&_Ποσότητες'!C52 & "m & Σειρά 2 L=" & '1_Στοιχεία_Μελέτης_&_Ποσότητες'!C54 & "m, +" & TEXT('1_Στοιχεία_Μελέτης_&_Ποσότητες'!C28,"0.0") & "m) @ 2.28 €/m"
A35: B.13 | B35: ='1_Στοιχεία_Μελέτης_&_Ποσότητες'!B112 | C35: ='1_Στοιχεία_Μελέτης_&_Ποσότητες'!C112 | D35: ='1_Στοιχεία_Μελέτης_&_Ποσότητες'!D112 | E35: 2.28 | F35: =ROUND(C35*E35, 2) | H35: ="Φύλλο 1 (B.13): " & ('1_Στοιχεία_Μελέτης_&_Ποσότητες'!C47*2) & " αγκυρώσεις " & '1_Στοιχεία_Μελέτης_&_Ποσότητες'!C57 & "-strands (Σειρά 3 L=" & '1_Στοιχεία_Μελέτης_&_Ποσότητες'!C56 & "m & Σειρά 4 L=" & '1_Στοιχεία_Μελέτης_&_Ποσότητες'!C58 & "m, +" & TEXT('1_Στοιχεία_Μελέτης_&_Ποσότητες'!C28,"0.0") & "m) @ 2.28 €/m"
A36: B.14 | B36: ='1_Στοιχεία_Μελέτης_&_Ποσότητες'!B113 | C36: ='1_Στοιχεία_Μελέτης_&_Ποσότητες'!C113 | D36: ='1_Στοιχεία_Μελέτης_&_Ποσότητες'!D113 | E36: 18 | F36: =ROUND(C36*E36, 2) | H36: ="Φύλλο 1 (B.14): Προένταση (Stressing & Lock-off) " & '1_Στοιχεία_Μελέτης_&_Ποσότητες'!C113 & " αγκυρώσεων Type B @ 18.00 €/No"
A37: B.15 | B37: ='1_Στοιχεία_Μελέτης_&_Ποσότητες'!B114 | C37: ='1_Στοιχεία_Μελέτης_&_Ποσότητες'!C114 | D37: ='1_Στοιχεία_Μελέτης_&_Ποσότητες'!D114 | E37: 55 | F37: =ROUND(C37*E37, 2) | H37: ="Φύλλο 1 (B.15): Πλήρες σετ κεφαλής (Head, Wedges, Plate) " & '1_Στοιχεία_Μελέτης_&_Ποσότητες'!C114 & " αγκυρώσεων Type B @ 55.00 €/No"
A39: TYPE C | B39: ="BERLIN WALL TYPE C: " & '1_Στοιχεία_Μελέτης_&_Ποσότητες'!C62 & "No Ζεύγη HEB200, L=" & TEXT('1_Στοιχεία_Μελέτης_&_Ποσότητες'!C66,"0.00") & "m για βάθος εκσκαφής " & TEXT('1_Στοιχεία_Μελέτης_&_Ποσότητες'!C64,"0.00") & "m και " & TEXT('1_Στοιχεία_Μελέτης_&_Ποσότητες'!C63,"0.00") & " τρ.μ." | C39: ='1_Στοιχεία_Μελέτης_&_Ποσότητες'!C63 | D39: τρ.μ. | E39: =ROUND(F39/C39, 2) | F39: =SUM(F40:F53) | G39: ΤΕΛ. ΣΥΝΟΛΑ | H39: ="Σύνολο Τοίχου Γ (Πυλώνες 2, 3 & 4 — HEB 200, " & '1_Στοιχεία_Μελέτης_&_Ποσότητες'!C62 & " πάσσαλοι, " & '1_Στοιχεία_Μελέτης_&_Ποσότητες'!C129 & " αγκυρώσεις)"
A40: C.1 | B40: ='1_Στοιχεία_Μελέτης_&_Ποσότητες'!B117 | C40: ='1_Στοιχεία_Μελέτης_&_Ποσότητες'!C117 | D40: ='1_Στοιχεία_Μελέτης_&_Ποσότητες'!D117 | E40: 75 | F40: =ROUND(C40*E40, 2) | G40: =F39 | H40: ="Φύλλο 1 (C.1): " & '1_Στοιχεία_Μελέτης_&_Ποσότητες'!C62 & " πάσσαλοι × " & TEXT('1_Στοιχεία_Μελέτης_&_Ποσότητες'!C66,"0.00") & "m @ 75.00 €/m (Ø" & ('1_Στοιχεία_Μελέτης_&_Ποσότητες'!C11*1000) & "mm)"
A41: C.2 | B41: ='1_Στοιχεία_Μελέτης_&_Ποσότητες'!B118 | C41: ='1_Στοιχεία_Μελέτης_&_Ποσότητες'!C118 | D41: ='1_Στοιχεία_Μελέτης_&_Ποσότητες'!D118 | E41: 120 | F41: =ROUND(C41*E41, 2) | H41: ="Φύλλο 1 (C.2): Πάκτωση H=" & TEXT('1_Στοιχεία_Μελέτης_&_Ποσότητες'!C65,"0.00") & "m σε Ø" & ('1_Στοιχεία_Μελέτης_&_Ποσότητες'!C11*1000) & "mm @ 120.00 €/m³ [Πορτοκαλί #FFE699]"
A42: C.3 | B42: ='1_Στοιχεία_Μελέτης_&_Ποσότητες'!B119 | C42: ='1_Στοιχεία_Μελέτης_&_Ποσότητες'!C119 | D42: ='1_Στοιχεία_Μελέτης_&_Ποσότητες'!D119 | E42: 1.4 | F42: =ROUND(C42*E42, 2) | H42: ="Φύλλο 1 (C.3): " & '1_Στοιχεία_Μελέτης_&_Ποσότητες'!C12 & " No. HEB 200 (" & TEXT('1_Στοιχεία_Μελέτης_&_Ποσότητες'!C14*'1_Στοιχεία_Μελέτης_&_Ποσότητες'!C12,"0.0") & " kg/m) @ 1.40 €/kg (1.00€ αγορά + 0.40€ επεξεργασία)"
A43: C.4 | B43: ='1_Στοιχεία_Μελέτης_&_Ποσότητες'!B120 | C43: ='1_Στοιχεία_Μελέτης_&_Ποσότητες'!C120 | D43: ='1_Στοιχεία_Μελέτης_&_Ποσότητες'!D120 | E43: 1.6 | F43: =ROUND(C43*E43, 2) | H43: ="Φύλλο 1 (C.4): Λάμες " & '1_Στοιχεία_Μελέτης_&_Ποσότητες'!C16 & "x" & '1_Στοιχεία_Μελέτης_&_Ποσότητες'!C17 & "x" & '1_Στοιχεία_Μελέτης_&_Ποσότητες'!C18 & "mm (" & ('1_Στοιχεία_Μελέτης_&_Ποσότητες'!C66/'1_Στοιχεία_Μελέτης_&_Ποσότητες'!C15) & " λάμες/οπή = " & ('1_Στοιχεία_Μελέτης_&_Ποσότητες'!C62*('1_Στοιχεία_Μελέτης_&_Ποσότητες'!C66/'1_Στοιχεία_Μελέτης_&_Ποσότητες'!C15)) & " τεμ.) @ 1.60 €/kg"
...

Sheet 3_Πίνακες_Διατομών_Χάλυβα
A1: ΒΙΒΛΙΟΘΗΚΗ ΔΙΑΤΟΜΩΝ ΧΑΛΥΒΑ (EUROPEAN STRUCTURAL STEEL PROFILES)
A2: Τεχνικά χαρακτηριστικά & βάρη ανά μέτρο για διατομές HEA, HEB, UPN & Γωνιών (L)
A4: 1. ΔΙΑΤΟΜΕΣ HEA (Ευρωπαϊκά Πλατύπελμα Ελαφρού Τύπου)
A5: Ονομασία Διατομής | B5: Ύψος h (mm) | C5: Πλάτος b (mm) | D5: Πάχος tw (mm) | E5: Πάχος tf (mm) | F5: Διατομή A (cm²) | G5: Βάρος (kg / m)
A6: HEA 140 | B6: 133 | C6: 140 | D6: 5.5 | E6: 8.5 | F6: 31.4 | G6: 24.7
A7: HEA 160 | B7: 152 | C7: 160 | D7: 6 | E7: 9 | F7: 38.8 | G7: 30.4
A8: HEA 180 | B8: 171 | C8: 180 | D8: 6 | E8: 9.5 | F8: 45.3 | G8: 35.5
A9: HEA 200 | B9: 190 | C9: 200 | D9: 6.5 | E9: 10 | F9: 53.8 | G9: 42.3
A10: HEA 220 | B10: 210 | C10: 220 | D10: 7 | E10: 11 | F10: 64.3 | G10: 50.5
A11: HEA 240 | B11: 230 | C11: 240 | D11: 7.5 | E11: 12 | F11: 76.8 | G11: 60.3
A12: HEA 260 | B12: 250 | C12: 260 | D12: 7.5 | E12: 12.5 | F12: 86.8 | G12: 68.2
A13: HEA 280 | B13: 270 | C13: 280 | D13: 8 | E13: 13 | F13: 97.3 | G13: 76.4
A14: HEA 300 | B14: 290 | C14: 300 | D14: 8.5 | E14: 14 | F14: 112.5 | G14: 88.3
A16: 2. ΔΙΑΤΟΜΕΣ HEB (Ευρωπαϊκά Πλατύπελμα Κανονικού Τύπου)
A17: Ονομασία Διατομής | B17: Ύψος h (mm) | C17: Πλάτος b (mm) | D17: Πάχος tw (mm) | E17: Πάχος tf (mm) | F17: Διατομή A (cm²) | G17: Βάρος (kg / m)
A18: HEB 140 | B18: 140 | C18: 140 | D18: 7 | E18: 12 | F18: 43 | G18: 33.7
A19: HEB 160 | B19: 160 | C19: 160 | D19: 8 | E19: 13 | F19: 54.3 | G19: 42.6
A20: HEB 180 | B20: 180 | C20: 180 | D20: 8.5 | E20: 14 | F20: 65.3 | G20: 51.2
A21: HEB 200 | B21: 200 | C21: 200 | D21: 9 | E21: 15 | F21: 78.1 | G21: 61.3
A22: HEB 220 | B22: 220 | C22: 220 | D22: 9.5 | E22: 16 | F22: 91 | G22: 71.5
A23: HEB 240 | B23: 240 | C23: 240 | D23: 10 | E23: 17 | F23: 106 | G23: 83.2
A24: HEB 260 | B24: 260 | C24: 260 | D24: 10 | E24: 17.5 | F24: 118.4 | G24: 93
A25: HEB 280 | B25: 280 | C25: 280 | D25: 10.5 | E25: 18 | F25: 131.4 | G25: 103
A26: HEB 300 | B26: 300 | C26: 300 | D26: 11 | E26: 19 | F26: 149.1 | G26: 117
A28: 3. ΔΙΑΤΟΜΕΣ UPN (Ευρωπαϊκά Κοίλα Προφίλ U)
A29: Ονομασία Διατομής | B29: Ύψος h (mm) | C29: Πλάτος b (mm) | D29: Πάχος tw (mm) | E29: Πάχος tf (mm) | F29: Διατομή A (cm²) | G29: Βάρος (kg / m)
A30: UPN 140 | B30: 140 | C30: 60 | D30: 7 | E30: 10 | F30: 20.4 | G30: 16
A31: UPN 160 | B31: 160 | C31: 65 | D31: 7.5 | E31: 10.5 | F31: 24 | G31: 18.8
A32: UPN 180 | B32: 180 | C32: 70 | D32: 8 | E32: 11 | F32: 28 | G32: 22
A33: UPN 200 | B33: 200 | C33: 75 | D33: 8.5 | E33: 11.5 | F33: 32.2 | G33: 25.3
A34: UPN 220 | B34: 220 | C34: 80 | D34: 9 | E34: 12.5 | F34: 37.4 | G34: 29.4
A35: UPN 240 | B35: 240 | C35: 85 | D35: 9.5 | E35: 13 | F35: 42.3 | G35: 33.2
A36: UPN 260 | B36: 260 | C36: 90 | D36: 10 | E36: 14 | F36: 48.3 | G36: 37.9
A37: UPN 280 | B37: 280 | C37: 95 | D37: 10 | E37: 15 | F37: 53.3 | G37: 41.8
A38: UPN 300 | B38: 300 | C38: 100 | D38: 10 | E38: 16 | F38: 58.8 | G38: 46.2
A40: 4. ΙΣΟΣΚΕΛΕΙΣ ΓΩΝΙΕΣ (Equal Angles L)
A41: Ονομασία Διατομής | B41: Ύψος h (mm) | C41: Πλάτος b (mm) | D41: Πάχος tw (mm) | E41: Πάχος tf (mm) | F41: Διατομή A (cm²) | G41: Βάρος (kg / m)
A42: L 50x50x5 | B42: 50 | C42: 50 | D42: 5 | E42: 5 | F42: 4.8 | G42: 3.77
A43: L 60x60x6 | B43: 60 | C43: 60 | D43: 6 | E43: 6 | F43: 6.91 | G43: 5.42
A44: L 70x70x6 | B44: 70 | C44: 70 | D44: 6 | E44: 6 | F44: 8.13 | G44: 6.38
...
