Workbook

Sheet 1_Στοιχεία_Μελέτης_&_Ποσότητες
A1: ΕΡΓΟ: BOLTON TOWER (BERLIN WALL & ΑΓΚΥΡΩΣΕΙΣ) — ΣΤΟΙΧΕΙΑ ΜΕΛΕΤΗΣ & ΦΥΣΙΚΕΣ ΠΟΣΟΤΗΤΕΣ ΑΝΑ ΤΥΠΟ ΤΟΙΧΟΥ (ΧΩΡΙΣ ΕΥΡΩ)
A2: ΟΡΓΑΝΩΜΕΝΟ ΣΕ ΚΟΥΤΙΑ (BOXES) ΑΝΑ ΤΥΠΟ ΤΟΙΧΟΥ (TYPE A, TYPE B, TYPE C) ΓΙΑ ΑΜΕΣΟ ΕΛΕΓΧΟ | [ΚΕΦΑΛΑΙΟ Α] = RAW INPUTS | [ΚΕΦΑΛΑΙΟ Β] = ΥΠΟΛΟΓΙΣΜΟΙ
A4: 🏛️ ΚΕΦΑΛΑΙΟ Α: ΣΤΟΙΧΕΙΑ ΜΕΛΕΤΗΣ (RAW INPUTS) — ΧΩΡΙΣΜΕΝΑ ΣΕ ΚΟΥΤΙΑ ΑΝΑ ΤΥΠΟ ΤΟΙΧΟΥ
A5: α/α | B5: ΠΕΡΙΓΡΑΦΗ ΣΤΟΙΧΕΙΟΥ / ΕΡΓΑΣΙΑΣ | C5: ΤΙΜΗ ΜΕΛΕΤΗΣ | D5: ΜΟΝ. | E5: ΠΗΓΗ ΜΕΛΕΤΗΣ (ΣΧΕΔΙΟ) | F5: ΤΕΧΝΙΚΗ ΣΗΜΕΙΩΣΗ / ΕΛΕΓΧΟΣ ΚΑΝΟΝΑ
A6: ΚΟΙΝΑ | B6: ΚΟΥΤΙ Α.0 — ΓΕΝΙΚΑ ΣΤΟΙΧΕΙΑ ΕΡΓΟΥ & ΚΟΙΝΕΣ ΠΡΟΔΙΑΓΡΑΦΕΣ (Εργοτάξιο, Διάτρηση, Σχάρα, Shotcrete, Λάμες, Γωνιές, Αγκυρώσεις)
A7: Κ.1 | B7: Έδρα Εταιρείας (Αφετηρία) | C7: Άγιος Συλάς, Σπύρου Κυπριανού 32, Λεμεσός | D7: - | E7: Βάση Εταιρείας | F7: Σταθερή βάση εκκίνησης συνεργείων & μηχανημάτων
A8: Κ.2 | B8: Τοποθεσία Εργοταξίου & Χιλιομετρική Απόσταση | C8: 12 | D8: km | E8: Σχέδιο ΘΕΜ/1 & ΘΕΜ/6 | F8: Λεμεσός (Bolton Tower) — Ζώνη 0-40 km (βασικές τιμές μετακινήσεων)
A9: Κ.3 | B9: Μέγιστο Πλήθος Οριζόντιων Σειρών Αγκυρώσεων Έργου | C9: 4 | D9: σειρές | E9: Σχέδιο ΘΕΜ/6, Τομές A, B, Γ | F9: Type A & B: 4 σειρές αγκυρώσεων | Type C: 3 σειρές αγκυρώσεων
A10: Κ.4 | B10: Αξονική Απόσταση Πασσάλων (s_c/c) | C10: 1.5 | D10: m | E10: Σχέδιο ΘΕΜ/1 & ΘΕΜ/6 | F10: [!!! ΣΥΓΚΡΟΥΣΗ ΜΕΛΕΤΗΣ !!!]: Αναγράφονται 2 διαφορετικοί αριθμοί: @ 2000mm στο κείμενο λεπτομέρειας vs (1500) στη διάσταση CL και 1.50m στις τομές. Επιλέχθηκε ο πιο ασφαλής στατικά αριθμός s = 1.50 m.
A11: Κ.5 | B11: Διάμετρος Οπής Διάτρησης Μεγάλου Τρυπανιού (D) | C11: 0.8 | D11: m | E11: Κανόνας Εταιρείας | F11: [DEFAULT ΕΤΑΙΡΕΙΑΣ]: Δεν αναγράφεται διάμετρος νέφκας στη μελέτη (το D=800 στο ΘΕΜ/1 αφορά υποστυλώματα κτιρίου). Εφαρμόζεται by default Ø800 mm.
A12: Κ.6 | B12: Πλήθος Προφίλ Χάλυβα ανά Πάσσαλο / Οπή | C12: 2 | D12: No/οπή | E12: Σχέδιο ΘΕΜ/6, Λεπτομέρεια | F12: Δίδυμο προφίλ (Ζεύγος 2 No. HEB ανά πάσσαλο)
A13: Κ.7 | B13: Θεωρητικό Βάρος Διατομής HEB 220 (για Type A) | C13: 71.5 | D13: kg/m | E13: Βιβλιοθήκη Διατομών (Φύλλο 3) | F13: 71.5 kg/m ανά HEB 220 (143.0 kg/m ανά ζεύγος)
A14: Κ.8 | B14: Θεωρητικό Βάρος Διατομής HEB 200 (για Type B & Type C) | C14: 61.3 | D14: kg/m | E14: Βιβλιοθήκη Διατομών (Φύλλο 3) | F14: 61.3 kg/m ανά HEB 200 (122.6 kg/m ανά ζεύγος)
A15: Κ.9 | B15: Κατακόρυφο Βήμα Λαμών Σύνδεσης (s_plate) | C15: 1 | D15: m | E15: Σχέδιο ΘΕΜ/6, Λεπτομέρεια | F15: Λάμες 200x200x10mm ανά 1000mm (1.0m) καθ' ύψος (Κανόνας L_beam / s_plate)
A16: Κ.10 | B16: Πλάτος / Μήκος / Πάχος Λάμας Σύνδεσης (200x200x10 mm) | C16: 3.14 | D16: kg/τεμ | E16: Σχέδιο ΘΕΜ/6, Λεπτομέρεια | F16: 0.20m × 0.20m × 0.010m × 7,850 kg/m³ = 3.140 kg ανά λάμα | G16: C16 πρεπει μεσα να εχει τον τυπο όχι το αποτελεσμα και αν αλλαζω οτιδιποτε εγω μεσα στον τυπο να αλλαζει και στην επεξηγηση και στον τιτλο π.χ αλλαξα ξερωγω το μεγεθος τις λαμας εδώ θα αλλαξει και στις σημειωσεις και στο αποτελεσμα και στον τιτλο
A17: Κ.11 | B17: Γωνιές Στήριξης Σχάρας L 70x70x6mm (2 τεμ. ανά πάσσαλο) | C17: 6.38 | D17: kg/m | E17: Σχέδιο ΘΕΜ/6 & Φύλλο 3 | F17: Γωνιές 70x70x6mm (6.38 kg/m × 2 γωνιές καθ' ύψος εκσκαφής H_exc)
A18: Κ.12 | B18: Διάμετρος Ράβδων Σχάρας Οριζόντιων & Κατακόρυφων (#Y8/150) | C18: 8 | D18: mm | E18: Σχέδιο ΘΕΜ/6, Λεπτομέρεια | F18: Αναγράφεται ρητά #Y8/150 (αυστηρή τήρηση Y8 βάσει κανόνα 2.3)
A19: Κ.13 | B19: Βήμα Ράβδων Σχάρας Οριζόντιων & Κατακόρυφων (s_mesh) | C19: 150 | D19: mm | E19: Σχέδιο ΘΕΜ/6, Λεπτομέρεια | F19: Βήμα 150mm × 150mm (2 × 6.67 m/m² × 0.395 kg/m = 5.261 kg/m²)
A20: Κ.14 | B20: Κατηγορία Σκυροδέματος Shotcrete & Πάκτωσης | C20: C30/37 | D20: - | E20: Κανόνας Εταιρείας | F20: [DEFAULT ΕΤΑΙΡΕΙΑΣ]: Δεν αναγράφεται στη μελέτη. Εφαρμόζεται by default C30/37 βάσει κανόνα εταιρείας.
A21: Κ.15 | B21: Ονομαστικό Πάχος Shotcrete Μελέτης (Gunite) | C21: 0.15 | D21: m | E21: Σχέδιο ΘΕΜ/6, Λεπτομέρεια | F21: 150 mm (15 cm) εκτοξευόμενο σκυρόδεμα (gunite)
A22: Κ.16 | B22: Πάγια Απώλεια / Αναπήδηση Shotcrete Εταιρείας | C22: 0.05 | D22: m | E22: Κανόνας Εταιρείας | F22: +5 cm πάγια προσαύξηση εταιρείας (+33.3% επί του ονομαστικού πάχους)
A23: Κ.17 | B23: Διάμετρος Οπής Διάτρησης Αγκυρώσεων (D_anc) | C23: 0.12 | D23: m | E23: Κανόνας Εταιρείας | F23: Ø120 mm τυπική διάμετρος διάτρησης αγκυρίων
A24: Κ.18 | B24: Συντελεστής Απώλειας Grout Αγκυρώσεων | C24: 1.2 | D24: - | E24: Κανόνας Εταιρείας | F24: +20% προσαύξηση όγκου τσιμεντενέματος (0.013572 m³/m)
A25: Κ.19 | B25: Πρόσθετο Μήκος Τένοντα εκτός Μετώπου (για τάνυση/κεφαλή) | C25: 1 | D25: m | E25: Κανόνας Εταιρείας | F25: +1.00 m έξω από το μέτωπο σε κάθε τένοντα
A26: Κ.20 | B26: Τυπικό Βάρος Τένοντα Προέντασης 0.6" (15.2mm) | C26: 1.1 | D26: kg/m | E26: Κανόνας Εταιρείας | F26: 7-wire strand 0.6" (1670/1860 MPa) = 1.10 kg/m
A28: TYPE A | B28: ΚΟΥΤΙ ΣΤΟΙΧΕΙΩΝ ΜΕΛΕΤΗΣ TYPE A — ΤΟΙΧΟΣ ΑΝΤΙΣΤΗΡΙΞΗΣ Α (Εκσκαφή 17.00m, 24No Ζεύγη HEB 220, L=19.00m, 4 Σειρές Αγκυρώσεων)
A29: A.in.1 | B29: Πλήθος Πασσάλων / Ζευγών HEB 220 (Type A) | C29: 27 | D29: No | E29: Σχέδιο ΘΕΜ/1 (Κάτοψη) & OpenCV | F29: 24 πάσσαλοι (Ανατολικό & Νότιο τμήμα Τοίχου Α) | G29: αλλαξα σε 27 εχω στα rules/agent το πως πρεπει να μετρας τις αγκυρωσεις αν δεν σου δινετε ο αριθμο, γιατι δεν το εκανες ετσι? Η το εκανες και βγηκε λαθος διοτι επρεπε ναταν 27
A30: A.in.2 | B30: Αναπτυγμένο Μήκος Μετώπου Type A (24 × 1.50m) | C30: =C29*C10 -> 40.5 | D30: τρ.μ. | E30: Σχέδιο ΘΕΜ/1 (Intervals) | F30: ="=" & C29 & " πάσσαλοι × " & TEXT(C10,"0.00") & "m = " & TEXT(C29*C10,"0.00") & " τρ.μ." -> =27 πάσσαλοι × 1.50m = 40.50 τρ.μ. | G30: δεν αλλαζει στον τιτλο μονο στις σημειωσεις όμως (δλδ το εκανα 27 αποπανω και στον τιτλο λεει 24*1.5
A31: A.in.3 | B31: Ελεύθερο Ύψος Εκσκαφής Type A (H_exc_A) | C31: 17 | D31: m | E31: Σχέδιο ΘΕΜ/6, Τομή Τοίχου Α | F31: Αναγραφόμενο ύψος εκσκαφής 17000 mm (17.00 m)
A32: A.in.4 | B32: Βάθος Πάκτωσης Νέφκας Type A (H_embed_A) | C32: 1.5 | D32: m | E32: Σχέδιο ΘΕΜ/6, Τομή Τοίχου Α | F32: Αναγραφόμενο βάθος πάκτωσης 2000 mm (2.00 m) | G32: 1500 λεει εινι και στα 3 ηδη λαθος εδώ
A33: A.in.5 | B33: Συνολικό Μήκος Νέφκας / Διάτρησης Type A (L_beam_A) | C33: =C31+C32 -> 18.5 | D33: m | E33: Σχέδιο ΘΕΜ/6, Τομή Τοίχου Α | F33: Αναγραφόμενο μήκος 19000 mm (17.00m + 2.00m = 19.00m) | G33: η πακτωση δεν είναι υποχρεωτικα ολο οσο δεν είναι ελευθερο. Η πακτωση είναι 1.5 π.χ το χωμα παει 2 μετρα και ελευθερο 15 μετρα….
A34: A.in.6 | B34: Αγκύρωση Σειρά 1 (στο -1.50m): Μήκος Διάτρησης L1 | C34: 20 | D34: m | E34: Σχέδιο ΘΕΜ/6, Τομή Τοίχου Α | F34: 10.0m ελεύθερο + 10.0m πάκτωση grout = 20.00m (30°, 144 kN)
A35: A.in.7 | B35: Αγκύρωση Σειρά 1 (στο -1.50m): Καλώδια (Strands) | C35: 2 | D35: καλώδια | E35: Σχέδιο ΘΕΜ/6, Τομή Τοίχου Α | F35: Αναγράφεται: 2 ΚΑΛΩΔΙΑ 15.2mm (Type 1670/1860)
A36: A.in.8 | B36: Αγκύρωση Σειρά 2 (στο -5.50m): Μήκος Διάτρησης L2 | C36: 19.5 | D36: m | E36: Σχέδιο ΘΕΜ/6, Τομή Τοίχου Α | F36: 8.5m ελεύθερο + 11.0m πάκτωση grout = 19.50m (30°, 338 kN)
A37: A.in.9 | B37: Αγκύρωση Σειρά 2 (στο -5.50m): Καλώδια (Strands) | C37: 2 | D37: καλώδια | E37: Σχέδιο ΘΕΜ/6, Τομή Τοίχου Α | F37: Αναγράφεται: 2 ΚΑΛΩΔΙΑ 15.2mm (Type 1670/1860)
A38: A.in.10 | B38: Αγκύρωση Σειρά 3 (στο -9.00m): Μήκος Διάτρησης L3 | C38: 20 | D38: m | E38: Σχέδιο ΘΕΜ/6, Τομή Τοίχου Α | F38: 8.0m ελεύθερο + 12.0m πάκτωση grout = 20.00m (30°, 439 kN)
A39: A.in.11 | B39: Αγκύρωση Σειρά 3 (στο -9.00m): Καλώδια (Strands) | C39: 3 | D39: καλώδια | E39: Σχέδιο ΘΕΜ/6, Τομή Τοίχου Α | F39: Αναγράφεται: 3 ΚΑΛΩΔΙΑ 15.2mm (Type 1670/1860)
A40: A.in.12 | B40: Αγκύρωση Σειρά 4 (στο -13.00m): Μήκος Διάτρησης L4 | C40: 18.5 | D40: m | E40: Σχέδιο ΘΕΜ/6, Τομή Τοίχου Α | F40: 3.5m ελεύθερο + 15.0m πάκτωση grout = 18.50m (30°, 584 kN)
A41: A.in.13 | B41: Αγκύρωση Σειρά 4 (στο -13.00m): Καλώδια (Strands) | C41: 3 | D41: καλώδια | E41: Σχέδιο ΘΕΜ/6, Τομή Τοίχου Α | F41: Αναγράφεται: 3 ΚΑΛΩΔΙΑ 15.2mm (Type 1670/1860)
A43: TYPE B | B43: ΚΟΥΤΙ ΣΤΟΙΧΕΙΩΝ ΜΕΛΕΤΗΣ TYPE B — ΤΟΙΧΟΣ ΑΝΤΙΣΤΗΡΙΞΗΣ Β (Εκσκαφή 15.60m, 63No Ζεύγη HEB 200, L=17.00m, 4 Σειρές Αγκυρώσεων)
...

Sheet 2_Υπολογισμοί_&_Κοστολόγηση
A1: ΕΡΓΟ: BOLTON TOWER (BERLIN WALL & ΑΓΚΥΡΩΣΕΙΣ) — ΟΙΚΟΝΟΜΙΚΗ ΠΡΟΣΦΟΡΑ ΑΝΑ ΤΥΠΟ ΤΟΙΧΟΥ (TYPE A, TYPE B, TYPE C)
A2: ΔΟΜΗ ΠΙΝΑΚΩΝ ΑΝΑ ΤΥΠΟ BERLIN WALL (BOX LAYOUT) | [ΚΙΤΡΙΝΟ #FFF2CC] = Τιμές Μονάδας Εταιρείας | [ΠΟΡΤΟΚΑΛΙ #FFE699] = Κουγκρί Πάκτωσης 120€
A4: α/α | B4: ΠΕΡΙΓΡΑΦΗ ΕΡΓΑΣΙΩΝ | C4: ΠΟΣΟΤΗΤΑ | D4: ΜΟΝ. | E4: ΤΙΜΗ (€) | F4: ΣΥΝΟΛΟ (€) | G4: ΤΕΛΙΚΟ ΠΟΣΟ (€) | H4: ΠΗΓΗ ΠΟΣΟΤΗΤΑΣ / ΤΕΧΝΙΚΟΣ ΚΑΝΟΝΑΣ & ΣΗΜΕΙΩΣΕΙΣ
A5: TYPE A | B5: ="BERLIN WALL TYPE A: " & '1_Στοιχεία_Μελέτης_&_Ποσότητες'!C29 & "No Ζεύγη HEB220, L=" & TEXT('1_Στοιχεία_Μελέτης_&_Ποσότητες'!C33,"0.00") & "m για βάθος εκσκαφής " & TEXT('1_Στοιχεία_Μελέτης_&_Ποσότητες'!C31,"0.00") & "m και " & TEXT('1_Στοιχεία_Μελέτης_&_Ποσότητες'!C30,"0.00") & " τρ.μ." -> BERLIN WALL TYPE A: 27No Ζεύγη HEB220, L=18.50m για βάθος εκσκαφής 17.00m και 40.50 τρ.μ. | C5: ='1_Στοιχεία_Μελέτης_&_Ποσότητες'!C30 -> 40.5 | D5: τρ.μ. | E5: =ROUND(F5/C5, 2) -> 7324.78 | F5: =SUM(F6:F20) -> 296653.73 | G5: ΤΕΛ. ΣΥΝΟΛΑ | H5: Σύνολο Τοίχου Α (Πυλώνες 2, 3 & 4 — HEB 220, 24 πάσσαλοι, 96 αγκυρώσεις)
A6: A.1 | B6: ='1_Στοιχεία_Μελέτης_&_Ποσότητες'!B80 -> ΤΡΥΠΗΜΑ Ø800mm = 27No X 18.50m | C6: ='1_Στοιχεία_Μελέτης_&_Ποσότητες'!C80 -> 499.5 | D6: ='1_Στοιχεία_Μελέτης_&_Ποσότητες'!D80 -> m | E6: 75 | F6: =ROUND(C6*E6, 2) -> 37462.5 | G6: =F5 -> 296653.73 | H6: ="Φύλλο 1 (A.1): " & '1_Στοιχεία_Μελέτης_&_Ποσότητες'!C29 & " πάσσαλοι × " & TEXT('1_Στοιχεία_Μελέτης_&_Ποσότητες'!C33,"0.00") & "m @ 75.00 €/m (Ø800mm Default Εταιρείας)" -> Φύλλο 1 (A.1): 27 πάσσαλοι × 18.50m @ 75.00 €/m (Ø800mm Default Εταιρείας)
A7: A.2 | B7: ='1_Στοιχεία_Μελέτης_&_Ποσότητες'!B81 -> ΜΠΕΤΟΝ ΠΑΚΤΩΣΗΣ C30/37 = 27No X 1.50m X 0.503m³/m | C7: ='1_Στοιχεία_Μελέτης_&_Ποσότητες'!C81 -> 20.36 | D7: ='1_Στοιχεία_Μελέτης_&_Ποσότητες'!D81 -> m³ | E7: 120 | F7: =ROUND(C7*E7, 2) -> 2443.2 | H7: ="Φύλλο 1 (A.2): Πάκτωση H=2.00m σε Ø800mm @ 120.00 €/m³ [Πορτοκαλί #FFE699]" -> Φύλλο 1 (A.2): Πάκτωση H=2.00m σε Ø800mm @ 120.00 €/m³ [Πορτοκαλί #FFE699]
A8: A.3 | B8: ='1_Στοιχεία_Μελέτης_&_Ποσότητες'!B82 -> HEB220 - ΠΡΟΜΗΘΕΙΑ, ΕΠΕΞΕΡΓΑΣΙΑ & ΤΟΠΟΘΕΤΗΣΗ (27No x 2No x 18.50m x 71.5kg/m) | C8: ='1_Στοιχεία_Μελέτης_&_Ποσότητες'!C82 -> 71428.5 | D8: ='1_Στοιχεία_Μελέτης_&_Ποσότητες'!D82 -> kg | E8: 1.4 | F8: =ROUND(C8*E8, 2) -> 99999.9 | H8: ="Φύλλο 1 (A.3): 2 No. HEB 220 (143.0 kg/m) @ 1.40 €/kg (1.00€ αγορά + 0.40€ επεξεργασία)" -> Φύλλο 1 (A.3): 2 No. HEB 220 (143.0 kg/m) @ 1.40 €/kg (1.00€ αγορά + 0.40€ επεξεργασία)
A9: A.4 | B9: ='1_Στοιχεία_Μελέτης_&_Ποσότητες'!B83 -> ΛΑΜΕΣ ΣΥΝΔΕΣΗΣ 200x200x10mm = 27No x (18.5No x 3.14kg) | C9: ='1_Στοιχεία_Μελέτης_&_Ποσότητες'!C83 -> 1568.43 | D9: ='1_Στοιχεία_Μελέτης_&_Ποσότητες'!D83 -> kg | E9: 1.6 | F9: =ROUND(C9*E9, 2) -> 2509.49 | H9: ="Φύλλο 1 (A.4): Κανόνας L_beam/s_plate = 19 λάμες/οπή (456 τεμ.) @ 1.60 €/kg" -> Φύλλο 1 (A.4): Κανόνας L_beam/s_plate = 19 λάμες/οπή (456 τεμ.) @ 1.60 €/kg
A10: A.5 | B10: ='1_Στοιχεία_Μελέτης_&_Ποσότητες'!B84 -> ΓΩΝΙΕΣ ΣΤΗΡΙΞΗΣ L70x70x6mm = 27No x 17.00m x 6.38kg/m x 2No | C10: ='1_Στοιχεία_Μελέτης_&_Ποσότητες'!C84 -> 5856.84 | D10: ='1_Στοιχεία_Μελέτης_&_Ποσότητες'!D84 -> kg | E10: 1.6 | F10: =ROUND(C10*E10, 2) -> 9370.94 | H10: ="Φύλλο 1 (A.5): 2 γωνιές L70x70x6 × 17.00m (816.0m) @ 1.60 €/kg" -> Φύλλο 1 (A.5): 2 γωνιές L70x70x6 × 17.00m (816.0m) @ 1.60 €/kg
A11: A.6 | B11: ='1_Στοιχεία_Μελέτης_&_Ποσότητες'!B85 -> ΑΓΟΡΑ ΧΑΛΥΒΑ ΣΧΑΡΑΣ #Y8/150 = 688.50m² x 5.261kg/m² | C11: ='1_Στοιχεία_Μελέτης_&_Ποσότητες'!C85 -> 3622.2 | D11: ='1_Στοιχεία_Μελέτης_&_Ποσότητες'!D85 -> kg | E11: 2.5 | F11: =ROUND(C11*E11, 2) -> 9055.5 | H11: ="Φύλλο 1 (A.6): Σχάρα #Y8/150 (" & TEXT('1_Στοιχεία_Μελέτης_&_Ποσότητες'!C75,"0.000") & " kg/m²) @ 2.50 €/kg αγορά" -> Φύλλο 1 (A.6): Σχάρα #Y8/150 (5.261 kg/m²) @ 2.50 €/kg αγορά
A12: A.7 | B12: ='1_Στοιχεία_Μελέτης_&_Ποσότητες'!B86 -> ΤΟΠΟΘΕΤΗΣΗ ΣΧΑΡΑΣ ΜΕΤΩΠΟΥ = 40.50m X 17.00m | C12: ='1_Στοιχεία_Μελέτης_&_Ποσότητες'!C86 -> 688.5 | D12: ='1_Στοιχεία_Μελέτης_&_Ποσότητες'!D86 -> m² | E12: 15 | F12: =ROUND(C12*E12, 2) -> 10327.5 | H12: ="Φύλλο 1 (A.7): Εργατικά τοποθέτησης σχάρας μετώπου (36.0m × 17.0m) @ 15.00 €/m²" -> Φύλλο 1 (A.7): Εργατικά τοποθέτησης σχάρας μετώπου (36.0m × 17.0m) @ 15.00 €/m²
A13: A.8 | B13: ='1_Στοιχεία_Μελέτης_&_Ποσότητες'!B87 -> ΑΓΟΡΑ ΣΚΥΡΟΔΕΜΑΤΟΣ SHOTCRETE C30/37 = 688.50m² x 0.15m | C13: ='1_Στοιχεία_Μελέτης_&_Ποσότητες'!C87 -> 103.28 | D13: ='1_Στοιχεία_Μελέτης_&_Ποσότητες'!D87 -> m³ | E13: 90 | F13: =ROUND(C13*E13, 2) -> 9295.2 | H13: ="Φύλλο 1 (A.8): Αγορά C30/37 ονομαστικού πάχους 15cm @ 90.00 €/m³" -> Φύλλο 1 (A.8): Αγορά C30/37 ονομαστικού πάχους 15cm @ 90.00 €/m³
A14: A.9 | B14: ='1_Στοιχεία_Μελέτης_&_Ποσότητες'!B88 -> ΤΟΠΟΘΕΤΗΣΗ / ΕΚΤΟΞΕΥΣΗ SHOTCRETE = 688.50m² x 0.15m (με απώλεια +33.3%) | C14: ='1_Στοιχεία_Μελέτης_&_Ποσότητες'!C88 -> 103.28 | D14: ='1_Στοιχεία_Μελέτης_&_Ποσότητες'!D88 -> m³ | E14: =ROUND((200*(1+'1_Στοιχεία_Μελέτης_&_Ποσότητες'!C77))-90, 2) -> 176.67 | F14: =ROUND(C14*E14, 2) -> 18246.48 | H14: ="Φύλλο 1 (A.9): Εκτόξευση/Αντλία = Βάση 200€ × (1+" & TEXT('1_Στοιχεία_Μελέτης_&_Ποσότητες'!C77,"0.0%") & " απώλεια) - 90€ = 176.67 €/m³" -> Φύλλο 1 (A.9): Εκτόξευση/Αντλία = Βάση 200€ × (1+33.3% απώλεια) - 90€ = 176.67 €/m³
A15: A.10 | B15: ='1_Στοιχεία_Μελέτης_&_Ποσότητες'!B89 -> ΔΙΑΤΡΗΣΗ ΑΓΚΥΡΩΣΕΩΝ Ø120mm (4 Σειρές: L1=20m, L2=19.5m, L3=20m, L4=18.5m) | C15: ='1_Στοιχεία_Μελέτης_&_Ποσότητες'!C89 -> 2106 | D15: ='1_Στοιχεία_Μελέτης_&_Ποσότητες'!D89 -> m | E15: 30 | F15: =ROUND(C15*E15, 2) -> 63180 | H15: ="Φύλλο 1 (A.10): Διάτρηση 96 αγκυρώσεων Ø120mm (Σειρές 1-4: 20m, 19.5m, 20m, 18.5m) @ 30.00 €/m" -> Φύλλο 1 (A.10): Διάτρηση 96 αγκυρώσεων Ø120mm (Σειρές 1-4: 20m, 19.5m, 20m, 18.5m) @ 30.00 €/m
A16: A.11 | B16: ='1_Στοιχεία_Μελέτης_&_Ποσότητες'!B90 -> GROUT ΤΣΙΜΕΝΤΕΝΕΜΑ ΑΓΚΥΡΩΣΕΩΝ (με απώλεια 1.20) = 2,106.00m x 0.0136m³/m | C16: ='1_Στοιχεία_Μελέτης_&_Ποσότητες'!C90 -> 28.58 | D16: ='1_Στοιχεία_Μελέτης_&_Ποσότητες'!D90 -> m³ | E16: 500 | F16: =ROUND(C16*E16, 2) -> 14290 | H16: ="Φύλλο 1 (A.11): Grout Ø120mm με απώλεια 1.20 (0.013572 m³/m) @ 500.00 €/m³" -> Φύλλο 1 (A.11): Grout Ø120mm με απώλεια 1.20 (0.013572 m³/m) @ 500.00 €/m³
A17: A.12 | B17: ='1_Στοιχεία_Μελέτης_&_Ποσότητες'!B91 -> 0 | C17: ='1_Στοιχεία_Μελέτης_&_Ποσότητες'!C91 -> 2241 | D17: ='1_Στοιχεία_Μελέτης_&_Ποσότητες'!D91 -> m | E17: 2.28 | F17: =ROUND(C17*E17, 2) -> 5109.48 | H17: ="Φύλλο 1 (A.12): 48 αγκυρώσεις 2-strands (Σειρά 1 L=20m & Σειρά 2 L=19.5m, +1.0m) @ 2.28 €/m" -> Φύλλο 1 (A.12): 48 αγκυρώσεις 2-strands (Σειρά 1 L=20m & Σειρά 2 L=19.5m, +1.0m) @ 2.28 €/m
A18: A.13 | B18: ='1_Στοιχεία_Μελέτης_&_Ποσότητες'!B92 -> 0 | C18: ='1_Στοιχεία_Μελέτης_&_Ποσότητες'!C92 -> 3280.5 | D18: ='1_Στοιχεία_Μελέτης_&_Ποσότητες'!D92 -> m | E18: 2.28 | F18: =ROUND(C18*E18, 2) -> 7479.54 | H18: ="Φύλλο 1 (A.13): 48 αγκυρώσεις 3-strands (Σειρά 3 L=20m & Σειρά 4 L=18.5m, +1.0m) @ 2.28 €/m" -> Φύλλο 1 (A.13): 48 αγκυρώσεις 3-strands (Σειρά 3 L=20m & Σειρά 4 L=18.5m, +1.0m) @ 2.28 €/m
A19: A.14 | B19: ='1_Στοιχεία_Μελέτης_&_Ποσότητες'!B93 -> ΠΡΟΕΝΤΑΣΗ ΑΓΚΥΡΩΣΕΩΝ (STRESSING & LOCK-OFF) = 4 Σειρές X 27No | C19: ='1_Στοιχεία_Μελέτης_&_Ποσότητες'!C93 -> 108 | D19: ='1_Στοιχεία_Μελέτης_&_Ποσότητες'!D93 -> No | E19: 18 | F19: =ROUND(C19*E19, 2) -> 1944 | H19: ="Φύλλο 1 (A.14): Προένταση (Stressing & Lock-off) 96 αγκυρώσεων Type A @ 18.00 €/No" -> Φύλλο 1 (A.14): Προένταση (Stressing & Lock-off) 96 αγκυρώσεων Type A @ 18.00 €/No
A20: A.15 | B20: ='1_Στοιχεία_Μελέτης_&_Ποσότητες'!B94 -> ΚΕΦΑΛΕΣ ΑΓΚΥΡΩΣΗΣ (ANCHOR HEAD, WEDGES, PLATE) = 4 Σειρές X 27No | C20: ='1_Στοιχεία_Μελέτης_&_Ποσότητες'!C94 -> 108 | D20: ='1_Στοιχεία_Μελέτης_&_Ποσότητες'!D94 -> No | E20: 55 | F20: =ROUND(C20*E20, 2) -> 5940 | H20: ="Φύλλο 1 (A.15): Πλήρες σετ κεφαλής (Head, Wedges, Plate) 96 αγκυρώσεων Type A @ 55.00 €/No" -> Φύλλο 1 (A.15): Πλήρες σετ κεφαλής (Head, Wedges, Plate) 96 αγκυρώσεων Type A @ 55.00 €/No
A22: TYPE B | B22: ="BERLIN WALL TYPE B: " & '1_Στοιχεία_Μελέτης_&_Ποσότητες'!C44 & "No Ζεύγη HEB200, L=" & TEXT('1_Στοιχεία_Μελέτης_&_Ποσότητες'!C48,"0.00") & "m για βάθος εκσκαφής " & TEXT('1_Στοιχεία_Μελέτης_&_Ποσότητες'!C46,"0.00") & "m και " & TEXT('1_Στοιχεία_Μελέτης_&_Ποσότητες'!C45,"0.00") & " τρ.μ." -> BERLIN WALL TYPE B: 74No Ζεύγη HEB200, L=17.00m για βάθος εκσκαφής 15.60m και 111.00 τρ.μ. | C22: ='1_Στοιχεία_Μελέτης_&_Ποσότητες'!C45 -> 111 | D22: τρ.μ. | E22: =ROUND(F22/C22, 2) -> 6539.23 | F22: =SUM(F23:F37) -> 725854.84 | G22: ΤΕΛ. ΣΥΝΟΛΑ | H22: Σύνολο Τοίχου Β (Πυλώνες 2, 3 & 4 — HEB 200, 63 πάσσαλοι, 252 αγκυρώσεις)
A23: B.1 | B23: ='1_Στοιχεία_Μελέτης_&_Ποσότητες'!B97 -> ΤΡΥΠΗΜΑ Ø800mm = 74No X 17.00m | C23: ='1_Στοιχεία_Μελέτης_&_Ποσότητες'!C97 -> 1258 | D23: ='1_Στοιχεία_Μελέτης_&_Ποσότητες'!D97 -> m | E23: 75 | F23: =ROUND(C23*E23, 2) -> 94350 | G23: =F22 -> 725854.84 | H23: ="Φύλλο 1 (B.1): " & '1_Στοιχεία_Μελέτης_&_Ποσότητες'!C44 & " πάσσαλοι × " & TEXT('1_Στοιχεία_Μελέτης_&_Ποσότητες'!C48,"0.00") & "m @ 75.00 €/m (Ø800mm Default Εταιρείας)" -> Φύλλο 1 (B.1): 74 πάσσαλοι × 17.00m @ 75.00 €/m (Ø800mm Default Εταιρείας)
A24: B.2 | B24: ='1_Στοιχεία_Μελέτης_&_Ποσότητες'!B98 -> ΜΠΕΤΟΝ ΠΑΚΤΩΣΗΣ C30/37 = 74No X 2.00m X 0.503m³/m | C24: ='1_Στοιχεία_Μελέτης_&_Ποσότητες'!C98 -> 74.39 | D24: ='1_Στοιχεία_Μελέτης_&_Ποσότητες'!D98 -> m³ | E24: 120 | F24: =ROUND(C24*E24, 2) -> 8926.8 | H24: ="Φύλλο 1 (B.2): Πάκτωση H=2.00m σε Ø800mm @ 120.00 €/m³ [Πορτοκαλί #FFE699]" -> Φύλλο 1 (B.2): Πάκτωση H=2.00m σε Ø800mm @ 120.00 €/m³ [Πορτοκαλί #FFE699]
A25: B.3 | B25: ='1_Στοιχεία_Μελέτης_&_Ποσότητες'!B99 -> HEB200 - ΠΡΟΜΗΘΕΙΑ, ΕΠΕΞΕΡΓΑΣΙΑ & ΤΟΠΟΘΕΤΗΣΗ (74No x 2No x 17.00m x 61.3kg/m) | C25: ='1_Στοιχεία_Μελέτης_&_Ποσότητες'!C99 -> 154230.8 | D25: ='1_Στοιχεία_Μελέτης_&_Ποσότητες'!D99 -> kg | E25: 1.4 | F25: =ROUND(C25*E25, 2) -> 215923.12 | H25: ="Φύλλο 1 (B.3): 2 No. HEB 200 (122.6 kg/m) @ 1.40 €/kg (1.00€ αγορά + 0.40€ επεξεργασία)" -> Φύλλο 1 (B.3): 2 No. HEB 200 (122.6 kg/m) @ 1.40 €/kg (1.00€ αγορά + 0.40€ επεξεργασία)
A26: B.4 | B26: ='1_Στοιχεία_Μελέτης_&_Ποσότητες'!B100 -> ΛΑΜΕΣ ΣΥΝΔΕΣΗΣ 200x200x10mm = 74No x (17No x 3.14kg) | C26: ='1_Στοιχεία_Μελέτης_&_Ποσότητες'!C100 -> 3950.12 | D26: ='1_Στοιχεία_Μελέτης_&_Ποσότητες'!D100 -> kg | E26: 1.6 | F26: =ROUND(C26*E26, 2) -> 6320.19 | H26: ="Φύλλο 1 (B.4): Κανόνας L_beam/s_plate = 17 λάμες/οπή (1,071 τεμ.) @ 1.60 €/kg" -> Φύλλο 1 (B.4): Κανόνας L_beam/s_plate = 17 λάμες/οπή (1,071 τεμ.) @ 1.60 €/kg
A27: B.5 | B27: ='1_Στοιχεία_Μελέτης_&_Ποσότητες'!B101 -> ΓΩΝΙΕΣ ΣΤΗΡΙΞΗΣ L70x70x6mm = 74No x 15.60m x 6.38kg/m x 2No | C27: ='1_Στοιχεία_Μελέτης_&_Ποσότητες'!C101 -> 14730.14 | D27: ='1_Στοιχεία_Μελέτης_&_Ποσότητες'!D101 -> kg | E27: 1.6 | F27: =ROUND(C27*E27, 2) -> 23568.22 | H27: ="Φύλλο 1 (B.5): 2 γωνιές L70x70x6 × 15.60m (1,965.6m) @ 1.60 €/kg" -> Φύλλο 1 (B.5): 2 γωνιές L70x70x6 × 15.60m (1,965.6m) @ 1.60 €/kg
A28: B.6 | B28: ='1_Στοιχεία_Μελέτης_&_Ποσότητες'!B102 -> ΑΓΟΡΑ ΧΑΛΥΒΑ ΣΧΑΡΑΣ #Y8/150 = 1,731.60m² x 5.261kg/m² | C28: ='1_Στοιχεία_Μελέτης_&_Ποσότητες'!C102 -> 9109.95 | D28: ='1_Στοιχεία_Μελέτης_&_Ποσότητες'!D102 -> kg | E28: 2.5 | F28: =ROUND(C28*E28, 2) -> 22774.88 | H28: ="Φύλλο 1 (B.6): Σχάρα #Y8/150 (" & TEXT('1_Στοιχεία_Μελέτης_&_Ποσότητες'!C75,"0.000") & " kg/m²) @ 2.50 €/kg αγορά" -> Φύλλο 1 (B.6): Σχάρα #Y8/150 (5.261 kg/m²) @ 2.50 €/kg αγορά
A29: B.7 | B29: ='1_Στοιχεία_Μελέτης_&_Ποσότητες'!B103 -> ΤΟΠΟΘΕΤΗΣΗ ΣΧΑΡΑΣ ΜΕΤΩΠΟΥ = 111.00m X 15.60m | C29: ='1_Στοιχεία_Μελέτης_&_Ποσότητες'!C103 -> 1731.6 | D29: ='1_Στοιχεία_Μελέτης_&_Ποσότητες'!D103 -> m² | E29: 15 | F29: =ROUND(C29*E29, 2) -> 25974 | H29: ="Φύλλο 1 (B.7): Εργατικά τοποθέτησης σχάρας μετώπου (94.5m × 15.6m) @ 15.00 €/m²" -> Φύλλο 1 (B.7): Εργατικά τοποθέτησης σχάρας μετώπου (94.5m × 15.6m) @ 15.00 €/m²
A30: B.8 | B30: ='1_Στοιχεία_Μελέτης_&_Ποσότητες'!B104 -> ΑΓΟΡΑ ΣΚΥΡΟΔΕΜΑΤΟΣ SHOTCRETE C30/37 = 1,731.60m² x 0.15m | C30: ='1_Στοιχεία_Μελέτης_&_Ποσότητες'!C104 -> 259.74 | D30: ='1_Στοιχεία_Μελέτης_&_Ποσότητες'!D104 -> m³ | E30: 90 | F30: =ROUND(C30*E30, 2) -> 23376.6 | H30: ="Φύλλο 1 (B.8): Αγορά C30/37 ονομαστικού πάχους 15cm @ 90.00 €/m³" -> Φύλλο 1 (B.8): Αγορά C30/37 ονομαστικού πάχους 15cm @ 90.00 €/m³
A31: B.9 | B31: ='1_Στοιχεία_Μελέτης_&_Ποσότητες'!B105 -> ΤΟΠΟΘΕΤΗΣΗ / ΕΚΤΟΞΕΥΣΗ SHOTCRETE = 1,731.60m² x 0.15m (με απώλεια +33.3%) | C31: ='1_Στοιχεία_Μελέτης_&_Ποσότητες'!C105 -> 259.74 | D31: ='1_Στοιχεία_Μελέτης_&_Ποσότητες'!D105 -> m³ | E31: =ROUND((200*(1+'1_Στοιχεία_Μελέτης_&_Ποσότητες'!C77))-90, 2) -> 176.67 | F31: =ROUND(C31*E31, 2) -> 45888.27 | H31: ="Φύλλο 1 (B.9): Εκτόξευση/Αντλία = Βάση 200€ × (1+" & TEXT('1_Στοιχεία_Μελέτης_&_Ποσότητες'!C77,"0.0%") & " απώλεια) - 90€ = 176.67 €/m³" -> Φύλλο 1 (B.9): Εκτόξευση/Αντλία = Βάση 200€ × (1+33.3% απώλεια) - 90€ = 176.67 €/m³
A32: B.10 | B32: ='1_Στοιχεία_Μελέτης_&_Ποσότητες'!B106 -> ΔΙΑΤΡΗΣΗ ΑΓΚΥΡΩΣΕΩΝ Ø120mm (4 Σειρές: L1=20m, L2=19.5m, L3=19.5m, L4=16m) | C32: ='1_Στοιχεία_Μελέτης_&_Ποσότητες'!C106 -> 5550 | D32: ='1_Στοιχεία_Μελέτης_&_Ποσότητες'!D106 -> m | E32: 30 | F32: =ROUND(C32*E32, 2) -> 166500 | H32: ="Φύλλο 1 (B.10): Διάτρηση 252 αγκυρώσεων Ø120mm (Σειρές 1-4: 20m, 19.5m, 19.5m, 16m) @ 30.00 €/m" -> Φύλλο 1 (B.10): Διάτρηση 252 αγκυρώσεων Ø120mm (Σειρές 1-4: 20m, 19.5m, 19.5m, 16m) @ 30.00 €/m
A33: B.11 | B33: ='1_Στοιχεία_Μελέτης_&_Ποσότητες'!B107 -> GROUT ΤΣΙΜΕΝΤΕΝΕΜΑ ΑΓΚΥΡΩΣΕΩΝ (με απώλεια 1.20) = 5,550.00m x 0.0136m³/m | C33: ='1_Στοιχεία_Μελέτης_&_Ποσότητες'!C107 -> 75.32 | D33: ='1_Στοιχεία_Μελέτης_&_Ποσότητες'!D107 -> m³ | E33: 500 | F33: =ROUND(C33*E33, 2) -> 37660 | H33: ="Φύλλο 1 (B.11): Grout Ø120mm με απώλεια 1.20 (0.013572 m³/m) @ 500.00 €/m³" -> Φύλλο 1 (B.11): Grout Ø120mm με απώλεια 1.20 (0.013572 m³/m) @ 500.00 €/m³
A34: B.12 | B34: ='1_Στοιχεία_Μελέτης_&_Ποσότητες'!B108 -> 0 | C34: ='1_Στοιχεία_Μελέτης_&_Ποσότητες'!C108 -> 6142 | D34: ='1_Στοιχεία_Μελέτης_&_Ποσότητες'!D108 -> m | E34: 2.28 | F34: =ROUND(C34*E34, 2) -> 14003.76 | H34: ="Φύλλο 1 (B.12): 126 αγκυρώσεις 2-strands (Σειρά 1 L=20m & Σειρά 2 L=19.5m, +1.0m) @ 2.28 €/m" -> Φύλλο 1 (B.12): 126 αγκυρώσεις 2-strands (Σειρά 1 L=20m & Σειρά 2 L=19.5m, +1.0m) @ 2.28 €/m
A35: B.13 | B35: ='1_Στοιχεία_Μελέτης_&_Ποσότητες'!B109 -> 0 | C35: ='1_Στοιχεία_Μελέτης_&_Ποσότητες'!C109 -> 8325 | D35: ='1_Στοιχεία_Μελέτης_&_Ποσότητες'!D109 -> m | E35: 2.28 | F35: =ROUND(C35*E35, 2) -> 18981 | H35: ="Φύλλο 1 (B.13): 126 αγκυρώσεις 3-strands (Σειρά 3 L=19.5m & Σειρά 4 L=16.0m, +1.0m) @ 2.28 €/m" -> Φύλλο 1 (B.13): 126 αγκυρώσεις 3-strands (Σειρά 3 L=19.5m & Σειρά 4 L=16.0m, +1.0m) @ 2.28 €/m
A36: B.14 | B36: ='1_Στοιχεία_Μελέτης_&_Ποσότητες'!B110 -> ΠΡΟΕΝΤΑΣΗ ΑΓΚΥΡΩΣΕΩΝ (STRESSING & LOCK-OFF) = 4 Σειρές X 74No | C36: ='1_Στοιχεία_Μελέτης_&_Ποσότητες'!C110 -> 296 | D36: ='1_Στοιχεία_Μελέτης_&_Ποσότητες'!D110 -> No | E36: 18 | F36: =ROUND(C36*E36, 2) -> 5328 | H36: ="Φύλλο 1 (B.14): Προένταση (Stressing & Lock-off) 252 αγκυρώσεων Type B @ 18.00 €/No" -> Φύλλο 1 (B.14): Προένταση (Stressing & Lock-off) 252 αγκυρώσεων Type B @ 18.00 €/No
A37: B.15 | B37: ='1_Στοιχεία_Μελέτης_&_Ποσότητες'!B111 -> ΚΕΦΑΛΕΣ ΑΓΚΥΡΩΣΗΣ (ANCHOR HEAD, WEDGES, PLATE) = 4 Σειρές X 74No | C37: ='1_Στοιχεία_Μελέτης_&_Ποσότητες'!C111 -> 296 | D37: ='1_Στοιχεία_Μελέτης_&_Ποσότητες'!D111 -> No | E37: 55 | F37: =ROUND(C37*E37, 2) -> 16280 | H37: ="Φύλλο 1 (B.15): Πλήρες σετ κεφαλής (Head, Wedges, Plate) 252 αγκυρώσεων Type B @ 55.00 €/No" -> Φύλλο 1 (B.15): Πλήρες σετ κεφαλής (Head, Wedges, Plate) 252 αγκυρώσεων Type B @ 55.00 €/No
A39: TYPE C | B39: ="BERLIN WALL TYPE C: " & '1_Στοιχεία_Μελέτης_&_Ποσότητες'!C59 & "No Ζεύγη HEB200, L=" & TEXT('1_Στοιχεία_Μελέτης_&_Ποσότητες'!C63,"0.00") & "m για βάθος εκσκαφής " & TEXT('1_Στοιχεία_Μελέτης_&_Ποσότητες'!C61,"0.00") & "m και " & TEXT('1_Στοιχεία_Μελέτης_&_Ποσότητες'!C60,"0.00") & " τρ.μ." -> BERLIN WALL TYPE C: 15No Ζεύγη HEB200, L=13.00m για βάθος εκσκαφής 11.10m και 22.50 τρ.μ. | C39: ='1_Στοιχεία_Μελέτης_&_Ποσότητες'!C60 -> 22.5 | D39: τρ.μ. | E39: =ROUND(F39/C39, 2) -> 4841.19 | F39: =SUM(F40:F53) -> 108926.88 | G39: ΤΕΛ. ΣΥΝΟΛΑ | H39: Σύνολο Τοίχου Γ (Πυλώνες 2, 3 & 4 — HEB 200, 11 πάσσαλοι, 33 αγκυρώσεις)
A40: C.1 | B40: ='1_Στοιχεία_Μελέτης_&_Ποσότητες'!B114 -> ΤΡΥΠΗΜΑ Ø800mm = 15No X 13.00m | C40: ='1_Στοιχεία_Μελέτης_&_Ποσότητες'!C114 -> 195 | D40: ='1_Στοιχεία_Μελέτης_&_Ποσότητες'!D114 -> m | E40: 75 | F40: =ROUND(C40*E40, 2) -> 14625 | G40: =F39 -> 108926.88 | H40: ="Φύλλο 1 (C.1): " & '1_Στοιχεία_Μελέτης_&_Ποσότητες'!C59 & " πάσσαλοι × " & TEXT('1_Στοιχεία_Μελέτης_&_Ποσότητες'!C63,"0.00") & "m @ 75.00 €/m (Ø800mm Default Εταιρείας)" -> Φύλλο 1 (C.1): 15 πάσσαλοι × 13.00m @ 75.00 €/m (Ø800mm Default Εταιρείας)
A41: C.2 | B41: ='1_Στοιχεία_Μελέτης_&_Ποσότητες'!B115 -> ΜΠΕΤΟΝ ΠΑΚΤΩΣΗΣ C30/37 = 15No X 2.00m X 0.503m³/m | C41: ='1_Στοιχεία_Μελέτης_&_Ποσότητες'!C115 -> 15.08 | D41: ='1_Στοιχεία_Μελέτης_&_Ποσότητες'!D115 -> m³ | E41: 120 | F41: =ROUND(C41*E41, 2) -> 1809.6 | H41: ="Φύλλο 1 (C.2): Πάκτωση H=2.00m σε Ø800mm @ 120.00 €/m³ [Πορτοκαλί #FFE699]" -> Φύλλο 1 (C.2): Πάκτωση H=2.00m σε Ø800mm @ 120.00 €/m³ [Πορτοκαλί #FFE699]
A42: C.3 | B42: ='1_Στοιχεία_Μελέτης_&_Ποσότητες'!B116 -> HEB200 - ΠΡΟΜΗΘΕΙΑ, ΕΠΕΞΕΡΓΑΣΙΑ & ΤΟΠΟΘΕΤΗΣΗ (15No x 2No x 13.00m x 61.3kg/m) | C42: ='1_Στοιχεία_Μελέτης_&_Ποσότητες'!C116 -> 23907 | D42: ='1_Στοιχεία_Μελέτης_&_Ποσότητες'!D116 -> kg | E42: 1.4 | F42: =ROUND(C42*E42, 2) -> 33469.8 | H42: ="Φύλλο 1 (C.3): 2 No. HEB 200 (122.6 kg/m) @ 1.40 €/kg (1.00€ αγορά + 0.40€ επεξεργασία)" -> Φύλλο 1 (C.3): 2 No. HEB 200 (122.6 kg/m) @ 1.40 €/kg (1.00€ αγορά + 0.40€ επεξεργασία)
A43: C.4 | B43: ='1_Στοιχεία_Μελέτης_&_Ποσότητες'!B117 -> ΛΑΜΕΣ ΣΥΝΔΕΣΗΣ 200x200x10mm = 15No x (13No x 3.14kg) | C43: ='1_Στοιχεία_Μελέτης_&_Ποσότητες'!C117 -> 612.3 | D43: ='1_Στοιχεία_Μελέτης_&_Ποσότητες'!D117 -> kg | E43: 1.6 | F43: =ROUND(C43*E43, 2) -> 979.68 | H43: ="Φύλλο 1 (C.4): Κανόνας L_beam/s_plate = 13 λάμες/οπή (143 τεμ.) @ 1.60 €/kg" -> Φύλλο 1 (C.4): Κανόνας L_beam/s_plate = 13 λάμες/οπή (143 τεμ.) @ 1.60 €/kg
...

Sheet 3_Πίνακες_Διατομών_Χάλυβα
A1: ΒΙΒΛΙΟΘΗΚΗ ΔΙΑΤΟΜΩΝ ΧΑΛΥΒΑ (EUROPEAN STRUCTURAL STEEL PROFILES)
A2: Τεχνικά χαρακτηριστικά & βάρη ανά μέτρο για διατομές HEA, HEB, UPN & Γωνιών (L)
A4: 1. ΔΙΑΤΟΜΕΣ HEA (Ευρωπαϊκά Πλατύπελμα Ελαφρού Τύπου)
A5: Ονομασία Διατομής | B5: Ύψος h (mm) | C5: Πλάτος b (mm) | D5: Πάχος tw (mm) | E5: Πάχος tf (mm) | F5: Διατομή A (cm²) | G5: Βάρος (kg / m)
A6: HEA 140 | B6: 133 | C6: 140 | D6: 5.5 | E6: 8.5 | F6: 31.4 | G6: 24.7
A7: HEA 160 | B7: 152 | C7: 160 | D7: 6 | E7: 9 | F7: 38.8 | G7: 30.4
A8: HEA 180 | B8: 171 | C8: 180 | D8: 6 | E8: 9.5 | F8: 45.3 | G8: 35.5
A9: HEA 200 | B9: 190 | C9: 200 | D9: 6.5 | E9: 10 | F9: 53.8 | G9: 42.3
A10: HEA 220 | B10: 210 | C10: 220 | D10: 7 | E10: 11 | F10: 64.3 | G10: 50.5
A11: HEA 240 | B11: 230 | C11: 240 | D11: 7.5 | E11: 12 | F11: 76.8 | G11: 60.3
A12: HEA 260 | B12: 250 | C12: 260 | D12: 7.5 | E12: 12.5 | F12: 86.8 | G12: 68.2
A13: HEA 280 | B13: 270 | C13: 280 | D13: 8 | E13: 13 | F13: 97.3 | G13: 76.4
A14: HEA 300 | B14: 290 | C14: 300 | D14: 8.5 | E14: 14 | F14: 112.5 | G14: 88.3
A16: 2. ΔΙΑΤΟΜΕΣ HEB (Ευρωπαϊκά Πλατύπελμα Κανονικού Τύπου)
A17: Ονομασία Διατομής | B17: Ύψος h (mm) | C17: Πλάτος b (mm) | D17: Πάχος tw (mm) | E17: Πάχος tf (mm) | F17: Διατομή A (cm²) | G17: Βάρος (kg / m)
A18: HEB 140 | B18: 140 | C18: 140 | D18: 7 | E18: 12 | F18: 43 | G18: 33.7
A19: HEB 160 | B19: 160 | C19: 160 | D19: 8 | E19: 13 | F19: 54.3 | G19: 42.6
A20: HEB 180 | B20: 180 | C20: 180 | D20: 8.5 | E20: 14 | F20: 65.3 | G20: 51.2
A21: HEB 200 | B21: 200 | C21: 200 | D21: 9 | E21: 15 | F21: 78.1 | G21: 61.3
A22: HEB 220 | B22: 220 | C22: 220 | D22: 9.5 | E22: 16 | F22: 91 | G22: 71.5
A23: HEB 240 | B23: 240 | C23: 240 | D23: 10 | E23: 17 | F23: 106 | G23: 83.2
A24: HEB 260 | B24: 260 | C24: 260 | D24: 10 | E24: 17.5 | F24: 118.4 | G24: 93
A25: HEB 280 | B25: 280 | C25: 280 | D25: 10.5 | E25: 18 | F25: 131.4 | G25: 103
A26: HEB 300 | B26: 300 | C26: 300 | D26: 11 | E26: 19 | F26: 149.1 | G26: 117
A28: 3. ΔΙΑΤΟΜΕΣ UPN (Ευρωπαϊκά Κοίλα Προφίλ U)
A29: Ονομασία Διατομής | B29: Ύψος h (mm) | C29: Πλάτος b (mm) | D29: Πάχος tw (mm) | E29: Πάχος tf (mm) | F29: Διατομή A (cm²) | G29: Βάρος (kg / m)
A30: UPN 140 | B30: 140 | C30: 60 | D30: 7 | E30: 10 | F30: 20.4 | G30: 16
A31: UPN 160 | B31: 160 | C31: 65 | D31: 7.5 | E31: 10.5 | F31: 24 | G31: 18.8
A32: UPN 180 | B32: 180 | C32: 70 | D32: 8 | E32: 11 | F32: 28 | G32: 22
A33: UPN 200 | B33: 200 | C33: 75 | D33: 8.5 | E33: 11.5 | F33: 32.2 | G33: 25.3
A34: UPN 220 | B34: 220 | C34: 80 | D34: 9 | E34: 12.5 | F34: 37.4 | G34: 29.4
A35: UPN 240 | B35: 240 | C35: 85 | D35: 9.5 | E35: 13 | F35: 42.3 | G35: 33.2
A36: UPN 260 | B36: 260 | C36: 90 | D36: 10 | E36: 14 | F36: 48.3 | G36: 37.9
A37: UPN 280 | B37: 280 | C37: 95 | D37: 10 | E37: 15 | F37: 53.3 | G37: 41.8
A38: UPN 300 | B38: 300 | C38: 100 | D38: 10 | E38: 16 | F38: 58.8 | G38: 46.2
A40: 4. ΙΣΟΣΚΕΛΕΙΣ ΓΩΝΙΕΣ (Equal Angles L)
A41: Ονομασία Διατομής | B41: Ύψος h (mm) | C41: Πλάτος b (mm) | D41: Πάχος tw (mm) | E41: Πάχος tf (mm) | F41: Διατομή A (cm²) | G41: Βάρος (kg / m)
A42: L 50x50x5 | B42: 50 | C42: 50 | D42: 5 | E42: 5 | F42: 4.8 | G42: 3.77
A43: L 60x60x6 | B43: 60 | C43: 60 | D43: 6 | E43: 6 | F43: 6.91 | G43: 5.42
A44: L 70x70x6 | B44: 70 | C44: 70 | D44: 6 | E44: 6 | F44: 8.13 | G44: 6.38
...
