Workbook

Sheet 1_Στοιχεία_Μελέτης_&_Ποσότητες
A1: ΕΡΓΟ: ALDO SQ1 — ΣΤΟΙΧΕΙΑ ΜΕΛΕΤΗΣ & ΦΥΣΙΚΕΣ ΠΟΣΟΤΗΤΕΣ (ΧΩΡΙΣ ΕΥΡΩ)
A2: ΧΩΡΙΣΜΕΝΟ ΣΕ 2 ΜΕΓΑΛΑ ΚΕΦΑΛΑΙΑ: [ΚΕΦΑΛΑΙΟ Α] = ΜΟΝΟ ΣΤΟΙΧΕΙΑ ΜΕΛΕΤΗΣ | [ΚΕΦΑΛΑΙΟ Β] = ΟΛΟΙ ΟΙ ΥΠΟΛΟΓΙΣΜΟΙ
A4: 🏛️ ΚΕΦΑΛΑΙΟ Α: ΜΟΝΟ ΣΤΟΙΧΕΙΑ ΠΟΥ ΔΙΑΒΑΣΤΗΚΑΝ ΑΠΟ ΤΗ ΜΕΛΕΤΗ (RAW INPUTS)
A5: Α.1 Τοποθεσία Εργοταξίου, Έδρα & Σειρές Μελέτης
A6: Έδρα Εταιρείας (Αφετηρία) | B6: Άγιος Συλάς, Σπύρου Κυπριανού 32, Λεμεσός | C6: - | D6: Σταθερή βάση εκκίνησης συνεργείων
A7: Τοποθεσία Εργοταξίου | B7: Κάτω Πολεμίδια, Λεμεσός | C7: - | D7: Από σχέδιο CB1.0
A8: Χιλιομετρική Απόσταση από Έδρα | B8: 12 | C8: km | D8: Απόσταση από εργοστάσιο στον Άγιο Συλά
A9: Πλήθος Οριζόντιων Σειρών Ήλων Μελέτης | B9: 6 | C9: σειρές | D9: Από τομή σχεδίου CB1.0 (6 σειρές ήλων)
A11: Α.2 Γεωμετρία Μετώπου Εκσκαφής
A12: Μήκος Τμήματος 1 (L1) | B12: 21.07 | C12: m | D12: Από κάτοψη σχεδίου CB1.0 (2107 cm)
A13: Μήκος Τμήματος 2 (L2) | B13: 5.5 | C13: m | D13: Από κάτοψη σχεδίου CB1.0 (550 cm)
A14: Μήκος Τμήματος 3 (L3) | B14: 14.1 | C14: m | D14: Από κάτοψη σχεδίου CB1.0 (1410 cm)
A15: Βάθος / Ύψος Εκσκαφής Μετώπου (H) | B15: 10 | C15: m | D15: Από τομή σχεδίου CB1.0 (10.00 m βάθος)
A17: Α.3 Σχάρες Μετώπου (Wire Mesh Grid)
A18: Τύπος Χάλυβα Σχάρας | B18: B500A Δομικό Πλέγμα | C18: - | D18: Από Note 4.2 μελέτης
A19: Διάμετρος Ράβδων Σχάρας (mm) | B19: 8 | C19: mm | D19: Αλλάξτε αυτό το νούμερο (π.χ. 8, 10, 12) και αλλάζει παντού!
A20: Οριζόντιο Βήμα Ράβδων (s_horiz) | B20: 200 | C20: mm | D20: Απόσταση οριζόντιων ράβδων σε mm (Note 4.2)
A21: Κάθετο Βήμα Ράβδων (s_vert) | B21: 200 | C21: mm | D21: Απόσταση κάθετων ράβδων σε mm (Note 4.2)
A23: Α.4 Εκτοξευόμενο Σκυρόδεμα (Shotcrete)
A24: Κατηγορία Σκυροδέματος Shotcrete | B24: C30/37 | C24: - | D24: Από Note 4.1 μελέτης
A25: Ονομαστικό Πάχος Σκυροδέματος Μελέτης | B25: 0.12 | C25: m | D25: 120 mm ονομαστικό πάχος σχεδίου CB1.0
A26: Πάγια Απώλεια / Αναπήδηση Εταιρείας | B26: 0.05 | C26: m | D26: +5 cm πάγια προσαύξηση εταιρείας (χρεώνεται στα €/m³)
A28: Α.5 Εδαφοηλώσεις (Ράβδοι, Διατάξεις, Grout, Πλάκες & Nuts)
A29: Διάμετρος Ράβδων Ήλωσης B500C (mm) | B29: 25 | C29: mm | D29: Αλλάξτε αυτό το νούμερο (π.χ. 20, 25, 28) και αλλάζει παντού!
A30: Μήκος Ήλων Σειρών 1, 2, 3 | B30: 7 | C30: m | D30: Από τομή CB1.0 (3 σειρές των 7m)
A31: Οριζόντιο Βήμα Σειρών 1, 2, 3 | B31: 1 | C31: m | D31: Από κάτοψη/τομή CB1.0 (ανά 1.0m)
A32: Μήκος Ήλων Σειρών 4, 5, 6 | B32: 6 | C32: m | D32: Από τομή CB1.0 (3 σειρές των 6m)
A33: Οριζόντιο Βήμα Σειρών 4, 5, 6 | B33: 1.5 | C33: m | D33: Από κάτοψη/τομή CB1.0 (ανά 2.0m)
A34: Διάμετρος Οπής Διάτρησης (D) | B34: 0.12 | C34: m | D34: ΠΑΝΤΑ 12 cm (ακτίνα R = 0.06 m) κανόνας μάστρου
A35: Συντελεστής Απώλειας Grout στο Έδαφος | B35: 1.2 | C35: - | D35: ΠΑΝΤΑ * 1.20 (+20% απώλεια) κανόνας μάστρου
A36: Μήκος Πλάκας Έδρασης (mm) | B36: 200 | C36: mm | D36: 200 mm μήκος πλάκας (Note 5 μελέτης)
A37: Πλάτος Πλάκας Έδρασης (mm) | B37: 200 | C37: mm | D37: 200 mm πλάτος πλάκας (Note 5 μελέτης)
A38: Πάχος Πλάκας Έδρασης (mm) | B38: 12 | C38: mm | D38: 12 mm πάχος πλάκας (Note 5 μελέτης)
A39: Nuts & Ροδέλες ανά Ήλο | B39: 1 | C39: σετ / ήλο | D39: 1 κοχλιωτό nut & ροδέλα σύσφιξης ανά ήλο (Note 5)
A42: ⚙️ ΚΕΦΑΛΑΙΟ Β: ΟΛΟΙ ΟΙ ΥΠΟΛΟΓΙΣΜΟΙ ΦΥΣΙΚΩΝ ΜΕΓΕΘΩΝ (ΜΕ ΒΑΣΗ ΤΟ ΚΕΦΑΛΑΙΟ Α)
A43: Β.1 Υπολογισμοί Στρατών Μετακίνησης
A44: Ζώνη Μετακίνησης (ακτίνα 50km) | B44: Ζώνη 1 (0 – 50 km) | C44: - | D44: Απόσταση <= 50 km από Άγιο Συλά
A45: Υπολογισμός Στρατών Shotcrete | B45: =B9+1 -> 7 | C45: στράτες | D45: Σειρές ήλων + 1 στράτα για πόδι/δάπεδο (6 + 1 = 7)
A46: Υπολογισμός Στρατών Εδαφοηλώσεων | B46: =B9 -> 6 | C46: στράτες | D46: 1 στράτα ανά οριζόντια σειρά ήλων (6 στράτες υλικών)
A47: Β.2 Υπολογισμοί Σχαρών (Μήκος, Εμβαδόν & Κιλά Χάλυβα)
...

Sheet 2_Υπολογισμοί_&_Κοστολόγηση
A1: ΕΡΓΟ: ALDO SQ1 — ΥΠΟΛΟΓΙΣΜΟΙ ΕΥΡΩ (€) & ΟΙΚΟΝΟΜΙΚΗ ΠΡΟΣΦΟΡΑ
A2: Οι ποσότητες αντλούνται από το Κεφάλαιο Β του Φύλλου 1 | [Χ %] = Ποσοστά προς συμπλήρωση από τον Μάστρο | Νέος Κανόνας Shotcrete
A4: Περιγραφή Εργασίας / Υλικού | B4: Ποσότητα | C4: Μονάδα | D4: Τιμή Μονάδας (€) | E4: Συνολικό Κόστος (€) | F4: Πηγή Ποσότητας / Τεχνικός Κανόνας
A5: ΠΥΛΩΝΑΣ 1: ΜΕΤΑΚΙΝΗΣΕΙΣ & ΣΤΡΑΤΕΣ
A6: Στράτες Shotcrete (Ζώνη 1: 0–50km) | B6: ='1_Στοιχεία_Μελέτης_&_Ποσότητες'!B45 -> 7 | C6: στράτες | D6: 200 | E6: =B6*D6 -> 1400 | F6: Από Φύλλο 1 (6 σειρές + 1 = 7 στράτες)
A7: Στράτες Εδαφοηλώσεων (Ζώνη 1: 0–50km) | B7: ='1_Στοιχεία_Μελέτης_&_Ποσότητες'!B46 -> 6 | C7: στράτες | D7: 300 | E7: =B7*D7 -> 1800 | F7: Από Φύλλο 1 (1 στράτα ανά σειρά = 6 στράτες)
A8: ΣΥΝΟΛΟ ΠΥΛΩΝΑ 1 (ΜΕΤΑΚΙΝΗΣΕΙΣ) | E8: =SUM(E6:E7) -> 3200
A10: ΠΥΛΩΝΑΣ 2: ΣΧΑΡΕΣ (WIRE MESH GRID)
A11: ="Αγορά Χάλυβα Σχάρας (Y" & '1_Στοιχεία_Μελέτης_&_Ποσότητες'!B19 & " " & '1_Στοιχεία_Μελέτης_&_Ποσότητες'!B18 & ")" -> Αγορά Χάλυβα Σχάρας (Y8 B500A Δομικό Πλέγμα) | B11: ='1_Στοιχεία_Μελέτης_&_Ποσότητες'!B53 -> 1604.84 | C11: kg | D11: 2.5 | E11: =B11*D11 -> 4012.1 | F11: ="Από Φύλλο 1 (" & TEXT(B11, "#,##0.00") & " kg) × 2.50 €/kg" -> Από Φύλλο 1 (1,604.84 kg) × 2.50 €/kg
A12: Τοποθέτηση Σχάρας / Εργατικά Μετώπου | B12: ='1_Στοιχεία_Μελέτης_&_Ποσότητες'!B49 -> 406.7 | C12: m² | D12: 15 | E12: =B12*D12 -> 6100.5 | F12: ="Από Φύλλο 1 (" & TEXT(B12, "#,##0.00") & " m²) × 15.00 €/m²" -> Από Φύλλο 1 (406.70 m²) × 15.00 €/m²
A13: ΣΥΝΟΛΟ ΠΥΛΩΝΑ 2 (ΣΧΑΡΕΣ) | E13: =SUM(E11:E12) -> 10112.6
A15: ΠΥΛΩΝΑΣ 3: ΕΚΤΟΞΕΥΟΜΕΝΟ ΣΚΥΡΟΔΕΜΑ (SHOTCRETE) — ΟΝΟΜΑΣΤΙΚΑ m³ ΧΩΡΙΣ ΑΠΩΛΕΙΑ
A16: ="Αγορά Σκυροδέματος Shotcrete (" & '1_Στοιχεία_Μελέτης_&_Ποσότητες'!B24 & ")" -> Αγορά Σκυροδέματος Shotcrete (C30/37) | B16: ='1_Στοιχεία_Μελέτης_&_Ποσότητες'!B57 -> 48.8 | C16: m³ | D16: 90 | E16: =B16*D16 -> 4392 | F16: Σταθερή τιμή αγοράς κουγκριού C30/37 (90 €/m³)
A17: Τοποθέτηση / Εκτόξευση / Αντλία (με προσαύξηση απώλειας) | B17: ='1_Στοιχεία_Μελέτης_&_Ποσότητες'!B57 -> 48.8 | C17: m³ | D17: =ROUND((IF(B16>7, 200, 250)*(1+'1_Στοιχεία_Μελέτης_&_Ποσότητες'!B56))-90, 2) -> 193.33 | E17: =B17*D17 -> 9434.504 | F17: ="Βάση " & IF(B16>7,200,250) & "€ × (1+" & TEXT('1_Στοιχεία_Μελέτης_&_Ποσότητες'!B56, "0.0%") & " απώλεια) - 90€ αγορά" -> Βάση 200€ × (1+41.7% απώλεια) - 90€ αγορά
A18: ΣΥΝΟΛΟ ΠΥΛΩΝΑ 3 (SHOTCRETE) | E18: =SUM(E16:E17) -> 13826.504
A20: ΠΥΛΩΝΑΣ 4: ΕΔΑΦΟΗΛΩΣΕΙΣ (SOIL NAILS)
A21: 4.1 Διάτρηση / Τρύπημα (L >= 6m) | B21: ='1_Στοιχεία_Μελέτης_&_Ποσότητες'!B66 -> 1365 | C21: m | D21: 25 | E21: =B21*D21 -> 34125 | F21: ="Από Φύλλο 1 (" & TEXT(B21, "#,##0.00") & " m) × 25.00 €/m" -> Από Φύλλο 1 (1,365.00 m) × 25.00 €/m
A22: 4.2 Grout Τσιμεντένεμα (με απώλεια 1.20) | B22: ='1_Στοιχεία_Μελέτης_&_Ποσότητες'!B70 -> 18.53 | C22: m³ | D22: 500 | E22: =B22*D22 -> 9265 | F22: ="Από Φύλλο 1 (" & TEXT(B22, "#,##0.00") & " m³) × 500.00 €/m³" -> Από Φύλλο 1 (18.53 m³) × 500.00 €/m³
A23: ="4.3 Χάλυβας Ήλων B500C (Y" & '1_Στοιχεία_Μελέτης_&_Ποσότητες'!B29 & ")" -> 4.3 Χάλυβας Ήλων B500C (Y25) | B23: ='1_Στοιχεία_Μελέτης_&_Ποσότητες'!B68 -> 5259.84 | C23: kg | D23: 1.5 | E23: =B23*D23 -> 7889.76 | F23: ="Από Φύλλο 1 (" & TEXT(B23, "#,##0.00") & " kg) × 1.50 €/kg" -> Από Φύλλο 1 (5,259.84 kg) × 1.50 €/kg
A24: 4.4 Διαμόρφωση Πάσου (Σπείρωμα Κεφαλής) | B24: ='1_Στοιχεία_Μελέτης_&_Ποσότητες'!B65 -> 207 | C24: τεμ. | D24: 20 | E24: =B24*D24 -> 4140 | F24: ="Από Φύλλο 1 (" & TEXT(B24, "#,##0") & " ήλοι) × 20.00 €/τεμ" -> Από Φύλλο 1 (207 ήλοι) × 20.00 €/τεμ
A25: ="4.5 Πλάκες Έδρασης (" & '1_Στοιχεία_Μελέτης_&_Ποσότητες'!B36 & "×" & '1_Στοιχεία_Μελέτης_&_Ποσότητες'!B37 & "×" & '1_Στοιχεία_Μελέτης_&_Ποσότητες'!B38 & "mm)" -> 4.5 Πλάκες Έδρασης (200×200×12mm) | B25: ='1_Στοιχεία_Μελέτης_&_Ποσότητες'!B74 -> 779.98 | C25: kg | D25: 2 | E25: =B25*D25 -> 1559.96 | F25: ="Από Φύλλο 1 (" & TEXT(B25, "#,##0.00") & " kg) × 2.00 €/kg" -> Από Φύλλο 1 (779.98 kg) × 2.00 €/kg
A26: 4.6 Nuts (Περικόχλια) & Ροδέλες | B26: ='1_Στοιχεία_Μελέτης_&_Ποσότητες'!B75 -> 207 | C26: τεμ. | D26: 5 | E26: =B26*D26 -> 1035 | F26: ="Από Φύλλο 1 (" & TEXT(B26, "#,##0") & " nuts) × 5.00 €/τεμ" -> Από Φύλλο 1 (207 nuts) × 5.00 €/τεμ
A27: ΣΥΝΟΛΟ ΠΥΛΩΝΑ 4 (ΕΔΑΦΟΗΛΩΣΕΙΣ) | E27: =SUM(E21:E26) -> 58014.72
A29: ΤΕΛΙΚΑ ΣΥΝΟΛΑ ΠΡΟΣΦΟΡΑΣ & ΕΠΙΒΑΡΥΝΣΕΙΣ ΜΑΣΤΡΟΥ [Χ %]
A30: ΑΜΕΣΟ ΚΟΣΤΟΣ ΕΡΓΟΥ (ΑΘΡΟΙΣΜΑ 4 ΠΥΛΩΝΩΝ) | E30: =E8+E13+E18+E27 -> 85153.824 | F30: Άμεσο κόστος εργασιών & υλικών
A31: Γενικά Έξοδα & Απρόβλεπτα [Χ %] | D31: 0.1 | E31: =ROUND(E30*D31, 2) -> 8515.38 | F31: Πράσινο κελί D31: Συμπληρώνει ο Μάστρος το % που θέλει
A32: Όφελος / Κέρδος Εργολάβου [Χ %] | D32: 0.15 | E32: =ROUND(E30*D32, 2) -> 12773.07 | F32: Πράσινο κελί D32: Συμπληρώνει ο Μάστρος το % που θέλει
A33: ΚΑΘΑΡΟ ΣΥΝΟΛΟ ΠΡΟΣΦΟΡΑΣ (ΠΡΟ Φ.Π.Α.) | E33: =E30+E31+E32 -> 106442.27 | F33: Καθαρή αξία προσφοράς προς ανάδοχο
A34: Φ.Π.Α. (19%) | E34: =ROUND(E33*0.19, 2) -> 20224.03 | F34: Νόμιμος Φ.Π.Α. Κύπρου (19%)
A35: ΤΕΛΙΚΟ ΠΛΗΡΩΤΕΟ ΠΟΣΟ (ΜΕ Φ.Π.Α.) | E35: =E33+E34 -> 126666.3 | F35: Τελικό πληρωτέο ποσό έργου
A36: Γενικό KPI: Κόστος ανά m² Μετώπου Εκσκαφής | E36: =ROUND(E33/'1_Στοιχεία_Μελέτης_&_Ποσότητες'!B49, 2) -> 261.72 | F36: ="Καθαρό σύνολο / " & '1_Στοιχεία_Μελέτης_&_Ποσότητες'!B49 & " m²" -> Καθαρό σύνολο / 406.7 m²
A37: Γενικό KPI: Κόστος ανά Εδαφοήλωση | E37: =ROUND(E33/'1_Στοιχεία_Μελέτης_&_Ποσότητες'!B65, 2) -> 514.21 | F37: ="Καθαρό σύνολο / " & '1_Στοιχεία_Μελέτης_&_Ποσότητες'!B65 & " ήλοι" -> Καθαρό σύνολο / 207 ήλοι
A40: 5. ΣΥΓΚΡΙΤΙΚΗ ΑΝΑΛΥΣΗ ΔΙΑΤΑΞΕΩΝ / VALUE ENGINEERING (ΑΝΑ ΖΩΝΗ & ΒΑΘΟΣ)
A41: Εργαλείο Value Engineering για Μελετητές: Σύγκριση κόστους ανά τεμάχιο ήλου (€/τεμ), ανά μέτρο διάτρησης (€/m) και ανά m² μετώπου (€/m²)
A42: Διάταξη / Ζώνη Ήλων | B42: Μήκος (L) [m] | C42: Βήμα (s) [m] | D42: Άμεσο Κόστος ανά Ήλο (€/τεμ) | E42: Κόστος ανά Τρέχον Μέτρο (€/m) | F42: Κόστος Ήλων ανά m² Μετώπου (€/m²) | G42: Συνολικό Σύστημα ανά m² Μετώπου (€/m²)
A43: ="Ζώνη 1 (Σειρές 1–3): " & '1_Στοιχεία_Μελέτης_&_Ποσότητες'!B30 & "m @ " & '1_Στοιχεία_Μελέτης_&_Ποσότητες'!B31 & "m" -> Ζώνη 1 (Σειρές 1–3): 7m @ 1m | B43: ='1_Στοιχεία_Μελέτης_&_Ποσότητες'!B30 -> 7 | C43: ='1_Στοιχεία_Μελέτης_&_Ποσότητες'!B31 -> 1 | D43: =(B43*$D$21)+(B43*'1_Στοιχεία_Μελέτης_&_Ποσότητες'!$B$69*$D$22)+(B43*'1_Στοιχεία_Μελέτης_&_Ποσότητες'!$B$67*$D$23)+$D$24+('1_Στοιχεία_Μελέτης_&_Ποσότητες'!$B$72*$D$25)+$D$26 -> 295.49716 | E43: =D43/B43 -> 42.21388 | F43: =('1_Στοιχεία_Μελέτης_&_Ποσότητες'!$B$60*D43)/('1_Στοιχεία_Μελέτης_&_Ποσότητες'!$B$49/2) -> 178.73691 | G43: =F43+($E$8+$E$13+$E$18)/'1_Στοιχεία_Μελέτης_&_Ποσότητες'!$B$49 -> 245.46694
A44: ="Ζώνη 2 (Σειρές 4–6): " & '1_Στοιχεία_Μελέτης_&_Ποσότητες'!B32 & "m @ " & '1_Στοιχεία_Μελέτης_&_Ποσότητες'!B33 & "m" -> Ζώνη 2 (Σειρές 4–6): 6m @ 1.5m | B44: ='1_Στοιχεία_Μελέτης_&_Ποσότητες'!B32 -> 6 | C44: ='1_Στοιχεία_Μελέτης_&_Ποσότητες'!B33 -> 1.5 | D44: =(B44*$D$21)+(B44*'1_Στοιχεία_Μελέτης_&_Ποσότητες'!$B$69*$D$22)+(B44*'1_Στοιχεία_Μελέτης_&_Ποσότητες'!$B$67*$D$23)+$D$24+('1_Στοιχεία_Μελέτης_&_Ποσότητες'!$B$72*$D$25)+$D$26 -> 257.93128 | E44: =D44/B44 -> 42.988546 | F44: =('1_Στοιχεία_Μελέτης_&_Ποσότητες'!$B$63*D44)/('1_Στοιχεία_Μελέτης_&_Ποσότητες'!$B$49/2) -> 106.54648 | G44: =F44+($E$8+$E$13+$E$18)/'1_Στοιχεία_Μελέτης_&_Ποσότητες'!$B$49 -> 173.27652
A45: ΔΙΑΦΟΡΑ / ΕΞΟΙΚΟΝΟΜΗΣΗ (ΖΩΝΗ 2 vs ΖΩΝΗ 1) | D45: =D43-D44 -> 37.56588 | E45: =E43-E44 -> -0.77466667 | F45: =F43-F44 -> 72.190426 | G45: =G43-G44 -> 72.190426
