Workbook

Sheet 1_Στοιχεία_Μελέτης_&_Ποσότητες
A1: ΕΡΓΟ: TOFARCO "ΑΘΗΝΑΙΟΝ" (TIVOLI PROPERTY LTD) — BERLIN WALL & ΑΓΚΥΡΩΣΕΙΣ
A2: ΦΥΛΛΟ 1: ΣΤΟΙΧΕΙΑ ΜΕΛΕΤΗΣ & ΦΥΣΙΚΕΣ ΠΟΣΟΤΗΤΕΣ | ΑΠΟΛΥΤΩΣ ΚΑΝΕΝΑ ΕΥΡΩ (€) ΣΕ ΑΥΤΗ ΤΗ ΣΕΛΙΔΑ
A4: 🏛️ ΚΕΦΑΛΑΙΟ Α: ΜΟΝΟ ΣΤΟΙΧΕΙΑ ΠΟΥ ΔΙΑΒΑΣΤΗΚΑΝ ΑΠΟ ΤΗ ΜΕΛΕΤΗ (RAW INPUTS)
A5: Α.1 Τοποθεσία Εργοταξίου, Έδρα & Σειρές Αγκυρώσεων
A6: Έδρα Εταιρείας (Βάση Υπολογισμού Αποστάσεων) | B6: Άγιος Συλάς, Σπύρου Κυπριανού 32, Λεμεσός | C6: έδρα | D6: Αφετηρία μηχανημάτων & μετακινήσεων
A7: Τοποθεσία Εργοταξίου Μελέτης | B7: Λευκωσία (Ευαγόρου / Μενάνδρου / Ανδρέα Δημητρίου) | C7: πόλη | D7: Τεμάχιο 873, απέναντι από Βουλή
A8: Χιλιομετρική Απόσταση από Έδρα | B8: 85 | C8: km | D8: Απόσταση > 80 km (κατηγορία Λευκωσίας)
A9: Πλήθος Οριζόντιων Σειρών Αγκυρώσεων Μελέτης | B9: 4 | C9: σειρές | D9: 4 σειρές αγκυρώσεων σε όλο το μέτωπο (1x15° + 3x30°)
A11: Α.2 Γεωμετρία Μετώπου Εκσκαφής (Διαστήματα & Μήκη ανά Πλευρά)
A12: Μήκος Δυτικής Πλευράς (Κάθετο τμήμα SW) | B12: 16 | C12: m | D12: 8 διαστήματα των 2.00 m c/c (ακριβής μέτρηση διαστημάτων)
A13: Μήκος Βορειοδυτικής Πλευράς (Πλάγιο τμήμα Ευαγόρου) | B13: 18 | C13: m | D13: 9 διαστήματα των 2.00 m c/c (από καμπή έως γωνία NW)
A14: Μήκος Βόρειας Πλευράς (Κατά μήκος Μενάνδρου) | B14: 54 | C14: m | D14: 27 διαστήματα των 2.00 m c/c (από γωνία NW έως NE)
A15: Μήκος Ανατολικής Πλευράς (Ανατολικό όριο) | B15: 22 | C15: m | D15: 11 διαστήματα των 2.00 m c/c (από γωνία NE έως SE)
A16: Μήκος Νότιας Πλευράς (Κατά μήκος Ανδρέα Δημητρίου) | B16: 86 | C16: m | D16: 43 διαστήματα των 2.00 m c/c (από γωνία SE έως SW)
A17: Ελεύθερο Ύψος Εκσκαφής Μετώπου (H_exc) | B17: 12.5 | C17: m | D17: 15.50m βάθος διάτρησης μείον 3.00m πάκτωση
A18: Βάθος Πάκτωσης Πασσάλων κάτω από Εκσκαφή (H_embed) | B18: 3 | C18: m | D18: 3.00 m πάκτωση (επιλογή ανώτερου C35/45 σχεδίου Σ01.1)
A20: Α.3 Σχάρες Οπλισμού & Εκτοξευόμενο Σκυρόδεμα (Gunite / Shotcrete)
A21: Οριζόντιος Οπλισμός Σχάρας Μελέτης | B21: Y20 / 200 | C21: διατομή | D21: Διάμετρος 20 mm ανά 200 mm c/c
A22: Διάμετρος Οριζόντιων Ράβδων | B22: 20 | C22: mm | D22: Ράβδοι B500C
A23: Βήμα Οριζόντιων Ράβδων | B23: 200 | C23: mm | D23: 5 ράβδοι ανά μέτρο ύψους
A24: Κατακόρυφος Οπλισμός Σχάρας Μελέτης | B24: Y14 / 200 | C24: διατομή | D24: Διάμετρος 14 mm ανά 200 mm c/c
A25: Διάμετρος Κατακόρυφων Ράβδων | B25: 14 | C25: mm | D25: Ράβδοι B500C
A26: Βήμα Κατακόρυφων Ράβδων | B26: 200 | C26: mm | D26: 5 ράβδοι ανά μέτρο μήκους
A27: Ονομαστικό Πάχος Shotcrete Μελέτης (t_nom) | B27: 0.15 | C27: m | D27: 150 mm ελάχιστο πάχος επικάλυψης σχεδίου
A28: Πάγια Απώλεια / Αναπήδηση Εταιρείας | B28: 0.05 | C28: m | D28: +5 cm πάγια προσαύξηση εταιρείας
A29: Κατηγορία Σκυροδέματος Μελέτης | B29: C30/40 CEMII 42.5 | C29: κατηγορία | D29: Πρόσμικτα RHEOMAC SE 100 56 & Sigunit L 22E
A31: Α.4 H-Beams (Πασσαλοκολώνες 2×UPN 350, Διάτρηση Ø800 & Λάμες)
A32: Αξονική Απόσταση Πασσάλων (s_beam) | B32: 2 | C32: m | D32: Ανά 2.00 m c/c στην περίμετρο
A33: Συνολικό Πλήθος Οπών / Πασσάλων Έργου | B33: 98 | C33: οπές / πάσσαλοι | D33: 98 διαστήματα των 2.0m c/c (196m περίμετρος)
A34: Διάμετρος Διάτρησης Μεγάλου Τρυπανιού (Κανόνας v2: min Ø800 mm) | B34: 0.8 | C34: m | D34: Ζητήθηκε Ø600 mm -> Εφαρμογή κανόνα: ελάχιστο Ø800 mm
A35: Συνολικό Βάθος Διάτρησης Μεγάλου Τρυπανιού | B35: 15.5 | C35: m | D35: Βάθος κάτω από δημόσιο δρόμο > 15.50 m
A36: Τύπος Μεταλλικού Προφίλ Νέφκας | B36: 2xUPN 350x100 | C36: προφίλ | D36: 2 κοιλοδοκοί UPN 350 ανά οπή
A37: Μήκος Μεταλλικής Κολώνας (h) | B37: 15 | C37: m | D37: Βυθίζεται 0.50m κάτω από ισόγειο
A38: Πλήθος Προφίλ ανά Οπή | B38: 2 | C38: προφίλ / οπή | D38: Διπλό UPN 350
A39: Θεωρητικό Βάρος Προφίλ ανά Μέτρο | B39: 60.6 | C39: kg / m | D39: 60.6 kg/m ανά UPN (Σύνολο 121.2 kg/m)
A40: Διαστάσεις Συνδετικής Λάμας (Πλάτος W x Μήκος L x Πάχος t) | B40: 350 x 100 x 12 | C40: mm | D40: PLT 350x100x12 mm
A41: Βήμα Τοποθέτησης Λαμών κατά Ύψος (s_plate) | B41: 0.6 | C41: m | D41: Απόσταση που ζητά ο μελετητής ανά 0.60 m
A42: Ύψος Σκυροδέματος Πάκτωσης Πασσάλου | B42: 3 | C42: m | D42: Πιάσιμο στον πυθμένα της διάτρησης σε ύψος 3.00 m
A43: Κατηγορία Σκυροδέματος Πάκτωσης (Κανόνας v2) | B43: C35/45 | C43: κατηγορία | D43: Επιλογή ανώτερου C35/45 (Σ02.1 ανέφερε C30/37 στα 2.5m)
A45: Α.5 Αγκυρώσεις (Prestressed Tieback Anchors)
...

Sheet 2_Υπολογισμοί_&_Κοστολόγηση
A1: ΠΡΟΣΦΟΡΑ ΚΟΣΤΟΛΟΓΗΣΗΣ: TOFARCO "ΑΘΗΝΑΙΟΝ" (TIVOLI PROPERTY LTD)
A2: ΑΝΑΛΥΣΗ ΚΟΣΤΟΥΣ 4 ΠΥΛΩΝΩΝ (v2) | ΓΕΝΙΚΑ ΕΞΟΔΑ & ΚΕΡΔΟΣ ΕΝΣΩΜΑΤΩΜΕΝΑ ΣΤΙΣ ΤΙΜΕΣ ΜΟΝΑΔΑΣ (ΚΙΤΡΙΝΑ ΚΕΛΙΑ)
A4: Περιγραφή Εργασίας / Υλικού | B4: Ποσότητα Μελέτης [ΑΠΟ ΦΥΛΛΟ 1] | C4: Μονάδα | D4: Τιμή Μονάδας (€) [ΚΙΤΡΙΝΟ = ΑΛΛΑΖΕΙ] | E4: Σύνολο (€) | F4: Παρατηρήσεις & Τεχνικές Σημειώσεις Μελέτης
A5: ΠΥΛΩΝΑΣ 1: ΜΕΤΑΚΙΝΗΣΕΙΣ ΕΞΟΠΛΙΣΜΟΥ & ΠΡΟΣΩΠΙΚΟΥ (ΛΕΥΚΩΣΙΑ > 80 km)
A6: 1.1 Μετακίνηση Μεγάλου Τρυπανιού (Piling Rig) | B6: ='1_Στοιχεία_Μελέτης_&_Ποσότητες'!B60 | C6: στράτες | D6: 3000 | E6: =B6*D6 | F6: 1 στράτα. Βασική 1500 € + 1500 € επιβάρυνση Λευκωσίας (>80 km)
A7: 1.2 Μετακινήσεις Εξοπλισμού Αγκυρώσεων | B7: ='1_Στοιχεία_Μελέτης_&_Ποσότητες'!B61 | C7: στράτες | D7: 400 | E7: =B7*D7 | F7: 4 στράτες (όσες οι σειρές αγκυρώσεων). 300 € + 2x50 € Λευκωσίας
A8: 1.3 Μετακινήσεις Συνεργείου & Αντλίας Shotcrete | B8: ='1_Στοιχεία_Μελέτης_&_Ποσότητες'!B62 | C8: στράτες | D8: 300 | E8: =B8*D8 | F8: 5 στράτες (σειρές αγκυρώσεων + 1). 200 € + 2x50 € Λευκωσίας
A9: ΣΥΝΟΛΟ ΠΥΛΩΝΑ 1 (ΜΕΤΑΚΙΝΗΣΕΙΣ) | E9: =SUM(E6:E8)
A11: ΠΥΛΩΝΑΣ 2: ΣΧΑΡΕΣ ΟΠΛΙΣΜΟΥ & ΕΚΤΟΞΕΥΟΜΕΝΟ ΣΚΥΡΟΔΕΜΑ (SHOTCRETE)
A12: ="2.1 Αγορά Χάλυβα Σχάρας (" & '1_Στοιχεία_Μελέτης_&_Ποσότητες'!B21 & " + " & '1_Στοιχεία_Μελέτης_&_Ποσότητες'!B24 & ")" | B12: ='1_Στοιχεία_Μελέτης_&_Ποσότητες'!B70 | C12: kg | D12: 2.5 | E12: =B12*D12 | F12: Χάλυβας B500C (18.37 kg/m² μετώπου)
A13: 2.2 Τοποθέτηση & Εργατικά Σχάρας Μετώπου | B13: ='1_Στοιχεία_Μελέτης_&_Ποσότητες'!B66 | C13: m² | D13: 15 | E13: =B13*D13 | F13: Ενιαία τιμή τοποθέτησης ανά m² μετώπου εκσκαφής
A14: 2.3 Αγορά Σκυροδέματος Shotcrete C30/40 | B14: ='1_Στοιχεία_Μελέτης_&_Ποσότητες'!B71 | C14: m³ | D14: 90 | E14: =B14*D14 | F14: 367.50 m³ ονομαστικός όγκος μελέτης (t=15cm, χωρίς απώλεια)
A15: 2.4 Εφαρμογή, Άντληση & Εκτόξευση Shotcrete | B15: ='1_Στοιχεία_Μελέτης_&_Ποσότητες'!B71 | C15: m³ | D15: =ROUND((200*(1+'1_Στοιχεία_Μελέτης_&_Ποσότητες'!B72))-90, 2) | E15: =B15*D15 | F15: Τύπος: [(200 x (1 + %απώλειας)) - 90] = 176.67 €/m³
A16: ΣΥΝΟΛΟ ΠΥΛΩΝΑ 2 (ΣΧΑΡΕΣ & SHOTCRETE) | E16: =SUM(E12:E15)
A18: ΠΥΛΩΝΑΣ 3: H-BEAMS (ΠΑΣΣΑΛΟΚΟΛΩΝΕΣ 2xUPN 350, ΔΙΑΤΡΗΣΗ Ø800, ΛΑΜΕΣ & ΚΟΥΓΚΡΙ)
A19: ="3.1 Διάτρηση Μεγάλου Τρυπανιού (Ø" & TEXT('1_Στοιχεία_Μελέτης_&_Ποσότητες'!B34*1000, "0") & " mm)" | B19: ='1_Στοιχεία_Μελέτης_&_Ποσότητες'!B76 | C19: m | D19: 75 | E19: =B19*D19 | F19: 98 οπές x 15.50 m (Κανόνας v2: Ελάχιστη διάτρηση Ø800 mm)
A20: ="3.2 Χάλυβας Νέφκων (" & '1_Στοιχεία_Μελέτης_&_Ποσότητες'!B36 & " @ 60.6 kg/m)" | B20: ='1_Στοιχεία_Μελέτης_&_Ποσότητες'!B79 | C20: kg | D20: 1.4 | E20: =B20*D20 | F20: 1.00 € αγορά + 0.40 € επεξεργασία & τοποθέτηση
A21: 3.3 Λάμες Σύνδεσης / Ενίσχυσης PLT 350x100x12 mm | B21: ='1_Στοιχεία_Μελέτης_&_Ποσότητες'!B83 | C21: kg | D21: 1.6 | E21: =B21*D21 | F21: 2,450 λάμες (Κανόνας v2: L/s = 25 λάμες/οπή, 1.00€ αγορά + 0.60€ συγκόλληση)
A22: 3.4 Κουγκρί Πάκτωσης Πασσάλων (H=3.0 m, Ø800 mm) | B22: ='1_Στοιχεία_Μελέτης_&_Ποσότητες'!B85 | C22: m³ | D22: 120 | E22: =B22*D22 | F22: 147.78 m³. Επιλογή C35/45 (Σ02.1 ανέφερε C30/37). Τιμή βάσης 120€ για C25/30
A23: 3.5 Γωνιές Στήριξης (Equal Angles L) | B23: 0 | C23: kg | D23: 1.6 | E23: =B23*D23 | F23: Δεν ζητούνται γωνιές στήριξης στα κατασκευαστικά σχέδια
A24: ΣΥΝΟΛΟ ΠΥΛΩΝΑ 3 (H-BEAMS) | E24: =SUM(E19:E23)
A26: ΠΥΛΩΝΑΣ 4: ΑΓΚΥΡΩΣΕΙΣ (PRESTRESSED TIEBACK ANCHORS — 4 ΣΕΙΡΕΣ)
A27: ="4.1 Διάτρηση Αγκυρώσεων (Ø" & TEXT('1_Στοιχεία_Μελέτης_&_Ποσότητες'!B53*1000, "0") & " mm)" | B27: ='1_Στοιχεία_Μελέτης_&_Ποσότητες'!B89 | C27: m | D27: 30 | E27: =B27*D27 | F27: 392 οπές x 13.30 m βάθος (εύρος τιμών: 25–35 €/m)
A28: 4.2 Grout Τσιμεντενέματος Πλήρωσης Αγκυρώσεων | B28: ='1_Στοιχεία_Μελέτης_&_Ποσότητες'!B91 | C28: m³ | D28: 500 | E28: =B28*D28 | F28: Υψηλής αντοχής fcu > 80 N/mm² (ASTM C-845)
A29: 4.3 Τένοντες Προέντασης (5 Strands 0.6" - 1.10 kg/m) | B29: ='1_Στοιχεία_Μελέτης_&_Ποσότητες'!B92 | C29: m | D29: 2.28 | E29: =B29*D29 | F29: 28,028 m (392 οπές x 14.30m x 5 strands @ 2.28 €/m)
A30: 4.4 Προένταση Αγκυρώσεων (Stressing & Lock-off) | B30: ='1_Στοιχεία_Μελέτης_&_Ποσότητες'!B95 | C30: τεμ | D30: 18 | E30: =B30*D30 | F30: 392 διαδικασίες τάνυσης και κλειδώματος σφηνών
A31: 4.5 Κεφαλή Αγκύρωσης, Σφήνες & Πλάκα Έδρασης | B31: ='1_Στοιχεία_Μελέτης_&_Ποσότητες'!B96 | C31: τεμ | D31: 55 | E31: =B31*D31 | F31: 392 πλήρη σετ κεφαλής, σφηνών και πλάκας έδρασης
A32: ΣΥΝΟΛΟ ΠΥΛΩΝΑ 4 (ΑΓΚΥΡΩΣΕΙΣ) | E32: =SUM(E27:E31)
A34: ΤΕΛΙΚΑ ΣΥΝΟΛΑ ΠΡΟΣΦΟΡΑΣ (ΓΕΝΙΚΑ ΕΞΟΔΑ & ΚΕΡΔΟΣ ΕΝΣΩΜΑΤΩΜΕΝΑ ΣΤΙΣ ΤΙΜΕΣ)
A35: ΚΑΘΑΡΟ ΣΥΝΟΛΟ ΠΡΟΣΦΟΡΑΣ (ΠΡΟ Φ.Π.Α.) | E35: =E9+E16+E24+E32
A36: Φ.Π.Α. (19%) | E36: =ROUND(E35*0.19, 2)
A37: ΤΕΛΙΚΟ ΠΛΗΡΩΤΕΟ ΠΟΣΟ (ΜΕ Φ.Π.Α.) | E37: =E35+E36
A39: ΒΑΣΙΚΟΙ ΔΕΙΚΤΕΣ ΚΟΣΤΟΥΣ & VALUE ENGINEERING (KPIs)
A40: KPI 1: Συνολικό Κόστος ανά m² Μετώπου Εκσκαφής | C40: € / m² | E40: =ROUND(E35/'1_Στοιχεία_Μελέτης_&_Ποσότητες'!B66, 2) | F40: Καθαρό Σύνολο Προσφοράς / 2,450 m² εμβαδόν μετώπου
A41: KPI 2: Συνολικό Κόστος ανά Αγκύρωση (Πλήρες Σύστημα Αγκύρωσης) | C41: € / αγκύρωση | E41: =ROUND(E32/'1_Στοιχεία_Μελέτης_&_Ποσότητες'!B88, 2) | F41: Σύνολο Πυλώνα 4 / 392 αγκυρώσεις
A42: KPI 3: Συνολικό Κόστος Σχαρών & Shotcrete ανά m² Μετώπου | C42: € / m² | E42: =ROUND(E16/'1_Στοιχεία_Μελέτης_&_Ποσότητες'!B66, 2) | F42: Σύνολο Πυλώνα 2 / 2,450 m² εμβαδόν μετώπου
A43: KPI 4: Συνολικό Κόστος H-Beams ανά Πάσσαλο / Οπή | C43: € / πάσσαλο | E43: =ROUND(E24/'1_Στοιχεία_Μελέτης_&_Ποσότητες'!B33, 2) | F43: Σύνολο Πυλώνα 3 / 98 πασσαλοκολώνες

Sheet 3_Πίνακες_Διατομών_Χάλυβα
A1: ΠΙΝΑΚΕΣ ΔΙΑΤΟΜΩΝ ΧΑΛΥΒΑ & ΘΕΩΡΗΤΙΚΑ ΒΑΡΗ (EUROCODES)
A2: Περιλαμβάνει Ευρωπαϊκά Πλατύπελμα HEA, HEB, Κοιλοδοκούς UPN (με έμφαση στο UPN 350) και Γωνίες L
A4: 1. ΔΙΑΤΟΜΕΣ HEA (Ευρωπαϊκά Πλατύπελμα Ελαφρού Τύπου)
A5: Ονομασία Διατομής | B5: Ύψος h (mm) | C5: Πλάτος b (mm) | D5: Πάχος tw (mm) | E5: Πάχος tf (mm) | F5: Βάρος (kg/m) | G5: Κόστος Υλικού (€/m) [1.40 €/kg]
A6: HEA 140 | B6: 133 | C6: 140 | D6: 5.5 | E6: 8.5 | F6: 24.7 | G6: =ROUND(F6*1.40, 2)
A7: HEA 160 | B7: 152 | C7: 160 | D7: 6 | E7: 9 | F7: 30.4 | G7: =ROUND(F7*1.40, 2)
A8: HEA 180 | B8: 171 | C8: 180 | D8: 6 | E8: 9.5 | F8: 35.5 | G8: =ROUND(F8*1.40, 2)
A9: HEA 200 | B9: 190 | C9: 200 | D9: 6.5 | E9: 10 | F9: 42.3 | G9: =ROUND(F9*1.40, 2)
A10: HEA 220 | B10: 210 | C10: 220 | D10: 7 | E10: 11 | F10: 50.5 | G10: =ROUND(F10*1.40, 2)
A11: HEA 240 | B11: 230 | C11: 240 | D11: 7.5 | E11: 12 | F11: 60.3 | G11: =ROUND(F11*1.40, 2)
A12: HEA 260 | B12: 250 | C12: 260 | D12: 7.5 | E12: 12.5 | F12: 68.2 | G12: =ROUND(F12*1.40, 2)
A13: HEA 280 | B13: 270 | C13: 280 | D13: 8 | E13: 13 | F13: 76.4 | G13: =ROUND(F13*1.40, 2)
A14: HEA 300 | B14: 290 | C14: 300 | D14: 8.5 | E14: 14 | F14: 88.3 | G14: =ROUND(F14*1.40, 2)
A16: 2. ΔΙΑΤΟΜΕΣ HEB (Ευρωπαϊκά Πλατύπελμα Κανονικού Τύπου)
A17: Ονομασία Διατομής | B17: Ύψος h (mm) | C17: Πλάτος b (mm) | D17: Πάχος tw (mm) | E17: Πάχος tf (mm) | F17: Βάρος (kg/m) | G17: Κόστος Υλικού (€/m) [1.40 €/kg]
A18: HEB 140 | B18: 140 | C18: 140 | D18: 7 | E18: 12 | F18: 33.7 | G18: =ROUND(F18*1.40, 2)
A19: HEB 160 | B19: 160 | C19: 160 | D19: 8 | E19: 13 | F19: 42.6 | G19: =ROUND(F19*1.40, 2)
A20: HEB 180 | B20: 180 | C20: 180 | D20: 8.5 | E20: 14 | F20: 51.2 | G20: =ROUND(F20*1.40, 2)
A21: HEB 200 | B21: 200 | C21: 200 | D21: 9 | E21: 15 | F21: 61.3 | G21: =ROUND(F21*1.40, 2)
A22: HEB 220 | B22: 220 | C22: 220 | D22: 9.5 | E22: 16 | F22: 71.5 | G22: =ROUND(F22*1.40, 2)
A23: HEB 240 | B23: 240 | C23: 240 | D23: 10 | E23: 17 | F23: 83.2 | G23: =ROUND(F23*1.40, 2)
A24: HEB 260 | B24: 260 | C24: 260 | D24: 10 | E24: 17.5 | F24: 93 | G24: =ROUND(F24*1.40, 2)
A25: HEB 280 | B25: 280 | C25: 280 | D25: 10.5 | E25: 18 | F25: 103 | G25: =ROUND(F25*1.40, 2)
A26: HEB 300 | B26: 300 | C26: 300 | D26: 11 | E26: 19 | F26: 117 | G26: =ROUND(F26*1.40, 2)
A28: 3. ΔΙΑΤΟΜΕΣ UPN (Κοιλοδοκοί U-Profiles — ΧΡΗΣΗ ΣΤΟ TOFARCO ATHENION)
A29: Ονομασία Διατομής | B29: Ύψος h (mm) | C29: Πλάτος b (mm) | D29: Πάχος tw (mm) | E29: Πάχος tf (mm) | F29: Βάρος (kg/m) | G29: Κόστος Υλικού (€/m) [1.40 €/kg]
A30: UPN 140 | B30: 140 | C30: 60 | D30: 7 | E30: 10 | F30: 16 | G30: =ROUND(F30*1.40, 2)
A31: UPN 160 | B31: 160 | C31: 65 | D31: 7.5 | E31: 10.5 | F31: 18.8 | G31: =ROUND(F31*1.40, 2)
A32: UPN 180 | B32: 180 | C32: 70 | D32: 8 | E32: 11 | F32: 22 | G32: =ROUND(F32*1.40, 2)
A33: UPN 200 | B33: 200 | C33: 75 | D33: 8.5 | E33: 11.5 | F33: 25.3 | G33: =ROUND(F33*1.40, 2)
A34: UPN 220 | B34: 220 | C34: 80 | D34: 9 | E34: 12.5 | F34: 29.4 | G34: =ROUND(F34*1.40, 2)
A35: UPN 240 | B35: 240 | C35: 85 | D35: 9.5 | E35: 13 | F35: 33.2 | G35: =ROUND(F35*1.40, 2)
A36: UPN 260 | B36: 260 | C36: 90 | D36: 10 | E36: 14 | F36: 37.9 | G36: =ROUND(F36*1.40, 2)
A37: UPN 280 | B37: 280 | C37: 95 | D37: 10 | E37: 15 | F37: 41.8 | G37: =ROUND(F37*1.40, 2)
A38: UPN 300 | B38: 300 | C38: 100 | D38: 10 | E38: 16 | F38: 46.2 | G38: =ROUND(F38*1.40, 2)
A39: UPN 350 | B39: 350 | C39: 100 | D39: 14 | E39: 16 | F39: 60.6 | G39: =ROUND(F39*1.40, 2)
A41: 4. ΙΣΟΣΚΕΛΕΙΣ ΓΩΝΙΕΣ (Equal Angles L)
A42: Ονομασία Γωνίας | B42: Πλάτος a (mm) | C42: Πλάτος b (mm) | D42: Πάχος t (mm) | E42: — | F42: Βάρος (kg/m) | G42: Κόστος Υλικού (€/m) [1.60 €/kg]
A43: L 50x50x5 | B43: 50 | C43: 50 | D43: 5 | E43: — | F43: 3.77 | G43: =ROUND(F43*1.60, 2)
A44: L 60x60x6 | B44: 60 | C44: 60 | D44: 6 | E44: — | F44: 5.42 | G44: =ROUND(F44*1.60, 2)
...
