Workbook

Sheet 1_Στοιχεία_Μελέτης_&_Ποσότητες
A1: ΕΡΓΟ: TOFARCO "ΑΘΗΝΑΙΟΝ" (TIVOLI PROPERTY LTD) — BERLIN WALL & ΑΓΚΥΡΩΣΕΙΣ
A2: ΦΥΛΛΟ 1: ΣΤΟΙΧΕΙΑ ΜΕΛΕΤΗΣ, ΠΗΓΕΣ (CITATIONS) & ΥΠΟΛΟΓΙΣΜΟΙ | ΑΠΟΛΥΤΩΣ ΚΑΝΕΝΑ ΕΥΡΩ (€) ΣΕ ΑΥΤΗ ΤΗ ΣΕΛΙΔΑ
A4: 🏛️ ΚΕΦΑΛΑΙΟ Α: ΜΟΝΟ ΣΤΟΙΧΕΙΑ ΠΟΥ ΔΙΑΒΑΣΤΗΚΑΝ ΑΠΟ ΤΗ ΜΕΛΕΤΗ (RAW INPUTS & CITATIONS)
A5: Περιγραφή Στοιχείου Μελέτης | B5: Τιμή Μελέτης | C5: Μονάδα | D5: Πηγή Μελέτης (Σχέδιο / Σελίδα) | E5: Τεχνική Σημείωση / Έλεγχος Κανόνα
A6: Α.1 Τοποθεσία Εργοταξίου, Έδρα & Σειρές Αγκυρώσεων
A7: Έδρα Εταιρείας (Βάση Υπολογισμού Αποστάσεων) | B7: Άγιος Συλάς, Σπύρου Κυπριανού 32, Λεμεσός | C7: έδρα | D7: Πολιτική Εταιρείας | E7: Αφετηρία μηχανημάτων & μετακινήσεων
A8: Τοποθεσία Εργοταξίου Μελέτης | B8: Λευκωσία (Ευαγόρου / Μενάνδρου / Ανδρέα Δημητρίου) | C8: πόλη | D8: Σχέδιο Σ01.1, Πινακίδα Μελέτης | E8: Τεμάχιο 873, απέναντι από Βουλή
A9: Χιλιομετρική Απόσταση από Έδρα | B9: 85 | C9: km | D9: Google Maps / Χιλιομετρικός Πίνακας | E9: Απόσταση > 80 km (κατηγορία Λευκωσίας)
A10: Πλήθος Οριζόντιων Σειρών Αγκυρώσεων Μελέτης | B10: 4 | C10: σειρές | D10: Σχέδιο Σ02.1, Τομή 1-1 | E10: 4 σειρές αγκυρώσεων σε όλο το μέτωπο (1x15° + 3x30°)
A12: Α.2 Γεωμετρία Μετώπου Εκσκαφής (Διαστήματα & Μήκη ανά Πλευρά)
A13: Μήκος Δυτικής Πλευράς (Κάθετο τμήμα SW) | B13: 16 | C13: m | D13: Σχέδιο Σ01.1, Κάτοψη -12.50m | E13: 8 διαστήματα των 2.00 m c/c (ακριβής μέτρηση διαστημάτων)
A14: Μήκος Βορειοδυτικής Πλευράς (Πλάγιο τμήμα Ευαγόρου) | B14: 18 | C14: m | D14: Σχέδιο Σ01.1, Κάτοψη -12.50m | E14: 9 διαστήματα των 2.00 m c/c (από καμπή έως γωνία NW)
A15: Μήκος Βόρειας Πλευράς (Κατά μήκος Μενάνδρου) | B15: 54 | C15: m | D15: Σχέδιο Σ01.1, Κάτοψη -12.50m | E15: 27 διαστήματα των 2.00 m c/c (από γωνία NW έως NE)
A16: Μήκος Ανατολικής Πλευράς (Ανατολικό όριο) | B16: 22 | C16: m | D16: Σχέδιο Σ01.1, Κάτοψη -12.50m | E16: 11 διαστήματα των 2.00 m c/c (από γωνία NE έως SE)
A17: Μήκος Νότιας Πλευράς (Κατά μήκος Ανδρέα Δημητρίου) | B17: 86 | C17: m | D17: Σχέδιο Σ01.1, Κάτοψη -12.50m | E17: 43 διαστήματα των 2.00 m c/c (από γωνία SE έως SW)
A18: Ελεύθερο Ύψος Εκσκαφής Μετώπου (H_exc) | B18: 12.5 | C18: m | D18: Σχέδιο Σ02.1, Τομή 1-1 | E18: 15.50m βάθος διάτρησης μείον 3.00m πάκτωση
A19: Βάθος Πάκτωσης Πασσάλων κάτω από Εκσκαφή (H_embed) | B19: 3 | C19: m | D19: Σχέδιο Σ01.1 & Σ02.1 | E19: [ΣΥΓΚΡΟΥΣΗ ΜΕΛΕΤΗΣ]: 3.00m στο Σ01.1 vs 2.50m στο Σ02.1. Επιλογή ασφαλέστερου 3.00m.
A21: Α.3 Σχάρες Οπλισμού & Εκτοξευόμενο Σκυρόδεμα (Gunite / Shotcrete)
A22: Οριζόντιος Οπλισμός Σχάρας Μελέτης | B22: Y20 / 200 | C22: διατομή | D22: Σχέδιο Σ02.1, Τομή 1-1 | E22: Διάμετρος 20 mm ανά 200 mm c/c
A23: Διάμετρος Οριζόντιων Ράβδων | B23: 20 | C23: mm | D23: Σχέδιο Σ02.1, Τομή 1-1 | E23: Ράβδοι B500C
A24: Βήμα Οριζόντιων Ράβδων | B24: 200 | C24: mm | D24: Σχέδιο Σ02.1, Τομή 1-1 | E24: 5 ράβδοι ανά μέτρο ύψους
A25: Κατακόρυφος Οπλισμός Σχάρας Μελέτης | B25: Y14 / 200 | C25: διατομή | D25: Σχέδιο Σ02.1, Τομή 1-1 | E25: Διάμετρος 14 mm ανά 200 mm c/c
A26: Διάμετρος Κατακόρυφων Ράβδων | B26: 14 | C26: mm | D26: Σχέδιο Σ02.1, Τομή 1-1 | E26: Ράβδοι B500C
A27: Βήμα Κατακόρυφων Ράβδων | B27: 200 | C27: mm | D27: Σχέδιο Σ02.1, Τομή 1-1 | E27: 5 ράβδοι ανά μέτρο μήκους
A28: Ονομαστικό Πάχος Shotcrete Μελέτης (t_nom) | B28: 0.15 | C28: m | D28: Σχέδιο Σ02.1, Τομή 1-1 | E28: 150 mm ελάχιστο πάχος επικάλυψης σχεδίου
A29: Πάγια Απώλεια / Αναπήδηση Εταιρείας | B29: 0.05 | C29: m | D29: Πολιτική Εταιρείας v2 | E29: +5 cm πάγια προσαύξηση εταιρείας
A30: Κατηγορία Σκυροδέματος Μελέτης | B30: C30/40 CEMII 42.5 | C30: κατηγορία | D30: Σχέδιο Σ02.1, Σημειώσεις Υλικών | E30: Πρόσμικτα RHEOMAC SE 100 56 & Sigunit L 22E
A32: Α.4 H-Beams (Πασσαλοκολώνες 2×UPN 350, Διάτρηση Ø800 & Λάμες)
A33: Αξονική Απόσταση Πασσάλων (s_beam) | B33: 2 | C33: m | D33: Σχέδιο Σ01.1, Κάτοψη -12.50m | E33: Ανά 2.00 m c/c στην περίμετρο
A34: Συνολικό Πλήθος Οπών / Πασσάλων Έργου | B34: 98 | C34: οπές / πάσσαλοι | D34: Σχέδιο Σ01.1, Κάτοψη -12.50m | E34: 98 διαστήματα των 2.0m c/c (196m περίμετρος)
A35: Διάμετρος Διάτρησης Μεγάλου Τρυπανιού (min Ø800 mm) | B35: 0.8 | C35: m | D35: Σχέδιο Σ02.1 & Κανόνας v2 | E35: [OVERRIDE ΚΑΝΟΝΑ v2]: Ζητήθηκε Ø600 mm. Εφαρμόζεται υποχρεωτικά Ø800 mm.
A36: Συνολικό Βάθος Διάτρησης Μεγάλου Τρυπανιού | B36: 15.5 | C36: m | D36: Σχέδιο Σ02.1, Τομή 1-1 | E36: Βάθος κάτω από δημόσιο δρόμο > 15.50 m
A37: Τύπος Μεταλλικού Προφίλ Νέφκας | B37: 2xUPN 350x100 | C37: προφίλ | D37: Σχέδιο Σ02.1, Τομή 1-1 | E37: 2 κοιλοδοκοί UPN 350 ανά οπή
A38: Μήκος Μεταλλικής Κολώνας (h) | B38: 15 | C38: m | D38: Σχέδιο Σ02.1, Τομή 1-1 | E38: Βυθίζεται 0.50m κάτω από ισόγειο
A39: Πλήθος Προφίλ ανά Οπή | B39: 2 | C39: προφίλ / οπή | D39: Σχέδιο Σ02.1, Τομή 1-1 | E39: Διπλό UPN 350
A40: Θεωρητικό Βάρος Προφίλ ανά Μέτρο | B40: 60.6 | C40: kg / m | D40: Πίνακας Διατομών UPN 350 | E40: 60.6 kg/m ανά UPN (Σύνολο 121.2 kg/m)
A41: Διαστάσεις Συνδετικής Λάμας (Πλάτος W x Μήκος L x Πάχος t) | B41: 350 x 100 x 12 | C41: mm | D41: Σχέδιο Σ02.1, Λεπτομέρεια Νέφκας | E41: PLT 350x100x12 mm
A42: Βήμα Τοποθέτησης Λαμών κατά Ύψος (s_plate) | B42: 0.6 | C42: m | D42: Σχέδιο Σ02.1, Τομή 1-1 | E42: Απόσταση που ζητά ο μελετητής ανά 0.60 m
A43: Ύψος Σκυροδέματος Πάκτωσης Πασσάλου | B43: 3 | C43: m | D43: Σχέδιο Σ01.1 & Σ02.1 | E43: [ΣΥΓΚΡΟΥΣΗ ΜΕΛΕΤΗΣ]: 3.00m στο Σ01.1 vs 2.50m στο Σ02.1. Επιλογή 3.00m.
A44: Κατηγορία Σκυροδέματος Πάκτωσης (Κανόνας v2) | B44: C35/45 | C44: κατηγορία | D44: Σχέδιο Σ01.1 & Σ02.1 | E44: [ΣΥΓΚΡΟΥΣΗ ΜΕΛΕΤΗΣ]: Επιλογή ανώτερου C35/45 (Σ01.1) έναντι C30/37 (Σ02.1).
...

Sheet 2_Υπολογισμοί_&_Κοστολόγηση
A1: ΕΡΓΟ: TOFARCO "ΑΘΗΝΑΙΟΝ" (TIVOLI PROPERTY LTD) — BERLIN WALL & ΑΓΚΥΡΩΣΕΙΣ
A2: ΦΥΛΛΟ 2: ΟΙΚΟΝΟΜΙΚΗ ΚΟΣΤΟΛΟΓΗΣΗ & ΠΡΟΣΦΟΡΑ (4 ΠΥΛΩΝΕΣ) | ΟΛΑ ΤΑ ΠΟΣΑ ΣΕ ΕΥΡΩ (€)
A4: Α/Α | B4: Περιγραφή Εργασίας / Υλικού | C4: Ποσότητα Μελέτης [ΑΠΟ ΦΥΛΛΟ 1] | D4: Μονάδα | E4: Τιμή Μονάδας (€) [ΚΙΤΡΙΝΟ = ΑΛΛΑΖΕΙ] | F4: Σύνολο (€) | G4: Τεχνική Σημείωση / Παραπομπή
A5: ΠΥΛΩΝΑΣ 1: ΜΕΤΑΚΙΝΗΣΕΙΣ ΕΞΟΠΛΙΣΜΟΥ (3 ΕΙΔΗ ΜΕΤΑΚΙΝΗΣΕΩΝ)
A6: 1.1 | B6: Μετακίνηση Μεγάλου Τρυπανιού (Piling Rig) | C6: ='1_Στοιχεία_Μελέτης_&_Ποσότητες'!B62 | D6: στράτες | E6: 3000 | F6: =C6*E6 | G6: Λευκωσία (>80 km από έδρα Αγίου Συλά)
A7: 1.2 | B7: Μετακινήσεις Εξοπλισμού Αγκυρώσεων | C7: ='1_Στοιχεία_Μελέτης_&_Ποσότητες'!B63 | D7: στράτες | E7: 400 | F7: =C7*E7 | G7: 4 στράτες (όσες οι σειρές αγκυρώσεων)
A8: 1.3 | B8: Μετακινήσεις Συνεργείου & Αντλίας Shotcrete | C8: ='1_Στοιχεία_Μελέτης_&_Ποσότητες'!B64 | D8: στράτες | E8: 300 | F8: =C8*E8 | G8: 5 στράτες (σειρές αγκυρώσεων + 1)
B9: ΜΕΡΙΚΟ ΣΥΝΟΛΟ ΠΥΛΩΝΑ 1 (ΜΕΤΑΚΙΝΗΣΕΙΣ): | F9: =SUM(F6:F8)
A11: ΠΥΛΩΝΑΣ 2: ΣΧΑΡΕΣ ΟΠΛΙΣΜΟΥ & ΕΚΤΟΞΕΥΟΜΕΝΟ ΣΚΥΡΟΔΕΜΑ (GUNITE / SHOTCRETE)
A12: 2.1 | B12: ="Αγορά Χάλυβα Σχάρας (" & '1_Στοιχεία_Μελέτης_&_Ποσότητες'!B22 & " + " & '1_Στοιχεία_Μελέτης_&_Ποσότητες'!B25 & ")" | C12: ='1_Στοιχεία_Μελέτης_&_Ποσότητες'!B72 | D12: kg | E12: 2.5 | F12: =C12*E12 | G12: B500C (Y20/200 + Y14/200)
A13: 2.2 | B13: Τοποθέτηση & Εργατικά Σχάρας Μετώπου | C13: ='1_Στοιχεία_Μελέτης_&_Ποσότητες'!B68 | D13: m² | E13: 15 | F13: =C13*E13 | G13: Εργατικά τοποθέτησης ανά m² μετώπου
A14: 2.3 | B14: Αγορά Σκυροδέματος Shotcrete C30/40 | C14: ='1_Στοιχεία_Μελέτης_&_Ποσότητες'!B73 | D14: m³ | E14: 90 | F14: =C14*E14 | G14: Πάγια τιμή αγοράς 90 €/m³
A15: 2.4 | B15: Εφαρμογή, Άντληση & Εκτόξευση Shotcrete | C15: ='1_Στοιχεία_Μελέτης_&_Ποσότητες'!B73 | D15: m³ | E15: =ROUND((200*(1+'1_Στοιχεία_Μελέτης_&_Ποσότητες'!B74))-90, 2) | F15: =C15*E15 | G15: Τιμή εφαρμογής βάσει 200€ + 33.33% απώλεια μείον 90€
B16: ΜΕΡΙΚΟ ΣΥΝΟΛΟ ΠΥΛΩΝΑ 2 (ΣΧΑΡΕΣ & SHOTCRETE): | F16: =SUM(F12:F15)
A18: ΠΥΛΩΝΑΣ 3: ΜΕΤΑΛΛΙΚΕΣ ΚΟΛΩΝΕΣ (H-BEAMS) & ΠΑΣΣΑΛΟΙ BERLIN WALL
A19: 3.1 | B19: ="Διάτρηση Μεγάλου Τρυπανιού (Ø" & TEXT('1_Στοιχεία_Μελέτης_&_Ποσότητες'!B35*1000, "0") & " mm)" | C19: ='1_Στοιχεία_Μελέτης_&_Ποσότητες'!B78 | D19: m | E19: 75 | F19: =C19*E19 | G19: Ελάχιστη διάμετρος Ø800 mm βάσει κανόνα v2
A20: 3.2 | B20: ="Χάλυβας Νέφκων (" & '1_Στοιχεία_Μελέτης_&_Ποσότητες'!B37 & " @ 60.6 kg/m)" | C20: ='1_Στοιχεία_Μελέτης_&_Ποσότητες'!B81 | D20: kg | E20: 1.4 | F20: =C20*E20 | G20: 1.00 € αγορά + 0.40 € επεξεργασία
A21: 3.3 | B21: Λάμες Σύνδεσης / Ενίσχυσης PLT 350x100x12 mm | C21: ='1_Στοιχεία_Μελέτης_&_Ποσότητες'!B85 | D21: kg | E21: 1.6 | F21: =C21*E21 | G21: Υπολογισμός 25 λάμες/κολώνα (L/s) βάσει κανόνα v2
A22: 3.4 | B22: Κουγκρί Πάκτωσης Πασσάλων (H=3.0 m, Ø800 mm) | C22: ='1_Στοιχεία_Μελέτης_&_Ποσότητες'!B87 | D22: m³ | E22: 120 | F22: =C22*E22 | G22: [ΣΥΓΚΡΟΥΣΗ]: Επιλογή C35/45 στα 3.0m (έντονη επισήμανση)
A23: 3.5 | B23: Γωνιές Στήριξης (Equal Angles L) | C23: 0 | D23: kg | E23: 1.6 | F23: =C23*E23 | G23: Δεν ζητήθηκαν γωνιές στήριξης στα σχέδια
B24: ΜΕΡΙΚΟ ΣΥΝΟΛΟ ΠΥΛΩΝΑ 3 (H-BEAMS & ΠΑΣΣΑΛΟΙ): | F24: =SUM(F19:F23)
A26: ΠΥΛΩΝΑΣ 4: ΠΡΟΕΝΤΕΤΑΜΕΝΕΣ ΑΓΚΥΡΩΣΕΙΣ ΕΔΑΦΟΥΣ (TIEBACK ANCHORS)
A27: 4.1 | B27: ="Διάτρηση Αγκυρώσεων (Ø" & TEXT('1_Στοιχεία_Μελέτης_&_Ποσότητες'!B54*1000, "0") & " mm)" | C27: ='1_Στοιχεία_Μελέτης_&_Ποσότητες'!B91 | D27: m | E27: 30 | F27: =C27*E27 | G27: Διάτρηση Ø150 mm σε βάθη 13.30 m
A28: 4.2 | B28: Grout Τσιμεντενέματος Πλήρωσης Αγκυρώσεων | C28: ='1_Στοιχεία_Μελέτης_&_Ποσότητες'!B93 | D28: m³ | E28: 500 | F28: =C28*E28 | G28: Grout υψηλής αντοχής fcu > 80 N/mm²
A29: 4.3 | B29: Τένοντες Προέντασης (5 Strands 0.6" - 1.10 kg/m) | C29: ='1_Στοιχεία_Μελέτης_&_Ποσότητες'!B94 | D29: m | E29: 2.28 | F29: =C29*E29 | G29: 5 κλώνοι x 14.3m x 1.10 kg/m
A30: 4.4 | B30: Προένταση Αγκυρώσεων (Stressing & Lock-off) | C30: ='1_Στοιχεία_Μελέτης_&_Ποσότητες'!B97 | D30: τεμ | E30: 18 | F30: =C30*E30 | G30: Τάνυση, δοκιμή καταλληλότητας & κλείδωμα
A31: 4.5 | B31: Κεφαλή Αγκύρωσης, Σφήνες & Πλάκα Έδρασης | C31: ='1_Στοιχεία_Μελέτης_&_Ποσότητες'!B98 | D31: τεμ | E31: 55 | F31: =C31*E31 | G31: Πλήρες σετ κεφαλής έδρασης
B32: ΜΕΡΙΚΟ ΣΥΝΟΛΟ ΠΥΛΩΝΑ 4 (ΑΓΚΥΡΩΣΕΙΣ): | F32: =SUM(F27:F31)
B34: ΚΑΘΑΡΟ ΣΥΝΟΛΟ ΕΡΓΟΥ (ΑΘΡΟΙΣΜΑ 4 ΠΥΛΩΝΩΝ): | F34: =F9+F16+F24+F32
B35: Φ.Π.Α. (19%): | F35: =ROUND(F34*0.19, 2)
B36: ΤΕΛΙΚΟ ΣΥΝΟΛΟ ΜΕ Φ.Π.Α. (ΠΛΗΡΩΤΕΟ): | F36: =F34+F35
A38: ΒΑΣΙΚΟΙ ΔΕΙΚΤΕΣ ΚΟΣΤΟΥΣ ΕΡΓΟΥ (KEY PERFORMANCE INDICATORS - KPIs)
B39: Κόστος ανά m² Μετώπου Αντιστήριξης | D39: € / m² | F39: =ROUND(F34/'1_Στοιχεία_Μελέτης_&_Ποσότητες'!B68, 2) | G39: Καθαρό κόστος ανά τετραγωνικό μέτρο όψης
B40: Κόστος ανά Τρέχον Μέτρο Περιμέτρου Εκσκαφής | D40: € / m | F40: =ROUND(F34/'1_Στοιχεία_Μελέτης_&_Ποσότητες'!B67, 2) | G40: Καθαρό κόστος ανά μέτρο περιμέτρου
B41: Κόστος ανά Πάσσαλο / Οπή Berlin Wall | D41: € / πάσσαλο | F41: =ROUND(F34/'1_Στοιχεία_Μελέτης_&_Ποσότητες'!B34, 2) | G41: Συνολικό κόστος επιμερισμένο ανά πάσσαλο
B42: Κόστος ανά Αγκύρωση Έργου (Πυλώνας 4) | D42: € / αγκύρωση | F42: =ROUND(F32/'1_Στοιχεία_Μελέτης_&_Ποσότητες'!B90, 2) | G42: Κόστος αγκυρώσεων ανά τεμάχιο αγκύρωσης

Sheet 3_Πίνακες_Διατομών_Χάλυβα
A1: ΒΙΒΛΙΟΘΗΚΗ ΔΙΑΤΟΜΩΝ ΧΑΛΥΒΑ BERLIN WALL & ΑΓΚΥΡΩΣΕΩΝ
A2: ΤΥΠΟΠΟΙΗΜΕΝΕΣ ΔΙΑΤΟΜΕΣ HEA, HEB, HEM, UPN, IPE & ΙΣΟΣΚΕΛΕΙΣ ΓΩΝΙΕΣ (L)
A4: Διατομή | B4: Ύψος h (mm) | C4: Πλάτος b (mm) | D4: Πάχος tw (mm) | E4: Πάχος tf (mm) | F4: Βάρος (kg/m) | G4: Χρήση / Εφαρμογή Berlin Wall
A5: ΚΟΙΛΟΔΟΚΟΙ UPN (EN 10365) — ΤΥΠΙΚΗ ΕΦΑΡΜΟΓΗ TOFARCO
A6: UPN 160 | B6: 160 | C6: 65 | D6: 7.5 | E6: 10.5 | F6: 18.8 | G6: Ελαφριές πασσαλοκολώνες
A7: UPN 180 | B7: 180 | C7: 70 | D7: 8 | E7: 11 | F7: 22 | G7: Ελαφριές πασσαλοκολώνες
A8: UPN 200 | B8: 200 | C8: 75 | D8: 8.5 | E8: 11.5 | F8: 25.3 | G8: Συνήθης διατομή Berlin Wall
A9: UPN 220 | B9: 220 | C9: 80 | D9: 9 | E9: 12.5 | F9: 29.4 | G9: Μεσαίο βάθος αντιστήριξης
A10: UPN 240 | B10: 240 | C10: 85 | D10: 9.5 | E10: 13 | F10: 33.2 | G10: Μεσαίο βάθος αντιστήριξης
A11: UPN 260 | B11: 260 | C11: 90 | D11: 10 | E11: 14 | F11: 37.9 | G11: Βαριά αντιστήριξη
A12: UPN 280 | B12: 280 | C12: 95 | D12: 10 | E12: 15 | F12: 41.8 | G12: Βαριά αντιστήριξη
A13: UPN 300 | B13: 300 | C13: 100 | D13: 10 | E13: 16 | F13: 46.2 | G13: Βαριά αντιστήριξη
A14: UPN 350 | B14: 350 | C14: 100 | D14: 14 | E14: 16 | F14: 60.6 | G14: ⭐ TOFARCO ATHENION (2xUPN 350)
A15: UPN 400 | B15: 400 | C15: 110 | D15: 14 | E15: 18 | F15: 71.8 | G15: Πολύ μεγάλα βάθη
A16: ΔΙΑΤΟΜΕΣ HEB (IPB / EN 10365) — ΠΑΣΣΑΛΟΚΟΛΩΝΕΣ ΜΕΓΑΛΗΣ ΔΥΣΚΑΜΨΙΑΣ
A17: HEB 180 | B17: 180 | C17: 180 | D17: 8.5 | E17: 14 | F17: 51.2 | G17: Μικρό/Μεσαίο βάθος
A18: HEB 200 | B18: 200 | C18: 200 | D18: 9 | E18: 15 | F18: 61.3 | G18: Συνήθης πασσαλοκολώνα
A19: HEB 220 | B19: 220 | C19: 220 | D19: 9.5 | E19: 16 | F19: 71.5 | G19: Συνήθης πασσαλοκολώνα
A20: HEB 240 | B20: 240 | C20: 240 | D20: 10 | E20: 17 | F20: 83.2 | G20: Μεγάλα βάθη & ωθήσεις
A21: HEB 260 | B21: 260 | C21: 260 | D21: 10 | E21: 17.5 | F21: 93 | G21: Μεγάλα βάθη & ωθήσεις
A22: HEB 280 | B22: 280 | C22: 280 | D22: 10.5 | E22: 18 | F22: 103 | G22: Πολύ βαριά αντιστήριξη
A23: HEB 300 | B23: 300 | C23: 300 | D23: 11 | E23: 19 | F23: 117 | G23: Πολύ βαριά αντιστήριξη
A24: ΔΙΑΤΟΜΕΣ HEA (IPBl / EN 10365) — ΕΛΑΦΡΙΑ ΣΕΙΡΑ
A25: HEA 180 | B25: 171 | C25: 180 | D25: 6 | E25: 9.5 | F25: 35.5 | G25: Ελαφριά αντιστήριξη
A26: HEA 200 | B26: 190 | C26: 200 | D26: 6.5 | E26: 10 | F26: 42.3 | G26: Ελαφριά αντιστήριξη
A27: HEA 220 | B27: 210 | C27: 220 | D27: 7 | E27: 11 | F27: 50.5 | G27: Μεσαίο βάθος
A28: HEA 240 | B28: 230 | C28: 240 | D28: 7.5 | E28: 12 | F28: 60.3 | G28: Μεσαίο βάθος
A29: HEA 260 | B29: 250 | C29: 260 | D29: 7.5 | E29: 12.5 | F29: 68.2 | G29: Μεγάλο βάθος
A30: HEA 280 | B30: 270 | C30: 280 | D30: 8 | E30: 13 | F30: 76.4 | G30: Μεγάλο βάθος
A31: HEA 300 | B31: 290 | C31: 300 | D31: 8.5 | E31: 14 | F31: 88.3 | G31: Βαριά αντιστήριξη
A32: ΙΣΟΣΚΕΛΕΙΣ ΓΩΝΙΕΣ L (EN 10056) — ΓΩΝΙΕΣ ΣΤΗΡΙΞΗΣ & ΣΥΝΔΕΣΕΙΣ
A33: L 50x50x5 | B33: 50 | C33: 50 | D33: 5 | E33: 5 | F33: 3.77 | G33: Ελαφριές συνδέσεις
A34: L 60x60x6 | B34: 60 | C34: 60 | D34: 6 | E34: 6 | F34: 5.42 | G34: Συνδέσεις λαμών
A35: L 70x70x7 | B35: 70 | C35: 70 | D35: 7 | E35: 7 | F35: 7.38 | G35: Συνδέσεις λαμών & σχαρών
A36: L 80x80x8 | B36: 80 | C36: 80 | D36: 8 | E36: 8 | F36: 9.63 | G36: Βαριές συνδέσεις
A37: L 100x100x10 | B37: 100 | C37: 100 | D37: 10 | E37: 10 | F37: 15 | G37: Στηρίξεις κεφαλών
