Workbook

Sheet Οικονομική Προσφορά
B2: ΟΙΚΟΝΟΜΙΚΗ ΠΡΟΣΦΟΡΑ ΠΑΣΣΑΛΩΝ ΘΕΜΕΛΙΩΣΗΣ
B3: Προϋπολογισμός Έργου για τον Πελάτη (Τιμολόγιο) — Επιμερισμός Μετακινήσεων, Τρύπημα, Κουγκρί & Χάλυβας
B5: ΠΙΝΑΚΑΣ ΟΙΚΟΝΟΜΙΚΗΣ ΠΡΟΣΦΟΡΑΣ (ΤΙΜΟΛΟΓΙΟ)
B6: A/A | C6: Περιγραφή Εργασίας / Υλικού | D6: Ποσότητα ανά Πάσσαλο | E6: Μονάδα | F6: Τιμή Μονάδας (€) | G6: Κόστος ανά Πάσσαλο (€) | H6: Σύνολο Όλων των Πασσάλων (€)
B7: 1 | C7: Μετακινήσεις & Εγκατάσταση Εξοπλισμού Γεωτρύπανου (Mobilization) | D7: 1 | E7: πάσσαλος | F7: ='Τεχνικοί Υπολογισμοί'!C9 -> 75 | G7: =D7*F7 -> 75 | H7: =G7*'Τεχνικοί Υπολογισμοί'!C14 -> 600
B8: 2 | C8: Τρύπημα / Διάτρηση Πασσάλων Ø600mm | D8: ='Τεχνικοί Υπολογισμοί'!D20 -> 4 | E8: m | F8: 70 | G8: =D8*F8 -> 280 | H8: =G8*'Τεχνικοί Υπολογισμοί'!C14 -> 2240
B9: 3 | C9: Σκυροδέτηση Πασσάλων (Κουγκρί με 10% απώλεια) | D9: ='Τεχνικοί Υπολογισμοί'!D21 -> 1.2440707 | E9: m³ | F9: 123 | G9: =D9*F9 -> 153.02069 | H9: =G9*'Τεχνικοί Υπολογισμοί'!C14 -> 1224.1656
B10: 4 | C10: Χάλυβας Οπλισμού (Σούστα & Κάθετες Ράβδοι B500C) | D10: ='Τεχνικοί Υπολογισμοί'!D22 -> 171.50247 | E10: kg | F10: 1.1 | G10: =D10*F10 -> 188.65272 | H10: =G10*'Τεχνικοί Υπολογισμοί'!C14 -> 1509.2217
B11: ΣΥΝΟΛΟ | C11: ΓΕΝΙΚΟ ΣΥΝΟΛΟ ΠΡΟΣΦΟΡΑΣ (GRAND TOTAL) | D11: - | E11: - | F11: - | G11: =SUM(G7:G10) -> 696.67341 | H11: =SUM(H7:H10) -> 5573.3873
B13: ΟΡΟΙ & ΠΑΡΑΤΗΡΗΣΕΙΣ ΠΡΟΣΦΟΡΑΣ:
B14: 1. Στις τιμές περιλαμβάνονται όλα τα απαιτούμενα υλικά, εργασία και μηχανολογικός εξοπλισμός για την πλήρη κατασκευή των πασσάλων. 2. Η τιμή μετακίνησης επιμερίζεται ισόποσα στο κόστος ανά πάσσαλο (500 € / 8 = 62.50 €/πάσσαλο). 3. Το τρύπημα τιμολογείται σε τρέχοντα μέτρα (m) διάτρησης. 4. Στο σκυρόδεμα υπολογίζεται συντελεστής απώλειας 10% (loss factor) επί του γεωμετρικού όγκου. 5. Ο χάλυβας οπλισμού (B500C) τιμολογείται με ενιαία τιμή 1.10 €/kg τόσο για τις κάθετες ράβδους όσο και για τη σούστα. 6. Αναλυτική τεχνική τεκμηρίωση και μαθηματικοί τύποι παρατίθενται στη σελίδα 'Τεχνικοί Υπολογισμοί'.

Sheet Τεχνικοί Υπολογισμοί
B2: ΤΕΧΝΙΚΗ ΤΕΚΜΗΡΙΩΣΗ & ΜΑΘΗΜΑΤΙΚΟΙ ΥΠΟΛΟΓΙΣΜΟΙ ΠΑΣΣΑΛΩΝ
B3: Δεδομένα Σχεδίου, Τελικές Ποσότητες Προσφοράς, Σταθερές Παραδοχές & Αναλυτικά Μαθηματικά
B5: 1. ΔΕΔΟΜΕΝΑ ΠΟΥ ΔΙΑΒΑΣΤΗΚΑΝ ΑΠΟ ΤΟ ΣΧΕΔΙΟ (ΚΑΘΕΤΟΣ ΔΙΑΧΩΡΙΣΜΟΣ)
B6: ΤΟΜΕΑΣ 1: ΜΕΤΑΚΙΝΗΣΕΙΣ (MOBILIZATION) | F6: ΤΟΜΕΑΣ 3: ΚΛΩΒΟΣ ΟΠΛΙΣΜΟΥ & ΠΡΟΔΙΑΓΡΑΦΕΣ
B7: Συνολικό Ποσό Μετακινήσεων Γεωτρύπανου | C7: 600 | D7: € | F7: Κάθετες Ράβδοι - Πλήθος (Nvert) | G7: 12 | H7: τεμ. | I7: 12 ράβδοι στην περίμετρο
B8: Εφάπαξ κατ' αποκοπή ποσό για το εργοτάξιο (θέστε 0 αν δεν χρεώνεται) | F8: Κάθετες Ράβδοι - Διάμετρος (Yvert) | G8: 20 | H8: mm | I8: Y20 (Ø20 mm)
B9: Τιμή Μετακίνησης ανά Πάσσαλο (Επιμερισμός) | C9: =C7/C14 -> 75 | D9: € / πάσσαλο | F9: Starter / Αναμονή στο Πέδιλο | G9: 0.5 | H9: m | I9: 50 cm (Foundation height 0.50m)
F10: Γωνία Πάνω (Top Bend / Hook) | G10: 0.5 | H10: m | I10: 50 cm (Οριζόντιο άγκιστρο στο σχέδιο)
B11: ΤΟΜΕΑΣ 2: ΣΚΥΡΟΔΕΜΑ & ΤΡΥΠΗΜΑ | F11: Γωνία στον Πυθμένα (Bottom Bend) | G11: 0 | H11: m | I11: Δεν δίνεται στο σχέδιο (0.00 m) / Δεν απαιτείται
B12: Διάμετρος Τρύπας Πασσάλου (D) | C12: 600 | D12: mm | F12: Επικάλυψη Οπλισμού (Cover) | G12: 75 | H12: mm | I12: 7.5 cm ανά πλευρά (Προεπιλογή αν δεν δίνεται)
B13: Βάθος Διάτρησης στο Έδαφος (L) | C13: 4 | D13: m | F13: Σούστα - Διάμετρος (Yspiral) | G13: 10 | H13: mm | I13: Y10 (Ø10 mm)
B14: Αριθμός Πασσάλων Έργου (Τρύπες) | C14: 8 | D14: τεμ. | F14: Σούστα - Βήμα / Απόσταση (s) | G14: 150 | H14: mm | I14: Βήμα σπείρας ανά 15 cm
F15: Αριθμός Ματίσεων ανά Ράβδο | G15: =IF((C13+G9+G10+G11)>D28, INT(((C13+G9+G10+G11)-0.001)/D28), 0) -> 0 | H15: ματίσεις | I15: Αυτόματος υπολογισμός αν L_bar > 12m
F16: Μήκος Μάτισης (Κανόνας 50×Φ) | G16: =D29*(G8/1000) -> 0.24 | H16: m | I16: 50 φορές το πάχος: 50×20mm = 1.00m
B18: 2. ΤΕΛΙΚΕΣ ΠΟΣΟΤΗΤΕΣ ΓΙΑ ΤΗΝ ΟΙΚΟΝΟΜΙΚΗ ΠΡΟΣΦΟΡΑ (ΣΥΝΟΨΗ ΑΠΟΤΕΛΕΣΜΑΤΩΝ)
B19: A/A | C19: Μέγεθος / Τελικός Υπολογισμός | D19: Ποσότητα ανά Πάσσαλο | E19: Μονάδα | F19: Σύνολο Έργου (όλοι οι πάσσαλοι) | G19: Μονάδα | H19: Μαθηματικός Τύπος & Σημείωση
B20: 1 | C20: Τρέχοντα Μέτρα Τρυπήματος (Διάτρηση) | D20: =D35 -> 4 | E20: m | F20: =D20*C14 -> 32 | G20: m | H20: L_drill = L = 4.00 m ανά πάσσαλο (Σύνολο 32.00 m)
B21: 2 | C21: Όγκος Σκυροδέματος (Κουγκρί με 10% απώλεια) | D21: =D37 -> 1.2440707 | E21: m³ | F21: =D21*C14 -> 9.9525655 | G21: m³ | H21: V_conc = V_exc × (1 + 10%) = 1.131 × 1.10 = 1.244 m³ ανά πάσσαλο
B22: 3 | C22: Συνολικό Βάρος Χάλυβα Οπλισμού (B500C) | D22: =D46 -> 171.50247 | E22: kg | F22: =D22*C14 -> 1372.0198 | G22: kg | H22: W_steel = Κάθετες (147.97 kg) + Σούστα (23.53 kg) = 171.50 kg ανά πάσσαλο
B25: 3. ΣΤΑΘΕΡΕΣ ΤΕΧΝΙΚΕΣ ΠΑΡΑΔΟΧΕΣ & ΚΑΝΟΝΕΣ (ΔΕΝ ΑΛΛΑΖΟΥΝ - ΔΕΝ ΠΕΡΙΛΑΜΒΑΝΟΝΤΑΙ ΣΤΑ ΔΕΔΟΜΕΝΑ ΣΧΕΔΙΟΥ)
B26: A/A | C26: Σταθερά / Παραδοχή | D26: Τιμή | E26: Μονάδα | F26: Κανόνας & Τεχνική Επεξήγηση
B27: 1 | C27: Συντελεστής Απώλειας Σκυροδέματος | D27: 0.1 | E27: % | F27: Πάγια υπερκατανάλωση κουγκριού 10% (loss factor) για πλήρωση κοιλοτήτων
B28: 2 | C28: Ειδικό Βάρος / Πυκνότητα Χάλυβα (ρ) | D28: 7850 | E28: kg/m³ | F28: Φυσική πυκνότητα δομικού χάλυβα B500C για υπολογισμό βαρών
B29: 3 | C29: Μέγιστο Εμπορικό Μήκος Βέργας | D29: 12 | E29: m | F29: Βέργες εμπορίου 12 μέτρων (όριο για απαίτηση μάτισης ράβδων)
B30: 4 | C30: Συντελεστής Μήκους Μάτισης (Lapping) | D30: 50 | E30: × Φ | F30: Κανόνας επικάλυψης 50 φορές τη διάμετρο της ράβδου (50Φ)
B31: 5 | C31: Μαθηματική Σταθερά π | D31: =PI() -> 3.1415927 | E31: - | F31: Ακριβής σταθερά κύκλου (3.14159...) για εμβαδά και περιμέτρους
B33: 4. ΑΝΑΛΥΤΙΚΑ ΜΑΘΗΜΑΤΙΚΑ & ΒΗΜΑ-ΒΗΜΑ ΥΠΟΛΟΓΙΣΜΟΙ (ΜΕ ΤΟΥΣ ΤΥΠΟΥΣ ΩΣ ΣΗΜΕΙΩΣΕΙΣ)
B34: A/A | C34: Μέγεθος / Υπολογισμός | D34: Ποσότητα ανά Πάσσαλο | E34: Μονάδα | F34: Σύνολο Έργου (8 Πάσσαλοι) | G34: Μονάδα | H34: Μαθηματικός Τύπος & Αναλυτικές Σημειώσεις
B35: 1 | C35: Τρύπημα / Διάτρηση Πασσάλου (L_drill) | D35: =C13 -> 4 | E35: m | F35: =D35*C14 -> 32 | G35: m | H35: L_drill = L = 4.00 m ανά πάσσαλο
B36: 2 | C36: Γεωμετρικός Όγκος Εκσκαφής | D36: =PI()*(C12/1000)^2/4 * C13 -> 1.1309734 | E36: m³ | F36: =D36*C14 -> 9.0477868 | G36: m³ | H36: V_exc = (π × D² / 4) × L = π × 0.60² / 4 × 4.00 m = 1.131 m³
B37: 3 | C37: Όγκος Σκυροδέματος (Κουγκρί με 10% απώλεια) | D37: =D36*(1+D27) -> 1.2440707 | E37: m³ | F37: =D37*C14 -> 9.9525655 | G37: m³ | H37: V_conc = V_exc × (1 + 10%) = 1.131 × 1.10 = 1.244 m³
B38: 4 | C38: Διάμετρος Κλωβού Οπλισμού (Dcage) | D38: =(C12-2*G12)/1000 -> 0.45 | E38: m | F38: =(D38*1000) -> 450 | G38: mm | H38: Dcage = D - 2×Cover = 0.60m - 2×0.075m = 0.450 m (450 mm)
B39: 5 | C39: Περίμετρος Σπείρας Κλωβού (Πcage) | D39: =PI()*D38 -> 1.4137167 | E39: m | F39: - | G39: - | H39: Πcage = π × Dcage = π × 0.450 m = 1.414 m
B40: 6 | C40: Ανεπτυγμένο Μήκος Κάθετης Ράβδου (L_bar) | D40: =C13+G9+G10+G11+(G15*G16) -> 5 | E40: m | F40: - | G40: - | H40: L_bar = L(4m) + Starter(0.5m) + Γωνία_πάνω(0.5m) + Γωνία_πυθμ(0m) + Lapping(0m) = 5.00 m
B41: 7 | C41: Μοναδιαίο Βάρος Κάθετων Ράβδων (Y20) | D41: =PI()*(G8/1000)^2/4 * D28 -> 2.4661502 | E41: kg/m | F41: - | G41: - | H41: w_vert = (π × 0.020² / 4) × 7850 = 2.466 kg/m
B42: 8 | C42: Βάρος Κάθετου Οπλισμού (12Y20) | D42: =G7*D40*D41 -> 147.96901 | E42: kg | F42: =D42*C14 -> 1183.7521 | G42: kg | H42: W_vert = N_vert(12) × L_bar(5.00m) × w_vert(2.466 kg/m) = 147.97 kg
B43: 9 | C43: Αριθμός Σπειρών Σούστας (Y10/150) | D43: =ROUNDUP(C13/(G14/1000),0) -> 27 | E43: σπείρες | F43: =D43*C14 -> 216 | G43: σπείρες | H43: N_turns = ROUNDUP(L / pitch, 0) = ROUNDUP(4.00m / 0.15m, 0) = 27 σπείρες | J43: +1 πάντα διοτι ξεκινα με διπλη σουστα
B44: 10 | C44: Μοναδιαίο Βάρος Σούστας (Y10) | D44: =PI()*(G13/1000)^2/4 * D28 -> 0.61653756 | E44: kg/m | F44: - | G44: - | H44: w_spiral = (π × 0.010² / 4) × 7850 = 0.617 kg/m
B45: 11 | C45: Βάρος Σιδήρου Σούστας (Y10/150) | D45: =D43*D39*D44 -> 23.533455 | E45: kg | F45: =D45*C14 -> 188.26764 | G45: kg | H45: W_spiral = 27 σπείρες × 1.414 m × 0.617 kg/m = 23.53 kg
B46: 12 | C46: ΣΥΝΟΛΙΚΟ ΒΑΡΟΣ ΧΑΛΥΒΑ (TOTAL STEEL) | D46: =D42+D45 -> 171.50247 | E46: kg | F46: =D46*C14 -> 1372.0198 | G46: kg | H46: W_total = Κάθετες (147.97 kg) + Σούστα (23.53 kg) = 171.50 kg (1.372 tn σύνολο)
...
