Workbook

Sheet 1_Στοιχεία_Μελέτης_&_Ποσότητες
A1: ΕΡΓΟ: ST788 LEXUM — ΣΤΟΙΧΕΙΑ ΜΕΛΕΤΗΣ & ΦΥΣΙΚΕΣ ΠΟΣΟΤΗΤΕΣ (ΧΩΡΙΣ ΕΥΡΩ)
A2: ΧΩΡΙΣΜΕΝΟ ΣΕ 2 ΜΕΓΑΛΑ ΚΕΦΑΛΑΙΑ: [ΚΕΦΑΛΑΙΟ Α] = ΜΟΝΟ ΣΤΟΙΧΕΙΑ ΜΕΛΕΤΗΣ | [ΚΕΦΑΛΑΙΟ Β] = ΟΛΟΙ ΟΙ ΥΠΟΛΟΓΙΣΜΟΙ
A4: 🏛️ ΚΕΦΑΛΑΙΟ Α: ΜΟΝΟ ΣΤΟΙΧΕΙΑ ΠΟΥ ΔΙΑΒΑΣΤΗΚΑΝ ΑΠΟ ΤΗ ΜΕΛΕΤΗ (RAW INPUTS)
A5: Α.1 Τοποθεσία Εργοταξίου, Έδρα & Σειρές ανά Ζώνη Μελέτης
A6: Έδρα Εταιρείας (Αφετηρία) | B6: Άγιος Συλάς, Σπύρου Κυπριανού 32, Λεμεσός | C6: - | D6: Σταθερή βάση εκκίνησης συνεργείων
A7: Τοποθεσία Εργοταξίου | B7: ST788 Lexum | C7: - | D7: Από κατασκευαστική λεπτομέρεια ASD-ST788-GEO-NAIL-03
A8: Χιλιομετρική Απόσταση από Έδρα | B8: 25 | C8: km | D8: Απόσταση < 50 km από Άγιο Συλά (Ζώνη 1: 0–50 km)
A9: Πλήθος Οριζόντιων Σειρών Ήλων Ζώνης Α | B9: 4 | C9: σειρές | D9: 4 οριζόντιες σειρές ήλων στη Ζώνη Α (H = 9.0m)
A10: Πλήθος Οριζόντιων Σειρών Ήλων Ζώνης Β | B10: 2 | C10: σειρές | D10: 2 οριζόντιες σειρές ήλων στη Ζώνη Β (H = 4.0m)
A12: Α.2 Γεωμετρία Μετώπου Εκσκαφής (Ανά Ζώνη)
A13: Μήκος Μετώπου Ζώνης Α (L_A) | B13: 50 | C13: m | D13: Δόθηκε από χρήστη (50.00 τρέχοντα μέτρα)
A14: Ύψος / Βάθος Ζώνης Α (H_A) | B14: 9 | C14: m | D14: Από σχέδιο (H = 9.0 m, q = 15 kPa τοίχος γείτονα)
A15: Μήκος Μετώπου Ζώνης Β (L_B) | B15: 27 | C15: m | D15: Δόθηκε από χρήστη (27.00 τρέχοντα μέτρα)
A16: Ύψος / Βάθος Ζώνης Β (H_B) | B16: 4 | C16: m | D16: Από σχέδιο (H = 4.0 m, q = 0 πλευρά δρόμου)
A18: Α.3 Σχάρες Μετώπου (Wire Mesh Grid)
A19: Τύπος Χάλυβα Σχάρας | B19: B500A Δομικό Πλέγμα | C19: - | D19: Από λεπτομέρεια (Πλέγμα πλάκας Φ10/150mm αμφίδρομα)
A20: Διάμετρος Ράβδων Σχάρας (mm) | B20: 10 | C20: mm | D20: Φ10 (Y10) αμφίδρομα
A21: Οριζόντιο Βήμα Ράβδων (s_horiz) | B21: 150 | C21: mm | D21: Απόσταση οριζόντιων ράβδων 150 mm
A22: Κάθετο Βήμα Ράβδων (s_vert) | B22: 150 | C22: mm | D22: Απόσταση κάθετων ράβδων 150 mm
A24: Α.4 Εκτοξευόμενο Σκυρόδεμα (Shotcrete)
A25: Κατηγορία Σκυροδέματος Shotcrete | B25: C25/30 | C25: - | D25: Από σχέδιο (Σκυρόδεμα πλάκας C25/30, h=150mm)
A26: Ονομαστικό Πάχος Σκυροδέματος Μελέτης | B26: 0.15 | C26: m | D26: 150 mm ονομαστικό πάχος (2 στρώσεις ~75mm, Λεπτομέρεια Δ)
A27: Πάγια Απώλεια / Αναπήδηση Εταιρείας | B27: 0.05 | C27: m | D27: +5 cm πάγια προσαύξηση εταιρείας (χρεώνεται στα €/m³)
A29: Α.5 Εδαφοηλώσεις (Ράβδοι, Διατάξεις, Grout, Πλάκες & Nuts)
A30: Διάμετρος Ράβδων Ήλωσης B500C (mm) | B30: 32 | C30: mm | D30: Ήλοι Τ32 B500C (Y32) από σχέδιο και λεπτομέρεια Δ
A31: Ζώνη Α: Μήκος Ήλων Σειρών 1, 2, 4 (L < 6m) | B31: 5.8 | C31: m | D31: 3 σειρές των 5.80 m (βάθη 3.0m, 5.0m, 9.0m)
A32: Ζώνη Α: Οριζόντιο Βήμα Σειρών 1, 2, 4 | B32: 1.1 | C32: m | D32: Sh = 1.1 m από σχέδιο Ζώνης Α
A33: Ζώνη Α: Μήκος Ήλων Σειράς 3 (L >= 6m) | B33: 6.8 | C33: m | D33: 1 σειρά των 6.80 m (βάθος 7.0m)
A34: Ζώνη Α: Οριζόντιο Βήμα Σειράς 3 | B34: 1.1 | C34: m | D34: Sh = 1.1 m από σχέδιο Ζώνης Α
A35: Ζώνη Β: Μήκος Ήλων Σειρών 1, 2 (L < 6m) | B35: 4.2 | C35: m | D35: 2 σειρές των 4.20 m (βάθη 2.5m, 4.0m)
A36: Ζώνη Β: Οριζόντιο Βήμα Σειρών 1, 2 | B36: 1.5 | C36: m | D36: Sh = 1.5 m (αμετάβλητο) από σχέδιο Ζώνης Β
A37: Διάμετρος Οπής Διάτρησης (D) | B37: 0.12 | C37: m | D37: ΠΑΝΤΑ 12 cm (ακτίνα R = 0.06 m) κανόνας μάστρου
A38: Συντελεστής Απώλειας Grout στο Έδαφος | B38: 1.2 | C38: - | D38: ΠΑΝΤΑ * 1.20 (+20% απώλεια) κανόνας μάστρου
A39: Ζώνη Α: Διαστάσεις Πλάκας Έδρασης (M, Π) | B39: 300 | C39: mm | D39: 300x300 mm πλάκα S275 (Σημείωση 2 μελέτης)
A40: Ζώνη Α: Πάχος Πλάκας Έδρασης | B40: 15 | C40: mm | D40: 15 mm πάχος πλάκας Ζώνης Α (>=15mm)
A41: Ζώνη Β: Διαστάσεις Πλάκας Έδρασης (M, Π) | B41: 200 | C41: mm | D41: 200x200 mm πλάκα S275
... A43: Nuts & Ροδέλες ανά Ήλο | B43: 1 | C43: σετ / ήλο | D43: 1 κοχλιωτό nut & ροδέλα σύσφιξης ανά ήλο (Λεπτομέρεια Δ)
A45: ⚙️ ΚΕΦΑΛΑΙΟ Β: ΟΛΟΙ ΟΙ ΥΠΟΛΟΓΙΣΜΟΙ ΦΥΣΙΚΩΝ ΜΕΓΕΘΩΝ (ΜΕ ΒΑΣΗ ΤΟ ΚΕΦΑΛΑΙΟ Α)
A46: Β.1 Υπολογισμοί Στρατών Μετακίνησης (Κανόνας Multi-Zone v7)
A47: Ζώνη Μετακίνησης (ακτίνα 50km) | B47: Ζώνη 1 (0 – 50 km) | C47: - | D47: Απόσταση <= 50 km από Άγιο Συλά
...

Sheet 2_Υπολογισμοί_&_Κοστολόγηση
A1: ΕΡΓΟ: ST788 LEXUM — ΠΡΟΫΠΟΛΟΓΙΣΜΟΣ ΚΟΣΤΟΥΣ & VALUE ENGINEERING
A2: ΑΥΣΤΗΡΟ ΜΟΝΤΕΛΟ 4 ΠΥΛΩΝΩΝ ΚΟΣΤΟΥΣ (ΜΕΤΑΚΙΝΗΣΕΙΣ, ΣΧΑΡΕΣ, SHOTCRETE, ΕΔΑΦΟΗΛΩΣΕΙΣ) — ΕΚΔΟΣΗ v7.0
A4: Περιγραφή Εργασίας / Υλικού | B4: Ποσότητα | C4: Μονάδα | D4: Τιμή Μονάδας (€) | E4: Συνολικό Κόστος (€) | F4: Πηγή Ποσότητας / Τεχνικός Κανόνας
A5: ΠΥΛΩΝΑΣ 1: ΜΕΤΑΚΙΝΗΣΕΙΣ ΕΡΓΟΤΑΞΙΟΥ (ΣΤΡΑΤΕΣ — ΖΩΝΗ 1: 0–50 km)
A6: Στράτες Εκτοξευόμενου Σκυροδέματος (Shotcrete) | B6: ='1_Στοιχεία_Μελέτης_&_Ποσότητες'!B49 -> 7 | C6: στράτες | D6: 200 | E6: =B6*D6 -> 1400 | F6: ="Από Φύλλο 1 (" & B6 & " στράτες = Σειρές+1) × 200.00 €/στράτα" -> Από Φύλλο 1 (7 στράτες = Σειρές+1) × 200.00 €/στράτα
A7: Στράτες Εδαφοηλώσεων & Εξοπλισμού Διάτρησης | B7: ='1_Στοιχεία_Μελέτης_&_Ποσότητες'!B50 -> 6 | C7: στράτες | D7: 300 | E7: =B7*D7 -> 1800 | F7: ="Από Φύλλο 1 (" & B7 & " στράτες = Σειρές) × 300.00 €/στράτα" -> Από Φύλλο 1 (6 στράτες = Σειρές) × 300.00 €/στράτα
A8: ΣΥΝΟΛΟ ΠΥΛΩΝΑ 1 (ΜΕΤΑΚΙΝΗΣΕΙΣ) | E8: =SUM(E6:E7) -> 3200
A10: ΠΥΛΩΝΑΣ 2: ΣΧΑΡΕΣ (WIRE MESH GRID)
A11: ="Αγορά Χάλυβα Σχάρας (Y" & '1_Στοιχεία_Μελέτης_&_Ποσότητες'!B20 & " " & '1_Στοιχεία_Μελέτης_&_Ποσότητες'!B19 & ")" -> Αγορά Χάλυβα Σχάρας (Y10 B500A Δομικό Πλέγμα) | B11: ='1_Στοιχεία_Μελέτης_&_Ποσότητες'!B62 -> 4587.32 | C11: kg | D11: 2.5 | E11: =B11*D11 -> 11468.3 | F11: ="Από Φύλλο 1 (" & TEXT(B11, "#,##0.00") & " kg) × 2.50 €/kg" -> Από Φύλλο 1 (4,587.32 kg) × 2.50 €/kg
A12: Τοποθέτηση Σχάρας / Εργατικά Μετώπου | B12: ='1_Στοιχεία_Μελέτης_&_Ποσότητες'!B58 -> 558 | C12: m² | D12: 15 | E12: =B12*D12 -> 8370 | F12: ="Από Φύλλο 1 (" & TEXT(B12, "#,##0.00") & " m²) × 15.00 €/m²" -> Από Φύλλο 1 (558.00 m²) × 15.00 €/m²
A13: ΣΥΝΟΛΟ ΠΥΛΩΝΑ 2 (ΣΧΑΡΕΣ) | E13: =SUM(E11:E12) -> 19838.3
A15: ΠΥΛΩΝΑΣ 3: ΕΚΤΟΞΕΥΟΜΕΝΟ ΣΚΥΡΟΔΕΜΑ (SHOTCRETE) — ΟΝΟΜΑΣΤΙΚΑ m³ ΧΩΡΙΣ ΑΠΩΛΕΙΑ
A16: ="Αγορά Σκυροδέματος Shotcrete (" & '1_Στοιχεία_Μελέτης_&_Ποσότητες'!B25 & ")" -> Αγορά Σκυροδέματος Shotcrete (C25/30) | B16: ='1_Στοιχεία_Μελέτης_&_Ποσότητες'!B67 -> 83.7 | C16: m³ | D16: 90 | E16: =B16*D16 -> 7533 | F16: ⚠️ ΠΡΟΣΟΧΗ: Η τιμή αυτή είναι εκτίμηση βάσει C30/37 (90 €/m³), ενώ ο μελετητής ζητά C25/30. Απαιτείται επιβεβαίωση προσφοράς από προμηθευτή.
A17: Τοποθέτηση / Εκτόξευση / Αντλία (με προσαύξηση απώλειας) | B17: ='1_Στοιχεία_Μελέτης_&_Ποσότητες'!B67 -> 83.7 | C17: m³ | D17: =ROUND((IF(B16>7, 200, 250)*(1+'1_Στοιχεία_Μελέτης_&_Ποσότητες'!B66))-90, 2) -> 176.67 | E17: =B17*D17 -> 14787.279 | F17: ="Βάση " & IF(B16>7,200,250) & "€ × (1+" & TEXT('1_Στοιχεία_Μελέτης_&_Ποσότητες'!B66, "0.0%") & " απώλεια) - 90€ αγορά" -> Βάση 200€ × (1+33.3% απώλεια) - 90€ αγορά
A18: ΣΥΝΟΛΟ ΠΥΛΩΝΑ 3 (SHOTCRETE) | E18: =SUM(E16:E17) -> 22320.279
A20: ΠΥΛΩΝΑΣ 4: ΕΔΑΦΟΗΛΩΣΕΙΣ (SOIL NAILS)
A21: 4.1a Διάτρηση / Τρύπημα (Ήλοι L >= 6.0 m) | B21: ='1_Στοιχεία_Μελέτης_&_Ποσότητες'!B80 -> 312.8 | C21: m | D21: 25 | E21: =B21*D21 -> 7820 | F21: ="Από Φύλλο 1 (" & TEXT(B21, "#,##0.00") & " m) × 25.00 €/m" -> Από Φύλλο 1 (312.80 m) × 25.00 €/m
A22: 4.1b Διάτρηση / Τρύπημα (Ήλοι L < 6.0 m) | B22: ='1_Στοιχεία_Μελέτης_&_Ποσότητες'!B81 -> 951.6 | C22: m | D22: 30 | E22: =B22*D22 -> 28548 | F22: ="Από Φύλλο 1 (" & TEXT(B22, "#,##0.00") & " m) × 30.00 €/m" -> Από Φύλλο 1 (951.60 m) × 30.00 €/m
A23: 4.2 Grout Τσιμεντένεμα (με απώλεια 1.20) | B23: ='1_Στοιχεία_Μελέτης_&_Ποσότητες'!B85 -> 17.16 | C23: m³ | D23: 500 | E23: =B23*D23 -> 8580 | F23: ="Από Φύλλο 1 (" & TEXT(B23, "#,##0.00") & " m³) × 500.00 €/m³" -> Από Φύλλο 1 (17.16 m³) × 500.00 €/m³
A24: ="4.3 Χάλυβας Ήλων B500C (Y" & '1_Στοιχεία_Μελέτης_&_Ποσότητες'!B30 & ")" -> 4.3 Χάλυβας Ήλων B500C (Y32) | B24: ='1_Στοιχεία_Μελέτης_&_Ποσότητες'!B83 -> 7982.59 | C24: kg | D24: 1.5 | E24: =B24*D24 -> 11973.885 | F24: ="Από Φύλλο 1 (" & TEXT(B24, "#,##0.00") & " kg) × 1.50 €/kg" -> Από Φύλλο 1 (7,982.59 kg) × 1.50 €/kg
A25: 4.4 Διαμόρφωση Πάσου (Σπείρωμα Κεφαλής) | B25: ='1_Στοιχεία_Μελέτης_&_Ποσότητες'!B78 -> 220 | C25: τεμ. | D25: 20 | E25: =B25*D25 -> 4400 | F25: ="Από Φύλλο 1 (" & TEXT(B25, "#,##0") & " ήλοι) × 20.00 €/τεμ" -> Από Φύλλο 1 (220 ήλοι) × 20.00 €/τεμ
A26: 4.5 Πλάκες Έδρασης (S275, 15mm πάχος) | B26: ='1_Στοιχεία_Μελέτης_&_Ποσότητες'!B90 -> 2119.59 | C26: kg | D26: 2 | E26: =B26*D26 -> 4239.18 | F26: ="Από Φύλλο 1 (" & TEXT(B26, "#,##0.00") & " kg) × 2.00 €/kg" -> Από Φύλλο 1 (2,119.59 kg) × 2.00 €/kg
A27: 4.6 Nuts (Περικόχλια) & Ροδέλες | B27: ='1_Στοιχεία_Μελέτης_&_Ποσότητες'!B91 -> 220 | C27: τεμ. | D27: 5 | E27: =B27*D27 -> 1100 | F27: ="Από Φύλλο 1 (" & TEXT(B27, "#,##0") & " nuts) × 5.00 €/τεμ" -> Από Φύλλο 1 (220 nuts) × 5.00 €/τεμ
A28: ΣΥΝΟΛΟ ΠΥΛΩΝΑ 4 (ΕΔΑΦΟΗΛΩΣΕΙΣ) | E28: =SUM(E21:E27) -> 66661.065
A30: ΤΕΛΙΚΑ ΣΥΝΟΛΑ ΠΡΟΣΦΟΡΑΣ (ΚΑΝΟΝΑΣ v7: ΟΛΑ ΜΕΣΑ ΣΤΙΣ ΤΙΜΕΣ ΜΟΝΑΔΑΣ)
A31: ΚΑΘΑΡΟ ΣΥΝΟΛΟ ΠΡΟΣΦΟΡΑΣ (ΠΡΟ Φ.Π.Α.) | E31: =E8+E13+E18+E28 -> 112019.64 | F31: Άθροισμα 4 Πυλώνων (Περιλαμβάνει άμεσο κόστος, Γ.Ε. & όφελος)
A32: Φ.Π.Α. (19%) | E32: =ROUND(E31*0.19, 2) -> 21283.73 | F32: Νόμιμος Φ.Π.Α. Κύπρου (19%)
A33: ΤΕΛΙΚΟ ΠΛΗΡΩΤΕΟ ΠΟΣΟ (ΜΕ Φ.Π.Α.) | E33: =E31+E32 -> 133303.37 | F33: Τελικό πληρωτέο ποσό έργου
A34: Γενικό KPI: Κόστος ανά m² Μετώπου Εκσκαφής | E34: =ROUND(E31/'1_Στοιχεία_Μελέτης_&_Ποσότητες'!B58, 2) -> 200.75 | F34: ="Καθαρό σύνολο / " & '1_Στοιχεία_Μελέτης_&_Ποσότητες'!B58 & " m²" -> Καθαρό σύνολο / 558 m²
A35: Γενικό KPI: Κόστος ανά Εδαφοήλωση | E35: =ROUND(E31/'1_Στοιχεία_Μελέτης_&_Ποσότητες'!B78, 2) -> 509.18 | F35: ="Καθαρό σύνολο / " & '1_Στοιχεία_Μελέτης_&_Ποσότητες'!B78 & " ήλοι" -> Καθαρό σύνολο / 220 ήλοι
A40: 5. ΣΥΓΚΡΙΤΙΚΗ ΑΝΑΛΥΣΗ ΔΙΑΤΑΞΕΩΝ / VALUE ENGINEERING (ΖΩΝΗ Α vs ΖΩΝΗ Β)
A41: Εργαλείο Value Engineering για Μελετητές: Σύγκριση κόστους ανά τεμάχιο ήλου (€/τεμ), ανά μέτρο διάτρησης (€/m) και ανά m² μετώπου (€/m²)
A42: Διάταξη / Ζώνη Ήλων | B42: Μέσο Μήκος (L) [m] | C42: Βήμα (s) [m] | D42: Άμεσο Κόστος ανά Ήλο (€/τεμ) | E42: Κόστος ανά Τρέχον Μέτρο (€/m) | F42: Κόστος Ήλων ανά m² Μετώπου (€/m²) | G42: Συνολικό Σύστημα ανά m² Μετώπου (€/m²)
A43: ="Ζώνη Α (H=9.0m): L_μέσο=" & TEXT(B43, "0.00") & "m @ " & '1_Στοιχεία_Μελέτης_&_Ποσότητες'!B32 & "m" -> Ζώνη Α (H=9.0m): L_μέσο=6.05m @ 1.1m | B43: =('1_Στοιχεία_Μελέτης_&_Ποσότητες'!B72+'1_Στοιχεία_Μελέτης_&_Ποσότητες'!B74)/('1_Στοιχεία_Μελέτης_&_Ποσότητες'!B71+'1_Στοιχεία_Μελέτης_&_Ποσότητες'!B73) -> 6.05 | C43: ='1_Στοιχεία_Μελέτης_&_Ποσότητες'!B32 -> 1.1 | D43: =ROUND((('1_Στοιχεία_Μελέτης_&_Ποσότητες'!B74*$D$21 + '1_Στοιχεία_Μελέτης_&_Ποσότητες'!B72*$D$22)/('1_Στοιχεία_Μελέτης_&_Ποσότητες'!B71+'1_Στοιχεία_Μελέτης_&_Ποσότητες'!B73)) + (B43*'1_Στοιχεία_Μελέτης_&_Ποσότητες'!$B$84*$D$23) + (B43*'1_Στοιχεία_Μελέτης_&_Ποσότητες'!$B$82*$D$24) + $D$25 + ('1_Στοιχεία_Μελέτης_&_Ποσότητες'!$B$86*$D$26) + $D$27, 2) -> 317.54 | E43: =ROUND(D43/B43, 2) -> 52.49 | F43: =ROUND((('1_Στοιχεία_Μελέτης_&_Ποσότητες'!B71+'1_Στοιχεία_Μελέτης_&_Ποσότητες'!B73)*D43)/'1_Στοιχεία_Μελέτης_&_Ποσότητες'!B54, 2) -> 129.84 | G43: =ROUND(F43 + ($E$8+$E$13+$E$18)/'1_Στοιχεία_Μελέτης_&_Ποσότητες'!B58, 2) -> 211.13
A44: ="Ζώνη Β (H=4.0m): L=" & '1_Στοιχεία_Μελέτης_&_Ποσότητες'!B35 & "m @ " & '1_Στοιχεία_Μελέτης_&_Ποσότητες'!B36 & "m" -> Ζώνη Β (H=4.0m): L=4.2m @ 1.5m | B44: ='1_Στοιχεία_Μελέτης_&_Ποσότητες'!B35 -> 4.2 | C44: ='1_Στοιχεία_Μελέτης_&_Ποσότητες'!B36 -> 1.5 | D44: =ROUND((B44*$D$22) + (B44*'1_Στοιχεία_Μελέτης_&_Ποσότητες'!$B$84*$D$23) + (B44*'1_Στοιχεία_Μελέτης_&_Ποσότητες'!$B$82*$D$24) + $D$25 + ('1_Στοιχεία_Μελέτης_&_Ποσότητες'!$B$88*$D$26) + $D$27, 2) -> 228.69 | E44: =ROUND(D44/B44, 2) -> 54.45 | F44: =ROUND(('1_Στοιχεία_Μελέτης_&_Ποσότητες'!B76*D44)/'1_Στοιχεία_Μελέτης_&_Ποσότητες'!B56, 2) -> 76.23 | G44: =ROUND(F44 + ($E$8+$E$13+$E$18)/'1_Στοιχεία_Μελέτης_&_Ποσότητες'!B58, 2) -> 157.52
A45: ΔΙΑΦΟΡΑ / ΕΞΟΙΚΟΝΟΜΗΣΗ (ΖΩΝΗ Α vs ΖΩΝΗ Β) | D45: =ROUND(D43-D44, 2) -> 88.85 | E45: =ROUND(E43-E44, 2) -> -1.96 | F45: =ROUND(F43-F44, 2) -> 53.61 | G45: =ROUND(G43-G44, 2) -> 53.61
