Workbook

Sheet 1_Τιμές_Εταιρείας
A1: ΚΕΝΤΡΙΚΟΣ ΤΙΜΟΚΑΤΑΛΟΓΟΣ ΕΤΑΙΡΕΙΑΣ ΠΑΣΣΑΛΩΝ — ΕΔΡΑ: ΑΓΙΟΣ ΣΥΛΑΣ, ΛΕΜΕΣΟΣ
A2: ΚΙΤΡΙΝΟ = Τιμές μονάδας που αλλάζουν με την αγορά | ΛΕΥΚΟ = Φυσικές σταθερές & τύποι (δεν αγγίζονται)
A4: Α/Α | B4: Πυλώνας Κόστους | C4: Είδος Υλικού / Εργασίας | D4: Τιμή Μονάδας (€) [ΚΙΤΡΙΝΟ = ΑΛΛΑΖΕΙ] | E4: Μονάδα | F4: Κανόνας & Χρήση στην Κοστολόγηση
A5: 1 | B5: 1. Μετακινήσεις | C5: Μετακίνηση & Εγκατάσταση Γεωτρύπανου — Βασική τιμή (Εντός Λεμεσού) | D5: ='6_Ανάλυση_Σκυροδέματος_&_TODO'!D12 -> 1000 | E5: €/μετακίνηση | F5: ="Βασική χρέωση "&ROUND(D5,2)&" € μέσα στη Λεμεσό (επιμερίζεται ανά πάσσαλο)" -> Βασική χρέωση 1000 € μέσα στη Λεμεσό (επιμερίζεται ανά πάσσαλο)
A6: 2 | B6: 1. Μετακινήσεις | C6: Επιβάρυνση μετακίνησης ανά 10 km (εκτός Λεμεσού) | D6: ='6_Ανάλυση_Σκυροδέματος_&_TODO'!D13 -> 200 | E6: €/10 km | F6: ="+"&ROUND(D6,2)&" € ανά "&ROUND(D28,0)&" km εκτός Λεμεσού" -> +200 € ανά 10 km εκτός Λεμεσού
A7: 3 | B7: 2. Τρύπημα | C7: Τρύπημα / Διάτρηση Πασσάλου Ø400mm | D7: 70 | E7: €/m | F7: ="Συνολικά μέτρα διάτρησης Ø400mm × "&ROUND(D7,2)&" €/m" -> Συνολικά μέτρα διάτρησης Ø400mm × 70 €/m
A8: 4 | B8: 2. Τρύπημα | C8: Τρύπημα / Διάτρηση Πασσάλου Ø500mm | D8: 80 | E8: €/m | F8: ="Συνολικά μέτρα διάτρησης Ø500mm × "&ROUND(D8,2)&" €/m" -> Συνολικά μέτρα διάτρησης Ø500mm × 80 €/m
A9: 5 | B9: 2. Τρύπημα | C9: Τρύπημα / Διάτρηση Πασσάλου Ø600mm | D9: 90 | E9: €/m | F9: ="Συνολικά μέτρα διάτρησης Ø600mm × "&ROUND(D9,2)&" €/m" -> Συνολικά μέτρα διάτρησης Ø600mm × 90 €/m
A10: 6 | B10: 2. Τρύπημα | C10: Τρύπημα / Διάτρηση Πασσάλου Ø700mm | D10: 100 | E10: €/m | F10: ="Συνολικά μέτρα διάτρησης Ø700mm × "&ROUND(D10,2)&" €/m" -> Συνολικά μέτρα διάτρησης Ø700mm × 100 €/m
A11: 7 | B11: 2. Τρύπημα | C11: Τρύπημα / Διάτρηση Πασσάλου Ø800mm | D11: 115 | E11: €/m | F11: ="Συνολικά μέτρα διάτρησης Ø800mm × "&ROUND(D11,2)&" €/m" -> Συνολικά μέτρα διάτρησης Ø800mm × 115 €/m
A12: 8 | B12: 2. Τρύπημα | C12: Τρύπημα / Διάτρηση Πασσάλου Ø900mm | D12: 130 | E12: €/m | F12: ="Συνολικά μέτρα διάτρησης Ø900mm × "&ROUND(D12,2)&" €/m" -> Συνολικά μέτρα διάτρησης Ø900mm × 130 €/m
A13: 9 | B13: 2. Τρύπημα | C13: Τρύπημα / Διάτρηση Πασσάλου Ø1000mm | D13: 150 | E13: €/m | F13: ="Συνολικά μέτρα διάτρησης Ø1000mm × "&ROUND(D13,2)&" €/m" -> Συνολικά μέτρα διάτρησης Ø1000mm × 150 €/m
A14: 10 | B14: 2. Τρύπημα | C14: Τρύπημα / Διάτρηση Πασσάλου Ø1200mm | D14: 190 | E14: €/m | F14: ="Συνολικά μέτρα διάτρησης Ø1200mm × "&ROUND(D14,2)&" €/m" -> Συνολικά μέτρα διάτρησης Ø1200mm × 190 €/m
A15: 11 | B15: 2. Τρύπημα | C15: Προσαύξηση διάτρησης σε σκληρό βράχο / ειδικές συνθήκες | D15: 25 | E15: €/m | F15: ="Εφαρμόζεται επιπλέον +"&ROUND(D15,2)&" €/m όταν ζητείται διάτρηση σε σκληρό πέτρωμα" -> Εφαρμόζεται επιπλέον +25 €/m όταν ζητείται διάτρηση σε σκληρό πέτρωμα
A16: 12 | B16: 3. Σκυροδέτηση | C16: Σκυρόδεμα C25/30 — Αγορά κουγκριού | D16: 105 | E16: €/m³ | F16: ="Τιμή αγοράς "&ROUND(D16,2)&" €/m³ | Όγκος = π × D²/4 × L × (1 + "&ROUND(D27*100,0)&"% απώλεια)" -> Τιμή αγοράς 105 €/m³ | Όγκος = π × D²/4 × L × (1 + 10% απώλεια)
A17: 13 | B17: 3. Σκυροδέτηση | C17: Σκυρόδεμα C30/37 — Αγορά κουγκριού | D17: 115 | E17: €/m³ | F17: ="Τιμή αγοράς "&ROUND(D17,2)&" €/m³ | Όγκος = π × D²/4 × L × (1 + "&ROUND(D27*100,0)&"% απώλεια)" -> Τιμή αγοράς 115 €/m³ | Όγκος = π × D²/4 × L × (1 + 10% απώλεια)
A18: 14 | B18: 3. Σκυροδέτηση | C18: Τοποθέτηση / Άντληση Κανονικού Σκυροδέματος (προστίθεται στην τιμή αγοράς) | D18: 15 | E18: €/m³ | F18: ="Κανόνας Κανονικού Σκυροδέματος: ROUND(Τιμή Αγοράς + "&ROUND(D18,2)&" €/m³ + (Στήσιμο Αντλίας ÷ m³ ανά στήσιμο), 0)" -> Κανόνας Κανονικού Σκυροδέματος: ROUND(Τιμή Αγοράς + 15 €/m³ + (Στήσιμο Αντλίας ÷ m³ ανά στήσιμο), 0)
A19: 15 | B19: 4. Χάλυβας | C19: Σίδηρος κάθετων ράβδων κλωβού (Αγορά + Κατασκευή + Τοποθέτηση) | D19: 1.1 | E19: €/kg | F19: ="Ενιαία τιμή ανά κιλό: Μήκος ράβδου (με starter/γωνίες/μάτιση) × kg/m × "&ROUND(D19,2)&" €/kg" -> Ενιαία τιμή ανά κιλό: Μήκος ράβδου (με starter/γωνίες/μάτιση) × kg/m × 1.1 €/kg
A20: 16 | B20: 4. Χάλυβας | C20: Σίδηρος σούστας (σπείρα Y10) — Αγορά + Τοποθέτηση | D20: 1.1 | E20: €/kg | F20: ="Ενιαία τιμή ανά κιλό: Αριθμός σπειρών (με +1) × Περίμετρος × kg/m × "&ROUND(D20,2)&" €/kg" -> Ενιαία τιμή ανά κιλό: Αριθμός σπειρών (με +1) × Περίμετρος × kg/m × 1.1 €/kg
A21: 17 | B21: 4. Χάλυβας | C21: Πλαστικοί Αποστάτες Κλωβού (Cover Spacers / Wheels) | D21: 1.5 | E21: €/τεμ. | F21: ="Τροχοειδείς αποστάτες ("&ROUND(D21,2)&" €/τεμ.) για εξασφάλιση επικάλυψης" -> Τροχοειδείς αποστάτες (1.5 €/τεμ.) για εξασφάλιση επικάλυψης
A22: 18 | B22: 5. Ειδικές Εργασίες | C22: Sleeves Προστασίας Starter — Βασική αναφορά (βλ. Ενότητα Γ & Φύλλο 5_Ανάλυση_Κόστους_Sleeves) | D22: =ROUND((('5_Ανάλυση_Κόστους_Sleeves'!F6+'5_Ανάλυση_Κόστους_Sleeves'!F18)*'5_Ανάλυση_Κόστους_Sleeves'!D17)*2,0)/2 -> 3 | E22: €/τεμ. | F22: ="Δυναμικά ανά έργο: [(Χρεωστέο μήκος × €/m) + "&ROUND('5_Ανάλυση_Κόστους_Sleeves'!F14,4)&" € + "&ROUND('5_Ανάλυση_Κόστους_Sleeves'!F16,4)&" €] × "&ROUND('5_Ανάλυση_Κόστους_Sleeves'!D17,2)&" στρογγυλοποιημένο στο 0,50 € (π.χ. Φ20 1m = "&ROUND(D22,2)&" €)" -> Δυναμικά ανά έργο: [(Χρεωστέο μήκος × €/m) + 0.78 € + 0.0876 €] × 1.3 στρογγυλοποιημένο στο 0,50 € (π.χ. Φ20 1m = 3 €)
A23: 19 | B23: 5. Ειδικές Εργασίες | C23: Κεφαλοκοπή Πασσάλων / Pile Breaking (Σπάσιμο) | D23: 150 | E23: €/πάσσαλο | F23: ="Καθαίρεση υπερυψωμένου σκυροδέματος μέχρι το Cut-Off Level ("&ROUND(D23,2)&" €/πάσσαλο — με κουμπί ΝΑΙ/ΟΧΙ στο Φύλλο 3)" -> Καθαίρεση υπερυψωμένου σκυροδέματος μέχρι το Cut-Off Level (150 €/πάσσαλο — με κουμπί ΝΑΙ/ΟΧΙ στο Φύλλο 3)
A25: Β. ΦΥΣΙΚΕΣ ΣΤΑΘΕΡΕΣ & ΠΑΓΙΟΙ ΚΑΝΟΝΕΣ (ΛΕΥΚΟ — ΔΕΝ ΑΛΛΑΖΟΥΝ ΠΟΤΕ)
A26: — | B26: Σταθερά | C26: Πυκνότητα χάλυβα (ρ) | D26: 7850 | E26: kg/m³ | F26: ="Φυσική σταθερά ("&ROUND(D26,0)&" kg/m³) για υπολογισμό κιλών ράβδων και σούστας" -> Φυσική σταθερά (7850 kg/m³) για υπολογισμό κιλών ράβδων και σούστας
A27: — | B27: Σταθερά | C27: Πάγια απώλεια / υπερκατανάλωση σκυροδέματος (+10%) | D27: 0.1 | E27: % | F27: ="Προστίθεται υποχρεωτικά +"&ROUND(D27*100,0)&"% στον γεωμετρικό όγκο (V_conc = V_exc × "&ROUND(1+D27,2)&")" -> Προστίθεται υποχρεωτικά +10% στον γεωμετρικό όγκο (V_conc = V_exc × 1.1)
A28: — | B28: Σταθερά | C28: Βήμα χιλιομετρικής ζώνης εκτός Λεμεσού (ανά 10 km) | D28: ='6_Ανάλυση_Σκυροδέματος_&_TODO'!D14 -> 10 | E28: km | F28: ="Κάθε "&ROUND(D28,0)&" km εκτός Λεμεσού χρεώνονται +"&ROUND(D6,2)&" €" -> Κάθε 10 km εκτός Λεμεσού χρεώνονται +200 €
A29: — | B29: Σταθερά | C29: Μέγιστο εμπορικό μήκος βέργας | D29: 12 | E29: m | F29: ="Βέργες εμπορίου "&ROUND(D29,0)&" μέτρων (όριο πέραν του οποίου απαιτείται μάτιση)" -> Βέργες εμπορίου 12 μέτρων (όριο πέραν του οποίου απαιτείται μάτιση)
A30: — | B30: Σταθερά | C30: Συντελεστής μήκους μάτισης ράβδων (Lapping) | D30: 50 | E30: × Φ | F30: ="Κανόνας επικάλυψης "&ROUND(D30,0)&" φορές τη διάμετρο Φ (όταν δεν δίνεται ρητά στο σχέδιο)" -> Κανόνας επικάλυψης 50 φορές τη διάμετρο Φ (όταν δεν δίνεται ρητά στο σχέδιο)
A31: — | B31: Σταθερά | C31: Μέγιστο ύψος υπερκάλυψης σκυροδέματος (+2m) | D31: 2 | E31: m | F31: ="Κανόνας καθαρού σκυροδέματος: έως +"&ROUND(D31,2)&"m πάνω από το Cut-Off αν υπάρχει κενή διάτρηση (Δh > 0)" -> Κανόνας καθαρού σκυροδέματος: έως +2m πάνω από το Cut-Off αν υπάρχει κενή διάτρηση (Δh > 0)
A33: Γ. ΠΑΡΑΜΕΤΡΟΙ SLEEVES (ΣΩΛΗΝΕΣ, ΑΤΟΜΑ, ΛΕΠΤΑ, ΕΡΓΑΤΟΩΡΑ, ΤΕΛΛΑ, ×1,30), ΣΥΝΟΔΕΙΑΣ ΑΣΤΥΝΟΜΙΑΣ & ΧΩΜΑΤΟΣ (100% ΔΥΝΑΜΙΚΕΣ)
A34: 18α | B34: 5. Sleeves (Υλικό) | C34: Sleeve Φ32 (για σίδερο έως Φ20) — Εμπορικό μήκος σωλήνα | D34: ='5_Ανάλυση_Κόστους_Sleeves'!D6 -> 3 | E34: m | F34: ="Σωλήνας "&ROUND(D34,2)&" μέτρων (από Φύλλο 5 κελί D6)" -> Σωλήνας 3 μέτρων (από Φύλλο 5 κελί D6)
A35: 18β | B35: 5. Sleeves (Υλικό) | C35: Sleeve Φ32 (για σίδερο έως Φ20) — Τιμή σωλήνα | D35: ='5_Ανάλυση_Κόστους_Sleeves'!E6 -> 4.02 | E35: €/σωλήνα | F35: =ROUND(D35,4)&" € ανά σωλήνα "&ROUND(D34,2)&"m ("&ROUND(D35/D34,4)&" €/m — από Φύλλο 5 κελί E6)" -> 4.02 € ανά σωλήνα 3m (1.34 €/m — από Φύλλο 5 κελί E6)
A36: 18γ | B36: 5. Sleeves (Υλικό) | C36: Sleeve Φ38 (για σίδερο Φ22–Φ25) — Εμπορικό μήκος σωλήνα | D36: ='5_Ανάλυση_Κόστους_Sleeves'!D7 -> 3 | E36: m | F36: ="Σωλήνας "&ROUND(D36,2)&" μέτρων (από Φύλλο 5 κελί D7)" -> Σωλήνας 3 μέτρων (από Φύλλο 5 κελί D7)
A37: 18δ | B37: 5. Sleeves (Υλικό) | C37: Sleeve Φ38 (για σίδερο Φ22–Φ25) — Τιμή σωλήνα | D37: ='5_Ανάλυση_Κόστους_Sleeves'!E7 -> 5.724 | E37: €/σωλήνα | F37: =ROUND(D37,4)&" € ανά σωλήνα "&ROUND(D36,2)&"m ("&ROUND(D37/D36,4)&" €/m — από Φύλλο 5 κελί E7)" -> 5.724 € ανά σωλήνα 3m (1.908 €/m — από Φύλλο 5 κελί E7)
A38: 18ε | B38: 5. Sleeves (Υλικό) | C38: Sleeve Φ50 (για σίδερο Φ26–Φ32) — Εμπορικό μήκος σωλήνα | D38: ='5_Ανάλυση_Κόστους_Sleeves'!D8 -> 6 | E38: m | F38: ="Σωλήνας "&ROUND(D38,2)&" μέτρων (από Φύλλο 5 κελί D8)" -> Σωλήνας 6 μέτρων (από Φύλλο 5 κελί D8)
A39: 18στ | B39: 5. Sleeves (Υλικό) | C39: Sleeve Φ50 (για σίδερο Φ26–Φ32) — Τιμή σωλήνα | D39: ='5_Ανάλυση_Κόστους_Sleeves'!E8 -> 12.0615 | E39: €/σωλήνα | F39: =ROUND(D39,4)&" € ανά σωλήνα "&ROUND(D38,2)&"m ("&ROUND(D39/D38,4)&" €/m — από Φύλλο 5 κελί E8)" -> 12.0615 € ανά σωλήνα 6m (2.0103 €/m — από Φύλλο 5 κελί E8)
A40: 18ζ1 | B40: 5. Sleeves (Εργατικά) | C40: Sleeve Εργατικά — Κόστος εργατοώρας ανά άτομο | D40: ='5_Ανάλυση_Κόστους_Sleeves'!D12 -> 15.6 | E40: €/ώρα | F40: ="Ωρομίσθιο εργάτη: "&ROUND(D40,2)&" €/ώρα (αλλάζει στο Φύλλο 5 κελί D12)" -> Ωρομίσθιο εργάτη: 15.6 €/ώρα (αλλάζει στο Φύλλο 5 κελί D12)
A41: 18ζ2 | B41: 5. Sleeves (Εργατικά) | C41: Sleeve Εργατικά — Μέγεθος συνεργείου τοποθέτησης (άτομα) | D41: ='5_Ανάλυση_Κόστους_Sleeves'!D13 -> 1 | E41: άτομα | F41: ="Συνεργείο "&ROUND(D41,2)&" ατόμων ("&ROUND(D41*D40,2)&" €/ώρα — αλλάζει στο Φύλλο 5 κελί D13)" -> Συνεργείο 1 ατόμων (15.6 €/ώρα — αλλάζει στο Φύλλο 5 κελί D13)
A42: 18ζ3 | B42: 5. Sleeves (Εργατικά) | C42: Sleeve Εργατικά — Χρόνος τοποθέτησης ανά σίδερο (λεπτά) | D42: ='5_Ανάλυση_Κόστους_Sleeves'!D14 -> 3 | E42: λεπτά | F42: =ROUND(D42,2)&" λεπτά ανά σίδερο (αλλάζει στο Φύλλο 5 κελί D14)" -> 3 λεπτά ανά σίδερο (αλλάζει στο Φύλλο 5 κελί D14)
A43: 18ζ | B43: 5. Sleeves (Εργατικά) | C43: Εργατικά τοποθέτησης Sleeve ανά σίδερο | D43: ='5_Ανάλυση_Κόστους_Sleeves'!F14 -> 0.78 | E43: €/σίδερο | F43: ="Αυτόματος τύπος: ("&ROUND(D42,2)&"/60) × "&ROUND(D41,2)&" άτομα × "&ROUND(D40,2)&" €/ώρα = "&ROUND(D43,4)&" €/σίδερο" -> Αυτόματος τύπος: (3/60) × 1 άτομα × 15.6 €/ώρα = 0.78 €/σίδερο
...

Sheet 2_Βάρη_Διατομών_Χάλυβα
A1: ΠΙΝΑΚΑΣ ΜΟΝΑΔΙΑΙΩΝ ΒΑΡΩΝ ΧΑΛΥΒΑ ΟΠΛΙΣΜΟΥ (B500C) — ρ = 7.850 kg/m³
A3: Διατομή (Φ) | B3: Ονομαστική Διάμετρος (mm) | C3: Εμβαδόν Διατομής (mm²) | D3: Μοναδιαίο Βάρος (kg/m) [Τύπος: π×d²/4 × 7850] | E3: Τυπική Χρήση σε Πασσάλους
A4: Y6 | B4: 6 | C4: =PI()*(B4^2)/4 -> 28.274334 | D4: =C4/1000000*7850 -> 0.22195352 | E4: Ελαφριοί συνδετήρες / βοηθητικός
A5: Y8 | B5: 8 | C5: =PI()*(B5^2)/4 -> 50.265482 | D5: =C5/1000000*7850 -> 0.39458404 | E5: Σούστα μικρών πασσάλων Ø400
A6: Y10 | B6: 10 | C6: =PI()*(B6^2)/4 -> 78.539816 | D6: =C6/1000000*7850 -> 0.61653756 | E6: Βασική σούστα (σπείρα) πασσάλων Ø600-Ø800
A7: Y12 | B7: 12 | C7: =PI()*(B7^2)/4 -> 113.09734 | D7: =C7/1000000*7850 -> 0.88781408 | E7: Σούστα βαρέων πασσάλων / ενισχύσεις
A8: Y14 | B8: 14 | C8: =PI()*(B8^2)/4 -> 153.93804 | D8: =C8/1000000*7850 -> 1.2084136 | E8: Κάθετος οπλισμός μικρών φορτίων
A9: Y16 | B9: 16 | C9: =PI()*(B9^2)/4 -> 201.06193 | D9: =C9/1000000*7850 -> 1.5783361 | E9: Κάθετος οπλισμός πασσάλων Ø500-Ø600
A10: Y20 | B10: 20 | C10: =PI()*(B10^2)/4 -> 314.15927 | D10: =C10/1000000*7850 -> 2.4661502 | E10: Κύριος οπλισμός τυπικού σχεδίου (Ø600 12Y20)
A11: Y25 | B11: 25 | C11: =PI()*(B11^2)/4 -> 490.87385 | D11: =C11/1000000*7850 -> 3.8533597 | E11: Κύριος οπλισμός βαρέων πασσάλων Ø800-Ø1000
A12: Y28 | B12: 28 | C12: =PI()*(B12^2)/4 -> 615.75216 | D12: =C12/1000000*7850 -> 4.8336545 | E12: Κύριος οπλισμός υψηλών ροπών κάμψης
A13: Y32 | B13: 32 | C13: =PI()*(B13^2)/4 -> 804.24772 | D13: =C13/1000000*7850 -> 6.3133446 | E13: Ειδικοί πάσσαλοι αντιστήριξης / βαθιές εκσκαφές
A14: Y40 | B14: 40 | C14: =PI()*(B14^2)/4 -> 1256.6371 | D14: =C14/1000000*7850 -> 9.8646009 | E14: Βαριά τεχνικά έργα / γέφυρες

Sheet 3_Υπολογιστές_Έργων_&_Math
A1: ΕΡΓΑΛΕΙΑ ΥΠΟΛΟΓΙΣΜΟΥ ΕΡΓΩΝ ΠΑΣΣΑΛΩΝ & ΕΠΕΞΗΓΗΣΗ ΜΑΘΗΜΑΤΙΚΩΝ (SANDBOX)
A2: ΓΑΛΑΖΙΑ ΚΕΛΙΑ = Εισαγωγή στοιχείων από τη μελέτη μηχανικού | Οι τιμές μονάδας αντλούνται αυτόματα από τον Τιμοκατάλογο (Φύλλο 1)
A4: 1. ΥΠΟΛΟΓΙΣΤΗΣ ΤΙΜΗΣ ΜΕΤΑΚΙΝΗΣΗΣ ΓΕΩΤΡΥΠΑΝΟΥ ΑΝΑ ΑΠΟΣΤΑΣΗ ΕΡΓΟΤΑΞΙΟΥ
A5: Εισάγετε τη χιλιομετρική απόσταση του έργου από την έδρα (Άγιος Συλάς, Σπύρου Κυπριανού 32):
A6: Παράμετρος Έργου | B6: Τιμή / Εισαγωγή | C6: Μονάδα | D6: Τύπος Υπολογισμού | E6: Αποτέλεσμα | F6: Παρατηρήσεις
A7: Χιλιόμετρα εκτός Λεμεσού (0 km αν είναι εντός Λεμεσού) | B7: 75 | C7: km | D7: Εισαγωγή από μελέτη / Google Maps | E7: — | F7: ="Βασική Λεμεσού = "&ROUND('1_Τιμές_Εταιρείας'!D5,2)&" €" -> Βασική Λεμεσού = 1000 €
A8: ="Δεκάδες χιλιομέτρων εκτός Λεμεσού (ανά "&ROUND('1_Τιμές_Εταιρείας'!D28,0)&" km)" -> Δεκάδες χιλιομέτρων εκτός Λεμεσού (ανά 10 km) | B8: =IF(B7>0,ROUNDUP(B7/'1_Τιμές_Εταιρείας'!D28,0),0) -> 8 | C8: ζώνες | D8: ="ROUNDUP(km / "&ROUND('1_Τιμές_Εταιρείας'!D28,0)&", 0)" -> ROUNDUP(km / 10, 0) | E8: =B8 -> 8 | F8: ="Κάθε "&ROUND('1_Τιμές_Εταιρείας'!D28,0)&" km χρεώνονται +"&ROUND('1_Τιμές_Εταιρείας'!D6,2)&" €" -> Κάθε 10 km χρεώνονται +200 €
A9: Τελική Τιμή Μετακίνησης Γεωτρύπανου για το Έργο | B9: ='1_Τιμές_Εταιρείας'!D5 + (B8 * '1_Τιμές_Εταιρείας'!D6) + (B7 * '1_Τιμές_Εταιρείας'!D48) -> 3200 | C9: € / μετακίνηση | D9: ="Βασική ("&ROUND('1_Τιμές_Εταιρείας'!D5,0)&"€) + Δεκάδες×"&ROUND('1_Τιμές_Εταιρείας'!D6,0)&"€ + Συνοδεία×"&ROUND('1_Τιμές_Εταιρείας'!D48,0)&"€/km" -> Βασική (1000€) + Δεκάδες×200€ + Συνοδεία×8€/km | E9: =B9 -> 3200 | F9: Εφάπαξ ποσό μετακίνησης εργοταξίου
A10: Αριθμός Πασσάλων Έργου | B10: 8 | C10: τεμ. | D10: Εισαγωγή από μελέτη / κάτοψη | E10: — | F10: Συνολικός αριθμός πασσάλων
A11: Επιμερισμένη Τιμή Μετακίνησης ανά Πάσσαλο | B11: =B9 / B10 -> 400 | C11: € / πάσσαλο | D11: Συνολική Μετακίνηση / Αριθμός Πασσάλων | E11: =B11 -> 400 | F11: Χρησιμοποιείται στην κοστολόγηση ανά πάσσαλο
A13: 2. ΥΠΟΛΟΓΙΣΤΗΣ ΤΡΥΠΗΜΑΤΟΣ & ΣΚΥΡΟΔΕΜΑΤΟΣ ΠΑΣΣΑΛΩΝ (GEOMETRY & CONCRETE)
A14: Παράμετρος Έργου | B14: Τιμή / Εισαγωγή | C14: Μονάδα | D14: Τύπος Υπολογισμού | E14: Αποτέλεσμα | F14: Παρατηρήσεις
A15: Διάμετρος Τρύπας Πασσάλου (D) | B15: 600 | C15: mm | D15: Εισαγωγή από μελέτη (τομή) | E15: — | F15: Διάμετρος γεώτρησης
A16: Βάθος Διάτρησης στο Έδαφος (L) | B16: 4 | C16: m | D16: Εισαγωγή από μελέτη | E16: — | F16: Μήκος πασσάλου στο έδαφος
A17: Αριθμός Πασσάλων | B17: =B10 -> 8 | C17: τεμ. | D17: Σύνδεση με υπολογιστή 1 | E17: — | F17: Πλήθος πασσάλων
A18: Συνολικά Τρέχοντα Μέτρα Τρυπήματος | B18: =B16 * B17 -> 32 | C18: m | D18: Βάθος L × Αριθμός Πασσάλων | E18: =B18 -> 32 | F18: Σύνολο διάτρησης έργου
A19: Κόστος Τρυπήματος ανά Τρέχον Μέτρο | B19: ='1_Τιμές_Εταιρείας'!D9 -> 90 | C19: € / m | D19: ="Αντλείται από Τιμοκατάλογο (Ø600: "&ROUND('1_Τιμές_Εταιρείας'!D9,2)&" €/m)" -> Αντλείται από Τιμοκατάλογο (Ø600: 90 €/m) | E19: =B19 -> 90 | F19: Τιμή μονάδας διάτρησης
A20: ΣΥΝΟΛΙΚΟ ΚΟΣΤΟΣ ΤΡΥΠΗΜΑΤΟΣ ΕΡΓΟΥ | B20: =B18 * B19 -> 2880 | C20: € | D20: Συνολικά μέτρα × Τιμή/m | E20: =B20 -> 2880 | F20: Κόστος γεώτρησης
A21: Γεωμετρικός Όγκος Εκσκαφής ανά Πάσσαλο | B21: =PI()*((B15/1000)^2)/4 * B16 -> 1.1309734 | C21: m³ | D21: (π × D² / 4) × L | E21: =B21 -> 1.1309734 | F21: Θεωρητικός όγκος κυλίνδρου
A22: Όγκος Σκυροδέματος ανά Πάσσαλο (+10% απώλεια) | B22: =B21 * (1 + '1_Τιμές_Εταιρείας'!D27) -> 1.2440707 | C22: m³ | D22: ="V_exc × "&ROUND(1+'1_Τιμές_Εταιρείας'!D27,2)&" (+"&ROUND('1_Τιμές_Εταιρείας'!D27*100,0)&"% απώλεια)" -> V_exc × 1.1 (+10% απώλεια) | E22: =B22 -> 1.2440707 | F22: Κουγκρί παραγγελίας ανά πάσσαλο
A23: ΣΥΝΟΛΙΚΟ ΚΟΣΤΟΣ ΣΚΥΡΟΔΕΜΑΤΟΣ ΕΡΓΟΥ | B23: =B22 * B17 * ('1_Τιμές_Εταιρείας'!D17 + '1_Τιμές_Εταιρείας'!D18) -> 1293.8335 | C23: € | D23: ="m³ × Πάσσαλοι × "&ROUND('1_Τιμές_Εταιρείας'!D17+'1_Τιμές_Εταιρείας'!D18,2)&" €/m³" -> m³ × Πάσσαλοι × 130 €/m³ | E23: =B23 -> 1293.8335 | F23: Κόστος κουγκριού C30/37
A25: 3. ΥΠΟΛΟΓΙΣΤΗΣ ΒΑΡΟΥΣ & ΚΟΣΤΟΥΣ ΚΛΩΒΟΥ ΟΠΛΙΣΜΟΥ (REBAR CAGE CALCULATOR)
A26: Παράμετρος Έργου | B26: Τιμή / Εισαγωγή | C26: Μονάδα | D26: Τύπος Υπολογισμού | E26: Αποτέλεσμα | F26: Παρατηρήσεις
A27: Κάθετες Ράβδοι — Πλήθος (Nvert) | B27: 12 | C27: τεμ. | D27: Εισαγωγή από σχέδιο | E27: — | F27: Περιμετρικές ράβδοι
A28: Κάθετες Ράβδοι — Διάμετρος (Yvert) | B28: 20 | C28: mm | D28: Εισαγωγή από σχέδιο | E28: — | F28: Διάμετρος κυρίως οπλισμού
A29: Starter (Αναμονή) + Γωνίες (Πάνω & Πυθμένα) | B29: 1 | C29: m | D29: 0.50m Starter + 0.50m Top + 0.00m Bot | E29: — | F29: Πρόσθετα μήκη κάθετης ράβδου
A30: Απαίτηση Μάτισης (αν L_bar > 12m) | B30: =IF((B16+B29)>'1_Τιμές_Εταιρείας'!D29, '1_Τιμές_Εταιρείας'!D30*(B28/1000), 0) -> 0 | C30: m | D30: ="Κανόνας "&ROUND('1_Τιμές_Εταιρείας'!D30,0)&"×Φ αν υπερβαίνει τα "&ROUND('1_Τιμές_Εταιρείας'!D29,0)&"m" -> Κανόνας 50×Φ αν υπερβαίνει τα 12m | E30: =B30 -> 0 | F30: 0 = ενιαία βέργα, 1.00m = μάτιση
A31: Τελικό Μήκος Κάθετης Ράβδου (L_bar) | B31: =B16 + B29 + B30 -> 5 | C31: m | D31: Βάθος + Αναμονές/Γωνίες + Μάτιση | E31: =B31 -> 5 | F31: Ανεπτυγμένο μήκος ράβδου
A32: Βάρος Κάθετων Ράβδων ανά Πάσσαλο | B32: =B27 * B31 * (PI()*((B28/1000)^2)/4 * '1_Τιμές_Εταιρείας'!D26) -> 147.96901 | C32: kg | D32: N_vert × L_bar × kg/m | E32: =B32 -> 147.96901 | F32: Κιλά κάθετου οπλισμού
A33: Σούστα (Σπείρα) — Διάμετρος Y & Βήμα s | B33: 10 | C33: mm | D33: Βήμα s = 150 mm, Cover = 75 mm | E33: — | F33: Y10 ανά 15cm
A34: Βάρος Σούστας ανά Πάσσαλο | B34: =(ROUNDUP(B16/0.15, 0)+1) * (PI()*((B15-150)/1000)) * (PI()*((B33/1000)^2)/4 * '1_Τιμές_Εταιρείας'!D26) -> 24.405064 | C34: kg | D34: (ROUNDUP(L/s, 0) + 1) × Περίμετρος × kg/m | E34: =B34 -> 24.405064 | F34: Κιλά σούστας
A35: ΣΥΝΟΛΙΚΟ ΒΑΡΟΣ ΧΑΛΥΒΑ ΑΝΑ ΠΑΣΣΑΛΟ | B35: =B32 + B34 -> 172.37408 | C35: kg | D35: Κάθετες + Σούστα | E35: =B35 -> 172.37408 | F35: Συνολικά κιλά ανά πάσσαλο
A36: ΣΥΝΟΛΙΚΟ ΚΟΣΤΟΣ ΧΑΛΥΒΑ ΕΡΓΟΥ | B36: =B35 * B17 * '1_Τιμές_Εταιρείας'!D19 -> 1516.8919 | C36: € | D36: ="kg/πάσσαλο × Πάσσαλοι × "&ROUND('1_Τιμές_Εταιρείας'!D19,2)&" €/kg" -> kg/πάσσαλο × Πάσσαλοι × 1.1 €/kg | E36: =B36 -> 1516.8919 | F36: Συνολικό κόστος σιδήρου B500C
A38: 4. ΥΠΟΛΟΓΙΣΤΗΣ ΥΨΟΜΕΤΡΩΝ, SLEEVES & ΚΕΦΑΛΟΚΟΠΗΣ (ELEVATION, SLEEVES & BREAKING)
A39: Παράμετρος Έργου | B39: Τιμή / Εισαγωγή | C39: Μονάδα | D39: Τύπος Υπολογισμού | E39: Αποτέλεσμα | F39: Παρατηρήσεις
A40: Στάθμη Πλατφόρμας Γεωτρύπανου (WPL) | B40: 0 | C40: m | D40: Εισαγωγή από τοπογραφικό σχεδίου | E40: — | F40: Στάθμη έναρξης διάτρησης
A41: Στάθμη Αποκοπής Πασσάλου (Cut-Off Level) | B41: 0 | C41: m | D41: Εισαγωγή από ξυλότυπο θεμελίωσης | E41: — | F41: Στάθμη κεφαλής πασσάλου
A42: Διαφορά Υψομέτρου Τρυπήματος - Cut-off (Δh) | B42: =B40-B41 -> 0 | C42: m | D42: WPL − Cut-off Level (Κενή Διάτρηση) | E42: =B42 -> 0 | F42: ΚΟΚΚΙΝΟΣ ΣΥΝΑΓΕΡΜΟΣ αν δεν δίνεται!
A43: Ύψος Υπερκάλυψης Σκυροδέματος (Overconcreting) | B43: =IF(B42>0, MIN('1_Τιμές_Εταιρείας'!D31, B42), 0) -> 0 | C43: m | D43: ="Έως +"&ROUND('1_Τιμές_Εταιρείας'!D31,2)&"m πάνω από cut-off αν Δh > 0" -> Έως +2m πάνω από cut-off αν Δh > 0 | E43: =B43 -> 0 | F43: Κανόνας υγιούς σκυροδέματος κεφαλής
A44: Συνολικό Βάθος Διάτρησης ανά Πάσσαλο (L_drill) | B44: =B16 + B42 -> 4 | C44: m | D44: L_pile + Δh | E44: =B44 -> 4 | F44: Συνολικό μήκος τρυπήματος
...

Sheet 4_Κανόνες_&_Πολιτική
A1: ΚΑΝΟΝΕΣ ΤΙΜΟΚΑΤΑΛΟΓΟΥ ΠΑΣΣΑΛΩΝ & ΠΟΛΙΤΙΚΗ ΑΠΟΥΣΙΑΣ ΥΛΙΚΟΥ (MISSING MATERIAL POLICY)
A3: Θέμα / Πεδίο | B3: Κανόνας Λειτουργίας & Οδηγία για το AI
A4: Κανόνας Χρωματισμού | B4: • ΚΙΤΡΙΝΟ (#FFF2CC): Τιμές μονάδας που αλλάζουν με τους καιρούς / συνθήκες αγοράς. • ΛΕΥΚΟ (Χωρίς γέμισμα): Φυσικές σταθερές (7850 kg/m³, π), γεωμετρία και δυναμικοί τύποι. • ΓΑΛΑΖΙΟ (#DDEBF7): Εισαγωγή στοιχείων ανά έργο στους διαδραστικούς υπολογιστές. • ΚΟΚΚΙΝΟ (#FEE2E2): Συναγερμός ελλιπών δεδομένων (Missing Elevation / Cut-Off Gap).
A5: Κανόνας Μετακινήσεων & Επιμερισμού | B5: ="Το ποσό μετακίνησης γεωτρύπανου είναι: "&ROUND('1_Τιμές_Εταιρείας'!D5,2)&" € εντός Λεμεσού + "&ROUND('1_Τιμές_Εταιρείας'!D6,2)&" € ανά "&ROUND('1_Τιμές_Εταιρείας'!D28,0)&" km εκτός Λεμεσού + "&ROUND('1_Τιμές_Εταιρείας'!D48,2)&" €/km Συνοδεία Αστυνομίας, και επιμερίζεται ισόποσα ανά πάσσαλο." -> Το ποσό μετακίνησης γεωτρύπανου είναι: 1000 € εντός Λεμεσού + 200 € ανά 10 km εκτός Λεμεσού + 8 €/km Συνοδεία Αστυνομίας, και επιμερίζεται ισόποσα ανά πάσσαλο.
A6: Κανόνας Τρυπήματος (Διάτρησης) | B6: Το τρύπημα τιμολογείται ΑΠΟΚΛΕΙΣΤΙΚΑ σε τρέχοντα μέτρα (m) βάσει της ονομαστικής διαμέτρου της τρύπας (Ø400, Ø500, Ø600, Ø700, Ø800, Ø900, Ø1000, Ø1200mm). Εάν υπάρχει διαφορά στάθμης πλατφόρμας έναντι cut-off (Δh > 0), τα τρέχοντα μέτρα ισούνται με το συνολικό βάθος L_drill = L_pile + Δh. Σε περίπτωση σκληρού βράχου, εφαρμόζεται πρόσθετη χρέωση ανά μέτρο.
A7: Κανόνας Σκυροδέματος (Κουγκρί) | B7: ="Για το κανονικό σκυρόδεμα: ROUND(Τιμή Αγοράς + "&ROUND('1_Τιμές_Εταιρείας'!D18,2)&" €/m³ τοποθέτηση + Στήσιμο Αντλίας/m³, 0). Στον γεωμετρικό όγκο προστίθεται απώλεια +"&ROUND('1_Τιμές_Εταιρείας'!D27*100,0)&"%." -> Για το κανονικό σκυρόδεμα: ROUND(Τιμή Αγοράς + 15 €/m³ τοποθέτηση + Στήσιμο Αντλίας/m³, 0). Στον γεωμετρικό όγκο προστίθεται απώλεια +10%.
A8: Κανόνας Χάλυβα Οπλισμού (Κλωβοί B500C) | B8: ="Ο σίδηρος τιμολογείται ενιαία προς "&ROUND('1_Τιμές_Εταιρείας'!D19,2)&" €/kg. Αν η βέργα ξεπερνά τα "&ROUND('1_Τιμές_Εταιρείας'!D29,0)&" m, μπαίνει το μήκος μάτισης του σχεδίου (ή "&ROUND('1_Τιμές_Εταιρείας'!D30,0)&"×Φ αν δεν δίνεται στο σχέδιο)." -> Ο σίδηρος τιμολογείται ενιαία προς 1.1 €/kg. Αν η βέργα ξεπερνά τα 12 m, μπαίνει το μήκος μάτισης του σχεδίου (ή 50×Φ αν δεν δίνεται στο σχέδιο).
A9: Κανόνας Στάθμης Cut-off & Υψομετρικής Διαφοράς (Κενή Διάτρηση / Empty Bore) | B9: Όταν η διάτρηση ξεκινά από στάθμη πλατφόρμας (WPL) υψηλότερη από τη στάθμη αποκοπής (Cut-off Level), υπάρχει υψομετρική διαφορά Δh = WPL − Cut-off. Σε αυτή την περίπτωση, το τρύπημα αυξάνεται κατά Δh (L_drill = L_pile + Δh), καθιστώντας τον όγκο διάτρησης μεγαλύτερο από τον όγκο σκυροδέτησης.
A10: Κανόνας Υπερκάλυψης Σκυροδέματος (+2.00m Overconcreting) | B10: ="Για καθαρό σκυρόδεμα στην κεφαλή, η σκυροδέτηση υπερβαίνει το Cut-Off κατά έως +"&ROUND('1_Τιμές_Εταιρείας'!D31,2)&" μέτρα (όταν Δh > 0)." -> Για καθαρό σκυρόδεμα στην κεφαλή, η σκυροδέτηση υπερβαίνει το Cut-Off κατά έως +2 μέτρα (όταν Δh > 0).
A11: Κανόνας Sleeves Αναμονών Starter (Debonding Sleeves) | B11: ="Τα Sleeves κοστολογούνται βάσει διαμέτρου Φ: [(Χρεωστέο μήκος × €/m) + Εργατικά ("&ROUND('5_Ανάλυση_Κόστους_Sleeves'!D13,2)&" άτομα × "&ROUND('5_Ανάλυση_Κόστους_Sleeves'!D14,1)&" λεπτά × "&ROUND('5_Ανάλυση_Κόστους_Sleeves'!D12,2)&" €/ώρα = "&ROUND('5_Ανάλυση_Κόστους_Sleeves'!F14,4)&" €) + Τέλλα ("&ROUND('5_Ανάλυση_Κόστους_Sleeves'!F16,4)&" €)] × "&ROUND('5_Ανάλυση_Κόστους_Sleeves'!D17,2)&" στρογγυλοποιημένο στο πλησιέστερο 0,50 €." -> Τα Sleeves κοστολογούνται βάσει διαμέτρου Φ: [(Χρεωστέο μήκος × €/m) + Εργατικά (1 άτομα × 3 λεπτά × 15.6 €/ώρα = 0.78 €) + Τέλλα (0.0876 €)] × 1.3 στρογγυλοποιημένο στο πλησιέστερο 0,50 €.
A12: Κανόνας Κεφαλοκοπής Πασσάλου (Pile Breaking / Cropping) | B12: ="Κεφαλοκοπή πασσάλου: "&ROUND('1_Τιμές_Εταιρείας'!D23,2)&" €/πάσσαλο (με κουμπί ΝΑΙ/ΟΧΙ στο Φύλλο 3). Απομάκρυνση χώματος & λατομικά τέλη: "&ROUND('1_Τιμές_Εταιρείας'!D49,2)&" €/m³ εκσκαφής (με κουμπί ΝΑΙ/ΟΧΙ στο Φύλλο 3)." -> Κεφαλοκοπή πασσάλου: 150 €/πάσσαλο (με κουμπί ΝΑΙ/ΟΧΙ στο Φύλλο 3). Απομάκρυνση χώματος & λατομικά τέλη: 15 €/m³ εκσκαφής (με κουμπί ΝΑΙ/ΟΧΙ στο Φύλλο 3).
A13: ΚΑΝΟΝΑΣ ΚΟΚΚΙΝΟΥ ΣΥΝΑΓΕΡΜΟΥ (RED ALERT ΣΕ ΕΛΛΕΙΨΗ ΥΨΟΜΕΤΡΩΝ ΣΧΕΔΙΟΥ) | B13: Πολλές φορές από τα σχέδια δεν φαίνεται η υψομετρική διαφορά τρυπήματος - cut-off: -> Το AI θέτει προσωρινά Δh = 0.00m, αλλά υποχρεούται να το χρωματίσει με ΚΟΚΚΙΝΟ ΣΥΝΑΓΕΡΜΟ (#FEE2E2 / #991B1B) στο Φύλλο 2 και να εμφανίσει κόκκινο warning banner στην κορυφή του Φύλλου 1. -> ΑΠΑΓΟΡΕΥΕΤΑΙ ΑΥΣΤΗΡΑ η αποστολή προσφοράς στον πελάτη χωρίς ρητή ειδοποίηση ότι εκκρεμεί επιβεβαίωση της στάθμης εργασίας, ώστε να μην υποτιμηθούν τα μέτρα διάτρησης, τα sleeves και η κεφαλοκοπή!
A14: ΚΑΝΟΝΑΣ ΑΠΟΥΣΙΑΣ ΥΛΙΚΟΥ (ΥΠΟΧΡΕΩΤΙΚΟ ΜΗΝΥΜΑ AI) | B14: Εάν ο μελετητής ζητήσει διάμετρο πασσάλου ή υλικό που ΔΕΝ υπάρχει στον παρόντα τιμοκατάλογο πασσάλων (π.χ. διάμετρος Ø1400mm, ειδική κατηγορία σκυροδέματος C40/50, διατομή εκτός πίνακα Y6–Y40, ανοξείδωτο χάλυβα, ειδικούς αποστάτες): -> Το σύστημα AI ΑΠΑΓΟΡΕΥΕΤΑΙ ΑΥΣΤΗΡΑ να μαντέψει ή να εφεύρει τιμή! -> Το σύστημα ΣΤΑΜΑΤΑΕΙ και εμφανίζει στον χρήστη ρητά το μήνυμα: «Δεν υπάρχει αυτό το είδος ([Όνομα Είδους]) στον τιμοκατάλογο πασσάλων. Καθοδήγησέ με με τιμή να ξέρω.» -> Μόνο αφού ο χρήστης δώσει την τιμή, η κοστολόγηση προχωρά.
A15: Κανόνας Απόστασης (Έδρα Άγιος Συλάς) | B15: ="Αφετηρία: Άγιος Συλάς, Λεμεσός. Εντός Λεμεσού: "&ROUND('1_Τιμές_Εταιρείας'!D5,2)&" €. Εκτός Λεμεσού: +"&ROUND('1_Τιμές_Εταιρείας'!D6,2)&" € ανά "&ROUND('1_Τιμές_Εταιρείας'!D28,0)&" km + "&ROUND('1_Τιμές_Εταιρείας'!D48,2)&" €/km Συνοδεία Αστυνομίας." -> Αφετηρία: Άγιος Συλάς, Λεμεσός. Εντός Λεμεσού: 1000 €. Εκτός Λεμεσού: +200 € ανά 10 km + 8 €/km Συνοδεία Αστυνομίας.

Sheet 5_Ανάλυση_Κόστους_Sleeves
A1: ="ΑΝΑΛΥΣΗ ΚΟΣΤΟΥΣ SLEEVES ΠΡΟΣΤΑΣΙΑΣ ΑΝΑΜΟΝΩΝ STARTER (ΥΛΙΚΑ + ΕΡΓΑΤΙΚΑ + ΤΕΛΛΑ) × "&ROUND(D17,2)&" (OVERHEAD, PROFIT & DAMAGES)" -> ΑΝΑΛΥΣΗ ΚΟΣΤΟΥΣ SLEEVES ΠΡΟΣΤΑΣΙΑΣ ΑΝΑΜΟΝΩΝ STARTER (ΥΛΙΚΑ + ΕΡΓΑΤΙΚΑ + ΤΕΛΛΑ) × 1.3 (OVERHEAD, PROFIT & DAMAGES)
A2: ΚΙΤΡΙΝΑ ΚΕΛΙΑ = Τιμές Προμηθευτών, Άτομα, Λεπτά, Εργατοώρα, Τέλλα & Συντελεστής Overhead (αν αλλάξεις οτιδήποτε εδώ, ενημερώνονται αυτόματα και οι τιμές ΚΑΙ όλες οι σημειώσεις!)
A4: Α. ΤΙΜΕΣ ΑΓΟΡΑΣ ΣΩΛΗΝΩΝ SLEEVES ΑΠΟ ΠΡΟΜΗΘΕΥΤΗ (ΑΝΑ ΔΙΑΜΕΤΡΟ ΚΑΘΕΤΟΥ ΣΙΔΗΡΟΥ Φ)
A5: Κωδ. | B5: Διάμετρος Κάθετου Σιδήρου | C5: Τύπος / Διάμετρος Sleeve | D5: Εμπορικό Μήκος Σωλήνα (m) [ΚΙΤΡΙΝΟ] | E5: Τιμή Αγοράς Σωλήνα (€/σωλήνα) [ΚΙΤΡΙΝΟ] | F5: Κόστος Υλικού ανά Μέτρο (€/m) [Αυτόματος Τύπος] | G5: Κανόνας Επιλογής & Κοπής (100% Δυναμική Σημείωση)
A6: SL.A1 | B6: Έως Φ20 (π.χ. Φ14–Φ20) | C6: Sleeve Φ32 | D6: 3 | E6: 4.02 | F6: =E6/D6 -> 1.34 | G6: ="Για κάθετη ράβδο έως Φ20 χρησιμοποιείται "&C6&" (έρχεται σε σωλήνες "&ROUND(D6,2)&"m προς "&ROUND(E6,4)&" € το ένα = "&ROUND(F6,4)&" €/m)" -> Για κάθετη ράβδο έως Φ20 χρησιμοποιείται Sleeve Φ32 (έρχεται σε σωλήνες 3m προς 4.02 € το ένα = 1.34 €/m)
A7: SL.A2 | B7: Φ22 έως Φ25 | C7: Sleeve Φ38 | D7: 3 | E7: 5.724 | F7: =E7/D7 -> 1.908 | G7: ="Για κάθετη ράβδο Φ22–Φ25 χρησιμοποιείται "&C7&" (έρχεται σε σωλήνες "&ROUND(D7,2)&"m προς "&ROUND(E7,4)&" € το ένα = "&ROUND(F7,4)&" €/m)" -> Για κάθετη ράβδο Φ22–Φ25 χρησιμοποιείται Sleeve Φ38 (έρχεται σε σωλήνες 3m προς 5.724 € το ένα = 1.908 €/m)
A8: SL.A3 | B8: Φ26 έως Φ32 | C8: Sleeve Φ50 | D8: 6 | E8: 12.0615 | F8: =E8/D8 -> 2.01025 | G8: ="Για κάθετη ράβδο Φ26–Φ32 χρησιμοποιείται "&C8&" (έρχεται σε σωλήνες "&ROUND(D8,2)&"m προς "&ROUND(E8,4)&" € το ένα = "&ROUND(F8,4)&" €/m)" -> Για κάθετη ράβδο Φ26–Φ32 χρησιμοποιείται Sleeve Φ50 (έρχεται σε σωλήνες 6m προς 12.0615 € το ένα = 2.0103 €/m)
A10: ="Β. ΣΤΑΘΕΡΟ ΚΟΣΤΟΣ ΕΡΓΑΤΙΚΩΝ, ΤΕΛΛΑΣ & ΣΥΝΤΕΛΕΣΤΗΣ OVERHEAD / PROFIT / DAMAGES (× "&ROUND(D17,2)&")" -> Β. ΣΤΑΘΕΡΟ ΚΟΣΤΟΣ ΕΡΓΑΤΙΚΩΝ, ΤΕΛΛΑΣ & ΣΥΝΤΕΛΕΣΤΗΣ OVERHEAD / PROFIT / DAMAGES (× 1.3)
A11: Κωδ. | B11: Παράμετρος Κόστους | C11: Μονάδα | D11: Τιμή [ΚΙΤΡΙΝΟ = ΑΛΛΑΖΕΙ] | E11: Δυναμικός Τύπος Υπολογισμού | F11: Κόστος / Συντελεστής | G11: Δυναμική Επεξήγηση (Ενημερώνεται Αυτόματα)
A12: SL.B1 | B12: Κόστος εργατοώρας ανά άτομο | C12: €/ώρα | D12: 15.6 | E12: ="Τιμή εργατοώρας = "&ROUND(D12,2)&" €/ώρα ανά άτομο" -> Τιμή εργατοώρας = 15.6 €/ώρα ανά άτομο | F12: — | G12: ="Βασικό ωρομίσθιο εργάτη: "&ROUND(D12,2)&" €/ώρα" -> Βασικό ωρομίσθιο εργάτη: 15.6 €/ώρα
A13: SL.B2 | B13: Μέγεθος συνεργείου τοποθέτησης sleeves (πόσα άτομα) | C13: άτομα | D13: 1 | E13: =ROUND(D13,2)&" άτομα → "&ROUND(D13,2)&" × "&ROUND(D12,2)&" € = "&ROUND(D13*D12,2)&" €/ώρα" -> 1 άτομα → 1 × 15.6 € = 15.6 €/ώρα | F13: — | G13: ="Συνεργείο "&ROUND(D13,2)&" ατόμων (συνολικό κόστος συνεργείου: "&ROUND(D13*D12,2)&" €/ώρα)" -> Συνεργείο 1 ατόμων (συνολικό κόστος συνεργείου: 15.6 €/ώρα)
A14: SL.B3 | B14: Χρόνος τοποθέτησης ανά κάθετο σίδερο (πόσα λεπτά) | C14: λεπτά | D14: 3 | E14: =ROUND(D14,2)&" λεπτά = "&ROUND(D14,2)&"/60 της ώρας ("&ROUND(D14/60,4)&" ώρες)" -> 3 λεπτά = 3/60 της ώρας (0.05 ώρες) | F14: =(D14/60)*D13*D12 -> 0.78 | G14: ="Εργατικά ανά σίδερο = ("&ROUND(D14,2)&"/60) × "&ROUND(D13,2)&" άτομα × "&ROUND(D12,2)&" €/ώρα = "&ROUND(F14,4)&" €/σίδερο" -> Εργατικά ανά σίδερο = (3/60) × 1 άτομα × 15.6 €/ώρα = 0.78 €/σίδερο
A15: SL.B4 | B15: Κόστος αγοράς ρολού Τέλλας (Μονωτική Ταινία) | C15: €/ρολό | D15: 2.19 | E15: ="Τιμή προμηθευτή = "&ROUND(D15,2)&" €/ρολό" -> Τιμή προμηθευτή = 2.19 €/ρολό | F15: — | G15: ="Μονωτική ταινία στεγανοποίησης sleeve ("&ROUND(D15,2)&" € το ρολό)" -> Μονωτική ταινία στεγανοποίησης sleeve (2.19 € το ρολό)
A16: SL.B5 | B16: Αριθμός σιδήρων που καλύπτει 1 ρολό Τέλλας | C16: σίδερα/ρολό | D16: 25 | E16: =ROUND(D15,2)&" € ÷ "&ROUND(D16,0)&" σίδερα" -> 2.19 € ÷ 25 σίδερα | F16: =D15/D16 -> 0.0876 | G16: ="Κόστος Τέλλας ανά σίδερο = "&ROUND(D15,2)&" € / "&ROUND(D16,0)&" σίδερα = "&ROUND(F16,4)&" €/σίδερο" -> Κόστος Τέλλας ανά σίδερο = 2.19 € / 25 σίδερα = 0.0876 €/σίδερο
A17: SL.B6 | B17: ="Συντελεστής Overhead, Profit & Damages (× "&ROUND(D17,2)&")" -> Συντελεστής Overhead, Profit & Damages (× 1.3) | C17: × | D17: 1.3 | E17: ="Πολλαπλασιάζεται × "&ROUND(D17,2)&" επί του κόστους (Υλικό + Εργατικά + Τέλλα)" -> Πολλαπλασιάζεται × 1.3 επί του κόστους (Υλικό + Εργατικά + Τέλλα) | F17: =D17 -> 1.3 | G17: ="Πάντα × "&ROUND(D17,2)&" (+"&ROUND((D17-1)*100,0)&"% Overhead, Κέρδος & Ζημιές) στην τελική τιμή του Sleeve!" -> Πάντα × 1.3 (+30% Overhead, Κέρδος & Ζημιές) στην τελική τιμή του Sleeve!
A18: ="ΣΥΝΟΛΙΚΟ ΣΤΑΘΕΡΟ ΕΣΩΤΕΡΙΚΟ ΚΟΣΤΟΣ ΑΝΑ ΣΙΔΕΡΟ (ΕΡΓΑΤΙΚΑ + ΤΕΛΛΑ — ΠΡΙΝ ΤΟ ×"&ROUND(D17,2)&"):" -> ΣΥΝΟΛΙΚΟ ΣΤΑΘΕΡΟ ΕΣΩΤΕΡΙΚΟ ΚΟΣΤΟΣ ΑΝΑ ΣΙΔΕΡΟ (ΕΡΓΑΤΙΚΑ + ΤΕΛΛΑ — ΠΡΙΝ ΤΟ ×1.3): | F18: =F14+F16 -> 0.8676 | G18: =ROUND(F14,4)&" € (Εργατικά: "&ROUND(D13,2)&" άτομα × "&ROUND(D14,1)&" λεπτά) + "&ROUND(F16,4)&" € (Τέλλα: "&ROUND(D15,2)&" € / "&ROUND(D16,0)&" σίδερα) = "&ROUND(F18,4)&" € ανά σίδερο" -> 0.78 € (Εργατικά: 1 άτομα × 3 λεπτά) + 0.0876 € (Τέλλα: 2.19 € / 25 σίδερα) = 0.8676 € ανά σίδερο
A20: ="Γ. ΚΑΝΟΝΑΣ ΚΟΠΗΣ ΣΩΛΗΝΑ SLEEVE, ΣΤΡΟΓΓΥΛΟΠΟΙΗΣΗΣ ΦΥΡΑΣ, ΠΡΟΣΑΥΞΗΣΗΣ ×"&ROUND(D17,2)&" & ΣΤΡΟΓΓΥΛΟΠΟΙΗΣΗΣ ΣΤΟ 0,50 €" -> Γ. ΚΑΝΟΝΑΣ ΚΟΠΗΣ ΣΩΛΗΝΑ SLEEVE, ΣΤΡΟΓΓΥΛΟΠΟΙΗΣΗΣ ΦΥΡΑΣ, ΠΡΟΣΑΥΞΗΣΗΣ ×1.3 & ΣΤΡΟΓΓΥΛΟΠΟΙΗΣΗΣ ΣΤΟ 0,50 €
A21: 1. Σε κάθε εργοτάξιο, το απαιτούμενο μήκος sleeve ανά κάθετο σίδερο είναι: L_req = Ύψος Αναμονής (Starter) + Γωνία Πάνω (Top Bend).
A22: ="2. Αν το L_req διαιρεί ακριβώς το εμπορικό μήκος του σωλήνα L_pipe (π.χ. L_req = 1,00 m σε σωλήνα "&ROUND(D6,2)&" m), δεν υπάρχει φύρα: Χρεωστέο μήκος L_billed = L_req." -> 2. Αν το L_req διαιρεί ακριβώς το εμπορικό μήκος του σωλήνα L_pipe (π.χ. L_req = 1,00 m σε σωλήνα 3 m), δεν υπάρχει φύρα: Χρεωστέο μήκος L_billed = L_req.
A23: 3. Αν ΔΕΝ είναι ακριβές υποπολλαπλάσιο του σωλήνα που μας φέρνουν, το κομμάτι που περισσεύει χάνεται: L_billed = L_pipe / INT(L_pipe / L_req) (ή CEILING(L_req, L_pipe) αν L_req > L_pipe).
A24: ="4. Εσωτερικό Κόστος Sleeve ανά σίδερο (€/τεμ.) = (L_billed × Κόστος Σωλήνα ανά μέτρο) + "&ROUND(F14,4)&" € (Εργατικά: "&ROUND(D13,2)&" άτομα × "&ROUND(D14,1)&" λεπτά × "&ROUND(D12,2)&" €/ώρα) + "&ROUND(F16,4)&" € (Τέλλα: "&ROUND(D15,2)&" € / "&ROUND(D16,0)&" σίδερα)." -> 4. Εσωτερικό Κόστος Sleeve ανά σίδερο (€/τεμ.) = (L_billed × Κόστος Σωλήνα ανά μέτρο) + 0.78 € (Εργατικά: 1 άτομα × 3 λεπτά × 15.6 €/ώρα) + 0.0876 € (Τέλλα: 2.19 € / 25 σίδερα).
A25: ="5. Προσαύξηση × "&ROUND(D17,2)&" (Overhead, Profit & Damages): Ακριβής Τιμή = Εσωτερικό Κόστος Sleeve × "&ROUND(D17,2)&"." -> 5. Προσαύξηση × 1.3 (Overhead, Profit & Damages): Ακριβής Τιμή = Εσωτερικό Κόστος Sleeve × 1.3.
A26: ="6. ΣΤΡΟΓΓΥΛΟΠΟΙΗΣΗ ΣΤΟ ΠΛΗΣΙΕΣΤΕΡΟ 0,50 €: Η τελική τιμή προσφοράς του Sleeve ανά σίδερο στρογγυλοποιείται πάντα στο πλησιέστερο 0,50 € με τον τύπο ROUND(Ακριβής_Τιμή × 2, 0) / 2. Π.χ. για Φ20 με L_billed = 1,00m: ("&ROUND(F6,4)&" + "&ROUND(F18,4)&") × "&ROUND(D17,2)&" = "&ROUND((F6+F18)*D17,4)&" € → "&ROUND(ROUND((F6+F18)*D17*2,0)/2,2)&" €/τεμ.!" -> 6. ΣΤΡΟΓΓΥΛΟΠΟΙΗΣΗ ΣΤΟ ΠΛΗΣΙΕΣΤΕΡΟ 0,50 €: Η τελική τιμή προσφοράς του Sleeve ανά σίδερο στρογγυλοποιείται πάντα στο πλησιέστερο 0,50 € με τον τύπο ROUND(Ακριβής_Τιμή × 2, 0) / 2. Π.χ. για Φ20 με L_billed = 1,00m: (1.34 + 0.8676) × 1.3 = 2.8699 € → 3 €/τεμ.!

Sheet 6_Ανάλυση_Σκυροδέματος_&_TODO
A1: ΑΝΑΛΥΣΗ ΚΑΝΟΝΙΚΟΥ ΣΚΥΡΟΔΕΜΑΤΟΣ, ΜΕΤΑΚΙΝΗΣΕΩΝ ΓΕΩΤΡΥΠΑΝΟΥ & ΛΙΣΤΑ ΕΚΚΡΕΜΟΤΗΤΩΝ (TODO LIST)
A3: Α. ΠΩΣ ΒΓΑΙΝΕΙ Η ΤΕΛΙΚΗ ΤΙΜΗ ΚΑΝΟΝΙΚΟΥ ΣΚΥΡΟΔΕΜΑΤΟΣ (ΟΧΙ ΕΚΤΟΞΕΥΟΜΕΝΟΥ) ΣΕ ΚΑΘΕ ΕΡΓΟ
A4: Κωδ. | B4: Στοιχείο Κόστους Σκυροδέματος | C4: Μονάδα | D4: Τιμή / Πηγή | E4: Δυναμικός Κανόνας & Εφαρμογή
A5: ΣΚ.1 | B5: Τιμή Αγοράς Σκυροδέματος (Κουγκρί) | C5: €/m³ | D5: Ορίζεται στο Έργο (Φύλλο 3) | E5: Διαφέρει ανά έργο/προμηθευτή — τη συμπληρώνει ο μηχανικός στο κουτάκι Τ.Β.1 του Φύλλου 3 («Τιμές & Έλεγχος»)
A6: ΣΚ.2 | B6: Κόστος Τοποθέτησης Σκυροδέματος | C6: €/m³ | D6: ='1_Τιμές_Εταιρείας'!D18 -> 15 | E6: ="Σταθερή επιβάρυνση τοποθέτησης = +"&ROUND(D6,2)&" €/m³ (από τον Τιμοκατάλογο Εταιρείας, κελί D18)" -> Σταθερή επιβάρυνση τοποθέτησης = +15 €/m³ (από τον Τιμοκατάλογο Εταιρείας, κελί D18)
A7: ΣΚ.3 | B7: Κόστος Στησίματος Αντλίας (Πρέσας) | C7: €/στήσιμο | D7: Ορίζεται στο Έργο (Φύλλο 3) | E7: Σταθερό ποσό ανά στήσιμο αντλίας, διαιρείται με τα κυβικά (m³) που αντλεί η αντλία ανά στήσιμο (Τρύπες ανά στήσιμο × m³/τρύπα)
A8: ΣΚ.4 | B8: ΤΕΛΙΚΗ ΦΟΡΜΟΥΛΑ ΣΚΥΡΟΔΕΤΗΣΗΣ (€/m³ — ΣΤΡΟΓΓΥΛΟΠΟΙΗΜΕΝΗ) | C8: €/m³ | D8: ="ROUND(Τιμή Αγοράς + "&ROUND(D6,2)&" € + (Στήσιμο Αντλίας ÷ m³ ανά στήσιμο), 0)" -> ROUND(Τιμή Αγοράς + 15 € + (Στήσιμο Αντλίας ÷ m³ ανά στήσιμο), 0) | E8: Υπολογίζεται και στρογγυλοποιείται αυτόματα σε ακέραιο € στο κελί Τ.Β.7 (D21) του Φύλλου 3 («Τιμές & Έλεγχος»)!
A10: Β. ΚΑΝΟΝΑΣ ΜΕΤΑΚΙΝΗΣΕΩΝ ΓΕΩΤΡΥΠΑΝΟΥ & ΣΥΝΟΔΕΙΑΣ ΑΣΤΥΝΟΜΙΑΣ (ΠΑΣΣΑΛΟΙ ΘΕΜΕΛΙΩΣΗΣ / ΝΕΦΚΕΣ)
A11: Κωδ. | B11: Στοιχείο Κόστους Μετακίνησης | C11: Μονάδα | D11: Τιμή [ΚΙΤΡΙΝΟ = ΑΛΛΑΖΕΙ] | E11: Δυναμικός Κανόνας & Εφαρμογή (Ενημερώνεται Αυτόματα)
A12: ΜΕΤ.1 | B12: Βασική μετακίνηση γεωτρύπανου μέσα στη Λεμεσό | C12: €/μετακίνηση | D12: 1000 | E12: ="Βασική χρέωση "&ROUND(D12,2)&" € για έργα εντός Λεμεσού" -> Βασική χρέωση 1000 € για έργα εντός Λεμεσού
A13: ΜΕΤ.2 | B13: ="Επιβάρυνση εκτός Λεμεσού ανά "&ROUND(D14,0)&" χιλιόμετρα" -> Επιβάρυνση εκτός Λεμεσού ανά 10 χιλιόμετρα | C13: ="€/"&ROUND(D14,0)&" km" -> €/10 km | D13: 200 | E13: ="+"&ROUND(D13,2)&" € για κάθε "&ROUND(D14,0)&" km εκτός Λεμεσού" -> +200 € για κάθε 10 km εκτός Λεμεσού
A14: ΜΕΤ.3 | B14: Βήμα χιλιομετρικής ζώνης εκτός Λεμεσού | C14: km | D14: 10 | E14: ="Υπολογισμός ανά "&ROUND(D14,0)&" km: ROUNDUP(Χιλιόμετρα εκτός Λεμεσού / "&ROUND(D14,0)&", 0) × "&ROUND(D13,2)&" €" -> Υπολογισμός ανά 10 km: ROUNDUP(Χιλιόμετρα εκτός Λεμεσού / 10, 0) × 200 €
A15: ΜΕΤ.4 | B15: Συνοδεία Αστυνομίας για μεταφορά γεωτρύπανου (Πάσσαλοι Θεμελίωσης / Νέφκες) | C15: €/km | D15: 8 | E15: ="+"&ROUND(D15,2)&" € ανά χιλιόμετρο συνοδείας Αστυνομίας (όταν έχουμε Πασσάλους Θεμελίωσης ή Νέφκες στις αγκυρώσεις)" -> +8 € ανά χιλιόμετρο συνοδείας Αστυνομίας (όταν έχουμε Πασσάλους Θεμελίωσης ή Νέφκες στις αγκυρώσεις)
A17: Γ. TODO LIST — ΕΚΚΡΕΜΕΙΣ ΑΝΑΛΥΣΕΙΣ ΚΟΣΤΟΥΣ ΠΟΥ ΘΑ ΠΡΟΣΤΕΘΟΥΝ ΣΤΟΝ ΤΙΜΟΚΑΤΑΛΟΓΟ
A18: Α/Α | B18: Κατηγορία Εργασίας | C18: Κατάσταση | D18: Λεπτομέρειες / Τι εκκρεμεί | E18: Σημειώσεις
A19: TODO 1 | B19: Κόστος ανά Τρύπα / Διάτρηση Πασσάλων | C19: ΕΚΚΡΕΜΕΙ | D19: Να προστεθεί η αναλυτική φόρμουλα για το πώς βγαίνει το κόστος ανά τρύπα / μέτρο διάτρησης για εμάς. | E19: Θα δοθεί από τον χρήστη σε επόμενο βήμα.
A20: TODO 2 | B20: ="Μετακινήσεις Γεωτρύπανου ("&ROUND(D12,0)&"€ Λεμεσός + "&ROUND(D13,0)&"€/"&ROUND(D14,0)&"km) & Συνοδεία Αστυνομίας ("&ROUND(D15,0)&"€/km)" -> Μετακινήσεις Γεωτρύπανου (1000€ Λεμεσός + 200€/10km) & Συνοδεία Αστυνομίας (8€/km) | C20: ΟΛΟΚΛΗΡΩΘΗΚΕ | D20: ="Ενσωματώθηκε στον Τιμοκατάλογο και στη Μηχανή v5.8: "&ROUND(D12,0)&"€ εντός Λεμεσού + "&ROUND(D13,0)&"€ ανά "&ROUND(D14,0)&"km + "&ROUND(D15,0)&"€/km συνοδεία Αστυνομίας." -> Ενσωματώθηκε στον Τιμοκατάλογο και στη Μηχανή v5.8: 1000€ εντός Λεμεσού + 200€ ανά 10km + 8€/km συνοδεία Αστυνομίας. | E20: Ενεργό στο Φύλλο 3 («Τιμές & Έλεγχος») και στις δυναμικές σημειώσεις.
A21: TODO 3 | B21: Λοιπές Αναλύσεις Τιμοκαταλόγου (Χάλυβας, Κεφαλοκοπή, Εκτοξευόμενο κ.λπ.) | C21: ΕΚΚΡΕΜΕΙ | D21: Να προστεθούν σταδιακά slides (φύλλα) με το εσωτερικό κόστος και τον τρόπο εξαγωγής της τελικής τιμής για κάθε αντικείμενο. | E21: Ώστε αν αλλάξει οποιαδήποτε τιμή στην αγορά να ενημερώνεται αυτόματα όλο το σύστημα.
A22: TODO 4 | B22: ="Απομάκρυνση Εκσκαπτόμενου Χώματος & Λατομικά Τέλη (Προσωρινά "&ROUND('1_Τιμές_Εταιρείας'!D49,2)&" €/m³ εκσκαφής)" -> Απομάκρυνση Εκσκαπτόμενου Χώματος & Λατομικά Τέλη (Προσωρινά 15 €/m³ εκσκαφής) | C22: ΕΚΚΡΕΜΕΙ | D22: ="Προσωρινή τιμή "&ROUND('1_Τιμές_Εταιρείας'!D49,2)&" €/m³ επί του γεωμετρικού όγκου εκσκαφής (V_exc) με κουμπί επιλογής ΝΑΙ/ΟΧΙ στο Φύλλο 3. Εκκρεμεί η αναλυτική φόρμουλα εσωτερικού κόστους." -> Προσωρινή τιμή 15 €/m³ επί του γεωμετρικού όγκου εκσκαφής (V_exc) με κουμπί επιλογής ΝΑΙ/ΟΧΙ στο Φύλλο 3. Εκκρεμεί η αναλυτική φόρμουλα εσωτερικού κόστους. | E22: Ενεργό στο Φύλλο 3 (Κουμπί ΝΑΙ/ΟΧΙ) και στις δυναμικές σημειώσεις.
