Workbook

Sheet 1_Τιμές_Εταιρείας
A1: ΚΕΝΤΡΙΚΟΣ ΤΙΜΟΚΑΤΑΛΟΓΟΣ ΕΤΑΙΡΕΙΑΣ ΠΑΣΣΑΛΩΝ — ΕΔΡΑ: ΑΓΙΟΣ ΣΥΛΑΣ, ΛΕΜΕΣΟΣ
A2: ΚΙΤΡΙΝΟ = Τιμές μονάδας που αλλάζουν με την αγορά | ΛΕΥΚΟ = Φυσικές σταθερές & τύποι (δεν αγγίζονται)
A4: Α/Α | B4: Πυλώνας Κόστους | C4: Είδος Υλικού / Εργασίας | D4: Τιμή Μονάδας (€) [ΚΙΤΡΙΝΟ = ΑΛΛΑΖΕΙ] | E4: Μονάδα | F4: Κανόνας & Χρήση στην Κοστολόγηση
A5: 1 | B5: 1. Μετακινήσεις | C5: Μετακίνηση & Εγκατάσταση Γεωτρύπανου — Βασική τιμή (Ζώνη 1: 0–50 km) | D5: 500 | E5: €/μετακίνηση | F5: Βάση: Άγιος Συλάς. Εφάπαξ ποσό ανά εργοτάξιο, επιμερίζεται ισόποσα ανά πάσσαλο
A6: 2 | B6: 1. Μετακινήσεις | C6: Επιβάρυνση ανά επιπλέον 50 km (έξω από τα 50 km) | D6: 100 | E6: €/μετακίνηση | F6: Υπολογίζεται αυτόματα: +100 € ανά ζώνη 50km πάνω από τη βασική ακτίνα των 50km
A7: 3 | B7: 2. Τρύπημα | C7: Τρύπημα / Διάτρηση Πασσάλου Ø400mm | D7: 70 | E7: €/m | F7: Συνολικά μέτρα διάτρησης Ø400mm
A8: 4 | B8: 2. Τρύπημα | C8: Τρύπημα / Διάτρηση Πασσάλου Ø500mm | D8: 80 | E8: €/m | F8: Συνολικά μέτρα διάτρησης Ø500mm
A9: 5 | B9: 2. Τρύπημα | C9: Τρύπημα / Διάτρηση Πασσάλου Ø600mm | D9: 90 | E9: €/m | F9: Συνολικά μέτρα διάτρησης Ø600mm (Τυπική διάμετρος σχεδίου)
A10: 6 | B10: 2. Τρύπημα | C10: Τρύπημα / Διάτρηση Πασσάλου Ø700mm | D10: 100 | E10: €/m | F10: Συνολικά μέτρα διάτρησης Ø700mm
A11: 7 | B11: 2. Τρύπημα | C11: Τρύπημα / Διάτρηση Πασσάλου Ø800mm | D11: 115 | E11: €/m | F11: Συνολικά μέτρα διάτρησης Ø800mm
A12: 8 | B12: 2. Τρύπημα | C12: Τρύπημα / Διάτρηση Πασσάλου Ø900mm | D12: 130 | E12: €/m | F12: Συνολικά μέτρα διάτρησης Ø900mm
A13: 9 | B13: 2. Τρύπημα | C13: Τρύπημα / Διάτρηση Πασσάλου Ø1000mm | D13: 150 | E13: €/m | F13: Συνολικά μέτρα διάτρησης Ø1000mm
A14: 10 | B14: 2. Τρύπημα | C14: Τρύπημα / Διάτρηση Πασσάλου Ø1200mm | D14: 190 | E14: €/m | F14: Συνολικά μέτρα διάτρησης Ø1200mm
A15: 11 | B15: 2. Τρύπημα | C15: Προσαύξηση διάτρησης σε σκληρό βράχο / ειδικές συνθήκες | D15: 25 | E15: €/m | F15: Εφαρμόζεται επιπλέον ανά μέτρο όταν ζητείται διάτρηση σε σκληρό πέτρωμα
A16: 12 | B16: 3. Σκυροδέτηση | C16: Σκυρόδεμα C25/30 — Αγορά κουγκριού | D16: 105 | E16: €/m³ | F16: Όγκος = π × D²/4 × L × (1 + 10% απώλεια)
... A23: 19 | B23: 5. Ειδικές Εργασίες | C23: Κεφαλοκοπή Πασσάλων / Pile Breaking (Σπάσιμο) | D23: 60 | E23: €/πάσσαλο | F23: Καθαίρεση υπερυψωμένου σκυροδέματος (+2.00m) μέχρι τη στάθμη Cut-Off Level με υδραυλικό κόφτη
A25: Β. ΦΥΣΙΚΕΣ ΣΤΑΘΕΡΕΣ & ΠΑΓΙΟΙ ΚΑΝΟΝΕΣ (ΛΕΥΚΟ — ΔΕΝ ΑΛΛΑΖΟΥΝ ΠΟΤΕ)
A26: — | B26: Σταθερά | C26: Πυκνότητα χάλυβα (ρ) | D26: 7850 | E26: kg/m³ | F26: Φυσική σταθερά για υπολογισμό κιλών ράβδων και σούστας
A27: — | B27: Σταθερά | C27: Πάγια απώλεια / υπερκατανάλωση σκυροδέματος (+10%) | D27: 0.1 | E27: % | F27: Προστίθεται υποχρεωτικά στον γεωμετρικό όγκο της μελέτης (V_conc = V_exc × 1.10)
A28: — | B28: Σταθερά | C28: Βασική ακτίνα απόστασης (Ζώνη 1) | D28: 50 | E28: km | F28: Καλύπτει ακτίνα 50 km από Άγιο Συλά, Σπύρου Κυπριανού 32, Λεμεσό
A29: — | B29: Σταθερά | C29: Μέγιστο εμπορικό μήκος βέργας | D29: 12 | E29: m | F29: Βέργες εμπορίου 12 μέτρων (όριο πέραν του οποίου απαιτείται μάτιση)
A30: — | B30: Σταθερά | C30: Συντελεστής μήκους μάτισης ράβδων (Lapping) | D30: 50 | E30: × Φ | F30: Κανόνας επικάλυψης 50 φορές τη διάμετρο της κάθετης ράβδου
A31: — | B31: Σταθερά | C31: Μέγιστο ύψος υπερκάλυψης σκυροδέματος (+2m) | D31: 2 | E31: m | F31: Κανόνας καθαρού σκυροδέματος: έως +2.0m πάνω από το cut-off αν υπάρχει κενή διάτρηση (Δh > 0)

Sheet 2_Βάρη_Διατομών_Χάλυβα
A1: ΠΙΝΑΚΑΣ ΜΟΝΑΔΙΑΙΩΝ ΒΑΡΩΝ ΧΑΛΥΒΑ ΟΠΛΙΣΜΟΥ (B500C) — ρ = 7.850 kg/m³
A3: Διατομή (Φ) | B3: Ονομαστική Διάμετρος (mm) | C3: Εμβαδόν Διατομής (mm²) | D3: Μοναδιαίο Βάρος (kg/m) [Τύπος: π×d²/4 × 7850] | E3: Τυπική Χρήση σε Πασσάλους
A4: Y6 | B4: 6 | C4: =PI()*(B4^2)/4 | D4: =C4/1000000*7850 | E4: Ελαφριοί συνδετήρες / βοηθητικός
A5: Y8 | B5: 8 | C5: =PI()*(B5^2)/4 | D5: =C5/1000000*7850 | E5: Σούστα μικρών πασσάλων Ø400
A6: Y10 | B6: 10 | C6: =PI()*(B6^2)/4 | D6: =C6/1000000*7850 | E6: Βασική σούστα (σπείρα) πασσάλων Ø600-Ø800
A7: Y12 | B7: 12 | C7: =PI()*(B7^2)/4 | D7: =C7/1000000*7850 | E7: Σούστα βαρέων πασσάλων / ενισχύσεις
A8: Y14 | B8: 14 | C8: =PI()*(B8^2)/4 | D8: =C8/1000000*7850 | E8: Κάθετος οπλισμός μικρών φορτίων
A9: Y16 | B9: 16 | C9: =PI()*(B9^2)/4 | D9: =C9/1000000*7850 | E9: Κάθετος οπλισμός πασσάλων Ø500-Ø600
A10: Y20 | B10: 20 | C10: =PI()*(B10^2)/4 | D10: =C10/1000000*7850 | E10: Κύριος οπλισμός τυπικού σχεδίου (Ø600 12Y20)
A11: Y25 | B11: 25 | C11: =PI()*(B11^2)/4 | D11: =C11/1000000*7850 | E11: Κύριος οπλισμός βαρέων πασσάλων Ø800-Ø1000
A12: Y28 | B12: 28 | C12: =PI()*(B12^2)/4 | D12: =C12/1000000*7850 | E12: Κύριος οπλισμός υψηλών ροπών κάμψης
A13: Y32 | B13: 32 | C13: =PI()*(B13^2)/4 | D13: =C13/1000000*7850 | E13: Ειδικοί πάσσαλοι αντιστήριξης / βαθιές εκσκαφές
A14: Y40 | B14: 40 | C14: =PI()*(B14^2)/4 | D14: =C14/1000000*7850 | E14: Βαριά τεχνικά έργα / γέφυρες

Sheet 3_Υπολογιστές_Έργων_&_Math
A1: ΕΡΓΑΛΕΙΑ ΥΠΟΛΟΓΙΣΜΟΥ ΕΡΓΩΝ ΠΑΣΣΑΛΩΝ & ΕΠΕΞΗΓΗΣΗ ΜΑΘΗΜΑΤΙΚΩΝ (SANDBOX)
A2: ΓΑΛΑΖΙΑ ΚΕΛΙΑ = Εισαγωγή στοιχείων από τη μελέτη μηχανικού | Οι τιμές μονάδας αντλούνται αυτόματα από τον Τιμοκατάλογο (Φύλλο 1)
A4: 1. ΥΠΟΛΟΓΙΣΤΗΣ ΤΙΜΗΣ ΜΕΤΑΚΙΝΗΣΗΣ ΓΕΩΤΡΥΠΑΝΟΥ ΑΝΑ ΑΠΟΣΤΑΣΗ ΕΡΓΟΤΑΞΙΟΥ
A5: Εισάγετε τη χιλιομετρική απόσταση του έργου από την έδρα (Άγιος Συλάς, Σπύρου Κυπριανού 32):
A6: Παράμετρος Έργου | B6: Τιμή / Εισαγωγή | C6: Μονάδα | D6: Τύπος Υπολογισμού | E6: Αποτέλεσμα | F6: Παρατηρήσεις
A7: Οδική Απόσταση Έργου από Άγιο Συλά | B7: 50 | C7: km | D7: Εισαγωγή από μελέτη / Google Maps | E7: — | F7: Βασική ζώνη έως 50 km
A8: Επιπλέον Ζώνες των 50 km | B8: =MAX(0, ROUNDUP((B7-50)/50, 0)) | C8: ζώνες | D8: MAX(0, ROUNDUP((km − 50)/50, 0)) | E8: =B8 | F8: 0 = έως 50km, 1 = 51-100km, 2 = 101-150km
A9: Τελική Τιμή Μετακίνησης Γεωτρύπανου για το Έργο | B9: ='1_Τιμές_Εταιρείας'!D5 + (B8 * '1_Τιμές_Εταιρείας'!D6) | C9: € / μετακίνηση | D9: Βασική (500 €) + Ζώνες × 100 € | E9: =B9 | F9: Εφάπαξ ποσό μετακίνησης εργοταξίου
A10: Αριθμός Πασσάλων Έργου | B10: 8 | C10: τεμ. | D10: Εισαγωγή από μελέτη / κάτοψη | E10: — | F10: Συνολικός αριθμός πασσάλων
A11: Επιμερισμένη Τιμή Μετακίνησης ανά Πάσσαλο | B11: =B9 / B10 | C11: € / πάσσαλο | D11: Συνολική Μετακίνηση / Αριθμός Πασσάλων | E11: =B11 | F11: Χρησιμοποιείται στην κοστολόγηση ανά πάσσαλο
A13: 2. ΥΠΟΛΟΓΙΣΤΗΣ ΤΡΥΠΗΜΑΤΟΣ & ΣΚΥΡΟΔΕΜΑΤΟΣ ΠΑΣΣΑΛΩΝ (GEOMETRY & CONCRETE)
A14: Παράμετρος Έργου | B14: Τιμή / Εισαγωγή | C14: Μονάδα | D14: Τύπος Υπολογισμού | E14: Αποτέλεσμα | F14: Παρατηρήσεις
A15: Διάμετρος Τρύπας Πασσάλου (D) | B15: 600 | C15: mm | D15: Εισαγωγή από μελέτη (τομή) | E15: — | F15: Διάμετρος γεώτρησης
A16: Βάθος Διάτρησης στο Έδαφος (L) | B16: 4 | C16: m | D16: Εισαγωγή από μελέτη | E16: — | F16: Μήκος πασσάλου στο έδαφος
A17: Αριθμός Πασσάλων | B17: =B10 | C17: τεμ. | D17: Σύνδεση με υπολογιστή 1 | E17: — | F17: Πλήθος πασσάλων
A18: Συνολικά Τρέχοντα Μέτρα Τρυπήματος | B18: =B16 * B17 | C18: m | D18: Βάθος L × Αριθμός Πασσάλων | E18: =B18 | F18: Σύνολο διάτρησης έργου
A19: Κόστος Τρυπήματος ανά Τρέχον Μέτρο | B19: ='1_Τιμές_Εταιρείας'!D9 | C19: € / m | D19: Αντλείται από Τιμοκατάλογο (Ø600: 90 €/m) | E19: =B19 | F19: Τιμή μονάδας διάτρησης
A20: ΣΥΝΟΛΙΚΟ ΚΟΣΤΟΣ ΤΡΥΠΗΜΑΤΟΣ ΕΡΓΟΥ | B20: =B18 * B19 | C20: € | D20: Συνολικά μέτρα × Τιμή/m | E20: =B20 | F20: Κόστος γεώτρησης
A21: Γεωμετρικός Όγκος Εκσκαφής ανά Πάσσαλο | B21: =PI()*((B15/1000)^2)/4 * B16 | C21: m³ | D21: (π × D² / 4) × L | E21: =B21 | F21: Θεωρητικός όγκος κυλίνδρου
A22: Όγκος Σκυροδέματος ανά Πάσσαλο (+10% απώλεια) | B22: =B21 * (1 + '1_Τιμές_Εταιρείας'!D27) | C22: m³ | D22: V_exc × 1.10 (loss factor) | E22: =B22 | F22: Κουγκρί παραγγελίας ανά πάσσαλο
A23: ΣΥΝΟΛΙΚΟ ΚΟΣΤΟΣ ΣΚΥΡΟΔΕΜΑΤΟΣ ΕΡΓΟΥ | B23: =B22 * B17 * '1_Τιμές_Εταιρείας'!D17 | C23: € | D23: m³ × Πάσσαλοι × 115,00 €/m³ | E23: =B23 | F23: Κόστος κουγκριού C30/37
A25: 3. ΥΠΟΛΟΓΙΣΤΗΣ ΒΑΡΟΥΣ & ΚΟΣΤΟΥΣ ΚΛΩΒΟΥ ΟΠΛΙΣΜΟΥ (REBAR CAGE CALCULATOR)
A26: Παράμετρος Έργου | B26: Τιμή / Εισαγωγή | C26: Μονάδα | D26: Τύπος Υπολογισμού | E26: Αποτέλεσμα | F26: Παρατηρήσεις
A27: Κάθετες Ράβδοι — Πλήθος (Nvert) | B27: 12 | C27: τεμ. | D27: Εισαγωγή από σχέδιο | E27: — | F27: Περιμετρικές ράβδοι
A28: Κάθετες Ράβδοι — Διάμετρος (Yvert) | B28: 20 | C28: mm | D28: Εισαγωγή από σχέδιο | E28: — | F28: Διάμετρος κυρίως οπλισμού
A29: Starter (Αναμονή) + Γωνίες (Πάνω & Πυθμένα) | B29: 1 | C29: m | D29: 0.50m Starter + 0.50m Top + 0.00m Bot | E29: — | F29: Πρόσθετα μήκη κάθετης ράβδου
A30: Απαίτηση Μάτισης (αν L_bar > 12m) | B30: =IF((B16+B29)>'1_Τιμές_Εταιρείας'!D29, '1_Τιμές_Εταιρείας'!D30*(B28/1000), 0) | C30: m | D30: Κανόνας 50×Φ αν υπερβαίνει τα 12m | E30: =B30 | F30: 0 = ενιαία βέργα, 1.00m = μάτιση
A31: Τελικό Μήκος Κάθετης Ράβδου (L_bar) | B31: =B16 + B29 + B30 | C31: m | D31: Βάθος + Αναμονές/Γωνίες + Μάτιση | E31: =B31 | F31: Ανεπτυγμένο μήκος ράβδου
A32: Βάρος Κάθετων Ράβδων ανά Πάσσαλο | B32: =B27 * B31 * (PI()*((B28/1000)^2)/4 * '1_Τιμές_Εταιρείας'!D26) | C32: kg | D32: N_vert × L_bar × kg/m | E32: =B32 | F32: Κιλά κάθετου οπλισμού
A33: Σούστα (Σπείρα) — Διάμετρος Y & Βήμα s | B33: 10 | C33: mm | D33: Βήμα s = 150 mm, Cover = 75 mm | E33: — | F33: Y10 ανά 15cm
A34: Βάρος Σούστας ανά Πάσσαλο | B34: =ROUNDUP(B16/0.15, 0) * (PI()*((B15-150)/1000)) * (PI()*((B33/1000)^2)/4 * '1_Τιμές_Εταιρείας'!D26) | C34: kg | D34: Σπείρες × Περίμετρος × kg/m | E34: =B34 | F34: Κιλά σούστας
A35: ΣΥΝΟΛΙΚΟ ΒΑΡΟΣ ΧΑΛΥΒΑ ΑΝΑ ΠΑΣΣΑΛΟ | B35: =B32 + B34 | C35: kg | D35: Κάθετες + Σούστα | E35: =B35 | F35: Συνολικά κιλά ανά πάσσαλο
A36: ΣΥΝΟΛΙΚΟ ΚΟΣΤΟΣ ΧΑΛΥΒΑ ΕΡΓΟΥ | B36: =B35 * B17 * '1_Τιμές_Εταιρείας'!D19 | C36: € | D36: kg/πάσσαλο × Πάσσαλοι × 1,10 €/kg | E36: =B36 | F36: Συνολικό κόστος σιδήρου B500C
A38: 4. ΥΠΟΛΟΓΙΣΤΗΣ ΥΨΟΜΕΤΡΩΝ, SLEEVES & ΚΕΦΑΛΟΚΟΠΗΣ (ELEVATION, SLEEVES & BREAKING)
A39: Παράμετρος Έργου | B39: Τιμή / Εισαγωγή | C39: Μονάδα | D39: Τύπος Υπολογισμού | E39: Αποτέλεσμα | F39: Παρατηρήσεις
A40: Στάθμη Πλατφόρμας Γεωτρύπανου (WPL) | B40: 0 | C40: m | D40: Εισαγωγή από τοπογραφικό σχεδίου | E40: — | F40: Στάθμη έναρξης διάτρησης
A41: Στάθμη Αποκοπής Πασσάλου (Cut-Off Level) | B41: 0 | C41: m | D41: Εισαγωγή από ξυλότυπο θεμελίωσης | E41: — | F41: Στάθμη κεφαλής πασσάλου
A42: Διαφορά Υψομέτρου Τρυπήματος - Cut-off (Δh) | B42: =B40-B41 | C42: m | D42: WPL − Cut-off Level (Κενή Διάτρηση) | E42: =B42 | F42: ΚΟΚΚΙΝΟΣ ΣΥΝΑΓΕΡΜΟΣ αν δεν δίνεται!
A43: Ύψος Υπερκάλυψης Σκυροδέματος (Overconcreting) | B43: =IF(B42>0, MIN('1_Τιμές_Εταιρείας'!D31, B42), 0.0) | C43: m | D43: Έως +2.0m πάνω από cut-off αν Δh > 0 | E43: =B43 | F43: Κανόνας υγιούς σκυροδέματος κεφαλής
A44: Συνολικό Βάθος Διάτρησης ανά Πάσσαλο (L_drill) | B44: =B16 + B42 | C44: m | D44: L_pile + Δh | E44: =B44 | F44: Συνολικό μήκος τρυπήματος
...

Sheet 4_Κανόνες_&_Πολιτική
A1: ΚΑΝΟΝΕΣ ΤΙΜΟΚΑΤΑΛΟΓΟΥ ΠΑΣΣΑΛΩΝ & ΠΟΛΙΤΙΚΗ ΑΠΟΥΣΙΑΣ ΥΛΙΚΟΥ (MISSING MATERIAL POLICY)
A3: Θέμα / Πεδίο | B3: Κανόνας Λειτουργίας & Οδηγία για το AI
A4: Κανόνας Χρωματισμού | B4: • ΚΙΤΡΙΝΟ (#FFF2CC): Τιμές μονάδας που αλλάζουν με τους καιρούς / συνθήκες αγοράς. • ΛΕΥΚΟ (Χωρίς γέμισμα): Φυσικές σταθερές (7850 kg/m³, π), γεωμετρία και δυναμικοί τύποι. • ΓΑΛΑΖΙΟ (#DDEBF7): Εισαγωγή στοιχείων ανά έργο στους διαδραστικούς υπολογιστές. • ΚΟΚΚΙΝΟ (#FEE2E2): Συναγερμός ελλιπών δεδομένων (Missing Elevation / Cut-Off Gap).
A5: Κανόνας Μετακινήσεων & Επιμερισμού | B5: Το ποσό μετακίνησης γεωτρύπανου είναι εφάπαξ ανά εργοτάξιο και επιμερίζεται ισόποσα στο κόστος ανά πάσσαλο: Τιμή ανά πάσσαλο = Συνολικό Κόστος Μετακίνησης / Αριθμός Πασσάλων Έργου. Εάν στο έργο δεν χρεώνονται μετακινήσεις, τίθεται 0.00 €.
A6: Κανόνας Τρυπήματος (Διάτρησης) | B6: Το τρύπημα τιμολογείται ΑΠΟΚΛΕΙΣΤΙΚΑ σε τρέχοντα μέτρα (m) βάσει της ονομαστικής διαμέτρου της τρύπας (Ø400, Ø500, Ø600, Ø700, Ø800, Ø900, Ø1000, Ø1200mm). Εάν υπάρχει διαφορά στάθμης πλατφόρμας έναντι cut-off (Δh > 0), τα τρέχοντα μέτρα ισούνται με το συνολικό βάθος L_drill = L_pile + Δh. Σε περίπτωση σκληρού βράχου, εφαρμόζεται πρόσθετη χρέωση ανά μέτρο.
A7: Κανόνας Σκυροδέματος (Κουγκρί) | B7: Το σκυρόδεμα τιμολογείται ανά κυβικό μέτρο (m³) έτοιμου σκυροδέματος (C25/30 ή C30/37). Στον γεωμετρικό όγκο της οπής προστίθεται υποχρεωτικά συντελεστής απώλειας / υπερκατανάλωσης +10% (V_conc = V_exc × 1.10) για κάλυψη κοιλοτήτων και απωλειών εδάφους.
A8: Κανόνας Χάλυβα Οπλισμού (Κλωβοί B500C) | B8: Ο σίδηρος τιμολογείται ΑΠΟΚΛΕΙΣΤΙΚΑ με βάση το βάρος σε ευρώ ανά κιλό (€/kg) ενιαία (1,10 €/kg) τόσο για τις κάθετες ράβδους όσο και για τη σούστα (σπείρα). Τα κιλά υπολογίζονται από τον ενιαίο πίνακα βαρών (Φύλλο 2). Εάν το μήκος της κάθετης ράβδου υπερβαίνει τα 12.00 m, υπολογίζεται υποχρεωτικά μάτιση (lapping) μήκους τουλάχιστον 50 φορές τη διάμετρο (50Φ).
A9: Κανόνας Στάθμης Cut-off & Υψομετρικής Διαφοράς (Κενή Διάτρηση / Empty Bore) | B9: Όταν η διάτρηση ξεκινά από στάθμη πλατφόρμας (WPL) υψηλότερη από τη στάθμη αποκοπής (Cut-off Level), υπάρχει υψομετρική διαφορά Δh = WPL − Cut-off. Σε αυτή την περίπτωση, το τρύπημα αυξάνεται κατά Δh (L_drill = L_pile + Δh), καθιστώντας τον όγκο διάτρησης μεγαλύτερο από τον όγκο σκυροδέτησης.
A10: Κανόνας Υπερκάλυψης Σκυροδέματος (+2.00m Overconcreting) | B10: Για λόγους διατήρησης καθαρού και υγιούς σκυροδέματος στο σώμα του πασσάλου, το σκυρόδεμα υπερβαίνει το Cut-off Level κατά έως +2.00 μέτρα (h_overc = MIN(2.0, Δh)). Εάν η διαφορά Δh είναι μικρότερη των 2.0 μέτρων, το σκυρόδεμα φτάνει μέχρι τη στάθμη πλατφόρμας.
A11: Κανόνας Sleeves Αναμονών Starter (Debonding Sleeves) | B11: Εφόσον το σκυρόδεμα υπερκαλύψει τα starter bars (αναμονές), τοποθετούνται υποχρεωτικά προστατευτικά sleeves σε κάθε κάθετη ράβδο (N_vert τεμάχια ανά πάσσαλο, 3,50 €/τεμ.). Τα sleeves αποτρέπουν την πρόσφυση του σκυροδέματος στις αναμονές ώστε να σπάσει η κεφαλή χωρίς να καταστραφεί ο οπλισμός σύνδεσης με το πέδιλο.
A12: Κανόνας Κεφαλοκοπής Πασσάλου (Pile Breaking / Cropping) | B12: Όταν υπάρχει overconcreting (Δh > 0), απαιτείται καθαίρεση και σπάσιμο του υπερυψωμένου σκυροδέματος μέχρι τη στάθμη Cut-Off Level με υδραυλικό κόφτη ή χειροκίνητα εργαλεία. Χρεώνεται 1 τεμάχιο κεφαλοκοπής ανά πάσσαλο (60,00 €/πάσσαλο).
A13: ΚΑΝΟΝΑΣ ΚΟΚΚΙΝΟΥ ΣΥΝΑΓΕΡΜΟΥ (RED ALERT ΣΕ ΕΛΛΕΙΨΗ ΥΨΟΜΕΤΡΩΝ ΣΧΕΔΙΟΥ) | B13: Πολλές φορές από τα σχέδια δεν φαίνεται η υψομετρική διαφορά τρυπήματος - cut-off: -> Το AI θέτει προσωρινά Δh = 0.00m, αλλά υποχρεούται να το χρωματίσει με ΚΟΚΚΙΝΟ ΣΥΝΑΓΕΡΜΟ (#FEE2E2 / #991B1B) στο Φύλλο 2 και να εμφανίσει κόκκινο warning banner στην κορυφή του Φύλλου 1. -> ΑΠΑΓΟΡΕΥΕΤΑΙ ΑΥΣΤΗΡΑ η αποστολή προσφοράς στον πελάτη χωρίς ρητή ειδοποίηση ότι εκκρεμεί επιβεβαίωση της στάθμης εργασίας, ώστε να μην υποτιμηθούν τα μέτρα διάτρησης, τα sleeves και η κεφαλοκοπή!
A14: ΚΑΝΟΝΑΣ ΑΠΟΥΣΙΑΣ ΥΛΙΚΟΥ (ΥΠΟΧΡΕΩΤΙΚΟ ΜΗΝΥΜΑ AI) | B14: Εάν ο μελετητής ζητήσει διάμετρο πασσάλου ή υλικό που ΔΕΝ υπάρχει στον παρόντα τιμοκατάλογο πασσάλων (π.χ. διάμετρος Ø1400mm, ειδική κατηγορία σκυροδέματος C40/50, διατομή εκτός πίνακα Y6–Y40, ανοξείδωτο χάλυβα, ειδικούς αποστάτες): -> Το σύστημα AI ΑΠΑΓΟΡΕΥΕΤΑΙ ΑΥΣΤΗΡΑ να μαντέψει ή να εφεύρει τιμή! -> Το σύστημα ΣΤΑΜΑΤΑΕΙ και εμφανίζει στον χρήστη ρητά το μήνυμα: «Δεν υπάρχει αυτό το είδος ([Όνομα Είδους]) στον τιμοκατάλογο πασσάλων. Καθοδήγησέ με με τιμή να ξέρω.» -> Μόνο αφού ο χρήστης δώσει την τιμή, η κοστολόγηση προχωρά.
A15: Κανόνας Απόστασης (Έδρα Άγιος Συλάς) | B15: Αφετηρία: Άγιος Συλάς, Σπύρου Κυπριανού 32, Λεμεσός. • Ζώνη 1 (0 – 50 km): Βασική τιμή μετακίνησης γεωτρύπανου (500 €). • Κάθε επιπλέον 50 km (ή μέρος αυτών): +100,00 € ανά μετακίνηση αυτόματα.
