Workbook
Name N_b2_breaking_note: 'Τεχνικοί Υπολογισμοί'!$G$61
Name N_b2_breaking_price: 'Τεχνικοί Υπολογισμοί'!$E$61
Name N_b2_breaking_qty: 'Τεχνικοί Υπολογισμοί'!$D$61
Name N_b2_breaking_total: 'Τεχνικοί Υπολογισμοί'!$F$61
Name N_b2_conc_note: 'Τεχνικοί Υπολογισμοί'!$G$55
Name N_b2_conc_price: 'Τεχνικοί Υπολογισμοί'!$E$55
Name N_b2_conc_qty: 'Τεχνικοί Υπολογισμοί'!$D$55
Name N_b2_conc_total: 'Τεχνικοί Υπολογισμοί'!$F$55
Name N_b2_drill_800_note: 'Τεχνικοί Υπολογισμοί'!$G$54
Name N_b2_drill_800_price: 'Τεχνικοί Υπολογισμοί'!$E$54
Name N_b2_drill_800_qty: 'Τεχνικοί Υπολογισμοί'!$D$54
Name N_b2_drill_800_total: 'Τεχνικοί Υπολογισμοί'!$F$54
Name N_b2_grand_total: 'Τεχνικοί Υπολογισμοί'!$F$62
Name N_b2_grand_total_note: 'Τεχνικοί Υπολογισμοί'!$G$62
Name N_b2_mob_note: 'Τεχνικοί Υπολογισμοί'!$G$53
Name N_b2_mob_price: 'Τεχνικοί Υπολογισμοί'!$E$53
Name N_b2_mob_qty: 'Τεχνικοί Υπολογισμοί'!$D$53
Name N_b2_mob_total: 'Τεχνικοί Υπολογισμοί'!$F$53
Name N_b2_sleeve_note: 'Τεχνικοί Υπολογισμοί'!$G$60
Name N_b2_sleeve_price: 'Τεχνικοί Υπολογισμοί'!$E$60
Name N_b2_sleeve_qty: 'Τεχνικοί Υπολογισμοί'!$D$60
Name N_b2_sleeve_total: 'Τεχνικοί Υπολογισμοί'!$F$60
Name N_b2_steel_head_note: 'Τεχνικοί Υπολογισμοί'!$G$58
Name N_b2_steel_head_price: 'Τεχνικοί Υπολογισμοί'!$E$58
Name N_b2_steel_head_qty: 'Τεχνικοί Υπολογισμοί'!$D$58
Name N_b2_steel_head_total: 'Τεχνικοί Υπολογισμοί'!$F$58
Name N_b2_steel_note: 'Τεχνικοί Υπολογισμοί'!$G$59
Name N_b2_steel_price: 'Τεχνικοί Υπολογισμοί'!$E$59
Name N_b2_steel_qty: 'Τεχνικοί Υπολογισμοί'!$D$59
Name N_b2_steel_spiral_note: 'Τεχνικοί Υπολογισμοί'!$G$57
Name N_b2_steel_spiral_price: 'Τεχνικοί Υπολογισμοί'!$E$57
Name N_b2_steel_spiral_qty: 'Τεχνικοί Υπολογισμοί'!$D$57
Name N_b2_steel_spiral_total: 'Τεχνικοί Υπολογισμοί'!$F$57
Name N_b2_steel_total: 'Τεχνικοί Υπολογισμοί'!$F$59
Name N_b2_steel_vert_note: 'Τεχνικοί Υπολογισμοί'!$G$56
Name N_b2_steel_vert_price: 'Τεχνικοί Υπολογισμοί'!$E$56
Name N_b2_steel_vert_qty: 'Τεχνικοί Υπολογισμοί'!$D$56
Name N_b2_steel_vert_total: 'Τεχνικοί Υπολογισμοί'!$F$56
Name N_c_barlen: 'Τεχνικοί Υπολογισμοί'!$D$68
Name N_c_density: 'Τεχνικοί Υπολογισμοί'!$D$67
Name N_c_lap: 'Τεχνικοί Υπολογισμοί'!$D$69
Name N_c_loss: 'Τεχνικοί Υπολογισμοί'!$D$66
Name N_c_overc: 'Τεχνικοί Υπολογισμοί'!$D$70
Name N_c_pi: 'Τεχνικοί Υπολογισμοί'!$D$71
Name N_c_starter_off: 'Τεχνικοί Υπολογισμοί'!$D$72
Name N_c_top_bend: 'Τεχνικοί Υπολογισμοί'!$D$73
Name N_conc_class: 'Τεχνικοί Υπολογισμοί'!$D$18
Name N_cover_mm: 'Τεχνικοί Υπολογισμοί'!$D$19
Name N_dist_km: 'Τιμές & Έλεγχος'!$D$6
Name N_extra_zones: 'Τεχνικοί Υπολογισμοί'!$D$9
Name N_g0_bottom_bend: 'Τεχνικοί Υπολογισμοί'!$D$32
Name N_g0_breaking: 'Τεχνικοί Υπολογισμοί'!$D$98
Name N_g0_count: 'Τεχνικοί Υπολογισμοί'!$D$23
Name N_g0_cutoff: 'Τεχνικοί Υπολογισμοί'!$D$26
Name N_g0_D_cage: 'Τεχνικοί Υπολογισμοί'!$D$83
Name N_g0_D_mm: 'Τεχνικοί Υπολογισμοί'!$D$24
Name N_g0_dh: 'Τεχνικοί Υπολογισμοί'!$D$77
Name N_g0_end_zone: 'Τεχνικοί Υπολογισμοί'!$D$36
Name N_g0_extra_len: 'Τεχνικοί Υπολογισμοί'!$D$41
Name N_g0_extra_n: 'Τεχνικοί Υπολογισμοί'!$D$39

Sheet Οικονομική Προσφορά
A1: ΘΕΜΕΛΙΟΤΕΧΝΙΚΗ ΛΤΔ — ΟΙΚΟΝΟΜΙΚΗ ΠΡΟΣΦΟΡΑ ΠΑΣΣΑΛΩΝ
A2: Έργο: ΠΟΛΥΚΑΤΟΙΚΙΑ KHALDOON AND OMAR (APARTMENT BUILDING) | Πελάτης: C+ Studio / LE. IR CY DEVELOPMENTS LTD (Khaldoon & Omar) | Τοποθεσία: Λάρνακα (Μετακίνηση: 1.000€ Λεμεσός + 200€/10km + 8€/km Συνοδεία Αστυνομίας) | Τιμές από Φύλλο 3: «Τιμές & Έλεγχος»
A7: Α/Α | B7: Περιγραφή Εργασίας / Υλικού | C7: Ποσότητα | D7: Μονάδα | E7: Τιμή Μονάδας (€) [Από «Τιμές & Έλεγχος»] | F7: Σύνολο (€) | G7: Μέσο Κόστος ανά Πάσσαλο (€)
A8: 1 | B8: Μετακινήσεις γεωτρύπανου & Συνοδεία Αστυνομίας (επιμερισμός ανά πάσσαλο) | C8: ='Τεχνικοί Υπολογισμοί'!$D$14 -> 18 | D8: πάσσαλο | E8: ='Τεχνικοί Υπολογισμοί'!$D$15 -> 177.77778 | F8: =$C$8*$E$8 -> 3200 | G8: =$F$8/'Τεχνικοί Υπολογισμοί'!$D$14 -> 177.77778
A9: 2 | B9: Τρύπημα / διάτρηση πασσάλων Ø800mm (18 τεμ.) | C9: ='Τεχνικοί Υπολογισμοί'!$D$45 -> 342.9 | D9: m | E9: ='Τιμές & Έλεγχος'!$D$9 -> 90 | F9: =$C$9*$E$9 -> 30861 | G9: =$F$9/'Τεχνικοί Υπολογισμοί'!$D$14 -> 1714.5
A10: 3 | B10: ="Σκυροδέτηση πασσάλων "&'Τεχνικοί Υπολογισμοί'!$D$18&" (με απώλεια +"&ROUND('Τεχνικοί Υπολογισμοί'!$D$66*100,0)&"%)" -> Σκυροδέτηση πασσάλων C40/50 (με απώλεια +10%) | C10: ='Τεχνικοί Υπολογισμοί'!$D$46 -> 174.41871 | D10: m³ | E10: ='Τιμές & Έλεγχος'!$D$21 -> 116 | F10: =$C$10*$E$10 -> 20232.57 | G10: =$F$10/'Τεχνικοί Υπολογισμοί'!$D$14 -> 1124.0317
A11: 4 | B11: ="Χάλυβας οπλισμού B500C (κάθετα σίδερα "&'Τεχνικοί Υπολογισμοί'!$D$28&"Φ"&'Τεχνικοί Υπολογισμοί'!$D$29&", σούστα Φ"&'Τεχνικοί Υπολογισμοί'!$D$34&"/"&ROUND('Τεχνικοί Υπολογισμοί'!$D$37/10,0)&" & στεφάνια αναμονής)" -> Χάλυβας οπλισμού B500C (κάθετα σίδερα 16Φ20, σούστα Φ10/15 & στεφάνια αναμονής) | C11: ='Τεχνικοί Υπολογισμοί'!$D$47 -> 15091.818 | D11: kg | E11: ='Τιμές & Έλεγχος'!$D$10 -> 1.1 | F11: =$C$11*$E$11 -> 16601 | G11: =$F$11/'Τεχνικοί Υπολογισμοί'!$D$14 -> 922.27776
A12: 5 | B12: ="Sleeves προστασίας αναμονών starter (Sleeve Φ32 για κάθετα σίδερα Φ"&'Τεχνικοί Υπολογισμοί'!$D$29&")" -> Sleeves προστασίας αναμονών starter (Sleeve Φ32 για κάθετα σίδερα Φ20) | C12: ='Τεχνικοί Υπολογισμοί'!$D$48 -> 288 | D12: τεμ. | E12: ='Τιμές & Έλεγχος'!$D$35 -> 3 | F12: =$C$12*$E$12 -> 864 | G12: =$F$12/'Τεχνικοί Υπολογισμοί'!$D$14 -> 48
A13: 6 | B13: Κεφαλοκοπή πασσάλων / Pile Breaking | C13: ='Τεχνικοί Υπολογισμοί'!$D$49 -> 18 | D13: τεμ. | E13: ='Τιμές & Έλεγχος'!$D$11 -> 150 | F13: =$C$13*$E$13 -> 2700 | G13: =$F$13/'Τεχνικοί Υπολογισμοί'!$D$14 -> 150
A14: ΓΕΝΙΚΟ ΣΥΝΟΛΟ ΠΡΟΣΦΟΡΑΣ (ΧΩΡΙΣ Φ.Π.Α.) | F14: =$F$8+$F$9+$F$10+$F$11+$F$12+$F$13 -> 74458.57 | G14: =$F$14/'Τεχνικοί Υπολογισμοί'!$D$14 -> 4136.5872
A16: ΟΡΟΙ, ΠΑΡΑΔΟΧΕΣ & ΠΑΡΑΤΗΡΗΣΕΙΣ (100% ΔΥΝΑΜΙΚΕΣ ΣΗΜΕΙΩΣΕΙΣ — ΕΝΗΜΕΡΩΝΟΝΤΑΙ ΑΥΤΟΜΑΤΑ ΑΠΟ ΤΟ ΦΥΛΛΟ «Τιμές & Έλεγχος»):
A17: ="1. Στις τιμές ΔΕΝ περιλαμβάνεται ο Φ.Π.Α. — Γενικό Σύνολο Προσφοράς: "&ROUND($F$14,2)&" € (Μέσο κόστος ανά πάσσαλο: "&ROUND($F$14/'Τεχνικοί Υπολογισμοί'!$D$14,2)&" € για "&'Τεχνικοί Υπολογισμοί'!$D$14&" πασσάλους)." -> 1. Στις τιμές ΔΕΝ περιλαμβάνεται ο Φ.Π.Α. — Γενικό Σύνολο Προσφοράς: 74458.57 € (Μέσο κόστος ανά πάσσαλο: 4136.59 € για 18 πασσάλους).
A18: ="2. Μετακινήσεις γεωτρύπανου: Βασική Λεμεσού ("&ROUND('Τιμές & Έλεγχος'!$D$7,2)&" €) + Εκτός Λεμεσού ανά "&ROUND('Τεχνικοί Υπολογισμοί'!$D$8,0)&"km ("&'Τεχνικοί Υπολογισμοί'!$D$9&" × "&ROUND('Τιμές & Έλεγχος'!$D$8,2)&" € = "&ROUND('Τεχνικοί Υπολογισμοί'!$D$9*'Τιμές & Έλεγχος'!$D$8,2)&" €) + Συνοδεία Αστυνομίας ("&ROUND('Τιμές & Έλεγχος'!$D$38,1)&" km × "&ROUND('Τιμές & Έλεγχος'!$D$39,2)&" €/km = "&ROUND('Τιμές & Έλεγχος'!$D$40,2)&" €) = "&ROUND('Τεχνικοί Υπολογισμοί'!$D$13,2)&" € ("&ROUND($E$8,2)&" €/πάσσαλο)." -> 2. Μετακινήσεις γεωτρύπανου: Βασική Λεμεσού (1000 €) + Εκτός Λεμεσού ανά 10km (8 × 200 € = 1600 €) + Συνοδεία Αστυνομίας (75 km × 8 €/km = 600 €) = 3200 € (177.78 €/πάσσαλο).
A19: ="3. Εκσκαφή / Διάτρηση (από στάθμη πλατφόρμας WPL "&ROUND('Τεχνικοί Υπολογισμοί'!$D$17,2)&"m): Ύψος σκυροδετημένου πασσάλου = "&ROUND('Τεχνικοί Υπολογισμοί'!$D$25,3)&"m, Συνολικά μέτρα διάτρησης = "&ROUND('Τεχνικοί Υπολογισμοί'!$D$45,2)&"m × Τιμή μέτρου ("&ROUND($E$9,2)&" €) = "&ROUND($F$9,2)&" €." -> 3. Εκσκαφή / Διάτρηση (από στάθμη πλατφόρμας WPL 0m): Ύψος σκυροδετημένου πασσάλου = 15.525m, Συνολικά μέτρα διάτρησης = 342.9m × Τιμή μέτρου (90 €) = 30861 €.
A20: ="4. Σκυρόδεμα "&'Τεχνικοί Υπολογισμοί'!$D$18&": ROUND(Αγορά "&ROUND('Τιμές & Έλεγχος'!$D$15,2)&" €/m³ + Τοποθέτηση "&ROUND('Τιμές & Έλεγχος'!$D$16,2)&" €/m³ + Αντλία "&ROUND('Τιμές & Έλεγχος'!$D$20,2)&" €/m³, 0) = "&ROUND($E$10,0)&" €/m³ × "&ROUND('Τεχνικοί Υπολογισμοί'!$D$46,2)&" m³ = "&ROUND($F$10,2)&" €." -> 4. Σκυρόδεμα C40/50: ROUND(Αγορά 94 €/m³ + Τοποθέτηση 15 €/m³ + Αντλία 6.71 €/m³, 0) = 116 €/m³ × 174.42 m³ = 20232.57 €.
A21: ="5. Οπλισμός κλωβού ("&'Τεχνικοί Υπολογισμοί'!$D$28&"Φ"&'Τεχνικοί Υπολογισμοί'!$D$29&" + σούστα Φ"&'Τεχνικοί Υπολογισμοί'!$D$34&"/"&ROUND('Τεχνικοί Υπολογισμοί'!$D$37/10,0)&"): Αναμονή starter = "&ROUND('Τεχνικοί Υπολογισμοί'!$D$30,2)&"m, Γωνία πάνω = "&ROUND('Τεχνικοί Υπολογισμοί'!$D$31,2)&"m, Γωνία κάτω = "&ROUND('Τεχνικοί Υπολογισμοί'!$D$32,2)&"m, Ύψος μάτισης = "&ROUND('Τεχνικοί Υπολογισμοί'!$D$33,2)&"m ("&'Τεχνικοί Υπολογισμοί'!$D$86&" μάτιση), Σπείρες σούστας = "&'Τεχνικοί Υπολογισμοί'!$D$90&" (με +1) + "&'Τεχνικοί Υπολογισμοί'!$D$93&" στεφάνια αναμονής (χωρίς +1) → "&ROUND('Τεχνικοί Υπολογισμοί'!$D$96,2)&" kg/πασσ., Σύνολο = "&ROUND('Τεχνικοί Υπολογισμοί'!$D$47,1)&" kg × Τιμή κιλού ("&ROUND($E$11,2)&" €) = "&ROUND($F$11,2)&" €." -> 5. Οπλισμός κλωβού (16Φ20 + σούστα Φ10/15): Αναμονή starter = 1m, Γωνία πάνω = 0m, Γωνία κάτω = 0m, Ύψος μάτισης = 1.15m (1 μάτιση), Σπείρες σούστας = 105 (με +1) + 7 στεφάνια αναμονής (χωρίς +1) → 838.43 kg/πασσ., Σύνολο = 15091.8 kg × Τιμή κιλού (1.1 €) = 16601 €.
A22: ="6. Sleeves αναμονών (Sleeve Φ32 για Φ"&'Τεχνικοί Υπολογισμοί'!$D$29&"): [Χρεωστέο μήκος "&ROUND('Τιμές & Έλεγχος'!$D$29,2)&"m × "&ROUND('Τιμές & Έλεγχος'!$D$27,4)&" €/m + Εργατικά ("&ROUND('Τιμές & Έλεγχος'!$D$31,4)&" €) + Τέλλα ("&ROUND('Τιμές & Έλεγχος'!$D$32,4)&" €) = "&ROUND('Τιμές & Έλεγχος'!$D$33,4)&" €] × "&ROUND('Τιμές & Έλεγχος'!$D$34,2)&" (Overhead/Profit/Damages) = "&ROUND($E$12,4)&" €/τεμ. × "&'Τεχνικοί Υπολογισμοί'!$D$48&" τεμ. = "&ROUND($F$12,2)&" € | Κεφαλοκοπή: "&'Τεχνικοί Υπολογισμοί'!$D$49&" τεμ. × "&ROUND($E$13,2)&" € = "&ROUND($F$13,2)&" €." -> 6. Sleeves αναμονών (Sleeve Φ32 για Φ20): [Χρεωστέο μήκος 1m × 1.34 €/m + Εργατικά (0.78 €) + Τέλλα (0.0876 €) = 2.2076 €] × 1.3 (Overhead/Profit/Damages) = 3 €/τεμ. × 288 τεμ. = 864 € | Κεφαλοκοπή: 18 τεμ. × 150 € = 2700 €.
A23: 7. Πληρωμή βάσει επιμετρήσεων πραγματικά εκτελεσθέντων μέτρων διάτρησης, κυβικών σκυροδέματος και κιλών οπλισμού. Όλες οι τιμές μονάδας ορίζονται στο Φύλλο 3 («Τιμές & Έλεγχος») και ενημερώνουν αυτόματα όλα τα φύλλα και τις σημειώσεις.

Sheet Τεχνικοί Υπολογισμοί
A1: ΘΕΜΕΛΙΟΤΕΧΝΙΚΗ ΛΤΔ — ΤΕΧΝΙΚΟΙ ΥΠΟΛΟΓΙΣΜΟΙ ΔΙΑΤΡΗΤΩΝ ΠΑΣΣΑΛΩΝ
A2: Έργο: ΠΟΛΥΚΑΤΟΙΚΙΑ KHALDOON AND OMAR (APARTMENT BUILDING) | Πελάτης: C+ Studio / LE. IR CY DEVELOPMENTS LTD (Khaldoon & Omar) | Μελέτη: X.S.N CIVIL ENGINEER L.L.C. (Xanthos Neofytou) — Project No. 2633 (07/2026) | Μηχανή v5.7 (Τιμές από Φύλλο 3: «Τιμές & Έλεγχος»)
A4: 1. ΔΕΔΟΜΕΝΑ ΣΧΕΔΙΟΥ & ΥΨΟΜΕΤΡΑ
A5: Κωδ. | B5: Παράμετρος | C5: Μονάδα | D5: Τιμή | G5: Παρατηρήσεις / Προέλευση
A6: Τομέας 1 — Μετακινήσεις & Συνοδεία Αστυνομίας (Τιμές από το Φύλλο 3: «Τιμές & Έλεγχος»)
A7: 1.1.1 | B7: Χιλιόμετρα εκτός Λεμεσού (0 km αν το έργο είναι μέσα στη Λεμεσό) | C7: km | D7: ='Τιμές & Έλεγχος'!$D$6 -> 75 | G7: Από Φύλλο 3 («Τιμές & Έλεγχος» Τ.1)
A8: 1.1.2 | B8: Βήμα χιλιομετρικής χρέωσης εκτός Λεμεσού (ανά 10 km) | C8: km | D8: 10 | G8: Τιμοκατάλογος (γρ. 28)
A9: 1.1.3 | B9: Δεκάδες χιλιομέτρων εκτός Λεμεσού (ανά 10 km) | C9: ζώνες | D9: =IF('Τιμές & Έλεγχος'!$D$6>0,ROUNDUP(ROUND('Τιμές & Έλεγχος'!$D$6/$D$8,9),0),0) -> 8 | G9: ROUNDUP(km εκτός Λεμεσού / 10, 0)
A10: 1.1.4 | B10: Μετακίνηση — βασική τιμή εντός Λεμεσού | C10: € | D10: ='Τιμές & Έλεγχος'!$D$7 -> 1000 | G10: Από Φύλλο 3 («Τιμές & Έλεγχος» Τ.2 = 1.000,00 €)
A11: 1.1.5 | B11: Μετακίνηση — επιβάρυνση ανά 10 km εκτός Λεμεσού | C11: € | D11: ='Τιμές & Έλεγχος'!$D$8 -> 200 | G11: Από Φύλλο 3 («Τιμές & Έλεγχος» Τ.3 = 200,00 €/10km)
A12: 1.1.6 | B12: Κόστος Συνοδείας Αστυνομίας (Χιλιόμετρα × 8,00 €/km) | C12: € | D12: ='Τιμές & Έλεγχος'!$D$40 -> 600 | G12: Από Φύλλο 3 («Τιμές & Έλεγχος» Τ.Δ.3 = police_km × 8,00 €/km)
A13: 1.1.7 | B13: Συνολικό εφάπαξ ποσό μετακίνησης & συνοδείας Αστυνομίας | C13: € | D13: ='Τιμές & Έλεγχος'!$D$7+$D$9*'Τιμές & Έλεγχος'!$D$8+'Τιμές & Έλεγχος'!$D$40 -> 3200 | G13: Βασική Λεμεσού (1.000€) + Δεκάδες km × 200€ + Συνοδεία Αστυνομίας
A14: 1.1.8 | B14: Συνολικό πλήθος πασσάλων έργου | C14: τεμ. | D14: =$D$23+$E$23 -> 18 | G14: Άθροισμα ομάδων
A15: 1.1.9 | B15: Επιμερισμένη μετακίνηση ανά πάσσαλο | C15: € | D15: =$D$13/$D$14 -> 177.77778 | G15: Συνολική μετακίνηση ÷ Πάσσαλοι
A16: Τομέας 2 — Υψόμετρα & Σκυρόδεμα (WPL κοινό για όλους, Cut-Off ανά πάσσαλο στον Τομέα 3)
A17: 1.2.1 | B17: Στάθμη πλατφόρμας γεωτρύπανου (WPL) — κοινή για όλους τους πασσάλους | C17: m | D17: 0 | G17: WPL = +0.00 m (βάσει email: «Τα Piles θα πρέπει να γίνουν μέχρι το +0.00» & σχεδίου S4.2)
A18: 1.2.2 | B18: Κατηγορία σκυροδέματος | C18: - | D18: C40/50 | G18: Από σχέδιο S4.2 («Concrete Strength : C40/50 MPa» & πίνακας αναμονών C40/50)
A19: 1.2.3 | B19: Επικάλυψη οπλισμού (Cover) | C19: mm | D19: 75 | G19: Από σχέδιο S4.2 («Cover - 75mm»)
A20: Τομέας 3 — Ομάδες πασσάλων & κλωβός οπλισμού (μία στήλη ανά ομάδα)
A21: Κωδ. | B21: Παράμετρος | C21: Μονάδα | D21: Ομάδα 1 | E21: Ομάδα 2 | G21: Παρατηρήσεις
A22: 1.3.0 | B22: Πάσσαλοι | D22: Ø800 (Cut-Off -3.475m) P1–P6, P8–P18 | E22: Ø800 (Cut-Off -4.375m) P7 (Ανελκυστήρας)
A23: 1.3.1 | B23: Πλήθος πασσάλων ομάδας | C23: τεμ. | D23: 17 | E23: 1 | F23: =$D$23+$E$23 -> 18 | G23: Από Κατάλογο Πασσάλων & κάτοψη Χάραξης Πασσάλων (Φύλλο S4.1): P1–P18 = 18 τεμ.
A24: 1.3.2 | B24: Διάμετρος τρύπας πασσάλου | C24: mm | D24: 800 | E24: 800 | G24: Από Κατάλογο Πασσάλων S4.1 (800 mm) & Λεπτομέρεια Πασσάλων S4.2 (PILE 800mm)
A25: 1.3.3 | B25: Ύψος σκυροδετημένου πασσάλου (κάτω από το Cut-Off) | C25: m | D25: 15.525 | E25: 15.525 | G25: Ύψος σκυροδετημένου πασσάλου κάτω από το Cut-Off: 15.525 m (CAST HEIGHT στο S4.2) για όλους τους 18 πασσάλους (διόρθωση λάθους μελέτης στον P7 ώστε να παραμείνει ίδιο μέγεθος σκυροδετημένου πασσάλου)
A26: 1.3.4 | B26: Στάθμη αποκοπής κεφαλής πασσάλου (Cut-Off) | C26: m | D26: -3.475 | E26: -4.375 | G26: Από Κατάλογο Πασσάλων S4.1: -3475 mm (-3.475 m) για P1–P6, P8–P18 και -4375 mm (-4.375 m, 90 cm βαθύτερα) για P7 (ανελκυστήρας)
A27: 1.3.5 | B27: Βάθος / Πάχος πεδιλόπλακας | C27: m | D27: 0.85 | E27: 0.7 | G27: Από λεπτομέρειες θεμελίωσης S7.1: 0.85 m (-3.60 έως -2.75) στο υπόγειο και 0.70 m (-5.00 έως -4.30) στον ανελκυστήρα
A28: 1.3.6 | B28: Κάθετα σίδερα κλωβού — Πλήθος | C28: τεμ. | D28: 16 | E28: 16 | G28: Από σχέδιο S4.2: «Vertical 16Y20» / «16nos Y20»
A29: 1.3.7 | B29: Κάθετα σίδερα κλωβού — Διάμετρος Φ | C29: mm | D29: 20 | E29: 20 | G29: Από σχέδιο S4.2: Y20 (20 mm) — καθορίζει και την τιμή του sleeve ανά μέγεθος σιδήρου Φ
A30: 1.3.8 | B30: Ύψος αναμονής / Starter (κενό σχεδίου → πεδιλόπλακα − 0.10m) | C30: m | D30: 1 | E30: 1 | G30: Από σχέδιο S4.2: 100 cm (1.00 m) από Cut-Off Level έως Top of Steel
A31: 1.3.9 | B31: Γωνία πάνω (κενό σχεδίου → 0.50m) | C31: m | D31: 0 | E31: 0 | G31: 0.00 m — το σχέδιο S4.2 δείχνει ευθύγραμμες αναμονές χωρίς γωνία (επιβεβαίωση χρήστη)
A32: 1.3.10 | B32: Γωνία κάτω (στον πυθμένα) | C32: m | D32: 0 | E32: 0 | G32: 0.00 m — το σχέδιο S4.2 δείχνει ευθύγραμμη απόληξη στον πυθμένα χωρίς γωνία
A33: 1.3.11 | B33: Ύψος μάτισης (κενό σχεδίου → 50×Φ) | C33: m | D33: 1.15 | E33: 1.15 | G33: Από σχέδιο S4.2: αναγράφεται ρητά 115 cm (1.15 m) στην τομή του πασσάλου (ο κανόνας 50Φ μπαίνει μόνο όταν δεν δίνεται στο σχέδιο)
A34: 1.3.12 | B34: Σούστα & στεφάνια — Διάμετρος Φ | C34: mm | D34: 10 | E34: 10 | G34: Από σχέδιο S4.2: «Horizontal Y10/150» / «Y10 @ 150mm c/c»
A35: 1.3.13 | B35: Βήμα σούστας στα άκρα (πρώτα & τελευταία μέτρα) | C35: mm | D35: 150 | E35: 150 | G35: 150 mm (ενιαίο βήμα σούστας σε όλο το μήκος)
... A37: 1.3.15 | B37: Βήμα σούστας (απόσταση μεταξύ σπειρών) | C37: mm | D37: 150 | E37: 150 | G37: Από σχέδιο S4.2: 150 mm («Y10 @ 150mm c/c»)
A38: 1.3.16 | B38: Στεφάνια αναμονής starter — ρητά από σχέδιο (κενό → υπολογισμός) | C38: τεμ. | D38: — | E38: — | G38: Κανόνας εταιρείας RULES_v5 §11.3: ROUNDUP(Starter / βήμα) = ROUNDUP(1000 / 150) = 7 τεμ. (χωρίς +1)
A39: 1.3.17 | B39: Πρόσθετος οπλισμός (U-bars κ.λπ.) — Πλήθος | C39: τεμ. | D39: 0 | E39: 0 | G39: Δεν προβλέπεται πρόσθετος οπλισμός (U-bars κ.λπ.) στο S4.2
A40: 1.3.18 | B40: Πρόσθετος οπλισμός — Διάμετρος Φ | C40: mm | D40: 0 | E40: 0 | G40: —
A41: 1.3.19 | B41: Πρόσθετος οπλισμός — Μήκος ανά βέργα | C41: m | D41: 0 | E41: 0 | G41: —
A43: 2. ΤΕΛΙΚΕΣ ΠΟΣΟΤΗΤΕΣ ΓΙΑ ΤΗΝ ΟΙΚΟΝΟΜΙΚΗ ΠΡΟΣΦΟΡΑ
...

Sheet Τιμές & Έλεγχος
A1: ΘΕΜΕΛΙΟΤΕΧΝΙΚΗ ΛΤΔ — ΚΕΝΤΡΙΚΟΣ ΠΙΝΑΚΑΣ ΤΙΜΩΝ & ΕΛΕΓΧΟΥ ΕΡΓΟΥ (ΑΛΛΑΖΕΙΣ ΤΙΜΕΣ ΜΟΝΟ ΕΔΩ!)
A2: Όλες οι τιμές μονάδας και τα κουτάκια μετακινήσεων/σκυροδέματος/sleeve ορίζονται ΑΠΟΚΛΕΙΣΤΙΚΑ εδώ και ενημερώνουν αυτόματα όλα τα φύλλα και τις σημειώσεις!
A4: Α. ΚΥΡΙΕΣ ΤΙΜΕΣ ΜΟΝΑΔΑΣ & ΜΕΤΑΚΙΝΗΣΕΙΣ (ΚΙΤΡΙΝΟ = ΑΛΛΑΖΕΙΣ ΕΔΩ)
A5: Κωδ. | B5: Περιγραφή Τιμής / Παραμέτρου | C5: Μονάδα | D5: Τιμή [ΑΛΛΑΖΕΙΣ ΕΔΩ] | E5: Προέλευση | F5: Πού Εφαρμόζεται
A6: Τ.1 | B6: Χιλιόμετρα εκτός Λεμεσού (0 km αν το έργο είναι μέσα στη Λεμεσό) | C6: km | D6: 75 | E6: Απόσταση έργου εκτός Λεμεσού (Λάρνακα) — αλλάζει δυναμικά στο κελί Τ.1 του Φύλλου 3 | F6: Υπολογίζει αυτόματα τις δεκάδες km (×200€) & τη Συνοδεία Αστυνομίας (×8€/km)
A7: Τ.2 | B7: Μετακίνηση γεωτρύπανου — Βασική τιμή (Μέσα στη Λεμεσό) | C7: € | D7: 1000 | E7: Τιμοκατάλογος (γρ. 5) | F7: Φύλλο 1 (Γρ. 1) & Φύλλο 2 (1.1.4 & 2Β.1)
A8: Τ.3 | B8: Μετακίνηση γεωτρύπανου — Επιβάρυνση ανά 10 km εκτός Λεμεσού (+200 €/10km) | C8: € | D8: 200 | E8: Τιμοκατάλογος (γρ. 6) | F8: Φύλλο 1 (Γρ. 1) & Φύλλο 2 (1.1.5 & 2Β.1)
A9: Τ.4.1 | B9: Τρύπημα / Διάτρηση Πασσάλων Ø800mm | C9: € | D9: 90 | E9: Τιμοκατάλογος (γρ. 11) | F9: Φύλλο 1 (Γρ. 2) & Φύλλο 2 (2Β.2) — €/m
A10: Τ.5 | B10: Χάλυβας οπλισμού B500C (Κάθετα σίδερα & Σούστα) — Τιμή κιλού | C10: € | D10: 1.1 | E10: Τιμοκατάλογος (γρ. 19) | F10: Φύλλο 1 (Γρ. 4) & Φύλλο 2 (2Β.4, 4α, 4β, 4γ) — €/kg
A11: Τ.6 | B11: Κεφαλοκοπή πασσάλων (Pile Breaking) — Τιμή τεμαχίου | C11: € | D11: 150 | E11: Τιμοκατάλογος (γρ. 23) | F11: Φύλλο 1 (Γρ. 6) & Φύλλο 2 (2Β.6) — €/τεμ.
A13: Β. ΥΠΟΛΟΓΙΣΜΟΣ ΤΙΜΗΣ ΚΑΝΟΝΙΚΟΥ ΣΚΥΡΟΔΕΜΑΤΟΣ (C40/50) — ΚΟΥΤΑΚΙΑ ΜΗΧΑΝΙΚΟΥ
A14: Κωδ. | B14: Παράμετρος Κόστους Σκυροδέτησης | C14: Μονάδα | D14: Τιμή / Κουτάκι | E14: Προέλευση / Τύπος | F14: Επεξήγηση
A15: Τ.Β.1 | B15: Τιμή αγοράς σκυροδέματος (C40/50) από προμηθευτή [ΚΟΥΤΑΚΙ ΜΗΧΑΝΙΚΟΥ] | C15: € | D15: 94 | E15: Κουτάκι Μηχανικού (Τιμή αγοράς κουγκριού) | F15: Συμπληρώνεται από τον μηχανικό ανάλογα με την προσφορά προμηθευτή (€/m³)
A16: Τ.Β.2 | B16: Κόστος τοποθέτησης σκυροδέματος (σταθερό ανά κυβικό) | C16: € | D16: 15 | E16: Τιμοκατάλογος (γρ. 18) | F16: Σταθερή χρέωση τοποθέτησης = +15,00 €/m³ από τον Τιμοκατάλογο Εταιρείας
A17: Τ.Β.3 | B17: Κόστος στησίματος αντλίας (πρέσας) ανά στήσιμο [ΚΟΥΤΑΚΙ ΜΗΧΑΝΙΚΟΥ] | C17: € | D17: 130 | E17: Κουτάκι Μηχανικού (Κόστος στησίματος αντλίας) | F17: Συμπληρώνεται από τον μηχανικό (€/στήσιμο αντλίας)
A18: Τ.Β.4 | B18: Πόσες τρύπες (πασσάλους) θα κάνει η αντλία ανά στήσιμο [ΚΟΥΤΑΚΙ ΜΗΧΑΝΙΚΟΥ] | C18: τρύπες | D18: 2 | E18: Κουτάκι Μηχανικού (Τρύπες/πασσάλους ανά στήσιμο αντλίας) | F18: Αριθμός πασσάλων που σκυροδετούνται σε 1 στήσιμο της αντλίας
A19: Τ.Β.5 | B19: Κυβικά κουγκριού που αντλεί η αντλία ανά στήσιμο (Τρύπες × m³/τρύπα) | C19: m³ | D19: =$D$18*('Τεχνικοί Υπολογισμοί'!$D$46/'Τεχνικοί Υπολογισμοί'!$D$14) -> 19.379857 | E19: Αυτόματος υπολογισμός: Τρύπες ανά στήσιμο × Μέσα κυβικά ανά πάσσαλο | F19: Κυβικά σκυροδέματος ανά στήσιμο αντλίας
A20: Τ.Β.6 | B20: Επιβάρυνση στησίματος αντλίας ανά κυβικό (Στήσιμο ÷ m³ ανά στήσιμο) | C20: € | D20: =IF(AND($D$17>0,$D$19>0),$D$17/$D$19,0) -> 6.7079959 | E20: Αυτόματος υπολογισμός: Κόστος στησίματος ÷ Κυβικά ανά στήσιμο | F20: Επιβάρυνση αντλίας σε €/m³
A21: Τ.Β.7 | B21: ΤΕΛΙΚΗ ΤΙΜΗ ΣΚΥΡΟΔΕΤΗΣΗΣ (C40/50) ΑΝΑ ΚΥΒΙΚΟ [ΣΤΡΟΓΓΥΛΟΠΟΙΗΜΕΝΗ ΣΕ ΑΚΕΡΑΙΟ €] | C21: € | D21: =ROUND($D$15+$D$16+$D$20,0) -> 116 | E21: ROUND(Τιμή Αγοράς + 15,00 € + Στήσιμο Αντλίας/m³, 0) | F21: Στρογγυλοποιημένη τελική τιμή — Τροφοδοτεί Φύλλο 1 (Γρ. 3) & Φύλλο 2 (2Β.3)
A23: Γ. ΚΟΣΤΟΛΟΓΗΣΗ SLEEVE ΤΗΣ ΣΥΓΚΕΚΡΙΜΕΝΗΣ ΔΟΥΛΕΙΑΣ — ΜΟΝΟ ΓΙΑ SLEEVE Φ32 (ΓΙΑ ΚΆΘΕΤΟ ΣΊΔΕΡΟ Φ20 ≤ Φ20)
A24: Κωδ. | B24: Στοιχείο Κόστους Sleeve Έργου | C24: Μονάδα | D24: Τιμή | E24: Προέλευση / Τύπος | F24: Κανόνας Κοπής, Φύρας, Εργατικών & ×1,30
A25: Τ.Γ.1 | B25: Εμπορικό μήκος σωλήνα που μας φέρνουν (Sleeve Φ32 (για κάθετο σίδερο Φ20 ≤ Φ20)) | C25: m | D25: 3 | E25: Τιμοκατάλογος (γρ. 34) | F25: Μήκος εμπορικού σωλήνα από Τιμοκατάλογο Εταιρείας (Φύλλο 5)
A26: Τ.Γ.2 | B26: Τιμή αγοράς εμπορικού σωλήνα (Sleeve Φ32 (για κάθετο σίδερο Φ20 ≤ Φ20)) | C26: € | D26: 4.02 | E26: Τιμοκατάλογος (γρ. 35) | F26: Τιμή αγοράς ολόκληρου σωλήνα από Τιμοκατάλογο Εταιρείας (Φύλλο 5)
A27: Τ.Γ.3 | B27: Τιμή υλικού σωλήνα ανά μέτρο (Τιμή σωλήνα ÷ Μήκος σωλήνα) | C27: €/m | D27: =$D$26/$D$25 -> 1.34 | E27: Αυτόματος υπολογισμός από Τιμοκατάλογο | F27: Κόστος υλικού σωλήνα ανά τρέχον μέτρο
A28: Τ.Γ.4 | B28: Απαιτούμενο μήκος sleeve ανά σίδερο (Starter + Γωνία πάνω) | C28: m | D28: ='Τεχνικοί Υπολογισμοί'!$D$30+'Τεχνικοί Υπολογισμοί'!$D$31 -> 1 | E28: Από Τεχνικούς Υπολογισμούς (1.3.8 Starter + 1.3.9 Γωνία πάνω) | F28: Μήκος sleeve που απαιτείται να κοπεί για κάθε κάθετη ράβδο
A29: Τ.Γ.5 | B29: Χρεωστέο μήκος σωλήνα ανά σίδερο (με στρογγυλοποίηση προς τα πάνω λόγω φύρας) | C29: m | D29: =IF($D$28<=0,0,IF($D$28<=$D$25,$D$25/INT(ROUND($D$25/$D$28,6)),CEILING($D$28,$D$25))) -> 1 | E29: Κανόνας φύρας: αν δεν διαιρεί ακριβώς τον σωλήνα, το ρετάλι χάνεται και χρεώνεται! | F29: Αν L_req=1.00m σε 3m σωλήνα → 3 τεμ./σωλήνα → χρεωστέο 1.00m (μηδενική φύρα)
A30: Τ.Γ.6 | B30: Κόστος υλικού σωλήνα ανά σίδερο (Χρεωστέο μήκος × Τιμή ανά μέτρο) | C30: € | D30: =$D$29*$D$27 -> 1.34 | E30: Χρεωστέο μήκος σωλήνα × Κόστος σωλήνα ανά μέτρο | F30: Καθαρό κόστος υλικού σωλήνα ανά κάθετο σίδερο
A31: Τ.Γ.7 | B31: Εργατικά τοποθέτησης ανά σίδερο (Συνεργείο 1,5 ατόμων × 2 λεπτά × 15,60 €/ώρα) | C31: € | D31: 0.78 | E31: Τιμοκατάλογος (γρ. 40) | F31: Σταθερό ανά σίδερο ανεξαρτήτως μήκους/πάχους: (2/60) × 1,5 × 15,60 € = 0,7800 €
A32: Τ.Γ.8 | B32: Κόστος Τέλλας (Μονωτικής Ταινίας) ανά σίδερο (Ρολό 2,19 € ÷ 25 σίδερα) | C32: € | D32: 0.0876 | E32: Τιμοκατάλογος (γρ. 41) | F32: Σταθερό ανά σίδερο ανεξαρτήτως μήκους/πάχους: 2,19 € / 25 = 0,0876 €
A33: Τ.Γ.9 | B33: Εσωτερικό Κόστος Sleeve για εμάς ανά σίδερο (Υλικό + Εργατικά + Τέλλα) | C33: € | D33: =$D$30+$D$31+$D$32 -> 2.2076 | E33: Άθροισμα: Υλικό σωλήνα + 0,7800 € (Εργατικά) + 0,0876 € (Τέλλα) | F33: Καθαρό εσωτερικό κόστος πριν το Overhead, Profit & Damages
A34: Τ.Γ.10 | B34: Συντελεστής Overhead, Profit & Damages (× 1,30) | C34: × | D34: 1.3 | E34: Τιμοκατάλογος (γρ. 42) | F34: Πολλαπλασιάζεται πάντα × 1,30 (+30% Overhead, Κέρδος & Ζημιές) στην τελική τιμή
A35: Τ.Γ.11 | B35: ΤΕΛΙΚΗ ΤΙΜΗ SLEEVE ΕΡΓΟΥ (Sleeve Φ32) ΑΝΑ ΣΙΔΕΡΟ [(Υλικό + Εργατικά + Τέλλα) × 1,30] | C35: € | D35: =3 -> 3 | E35: Εσωτερικό Κόστος Sleeve × 1,30 (Overhead, Profit & Damages) | F35: Τροφοδοτεί αυτόματα Φύλλο 1 (Γρ. 5) & Φύλλο 2 (2Β.5)
A37: Δ. ΣΥΝΟΔΕΙΑ ΑΣΤΥΝΟΜΙΑΣ ΓΕΩΤΡΥΠΑΝΟΥ (8 €/km) & ΖΩΝΤΑΝΟΣ ΕΛΕΓΧΟΣ ΣΥΝΟΛΩΝ
A38: Τ.Δ.1 | B38: Χιλιόμετρα Συνοδείας Αστυνομίας (Πάσσαλοι Θεμελίωσης / Νέφκες — βάλε 0 αν δεν έχει) | C38: km | D38: =$D$6 -> 75 | E38: Συνδεδεμένο με την απόσταση Τ.1 (ή γράψε 0 αν δεν απαιτείται συνοδεία) | F38: Πολλαπλασιάζεται με τα 8,00 €/km για τη μεταφορά του γεωτρύπανου
A39: Τ.Δ.2 | B39: Κόστος Συνοδείας Αστυνομίας ανά χιλιόμετρο (8,00 €/km) | C39: €/km | D39: 8 | E39: Τιμοκατάλογος (γρ. 43) | F39: Από Τιμοκατάλογο Εταιρείας (Φύλλο 6): 8,00 €/km
A40: Τ.Δ.3 | B40: Συνολικό Κόστος Συνοδείας Αστυνομίας (Χιλιόμετρα × 8,00 €/km) | C40: € | D40: =$D$38*$D$39 -> 600 | E40: Αυτόματος υπολογισμός: Χιλιόμετρα Συνοδείας × 8,00 €/km | F40: Προστίθεται αυτόματα στις Μετακινήσεις (Φύλλο 1 Γρ. 1 & Φύλλο 2 2Β.1)
A42: ΓΕΝΙΚΟ ΣΥΝΟΛΟ ΠΡΟΣΦΟΡΑΣ (ΧΩΡΙΣ Φ.Π.Α.): | D42: ='Οικονομική Προσφορά'!$F$14 -> 74458.57 | E42: ="Μέσο Κόστος ανά Πάσσαλο: "&ROUND('Οικονομική Προσφορά'!$F$14/'Τεχνικοί Υπολογισμοί'!$D$14,2)&" € ("&'Τεχνικοί Υπολογισμοί'!$D$14&" πάσσαλοι)" -> Μέσο Κόστος ανά Πάσσαλο: 4136.59 € (18 πάσσαλοι)
