Workbook
Name N_b2_breaking_note: 'Τεχνικοί Υπολογισμοί'!$G$62
Name N_b2_breaking_price: 'Τεχνικοί Υπολογισμοί'!$E$62
Name N_b2_breaking_qty: 'Τεχνικοί Υπολογισμοί'!$D$62
Name N_b2_breaking_total: 'Τεχνικοί Υπολογισμοί'!$F$62
Name N_b2_conc_note: 'Τεχνικοί Υπολογισμοί'!$G$56
Name N_b2_conc_price: 'Τεχνικοί Υπολογισμοί'!$E$56
Name N_b2_conc_qty: 'Τεχνικοί Υπολογισμοί'!$D$56
Name N_b2_conc_total: 'Τεχνικοί Υπολογισμοί'!$F$56
Name N_b2_drill_800_note: 'Τεχνικοί Υπολογισμοί'!$G$55
Name N_b2_drill_800_price: 'Τεχνικοί Υπολογισμοί'!$E$55
Name N_b2_drill_800_qty: 'Τεχνικοί Υπολογισμοί'!$D$55
Name N_b2_drill_800_total: 'Τεχνικοί Υπολογισμοί'!$F$55
Name N_b2_grand_total: 'Τεχνικοί Υπολογισμοί'!$F$64
Name N_b2_grand_total_note: 'Τεχνικοί Υπολογισμοί'!$G$64
Name N_b2_mob_note: 'Τεχνικοί Υπολογισμοί'!$G$54
Name N_b2_mob_price: 'Τεχνικοί Υπολογισμοί'!$E$54
Name N_b2_mob_qty: 'Τεχνικοί Υπολογισμοί'!$D$54
Name N_b2_mob_total: 'Τεχνικοί Υπολογισμοί'!$F$54
Name N_b2_sleeve_note: 'Τεχνικοί Υπολογισμοί'!$G$61
Name N_b2_sleeve_price: 'Τεχνικοί Υπολογισμοί'!$E$61
Name N_b2_sleeve_qty: 'Τεχνικοί Υπολογισμοί'!$D$61
Name N_b2_sleeve_total: 'Τεχνικοί Υπολογισμοί'!$F$61
Name N_b2_soil_note: 'Τεχνικοί Υπολογισμοί'!$G$63
Name N_b2_soil_price: 'Τεχνικοί Υπολογισμοί'!$E$63
Name N_b2_soil_qty: 'Τεχνικοί Υπολογισμοί'!$D$63
Name N_b2_soil_total: 'Τεχνικοί Υπολογισμοί'!$F$63
Name N_b2_steel_head_note: 'Τεχνικοί Υπολογισμοί'!$G$59
Name N_b2_steel_head_price: 'Τεχνικοί Υπολογισμοί'!$E$59
Name N_b2_steel_head_qty: 'Τεχνικοί Υπολογισμοί'!$D$59
Name N_b2_steel_head_total: 'Τεχνικοί Υπολογισμοί'!$F$59
Name N_b2_steel_note: 'Τεχνικοί Υπολογισμοί'!$G$60
Name N_b2_steel_price: 'Τεχνικοί Υπολογισμοί'!$E$60
Name N_b2_steel_qty: 'Τεχνικοί Υπολογισμοί'!$D$60
Name N_b2_steel_spiral_note: 'Τεχνικοί Υπολογισμοί'!$G$58
Name N_b2_steel_spiral_price: 'Τεχνικοί Υπολογισμοί'!$E$58
Name N_b2_steel_spiral_qty: 'Τεχνικοί Υπολογισμοί'!$D$58
Name N_b2_steel_spiral_total: 'Τεχνικοί Υπολογισμοί'!$F$58
Name N_b2_steel_total: 'Τεχνικοί Υπολογισμοί'!$F$60
Name N_b2_steel_vert_note: 'Τεχνικοί Υπολογισμοί'!$G$57
Name N_b2_steel_vert_price: 'Τεχνικοί Υπολογισμοί'!$E$57
Name N_b2_steel_vert_qty: 'Τεχνικοί Υπολογισμοί'!$D$57
Name N_b2_steel_vert_total: 'Τεχνικοί Υπολογισμοί'!$F$57
Name N_b2g_grand_total: 'Τεχνικοί Υπολογισμοί'!$F$95
Name N_b2g_grand_total_note: 'Τεχνικοί Υπολογισμοί'!$G$95
Name N_b2g0_breaking_note: 'Τεχνικοί Υπολογισμοί'!$G$77
Name N_b2g0_breaking_price: 'Τεχνικοί Υπολογισμοί'!$E$77
Name N_b2g0_breaking_qty: 'Τεχνικοί Υπολογισμοί'!$D$77
Name N_b2g0_breaking_total: 'Τεχνικοί Υπολογισμοί'!$F$77
Name N_b2g0_conc_note: 'Τεχνικοί Υπολογισμοί'!$G$71
Name N_b2g0_conc_price: 'Τεχνικοί Υπολογισμοί'!$E$71
Name N_b2g0_conc_qty: 'Τεχνικοί Υπολογισμοί'!$D$71
Name N_b2g0_conc_total: 'Τεχνικοί Υπολογισμοί'!$F$71
Name N_b2g0_drill_note: 'Τεχνικοί Υπολογισμοί'!$G$70
Name N_b2g0_drill_price: 'Τεχνικοί Υπολογισμοί'!$E$70
Name N_b2g0_drill_qty: 'Τεχνικοί Υπολογισμοί'!$D$70
Name N_b2g0_drill_total: 'Τεχνικοί Υπολογισμοί'!$F$70
Name N_b2g0_group_total: 'Τεχνικοί Υπολογισμοί'!$F$80
Name N_b2g0_group_total_note: 'Τεχνικοί Υπολογισμοί'!$G$80
Name N_b2g0_mob_note: 'Τεχνικοί Υπολογισμοί'!$G$69
Name N_b2g0_mob_price: 'Τεχνικοί Υπολογισμοί'!$E$69

Sheet Οικονομική Προσφορά
A1: ΘΕΜΕΛΙΟΤΕΧΝΙΚΗ ΛΤΔ — ΟΙΚΟΝΟΜΙΚΗ ΠΡΟΣΦΟΡΑ ΠΑΣΣΑΛΩΝ
A2: Έργο: ΠΟΛΥΚΑΤΟΙΚΙΑ KHALDOON AND OMAR (APARTMENT BUILDING) | Πελάτης: C+ Studio / LE. IR CY DEVELOPMENTS LTD (Khaldoon & Omar) | Τοποθεσία: Λάρνακα (Μετακίνηση: 1.000€ Λεμεσός + 200€/10km + 8€/km Συνοδεία Αστυνομίας) | Τιμές & Κουμπιά ΝΑΙ/ΟΧΙ στο Φύλλο 3: «Τιμές & Έλεγχος»
A7: Α/Α | B7: Περιγραφή Εργασίας / Υλικού | C7: Ποσότητα | D7: Μονάδα | E7: Τιμή Μονάδας (€) [Από «Τιμές & Έλεγχος»] | F7: Σύνολο (€) | G7: Μέσο Κόστος ανά Πάσσαλο (€)
A8: 1 | B8: Μετακινήσεις γεωτρύπανου & Συνοδεία Αστυνομίας (επιμερισμός ανά πάσσαλο) | C8: ='Τεχνικοί Υπολογισμοί'!$D$14 -> 18 | D8: πάσσαλο | E8: ='Τεχνικοί Υπολογισμοί'!$D$15 -> 177.77778 | F8: =$C$8*$E$8 -> 3200 | G8: =$F$8/'Τεχνικοί Υπολογισμοί'!$D$14 -> 177.77778
A9: 2 | B9: Τρύπημα / διάτρηση πασσάλων Ø800mm (18 τεμ.) | C9: ='Τεχνικοί Υπολογισμοί'!$D$45 -> 342.9 | D9: m | E9: ='Τιμές & Έλεγχος'!$D$9 -> 90 | F9: =$C$9*$E$9 -> 30861 | G9: =$F$9/'Τεχνικοί Υπολογισμοί'!$D$14 -> 1714.5
A10: 3 | B10: ="Σκυροδέτηση πασσάλων "&'Τεχνικοί Υπολογισμοί'!$D$18&" (με απώλεια +"&ROUND('Τεχνικοί Υπολογισμοί'!$D$99*100,0)&"%)" -> Σκυροδέτηση πασσάλων C40/50 (με απώλεια +10%) | C10: ='Τεχνικοί Υπολογισμοί'!$D$46 -> 174.41871 | D10: m³ | E10: ='Τιμές & Έλεγχος'!$D$21 -> 116 | F10: =$C$10*$E$10 -> 20232.57 | G10: =$F$10/'Τεχνικοί Υπολογισμοί'!$D$14 -> 1124.0317
A11: 4 | B11: ="Χάλυβας οπλισμού B500C (κάθετα σίδερα "&'Τεχνικοί Υπολογισμοί'!$D$28&"Φ"&'Τεχνικοί Υπολογισμοί'!$D$29&", σούστα Φ"&'Τεχνικοί Υπολογισμοί'!$D$34&"/"&ROUND('Τεχνικοί Υπολογισμοί'!$D$37/10,0)&" & στεφάνια αναμονής)" -> Χάλυβας οπλισμού B500C (κάθετα σίδερα 16Φ20, σούστα Φ10/15 & στεφάνια αναμονής) | C11: ='Τεχνικοί Υπολογισμοί'!$D$47 -> 15091.818 | D11: kg | E11: ='Τιμές & Έλεγχος'!$D$10 -> 1.1 | F11: =$C$11*$E$11 -> 16601 | G11: =$F$11/'Τεχνικοί Υπολογισμοί'!$D$14 -> 922.27776
A12: 5 | B12: ="Sleeves προστασίας αναμονών starter (Sleeve Φ32 για κάθετα σίδερα Φ"&'Τεχνικοί Υπολογισμοί'!$D$29&")" -> Sleeves προστασίας αναμονών starter (Sleeve Φ32 για κάθετα σίδερα Φ20) | C12: ='Τεχνικοί Υπολογισμοί'!$D$48 -> 288 | D12: τεμ. | E12: ='Τιμές & Έλεγχος'!$D$26 -> 3 | F12: =$C$12*$E$12 -> 864 | G12: =$F$12/'Τεχνικοί Υπολογισμοί'!$D$14 -> 48
A13: =IF('Τιμές & Έλεγχος'!$D$35="ΝΑΙ","6","") | B13: =IF('Τιμές & Έλεγχος'!$D$35="ΝΑΙ","Κεφαλοκοπή πασσάλων / Pile Breaking","") | C13: =IF('Τιμές & Έλεγχος'!$D$35="ΝΑΙ",'Τεχνικοί Υπολογισμοί'!$D$49,0) -> 0 | D13: =IF('Τιμές & Έλεγχος'!$D$35="ΝΑΙ","τεμ.","") | E13: =IF('Τιμές & Έλεγχος'!$D$35="ΝΑΙ",'Τιμές & Έλεγχος'!$D$11,0) -> 0 | F13: =$C$13*$E$13 -> 0 | G13: =$F$13/'Τεχνικοί Υπολογισμοί'!$D$14 -> 0
A14: =IF('Τιμές & Έλεγχος'!$D$36="ΝΑΙ",IF('Τιμές & Έλεγχος'!$D$35="ΝΑΙ","7","6"),"") | B14: =IF('Τιμές & Έλεγχος'!$D$36="ΝΑΙ","Απομάκρυνση εκσκαπτόμενου χώματος & Λατομικά τέλη","") | C14: =IF('Τιμές & Έλεγχος'!$D$36="ΝΑΙ",'Τεχνικοί Υπολογισμοί'!$D$50,0) -> 0 | D14: =IF('Τιμές & Έλεγχος'!$D$36="ΝΑΙ","m³","") | E14: =IF('Τιμές & Έλεγχος'!$D$36="ΝΑΙ",'Τιμές & Έλεγχος'!$D$37,0) -> 0 | F14: =$C$14*$E$14 -> 0 | G14: =$F$14/'Τεχνικοί Υπολογισμοί'!$D$14 -> 0
A15: ΓΕΝΙΚΟ ΣΥΝΟΛΟ ΠΡΟΣΦΟΡΑΣ (ΧΩΡΙΣ Φ.Π.Α.) | F15: =ROUNDUP($F$8+$F$9+$F$10+$F$11+$F$12+$F$13+$F$14,-3) -> 72000 | G15: =ROUNDUP($F$15/'Τεχνικοί Υπολογισμοί'!$D$14,-3) -> 4000 | H15: Στρογγυλοποιηση
A17: ΟΡΟΙ, ΠΑΡΑΔΟΧΕΣ & ΠΑΡΑΤΗΡΗΣΕΙΣ (100% ΔΥΝΑΜΙΚΕΣ ΣΗΜΕΙΩΣΕΙΣ — ΕΝΗΜΕΡΩΝΟΝΤΑΙ ΑΥΤΟΜΑΤΑ ΑΠΟ ΤΟ ΦΥΛΛΟ «Τιμές & Έλεγχος»):
A18: ="1. Στις τιμές ΔΕΝ περιλαμβάνεται ο Φ.Π.Α. — Γενικό Σύνολο Προσφοράς: "&ROUND($F$15,2)&" € (Μέσο κόστος ανά πάσσαλο: "&ROUND($F$15/'Τεχνικοί Υπολογισμοί'!$D$14,2)&" € για "&'Τεχνικοί Υπολογισμοί'!$D$14&" πασσάλους)." -> 1. Στις τιμές ΔΕΝ περιλαμβάνεται ο Φ.Π.Α. — Γενικό Σύνολο Προσφοράς: 72000 € (Μέσο κόστος ανά πάσσαλο: 4000 € για 18 πασσάλους).
A19: ="2. Μετακινήσεις γεωτρύπανου: Βασική Λεμεσού ("&ROUND('Τιμές & Έλεγχος'!$D$7,2)&" €) + Εκτός Λεμεσού ανά "&ROUND('Τεχνικοί Υπολογισμοί'!$D$8,0)&"km ("&'Τεχνικοί Υπολογισμοί'!$D$9&" × "&ROUND('Τιμές & Έλεγχος'!$D$8,2)&" € = "&ROUND('Τεχνικοί Υπολογισμοί'!$D$9*'Τιμές & Έλεγχος'!$D$8,2)&" €) + Συνοδεία Αστυνομίας ("&ROUND('Τιμές & Έλεγχος'!$D$29,1)&" km × "&ROUND('Τιμές & Έλεγχος'!$D$30,2)&" €/km = "&ROUND('Τιμές & Έλεγχος'!$D$31,2)&" €) = "&ROUND('Τεχνικοί Υπολογισμοί'!$D$13,2)&" € ("&ROUND($E$8,2)&" €/πάσσαλο)." -> 2. Μετακινήσεις γεωτρύπανου: Βασική Λεμεσού (1000 €) + Εκτός Λεμεσού ανά 10km (8 × 200 € = 1600 €) + Συνοδεία Αστυνομίας (75 km × 8 €/km = 600 €) = 3200 € (177.78 €/πάσσαλο).
A20: ="3. Εκσκαφή / Διάτρηση (από στάθμη πλατφόρμας WPL "&ROUND('Τεχνικοί Υπολογισμοί'!$D$17,2)&"m): Ύψος σκυροδετημένου πασσάλου = "&ROUND('Τεχνικοί Υπολογισμοί'!$D$25,3)&"m, Συνολικά μέτρα διάτρησης = "&ROUND('Τεχνικοί Υπολογισμοί'!$D$45,2)&"m × Τιμή μέτρου ("&ROUND($E$9,2)&" €) = "&ROUND($F$9,2)&" €." -> 3. Εκσκαφή / Διάτρηση (από στάθμη πλατφόρμας WPL 0m): Ύψος σκυροδετημένου πασσάλου = 15.525m, Συνολικά μέτρα διάτρησης = 342.9m × Τιμή μέτρου (90 €) = 30861 €.
A21: ="4. Σκυρόδεμα "&'Τεχνικοί Υπολογισμοί'!$D$18&": ROUND(Αγορά "&ROUND('Τιμές & Έλεγχος'!$D$15,2)&" €/m³ + Τοποθέτηση "&ROUND('Τιμές & Έλεγχος'!$D$16,2)&" €/m³ + Αντλία "&ROUND('Τιμές & Έλεγχος'!$D$20,2)&" €/m³, 0) = "&ROUND($E$10,0)&" €/m³ × "&ROUND('Τεχνικοί Υπολογισμοί'!$D$46,2)&" m³ = "&ROUND($F$10,2)&" €." -> 4. Σκυρόδεμα C40/50: ROUND(Αγορά 94 €/m³ + Τοποθέτηση 15 €/m³ + Αντλία 6.71 €/m³, 0) = 116 €/m³ × 174.42 m³ = 20232.57 €.
A22: ="5. Οπλισμός κλωβού ("&'Τεχνικοί Υπολογισμοί'!$D$28&"Φ"&'Τεχνικοί Υπολογισμοί'!$D$29&" + σούστα Φ"&'Τεχνικοί Υπολογισμοί'!$D$34&"/"&ROUND('Τεχνικοί Υπολογισμοί'!$D$37/10,0)&"): Αναμονή starter = "&ROUND('Τεχνικοί Υπολογισμοί'!$D$30,2)&"m, Γωνία πάνω = "&ROUND('Τεχνικοί Υπολογισμοί'!$D$31,2)&"m, Γωνία κάτω = "&ROUND('Τεχνικοί Υπολογισμοί'!$D$32,2)&"m, Ύψος μάτισης = "&ROUND('Τεχνικοί Υπολογισμοί'!$D$33,2)&"m ("&'Τεχνικοί Υπολογισμοί'!$D$119&" μάτιση), Σπείρες σούστας = "&'Τεχνικοί Υπολογισμοί'!$D$123&" (με +1) + "&'Τεχνικοί Υπολογισμοί'!$D$126&" στεφάνια αναμονής (χωρίς +1) → "&ROUND('Τεχνικοί Υπολογισμοί'!$D$129,2)&" kg/πασσ., Σύνολο = "&ROUND('Τεχνικοί Υπολογισμοί'!$D$47,1)&" kg × Τιμή κιλού ("&ROUND($E$11,2)&" €) = "&ROUND($F$11,2)&" €." -> 5. Οπλισμός κλωβού (16Φ20 + σούστα Φ10/15): Αναμονή starter = 1m, Γωνία πάνω = 0m, Γωνία κάτω = 0m, Ύψος μάτισης = 1.15m (1 μάτιση), Σπείρες σούστας = 105 (με +1) + 7 στεφάνια αναμονής (χωρίς +1) → 838.43 kg/πασσ., Σύνολο = 15091.8 kg × Τιμή κιλού (1.1 €) = 16601 €.
A23: ="6. Sleeves αναμονών (Sleeve Φ32 για Φ"&'Τεχνικοί Υπολογισμοί'!$D$29&"): ((Κόστος αγοράς + Κόστος τοποθέτησης) × Profit, Waste, Overhead) = "&ROUND('Τιμές & Έλεγχος'!$D$25,2)&" € → Στρογγυλεμένο τελικό αποτέλεσμα = "&ROUND($E$12,2)&" €/τεμ. × "&'Τεχνικοί Υπολογισμοί'!$D$48&" τεμ. = "&ROUND($F$12,2)&" €." -> 6. Sleeves αναμονών (Sleeve Φ32 για Φ20): ((Κόστος αγοράς + Κόστος τοποθέτησης) × Profit, Waste, Overhead) = 2.87 € → Στρογγυλεμένο τελικό αποτέλεσμα = 3 €/τεμ. × 288 τεμ. = 864 €.
A24: ="7. Κεφαλοκοπή πασσάλων (Κουμπί Τ.Ε.1 = "&'Τιμές & Έλεγχος'!$D$35&"): "&IF('Τιμές & Έλεγχος'!$D$35="ΝΑΙ","ΠΕΡΙΛΑΜΒΑΝΕΤΑΙ στην προσφορά ("&$C$13&" τεμ. × "&ROUND($E$13,2)&" € = "&ROUND($F$13,2)&" €).","ΔΕΝ ΠΕΡΙΛΑΜΒΑΝΕΤΑΙ στην προσφορά (Ευθύνη Πελάτη / Εργολάβου — 0,00 €).")&" | Απομάκρυνση εκσκαπτόμενου χώματος & Λατομικά τέλη (Κουμπί Τ.Ε.2 = "&'Τιμές & Έλεγχος'!$D$36&"): "&IF('Τιμές & Έλεγχος'!$D$36="ΝΑΙ","ΠΕΡΙΛΑΜΒΑΝΕΤΑΙ στην προσφορά ("&ROUND($C$14,2)&" m³ × "&ROUND($E$14,2)&" €/m³ = "&ROUND($F$14,2)&" €).","ΔΕΝ ΠΕΡΙΛΑΜΒΑΝΕΤΑΙ στην προσφορά (Ευθύνη Πελάτη / Εργολάβου — 0,00 €).") -> 7. Κεφαλοκοπή πασσάλων (Κουμπί Τ.Ε.1 = ΟΧΙ): ΔΕΝ ΠΕΡΙΛΑΜΒΑΝΕΤΑΙ στην προσφορά (Ευθύνη Πελάτη / Εργολάβου — 0,00 €). | Απομάκρυνση εκσκαπτόμενου χώματος & Λατομικά τέλη (Κουμπί Τ.Ε.2 = ΟΧΙ): ΔΕΝ ΠΕΡΙΛΑΜΒΑΝΕΤΑΙ στην προσφορά (Ευθύνη Πελάτη / Εργολάβου — 0,00 €).
A25: 8. Πληρωμή βάσει επιμετρήσεων πραγματικά εκτελεσθέντων μέτρων διάτρησης, κυβικών σκυροδέματος και κιλών οπλισμού. Όλες οι τιμές μονάδας και τα κουμπιά επιλογής (ΝΑΙ/ΟΧΙ) ορίζονται στο Φύλλο 3 («Τιμές & Έλεγχος»).

Sheet Τεχνικοί Υπολογισμοί
A1: ΘΕΜΕΛΙΟΤΕΧΝΙΚΗ ΛΤΔ — ΤΕΧΝΙΚΟΙ ΥΠΟΛΟΓΙΣΜΟΙ ΔΙΑΤΡΗΤΩΝ ΠΑΣΣΑΛΩΝ
A2: Έργο: ΠΟΛΥΚΑΤΟΙΚΙΑ KHALDOON AND OMAR (APARTMENT BUILDING) | Πελάτης: C+ Studio / LE. IR CY DEVELOPMENTS LTD (Khaldoon & Omar) | Μελέτη: X.S.N CIVIL ENGINEER L.L.C. (Xanthos Neofytou) — Project No. 2633 (07/2026) | Μηχανή v5.8 (Τιμές & Κουμπιά ΝΑΙ/ΟΧΙ στο Φύλλο 3: «Τιμές & Έλεγχος»)
A4: 1. ΔΕΔΟΜΕΝΑ ΣΧΕΔΙΟΥ & ΥΨΟΜΕΤΡΑ
A5: Κωδ. | B5: Παράμετρος | C5: Μονάδα | D5: Τιμή | G5: Παρατηρήσεις / Προέλευση
A6: Τομέας 1 — Μετακινήσεις & Συνοδεία Αστυνομίας (Τιμές από το Φύλλο 3: «Τιμές & Έλεγχος»)
A7: 1.1.1 | B7: Χιλιόμετρα εκτός Λεμεσού (0 km αν το έργο είναι μέσα στη Λεμεσό) | C7: km | D7: ='Τιμές & Έλεγχος'!$D$6 -> 75 | G7: Από Φύλλο 3 («Τιμές & Έλεγχος» Τ.1)
A8: 1.1.2 | B8: Βήμα χιλιομετρικής χρέωσης εκτός Λεμεσού (ανά 10 km) | C8: km | D8: 10 | G8: Τιμοκατάλογος (γρ. 28)
A9: 1.1.3 | B9: Δεκάδες χιλιομέτρων εκτός Λεμεσού (ανά 10 km) | C9: ζώνες | D9: =IF('Τιμές & Έλεγχος'!$D$6>0,ROUNDUP(ROUND('Τιμές & Έλεγχος'!$D$6/$D$8,9),0),0) -> 8 | G9: ROUNDUP(km εκτός Λεμεσού / 10, 0)
A10: 1.1.4 | B10: Μετακίνηση — βασική τιμή εντός Λεμεσού | C10: € | D10: ='Τιμές & Έλεγχος'!$D$7 -> 1000 | G10: Από Φύλλο 3 («Τιμές & Έλεγχος» Τ.2 = 1.000,00 €)
A11: 1.1.5 | B11: Μετακίνηση — επιβάρυνση ανά 10 km εκτός Λεμεσού | C11: € | D11: ='Τιμές & Έλεγχος'!$D$8 -> 200 | G11: Από Φύλλο 3 («Τιμές & Έλεγχος» Τ.3 = 200,00 €/10km)
A12: 1.1.6 | B12: Κόστος Συνοδείας Αστυνομίας (Χιλιόμετρα × 8,00 €/km) | C12: € | D12: ='Τιμές & Έλεγχος'!$D$31 -> 600 | G12: Από Φύλλο 3 («Τιμές & Έλεγχος» Τ.Δ.3 = police_km × 8,00 €/km)
A13: 1.1.7 | B13: Συνολικό εφάπαξ ποσό μετακίνησης & συνοδείας Αστυνομίας | C13: € | D13: ='Τιμές & Έλεγχος'!$D$7+$D$9*'Τιμές & Έλεγχος'!$D$8+'Τιμές & Έλεγχος'!$D$31 -> 3200 | G13: Βασική Λεμεσού (1.000€) + Δεκάδες km × 200€ + Συνοδεία Αστυνομίας
A14: 1.1.8 | B14: Συνολικό πλήθος πασσάλων έργου | C14: τεμ. | D14: =$D$23+$E$23 -> 18 | G14: Άθροισμα ομάδων
A15: 1.1.9 | B15: Επιμερισμένη μετακίνηση ανά πάσσαλο | C15: € | D15: =$D$13/$D$14 -> 177.77778 | G15: Συνολική μετακίνηση ÷ Πάσσαλοι
A16: Τομέας 2 — Υψόμετρα & Σκυρόδεμα (WPL κοινό για όλους, Cut-Off ανά πάσσαλο στον Τομέα 3)
A17: 1.2.1 | B17: Στάθμη πλατφόρμας γεωτρύπανου (WPL) — κοινή για όλους τους πασσάλους | C17: m | D17: 0 | G17: WPL = +0.00 m (βάσει email: «Τα Piles θα πρέπει να γίνουν μέχρι το +0.00» & σχεδίου S4.2)
A18: 1.2.2 | B18: Κατηγορία σκυροδέματος | C18: - | D18: C40/50 | G18: Από σχέδιο S4.2 («Concrete Strength : C40/50 MPa» & πίνακας αναμονών C40/50)
A19: 1.2.3 | B19: Επικάλυψη οπλισμού (Cover) | C19: mm | D19: 75 | G19: Από σχέδιο S4.2 («Cover - 75mm»)
A20: Τομέας 3 — Ομάδες πασσάλων & κλωβός οπλισμού (μία στήλη ανά ομάδα)
A21: Κωδ. | B21: Παράμετρος | C21: Μονάδα | D21: Ομάδα 1 | E21: Ομάδα 2 | G21: Παρατηρήσεις
A22: 1.3.0 | B22: Πάσσαλοι | D22: Ø800 (Cut-Off -3.475m) P1–P6, P8–P18 | E22: Ø800 (Cut-Off -4.375m) P7 (Ανελκυστήρας)
A23: 1.3.1 | B23: Πλήθος πασσάλων ομάδας | C23: τεμ. | D23: 17 | E23: 1 | F23: =$D$23+$E$23 -> 18 | G23: Από Κατάλογο Πασσάλων & κάτοψη Χάραξης Πασσάλων (Φύλλο S4.1): P1–P18 = 18 τεμ.
A24: 1.3.2 | B24: Διάμετρος τρύπας πασσάλου | C24: mm | D24: 800 | E24: 800 | G24: Από Κατάλογο Πασσάλων S4.1 (800 mm) & Λεπτομέρεια Πασσάλων S4.2 (PILE 800mm)
A25: 1.3.3 | B25: Ύψος σκυροδετημένου πασσάλου (κάτω από το Cut-Off) | C25: m | D25: 15.525 | E25: 15.525 | G25: Ύψος σκυροδετημένου πασσάλου κάτω από το Cut-Off: 15.525 m (CAST HEIGHT στο S4.2) για όλους τους 18 πασσάλους (διόρθωση λάθους μελέτης στον P7 ώστε να παραμείνει ίδιο μέγεθος σκυροδετημένου πασσάλου)
A26: 1.3.4 | B26: Στάθμη αποκοπής κεφαλής πασσάλου (Cut-Off) | C26: m | D26: -3.475 | E26: -4.375 | G26: Από Κατάλογο Πασσάλων S4.1: -3475 mm (-3.475 m) για P1–P6, P8–P18 και -4375 mm (-4.375 m, 90 cm βαθύτερα) για P7 (ανελκυστήρας)
A27: 1.3.5 | B27: Βάθος / Πάχος πεδιλόπλακας | C27: m | G27: Από λεπτομέρειες θεμελίωσης S7.1: 0.85 m (-3.60 έως -2.75) στο υπόγειο και 0.70 m (-5.00 έως -4.30) στον ανελκυστήρα
A28: 1.3.6 | B28: Κάθετα σίδερα κλωβού — Πλήθος | C28: τεμ. | D28: 16 | E28: 16 | G28: Από σχέδιο S4.2: «Vertical 16Y20» / «16nos Y20»
A29: 1.3.7 | B29: Κάθετα σίδερα κλωβού — Διάμετρος Φ | C29: mm | D29: 20 | E29: 20 | G29: Από σχέδιο S4.2: Y20 (20 mm) — καθορίζει και την τιμή του sleeve ανά μέγεθος σιδήρου Φ
A30: 1.3.8 | B30: Ύψος αναμονής / Starter (κενό σχεδίου → πεδιλόπλακα − 0.10m) | C30: m | D30: 1 | E30: 1 | G30: Από σχέδιο S4.2: 100 cm (1.00 m) από Cut-Off Level έως Top of Steel
A31: 1.3.9 | B31: Γωνία πάνω (κενό σχεδίου → 0.50m) | C31: m | D31: 0 | E31: 0 | G31: 0.00 m — το σχέδιο S4.2 δείχνει ευθύγραμμες αναμονές χωρίς γωνία (επιβεβαίωση χρήστη)
A32: 1.3.10 | B32: Γωνία κάτω (στον πυθμένα) | C32: m | D32: 0 | E32: 0 | G32: 0.00 m — το σχέδιο S4.2 δείχνει ευθύγραμμη απόληξη στον πυθμένα χωρίς γωνία
A33: 1.3.11 | B33: Ύψος μάτισης (κενό σχεδίου → 50×Φ) | C33: m | D33: 1.15 | E33: 1.15 | G33: Από σχέδιο S4.2: αναγράφεται ρητά 115 cm (1.15 m) στην τομή του πασσάλου (ο κανόνας 50Φ μπαίνει μόνο όταν δεν δίνεται στο σχέδιο)
A34: 1.3.12 | B34: Σούστα & στεφάνια — Διάμετρος Φ | C34: mm | D34: 10 | E34: 10 | G34: Από σχέδιο S4.2: «Horizontal Y10/150» / «Y10 @ 150mm c/c»
A35: 1.3.13 | B35: Βήμα σούστας στα άκρα (πρώτα & τελευταία μέτρα) | C35: mm | D35: 150 | E35: 150 | G35: 150 mm (ενιαίο βήμα σούστας σε όλο το μήκος)
A36: 1.3.14 | B36: Μήκος ζώνης πύκνωσης άκρου (πάνω & κάτω) | C36: m | D36: 0 | E36: 0 | G36: 0.00 m (δεν υπάρχουν διαφορετικές ζώνες πύκνωσης στο S4.2)
A37: 1.3.15 | B37: Βήμα σούστας (απόσταση μεταξύ σπειρών) | C37: mm | D37: 150 | E37: 150 | G37: Από σχέδιο S4.2: 150 mm («Y10 @ 150mm c/c»)
A38: 1.3.16 | B38: Στεφάνια αναμονής starter — ρητά από σχέδιο (κενό → υπολογισμός) | C38: τεμ. | D38: — | E38: — | G38: Κανόνας εταιρείας RULES_v5 §11.3: ROUNDUP(Starter / βήμα) = ROUNDUP(1000 / 150) = 7 τεμ. (χωρίς +1)
A39: 1.3.17 | B39: Πρόσθετος οπλισμός (U-bars κ.λπ.) — Πλήθος | C39: τεμ. | D39: 0 | E39: 0 | G39: Δεν προβλέπεται πρόσθετος οπλισμός (U-bars κ.λπ.) στο S4.2
A40: 1.3.18 | B40: Πρόσθετος οπλισμός — Διάμετρος Φ | C40: mm | D40: 0 | E40: 0 | G40: —
A41: 1.3.19 | B41: Πρόσθετος οπλισμός — Μήκος ανά βέργα | C41: m | D41: 0 | E41: 0 | G41: —
...

Sheet Τιμές & Έλεγχος
A1: ΘΕΜΕΛΙΟΤΕΧΝΙΚΗ ΛΤΔ — ΚΕΝΤΡΙΚΟΣ ΠΙΝΑΚΑΣ ΤΙΜΩΝ, ΚΟΥΜΠΙΩΝ (ΝΑΙ/ΟΧΙ) & ΕΛΕΓΧΟΥ ΕΡΓΟΥ | Z1: ΝΑΙ
A2: Όλες οι τιμές μονάδας, τα κουτάκια σκυροδέματος/sleeve (άτομα, λεπτά, εργατοώρα, τέλλα) και τα κουμπιά ΝΑΙ/ΟΧΙ ορίζονται ΕΔΩ και ενημερώνουν αυτόματα όλα τα φύλλα και όλες τις σημειώσεις! | Z2: ΟΧΙ
A4: Α. ΚΥΡΙΕΣ ΤΙΜΕΣ ΜΟΝΑΔΑΣ & ΜΕΤΑΚΙΝΗΣΕΙΣ (ΚΙΤΡΙΝΟ = ΑΛΛΑΖΕΙΣ ΕΔΩ)
A5: Κωδ. | B5: Περιγραφή Τιμής / Παραμέτρου | C5: Μονάδα | D5: Τιμή [ΑΛΛΑΖΕΙΣ ΕΔΩ] | E5: Προέλευση | F5: Πού Εφαρμόζεται (100% Δυναμική Σημείωση)
A6: Τ.1 | B6: Χιλιόμετρα εκτός Λεμεσού (0 km αν το έργο είναι μέσα στη Λεμεσό) | C6: km | D6: 75 | E6: Απόσταση έργου εκτός Λεμεσού (Λάρνακα) — αλλάζει δυναμικά στο κελί Τ.1 του Φύλλου 3 | F6: ="Υπολογίζει αυτόματα τις ζώνες των "&ROUND('Τεχνικοί Υπολογισμοί'!$D$8,0)&" km ("&'Τεχνικοί Υπολογισμοί'!$D$9&" × "&ROUND($D$8,2)&" €) & τη Συνοδεία Αστυνομίας (× "&ROUND($D$30,2)&" €/km)" -> Υπολογίζει αυτόματα τις ζώνες των 10 km (8 × 200 €) & τη Συνοδεία Αστυνομίας (× 8 €/km)
A7: Τ.2 | B7: Μετακίνηση γεωτρύπανου — Βασική τιμή (Μέσα στη Λεμεσό) | C7: € | D7: 1000 | E7: Τιμοκατάλογος (γρ. 5) | F7: ="Βασική χρέωση "&ROUND($D$7,2)&" € εντός Λεμεσού → Φύλλο 1 (Γρ. 1) & Φύλλο 2 (1.1.4, 2Β.1 & 2Γ)" -> Βασική χρέωση 1000 € εντός Λεμεσού → Φύλλο 1 (Γρ. 1) & Φύλλο 2 (1.1.4, 2Β.1 & 2Γ)
A8: Τ.3 | B8: ="Μετακίνηση γεωτρύπανου — Επιβάρυνση ανά "&ROUND('Τεχνικοί Υπολογισμοί'!$D$8,0)&" km εκτός Λεμεσού (+"&ROUND($D$8,0)&" €/"&ROUND('Τεχνικοί Υπολογισμοί'!$D$8,0)&"km)" -> Μετακίνηση γεωτρύπανου — Επιβάρυνση ανά 10 km εκτός Λεμεσού (+200 €/10km) | C8: € | D8: 200 | E8: Τιμοκατάλογος (γρ. 6) | F8: ="+"&ROUND($D$8,2)&" € ανά "&ROUND('Τεχνικοί Υπολογισμοί'!$D$8,0)&" km εκτός Λεμεσού → Φύλλο 1 (Γρ. 1) & Φύλλο 2 (1.1.5, 2Β.1 & 2Γ)" -> +200 € ανά 10 km εκτός Λεμεσού → Φύλλο 1 (Γρ. 1) & Φύλλο 2 (1.1.5, 2Β.1 & 2Γ)
A9: Τ.4.1 | B9: Τρύπημα / Διάτρηση Πασσάλων Ø800mm | C9: € | D9: 90 | E9: Τιμοκατάλογος (γρ. 11) | F9: ="Τιμή διάτρησης Ø800mm = "&ROUND($D$9,2)&" €/m → Φύλλο 1 (Γρ. 2) & Φύλλο 2 (2Β.2 & 2Γ)" -> Τιμή διάτρησης Ø800mm = 90 €/m → Φύλλο 1 (Γρ. 2) & Φύλλο 2 (2Β.2 & 2Γ)
A10: Τ.5 | B10: Χάλυβας οπλισμού B500C (Κάθετα σίδερα & Σούστα) — Τιμή κιλού | C10: € | D10: 1.1 | E10: Τιμοκατάλογος (γρ. 19) | F10: ="Τιμή σιδήρου = "&ROUND($D$10,2)&" €/kg → Φύλλο 1 (Γρ. 4) & Φύλλο 2 (2Β.4 & 2Γ)" -> Τιμή σιδήρου = 1.1 €/kg → Φύλλο 1 (Γρ. 4) & Φύλλο 2 (2Β.4 & 2Γ)
A11: Τ.6 | B11: Κεφαλοκοπή πασσάλων (Pile Breaking) — Τιμή τεμαχίου | C11: € | D11: 150 | E11: Τιμοκατάλογος (γρ. 23) | F11: ="Τιμή κεφαλοκοπής = "&ROUND($D$11,2)&" €/πάσσαλο (Κουμπί Τ.Ε.1 = "&$D$35&") → Φύλλο 1 (Γρ. 6) & Φύλλο 2 (2Β.6 & 2Γ)" -> Τιμή κεφαλοκοπής = 150 €/πάσσαλο (Κουμπί Τ.Ε.1 = ΟΧΙ) → Φύλλο 1 (Γρ. 6) & Φύλλο 2 (2Β.6 & 2Γ)
A13: Β. ΥΠΟΛΟΓΙΣΜΟΣ ΤΙΜΗΣ ΚΑΝΟΝΙΚΟΥ ΣΚΥΡΟΔΕΜΑΤΟΣ (C40/50) — ΚΟΥΤΑΚΙΑ ΜΗΧΑΝΙΚΟΥ
A14: Κωδ. | B14: Παράμετρος Κόστους Σκυροδέτησης | C14: Μονάδα | D14: Τιμή / Κουτάκι | E14: Προέλευση / Τύπος | F14: Δυναμική Επεξήγηση
A15: Τ.Β.1 | B15: Τιμή αγοράς σκυροδέματος (C40/50) από προμηθευτή [ΚΟΥΤΑΚΙ ΜΗΧΑΝΙΚΟΥ] | C15: € | D15: 94 | E15: Κουτάκι Μηχανικού (Τιμή αγοράς κουγκριού) | F15: ="Τιμή αγοράς κουγκριού από προμηθευτή = "&ROUND($D$15,2)&" €/m³" -> Τιμή αγοράς κουγκριού από προμηθευτή = 94 €/m³
A16: Τ.Β.2 | B16: Κόστος τοποθέτησης σκυροδέματος (σταθερό ανά κυβικό) | C16: € | D16: 15 | E16: Τιμοκατάλογος (γρ. 18) | F16: ="Σταθερή χρέωση τοποθέτησης = +"&ROUND($D$16,2)&" €/m³ από τον Τιμοκατάλογο Εταιρείας" -> Σταθερή χρέωση τοποθέτησης = +15 €/m³ από τον Τιμοκατάλογο Εταιρείας
A17: Τ.Β.3 | B17: Κόστος στησίματος αντλίας (πρέσας) ανά στήσιμο [ΚΟΥΤΑΚΙ ΜΗΧΑΝΙΚΟΥ] | C17: € | D17: 130 | E17: Κουτάκι Μηχανικού (Κόστος στησίματος αντλίας) | F17: ="Κόστος στησίματος αντλίας = "&ROUND($D$17,2)&" €/στήσιμο" -> Κόστος στησίματος αντλίας = 130 €/στήσιμο
A18: Τ.Β.4 | B18: Πόσες τρύπες (πασσάλους) θα κάνει η αντλία ανά στήσιμο [ΚΟΥΤΑΚΙ ΜΗΧΑΝΙΚΟΥ] | C18: τρύπες | D18: 2 | E18: Κουτάκι Μηχανικού (Τρύπες/πασσάλους ανά στήσιμο αντλίας) | F18: ="Η αντλία σκυροδετεί "&ROUND($D$18,0)&" πασσάλους ανά στήσιμο" -> Η αντλία σκυροδετεί 2 πασσάλους ανά στήσιμο
A19: Τ.Β.5 | B19: Κυβικά κουγκριού που αντλεί η αντλία ανά στήσιμο (Τρύπες × m³/τρύπα) | C19: m³ | D19: =$D$18*('Τεχνικοί Υπολογισμοί'!$D$46/'Τεχνικοί Υπολογισμοί'!$D$14) -> 19.379857 | E19: ="Αυτόματος τύπος: "&ROUND($D$18,0)&" τρύπες × "&ROUND('Τεχνικοί Υπολογισμοί'!$D$46/'Τεχνικοί Υπολογισμοί'!$D$14,3)&" m³/τρύπα" -> Αυτόματος τύπος: 2 τρύπες × 9.69 m³/τρύπα | F19: ="Κυβικά ανά στήσιμο αντλίας = "&ROUND($D$19,2)&" m³" -> Κυβικά ανά στήσιμο αντλίας = 19.38 m³
A20: Τ.Β.6 | B20: Επιβάρυνση στησίματος αντλίας ανά κυβικό (Στήσιμο ÷ m³ ανά στήσιμο) | C20: € | D20: =IF(AND($D$17>0,$D$19>0),$D$17/$D$19,0) -> 6.7079959 | E20: ="Αυτόματος τύπος: "&ROUND($D$17,2)&" € ÷ "&ROUND($D$19,2)&" m³" -> Αυτόματος τύπος: 130 € ÷ 19.38 m³ | F20: ="Επιβάρυνση αντλίας = "&ROUND($D$20,2)&" €/m³" -> Επιβάρυνση αντλίας = 6.71 €/m³
A21: Τ.Β.7 | B21: ΤΕΛΙΚΗ ΤΙΜΗ ΣΚΥΡΟΔΕΤΗΣΗΣ (C40/50) ΑΝΑ ΚΥΒΙΚΟ [ΣΤΡΟΓΓΥΛΟΠΟΙΗΜΕΝΗ ΣΕ ΑΚΕΡΑΙΟ €] | C21: € | D21: =ROUND($D$15+$D$16+$D$20,0) -> 116 | E21: ="ROUND("&ROUND($D$15,2)&" € + "&ROUND($D$16,2)&" € + "&ROUND($D$20,2)&" €, 0) = "&ROUND($D$21,0)&" €/m³" -> ROUND(94 € + 15 € + 6.71 €, 0) = 116 €/m³ | F21: ="Στρογγυλοποιημένη τελική τιμή ("&ROUND($D$21,0)&" €/m³) — Τροφοδοτεί Φύλλο 1 (Γρ. 3) & Φύλλο 2 (2Β.3 & 2Γ)" -> Στρογγυλοποιημένη τελική τιμή (116 €/m³) — Τροφοδοτεί Φύλλο 1 (Γρ. 3) & Φύλλο 2 (2Β.3 & 2Γ)
A23: Γ. ΚΟΣΤΟΛΟΓΗΣΗ SLEEVE ΕΡΓΟΥ — ΜΟΝΟ ΓΙΑ SLEEVE Φ32 (ΓΙΑ ΚΆΘΕΤΟ ΣΊΔΕΡΟ Φ20 ≤ Φ20)
A24: Κωδ. | B24: Στοιχείο Κόστους Sleeve Έργου | C24: Μονάδα | D24: Τιμή | E24: Προέλευση / Τύπος | F24: Δυναμική Επεξήγηση
A25: Τ.Γ.1 | B25: Τελικό Αποτέλεσμα Sleeve (Sleeve Φ32): ((Κόστος αγοράς + Κόστος τοποθέτησης) × Profit, Waste, Overhead) | C25: € | D25: =((IF('Τεχνικοί Υπολογισμοί'!$D$30+'Τεχνικοί Υπολογισμοί'!$D$31<=0,0,IF('Τεχνικοί Υπολογισμοί'!$D$30+'Τεχνικοί Υπολογισμοί'!$D$31<=3,3/INT(ROUND(3/('Τεχνικοί Υπολογισμοί'!$D$30+'Τεχνικοί Υπολογισμοί'!$D$31),6)),CEILING('Τεχνικοί Υπολογισμοί'!$D$30+'Τεχνικοί Υπολογισμοί'!$D$31,3)))*1.34)+0.8676)*1.3 -> 2.86988 | E25: Από Τιμοκατάλογο Εταιρείας: ((Κόστος αγοράς + Κόστος τοποθέτησης) × Profit, Waste, Overhead) | F25: ="((Κόστος αγοράς + Κόστος τοποθέτησης) × Profit, Waste, Overhead) = "&ROUND($D$25,2)&" €/τεμ." -> ((Κόστος αγοράς + Κόστος τοποθέτησης) × Profit, Waste, Overhead) = 2.87 €/τεμ.
A26: Τ.Γ.2 | B26: ΣΤΡΟΓΓΥΛΕΜΕΝΟ ΤΕΛΙΚΟ ΑΠΟΤΕΛΕΣΜΑ SLEEVE (Sleeve Φ32) [ΣΤΟ ΠΛΗΣΙΕΣΤΕΡΟ 0,50 €] | C26: € | D26: =ROUND($D$25*2,0)/2 -> 3 | E26: ="ROUND("&ROUND($D$25,2)&" × 2, 0) / 2 = "&ROUND($D$26,2)&" €/τεμ." -> ROUND(2.87 × 2, 0) / 2 = 3 €/τεμ. | F26: ="Στρογγυλεμένο τελικό αποτέλεσμα ("&ROUND($D$26,2)&" €/τεμ.) — Τροφοδοτεί Φύλλο 1 (Γρ. 5) & Φύλλο 2 (2Β.5 & 2Γ)" -> Στρογγυλεμένο τελικό αποτέλεσμα (3 €/τεμ.) — Τροφοδοτεί Φύλλο 1 (Γρ. 5) & Φύλλο 2 (2Β.5 & 2Γ)
A28: ="Δ. ΣΥΝΟΔΕΙΑ ΑΣΤΥΝΟΜΙΑΣ ΓΕΩΤΡΥΠΑΝΟΥ ("&ROUND($D$30,2)&" €/km)" -> Δ. ΣΥΝΟΔΕΙΑ ΑΣΤΥΝΟΜΙΑΣ ΓΕΩΤΡΥΠΑΝΟΥ (8 €/km)
A29: Τ.Δ.1 | B29: Χιλιόμετρα Συνοδείας Αστυνομίας (Πάσσαλοι Θεμελίωσης / Νέφκες — βάλε 0 αν δεν έχει) | C29: km | D29: =$D$6 -> 75 | E29: Συνδεδεμένο με την απόσταση Τ.1 (ή γράψε 0 αν δεν απαιτείται συνοδεία) | F29: ="Πολλαπλασιάζεται με τα "&ROUND($D$30,2)&" €/km για τη μεταφορά του γεωτρύπανου" -> Πολλαπλασιάζεται με τα 8 €/km για τη μεταφορά του γεωτρύπανου
A30: Τ.Δ.2 | B30: ="Κόστος Συνοδείας Αστυνομίας ανά χιλιόμετρο ("&ROUND($D$30,2)&" €/km)" -> Κόστος Συνοδείας Αστυνομίας ανά χιλιόμετρο (8 €/km) | C30: €/km | D30: 8 | E30: Τιμοκατάλογος (γρ. 48) | F30: ="Από Τιμοκατάλογο Εταιρείας (Φύλλο 6): "&ROUND($D$30,2)&" €/km" -> Από Τιμοκατάλογο Εταιρείας (Φύλλο 6): 8 €/km
A31: Τ.Δ.3 | B31: ="Συνολικό Κόστος Συνοδείας Αστυνομίας ("&ROUND($D$29,1)&" km × "&ROUND($D$30,2)&" €/km)" -> Συνολικό Κόστος Συνοδείας Αστυνομίας (75 km × 8 €/km) | C31: € | D31: =$D$29*$D$30 -> 600 | E31: ="Αυτόματος υπολογισμός: "&ROUND($D$29,1)&" km × "&ROUND($D$30,2)&" €/km = "&ROUND($D$31,2)&" €" -> Αυτόματος υπολογισμός: 75 km × 8 €/km = 600 € | F31: Προστίθεται αυτόματα στις Μετακινήσεις (Φύλλο 1 Γρ. 1 & Φύλλο 2 2Β.1 & 2Γ)
A33: Ε. ΚΟΥΜΠΙΑ ΕΠΙΛΟΓΗΣ ΕΡΓΑΣΙΩΝ (ΠΑΤΗΣΕ «ΝΑΙ» Ή «ΟΧΙ») — ΚΕΦΑΛΟΚΟΠΗ & ΑΠΟΜΑΚΡΥΝΣΗ ΧΩΜΑΤΟΣ
A34: Κωδ. | B34: Εργασία / Ερώτηση Ευθύνης (Πάνω μας ή Πάνω τους;) | C34: Μονάδα | D34: ΚΟΥΜΠΙ / ΤΙΜΗ [ΠΑΤΗΣΕ ΕΔΩ] | E34: Προέλευση / Επιλογή | F34: Τι κάνει όταν πατήσεις ΝΑΙ ή ΟΧΙ (100% Δυναμική Σημείωση)
A35: Τ.Ε.1 | B35: ΚΟΥΜΠΙ 1 — Η Κεφαλοκοπή Πασσάλων (Pile Breaking) είναι πάνω μας; [Πάτησε το βελάκι: ΝΑΙ / ΟΧΙ] | C35: ΝΑΙ / ΟΧΙ | D35: ΟΧΙ | E35: Κουμπί Επιλογής Μηχανικού (Dropdown: ΝΑΙ ή ΟΧΙ) | F35: ="Τώρα είναι «"&$D$35&"»: Αν ΝΑΙ → χρεώνεται ("&ROUND($D$11,2)&" €/τεμ.). Αν ΟΧΙ → κρύβεται αυτόματα (0,00 €) σε όλα τα φύλλα!" -> Τώρα είναι «ΟΧΙ»: Αν ΝΑΙ → χρεώνεται (150 €/τεμ.). Αν ΟΧΙ → κρύβεται αυτόματα (0,00 €) σε όλα τα φύλλα!
A36: Τ.Ε.2 | B36: ΚΟΥΜΠΙ 2 — Η Απομάκρυνση Εκσκαπτόμενου Χώματος & Λατομικά Τέλη είναι πάνω μας; [Πάτησε το βελάκι: ΝΑΙ / ΟΧΙ] | C36: ΝΑΙ / ΟΧΙ | D36: ΟΧΙ | E36: Κουμπί Επιλογής Μηχανικού (Dropdown: ΝΑΙ ή ΟΧΙ) | F36: ="Τώρα είναι «"&$D$36&"»: Αν ΝΑΙ → χρεώνεται ("&ROUND($D$38,2)&" m³ × "&ROUND($D$37,2)&" €/m³ = "&ROUND($D$39,2)&" €). Αν ΟΧΙ → κρύβεται αυτόματα (0,00 €)!" -> Τώρα είναι «ΟΧΙ»: Αν ΝΑΙ → χρεώνεται (172.36 m³ × 15 €/m³ = 0 €). Αν ΟΧΙ → κρύβεται αυτόματα (0,00 €)!
A37: Τ.Ε.3 | B37: Τιμή Απομάκρυνσης Εκσκαπτόμενου Χώματος & Λατομικών Τελών (ανά m³ εκσκαφής) | C37: € | D37: 15 | E37: Τιμή χρήστη (εκτός τιμοκαταλόγου) | F37: ="Πολλαπλασιάζεται με τα κυβικά που σκάβουμε ("&ROUND($D$38,2)&" m³ × "&ROUND($D$37,2)&" €/m³) όταν το Κουμπί 2 (Τ.Ε.2) είναι «ΝΑΙ»" -> Πολλαπλασιάζεται με τα κυβικά που σκάβουμε (172.36 m³ × 15 €/m³) όταν το Κουμπί 2 (Τ.Ε.2) είναι «ΝΑΙ»
A38: Τ.Ε.4 | B38: Συνολικά Κυβικά Εκσκαπτόμενου Χώματος Έργου (V_exc από Τεχνικούς Υπολογισμούς) | C38: m³ | D38: ='Τεχνικοί Υπολογισμοί'!$F$113 -> 172.36034 | E38: Αυτόματος υπολογισμός: Άθροισμα (π × Διάμετρος² / 4 × Βάθος Τρυπήματος) όλων των πασσάλων | F38: ="Συνολικά κυβικά χώματος που βγαίνουν από τις τρύπες = "&ROUND($D$38,2)&" m³" -> Συνολικά κυβικά χώματος που βγαίνουν από τις τρύπες = 172.36 m³
A39: Τ.Ε.5 | B39: Συνολικό Κόστος Απομάκρυνσης Χώματος & Λατομικών Τελών (όταν Κουμπί 2 = ΝΑΙ) | C39: € | D39: =IF($D$36="ΝΑΙ",'Τεχνικοί Υπολογισμοί'!$F$113*$D$37,0) -> 0 | E39: ="IF(Κουμπί_2 = ΝΑΙ, "&ROUND($D$38,2)&" m³ × "&ROUND($D$37,2)&" €/m³, 0) = "&ROUND($D$39,2)&" €" -> IF(Κουμπί_2 = ΝΑΙ, 172.36 m³ × 15 €/m³, 0) = 0 € | F39: Τροφοδοτεί Φύλλο 1 (Γρ. 7) & Φύλλο 2 (2Β.7 & 2Γ)
A41: ΓΕΝΙΚΟ ΣΥΝΟΛΟ ΠΡΟΣΦΟΡΑΣ (ΧΩΡΙΣ Φ.Π.Α.): | D41: ='Οικονομική Προσφορά'!$F$15 -> 72000 | E41: ="Μέσο Κόστος ανά Πάσσαλο: "&ROUND('Οικονομική Προσφορά'!$F$15/'Τεχνικοί Υπολογισμοί'!$D$14,2)&" € ("&'Τεχνικοί Υπολογισμοί'!$D$14&" πάσσαλοι)" -> Μέσο Κόστος ανά Πάσσαλο: 4000 € (18 πάσσαλοι)
