Workbook
Name N_c_barlen: 'Τεχνικοί Υπολογισμοί'!$D$55
Name N_c_density: 'Τεχνικοί Υπολογισμοί'!$D$54
Name N_c_lap: 'Τεχνικοί Υπολογισμοί'!$D$56
Name N_c_loss: 'Τεχνικοί Υπολογισμοί'!$D$53
Name N_c_overc: 'Τεχνικοί Υπολογισμοί'!$D$57
Name N_c_pi: 'Τεχνικοί Υπολογισμοί'!$D$58
Name N_conc_class: 'Τεχνικοί Υπολογισμοί'!$D$20
Name N_cover_mm: 'Τεχνικοί Υπολογισμοί'!$D$21
Name N_cutoff: 'Τεχνικοί Υπολογισμοί'!$D$17
Name N_dh: 'Τεχνικοί Υπολογισμοί'!$D$18
Name N_dist_km: 'Τεχνικοί Υπολογισμοί'!$D$7
Name N_extra_zones: 'Τεχνικοί Υπολογισμοί'!$D$9
Name N_g0_bottom_bend: 'Τεχνικοί Υπολογισμοί'!$D$32
Name N_g0_breaking: 'Τεχνικοί Υπολογισμοί'!$D$80
Name N_g0_count: 'Τεχνικοί Υπολογισμοί'!$D$25
Name N_g0_D_cage: 'Τεχνικοί Υπολογισμοί'!$D$66
Name N_g0_D_mm: 'Τεχνικοί Υπολογισμοί'!$D$26
Name N_g0_end_zone: 'Τεχνικοί Υπολογισμοί'!$D$35
Name N_g0_extra_len: 'Τεχνικοί Υπολογισμοί'!$D$40
Name N_g0_extra_n: 'Τεχνικοί Υπολογισμοί'!$D$38
Name N_g0_extra_y: 'Τεχνικοί Υπολογισμοί'!$D$39
Name N_g0_head_links: 'Τεχνικοί Υπολογισμοί'!$D$37
Name N_g0_L_bar: 'Τεχνικοί Υπολογισμοί'!$D$70
Name N_g0_L_base: 'Τεχνικοί Υπολογισμοί'!$D$68
Name N_g0_L_conc: 'Τεχνικοί Υπολογισμοί'!$D$64
Name N_g0_L_drill: 'Τεχνικοί Υπολογισμοί'!$D$62
Name N_g0_L_pile: 'Τεχνικοί Υπολογισμοί'!$D$27
Name N_g0_n_laps: 'Τεχνικοί Υπολογισμοί'!$D$69
Name N_g0_n_turns: 'Τεχνικοί Υπολογισμοί'!$D$73
Name N_g0_n_vert: 'Τεχνικοί Υπολογισμοί'!$D$28
Name N_g0_P_cage: 'Τεχνικοί Υπολογισμοί'!$D$67
Name N_g0_s_end: 'Τεχνικοί Υπολογισμοί'!$D$34
Name N_g0_s_mid: 'Τεχνικοί Υπολογισμοί'!$D$36
Name N_g0_sleeves: 'Τεχνικοί Υπολογισμοί'!$D$79
Name N_g0_starter: 'Τεχνικοί Υπολογισμοί'!$D$30
Name N_g0_top_bend: 'Τεχνικοί Υπολογισμοί'!$D$31
Name N_g0_V_conc: 'Τεχνικοί Υπολογισμοί'!$D$65
Name N_g0_V_exc: 'Τεχνικοί Υπολογισμοί'!$D$63
Name N_g0_W_extra: 'Τεχνικοί Υπολογισμοί'!$D$77
Name N_g0_W_head: 'Τεχνικοί Υπολογισμοί'!$D$76
Name N_g0_W_spiral: 'Τεχνικοί Υπολογισμοί'!$D$75
Name N_g0_W_total: 'Τεχνικοί Υπολογισμοί'!$D$78
Name N_g0_W_vert: 'Τεχνικοί Υπολογισμοί'!$D$72
Name N_g0_y_spiral: 'Τεχνικοί Υπολογισμοί'!$D$33
Name N_g0_y_vert: 'Τεχνικοί Υπολογισμοί'!$D$29
Name N_g1_bottom_bend: 'Τεχνικοί Υπολογισμοί'!$E$32
Name N_g1_breaking: 'Τεχνικοί Υπολογισμοί'!$E$80
Name N_g1_count: 'Τεχνικοί Υπολογισμοί'!$E$25
Name N_g1_D_cage: 'Τεχνικοί Υπολογισμοί'!$E$66
Name N_g1_D_mm: 'Τεχνικοί Υπολογισμοί'!$E$26
Name N_g1_end_zone: 'Τεχνικοί Υπολογισμοί'!$E$35
Name N_g1_extra_len: 'Τεχνικοί Υπολογισμοί'!$E$40
Name N_g1_extra_n: 'Τεχνικοί Υπολογισμοί'!$E$38
Name N_g1_extra_y: 'Τεχνικοί Υπολογισμοί'!$E$39
Name N_g1_head_links: 'Τεχνικοί Υπολογισμοί'!$E$37
Name N_g1_L_bar: 'Τεχνικοί Υπολογισμοί'!$E$70
Name N_g1_L_base: 'Τεχνικοί Υπολογισμοί'!$E$68
Name N_g1_L_conc: 'Τεχνικοί Υπολογισμοί'!$E$64
Name N_g1_L_drill: 'Τεχνικοί Υπολογισμοί'!$E$62
Name N_g1_L_pile: 'Τεχνικοί Υπολογισμοί'!$E$27

Sheet Οικονομική Προσφορά
A1: ΘΕΜΕΛΙΟΤΕΧΝΙΚΗ ΛΤΔ — ΟΙΚΟΝΟΜΙΚΗ ΠΡΟΣΦΟΡΑ ΠΑΣΣΑΛΩΝ
A2: Έργο: BOLTON TOWER | Πελάτης: ΛΑΚΕΜΙΑ ΚΤΗΜΑΤΙΚΗ Λτδ | Τοποθεσία: Λεμεσός
A4: 🛑 ΠΡΟΣΟΧΗ — RED ALERT: Στα σχέδια ΔΕΝ αναγράφονται τα υψόμετρα πλατφόρμας εργασίας (WPL) και Cut-Off Level. Η προσφορά υπολογίζει προσωρινά Δh = 0.00 m (χωρίς κενή διάτρηση, sleeves και κεφαλοκοπή). Απαιτείται επιβεβαίωση πριν την οριστικοποίηση.
A6: ΠΡΟΣΧΕΔΙΟ ΓΙΑ ΑΠΟΦΑΣΗ — Εκκρεμούν υψόμετρα (WPL / Cut-Off). Η πηγή κάθε στοιχείου: Φύλλο «Τεχνικοί Υπολογισμοί», Ενότητα 5.
A8: Α/Α | B8: Περιγραφή Εργασίας / Υλικού | C8: Ποσότητα | D8: Μονάδα | E8: Τιμή Μονάδας (€) | F8: Σύνολο (€) | G8: Μέσο Κόστος ανά Πάσσαλο (€)
A9: 1 | B9: Μετακινήσεις & εγκατάσταση γεωτρύπανου (επιμερισμός ανά πάσσαλο) | C9: ='Τεχνικοί Υπολογισμοί'!$D$13 -> 50 | D9: πάσσαλο | E9: ='Τεχνικοί Υπολογισμοί'!$D$14 -> 10 | F9: =$C$9*$E$9 -> 500 | G9: =$F$9/'Τεχνικοί Υπολογισμοί'!$D$13 -> 10
A10: 2a | B10: Τρύπημα / διάτρηση πασσάλων Ø1500mm (21 τεμ.) | C10: ='Τεχνικοί Υπολογισμοί'!$D$44 -> 588 | D10: m | E10: 120.75 | F10: =$C$10*$E$10 -> 71001 | G10: =$F$10/'Τεχνικοί Υπολογισμοί'!$D$13 -> 1420.02
A11: 2b | B11: Τρύπημα / διάτρηση πασσάλων Ø1200mm (29 τεμ.) | C11: ='Τεχνικοί Υπολογισμοί'!$D$45 -> 656 | D11: m | E11: 120.75 | F11: =$C$11*$E$11 -> 79212 | G11: =$F$11/'Τεχνικοί Υπολογισμοί'!$D$13 -> 1584.24
A12: 3 | B12: Σκυροδέτηση πασσάλων C50/60 (με απώλεια 10%) | C12: ='Τεχνικοί Υπολογισμοί'!$D$46 -> 1651.5038 | D12: m³ | E12: 140 | F12: =$C$12*$E$12 -> 231210.54 | G12: =$F$12/'Τεχνικοί Υπολογισμοί'!$D$13 -> 4624.2108
A13: 4 | B13: Χάλυβας οπλισμού B500C (κάθετες ράβδοι, σούστα, πρόσθετος οπλισμός) | C13: ='Τεχνικοί Υπολογισμοί'!$D$47 -> 127440.96 | D13: kg | E13: 1.1 | F13: =$C$13*$E$13 -> 140185.06 | G13: =$F$13/'Τεχνικοί Υπολογισμοί'!$D$13 -> 2803.7012
A14: 5 | B14: Sleeves προστασίας starter αναμονών | C14: ='Τεχνικοί Υπολογισμοί'!$D$48 -> 800 | D14: τεμ. | E14: 22 | F14: =$C$14*$E$14 -> 17600 | G14: =$F$14/'Τεχνικοί Υπολογισμοί'!$D$13 -> 352
A15: 6 | B15: Κεφαλοκοπή πασσάλων / pile breaking | C15: ='Τεχνικοί Υπολογισμοί'!$D$49 -> 50 | D15: τεμ. | E15: 150 | F15: =$C$15*$E$15 -> 7500 | G15: =$F$15/'Τεχνικοί Υπολογισμοί'!$D$13 -> 150
A16: ΓΕΝΙΚΟ ΣΥΝΟΛΟ ΠΡΟΣΦΟΡΑΣ (ΧΩΡΙΣ Φ.Π.Α.) | F16: =$F$9+$F$10+$F$11+$F$12+$F$13+$F$14+$F$15 -> 547208.6 | G16: =$F$16/'Τεχνικοί Υπολογισμοί'!$D$13 -> 10944.172
A18: ΟΡΟΙ, ΠΑΡΑΔΟΧΕΣ & ΠΑΡΑΤΗΡΗΣΕΙΣ:
A19: 1. Στις τιμές ΔΕΝ περιλαμβάνεται ο Φ.Π.Α.
A20: 2. Η πηγή κάθε στοιχείου (σχέδιο / μέτρηση / κανονισμός / παραδοχή) αναγράφεται στο Φύλλο «Τεχνικοί Υπολογισμοί», Ενότητα 5.
A21: 3. Γραμμή 1: προέλευση τιμής — Τιμοκατάλογος (γρ. 5).
A22: 4. Γραμμή 2a: προέλευση τιμής — Τιμή χρήστη (εκτός τιμοκαταλόγου).
A23: 5. Γραμμή 2b: προέλευση τιμής — Τιμοκατάλογος (γρ. 14).
A24: 6. Γραμμή 3: προέλευση τιμής — Τιμή χρήστη (εκτός τιμοκαταλόγου).
A25: 7. Γραμμή 4: προέλευση τιμής — Τιμοκατάλογος (γρ. 19).
A26: 8. Γραμμή 5: προέλευση τιμής — Τιμοκατάλογος (γρ. 22).
A27: 9. Γραμμή 6: προέλευση τιμής — Τιμοκατάλογος (γρ. 23).
A28: 10. Υψόμετρα WPL / Cut-Off δεν δίνονται στο σχέδιο: προσωρινά Δh = 0.00 m. Αν διαπιστωθεί κενή διάτρηση (Δh > 0), τιμολογούνται επιπλέον μέτρα διάτρησης, sleeves και κεφαλοκοπή.
A29: 11. Τιμολόγηση διάτρησης Ø1500mm στα 210,00 €/m κατόπιν οδηγίας (εκτός τιμοκαταλόγου).
... A40: 22. Πληρωμή βάσει επιμετρήσεων πραγματικά εκτελεσθέντων μέτρων και κιλών οπλισμού.

Sheet Τεχνικοί Υπολογισμοί
A1: ΘΕΜΕΛΙΟΤΕΧΝΙΚΗ ΛΤΔ — ΤΕΧΝΙΚΟΙ ΥΠΟΛΟΓΙΣΜΟΙ ΔΙΑΤΡΗΤΩΝ ΠΑΣΣΑΛΩΝ
A2: Έργο: BOLTON TOWER | Πελάτης: ΛΑΚΕΜΙΑ ΚΤΗΜΑΤΙΚΗ Λτδ | Μελέτη: Hyperstatic Engineering Design (αρ. έργου 220138) | Μηχανή v5.0
A4: 1. ΔΕΔΟΜΕΝΑ ΣΧΕΔΙΟΥ & ΥΨΟΜΕΤΡΑ
A5: Κωδ. | B5: Παράμετρος | C5: Μονάδα | D5: Τιμή | K5: Παρατηρήσεις / Προέλευση
A6: Τομέας 1 — Μετακινήσεις
A7: 1.1.1 | B7: Οδική απόσταση έργου από έδρα (Άγιος Συλάς) | C7: km | D7: 15 | K7: ΠΑΡΑΔΟΧΗ: το σχέδιο γράφει μόνο «ΛΕΜΕΣΟΣ» — Ζώνη 1 (≤ 50 km)
A8: 1.1.2 | B8: Βασική ακτίνα Ζώνης 1 | C8: km | D8: 50 | K8: Τιμοκατάλογος (γρ. 28)
A9: 1.1.3 | B9: Επιπλέον ζώνες των 50 km | C9: ζώνες | D9: =MAX(0,ROUNDUP(ROUND(($D$7-$D$8)/$D$8,9),0)) -> 0 | K9: MAX(0, ROUNDUP((km − 50)/50, 0))
A10: 1.1.4 | B10: Μετακίνηση — βασική τιμή | C10: € | D10: 500 | K10: Τιμοκατάλογος (γρ. 5)
A11: 1.1.5 | B11: Μετακίνηση — επιβάρυνση ανά ζώνη 50 km | C11: € | D11: 100 | K11: Τιμοκατάλογος (γρ. 6)
A12: 1.1.6 | B12: Συνολικό εφάπαξ ποσό μετακίνησης | C12: € | D12: =$D$10+$D$9*$D$11 -> 500 | K12: Βασική + Ζώνες × Επιβάρυνση
A13: 1.1.7 | B13: Συνολικό πλήθος πασσάλων έργου | C13: τεμ. | D13: =$D$25+$E$25+$F$25+$G$25+$H$25+$I$25 -> 50 | K13: Άθροισμα ομάδων
A14: 1.1.8 | B14: Επιμερισμένη μετακίνηση ανά πάσσαλο | C14: € | D14: =$D$12/$D$13 -> 10 | K14: Συνολικό ποσό / Πλήθος πασσάλων
A15: Τομέας 2 — Υψόμετρα, Cut-Off & Σκυρόδεμα
A16: 1.2.1 | B16: Στάθμη πλατφόρμας γεωτρύπανου (WPL) | C16: m | D16: -6 | K16: ΚΟΚΚΙΝΟΣ ΣΥΝΑΓΕΡΜΟΣ: δεν δίνεται στο σχέδιο — προσωρινά 0.00
A17: 1.2.2 | B17: Στάθμη αποκοπής (Cut-Off Level) | C17: m | D17: -12 | K17: ΚΟΚΚΙΝΟΣ ΣΥΝΑΓΕΡΜΟΣ: δεν δίνεται στο σχέδιο — προσωρινά 0.00
A18: 1.2.3 | B18: Διαφορά στάθμης Δh = WPL − Cut-Off | C18: m | D18: =$D$16-$D$17 -> 6 | K18: Κενή διάτρηση
A19: 1.2.4 | B19: Ύψος υπερκάλυψης σκυροδέματος h_overc | C19: m | D19: =IF($D$18>0,MIN($D$57,$D$18),0) -> 2 | K19: IF(Δh > 0, MIN(2.00, Δh), 0)
A20: 1.2.5 | B20: Κατηγορία σκυροδέματος | C20: - | D20: C50/60 | K20: Σχέδιο, Παρατηρήσεις §1: «ΚΑΤΗΓΟΡΙΑΣ C50/60 … ΓΕΝΙΚΑ ΓΙΑ ΟΛΑ ΤΑ ΔΟΜΙΚΑ ΣΤΟΙΧΕΙΑ»
A21: 1.2.6 | B21: Επικάλυψη οπλισμού (Cover) | C21: mm | D21: 75 | K21: Σχέδιο, Παρατηρήσεις §3: «ΠΑΣΣΑΛΟΙ : 75mm»
A22: Τομέας 3 — Ομάδες πασσάλων & κλωβός οπλισμού (μία στήλη ανά ομάδα)
A23: Κωδ. | B23: Παράμετρος | C23: Μονάδα | D23: Ομάδα 1 | E23: Ομάδα 2 | F23: Ομάδα 3 | G23: Ομάδα 4 | H23: Ομάδα 5 | I23: Ομάδα 6 | K23: Παρατηρήσεις
A24: 1.3.0 | B24: Πάσσαλοι | D24: Ø1500 L=22.0 P1–P21 | E24: Ø1200 L=16.0 P22–P32, P41–P42 | F24: Ø1200 L=17.0 P36–P40 | G24: Ø1200 L=18.0 P33–P35 | H24: Ø1200 L=19.0 P43–P48 | I24: Ø1200 L=10.5 P49–P50
A25: 1.3.1 | B25: Πλήθος πασσάλων ομάδας | C25: τεμ. | D25: 21 | E25: 13 | F25: 5 | G25: 3 | H25: 6 | I25: 2 | J25: =$D$25+$E$25+$F$25+$G$25+$H$25+$I$25 -> 50 | K25: Κατάλογος πασσάλων (στήλη Α/Α)
A26: 1.3.2 | B26: Διάμετρος διάτρησης D | C26: mm | D26: 1500 | E26: 1200 | F26: 1200 | G26: 1200 | H26: 1200 | I26: 1200 | K26: Κατάλογος — στήλη «ΔΙΑΣΤΑΣΕΙΣ»
A27: 1.3.3 | B27: Μήκος πασσάλου στο έδαφος L_pile | C27: m | D27: 22 | E27: 16 | F27: 17 | G27: 18 | H27: 19 | I27: 10.5 | K27: Κατάλογος — στήλη «ΒΑΘΟΣ (ΠΑΣΑΛΛΟΥ)»
A28: 1.3.4 | B28: Κάθετες ράβδοι — πλήθος N_vert | C28: τεμ. | D28: 16 | E28: 16 | F28: 16 | G28: 16 | H28: 16 | I28: 16 | K28: Κατάλογος — στήλη «# ΟΠΛΙΣΜΟΣ ΠΑΣΣΑΛΩΝ»
A29: 1.3.5 | B29: Κάθετες ράβδοι — διάμετρος Φ | C29: mm | D29: 32 | E29: 25 | F29: 25 | G29: 25 | H29: 25 | I29: 25
A30: 1.3.6 | B30: Αναμονή / Starter | C30: m | D30: 1.485 | E30: 1.485 | F30: 1.485 | G30: 1.485 | H30: 1.485 | I30: 0.585 | K30: ΜΕΤΡΗΣΗ: βάθος πεδιλόπλακας (κατάλογος) − 0.215 m (τυπική όψη) | L30: βαζε 10 ποντους λιγοτερους από το υψος της πεδιλοπλακας ανδεν σου λεει εχτως αν είναι η πεδιλοπλακα
A31: 1.3.7 | B31: Γωνία πάνω (top hook) | C31: m | D31: 0.225 | E31: 0.225 | F31: 0.225 | G31: 0.225 | H31: 0.225 | I31: 0.225 | K31: ΜΕΤΡΗΣΗ: (πλάτος κεφαλής 1800/1500 − κλωβός 1350/1050) / 2 | L31: βαζε στανταρ 50 ποντους γωνια αν δεν σου την δωσει στο σχεδιο εχτως αν η πεδιπλακα είναι μικροτερη 80 ποντους τοτε η γωνια είναι κατι άλλο. Ζητα μου το εμενα
A32: 1.3.8 | B32: Γωνία πυθμένα (bottom bend) | C32: m | D32: 0 | E32: 0 | F32: 0 | G32: 0 | H32: 0 | I32: 0
A33: 1.3.9 | B33: Σούστα / συνδετήρες — διάμετρος Φ | C33: mm | D33: 14 | E33: 12 | F33: 12 | G33: 12 | H33: 12 | I33: 12 | K33: Κατάλογος — στήλες «ΣΥΝΔΕΤΗΡΕΣ»
A34: 1.3.10 | B34: Βήμα σούστας στα άκρα | C34: mm | D34: 100 | E34: 100 | F34: 100 | G34: 100 | H34: 100 | I34: 100 | K34: Κατάλογος — «3Μ ΠΡΩΤΑ / 3Μ ΤΕΛΕΥΤΑΙΑ ΜΕΤΡΑ»
A35: 1.3.11 | B35: Μήκος ζώνης άκρου (πάνω & κάτω, έκαστη) | C35: m | D35: 3 | E35: 3 | F35: 3 | G35: 3 | H35: 3 | I35: 3 | K35: Σχέδιο — διαστάσεις 3000 στις όψεις
A36: 1.3.12 | B36: Βήμα σούστας στο μέσο | C36: mm | D36: 150 | E36: 150 | F36: 150 | G36: 150 | H36: 150 | I36: 150 | K36: Κατάλογος — «ΣΥΝΔΕΤΗΡΕΣ (ΜΕΣΟ)»
A37: 1.3.13 | B37: Συνδετήρες στην κεφαλή (μέσα στην πεδιλόπλακα) | C37: τεμ. | D37: 10 | E37: 10 | F37: 10 | G37: 10 | H37: 10 | I37: 5 | K37: ΜΕΤΡΗΣΗ: 10 συνδετήρες σχεδιασμένοι στην κεφαλή (όψεις)· P49–P50: ΠΑΡΑΔΟΧΗ 5 | L37: εδώ επρεπε να κανεις υψος πεδιλοπλακας δια αποσταση σουστας πρωτων 3 μετρων εφοσον δεν σου εδωσε την σουστα εκεινη. Αν στην δωσει κανεις δια την αποσταση π σ λεει
A38: 1.3.14 | B38: Πρόσθετος οπλισμός (U-bars κ.λπ.) — πλήθος | C38: τεμ. | D38: 8 | E38: 8 | F38: 8 | G38: 8 | H38: 8 | I38: 8 | K38: Σχέδιο — «8Y32 U-BARS» / «8Y25 U-BARS» στη βάση των όψεων
A39: 1.3.15 | B39: Πρόσθετος οπλισμός — διάμετρος Φ | C39: mm | D39: 32 | E39: 25 | F39: 25 | G39: 25 | H39: 25 | I39: 25
A40: 1.3.16 | B40: Πρόσθετος οπλισμός — μήκος ανά ράβδο | C40: m | D40: 4.55 | E40: 3.55 | F40: 3.55 | G40: 3.55 | H40: 3.55 | I40: 3.55 | K40: Σχέδιο — U-bar 1600×1350 / 1250×1050 → 2×σκέλος + πλάτος
A42: 2. ΤΕΛΙΚΕΣ ΠΟΣΟΤΗΤΕΣ ΓΙΑ ΤΗΝ ΟΙΚΟΝΟΜΙΚΗ ΠΡΟΣΦΟΡΑ
...
