Workbook

Sheet Οικονομική Προσφορά
A1: ΘΕΜΕΛΙΟΤΕΧΝΙΚΗ ΛΤΔ — ΟΙΚΟΝΟΜΙΚΗ ΠΡΟΣΦΟΡΑ ΠΑΣΣΑΛΩΝ
A2: Έργο: BOLTON TOWER | Πελάτης: ΛΑΚΕΜΙΑ ΚΤΗΜΑΤΙΚΗ Λτδ | Τοποθεσία: Λεμεσός | Πλήθος Πασσάλων: 50 τεμ.
A4: 🛑 ΠΡΟΣΟΧΗ — RED ALERT: Στα σχέδια της μελέτης ΔΕΝ αναγράφονται τα υψόμετρα πλατφόρμας εργασίας (WPL) και Cut-Off Level. Η παρούσα προσφορά έχει υπολογιστεί προσωρινά με μηδενική κενή διάτρηση (Δh = 0.00 m). Απαιτείται επιβεβαίωση στο εργοτάξιο πριν την οριστικοποίηση.
A7: Α/Α | B7: Περιγραφή Εργασίας / Υλικού | C7: Ποσότητα ανά Πάσσαλο | D7: Μονάδα | E7: Τιμή Μονάδας (€) [ΚΙΤΡΙΝΟ] | F7: Κόστος ανά Πάσσαλο (€) | G7: Σύνολο Όλων των Πασσάλων (€)
A8: 1 | B8: Μετακινήσεις & Εγκατάσταση Γεωτρύπανου (Επιμερισμός σε 50 πασσάλους) | C8: 1 | D8: πάσσαλο | E8: 10 | F8: =C8*E8 -> 10 | G8: ='Τεχνικοί Υπολογισμοί'!E10 -> 500
A9: 2a | B9: Τρύπημα / Διάτρηση Πασσάλων Ø1500mm (21 τεμ., Βάθος 22.00m) | C9: ='Τεχνικοί Υπολογισμοί'!E23 -> 22 | D9: m | E9: 210 | F9: =C9*E9 -> 4620 | G9: ='Τεχνικοί Υπολογισμοί'!F23*E9 -> 97020
A10: 2b | B10: Τρύπημα / Διάτρηση Πασσάλων Ø1200mm (29 τεμ., Βάθη 10.50m - 19.00m) | C10: ='Τεχνικοί Υπολογισμοί'!E24 -> #VALUE! | D10: m | E10: 190 | F10: =C10*E10 -> #VALUE! | G10: ='Τεχνικοί Υπολογισμοί'!F24*E10 -> #VALUE!
A11: 3 | B11: Σκυροδέτηση Πασσάλων C30/37 (Κουγκρί με +10% απώλεια) | C11: ='Τεχνικοί Υπολογισμοί'!E25 -> 18.541271 | D11: m³ | E11: 115 | F11: =C11*E11 -> 2132.2461 | G11: ='Τεχνικοί Υπολογισμοί'!F25*E11 -> 106612.31
A12: 4 | B12: Χάλυβας Οπλισμού B500C (Κλωβοί: Κάθετες Ράβδοι & Σούστα) | C12: ='Τεχνικοί Υπολογισμοί'!E26 -> #VALUE! | D12: kg | E12: 1.1 | F12: =C12*E12 -> #VALUE! | G12: ='Τεχνικοί Υπολογισμοί'!F26*E12 -> #VALUE!
A13: 5 | B13: Sleeves Προστασίας Starter Αναμονών (Debonding) | C13: ='Τεχνικοί Υπολογισμοί'!E27 -> 0 | D13: τεμ. | E13: 3.5 | F13: =C13*E13 -> 0 | G13: ='Τεχνικοί Υπολογισμοί'!F27*E13 -> 0
A14: 6 | B14: Κεφαλοκοπή Πασσάλων / Pile Breaking (Σπάσιμο) | C14: ='Τεχνικοί Υπολογισμοί'!E28 -> 0 | D14: πάσσαλο | E14: 60 | F14: =C14*E14 -> 0 | G14: ='Τεχνικοί Υπολογισμοί'!F28*E14 -> 0
A15: ΓΕΝΙΚΟ ΣΥΝΟΛΟ ΟΙΚΟΝΟΜΙΚΗΣ ΠΡΟΣΦΟΡΑΣ (ΧΩΡΙΣ Φ.Π.Α.) | F15: =SUM(F8:F14) -> #VALUE! | G15: =SUM(G8:G14) -> #VALUE!
A17: ΟΡΟΙ, ΠΡΟΫΠΟΘΕΣΕΙΣ & ΤΕΧΝΙΚΕΣ ΠΑΡΑΤΗΡΗΣΕΙΣ ΠΡΟΣΦΟΡΑΣ:
A18: 1. Στις ανωτέρω τιμές ΔΕΝ συμπεριλαμβάνεται ο εκάστοτε νόμιμος Φ.Π.Α. (19%).
A19: 2. Τιμολόγηση Διάτρησης: Ø1500mm στα 210.00 €/m (κατόπιν ρητής οδηγίας πελάτη) και Ø1200mm στα 190,00 €/m (επίσημος τιμοκατάλογος εταιρείας).
A20: 3. Σκυρόδεμα κατηγορίας C30/37 στα 115,00 €/m³ με συνυπολογισμένο πάγιο συντελεστή απώλειας / υπερκατανάλωσης +10%.
A21: 4. Χάλυβας οπλισμού ποιότητας B500C ενιαία στα 1,10 €/kg (αγορά, κοπή, κατασκευή κλωβών και τοποθέτηση).
A22: 5. Υψομετρική Διαφορά (WPL - CutOff): Επειδή στα σχέδια δεν δίνονται υψόμετρα, η προσφορά υπολογίζει προσωρινά Δh = 0.00 m. Εάν κατά την έναρξη των εργασιών διαπιστωθεί κενή διάτρηση (Δh > 0), θα τιμολογηθούν τα πρόσθετα μέτρα διάτρησης, τα sleeves προστασίας αναμονών (3,50 €/τεμ.) και η κεφαλοκοπή (60,00 €/πάσσαλο).
A23: 6. Μετακινήσεις: Εφάπαξ ποσό 500,00 € (Ζώνη 1: 0-50km από έδρα Αγίου Συλά, Λεμεσός), επιμερισμένο ισόποσα σε 10,00 € ανά πάσσαλο (500 € / 50 πάσσαλοι).
A24: 7. Πληρωμή: Βάσει επιμετρήσεων πραγματικών εκτελεσθέντων μέτρων και κιλών οπλισμού κατά την παράδοση του έργου.
A25: 8. ΣΗΜΕΙΩΣΗ ΤΙΜΩΝ ΔΙΑΤΡΗΣΗΣ: Οι τιμές τρυπήματος/διάτρησης ενδέχεται να αναθεωρηθούν / αλλάξουν μελλοντικά βάσει των συνθηκών της αγοράς, του κόστους καυσίμων και της διαθεσιμότητας του εξοπλισμού.

Sheet Τεχνικοί Υπολογισμοί
A1: ΘΕΜΕΛΙΟΤΕΧΝΙΚΗ ΛΤΔ — ΤΕΧΝΙΚΟΙ ΥΠΟΛΟΓΙΣΜΟΙ ΔΙΑΤΡΗΤΩΝ ΠΑΣΣΑΛΩΝ
A2: Έργο: BOLTON TOWER (Λεμεσός) | Μελέτη: Hyperstatic Eng. | Πάσσαλοι: 50 τεμ. (21×Ø1500mm, 29×Ø1200mm)
A4: 1. ΔΕΔΟΜΕΝΑ ΠΟΥ ΔΙΑΒΑΣΤΗΚΑΝ ΑΠΟ ΤΟ ΣΧΕΔΙΟ & ΥΨΟΜΕΤΡΑ (3 ΤΟΜΕΙΣ)
A5: Α/Α | B5: Κωδικός | C5: Παράμετρος Έργου | D5: Μονάδα | E5: Τιμή Εισαγωγής | F5: Περιγραφή Σχεδίου | G5: Παρατηρήσεις / Προέλευση
A6: 1 | B6: 1.1.1 | C6: Αφετηρία Γεωτρύπανου | D6: text | E6: Άγιος Συλάς, Λεμεσός | F6: Έδρα Εταιρείας | G6: Βασική αφετηρία εξοπλισμού
A7: 2 | B7: 1.1.2 | C7: Τοποθεσία Έργου | D7: text | E7: Λεμεσός (Bolton Tower) | F7: Σχέδιο CAD | G7: Κέντρο Λεμεσού
A8: 3 | B8: 1.1.3 | C8: Οδική Απόσταση Έργου από Έδρα | D8: km | E8: 15 | F8: 15.0 km | G8: Εντός Ζώνης 1 (0-50 km)
A9: 4 | B9: 1.1.4 | C9: Συνολικό Πλήθος Πασσάλων Έργου | D9: τεμ. | E9: 50 | F9: 50 πάσσαλοι | G9: 21×Ø1500mm + 29×Ø1200mm
A10: 5 | B10: 1.1.5 | C10: Συνολικό Εφάπαξ Ποσό Μετακίνησης | D10: € | E10: 500 | F10: 500.00 € | G10: Βασική τιμή Ζώνης 1 καταλόγου
A11: 6 | B11: 1.1.6 | C11: Επιμερισμένη Τιμή Μετακίνησης ανά Πάσσαλο | D11: €/πάσσαλο | E11: =E10/E9 -> 10 | F11: 10.00 €/πάσσαλο | G11: Εφάπαξ ποσό επιμερισμένο σε 50 πασσάλους
A12: 7 | B12: 1.2.1 | C12: Στάθμη Πλατφόρμας Γεωτρύπανου (WPL) | D12: m | E12: 0 | F12: Δεν δίνεται στο σχέδιο | G12: RED ALERT: Προσωρινή τιμή 0.00m
A13: 8 | B13: 1.2.2 | C13: Στάθμη Αποκοπής Πασσάλων (Cut-Off Level) | D13: m | E13: 0 | F13: Δεν δίνεται στο σχέδιο | G13: RED ALERT: Προσωρινή τιμή 0.00m
A14: 9 | B14: 1.2.3 | C14: Διαφορά Στάθμης Διάτρησης - Cut-Off (Δh) | D14: m | E14: =E12-E13 -> 0 | F14: 0.00 m (WPL - CutOff) | G14: RED ALERT: Κενή διάτρηση προσωρινά 0.00m
A15: 10 | B15: 1.2.4 | C15: Ύψος Υπερκάλυψης Σκυροδέματος (h_overc) | D15: m | E15: =IF(E14>0,MIN(2,E14),0) -> 0 | F15: Overconcreting | G15: Έως +2.0m αν Δh > 0
A16: 11 | B16: 1.2.5 | C16: Κατηγορία Σκυροδέματος Μελέτης | D16: class | E16: C30/37 | F16: C30/37 (115,00 €/m³) | G16: Default εταιρείας (ανωδομή C50/60)
A17: 12 | B17: 1.3.1 | C17: Επικάλυψη Οπλισμού (Cover) | D17: mm | E17: 75 | F17: 75 mm | G17: Αναγράφεται ρητά στις παρατηρήσεις σχεδίου
A18: 13 | B18: 1.3.2 | C18: Γωνία Πυθμένα Κλωβού (Bottom Bend) | D18: m | E18: 0 | F18: 0.00 m / Δεν απαιτείται | G18: Δεν αναφέρεται στο σχέδιο
A19: 14 | B19: 1.3.3 | C19: Sleeves Προστασίας Starter ανά Πάσσαλο | D19: τεμ./πάσσαλο | E19: =IF(E14>0,16,0) -> 0 | F19: IF(Δh>0, Nvert, 0) | G19: 0 τεμ. όταν Δh = 0
A21: 2. ΤΕΛΙΚΕΣ ΠΟΣΟΤΗΤΕΣ ΓΙΑ ΤΗΝ ΟΙΚΟΝΟΜΙΚΗ ΠΡΟΣΦΟΡΑ (SUMMARY RESULTS)
A22: Α/Α | B22: Κωδικός | C22: Περιγραφή Τελικής Ποσότητας | D22: Μονάδα | E22: Μέση Ποσότητα / Πάσσαλο | F22: Σύνολο Όλων των Πασσάλων | G22: Σύνδεση με Φύλλο 1
A23: 1 | B23: 2.1 | C23: Τρέχοντα Μέτρα Διάτρησης Ø1500mm (21 πάσσαλοι) | D23: m | E23: =F23/21 -> 22 | F23: =F45 -> 462 | G23: Τροφοδοτεί Γραμμή 2a Προσφοράς
A24: 2 | B24: 2.2 | C24: Τρέχοντα Μέτρα Διάτρησης Ø1200mm (29 πάσσαλοι) | D24: m | E24: =F24/29 -> #VALUE! | F24: =F61 -> — | G24: Τροφοδοτεί Γραμμή 2b Προσφοράς
A25: 3 | B25: 2.3 | C25: Κυβικά Σκυροδέματος C30/37 με +10% απώλεια | D25: m³ | E25: =F25/E9 -> 18.541271 | F25: =F47+F63 -> 927.06353 | G25: Τροφοδοτεί Γραμμή 3 Προσφοράς
A26: 4 | B26: 2.4 | C26: Συνολικό Βάρος Χάλυβα Οπλισμού B500C | D26: kg | E26: =F26/E9 -> #VALUE! | F26: =F55+F71 -> #VALUE! | G26: Τροφοδοτεί Γραμμή 4 Προσφοράς
A27: 5 | B27: 2.5 | C27: Sleeves Προστασίας Starter Αναμονών | D27: τεμ. | E27: =F27/E9 -> 0 | F27: =IF(E14>0,50*16,0) -> 0 | G27: Τροφοδοτεί Γραμμή 5 Προσφοράς
A28: 6 | B28: 2.6 | C28: Κεφαλοκοπή Πασσάλων / Pile Breaking | D28: τεμ. | E28: =F28/E9 -> 0 | F28: =IF(E14>0,50,0) -> 0 | G28: Τροφοδοτεί Γραμμή 6 Προσφοράς
A30: 3. ΣΤΑΘΕΡΕΣ ΤΕΧΝΙΚΕΣ ΠΑΡΑΔΟΧΕΣ (COMPANY STANDARDS)
A31: Α/Α | B31: Κωδικός | C31: Παραδοχή / Φυσική Σταθερά | D31: Μονάδα | E31: Αριθμητική Τιμή | F31: Περιγραφή | G31: Κανόνας Τιμοκαταλόγου
A32: 1 | B32: 3.1 | C32: Συντελεστής Απώλειας / Υπερκατανάλωσης Σκυροδέματος | D32: % | E32: 0.1 | F32: 10% | G32: Πάγια προσαύξηση όγκου +10% (V_conc = V_geom × 1.10)
A33: 2 | B33: 3.2 | C33: Ειδικό Βάρος Δομικού Χάλυβα Οπλισμού (ρ) | D33: kg/m³ | E33: 7850 | F33: 7,850 kg/m³ | G33: Φυσική σταθερά χάλυβα B500C
A34: 3 | B34: 3.3 | C34: Μέγιστο Εμπορικό Μήκος Βέργας Χάλυβα | D34: m | E34: 12 | F34: 12.00 m | G34: Όριο πέραν του οποίου απαιτείται μάτιση
A35: 4 | B35: 3.4 | C35: Συντελεστής Μήκους Μάτισης Ράβδων (Lapping) | D35: ×Φ | E35: 50 | F35: 50 × Φ | G35: Επικάλυψη ράβδων σε βαθιούς πασσάλους
A36: 5 | B36: 3.5 | C36: Μέγιστο Ύψος Υπερκάλυψης Σκυροδέματος (Overconcreting) | D36: m | E36: 2 | F36: +2.00 m | G36: Έως +2.0m πάνω από cut-off αν Δh > 0
A37: 6 | B37: 3.6 | C37: Μαθηματική Σταθερά π | D37: const | E37: =PI() -> 3.1415927 | F37: 3.14159... | G37: Υπολογισμός εμβαδού και όγκου κυλίνδρου
A40: 4.1 ΤΥΠΟΣ 1: ΠΑΣΣΑΛΟΙ Ø1500mm — 21 ΤΕΜΑΧΙΑ (P1 - P21, ΒΑΘΟΣ 22.00m)
A41: Βήμα | B41: Κωδικός | C41: Μαθηματικό Βήμα Υπολογισμού | D41: Μονάδα | E41: Τιμή ανά Πάσσαλο | F41: Σύνολο Τύπου 1 (21 τεμ.) | G41: Τύπος Υπολογισμού (Excel Formula)
A42: 1 | B42: T1.1 | C42: Πλήθος πασσάλων Τύπου 1 | D42: τεμ. | E42: 21 | F42: 21 | G42: 21 πάσσαλοι (P1 έως P21)
A43: 2 | B43: T1.2 | C43: Ονομαστική διάμετρος διάτρησης (D) | D43: mm | E43: 1500 | F43: — | G43: Διάμετρος οπής 1.50 m
A44: 3 | B44: T1.3 | C44: Μήκος πασσάλου στο έδαφος (L_pile) | D44: m | E44: 22 | F44: — | G44: Καθαρό βάθος πασσάλου
A45: 4 | B45: T1.4 | C45: Συνολικό βάθος διάτρησης (L_drill) | D45: m | E45: =E44+E14 -> 22 | F45: =E45*E42 -> 462 | G45: L_drill = L_pile + Δh
...
